Workbook

Sheet TOTAL
A3: DATE: | D3: 46153 | K3: MINE EXPLOSIVES DAILY REPORT
A5: SHIFT | B5: CONT. | C5: DRILL STEEL | D5: WORKING PLACE | E5: SUPER POWER | F5: PULSAR | G5: EM AUSTIN | H5: NEOGEL | I5: PULSAR | J5: PULSAR | K5: ANFO | L5: SAFETY FUSE | M5: OBC | N5: NONEL | P5: EXEL | Q5: SUPREME | S5: EXEL | T5: EXEL | U5: SHOCK STAR | V5: MS 18 | W5: CORDTEX | AA5: FUSE LIGHTER | AB5: EBC | AC5: BILL WIRE | AE5: STOPE | AG5: ROBBING | AI5: HORIZONTAL | AK5: RAISE | AM5: WINZE | AO5: SHAFT/CHAMBER/OREPASS
E6: 208 | F6: 38 | G6: 200 | H6: 200 | I6: 135 | J6: 215 | N6: 2.4 | O6: 3.6 | P6: 3.6 | Q6: 2.4 | R6: 3.6 | S6: 4.9 | T6: 2.4 | U6: 2.4 | W6: 5 | X6: 10 | Y6: DCORD I5 | Z6: 40
E7: PCS | F7: PCS | G7: PCS | H7: PCS | I7: PCS | J7: PCS | K7: KLS | L7: MTRS | M7: PCS | N7: PCS | O7: PCS | P7: PCS | Q7: PCS | R7: PCS | S7: PCS | T7: PCS | U7: PCS | V7: PCS | W7: MTR | X7: MTR | Y7: MTR | Z7: MTR | AA7: PCS | AB7: PCS | AC7: PCS | AE7: PB | AF7: SB | AG7: PB | AH7: SB | AI7: PB | AJ7: SB | AK7: PB | AL7: SB | AM7: PB | AN7: SB | AO7: PB | AP7: SB
D8: STOCK CODE | E8: 17457 | F8: 21811 | G8: 31496 | H8: 35245 | I8: 21810 | J8: 11082 | K8: 10128 | L8: 12487 | M8: 11966 | N8: 10962 | O8: 15427 | P8: 10966 | Q8: 16623 | R8: 16967 | S8: 21809 | T8: 10965 | U8: 28230 | V8: 10964 | W8: 10960 | X8: 10961 | Y8: 33442 | Z8: 10959 | AA8: 11342 | AB8: 11089 | AC8: 16823
A10: 1 | L10: =M10*2.43 -> 0
A11: 1 | L11: =M11*2.43 -> 0
A12: 1 | L12: =M12*2.43 -> 0
A13: TOTAL | E13: =SUM(E10:E12) -> 0 | F13: =SUM(F10:F12) -> 0 | G13: =SUM(G10:G12) -> 0 | H13: =SUM(H10:H12) -> 0 | I13: =SUM(I10:I12) -> 0 | J13: =SUM(J10:J12) -> 0 | K13: =SUM(K10:K12) -> 0 | L13: =SUM(L10:L12) -> 0 | ... AC13: =SUM(AC10:AC12) -> 0 | AE13: =SUM(AE10:AE12) -> 0 | AF13: =SUM(AF10:AF12) -> 0 | AG13: =SUM(AG10:AG12) -> 0 | AH13: =SUM(AH10:AH12) -> 0 | AI13: =SUM(AI10:AI12) -> 0 | AJ13: =SUM(AJ10:AJ12) -> 0 | AK13: =SUM(AK10:AK12) -> 0 | AL13: =SUM(AL10:AL12) -> 0 | ... AP13: =SUM(AP10:AP12) -> 0
A14: 2 | L14: =M14*2.43 -> 0
A15: 2 | L15: =M15*2.43 -> 0
A16: 2 | L16: =M16*2.43 -> 0
A17: TOTAL | E17: =SUM(E14:E16) -> 0 | F17: =SUM(F14:F16) -> 0 | G17: =SUM(G14:G16) -> 0 | H17: =SUM(H14:H16) -> 0 | I17: =SUM(I14:I16) -> 0 | J17: =SUM(J14:J16) -> 0 | K17: =SUM(K14:K16) -> 0 | L17: =SUM(L14:L16) -> 0 | ... AC17: =SUM(AC14:AC16) -> 0 | AE17: =SUM(AE14:AE16) -> 0 | AF17: =SUM(AF14:AF16) -> 0 | AG17: =SUM(AG14:AG16) -> 0 | AH17: =SUM(AH14:AH16) -> 0 | AI17: =SUM(AI14:AI16) -> 0 | AJ17: =SUM(AJ14:AJ16) -> 0 | AK17: =SUM(AK14:AK16) -> 0 | AL17: =SUM(AL14:AL16) -> 0 | ... AP17: =SUM(AP14:AP16) -> 0
A18: 3 | L18: =M18*2.43 -> 0
A19: 3 | L19: =M19*2.43 -> 0
A20: 3 | L20: =M20*2.43 -> 0
A21: 3 | L21: =M21*2.43 -> 0
A22: TOTAL | E22: =SUM(E18:E21) -> 0 | F22: =SUM(F18:F21) -> 0 | G22: =SUM(G18:G21) -> 0 | H22: =SUM(H18:H21) -> 0 | I22: =SUM(I18:I21) -> 0 | J22: =SUM(J18:J21) -> 0 | K22: =SUM(K18:K21) -> 0 | L22: =SUM(L18:L21) -> 0 | ... AC22: =SUM(AC18:AC21) -> 0 | AE22: =SUM(AE18:AE21) -> 0 | AF22: =SUM(AF18:AF21) -> 0 | AG22: =SUM(AG18:AG21) -> 0 | AH22: =SUM(AH18:AH21) -> 0 | AI22: =SUM(AI18:AI21) -> 0 | AJ22: =SUM(AJ18:AJ21) -> 0 | AK22: =SUM(AK18:AK21) -> 0 | AL22: =SUM(AL18:AL21) -> 0 | ... AP22: =SUM(AP18:AP21) -> 0 | AQ22: CLASSIC | AR22: PB | AS22: SB
AQ23: DRIFT/CROSSCUT | AR23: =AI24 -> 0 | AS23: =AJ24 -> 0
A24: GRAND TOTAL | E24: =E22+E17+E13 -> 0 | F24: =F22+F17+F13 -> 0 | G24: =G22+G17+G13 -> 0 | H24: =H22+H17+H13 -> 0 | I24: =I22+I17+I13 -> 0 | J24: =J22+J17+J13 -> 0 | K24: =K22+K17+K13 -> 0 | L24: =L22+L17+L13 -> 0 | ... AC24: =AC22+AC17+AC13 -> 0 | AE24: =AE22+AE17+AE13 -> 0 | AF24: =AF22+AF17+AF13 -> 0 | AG24: =AG22+AG17+AG13 -> 0 | AH24: =AH22+AH17+AH13 -> 0 | AI24: =AI22+AI17+AI13 -> 0 | AJ24: =AJ22+AJ17+AJ13 -> 0 | AK24: =AK22+AK17+AK13 -> 0 | AL24: =AL22+AL17+AL13 -> 0 | ... AP24: =AP22+AP17+AP13 -> 0 | AQ24: RAISE | AR24: =AK24 -> 0 | AS24: =AL24 -> 0
B25: PRICE | E25: 21.64 | F25: 26.83 | G25: 35.47 | H25: 26.67 | I25: 40 | J25: 26.42 | K25: 85.25 | L25: 26.5 | M25: 28.5 | N25: 192.35 | O25: 198 | P25: 198 | Q25: 192.35 | R25: 198 | T25: 192 | U25: 359.83 | V25: 379.46 | W25: 35.2 | X25: 40.2 | Y25: 36.4 | Z25: 81.9 | AA25: 16.5 | AB25: 285 | AC25: 16.8 | AQ25: WINZE | AR25: =AM24 -> 0 | AS25: =AN24 -> 0
B26: TOTAL COST | D26: 0 | E26: =E24*E25 -> 0 | F26: =F24*F25 -> 0 | G26: =G24*G25 -> 0 | H26: =H24*H25 -> 0 | I26: =I24*I25 -> 0 | J26: =J24*J25 -> 0 | K26: =K24*K25 -> 0 | L26: =L24*L25 -> 0 | ... AC26: =AC24*AC25 -> 0
A28: OVER ALL TOTAL | E28: ='SINUG-ANG'!F19+'L03'!F13+'L6'!E13+'L7'!F14+'L8'!F28+'L9'!F17+'L10'!F18+'L11'!F27+'L12'!F24+'L425'!F38+'L460'!F23 -> 0 | F28: ='SINUG-ANG'!G19+'L03'!G13+'L6'!F13+'L7'!G14+'L8'!G28+'L9'!G17+'L10'!G18+'L11'!G27+'L12'!G24+'L425'!G38+'L460'!G23 -> 0 | G28: ='SINUG-ANG'!H19+'L03'!H13+'L6'!G13+'L7'!H14+'L8'!H28+'L9'!H17+'L10'!H18+'L11'!H27+'L12'!H24+'L425'!H38+'L460'!H23 -> 0 | H28: ='SINUG-ANG'!I19+'L03'!I13+'L6'!H13+'L7'!I14+'L8'!I28+'L9'!I17+'L10'!I18+'L11'!I27+'L12'!I24+'L425'!I38+'L460'!I23 -> 1697 | I28: ='SINUG-ANG'!J19+'L03'!J13+'L6'!I13+'L7'!J14+'L8'!J28+'L9'!J17+'L10'!J18+'L11'!J27+'L12'!J24+'L425'!J38+'L460'!J23 -> 0 | J28: ='SINUG-ANG'!K19+'L03'!K13+'L6'!J13+'L7'!K14+'L8'!K28+'L9'!K17+'L10'!K18+'L11'!K27+'L12'!K24+'L425'!K38+'L460'!K23 -> 1404 | K28: ='SINUG-ANG'!L19+'L03'!L13+'L6'!K13+'L7'!L14+'L8'!L28+'L9'!L17+'L10'!L18+'L11'!L27+'L12'!L24+'L425'!L38+'L460'!L23 -> 1179 | L28: ='SINUG-ANG'!M19+'L03'!M13+'L6'!L13+'L7'!M14+'L8'!M28+'L9'!M17+'L10'!M18+'L11'!M27+'L12'!M24+'L425'!M38+'L460'!M23 -> 464.13 | ... AC28: ='SINUG-ANG'!AD19+'L03'!AD13+'L6'!AC13+'L7'!AD14+'L8'!AD28+'L9'!AD17+'L10'!AD18+'L11'!AD27+'L12'!AD24+'L425'!AD38+'L460'!AD23 -> 30 | AD28: =SUM(E28:AC28) -> 7517.13 | AQ28: STOPE/STOPE PREP | AR28: =AE24 -> 0 | AS28: =AF24 -> 0
A29: UNIT PRICE | E29: 26.2921 | F29: 115.8 | G29: 35.47 | H29: 27.3438 | I29: 40 | J29: 29.5639 | K29: 145.88 | L29: 27.66 | M29: 26.25 | N29: 171.74107 | O29: 176.78571 | P29: 195 | Q29: 180.35714 | R29: 198 | S29: 195 | T29: 189.38 | U29: 207 | V29: 379.46 | W29: 35.15 | X29: 35.893 | Y29: 37.5 | Z29: 81.9 | AA29: 20.62 | AB29: 267.18 | AC29: 7.5
A30: TOTAL COST | E30: =E28*E29 -> 0 | F30: =F28*F29 -> 0 | G30: =G28*G29 -> 0 | H30: =H28*H29 -> 46402.429 | I30: =I28*I29 -> 0 | J30: =J28*J29 -> 41507.716 | K30: =K28*K29 -> 171992.52 | L30: =L28*L29 -> 12837.836 | ... AC30: =AC28*AC29 -> 225
M32: NONEL 2.4/3.6 | R32: =N28+O28 -> 0 | AQ32: CHAMBER/SHAFT | AR32: =AO24 -> 0 | AS32: =AP24 -> 0
A33: PRIMARY BLAST | M33: EXEL 3.6/2.4/4.9 | R33: =P28+T28+S28 -> 1770 | X33: ='L2'!D36+'SINUG-ANG'!E21+'L03'!E15+'L6'!D15+'L7'!E16+'L8'!E30+'L9'!E19+'L10'!E20+'L11'!E29+'L12'!E26 -> 408278.51
A34: NO. OF HOLES | M34: SUPREME 2.4/3.6 | R34: =Q28+R28 -> 0
A35: SECONDARY BLAST | M35: CORDTEX 5/6/40/10 | R35: =W28+X28+Y28+Z28 -> 780 | W35: DAILY COST | Z35: =E30+F30+J30+K30+L30+M30+N30+O30+P30+Q30+R30+T30+W30+X30+Y30+Z30+AA30+AB30+AC30+U30+V30+G30+H30+S30 -> 641417.77
A36: NO. OF HOLES | M36: SHOCKSTAR 2.4 | R36: =U28 -> 0
A37: Bouldering | W37: TODATE COST
A40: PREPARED BY: __________________ | G40: CHECKED BY: _____________________ | P40: ENTRY DATABASE: | S40: ____________________
D45: DESCRIPTION | E45: ISSUANCE | F45: PRICE | G45: COST
D46: DYNA SUPERPOWER 208 | E46: =E28 -> 0 | F46: 26.2921 | G46: =E46*F46 -> 0
D47: NEOGEL 200 | E47: =H28 -> 1697 | F47: 27.3438
D48: DYNAPULSAR 215 | E48: =J28 -> 1404 | F48: 29.5639 | G48: =E48*F48 -> 41507.716
D49: ANFO | E49: =K28 -> 1179 | F49: 145.88 | G49: =E49*F49 -> 171992.52
D50: S/FUSE | E50: =L28 -> 464.13 | F50: 27.66 | G50: =E50*F50 -> 12837.836
D51: OBC | E51: =M28 -> 191 | F51: 26.25 | G51: =E51*F51 -> 5013.75
D52: F/LIGHTER | E52: =AA28 -> 0 | F52: 20.62 | G52: =E52*F52 -> 0
...

Sheet SINUG-ANG
A1: DATE: | C1: =TOTAL!D3 -> 46153 | N1: SINUG-ANG
A3: SHIFT | B3: CONT. | C3: Sup | D3: DRILL STEEL | E3: WORKING PLACE | F3: SUPER POWER | G3: PULSAR | H3: EM AUSTIN | I3: NEOGEL | J3: PULSAR | K3: PULSAR | L3: ANFO | M3: SAFETY FUSE | N3: OBC | O3: NONEL | Q3: EXEL | R3: SUPREME | T3: EXEL | U3: EXEL | V3: SHOCK STAR | W3: MS 18 | X3: CORDTEX | AB3: FUSE LIGHTER | AC3: EBC | AD3: BILL WIRE | AF3: STOPE | AH3: ROBBING | AJ3: HORIZONTAL | AL3: RAISE | AN3: WINZE | AP3: SHAFT/CHAMBER/OREPASS
F4: 208 | G4: 38 | H4: 200 | I4: 200 | J4: 135 | K4: 215 | O4: 2.4 | P4: 3.6 | Q4: 3.6 | R4: 2.4 | S4: 3.6 | T4: 4.9 | U4: 2.4 | V4: 2.4 | X4: 5 | Y4: 10 | Z4: DCORD I5 | AA4: 40
F5: PCS | G5: PCS | H5: PCS | I5: PCS | J5: PCS | K5: PCS | L5: KLS | M5: MTRS | N5: PCS | O5: PCS | P5: PCS | Q5: PCS | R5: PCS | S5: PCS | T5: PCS | U5: PCS | V5: PCS | W5: PCS | X5: MTR | Y5: MTR | Z5: MTR | AA5: MTR | AB5: PCS | AC5: PCS | AD5: PCS | AF5: PB | AG5: SB | AH5: PB | AI5: SB | AJ5: PB | AK5: SB | AL5: PB | AM5: SB | AN5: PB | AO5: SB | AP5: PB | AQ5: SB
A6: 1 | B6: NO BLAST | M6: =N6*2.43 -> 0 | AE6: =O6+P6+Q6+R6+S6+T6+U6+V6 -> 0
A7: 1 | M7: =N7*2.43 -> 0 | AE7: =O7+P7+Q7+R7+S7+T7+U7+V7 -> 0
A8: 1 | M8: =N8*2.43 -> 0 | AE8: =O8+P8+Q8+R8+S8+T8+U8+V8 -> 0
A9: TOTAL | F9: =SUM(F6:F8) -> 0 | G9: =SUM(G6:G8) -> 0 | H9: =SUM(H6:H8) -> 0 | I9: =SUM(I6:I8) -> 0 | J9: =SUM(J6:J8) -> 0 | K9: =SUM(K6:K8) -> 0 | L9: =SUM(L6:L8) -> 0 | M9: =SUM(M6:M8) -> 0 | ... AD9: =SUM(AD6:AD8) -> 0 | AF9: =SUM(AF6:AF8) -> 0 | AG9: =SUM(AG6:AG8) -> 0 | AH9: =SUM(AH6:AH8) -> 0 | AI9: =SUM(AI6:AI8) -> 0 | AJ9: =SUM(AJ6:AJ8) -> 0 | AK9: =SUM(AK6:AK8) -> 0 | AL9: =SUM(AL6:AL8) -> 0 | AM9: =SUM(AM6:AM8) -> 0 | ... AQ9: =SUM(AQ6:AQ8) -> 0
A10: 2 | B10: NO BLAST | M10: =N10*2.43 -> 0 | AE10: =O10+P10+Q10+R10+S10+T10+U10+V10 -> 0
A11: 2 | M11: =N11*2.43 -> 0 | AE11: =O11+P11+Q11+R11+S11+T11+U11+V11 -> 0
A12: 2 | M12: =N12*2.43 -> 0 | AE12: =O12+P12+Q12+R12+S12+T12+U12+V12 -> 0
A13: TOTAL | F13: =SUM(F10:F12) -> 0 | G13: =SUM(G10:G12) -> 0 | H13: =SUM(H10:H12) -> 0 | I13: =SUM(I10:I12) -> 0 | J13: =SUM(J10:J12) -> 0 | K13: =SUM(K10:K12) -> 0 | L13: =SUM(L10:L12) -> 0 | M13: =SUM(M10:M12) -> 0 | ... AD13: =SUM(AD10:AD12) -> 0 | AF13: =SUM(AF10:AF12) -> 0 | AG13: =SUM(AG10:AG12) -> 0 | AH13: =SUM(AH10:AH12) -> 0 | AI13: =SUM(AI10:AI12) -> 0 | AJ13: =SUM(AJ10:AJ12) -> 0 | AK13: =SUM(AK10:AK12) -> 0 | AL13: =SUM(AL10:AL12) -> 0 | AM13: =SUM(AM10:AM12) -> 0 | ... AQ13: =SUM(AQ10:AQ12) -> 0
A14: 3 | B14: NO BLAST | M14: =N14*2.43 -> 0 | AE14: =O14+P14+Q14+R14+S14+T14+U14+V14 -> 0
A15: 3 | M15: =N15*2.43 -> 0 | AE15: =O15+P15+Q15+R15+S15+T15+U15+V15 -> 0 | AF15: =SUM(AE15) -> 0
A16: 3 | M16: =N16*2.43 -> 0 | AE16: =O16+P16+Q16+R16+S16+T16+U16+V16 -> 0 | AF16: =SUM(AE16) -> 0
A17: TOTAL | F17: =SUM(F14:F16) -> 0 | G17: =SUM(G14:G16) -> 0 | H17: =SUM(H14:H16) -> 0 | I17: =SUM(I14:I16) -> 0 | J17: =SUM(J14:J16) -> 0 | K17: =SUM(K14:K16) -> 0 | L17: =SUM(L14:L16) -> 0 | M17: =SUM(M14:M16) -> 0 | ... AD17: =SUM(AD14:AD16) -> 0 | AF17: =SUM(AF14:AF16) -> 0 | AG17: =SUM(AG14:AG16) -> 0 | AH17: =SUM(AH14:AH16) -> 0 | AI17: =SUM(AI14:AI16) -> 0 | AJ17: =SUM(AJ14:AJ16) -> 0 | AK17: =SUM(AK14:AK16) -> 0 | AL17: =SUM(AL14:AL16) -> 0 | AM17: =SUM(AM14:AM16) -> 0 | ... AQ17: =SUM(AQ14:AQ16) -> 0 | AR17: CLASSIC | AS17: PB | AT17: SB
AR18: DRIFT/CROSSCUT | AS18: =AJ19 -> 0 | AT18: =AK19 -> 0
A19: GRAND TOTAL | F19: =F17+F13+F9 -> 0 | G19: =G17+G13+G9 -> 0 | H19: =H17+H13+H9 -> 0 | I19: =I17+I13+I9 -> 0 | J19: =J17+J13+J9 -> 0 | K19: =K17+K13+K9 -> 0 | L19: =L17+L13+L9 -> 0 | M19: =M17+M13+M9 -> 0 | ... AD19: =AD17+AD13+AD9 -> 0 | AF19: =AF17+AF13+AF9 -> 0 | AG19: =AG17+AG13+AG9 -> 0 | AH19: =AH17+AH13+AH9 -> 0 | AI19: =AI17+AI13+AI9 -> 0 | AJ19: =AJ17+AJ13+AJ9 -> 0 | AK19: =AK17+AK13+AK9 -> 0 | AL19: =AL17+AL13+AL9 -> 0 | AM19: =AM17+AM13+AM9 -> 0 | ... AQ19: =AQ17+AQ13+AQ9 -> 0 | AR19: RAISE | AS19: =AL19 -> 0 | AT19: =AM19 -> 0
C20: PRICE | F20: 26.2921 | G20: 115.8 | H20: 35.47 | I20: 27.3438 | J20: 40 | K20: 29.5639 | L20: 145.88 | M20: 27.66 | N20: 26.25 | O20: 171.74107 | P20: 176.78571 | Q20: 195 | R20: 180.35714 | S20: 198 | T20: 195 | U20: 189.38 | V20: 207 | W20: 379.46 | X20: 35.15 | Y20: 35.893 | Z20: 37.5 | AA20: 81.9 | AB20: 20.62 | AC20: 267.18 | AD20: 7.5 | AR20: WINZE | AS20: =AN19 -> 0 | AT20: =AO19 -> 0
C21: TOTAL COST | E21: =F21+G21+K21+L21+M21+N21+O21+P21+Q21+R21+S21+U21+X21+Y21+Z21+AA21+AB21+AC21+AD21+H21+I21 -> 0 | F21: =F19*F20 -> 0 | G21: =G19*G20 -> 0 | H21: =H19*H20 -> 0 | I21: =I19*I20 -> 0 | K21: =K19*K20 -> 0 | L21: =L19*L20 -> 0 | M21: =M19*M20 -> 0 | N21: =N19*N20 -> 0 | O21: =O19*O20 -> 0 | P21: =P19*P20 -> 0 | Q21: =Q19*Q20 -> 0 | R21: =R19*R20 -> 0 | ... AD21: =AD19*AD20 -> 0 | AR21: STOPE/STOPE PREP | AS21: =AF19 -> 0 | AT21: =AG19 -> 0
AR22: ROBBING | AS22: =AH19 -> 0 | AT22: =AI19 -> 0
AR23: CHAMBER/SHAFT | AS23: =AP19 -> 0 | AT23: =AQ19 -> 0
B27: DESCRIPTION | C27: ISSUANCE | D27: PRICE | E27: COST
B28: DYNA SUPERPOWER 208 | D28: 26.2921 | E28: =C28*D28 -> 0
B29: NEOGEL 200 | C29: =I19 -> 0 | D29: 27.3438
B30: DYNAPULSAR 215 | C30: =K19 -> 0 | D30: 29.5639 | E30: =C30*D30 -> 0
B31: ANFO | C31: =L19 -> 0 | D31: 145.88 | E31: =C31*D31 -> 0
B32: S/FUSE | C32: =M19 -> 0 | D32: 27.66 | E32: =C32*D32 -> 0
B33: OBC | C33: =N19 -> 0 | D33: 26.25 | E33: =C33*D33 -> 0
B34: F/LIGHTER | C34: =AB19 -> 0 | D34: 20.62 | E34: =C34*D34 -> 0
B35: NONEL 2.4 | D35: 171.74107 | E35: =C35*D35 -> 0
B36: NONEL 3.6 | D36: 176.78571 | E36: =C36*D36 -> 0
B37: SUPREME 2.4 | D37: 180.35714 | E37: =C37*D37 -> 0
B38: SHOCK STAR | D38: 207 | E38: =C38*D38 -> 0
B39: PENTEX STOPE PREIME | D39: 331 | E39: =C39*D39 -> 0
B40: EXEL 2.4 | C40: =U19 -> 0 | D40: 189.38 | E40: =C40*D40 -> 0
B41: EXEL 4.9 | D41: 195 | E41: =C41*D41 -> 0
B42: EXEL 3.6 | C42: =Q19 -> 0 | D42: 195 | E42: =C42*D42 -> 0
B43: MS 12 | D43: 359.83 | E43: =C43*D43 -> 0
B44: MS 18 | D44: 379.46 | E44: =C44*D44 -> 0
...

Sheet L2
A1: DATE: | C1: =TOTAL!D3:E3 -> #VALUE! | M1: LEVEL 2
A3: SHIFT | B3: CONT. | C3: Sup | D3: WORKING PLACE | E3: SUPER POWER | F3: EMULEX | G3: SP | H3: MAGNUM | I3: PULSAR | J3: ANFO | K3: SAFETY FUSE | L3: OBC | M3: NONEL | O3: EXEL | P3: SUPREME | R3: EXEL | S3: MS 12 | T3: MS 18 | U3: CORDTEX | Y3: FUSE LIGHTER | Z3: EBC | AA3: BILL WIRE | AC3: STOPE | AE3: ROBBING | AG3: HORIZONTAL | AI3: RAISE | AK3: WINZE | AM3: SHAFT/CHAMBER/OREPASS
E4: 208 | F4: 208 | G4: 150 | H4: 150 | I4: 215 | M4: 2.4 | N4: 3.6 | O4: 3.6 | P4: 2.4 | Q4: 3.6 | R4: 2.4 | U4: 5 | V4: 10 | W4: 6 | X4: 40
E5: PCS | F5: PCS | G5: PCS | H5: PCS | I5: PCS | J5: KLS | K5: MTRS | L5: PCS | M5: PCS | N5: PCS | O5: PCS | P5: PCS | Q5: PCS | R5: PCS | S5: PCS | T5: PCS | U5: MTR | V5: MTR | W5: MTR | X5: MTR | Y5: PCS | Z5: PCS | AA5: PCS | AC5: PB | AD5: SB | AE5: PB | AF5: SB | AG5: PB | AH5: SB | AI5: PB | AJ5: SB | AK5: PB | AL5: SB | AM5: PB | AN5: SB
A6: 1 | K6: =L6*2.43 -> 0 | AB6: =M6+N6+O6+P6+Q6+R6 -> 0
A7: 1 | K7: =L7*2.43 -> 0 | AB7: =M7+N7+O7+P7+Q7+R7 -> 0
A8: 1 | K8: =L8*2.43 -> 0 | AB8: =M8+N8+O8+P8+Q8+R8 -> 0
A9: 1 | K9: =L9*2.43 -> 0 | AB9: =M9+N9+O9+P9+Q9+R9 -> 0
A10: 1 | K10: =L10*2.43 -> 0 | AB10: =M10+N10+O10+P10+Q10+R10 -> 0
A11: 1 | K11: =L11*2.43 -> 0 | AB11: =M11+N11+O11+P11+Q11+R11 -> 0
A12: 1 | K12: =L12*2.43 -> 0 | AB12: =M12+N12+O12+P12+Q12+R12 -> 0
A13: 1 | K13: =L13*2.43 -> 0 | AB13: =M13+N13+O13+P13+Q13+R13 -> 0
A14: TOTAL | E14: =SUM(E6:E13) -> 0 | F14: =SUM(F6:F13) -> 0 | G14: =SUM(G6:G13) -> 0 | H14: =SUM(H6:H13) -> 0 | I14: =SUM(I6:I13) -> 0 | J14: =SUM(J6:J13) -> 0 | K14: =SUM(K6:K13) -> 0 | L14: =SUM(L6:L13) -> 0 | ... AA14: =SUM(AA6:AA13) -> 0 | AC14: =SUM(AC6:AC13) -> 0 | AD14: =SUM(AD6:AD13) -> 0 | AE14: =SUM(AE6:AE13) -> 0 | AF14: =SUM(AF6:AF13) -> 0 | AG14: =SUM(AG6:AG13) -> 0 | AH14: =SUM(AH6:AH13) -> 0 | AI14: =SUM(AI6:AI13) -> 0 | AJ14: =SUM(AJ6:AJ13) -> 0 | ... AN14: =SUM(AN6:AN13) -> 0
A15: 2 | K15: =L15*2.43 -> 0 | AB15: =M15+N15+O15+P15+Q15+R15 -> 0
A16: 2 | K16: =L16*2.43 -> 0 | AB16: =M16+N16+O16+P16+Q16+R16 -> 0
A17: 2 | K17: =L17*2.43 -> 0 | AB17: =M17+N17+O17+P17+Q17+R17 -> 0
A18: 2 | K18: =L18*2.43 -> 0 | AB18: =M18+N18+O18+P18+Q18+R18 -> 0
A19: 2 | K19: =L19*2.43 -> 0 | AB19: =M19+N19+O19+P19+Q19+R19 -> 0
A20: 2 | K20: =L20*2.43 -> 0 | AB20: =M20+N20+O20+P20+Q20+R20 -> 0
A21: 2 | K21: =L21*2.43 -> 0 | AB21: =M21+N21+O21+P21+Q21+R21 -> 0
A22: TOTAL | E22: =SUM(E15:E21) -> 0 | F22: =SUM(F15:F21) -> 0 | G22: =SUM(G15:G21) -> 0 | H22: =SUM(H15:H21) -> 0 | I22: =SUM(I15:I21) -> 0 | J22: =SUM(J15:J21) -> 0 | K22: =SUM(K15:K21) -> 0 | L22: =SUM(L15:L21) -> 0 | ... AA22: =SUM(AA15:AA21) -> 0 | AC22: =SUM(AC15:AC21) -> 0 | AD22: =SUM(AD15:AD21) -> 0 | AE22: =SUM(AE15:AE21) -> 0 | AF22: =SUM(AF15:AF21) -> 0 | AG22: =SUM(AG15:AG21) -> 0 | AH22: =SUM(AH15:AH21) -> 0 | AI22: =SUM(AI15:AI21) -> 0 | AJ22: =SUM(AJ15:AJ21) -> 0 | ... AN22: =SUM(AN15:AN21) -> 0
A23: 3 | K23: =L23*2.43 -> 0 | AB23: =M23+N23+O23+P23+Q23+R23 -> 0
A24: 3 | K24: =L24*2.43 -> 0 | AB24: =M24+N24+O24+P24+Q24+R24 -> 0
A25: 3 | K25: =L25*2.43 -> 0 | AB25: =M25+N25+O25+P25+Q25+R25 -> 0
A26: 3 | K26: =L26*2.43 -> 0 | AB26: =M26+N26+O26+P26+Q26+R26 -> 0
A27: 3 | K27: =L27*2.43 -> 0 | AB27: =M27+N27+O27+P27+Q27+R27 -> 0
A28: 3 | K28: =L28*2.43 -> 0 | AB28: =M28+N28+O28+P28+Q28+R28 -> 0
A29: 3 | K29: =L29*2.43 -> 0 | AB29: =M29+N29+O29+P29+Q29+R29 -> 0
A30: 3 | K30: =L30*2.43 -> 0 | AB30: =M30+N30+O30+P30+Q30+R30 -> 0
A31: 3 | K31: =L31*2.43 -> 0 | AB31: =M31+N31+O31+P31+Q31+R31 -> 0
A32: TOTAL | E32: =SUM(E23:E31) -> 0 | F32: =SUM(F23:F31) -> 0 | G32: =SUM(G23:G31) -> 0 | H32: =SUM(H23:H31) -> 0 | I32: =SUM(I23:I31) -> 0 | J32: =SUM(J23:J31) -> 0 | K32: =SUM(K23:K31) -> 0 | L32: =SUM(L23:L31) -> 0 | ... AA32: =SUM(AA23:AA31) -> 0 | AC32: =SUM(AC23:AC31) -> 0 | AD32: =SUM(AD23:AD31) -> 0 | AE32: =SUM(AE23:AE31) -> 0 | AF32: =SUM(AF23:AF31) -> 0 | AG32: =SUM(AG23:AG31) -> 0 | AH32: =SUM(AH23:AH31) -> 0 | AI32: =SUM(AI23:AI31) -> 0 | AJ32: =SUM(AJ23:AJ31) -> 0 | ... AN32: =SUM(AN23:AN31) -> 0 | AO32: CLASSIC | AP32: PB | AQ32: SB
AO33: DRIFT/CROSSCUT | AP33: =AG34 -> 0 | AQ33: =AH34 -> 0
A34: GRAND TOTAL | E34: =E32+E22+E14 -> 0 | F34: =F32+F22+F14 -> 0 | G34: =G32+G22+G14 -> 0 | H34: =H32+H22+H14 -> 0 | I34: =I32+I22+I14 -> 0 | J34: =J32+J22+J14 -> 0 | K34: =K32+K22+K14 -> 0 | L34: =L32+L22+L14 -> 0 | ... AA34: =AA32+AA22+AA14 -> 0 | AC34: =AC32+AC22+AC14 -> 0 | AD34: =AD32+AD22+AD14 -> 0 | AE34: =AE32+AE22+AE14 -> 0 | AF34: =AF32+AF22+AF14 -> 0 | AG34: =AG32+AG22+AG14 -> 0 | AH34: =AH32+AH22+AH14 -> 0 | AI34: =AI32+AI22+AI14 -> 0 | AJ34: =AJ32+AJ22+AJ14 -> 0 | ... AN34: =AN32+AN22+AN14 -> 0 | AO34: RAISE | AP34: =AI34 -> 0 | AQ34: =AJ34 -> 0
C35: PRICE | E35: 21.64 | F35: 26.83 | G35: 35.47 | H35: 26.67 | I35: 26.42 | J35: 85.25 | K35: 26.5 | L35: 28.5 | M35: 192.35 | N35: 198 | O35: 192 | P35: 192.35 | Q35: 198 | R35: 192 | S35: 359.83 | T35: 379.46 | U35: 35.2 | V35: 40.2 | W35: 36.4 | X35: 81.9 | Y35: 16.5 | Z35: 285 | AA35: 16.8 | AO35: WINZE | AP35: =AK34 -> 0 | AQ35: =AL34 -> 0
C36: TOTAL COST | D36: =E36+F36+I36+J36+K36+L36+M36+N36+O36+P36+Q36+R36+U36+V36+W36+X36+Y36+Z36+AA36+G36+H36 -> 0 | E36: =E34*E35 -> 0 | F36: =F34*F35 -> 0 | G36: =G34*G35 -> 0 | H36: =H34*H35 -> 0 | I36: =I34*I35 -> 0 | J36: =J34*J35 -> 0 | K36: =K34*K35 -> 0 | L36: =L34*L35 -> 0 | ... AA36: =AA34*AA35 -> 0 | AO36: STOPE/STOPE PREP | AP36: =AC34 -> 0 | AQ36: =AD34 -> 0
AO37: ROBBING | AP37: =AE34 -> 0 | AQ37: =AF34 -> 0
AO38: CHAMBER/SHAFT | AP38: =AM34 -> 0 | AQ38: =AN34 -> 0

Sheet L3
A1: DATE: | C1: 43497 | J1: LEVEL | K1: 3
A2: SHIFT | B2: CONT. | C2: WORKING PLACE | D2: EMULEX | E2: SUPER POWER | F2: PULSAR | G2: ANFO | H2: SAFETY FUSE | I2: OBC | J2: NONEL | L2: EXEL | M2: SUPREME | O2: EXEL | P2: MS 12 | Q2: MS 18 | R2: CORDTEX | V2: FUSE LIGHTER | W2: EBC | X2: BILL WIRE | Y2: STOPE | AA2: ROBBING | AC2: HORIZONTAL | AE2: RAISE | AG2: WINZE | AI2: SHAFT/CHAMBER/OREPASS
D3: 208 | E3: 150 | F3: 215 | J3: 2.4 | K3: 3.6 | L3: 3.6 | M3: 2.4 | N3: 3.6 | O3: 2.4 | R3: 5 | S3: 10 | T3: 6 | U3: 40
D4: PCS | E4: PCS | F4: PCS | G4: KLS | H4: MTRS | I4: PCS | J4: PCS | K4: PCS | L4: PCS | M4: PCS | N4: PCS | O4: PCS | P4: PCS | Q4: PCS | R4: MTR | S4: MTR | T4: MTR | U4: MTR | V4: PCS | W4: PCS | X4: PCS | Y4: PB | Z4: SB | AA4: PB | AB4: SB | AC4: PB | AD4: SB | AE4: PB | AF4: SB | AG4: PB | AH4: SB | AI4: PB | AJ4: SB
A16: 1 | H16: =I16*2.43 -> 0
A17: 1 | H17: =I17*2.43 -> 0
A18: 1 | H18: =I18*2.43 -> 0
A19: 1 | H19: =I19*2.43 -> 0
A20: TOTAL | D20: =SUM(D5:D19) -> 0 | E20: =SUM(E5:E19) -> 0 | F20: =SUM(F5:F19) -> 0 | G20: =SUM(G5:G19) -> 0 | H20: =SUM(H5:H19) -> 0 | I20: =SUM(I5:I19) -> 0 | J20: =SUM(J5:J19) -> 0 | K20: =SUM(K5:K19) -> 0 | ... AJ20: =SUM(AJ5:AJ19) -> 0
A21: 2 | H21: =I21*2.43 -> 0
A22: 2 | H22: =I22*2.43 -> 0
A23: 2 | H23: =I23*2.43 -> 0
A24: 2 | H24: =I24*2.43 -> 0
A25: 2 | H25: =I25*2.43 -> 0
A26: 2 | H26: =I26*2.43 -> 0
A27: 2 | H27: =I27*2.43 -> 0
A28: 2 | H28: =I28*2.43 -> 0
A29: 2 | H29: =I29*2.43 -> 0
A30: 2 | H30: =I30*2.43 -> 0
A31: 2 | H31: =I31*2.43 -> 0
A32: 2 | H32: =I32*2.43 -> 0
... A35: 2 | H35: =I35*2.43 -> 0
A36: TOTAL | D36: =SUM(D21:D35) -> 0 | E36: =SUM(E21:E35) -> 0 | F36: =SUM(F21:F35) -> 0 | G36: =SUM(G21:G35) -> 0 | H36: =SUM(H21:H35) -> 0 | I36: =SUM(I21:I35) -> 0 | J36: =SUM(J21:J35) -> 0 | K36: =SUM(K21:K35) -> 0 | ... AJ36: =SUM(AJ21:AJ35) -> 0
A37: 3 | H37: =I37*2.43 -> 0
A38: 3 | H38: =I38*2.43 -> 0
A39: 3 | H39: =I39*2.43 -> 0
A40: 3 | H40: =I40*2.43 -> 0
A41: 3 | H41: =I41*2.43 -> 0
A42: 3 | H42: =I42*2.43 -> 0
A43: 3 | H43: =I43*2.43 -> 0
A44: 3 | H44: =I44*2.43 -> 0
A45: 3 | H45: =I45*2.43 -> 0
A46: 3 | H46: =I46*2.43 -> 0
A47: 3 | H47: =I47*2.43 -> 0
A48: 3 | H48: =I48*2.43 -> 0
... A51: 3 | H51: =I51*2.43 -> 0
A52: TOTAL | D52: =SUM(D37:D51) -> 0 | E52: =SUM(E37:E51) -> 0 | F52: =SUM(F37:F51) -> 0 | G52: =SUM(G37:G51) -> 0 | H52: =SUM(H37:H51) -> 0 | I52: =SUM(I37:I51) -> 0 | J52: =SUM(J37:J51) -> 0 | K52: =SUM(K37:K51) -> 0 | ... AJ52: =SUM(AJ37:AJ51) -> 0 | AK52: CLASSIC | AL52: PB | AM52: SB
AK53: DRIFT/CROSSCUT | AL53: =AC54 -> 0 | AM53: =AD54 -> 0
A54: GRAND TOTAL | D54: =D52+D36+D20 -> 0 | E54: =E52+E36+E20 -> 0 | F54: =F52+F36+F20 -> 0 | G54: =G52+G36+G20 -> 0 | H54: =H52+H36+H20 -> 0 | I54: =I52+I36+I20 -> 0 | J54: =J52+J36+J20 -> 0 | K54: =K52+K36+K20 -> 0 | ... AJ54: =AJ52+AJ36+AJ20 -> 0 | AK54: RAISE | AL54: =AE54 -> 0 | AM54: =AF54 -> 0
AK55: WINZE | AL55: =AG54 -> 0 | AM55: =AH54 -> 0
...

Sheet L03
A1: DATE: | C1: =TOTAL!D3 -> 46153 | N1: LEVEL 3
A3: SHIFT | B3: CONT. | C3: Sup | D3: DRILL STEEL | E3: WORKING PLACE | F3: SUPER POWER | G3: PULSAR | H3: EM AUSTIN | I3: NEOGEL | J3: PULSAR | K3: PULSAR | L3: ANFO | M3: SAFETY FUSE | N3: OBC | O3: NONEL | Q3: EXEL | R3: SUPREME | T3: EXEL | U3: EXEL | V3: SHOCK STAR | W3: MS 18 | X3: CORDTEX | AB3: FUSE LIGHTER | AC3: EBC | AD3: BILL WIRE | AF3: STOPE | AH3: ROBBING | AJ3: HORIZONTAL | AL3: RAISE | AN3: WINZE | AP3: SHAFT/CHAMBER/OREPASS
F4: 208 | G4: 38 | H4: 200 | I4: 200 | J4: 135 | K4: 215 | O4: 2.4 | P4: 3.6 | Q4: 3.6 | R4: 2.4 | S4: 3.6 | T4: 4.9 | U4: 2.4 | V4: 2.4 | X4: 5 | Y4: 10 | Z4: DCORD i5 | AA4: 40
F5: PCS | G5: PCS | H5: PCS | I5: PCS | J5: PCS | K5: PCS | L5: KLS | M5: MTRS | N5: PCS | O5: PCS | P5: PCS | Q5: PCS | R5: PCS | S5: PCS | T5: PCS | U5: PCS | V5: PCS | W5: PCS | X5: MTR | Y5: MTR | Z5: MTR | AA5: MTR | AB5: PCS | AC5: PCS | AD5: PCS | AF5: PB | AG5: SB | AH5: PB | AI5: SB | AJ5: PB | AK5: SB | AL5: PB | AM5: SB | AN5: PB | AO5: SB | AP5: PB | AQ5: SB
A6: 1 | B6: NO BLAST | M6: =N6*2.43 -> 0 | AE6: =O6+P6+Q6+R6+S6+T6+U6+V6 -> 0 | AV6: =COUNTIFS(AE6,">=11") -> 0
A7: TOTAL | F7: =SUM(F6:F6) -> 0 | G7: =SUM(G6:G6) -> 0 | H7: =SUM(H6:H6) -> 0 | I7: =SUM(I6:I6) -> 0 | J7: =SUM(J6:J6) -> 0 | K7: =SUM(K6:K6) -> 0 | L7: =SUM(L6:L6) -> 0 | M7: =SUM(M6:M6) -> 0 | ... AD7: =SUM(AD6:AD6) -> 0 | AF7: =SUM(AF6:AF6) -> 0 | AG7: =SUM(AG6:AG6) -> 0 | AH7: =SUM(AH6:AH6) -> 0 | AI7: =SUM(AI6:AI6) -> 0 | AJ7: =SUM(AJ6:AJ6) -> 0 | AK7: =SUM(AK6:AK6) -> 0 | AL7: =SUM(AL6:AL6) -> 0 | AM7: =SUM(AM6:AM6) -> 0 | ... AQ7: =SUM(AQ6:AQ6) -> 0 | AV7: =COUNTIFS(AE7,">=11") -> 0
A8: 2 | B8: FERNANDEZ | C8: AÑABIEZA | E8: 53E ROBB | K8: 20 | M8: =N8*2.43 -> 12.15 | N8: 5 | X8: 20 | AE8: =O8+P8+Q8+R8+S8+T8+U8+V8 -> 0 | AI8: 1 | AV8: =COUNTIFS(AE8,">=11") -> 0
A9: TOTAL | F9: =SUM(F8:F8) -> 0 | G9: =SUM(G8:G8) -> 0 | H9: =SUM(H8:H8) -> 0 | I9: =SUM(I8:I8) -> 0 | J9: =SUM(J8:J8) -> 0 | K9: =SUM(K8:K8) -> 20 | L9: =SUM(L8:L8) -> 0 | M9: =SUM(M8:M8) -> 12.15 | ... AD9: =SUM(AD8:AD8) -> 0 | AF9: =SUM(AF8:AF8) -> 0 | AG9: =SUM(AG8:AG8) -> 0 | AH9: =SUM(AH8:AH8) -> 0 | AI9: =SUM(AI8:AI8) -> 1 | AJ9: =SUM(AJ8:AJ8) -> 0 | AK9: =SUM(AK8:AK8) -> 0 | AL9: =SUM(AL8:AL8) -> 0 | AM9: =SUM(AM8:AM8) -> 0 | ... AQ9: =SUM(AQ8:AQ8) -> 0 | AV9: =COUNTIFS(AE9,">=11") -> 0
A10: 3 | B10: NO BLAST | M10: =N10*2.43 -> 0 | AE10: =O10+P10+Q10+R10+S10+T10+U10+V10 -> 0 | AV10: =COUNTIFS(AE10,">=11") -> 0
A11: TOTAL | F11: =SUM(F10:F10) -> 0 | G11: =SUM(G10:G10) -> 0 | H11: =SUM(H10:H10) -> 0 | I11: =SUM(I10:I10) -> 0 | J11: =SUM(J10:J10) -> 0 | K11: =SUM(K10:K10) -> 0 | L11: =SUM(L10:L10) -> 0 | M11: =SUM(M10:M10) -> 0 | ... AD11: =SUM(AD10:AD10) -> 0 | AF11: =SUM(AF10:AF10) -> 0 | AG11: =SUM(AG10:AG10) -> 0 | AH11: =SUM(AH10:AH10) -> 0 | AI11: =SUM(AI10:AI10) -> 0 | AJ11: =SUM(AJ10:AJ10) -> 0 | AK11: =SUM(AK10:AK10) -> 0 | AL11: =SUM(AL10:AL10) -> 0 | AM11: =SUM(AM10:AM10) -> 0 | ... AQ11: =SUM(AQ10:AQ10) -> 0 | AR11: CLASSIC | AS11: PB | AT11: SB
AR12: DRIFT/CROSSCUT | AS12: =AJ13 -> 0 | AT12: =AK13 -> 0
A13: GRAND TOTAL | F13: =F11+F9+F7 -> 0 | G13: =G11+G9+G7 -> 0 | H13: =H11+H9+H7 -> 0 | I13: =I11+I9+I7 -> 0 | J13: =J11+J9+J7 -> 0 | K13: =K11+K9+K7 -> 20 | L13: =L11+L9+L7 -> 0 | M13: =M11+M9+M7 -> 12.15 | ... AD13: =AD11+AD9+AD7 -> 0 | AF13: =AF11+AF9+AF7 -> 0 | AG13: =AG11+AG9+AG7 -> 0 | AH13: =AH11+AH9+AH7 -> 0 | AI13: =AI11+AI9+AI7 -> 1 | AJ13: =AJ11+AJ9+AJ7 -> 0 | AK13: =AK11+AK9+AK7 -> 0 | AL13: =AL11+AL9+AL7 -> 0 | AM13: =AM11+AM9+AM7 -> 0 | ... AQ13: =AQ11+AQ9+AQ7 -> 0 | AR13: RAISE | AS13: =AL13 -> 0 | AT13: =AM13 -> 0
C14: PRICE | F14: 26.2921 | G14: 115.8 | H14: 35.47 | I14: 27.3438 | J14: 40 | K14: 29.5639 | L14: 145.88 | M14: 27.66 | N14: 26.25 | O14: 171.74107 | P14: 176.78571 | Q14: 195 | R14: 180.35714 | S14: 198 | T14: 195 | U14: 189.38 | V14: 207 | W14: 379.46 | X14: 35.15 | Y14: 35.893 | Z14: 37.5 | AA14: 81.9 | AB14: 20.62 | AC14: 267.18 | AD14: 7.5 | AR14: WINZE | AS14: =AN13 -> 0 | AT14: =AO13 -> 0
C15: TOTAL COST | E15: =F15+G15+K15+L15+M15+N15+O15+P15+Q15+R15+S15+U15+X15+Y15+Z15+AA15+AB15+AC15+AD15+H15+I15 -> 1761.597 | F15: =F13*F14 -> 0 | G15: =G13*G14 -> 0 | H15: =H13*H14 -> 0 | I15: =I13*I14 -> 0 | J15: =J13*J14 -> 0 | K15: =K13*K14 -> 591.278 | L15: =L13*L14 -> 0 | M15: =M13*M14 -> 336.069 | ... AD15: =AD13*AD14 -> 0 | AR15: STOPE/STOPE PREP | AS15: =AF13 -> 0 | AT15: =AG13 -> 0
AR16: ROBBING | AS16: =AH13 -> 0 | AT16: =AI13 -> 1
AR17: CHAMBER/SHAFT | AS17: =AP13 -> 0 | AT17: =AQ13 -> 0
AQ18: =AR18-AS18 -> 0 | AR18: =SUM(AV6:AV10) -> 0 | AS18: =SUM(AS12:AS17) -> 0
B20: DESCRIPTION | C20: ISSUANCE | D20: PRICE | E20: COST
B21: DYNA SUPERPOWER 208 | D21: 26.2921 | E21: =C21*D21 -> 0
B22: NEOGEL 200 | C22: =I13 -> 0 | D22: 27.3438
B23: DYNAPULSAR 215 | C23: =K13 -> 20 | D23: 29.5639 | E23: =C23*D23 -> 591.278
B24: ANFO | C24: =L13 -> 0 | D24: 145.88 | E24: =C24*D24 -> 0
B25: S/FUSE | C25: =M13 -> 12.15 | D25: 27.66 | E25: =C25*D25 -> 336.069
B26: OBC | C26: =N13 -> 5 | D26: 26.25 | E26: =C26*D26 -> 131.25
B27: F/LIGHTER | C27: =AB13 -> 0 | D27: 20.62 | E27: =C27*D27 -> 0
B28: NONEL 2.4 | D28: 171.74107 | E28: =C28*D28 -> 0
B29: NONEL 3.6 | D29: 176.78571 | E29: =C29*D29 -> 0
B30: SUPREME 2.4 | D30: 180.35714 | E30: =C30*D30 -> 0
B31: SHOCK STAR | D31: 207 | E31: =C31*D31 -> 0
B32: PENTEX STOPE PREIME | D32: 331 | E32: =C32*D32 -> 0
B33: EXEL 2.4 | C33: =U13 -> 0 | D33: 189.38 | E33: =C33*D33 -> 0
B34: EXEL 4.9 | D34: 195 | E34: =C34*D34 -> 0
B35: EXEL 3.6 | C35: =Q13 -> 0 | D35: 195 | E35: =C35*D35 -> 0
B36: MS 12 | D36: 359.83 | E36: =C36*D36 -> 0
B37: MS 18 | D37: 379.46 | E37: =C37*D37 -> 0
B38: CORDTEX 5 | C38: =X13 -> 20 | D38: 35.15 | E38: =C38*D38 -> 703
B39: CORDTEX 10 | C39: =Y13 -> 0 | D39: 35.893 | E39: =C39*D39 -> 0
B40: DCORD 15 | C40: =W8 -> 0 | D40: 37.5 | E40: =C40*D40 -> 0
B41: CORDTEX 40 | C41: =AA13 -> 0 | D41: 81.9 | E41: =C41*D41 -> 0
B42: BILL WIRE | C42: =AD13 -> 0 | D42: 7.5 | E42: =C42*D42 -> 0
...

Sheet L6
A1: DATE: | C1: =TOTAL!D3:E3 -> #VALUE! | M1: LEVEL 6
A3: SHIFT | B3: CONT. | C3: Sup | D3: WORKING PLACE | E3: SUPER POWER | F3: PULSAR | G3: EM AUSTIN | H3: MAGNUM | I3: PULSAR | J3: PULSAR | K3: ANFO | L3: SAFETY FUSE | M3: OBC | N3: NONEL | P3: EXEL | Q3: SUPREME | S3: EXEL | T3: EXEL | U3: SHOCK STAR | V3: MS 18 | W3: CORDTEX | AA3: FUSE LIGHTER | AB3: EBC | AC3: BILL WIRE | AE3: STOPE | AG3: ROBBING | AI3: HORIZONTAL | AK3: RAISE | AM3: WINZE | AO3: SHAFT/CHAMBER/OREPASS
E4: 208 | F4: 38 | G4: 200 | H4: 150 | I4: 135 | J4: 215 | N4: 2.4 | O4: 3.6 | P4: 3.6 | Q4: 2.4 | R4: 3.6 | S4: 4.9 | T4: 2.4 | U4: 2.4 | W4: 5 | X4: 10 | Y4: 6 | Z4: 40
E5: PCS | F5: PCS | G5: PCS | H5: PCS | I5: PCS | J5: PCS | K5: KLS | L5: MTRS | M5: PCS | N5: PCS | O5: PCS | P5: PCS | Q5: PCS | R5: PCS | S5: PCS | T5: PCS | U5: PCS | V5: PCS | W5: MTR | X5: MTR | Y5: MTR | Z5: MTR | AA5: PCS | AB5: PCS | AC5: PCS | AE5: PB | AF5: SB | AG5: PB | AH5: SB | AI5: PB | AJ5: SB | AK5: PB | AL5: SB | AM5: PB | AN5: SB | AO5: PB | AP5: SB
A6: 1 | L6: =M6*2.43 -> 0 | AD6: =N6+O6+P6+Q6+R6+S6+T6+U6 -> 0
A7: TOTAL | E7: =SUM(E6:E6) -> 0 | F7: =SUM(F6:F6) -> 0 | G7: =SUM(G6:G6) -> 0 | H7: =SUM(H6:H6) -> 0 | I7: =SUM(I6:I6) -> 0 | J7: =SUM(J6:J6) -> 0 | K7: =SUM(K6:K6) -> 0 | L7: =SUM(L6:L6) -> 0 | ... AC7: =SUM(AC6:AC6) -> 0 | AE7: =SUM(AE6:AE6) -> 0 | AF7: =SUM(AF6:AF6) -> 0 | AG7: =SUM(AG6:AG6) -> 0 | AH7: =SUM(AH6:AH6) -> 0 | AI7: =SUM(AI6:AI6) -> 0 | AJ7: =SUM(AJ6:AJ6) -> 0 | AK7: =SUM(AK6:AK6) -> 0 | AL7: =SUM(AL6:AL6) -> 0 | ... AP7: =SUM(AP6:AP6) -> 0
A8: 2 | L8: =M8*2.43 -> 0 | AD8: =N8+O8+P8+Q8+R8+S8+T8+U8 -> 0
A9: TOTAL | E9: =SUM(E8:E8) -> 0 | F9: =SUM(F8:F8) -> 0 | G9: =SUM(G8:G8) -> 0 | H9: =SUM(H8:H8) -> 0 | I9: =SUM(I8:I8) -> 0 | J9: =SUM(J8:J8) -> 0 | K9: =SUM(K8:K8) -> 0 | L9: =SUM(L8:L8) -> 0 | ... AC9: =SUM(AC8:AC8) -> 0 | AE9: =SUM(AE8:AE8) -> 0 | AF9: =SUM(AF8:AF8) -> 0 | AG9: =SUM(AG8:AG8) -> 0 | AH9: =SUM(AH8:AH8) -> 0 | AI9: =SUM(AI8:AI8) -> 0 | AJ9: =SUM(AJ8:AJ8) -> 0 | AK9: =SUM(AK8:AK8) -> 0 | AL9: =SUM(AL8:AL8) -> 0 | ... AP9: =SUM(AP8:AP8) -> 0
A10: 3 | L10: =M10*2.43 -> 0 | AD10: =N10+O10+P10+Q10+R10+S10+T10+U10 -> 0
A11: TOTAL | E11: =SUM(E10:E10) -> 0 | F11: =SUM(F10:F10) -> 0 | G11: =SUM(G10:G10) -> 0 | H11: =SUM(H10:H10) -> 0 | I11: =SUM(I10:I10) -> 0 | J11: =SUM(J10:J10) -> 0 | K11: =SUM(K10:K10) -> 0 | L11: =SUM(L10:L10) -> 0 | ... AC11: =SUM(AC10:AC10) -> 0 | AE11: =SUM(AE10:AE10) -> 0 | AF11: =SUM(AF10:AF10) -> 0 | AG11: =SUM(AG10:AG10) -> 0 | AH11: =SUM(AH10:AH10) -> 0 | AI11: =SUM(AI10:AI10) -> 0 | AJ11: =SUM(AJ10:AJ10) -> 0 | AK11: =SUM(AK10:AK10) -> 0 | AL11: =SUM(AL10:AL10) -> 0 | ... AP11: =SUM(AP10:AP10) -> 0 | AQ11: CLASSIC | AR11: PB | AS11: SB
AQ12: DRIFT/CROSSCUT | AR12: =AI13 -> 0 | AS12: =AJ13 -> 0
A13: GRAND TOTAL | E13: =E11+E9+E7 -> 0 | F13: =F11+F9+F7 -> 0 | G13: =G11+G9+G7 -> 0 | H13: =H11+H9+H7 -> 0 | I13: =I11+I9+I7 -> 0 | J13: =J11+J9+J7 -> 0 | K13: =K11+K9+K7 -> 0 | L13: =L11+L9+L7 -> 0 | ... AC13: =AC11+AC9+AC7 -> 0 | AE13: =AE11+AE9+AE7 -> 0 | AF13: =AF11+AF9+AF7 -> 0 | AG13: =AG11+AG9+AG7 -> 0 | AH13: =AH11+AH9+AH7 -> 0 | AI13: =AI11+AI9+AI7 -> 0 | AJ13: =AJ11+AJ9+AJ7 -> 0 | AK13: =AK11+AK9+AK7 -> 0 | AL13: =AL11+AL9+AL7 -> 0 | ... AP13: =AP11+AP9+AP7 -> 0 | AQ13: RAISE | AR13: =AK13 -> 0 | AS13: =AL13 -> 0
C14: PRICE | E14: 21.64 | F14: 115.8 | G14: 35.47 | H14: 26.67 | I14: 40 | J14: 26.42 | K14: 97.6 | L14: 26.5 | M14: 28.5 | N14: 192.35 | O14: 198 | P14: 192 | Q14: 192.35 | R14: 198 | S14: 207 | T14: 192 | U14: 192.35 | V14: 379.46 | W14: 35.2 | X14: 40.2 | Y14: 36.4 | Z14: 81.9 | AA14: 16.5 | AB14: 285 | AC14: 16.8 | AQ14: WINZE | AR14: =AM13 -> 0 | AS14: =AN13 -> 0
C15: TOTAL COST | D15: =E15+F15+J15+K15+L15+M15+N15+O15+P15+Q15+R15+T15+W15+X15+Y15+Z15+AA15+AB15+AC15+G15+H15 -> 0 | E15: =E13*E14 -> 0 | F15: =F13*F14 -> 0 | G15: =G13*G14 -> 0 | H15: =H13*H14 -> 0 | I15: =I13*I14 -> 0 | J15: =J13*J14 -> 0 | K15: =K13*K14 -> 0 | L15: =L13*L14 -> 0 | ... AC15: =AC13*AC14 -> 0 | AQ15: STOPE/STOPE PREP | AR15: =AE13 -> 0 | AS15: =AF13 -> 0
AQ16: ROBBING | AR16: =AG13 -> 0 | AS16: =AH13 -> 0
AQ17: CHAMBER/SHAFT | AR17: =AO13 -> 0 | AS17: =AP13 -> 0

Sheet L7
A1: DATE: | C1: =TOTAL!D3 -> 46153 | N1: LEVEL 7
A3: SHIFT | B3: CONT. | C3: Sup | D3: DRILL STEEL | E3: WORKING PLACE | F3: SUPER POWER | G3: PULSAR | H3: EM AUSTIN | I3: NEOGEL | J3: PULSAR | K3: PULSAR | L3: ANFO | M3: SAFETY FUSE | N3: OBC | O3: NONEL | Q3: EXEL | R3: SUPREME | T3: EXEL | U3: EXEL | V3: SHOCK STAR | W3: MS 18 | X3: CORDTEX | AB3: FUSE LIGHTER | AC3: EBC | AD3: BILL WIRE | AF3: STOPE | AH3: ROBBING | AJ3: HORIZONTAL | AL3: RAISE | AN3: WINZE | AP3: SHAFT/CHAMBER/OREPASS
F4: 208 | G4: 38 | H4: 200 | I4: 200 | J4: 135 | K4: 215 | O4: 2.4 | P4: 3.6 | Q4: 3.6 | R4: 2.4 | S4: 3.6 | T4: 4.9 | U4: 2.4 | V4: 2.4 | X4: 5 | Y4: 10 | Z4: 6 | AA4: 40
F5: PCS | G5: PCS | H5: PCS | I5: PCS | J5: PCS | K5: PCS | L5: KLS | M5: MTRS | N5: PCS | O5: PCS | P5: PCS | Q5: PCS | R5: PCS | S5: PCS | T5: PCS | U5: PCS | V5: PCS | W5: PCS | X5: MTR | Y5: MTR | Z5: MTR | AA5: MTR | AB5: PCS | AC5: PCS | AD5: PCS | AF5: PB | AG5: SB | AH5: PB | AI5: SB | AJ5: PB | AK5: SB | AL5: PB | AM5: SB | AN5: PB | AO5: SB | AP5: PB | AQ5: SB
A6: 1 | B6: NO BLAST | M6: =N6*2.43 -> 0 | AE6: =O6+P6+Q6+R6+S6+T6+U6+V6 -> 0 | AV6: =COUNTIFS(AE6,">=11") -> 0
A7: 1 | M7: =N7*2.43 -> 0 | AE7: =O7+P7+Q7+R7+S7+T7+U7+V7 -> 0 | AV7: =COUNTIFS(AE7,">=11") -> 0
A8: TOTAL | F8: =SUM(F6:F7) -> 0 | G8: =SUM(G6:G7) -> 0 | H8: =SUM(H6:H7) -> 0 | I8: =SUM(I6:I7) -> 0 | J8: =SUM(J6:J7) -> 0 | K8: =SUM(K6:K7) -> 0 | L8: =SUM(L6:L7) -> 0 | M8: =SUM(M6:M7) -> 0 | ... AD8: =SUM(AD6:AD7) -> 0 | AF8: =SUM(AF6:AF7) -> 0 | AG8: =SUM(AG6:AG7) -> 0 | AH8: =SUM(AH6:AH7) -> 0 | AI8: =SUM(AI6:AI7) -> 0 | AJ8: =SUM(AJ6:AJ7) -> 0 | AK8: =SUM(AK6:AK7) -> 0 | AL8: =SUM(AL6:AL7) -> 0 | AM8: =SUM(AM6:AM7) -> 0 | ... AQ8: =SUM(AQ6:AQ7) -> 0 | AV8: =COUNTIFS(AE8,">=11") -> 0
A9: 2 | B9: PMC MINERS | C9: EVANGELISTA | D9: 5 | E9: 35E XCN | K9: 48 | L9: 19.2 | M9: =N9*2.43 -> 4.86 | N9: 2 | U9: 28 | X9: 10 | AE9: =O9+P9+Q9+R9+S9+T9+U9+V9 -> 28 | AJ9: 1 | AV9: =COUNTIFS(AE9,">=11") -> 1
A10: TOTAL | F10: =SUM(F9:F9) -> 0 | G10: =SUM(G9:G9) -> 0 | H10: =SUM(H9:H9) -> 0 | I10: =SUM(I9:I9) -> 0 | J10: =SUM(J9:J9) -> 0 | K10: =SUM(K9:K9) -> 48 | L10: =SUM(L9:L9) -> 19.2 | M10: =SUM(M9:M9) -> 4.86 | ... AD10: =SUM(AD9:AD9) -> 0 | AF10: =SUM(AF9:AF9) -> 0 | AG10: =SUM(AG9:AG9) -> 0 | AH10: =SUM(AH9:AH9) -> 0 | AI10: =SUM(AI9:AI9) -> 0 | AJ10: =SUM(AJ9:AJ9) -> 1 | AK10: =SUM(AK9:AK9) -> 0 | AL10: =SUM(AL9:AL9) -> 0 | AM10: =SUM(AM9:AM9) -> 0 | ... AQ10: =SUM(AQ9:AQ9) -> 0 | AV10: =COUNTIFS(AE10,">=11") -> 0
A11: 3 | B11: NO BLAST | M11: =N11*2.43 -> 0 | AE11: =O11+P11+Q11+R11+S11+T11+U11+V11 -> 0 | AV11: =COUNTIFS(AE11,">=11") -> 0
A12: TOTAL | F12: =SUM(F11:F11) -> 0 | G12: =SUM(G11:G11) -> 0 | H12: =SUM(H11:H11) -> 0 | I12: =SUM(I11:I11) -> 0 | J12: =SUM(J11:J11) -> 0 | K12: =SUM(K11:K11) -> 0 | L12: =SUM(L11:L11) -> 0 | M12: =SUM(M11:M11) -> 0 | ... AD12: =SUM(AD11:AD11) -> 0 | AF12: =SUM(AF11:AF11) -> 0 | AG12: =SUM(AG11:AG11) -> 0 | AH12: =SUM(AH11:AH11) -> 0 | AI12: =SUM(AI11:AI11) -> 0 | AJ12: =SUM(AJ11:AJ11) -> 0 | AK12: =SUM(AK11:AK11) -> 0 | AL12: =SUM(AL11:AL11) -> 0 | AM12: =SUM(AM11:AM11) -> 0 | ... AQ12: =SUM(AQ11:AQ11) -> 0 | AR12: CLASSIC | AS12: PB | AT12: SB
AR13: DRIFT/CROSSCUT | AS13: =AJ14 -> 1 | AT13: =AK14 -> 0
A14: GRAND TOTAL | F14: =F12+F10+F8 -> 0 | G14: =G12+G10+G8 -> 0 | H14: =H12+H10+H8 -> 0 | I14: =I12+I10+I8 -> 0 | J14: =J12+J10+J8 -> 0 | K14: =K12+K10+K8 -> 48 | L14: =L12+L10+L8 -> 19.2 | M14: =M12+M10+M8 -> 4.86 | ... AD14: =AD12+AD10+AD8 -> 0 | AF14: =AF12+AF10+AF8 -> 0 | AG14: =AG12+AG10+AG8 -> 0 | AH14: =AH12+AH10+AH8 -> 0 | AI14: =AI12+AI10+AI8 -> 0 | AJ14: =AJ12+AJ10+AJ8 -> 1 | AK14: =AK12+AK10+AK8 -> 0 | AL14: =AL12+AL10+AL8 -> 0 | AM14: =AM12+AM10+AM8 -> 0 | ... AQ14: =AQ12+AQ10+AQ8 -> 0 | AR14: RAISE | AS14: =AL14 -> 0 | AT14: =AM14 -> 0
C15: PRICE | F15: 26.2921 | G15: 115.8 | H15: 35.47 | I15: 27.3438 | J15: 40 | K15: 29.5639 | L15: 145.88 | M15: 27.66 | N15: 26.25 | O15: 171.74107 | P15: 176.78571 | Q15: 195 | R15: 180.35714 | S15: 198 | T15: 195 | U15: 189.38 | V15: 207 | W15: 379.46 | X15: 35.15 | Y15: 35.893 | Z15: 37.5 | AA15: 81.9 | AB15: 20.62 | AC15: 267.18 | AD15: 7.5 | AR15: WINZE | AS15: =AN14 -> 0 | AT15: =AO14 -> 0
C16: TOTAL COST | E16: =F16+G16+K16+L16+M16+N16+O16+P16+Q16+R16+S16+U16+X16+Y16+Z16+AA16+AB16+AC16+AD16+H16+I16 -> 10061.031 | F16: =F14*F15 -> 0 | G16: =G14*G15 -> 0 | H16: =H14*H15 -> 0 | I16: =I14*I15 -> 0 | J16: =J14*J15 -> 0 | K16: =K14*K15 -> 1419.0672 | L16: =L14*L15 -> 2800.896 | M16: =M14*M15 -> 134.4276 | ... AD16: =AD14*AD15 -> 0 | AR16: STOPE/STOPE PREP | AS16: =AF14 -> 0 | AT16: =AG14 -> 0
AR17: ROBBING | AS17: =AH14 -> 0 | AT17: =AI14 -> 0
AR18: CHAMBER/SHAFT | AS18: =AP14 -> 0 | AT18: =AQ14 -> 0
AQ19: =AR19-AS19 -> 0 | AR19: =SUM(AV6:AV11) -> 1 | AS19: =SUM(AS13:AS18) -> 1

Sheet L8
A3: DATE: | C3: =TOTAL!D3 -> 46153 | N3: LEVEL 8
A5: SHIFT | B5: CONT. | C5: Sup | D5: DRILL STEEL | E5: WORKING PLACE | F5: SUPER POWER | G5: PULSAR | H5: EM AUSTIN | I5: NEOGEL | J5: PULSAR | K5: PULSAR | L5: ANFO | M5: SAFETY FUSE | N5: OBC | O5: NONEL | Q5: EXEL | R5: SUPREME | T5: EXEL | U5: EXEL | V5: SHOCK STAR | W5: MS 18 | X5: CORDTEX | AB5: FUSE LIGHTER | AC5: EBC | AD5: BILL WIRE | AE5: COMPUTED DETONATOR COUNT | AF5: MANUAL DETONATOR COUNT | AG5: REMARKS | AH5: STOPE | AJ5: ROBBING | AL5: HORIZONTAL | AN5: RAISE | AP5: WINZE | AR5: SHAFT/CHAMBER/OREPASS
F6: 208 | G6: 38 | H6: 200 | I6: 200 | J6: 135 | K6: 215 | O6: 2.4 | P6: 3.6 | Q6: 3.6 | R6: 2.4 | S6: 3.6 | T6: 4.9 | U6: 2.4 | V6: 2.4 | X6: 5 | Y6: 10 | Z6: DCORD i5 | AA6: 40
F7: PCS | G7: PCS | H7: PCS | I7: PCS | J7: PCS | K7: PCS | L7: KLS | M7: MTRS | N7: PCS | O7: PCS | P7: PCS | Q7: PCS | R7: PCS | S7: PCS | T7: PCS | U7: PCS | V7: PCS | W7: PCS | X7: MTR | Y7: MTR | Z7: MTR | AA7: MTR | AB7: PCS | AC7: PCS | AD7: PCS | AH7: PB | AI7: SB | AJ7: PB | AK7: SB | AL7: PB | AM7: SB | AN7: PB | AO7: SB | AP7: PB | AQ7: SB | AR7: PB | AS7: SB
A8: 1 | B8: NO BLAST | M8: =N8*2.43 -> 0 | AE8: =O8+P8+Q8+R8+S8+T8+U8+V8 -> 0 | AX8: =COUNTIFS(AE8,">=11") -> 0
A9: TOTAL | F9: =SUM(F8:F8) -> 0 | G9: =SUM(G8:G8) -> 0 | H9: =SUM(H8:H8) -> 0 | I9: =SUM(I8:I8) -> 0 | J9: =SUM(J8:J8) -> 0 | K9: =SUM(K8:K8) -> 0 | L9: =SUM(L8:L8) -> 0 | M9: =SUM(M8:M8) -> 0 | ... AD9: =SUM(AD8:AD8) -> 0 | AH9: =SUM(AH8:AH8) -> 0 | AI9: =SUM(AI8:AI8) -> 0 | AJ9: =SUM(AJ8:AJ8) -> 0 | AK9: =SUM(AK8:AK8) -> 0 | AL9: =SUM(AL8:AL8) -> 0 | AM9: =SUM(AM8:AM8) -> 0 | AN9: =SUM(AN8:AN8) -> 0 | AO9: =SUM(AO8:AO8) -> 0 | ... AS9: =SUM(AS8:AS8) -> 0 | AX9: =COUNTIFS(AE9,">=11") -> 0
A10: 2 | B10: CANTAGO | C10: ABOOL | D10: 5 | E10: 39E W STP PREP | K10: 35 | L10: 18.4 | M10: =N10*2.43 -> 4.86 | N10: 2 | U10: 25 | X10: 10 | AE10: =O10+P10+Q10+R10+S10+T10+U10+V10 -> 25 | AJ10: 1 | AX10: =COUNTIFS(AE10,">=11") -> 1
A11: 2 | B11: NITRO CN | C11: ABOOL | D11: 5 | E11: 27E RAISE | K11: 21 | L11: 16.8 | M11: =N11*2.43 -> 4.86 | N11: 2 | U11: 21 | X11: 10 | AE11: =O11+P11+Q11+R11+S11+T11+U11+V11 -> 21 | AN11: 1 | AX11: =COUNTIFS(AE11,">=11") -> 1
A12: 2 | B12: CANTAGO | C12: ABOOL | E12: 49E W STP PREP | K12: 42 | L12: 20.8 | M12: =N12*2.43 -> 4.86 | N12: 2 | U12: 30 | X12: 17 | AE12: =O12+P12+Q12+R12+S12+T12+U12+V12 -> 30 | AJ12: 1 | AX12: =COUNTIFS(AE12,">=11") -> 1
A13: 2 | B13: FERNANDEZ | C13: ABOOL | D13: 5 | E13: 35E STP | K13: 17 | L13: 13.6 | M13: =N13*2.43 -> 4.86 | N13: 2 | U13: 17 | X13: 10 | AE13: =O13+P13+Q13+R13+S13+T13+U13+V13 -> 17 | AH13: 1 | AX13: =COUNTIFS(AE13,">=11") -> 1
A14: 2 | B14: FERNANDEZ | C14: ABOOL | D14: 5 | E14: 19E STP PREP | K14: 22 | L14: 17.6 | M14: =N14*2.43 -> 4.86 | N14: 2 | U14: 22 | X14: 10 | AE14: =O14+P14+Q14+R14+S14+T14+U14+V14 -> 22 | AH14: 1 | AX14: =COUNTIFS(AE14,">=11") -> 1
A15: 2 | B15: CAPUYAN | C15: ABOOL | D15: 5 | E15: 20E DE ISL | K15: 40 | L15: 12.8 | M15: =N15*2.43 -> 4.86 | N15: 2 | U15: 20 | X15: 6 | AE15: =O15+P15+Q15+R15+S15+T15+U15+V15 -> 20 | AL15: 1 | AX15: =COUNTIFS(AE15,">=11") -> 1
A16: 2 | B16: FERNANDEZ | C16: ABOOL | D16: 5 | E16: 34E DW ISL | K16: 39 | L16: 16.8 | M16: =N16*2.43 -> 4.86 | N16: 2 | U16: 24 | X16: 12 | AE16: =O16+P16+Q16+R16+S16+T16+U16+V16 -> 24 | AL16: 1 | AX16: =COUNTIFS(AE16,">=11") -> 1
A17: 2 | B17: FERNANDEZ | C17: ABOOL | D17: 3 | E17: 17W ROBB | K17: 16 | L17: 9.6 | M17: =N17*2.43 -> 4.86 | N17: 2 | U17: 16 | X17: 12 | AE17: =O17+P17+Q17+R17+S17+T17+U17+V17 -> 16 | AJ17: 1 | AX17: =COUNTIFS(AE17,">=11") -> 1
A18: TOTAL | F18: =SUM(F10:F17) -> 0 | G18: =SUM(G10:G17) -> 0 | H18: =SUM(H10:H17) -> 0 | I18: =SUM(I10:I17) -> 0 | J18: =SUM(J10:J17) -> 0 | K18: =SUM(K10:K17) -> 232 | L18: =SUM(L10:L17) -> 126.4 | M18: =SUM(M10:M17) -> 38.88 | ... AD18: =SUM(AD10:AD17) -> 0 | AH18: =SUM(AH10:AH17) -> 2 | AI18: =SUM(AI10:AI17) -> 0 | AJ18: =SUM(AJ10:AJ17) -> 3 | AK18: =SUM(AK10:AK17) -> 0 | AL18: =SUM(AL10:AL17) -> 2 | AM18: =SUM(AM10:AM17) -> 0 | AN18: =SUM(AN10:AN17) -> 1 | AO18: =SUM(AO10:AO17) -> 0 | ... AS18: =SUM(AS10:AS17) -> 0 | AX18: =COUNTIFS(AE18,">=11") -> 0
A19: 3 | B19: CANTAGO | C19: GALLEGO | D19: 5 | E19: 49E STP PREP | K19: 30 | L19: 24 | M19: =N19*2.43 -> 9.72 | N19: 4 | U19: 30 | X19: 12 | AE19: =O19+P19+Q19+R19+S19+T19+U19+V19 -> 30 | AH19: 1 | AX19: =COUNTIFS(AE19,">=11") -> 1
A20: 3 | B20: CANTAGO | C20: GALLEGO | D20: 5 | E20: 10W RAISE | K20: 21 | L20: 16.8 | M20: =N20*2.43 -> 4.86 | N20: 2 | U20: 21 | X20: 9 | AE20: =O20+P20+Q20+R20+S20+T20+U20+V20 -> 21 | AN20: 1 | AX20: =COUNTIFS(AE20,">=11") -> 1
A21: 3 | B21: CAPUYAN | C21: GALLEGO | D21: 5 | E21: 21E STP | K21: 11 | L21: 8.8 | M21: =N21*2.43 -> 4.86 | N21: 2 | U21: 11 | X21: 8 | AE21: =O21+P21+Q21+R21+S21+T21+U21+V21 -> 11 | AH21: 1 | AX21: =COUNTIFS(AE21,">=11") -> 1
A22: 3 | B22: CANTAGO | C22: GALLEGO | D22: 5 | E22: 39E STP PREP | K22: 22 | L22: 17.2 | M22: =N22*2.43 -> 4.86 | N22: 2 | U22: 22 | X22: 9 | AE22: =O22+P22+Q22+R22+S22+T22+U22+V22 -> 22 | AH22: 1 | AX22: =COUNTIFS(AE22,">=11") -> 1
A23: 3 | B23: CARIKITAN | C23: GALLEGO | D23: 5 | E23: 26E DW ISL | K23: 43 | L23: 15.2 | M23: =N23*2.43 -> 4.86 | N23: 2 | U23: 23 | X23: 8 | AE23: =O23+P23+Q23+R23+S23+T23+U23+V23 -> 23 | AL23: 1 | AX23: =COUNTIFS(AE23,">=11") -> 1
A24: 3 | B24: FERNANDEZ | C24: GALLEGO | D24: 3 | E24: 19E STP PREP | K24: 22 | L24: 13.2 | M24: =N24*2.43 -> 4.86 | N24: 2 | U24: 22 | X24: 12 | AE24: =O24+P24+Q24+R24+S24+T24+U24+V24 -> 22 | AH24: 1 | AX24: =COUNTIFS(AE24,">=11") -> 1
A25: 3 | B25: NITRO CN | C25: GALLEGO | D25: 3 | E25: 14W WINZE | K25: 104 | M25: =N25*2.43 -> 4.86 | N25: 2 | U25: 26 | X25: 12 | AE25: =O25+P25+Q25+R25+S25+T25+U25+V25 -> 26 | AP25: 1 | AX25: =COUNTIFS(AE25,">=11") -> 1
A26: TOTAL | F26: =SUM(F19:F25) -> 0 | G26: =SUM(G19:G25) -> 0 | H26: =SUM(H19:H25) -> 0 | I26: =SUM(I19:I25) -> 0 | J26: =SUM(J19:J25) -> 0 | K26: =SUM(K19:K25) -> 253 | L26: =SUM(L19:L25) -> 95.2 | M26: =SUM(M19:M25) -> 38.88 | ... AD26: =SUM(AD19:AD25) -> 0 | AH26: =SUM(AH19:AH25) -> 4 | AI26: =SUM(AI19:AI25) -> 0 | AJ26: =SUM(AJ19:AJ25) -> 0 | AK26: =SUM(AK19:AK25) -> 0 | AL26: =SUM(AL19:AL25) -> 1 | AM26: =SUM(AM19:AM25) -> 0 | AN26: =SUM(AN19:AN25) -> 1 | AO26: =SUM(AO19:AO25) -> 0 | ... AS26: =SUM(AS19:AS25) -> 0 | AT26: CLASSIC | AU26: PB | AV26: SB
AT27: DRIFT/CROSSCUT | AU27: =AL28 -> 3 | AV27: =AM28 -> 0
A28: GRAND TOTAL | F28: =F26+F18+F9 -> 0 | G28: =G26+G18+G9 -> 0 | H28: =H26+H18+H9 -> 0 | I28: =I26+I18+I9 -> 0 | J28: =J26+J18+J9 -> 0 | K28: =K26+K18+K9 -> 485 | L28: =L26+L18+L9 -> 221.6 | M28: =M26+M18+M9 -> 77.76 | ... AD28: =AD26+AD18+AD9 -> 0 | AH28: =AH26+AH18+AH9 -> 6 | AI28: =AI26+AI18+AI9 -> 0 | AJ28: =AJ26+AJ18+AJ9 -> 3 | AK28: =AK26+AK18+AK9 -> 0 | AL28: =AL26+AL18+AL9 -> 3 | AM28: =AM26+AM18+AM9 -> 0 | AN28: =AN26+AN18+AN9 -> 2 | AO28: =AO26+AO18+AO9 -> 0 | ... AS28: =AS26+AS18+AS9 -> 0 | AT28: RAISE | AU28: =AN28 -> 2 | AV28: =AO28 -> 0
C29: PRICE | F29: 26.2921 | G29: 115.8 | H29: 35.47 | I29: 27.3438 | J29: 40 | K29: 29.5639 | L29: 145.88 | M29: 27.66 | N29: 26.25 | O29: 171.74107 | P29: 176.78571 | Q29: 195 | R29: 180.35714 | S29: 198 | T29: 195 | U29: 189.38 | V29: 207 | W29: 379.46 | X29: 35.15 | Y29: 35.893 | Z29: 37.5 | AA29: 81.9 | AB29: 20.62 | AC29: 267.18 | AD29: 7.5 | AT29: WINZE | AU29: =AP28 -> 1 | AV29: =AQ28 -> 0
C30: TOTAL COST | E30: =F30+G30+K30+L30+M30+N30+O30+P30+Q30+R30+S30+U30+X30+Y30+Z30+AA30+AB30+AC30+AD30+H30+I30 -> 117670.29 | F30: =F28*F29 -> 0 | G30: =G28*G29 -> 0 | H30: =H28*H29 -> 0 | I30: =I28*I29 -> 0 | J30: =J28*J29 -> 0 | K30: =K28*K29 -> 14338.492 | L30: =L28*L29 -> 32327.008 | M30: =M28*M29 -> 2150.8416 | ... AD30: =AD28*AD29 -> 0 | AT30: STOPE/STOPE PREP | AU30: =AH28 -> 6 | AV30: =AI28 -> 0
AT31: ROBBING | AU31: =AJ28 -> 3 | AV31: =AK28 -> 0
AT32: CHAMBER/SHAFT | AU32: =AR28 -> 0 | AV32: =AS28 -> 0
AS33: =AT33-AU33 -> 0 | AT33: =SUM(AX8:AX25) -> 15 | AU33: =SUM(AU27:AU32) -> 15
B35: DESCRIPTION | C35: ISSUANCE | D35: PRICE | E35: COST
B36: DYNA SUPERPOWER 208 | D36: 26.2921 | E36: =C36*D36 -> 0
B37: NEOGEL 200 | C37: =I28 -> 0 | D37: 27.3438
B38: DYNAPULSAR 215 | C38: =K28 -> 485 | D38: 29.5639 | E38: =C38*D38 -> 14338.492
B39: ANFO | C39: =L28 -> 221.6 | D39: 145.88 | E39: =C39*D39 -> 32327.008
B40: S/FUSE | C40: =M28 -> 77.76 | D40: 27.66 | E40: =C40*D40 -> 2150.8416
B41: OBC | C41: =N28 -> 32 | D41: 26.25 | E41: =C41*D41 -> 840
B42: F/LIGHTER | C42: =AB28 -> 0 | D42: 20.62 | E42: =C42*D42 -> 0
B43: NONEL 2.4 | D43: 171.74107 | E43: =C43*D43 -> 0
B44: NONEL 3.6 | D44: 176.78571 | E44: =C44*D44 -> 0
...

Sheet L9
A2: DATE: | C2: =TOTAL!D3 -> 46153 | N2: LEVEL 9
A4: SHIFT | B4: CONT. | C4: Sup | D4: DRILL STEEL | E4: WORKING PLACE | F4: SUPER POWER | G4: PULSAR | H4: EM AUSTIN | I4: NEOGEL | J4: PULSAR | K4: PULSAR | L4: ANFO | M4: SAFETY FUSE | N4: OBC | O4: NONEL | Q4: EXEL | R4: SUPREME | T4: EXEL | U4: EXEL | V4: SHOCK STAR | W4: MS 18 | X4: CORDTEX | AB4: FUSE LIGHTER | AC4: EBC | AD4: BILL WIRE | AE4: COMPUTED DETONATOR COUNT | AF4: MANUAL DETONATOR COUNT | AG4: REMARKS | AH4: STOPE | AJ4: ROBBING | AL4: HORIZONTAL | AN4: RAISE | AP4: WINZE | AR4: SHAFT/CHAMBER/OREPASS
F5: 208 | G5: 38 | H5: 200 | I5: 200 | J5: 135 | K5: 215 | O5: 2.4 | P5: 3.6 | Q5: 3.6 | R5: 2.4 | S5: 3.6 | T5: 4.9 | U5: 2.4 | V5: 2.4 | X5: 5 | Y5: 10 | Z5: DCORD i5 | AA5: 40
F6: PCS | G6: PCS | H6: PCS | I6: PCS | J6: PCS | K6: PCS | L6: KLS | M6: MTRS | N6: PCS | O6: PCS | P6: PCS | Q6: PCS | R6: PCS | S6: PCS | T6: PCS | U6: PCS | V6: PCS | W6: PCS | X6: MTR | Y6: MTR | Z6: MTR | AA6: MTR | AB6: PCS | AC6: PCS | AD6: PCS | AH6: PB | AI6: SB | AJ6: PB | AK6: SB | AL6: PB | AM6: SB | AN6: PB | AO6: SB | AP6: PB | AQ6: SB | AR6: PB | AS6: SB
A7: 1 | B7: NO BLAST | M7: =N7*2.43 -> 0 | AE7: =O7+P7+Q7+R7+S7+T7+U7+V7 -> 0 | AX7: =COUNTIFS(AE7,">=11") -> 0
A8: TOTAL | F8: =SUM(F7:F7) -> 0 | G8: =SUM(G7:G7) -> 0 | H8: =SUM(H7:H7) -> 0 | I8: =SUM(I7:I7) -> 0 | J8: =SUM(J7:J7) -> 0 | K8: =SUM(K7:K7) -> 0 | L8: =SUM(L7:L7) -> 0 | M8: =SUM(M7:M7) -> 0 | ... AD8: =SUM(AD7:AD7) -> 0 | AH8: =SUM(AH7:AH7) -> 0 | AI8: =SUM(AI7:AI7) -> 0 | AJ8: =SUM(AJ7:AJ7) -> 0 | AK8: =SUM(AK7:AK7) -> 0 | AL8: =SUM(AL7:AL7) -> 0 | AM8: =SUM(AM7:AM7) -> 0 | AN8: =SUM(AN7:AN7) -> 0 | AO8: =SUM(AO7:AO7) -> 0 | ... AS8: =SUM(AS7:AS7) -> 0 | AX8: =COUNTIFS(AE8,">=11") -> 0
A9: 2 | B9: DELOS REYES | C9: ABELLA | D9: 5 | E9: 37E STP | K9: 24 | L9: 19.2 | M9: =N9*2.43 -> 4.86 | N9: 2 | Q9: 2 | U9: 22 | X9: 12 | AE9: =O9+P9+Q9+R9+S9+T9+U9+V9 -> 24 | AH9: 1 | AX9: =COUNTIFS(AE9,">=11") -> 1
A10: 2 | B10: BALANGHIG | C10: ABELLA | D10: 5 | E10: 36E W STP | K10: 16 | L10: 12.8 | M10: =N10*2.43 -> 0 | Q10: 2 | U10: 14 | X10: 8 | AC10: 2 | AE10: =O10+P10+Q10+R10+S10+T10+U10+V10 -> 16 | AJ10: 1 | AX10: =COUNTIFS(AE10,">=11") -> 1
A11: TOTAL | F11: =SUM(F9:F10) -> 0 | G11: =SUM(G9:G10) -> 0 | H11: =SUM(H9:H10) -> 0 | I11: =SUM(I9:I10) -> 0 | J11: =SUM(J9:J10) -> 0 | K11: =SUM(K9:K10) -> 40 | L11: =SUM(L9:L10) -> 32 | M11: =SUM(M9:M10) -> 4.86 | ... AD11: =SUM(AD9:AD10) -> 0 | AH11: =SUM(AH9:AH10) -> 1 | AI11: =SUM(AI9:AI10) -> 0 | AJ11: =SUM(AJ9:AJ10) -> 1 | AK11: =SUM(AK9:AK10) -> 0 | AL11: =SUM(AL9:AL10) -> 0 | AM11: =SUM(AM9:AM10) -> 0 | AN11: =SUM(AN9:AN10) -> 0 | AO11: =SUM(AO9:AO10) -> 0 | ... AS11: =SUM(AS9:AS10) -> 0 | AX11: =COUNTIFS(AE11,">=11") -> 0
A12: 3 | B12: DELOS REYES | C12: TUGOT | D12: 5 | E12: 73E ROBB | K12: 18 | L12: 14.4 | M12: =N12*2.43 -> 4.86 | N12: 2 | U12: 18 | X12: 12 | AE12: =O12+P12+Q12+R12+S12+T12+U12+V12 -> 18 | AJ12: 1 | AX12: =COUNTIFS(AE12,">=11") -> 1
A13: 3 | B13: DELOS REYES | C13: LARONA | D13: 5 | E13: 37E STP | K13: 29 | L13: 23.2 | M13: =N13*2.43 -> 4.86 | N13: 2 | Q13: 2 | U13: 27 | X13: 12 | AE13: =O13+P13+Q13+R13+S13+T13+U13+V13 -> 29 | AH13: 1 | AX13: =COUNTIFS(AE13,">=11") -> 1
A14: 3 | B14: FERNANDEZ | C14: LARONA | D14: 5 | E14: 8E XCS | K14: 156 | M14: =N14*2.43 -> 4.86 | N14: 2 | Q14: 2 | U14: 24 | X14: 8 | AE14: =O14+P14+Q14+R14+S14+T14+U14+V14 -> 26 | AL14: 1 | AX14: =COUNTIFS(AE14,">=11") -> 1
A15: TOTAL | F15: =SUM(F12:F14) -> 0 | G15: =SUM(G12:G14) -> 0 | H15: =SUM(H12:H14) -> 0 | I15: =SUM(I12:I14) -> 0 | J15: =SUM(J12:J14) -> 0 | K15: =SUM(K12:K14) -> 203 | L15: =SUM(L12:L14) -> 37.6 | M15: =SUM(M12:M14) -> 14.58 | ... AD15: =SUM(AD12:AD14) -> 0 | AH15: =SUM(AH12:AH14) -> 1 | AI15: =SUM(AI12:AI14) -> 0 | AJ15: =SUM(AJ12:AJ14) -> 1 | AK15: =SUM(AK12:AK14) -> 0 | AL15: =SUM(AL12:AL14) -> 1 | AM15: =SUM(AM12:AM14) -> 0 | AN15: =SUM(AN12:AN14) -> 0 | AO15: =SUM(AO12:AO14) -> 0 | ... AS15: =SUM(AS12:AS14) -> 0 | AT15: CLASSIC | AU15: PB | AV15: SB
AT16: DRIFT/CROSSCUT | AU16: =AL17 -> 1 | AV16: =AM17 -> 0
A17: GRAND TOTAL | F17: =F15+F11+F8 -> 0 | G17: =G15+G11+G8 -> 0 | H17: =H15+H11+H8 -> 0 | I17: =I15+I11+I8 -> 0 | J17: =J15+J11+J8 -> 0 | K17: =K15+K11+K8 -> 243 | L17: =L15+L11+L8 -> 69.6 | M17: =M15+M11+M8 -> 19.44 | ... AD17: =AD15+AD11+AD8 -> 0 | AH17: =AH15+AH11+AH8 -> 2 | AI17: =AI15+AI11+AI8 -> 0 | AJ17: =AJ15+AJ11+AJ8 -> 2 | AK17: =AK15+AK11+AK8 -> 0 | AL17: =AL15+AL11+AL8 -> 1 | AM17: =AM15+AM11+AM8 -> 0 | AN17: =AN15+AN11+AN8 -> 0 | AO17: =AO15+AO11+AO8 -> 0 | ... AS17: =AS15+AS11+AS8 -> 0 | AT17: RAISE | AU17: =AN17 -> 0 | AV17: =AO17 -> 0
C18: PRICE | F18: 26.2921 | G18: 115.8 | H18: 35.47 | I18: 27.3438 | J18: 40 | K18: 29.5639 | L18: 145.88 | M18: 27.66 | N18: 26.25 | O18: 171.74107 | P18: 176.78571 | Q18: 195 | R18: 180.35714 | S18: 198 | T18: 195 | U18: 189.38 | V18: 207 | W18: 379.46 | X18: 35.15 | Y18: 35.893 | Z18: 37.5 | AA18: 81.9 | AB18: 20.62 | AC18: 267.18 | AD18: 7.5 | AT18: WINZE | AU18: =AP17 -> 0 | AV18: =AQ17 -> 0
C19: TOTAL COST | E19: =F19+G19+K19+L19+M19+N19+O19+P19+Q19+R19+S19+U19+X19+Y19+Z19+AA19+AB19+AC19+AD19+H19+I19 -> 41892.046 | F19: =F17*F18 -> 0 | G19: =G17*G18 -> 0 | H19: =H17*H18 -> 0 | I19: =I17*I18 -> 0 | J19: =J17*J18 -> 0 | K19: =K17*K18 -> 7184.0277 | L19: =L17*L18 -> 10153.248 | M19: =M17*M18 -> 537.7104 | ... AD19: =AD17*AD18 -> 0 | AT19: STOPE/STOPE PREP | AU19: =AH17 -> 2 | AV19: =AI17 -> 0
AT20: ROBBING | AU20: =AJ17 -> 2 | AV20: =AK17 -> 0
AT21: CHAMBER/SHAFT | AU21: =AR17 -> 0 | AV21: =AS17 -> 0
AS22: =AT22-AU22 -> 0 | AT22: =SUM(AX7:AX14) -> 5 | AU22: =SUM(AU16:AU21) -> 5
B24: DESCRIPTION | C24: ISSUANCE | D24: PRICE | E24: COST
B25: DYNA SUPERPOWER 208 | D25: 26.2921 | E25: =C25*D25 -> 0
B26: NEOGEL 200 | C26: =I17 -> 0 | D26: 27.3438
B27: DYNAPULSAR 215 | C27: =K17 -> 243 | D27: 29.5639 | E27: =C27*D27 -> 7184.0277
B28: ANFO | C28: =L17 -> 69.6 | D28: 145.88 | E28: =C28*D28 -> 10153.248
B29: S/FUSE | C29: =M17 -> 19.44 | D29: 27.66 | E29: =C29*D29 -> 537.7104
B30: OBC | C30: =N17 -> 8 | D30: 26.25 | E30: =C30*D30 -> 210
B31: F/LIGHTER | C31: =AB17 -> 0 | D31: 20.62 | E31: =C31*D31 -> 0
B32: NONEL 2.4 | D32: 171.74107 | E32: =C32*D32 -> 0
B33: NONEL 3.6 | D33: 176.78571 | E33: =C33*D33 -> 0
B34: SUPREME 2.4 | D34: 180.35714 | E34: =C34*D34 -> 0
B35: SHOCK STAR | D35: 207 | E35: =C35*D35 -> 0
B36: PENTEX STOPE PREIME | D36: 331 | E36: =C36*D36 -> 0
B37: EXEL 2.4 | C37: =U17 -> 105 | D37: 189.38 | E37: =C37*D37 -> 19884.9
B38: EXEL 4.9 | D38: 195 | E38: =C38*D38 -> 0
B39: EXEL 3.6 | C39: =Q17 -> 8 | D39: 195 | E39: =C39*D39 -> 1560
B40: MS 12 | D40: 359.83 | E40: =C40*D40 -> 0
B41: MS 18 | D41: 379.46 | E41: =C41*D41 -> 0
B42: CORDTEX 5 | C42: =X17 -> 52 | D42: 35.15 | E42: =C42*D42 -> 1827.8
B43: CORDTEX 10 | C43: =Y17 -> 0 | D43: 35.893 | E43: =C43*D43 -> 0
...

Sheet L10
A2: DATE: | C2: =TOTAL!D3 -> 46153 | N2: LEVEL 10
A4: SHIFT | B4: CONT. | C4: Sup | D4: DRILL STEEL | E4: WORKING PLACE | F4: SUPER POWER | G4: PULSAR | H4: EM AUSTIN | I4: NEOGEL | J4: PULSAR | K4: PULSAR | L4: ANFO | M4: SAFETY FUSE | N4: OBC | O4: NONEL | Q4: EXEL | R4: SUPREME | T4: EXEL | U4: EXEL | V4: SHOCK STAR | W4: MS 18 | X4: CORDTEX | AB4: FUSE LIGHTER | AC4: EBC | AD4: BILL WIRE | AE4: COMPUTED DETONATOR COUNT | AF4: MANUAL DETONATOR COUNT | AG4: REMARKS | AH4: STOPE | AJ4: ROBBING | AL4: HORIZONTAL | AN4: RAISE | AP4: WINZE | AR4: SHAFT/CHAMBER/OREPASS
F5: 208 | G5: 38 | H5: 200 | I5: 200 | J5: 135 | K5: 215 | O5: 2.4 | P5: 3.6 | Q5: 3.6 | R5: 2.4 | S5: 3.6 | T5: 4.9 | U5: 2.4 | V5: 2.4 | X5: 5 | Y5: 10 | Z5: DCORD i5 | AA5: 40
F6: PCS | G6: PCS | H6: PCS | I6: PCS | J6: PCS | K6: PCS | L6: KLS | M6: MTRS | N6: PCS | O6: PCS | P6: PCS | Q6: PCS | R6: PCS | S6: PCS | T6: PCS | U6: PCS | V6: PCS | W6: PCS | X6: MTR | Y6: MTR | Z6: MTR | AA6: MTR | AB6: PCS | AC6: PCS | AD6: PCS | AH6: PB | AI6: SB | AJ6: PB | AK6: SB | AL6: PB | AM6: SB | AN6: PB | AO6: SB | AP6: PB | AQ6: SB | AR6: PB | AS6: SB
A7: 1 | B7: NO BLAST | M7: =N7*2.43 -> 0 | AE7: =O7+P7+Q7+R7+S7+T7+U7+V7 -> 0 | AX7: =COUNTIFS(AE7,">=11") -> 0
A8: TOTAL | F8: =SUM(F7:F7) -> 0 | G8: =SUM(G7:G7) -> 0 | H8: =SUM(H7:H7) -> 0 | I8: =SUM(I7:I7) -> 0 | J8: =SUM(J7:J7) -> 0 | K8: =SUM(K7:K7) -> 0 | L8: =SUM(L7:L7) -> 0 | M8: =SUM(M7:M7) -> 0 | ... AD8: =SUM(AD7:AD7) -> 0 | AH8: =SUM(AH7:AH7) -> 0 | AI8: =SUM(AI7:AI7) -> 0 | AJ8: =SUM(AJ7:AJ7) -> 0 | AK8: =SUM(AK7:AK7) -> 0 | AL8: =SUM(AL7:AL7) -> 0 | AM8: =SUM(AM7:AM7) -> 0 | AN8: =SUM(AN7:AN7) -> 0 | AO8: =SUM(AO7:AO7) -> 0 | ... AS8: =SUM(AS7:AS7) -> 0 | AX8: =COUNTIFS(AE8,">=11") -> 0
A9: 2 | B9: DELOS REYES | C9: NAVALES | D9: 5 | E9: 12W XCN | K9: 44 | L9: 16 | M9: =N9*2.43 -> 4.86 | N9: 2 | Q9: 2 | U9: 22 | X9: 8 | AE9: =O9+P9+Q9+R9+S9+T9+U9+V9 -> 24 | AL9: 1 | AX9: =COUNTIFS(AE9,">=11") -> 1
A10: 2 | B10: LARGO | C10: NAVALES | D10: 5 | E10: 28W STP PREP | K10: 13 | L10: 10.4 | M10: =N10*2.43 -> 4.86 | N10: 2 | U10: 13 | X10: 5 | AE10: =O10+P10+Q10+R10+S10+T10+U10+V10 -> 13 | AJ10: 1 | AX10: =COUNTIFS(AE10,">=11") -> 1
A11: 2 | B11: LARGO | C11: NAVALES | D11: 5 | E11: 46E DE | K11: 44 | L11: 16 | M11: =N11*2.43 -> 4.86 | N11: 2 | U11: 24 | X11: 8 | AE11: =O11+P11+Q11+R11+S11+T11+U11+V11 -> 24 | AL11: 1 | AX11: =COUNTIFS(AE11,">=11") -> 1
A12: 2 | B12: SAMBERE | C12: NAVALES | D12: 5 | E12: 16E XCS | K12: 42 | L12: 14.4 | M12: =N12*2.43 -> 4.86 | N12: 2 | Q12: 2 | U12: 20 | X12: 8 | AE12: =O12+P12+Q12+R12+S12+T12+U12+V12 -> 22 | AL12: 1 | AX12: =COUNTIFS(AE12,">=11") -> 1
A13: TOTAL | F13: =SUM(F9:F12) -> 0 | G13: =SUM(G9:G12) -> 0 | H13: =SUM(H9:H12) -> 0 | I13: =SUM(I9:I12) -> 0 | J13: =SUM(J9:J12) -> 0 | K13: =SUM(K9:K12) -> 143 | L13: =SUM(L9:L12) -> 56.8 | M13: =SUM(M9:M12) -> 19.44 | ... AD13: =SUM(AD9:AD12) -> 0 | AH13: =SUM(AH9:AH12) -> 0 | AI13: =SUM(AI9:AI12) -> 0 | AJ13: =SUM(AJ9:AJ12) -> 1 | AK13: =SUM(AK9:AK12) -> 0 | AL13: =SUM(AL9:AL12) -> 3 | AM13: =SUM(AM9:AM12) -> 0 | AN13: =SUM(AN9:AN12) -> 0 | AO13: =SUM(AO9:AO12) -> 0 | ... AS13: =SUM(AS9:AS12) -> 0 | AX13: =COUNTIFS(AE13,">=11") -> 0
A14: 3 | B14: LARGO | C14: CARVAJAL | D14: 5 | E14: 28E STP PREP | K14: 19 | L14: 15.2 | M14: =N14*2.43 -> 4.86 | N14: 2 | U14: 19 | X14: 6 | AE14: =O14+P14+Q14+R14+S14+T14+U14+V14 -> 19 | AH14: 1 | AX14: =COUNTIFS(AE14,">=11") -> 1
A15: 3 | B15: FERNANDEZ | C15: CARVAJAL | E15: 66E ROBB | K15: 30 | M15: =N15*2.43 -> 14.58 | N15: 6 | X15: 15 | AE15: =O15+P15+Q15+R15+S15+T15+U15+V15 -> 0 | AK15: 1 | AX15: =COUNTIFS(AE15,">=11") -> 0
A16: TOTAL | F16: =SUM(F14:F15) -> 0 | G16: =SUM(G14:G15) -> 0 | H16: =SUM(H14:H15) -> 0 | I16: =SUM(I14:I15) -> 0 | J16: =SUM(J14:J15) -> 0 | K16: =SUM(K14:K15) -> 49 | L16: =SUM(L14:L15) -> 15.2 | M16: =SUM(M14:M15) -> 19.44 | ... AD16: =SUM(AD14:AD15) -> 0 | AH16: =SUM(AH14:AH15) -> 1 | AI16: =SUM(AI14:AI15) -> 0 | AJ16: =SUM(AJ14:AJ15) -> 0 | AK16: =SUM(AK14:AK15) -> 1 | AL16: =SUM(AL14:AL15) -> 0 | AM16: =SUM(AM14:AM15) -> 0 | AN16: =SUM(AN14:AN15) -> 0 | AO16: =SUM(AO14:AO15) -> 0 | ... AS16: =SUM(AS14:AS15) -> 0 | AT16: CLASSIC | AU16: PB | AV16: SB
AT17: DRIFT/CROSSCUT | AU17: =AL18 -> 3 | AV17: =AM18 -> 0
A18: GRAND TOTAL | F18: =F16+F13+F8 -> 0 | G18: =G16+G13+G8 -> 0 | H18: =H16+H13+H8 -> 0 | I18: =I16+I13+I8 -> 0 | J18: =J16+J13+J8 -> 0 | K18: =K16+K13+K8 -> 192 | L18: =L16+L13+L8 -> 72 | M18: =M16+M13+M8 -> 38.88 | ... AD18: =AD16+AD13+AD8 -> 0 | AH18: =AH16+AH13+AH8 -> 1 | AI18: =AI16+AI13+AI8 -> 0 | AJ18: =AJ16+AJ13+AJ8 -> 1 | AK18: =AK16+AK13+AK8 -> 1 | AL18: =AL16+AL13+AL8 -> 3 | AM18: =AM16+AM13+AM8 -> 0 | AN18: =AN16+AN13+AN8 -> 0 | AO18: =AO16+AO13+AO8 -> 0 | ... AS18: =AS16+AS13+AS8 -> 0 | AT18: RAISE | AU18: =AN18 -> 0 | AV18: =AO18 -> 0
C19: PRICE | F19: 26.2921 | G19: 115.8 | H19: 35.47 | I19: 27.3438 | J19: 40 | K19: 29.5639 | L19: 145.88 | M19: 27.66 | N19: 26.25 | O19: 171.74107 | P19: 176.78571 | Q19: 195 | R19: 180.35714 | S19: 198 | T19: 195 | U19: 189.38 | V19: 207 | W19: 379.46 | X19: 35.15 | Y19: 35.893 | Z19: 37.5 | AA19: 81.9 | AB19: 20.62 | AC19: 267.18 | AD19: 7.5 | AT19: WINZE | AU19: =AP18 -> 0 | AV19: =AQ18 -> 0
C20: TOTAL COST | E20: =F20+G20+K20+L20+M20+N20+O20+P20+Q20+R20+S20+U20+X20+Y20+Z20+AA20+AB20+AC20+AD20+H20+I20 -> 38771.79 | F20: =F18*F19 -> 0 | G20: =G18*G19 -> 0 | H20: =H18*H19 -> 0 | I20: =I18*I19 -> 0 | J20: =J18*J19 -> 0 | K20: =K18*K19 -> 5676.2688 | L20: =L18*L19 -> 10503.36 | M20: =M18*M19 -> 1075.4208 | ... AD20: =AD18*AD19 -> 0 | AT20: STOPE/STOPE PREP | AU20: =AH18 -> 1 | AV20: =AI18 -> 0
AT21: ROBBING | AU21: =AJ18 -> 1 | AV21: =AK18 -> 1
AT22: CHAMBER/SHAFT | AU22: =AR18 -> 0 | AV22: =AS18 -> 0
AS23: =AT23-AU23 -> 0 | AT23: =SUM(AX7:AX15) -> 5 | AU23: =SUM(AU17:AU22) -> 5
B25: DESCRIPTION | C25: ISSUANCE | D25: PRICE | E25: COST
B26: DYNA SUPERPOWER 208 | D26: 26.2921 | E26: =C26*D26 -> 0
B27: NEOGEL 200 | C27: =I18 -> 0 | D27: 27.3438
B28: DYNAPULSAR 215 | C28: =K18 -> 192 | D28: 29.5639 | E28: =C28*D28 -> 5676.2688
B29: ANFO | C29: =L18 -> 72 | D29: 145.88 | E29: =C29*D29 -> 10503.36
B30: S/FUSE | C30: =M18 -> 38.88 | D30: 27.66 | E30: =C30*D30 -> 1075.4208
B31: OBC | C31: =N18 -> 16 | D31: 26.25 | E31: =C31*D31 -> 420
B32: F/LIGHTER | C32: =AB18 -> 0 | D32: 20.62 | E32: =C32*D32 -> 0
B33: NONEL 2.4 | D33: 171.74107 | E33: =C33*D33 -> 0
B34: NONEL 3.6 | D34: 176.78571 | E34: =C34*D34 -> 0
B35: SUPREME 2.4 | D35: 180.35714 | E35: =C35*D35 -> 0
B36: SHOCK STAR | D36: 207 | E36: =C36*D36 -> 0
B37: PENTEX STOPE PREIME | D37: 331 | E37: =C37*D37 -> 0
B38: EXEL 2.4 | C38: =U18 -> 98 | D38: 189.38 | E38: =C38*D38 -> 18559.24
B39: EXEL 4.9 | D39: 195 | E39: =C39*D39 -> 0
B40: EXEL 3.6 | C40: =Q18 -> 4 | D40: 195 | E40: =C40*D40 -> 780
B41: MS 12 | D41: 359.83 | E41: =C41*D41 -> 0
B42: MS 18 | D42: 379.46 | E42: =C42*D42 -> 0
B43: CORDTEX 5 | C43: =X18 -> 50 | D43: 35.15 | E43: =C43*D43 -> 1757.5
...

Sheet L11
A2: DATE: | C2: =TOTAL!D3 -> 46153 | N2: LEVEL 11
