Workbook

Sheet MT.ROCK (PURCHASED & SF)
A2: DATE | B2: SERVICE FEES/DELIVERY | C2: GROSS AMOUNT BILLED | D2: NET OF VAT | F2: DATE | G2: INVOICES/DELIVERY | H2: GROSS AMOUNT BILLED | I2: NET OF VAT
A3: 44230 | B3: SI1125 | C3: =178716.38+21445.97 -> 200162.35 | D3: =C3/1.12 -> 178716.38 | F3: 44226 | G3: SI1125 | H3: =3574327.08+428919.25 -> 4003246.3 | I3: =H3/1.12 -> 3574327.1
A4: 44260 | B4: SI1148 | C4: =168569.96+20228.39 -> 188798.35 | D4: =C4/1.12 -> 168569.96 | F4: 44246 | G4: SI1148 | H4: =3371400.4+404568.04 -> 3775968.4 | I4: =H4/1.12 -> 3371400.4
A5: 44260 | B5: SI1140 | C5: =257303.97+30876.48 -> 288180.45 | D5: =C5/1.12 -> 257303.97 | F5: 44239 | G5: SI1140 | H5: =5146078.47+617592.42 -> 5763670.9 | I5: =H5/1.12 -> 5146134.7
A6: 44289 | B6: CI1166 | C6: =111814.51+13417.74 -> 125232.25 | D6: =C6/1.12 -> 111814.51 | F6: 44258 | G6: SI1166 | H6: 2236290 | I6: =H6/1.12 -> 1996687.5
A7: 44289 | B7: CI1179 | C7: =127662.01+15319.44 -> 142981.45 | D7: =C7/1.12 -> 127662.01 | F7: 44272 | G7: SI1179 | H7: =2553239.67+306388.76 -> 2859628.4 | I7: =H7/1.12 -> 2553239.7
A8: 44289 | B8: SI1176 | C8: =128845.04+15461.41 -> 144306.45 | D8: =C8/1.12 -> 128845.04 | F8: 44266 | G8: SI1176 | H8: =2576900.37+309228.04 -> 2886128.4 | I8: =H8/1.12 -> 2576900.4
A9: 44319 | B9: SI1203 | C9: =95812.66+11497.52 -> 107310.18 | D9: =C9/1.12 -> 95812.661 | F9: 44305 | G9: SI1203 | H9: =1916252.88+229950.35 -> 2146203.2 | I9: =H9/1.12 -> 1916252.9
A10: 44319 | B10: SI1187 | C10: =116967.26+14036.07 -> 131003.33 | D10: =C10/1.12 -> 116967.26 | F10: 44280 | G10: SI1187 | H10: =2339344.91+280721.39 -> 2620066.3 | I10: =H10/1.12 -> 2339344.9
A11: 44340 | B11: SI1232 | C11: =77569.29+9308.31 -> 86877.6 | D11: =C11/1.12 -> 77569.286 | F11: 44326 | G11: SI1232 | H11: =1551385.33+186166.24 -> 1737551.6 | I11: =H11/1.12 -> 1551385.3
A12: 44340 | B12: SI1211 | C12: =125946.99+15113.64 -> 141060.63 | D12: =C12/1.12 -> 125946.99 | F12: 44313 | G12: SI1211 | H12: =2518939.35+302272.73 -> 2821212.1 | I12: =H12/1.12 -> 2518939.4
A13: 44347 | B13: SI1238 | C13: =147525.67+17703.08 -> 165228.75 | D13: =C13/1.12 -> 147525.67 | F13: 44331 | G13: SI1238 | H13: =2842834.37+341140.13 -> 3183974.5 | I13: =H13/1.12 -> 2842834.4
A14: 44355 | B14: SI1245 | C14: =150070.31+18008.44 -> 168078.75 | D14: =C14/1.12 -> 150070.31 | F14: 44337 | G14: SI1245 | H14: =2678369.72+321404.37 -> 2999774.1 | I14: =H14/1.12 -> 2678369.7
A15: 44368 | B15: SI1257 | C15: =202801.65+24336.2 -> 227137.85 | D15: =C15/1.12 -> 202801.65 | F15: 44355 | G15: SI1257 | H15: =4056032.75+486723.93 -> 4542756.7 | I15: =H15/1.12 -> 4056032.7
A16: 44364 | B16: SI1256 | C16: 180327.25 | D16: =C16/1.12 -> 161006.47 | F16: 44350 | G16: SI1256 | H16: =3220130.69+386415.69 -> 3606546.4 | I16: =H16/1.12 -> 3220130.7
A17: 44385 | B17: SI1273/BS3 | C17: =102076.59+12249.19 -> 114325.78 | D17: =C17/1.12 -> 102076.59 | F17: 44372 | G17: SI1273 | H17: =2041529.94+244983.59 -> 2286513.5 | I17: =H17/1.12 -> 2041529.9
A18: 44393 | B18: SI1274/BS4 | C18: =81336.61+9760.39 -> 91097 | D18: =C18/1.12 -> 81336.607 | F18: 44379 | G18: SI274 | H18: =1626731.62+195207.8 -> 1821939.4 | I18: =H18/1.12 -> 1626731.6
A19: 44393 | B19: SI1285/BS7 | C19: =53792.32+6455.08 -> 60247.4 | D19: =C19/1.12 -> 53792.321 | F19: 44385 | G19: SI1285 | H19: =1075845.83+129101.5 -> 1204947.3 | I19: =H19/1.12 -> 1075845.8
A20: 44407 | B20: SI1300/BS12 | C20: =122184.73+14662.17 -> 136846.9 | D20: =C20/1.12 -> 122184.73 | F20: 44398 | G20: SI1300 | H20: =2443695.2+293243.42 -> 2736938.6 | I20: =H20/1.12 -> 2443695.2
A21: 44413 | B21: SI1308/BS16 | C21: =106722.44+12806.69 -> 119529.13 | D21: =C21/1.12 -> 106722.44 | F21: 44406 | G21: SI1308 | H21: =2134448.35+256133.8 -> 2390582.1 | I21: =H21/1.12 -> 2134448.3
A22: 44427 | B22: SI1322/BS18 | C22: =151117.62+18134.11 -> 169251.73 | D22: =C22/1.12 -> 151117.62 | F22: 44413 | G22: SI1322 | H22: =3022351.9+362682.23 -> 3385034.1 | I22: =H22/1.12 -> 3022351.9
A23: 44439 | B23: SI1340/BS24 | C23: =143693.3+17243.2 -> 160936.5 | D23: =C23/1.12 -> 143693.3 | F23: 44426 | G23: SI1340 | H23: =2873865.14+344863.82 -> 3218729 | I23: =H23/1.12 -> 2873865.1
A24: 44439 | B24: SI1327/BS20 | C24: =146455.58+17574.67 -> 164030.25 | D24: =C24/1.12 -> 146455.58 | F24: 44420 | G24: SI1327 | H24: =2929111.36+351493.37 -> 3280604.7 | I24: =H24/1.12 -> 2929111.4
A25: 44455 | B25: SI1351/BS31 | C25: =153671.54+18440.58 -> 172112.12 | D25: =C25/1.12 -> 153671.54 | F25: 44441 | G25: SI1351 | H25: =3073431.97+368811.84 -> 3442243.8 | I25: =H25/1.12 -> 3073432
A26: 44463 | B26: SI1369/BS37 | C26: =114479.13+13737.5 -> 128216.63 | D26: =C26/1.12 -> 114479.13 | F26: 44447 | G26: SI1369 | H26: =2289581.89+274749.82 -> 2564331.7 | I26: =H26/1.12 -> 2289581.9
A27: 44487 | B27: SI1392/BS48 | C27: =212107.71+25452.93 -> 237560.64 | D27: =C27/1.12 -> 212107.71 | F27: 44462 | G27: SI1392 | H27: =4242154.83+509058.59 -> 4751213.4 | I27: =H27/1.12 -> 4242154.8
A28: 44483 | B28: SI1398/BS50 | C28: =101471.3+12176.56 -> 113647.86 | D28: =C28/1.12 -> 101471.3 | F28: 44468 | G28: SI1398 | H28: =2029426.55+243531.19 -> 2272957.7 | I28: =H28/1.12 -> 2029426.6
A29: 44477 | B29: BS48 | C29: 237560.64 | D29: 212107.71
A30: 44494 | B30: SI1417/BS56 | C30: =154464.87+18535.78 -> 173000.65 | D30: =C30/1.12 -> 154464.87 | F30: 44476 | G30: SI1247 | H30: =3089296.45+370715.57 -> 3460012 | I30: =H30/1.12 -> 3089296.4
A31: 44510 | B31: SI1450/BS91 | C31: =84066.47+10087.98 -> 94154.45 | D31: =C31/1.12 -> 84066.473 | F31: 44496 | G31: SI1450 | H31: =1681329.5+201759.54 -> 1883089 | I31: =H31/1.12 -> 1681329.5
A32: 44522 | B32: SI1457/BS105 | C32: =75519.96+9062.4 -> 84582.36 | D32: =C32/1.12 -> 75519.964 | F32: 44511 | G32: SI1457 | H32: =1510399.12+181247.89 -> 1691647 | I32: =H32/1.12 -> 1510399.1
A33: 44539 | B33: SI1456/BS122 | C33: =60004.33+7200.52 -> 67204.85 | D33: =C33/1.12 -> 60004.33 | F33: 44530 | G33: SI1456 | H33: =1200086.62+144010.38 -> 1344097 | I33: =H33/1.12 -> 1200086.6
A34: 44561 | B34: SI1509/BS152 | C34: =61187.37+7342.48 -> 68529.85 | D34: =C34/1.12 -> 61187.366 | F34: 44543 | G34: SI1509 | H34: =1223747.37+146849.69 -> 1370597.1 | I34: =H34/1.12 -> 1223747.4
A35: 44561 | B35: SI1510/BS153 | C35: =61187.37+7342.48 -> 68529.85 | D35: =C35/1.12 -> 61187.366 | F35: 44551 | G35: SI1510 | H35: =1223747.37+146849.69 -> 1370597.1 | I35: =H35/1.12 -> 1223747.4
A36: 44561 | B36: SI1512/BS154 | C36: =27733.13+3327.98 -> 31061.11 | D36: =C36/1.12 -> 27733.134 | F36: 44551 | G36: SI1512 | H36: =554662.47+66559.5 -> 621221.97 | I36: =H36/1.12 -> 554662.47
A37: 44601 | B37: SI1546/BS189 | C37: =91669.78+11000.37 -> 102670.15 | D37: =C37/1.12 -> 91669.777 | F37: 44581 | G37: SI1546 | H37: =1833395.56+220007.46 -> 2053403 | I37: =H37/1.12 -> 1833395.6
A38: 44614 | B38: SI1548/BS191 | C38: =60640.31+7276.84 -> 67917.15 | D38: =C38/1.12 -> 60640.312 | F38: 44588 | G38: SI1548 | H38: =1212806.37+145536.76 -> 1358343.1 | I38: =H38/1.12 -> 1212806.4
A39: 44615 | B39: SI1549/BS192 | C39: =35909.6+4309.15 -> 40218.75 | D39: =C39/1.12 -> 35909.598 | F39: 44595 | G39: SI1549 | H39: =718192+86183.04 -> 804375.04 | I39: =H39/1.12 -> 718192
A40: 44615 | B40: SI1550/BS203 | C40: =15184.15+1822.1 -> 17006.25 | D40: =C40/1.12 -> 15184.152 | F40: 44602 | G40: SI1550 | H40: =303683+36441.96 -> 340124.96 | I40: =H40/1.12 -> 303683
A41: 44628 | B41: SI1565/BS221 | C41: =4821.43+578.57 -> 5400 | D41: =C41/1.12 -> 4821.4286 | F41: 44616 | G41: SI1565 | H41: =96428.5+11571.42 -> 107999.92 | I41: =H41/1.12 -> 96428.5
...

Sheet EXPEDITION (PURCHASED & SF)
A2: DATE | B2: SERVICE FEES/DELIVERY | C2: GROSS AMOUNT BILLED | D2: NET OF VAT | F2: DATE | G2: INVOICES/DELIVERY | H2: GROSS AMOUNT BILLED | I2: NET OF VAT
A3: 44237 | B3: CI3273 | C3: =177736.61+21328.39 -> 199065 | D3: =C3/1.12 -> 177736.61 | F3: 44226 | G3: CI3273 | H3: =3554731.85+426567.83 -> 3981299.7 | I3: =H3/1.12 -> 3554731.9
A4: 44260 | B4: CI3274 | C4: =259390.18+31126.82 -> 290517 | D4: =C4/1.12 -> 259390.18 | F4: 44239 | G4: CI3274 | H4: =5187803.17+622536.38 -> 5810339.5 | I4: =H4/1.12 -> 5187803.2
A5: 44260 | B5: CI3275 | C5: =170235.27+20428.23 -> 190663.5 | D5: =C5/1.12 -> 170235.27 | F5: 44246 | G5: CI3275 | H5: =3404704.57+408564.55 -> 3813269.1 | I5: =H5/1.12 -> 3404704.6
A6: 44289 | B6: AP25997-CI3277 | C6: =111817.86+13418.14 -> 125236 | D6: =C6/1.12 -> 111817.86 | F6: 44258 | G6: CI3277 | H6: =2236357.06+268362.85 -> 2504719.9 | I6: =H6/1.12 -> 2236357.1
A7: 44289 | B7: AP25997-CI3279 | C7: =129317.86+15518.14 -> 144836 | D7: =C7/1.12 -> 129317.86 | F7: 44265 | G7: CI3279 | H7: =2586356.91+310362.83 -> 2896719.7 | I7: =H7/1.12 -> 2586356.9
A8: 44289 | B8: AP25997-CI3281 | C8: =131460.71+15775.29 -> 147236 | D8: =C8/1.12 -> 131460.71 | F8: 44271 | G8: CI3281 | H8: =2629214.06+315505.69 -> 2944719.8 | I8: =H8/1.12 -> 2629214.1
A9: 44319 | B9: AP25932-CI3282 | C9: =119786.61+14374.39 -> 134161 | D9: =C9/1.12 -> 119786.61 | F9: 44280 | G9: CI3282 | H9: =2395732.14+287487.87 -> 2683220 | I9: =H9/1.12 -> 2395732.2
A10: 44319 | B10: AP25932-CI3285 | C10: =96006.25+11520.75 -> 107527 | D10: =C10/1.12 -> 96006.25 | F10: 44305 | G10: CI3285 | H10: =1920124.9+230415 -> 2150539.9 | I10: =H10/1.12 -> 1920124.9
A11: 44340 | B11: AP26253-CI3291 | C11: =82063.39+9847.61 -> 91911 | D11: =C11/1.12 -> 82063.393 | F11: 44326 | G11: CI3291 | H11: =1641267.66+196952.13 -> 1838219.8 | I11: =H11/1.12 -> 1641267.7
A12: 44340 | B12: AP26253-CI3289 | C12: =141110.71+16933.29 -> 158044 | D12: =C12/1.12 -> 141110.71 | F12: 44313 | G12: CI3289 | H12: =2822214.03+338665.69 -> 3160879.7 | I12: =H12/1.12 -> 2822214
A13: 44347 | B13: AP26384-CI3292 | C13: =148151.79+17778.21 -> 165930 | D13: =C13/1.12 -> 148151.79 | F13: 44331 | G13: CI3292 | H13: =2963035.61+355564.27 -> 3318599.9 | I13: =H13/1.12 -> 2963035.6
A14: 44355 | B14: AP26549-CI3296 | C14: =147669.64+17720.36 -> 165390 | D14: =C14/1.12 -> 147669.64 | F14: 44337 | G14: CI3296 | H14: =2953392.75+354407.13 -> 3307799.9 | I14: =H14/1.12 -> 2953392.7
A15: 44364 | B15: SI03298 | C15: =158545.54+19025.46 -> 177571 | D15: =C15/1.12 -> 158545.54 | F15: 44350 | G15: CI3298 | H15: =3170910.52+380509.27 -> 3551419.8 | I15: =H15/1.12 -> 3170910.5
A16: 44368 | B16: AP26849-1_CI3301 | C16: =198718.75+23846.25 -> 222565 | D16: =C16/1.12 -> 198718.75 | F16: 44355 | G16: CI3301 | H16: =3974374.92+476924.99 -> 4451299.9 | I16: =H16/1.12 -> 3974374.9
A17: 44383 | B17: AP29470-CI3303 | C17: =101377.68+12165.32 -> 113543 | D17: =C17/1.12 -> 101377.68 | F17: 44372 | G17: CI3303 | H17: =2027553.01+243306.37 -> 2270859.4 | I17: =H17/1.12 -> 2027553
A18: 44393 | B18: AP29538-CI3308 | C18: =83035.71+9964.29 -> 93000 | D18: =C18/1.12 -> 83035.714 | F18: 44385 | G18: CI3308 | H18: =1660714.07+199285.69 -> 1859999.8 | I18: =H18/1.12 -> 1660714.1
A19: 44393 | B19: AP29538-CI3304 | C19: =99866.07+11983.93 -> 111850 | D19: =C19/1.12 -> 99866.071 | F19: 44379 | G19: CI3304 | H19: =1940535.58+232864.27+56785.73+6814.29 -> 2236999.9 | I19: =H19/1.12 -> 1997321.3
A20: 44407 | B20: AP29647-CI3309 | C20: =182790.18+21934.82 -> 204725 | D20: =C20/1.12 -> 182790.18 | F20: 44398 | G20: CI3309 | H20: =3655803.15+438696.38 -> 4094499.5 | I20: =H20/1.12 -> 3655803.2
A21: 44413 | B21: AP29728-CI3310 | C21: =103372.32+12404.68 -> 115777 | D21: =C21/1.12 -> 103372.32 | F21: 44406 | G21: CI3310 | H21: =2067446.35+248093.57 -> 2315539.9 | I21: =H21/1.12 -> 2067446.4
A22: 44427 | B22: AP29832-CI3311 | C22: =150459.82+18055.18 -> 168515 | D22: =C22/1.12 -> 150459.82 | F22: 44413 | G22: CI3311 | H22: =3009196.41+361103.57 -> 3370300 | I22: =H22/1.12 -> 3009196.4
A23: 44439 | B23: AP2982-CI3312 | C23: =143730.58+17247.67 -> 160978.25 | D23: =C23/1.12 -> 143730.58 | F23: 44420 | G23: CI3312 | H23: =2874611.49+344953.38 -> 3219564.9 | I23: =H23/1.12 -> 2874611.5
A24: 44439 | B24: AP29982-CI3313 | C24: =145599.11+17471.89 -> 163071 | D24: =C24/1.12 -> 145599.11 | F24: 44426 | G24: CI3313 | H24: =2911981.57+349437.78 -> 3261419.3 | I24: =H24/1.12 -> 2911981.6
A25: 44455 | B25: AP30118-CI3314 | C25: =154565.85+18547.9 -> 173113.75 | D25: =C25/1.12 -> 154565.85 | F25: 44441 | G25: CI3314 | H25: =3091316.38+370957.97 -> 3462274.3 | I25: =H25/1.12 -> 3091316.4
A26: 44463 | B26: AP30179-CI3315 | C26: =114243.97+13709.28 -> 127953.25 | D26: =C26/1.12 -> 114243.97 | F26: 44447 | G26: CI3315 | H26: =2284879.02+274185.49 -> 2559064.5 | I26: =H26/1.12 -> 2284879
A27: 44477 | B27: AP30306-CI3316 | C27: =211887.5+25426.5 -> 237314 | D27: =C27/1.12 -> 211887.5 | F27: 44462 | G27: CI3316 | H27: =4237749.82+508529.99 -> 4746279.8 | I27: =H27/1.12 -> 4237749.8
A28: 44483 | B28: AP30343-CI3318 | C28: =102368.97+12284.28 -> 114653.25 | D28: =C28/1.12 -> 102368.97 | F28: 44468 | G28: CI3318 | H28: =2047379.24+245685.51 -> 2293064.8 | I28: =H28/1.12 -> 2047379.2
A29: 44494 | B29: AP30424-CI3321 | C29: =225429.91+27051.59 -> 252481.5 | D29: =C29/1.12 -> 225429.91 | F29: 44476 | G29: CI3321 | H29: =4508598.83+541031.86 -> 5049630.7 | I29: =H29/1.12 -> 4508598.8
A30: 44510 | B30: AP30235-CI3322 | C30: =179708.93+21565.07 -> 201274 | D30: =C30/1.12 -> 179708.93 | F30: 44496 | G30: CI3322 | H30: =3594178.44+431301.42 -> 4025479.9 | I30: =H30/1.12 -> 3594178.4
A31: 44516 | B31: AP30631-CI3325 | C31: =175314.73+21037.77 -> 196352.5 | D31: =C31/1.12 -> 175314.73 | F31: 44511 | G31: CI3325 | H31: =3506294.5+420755.34 -> 3927049.8 | I31: =H31/1.12 -> 3506294.5
A32: 44539 | B32: AP30846-CI3326 | C32: =222651.79+26718.21 -> 249370 | D32: =C32/1.12 -> 222651.79 | F32: 44526 | G32: CI3326 | H32: =4453035.75+534364.28 -> 4987400 | I32: =H32/1.12 -> 4453035.7
A33: 44561 | B33: AP30970-CI3327 | C33: =187019.2+22442.3 -> 209461.5 | D33: =C33/1.12 -> 187019.2 | F33: 44543 | G33: CI3327 | H33: =3740382.63+448845.91 -> 4189228.5 | I33: =H33/1.12 -> 3740382.6
A34: 44561 | B34: AP30988-CI3328 | C34: =214090.63+25690.88 -> 239781.51 | D34: =C34/1.12 -> 214090.63 | F34: 44551 | G34: CI3328 | H34: =4281811.48+513817.37 -> 4795628.9 | I34: =H34/1.12 -> 4281811.5
A35: 44561 | B35: AP30988-CI3329 | C35: =133764.29+16051.71 -> 149816 | D35: =C35/1.12 -> 133764.29 | F35: 44551 | G35: CI3329 | H35: =2675285.04+321034.2 -> 2996319.2 | I35: =H35/1.12 -> 2675285
A36: 44601 | B36: AP31250-CI3333 | C36: =158620.54+19034.46 -> 177655 | D36: =C36/1.12 -> 158620.54 | F36: 44581 | G36: CI3333 | H36: =653571.75+78428.61+2518837.58+302260.52 -> 3553098.5 | I36: =H36/1.12 -> 3172409.3
A37: 44615 | B37: AP31349-CI3334 | C37: =158037.95+18964.55 -> 177002.5 | D37: =C37/1.12 -> 158037.95 | F37: 44588 | G37: CI3334 | H37: =653572.5+78428.7+2507186.15+300862.85 -> 3540050.2 | I37: =H37/1.12 -> 3160759.1
A38: 44615 | B38: AP31349-CI3335 | C38: =177832.59+21339.91 -> 199172.5 | D38: =C38/1.12 -> 177832.59 | F38: 44595 | G38: CI3335 | H38: =4233795.7+508055.49+653571.75+78428.61 -> 5473851.6 | I38: =H38/1.12 -> 4887367.5
A39: 44615 | B39: AP31349-CI3338 | C39: =372680.8+44721.7 -> 417402.5 | D39: =C39/1.12 -> 372680.8 | F39: 44602 | G39: CI3338/3337 | H39: =1089286.25+130714.35+7695046.28+923405.56 -> 9838452.4 | I39: =H39/1.12 -> 8784332.5
A40: 44624 | B40: AP31452-CI3339 | C40: =304130.58+36495.67 -> 340626.25 | D40: =C40/1.12 -> 304130.58 | F40: 44616 | G40: CI3339/3341 | H40: =1307143.5+156857.22+5806773.83+696812.87 -> 7967587.4 | I40: =H40/1.12 -> 7113917.3
A41: 44638 | B41: AP31591-CI3342 | C41: =214003.35+25680.4 -> 239683.75 | D41: =C41/1.12 -> 214003.35 | F41: 44623 | G41: CI3342/3343 | H41: =1307143.5+156857.22+4603050.22+552366.03 -> 6619417 | I41: =H41/1.12 -> 5910193.7
...

Sheet PURCHASED & SF ANALYSIS
B2: VAT INCLUSIVE
B3: FISCAL YEAR | C3: BUDGET (VAT INCLUSIVE) | E3: ACTUAL PURCHASED | G3: ACTUAL SERVICE FEE | I3: TOTAL PURCHASED | J3: TOTAL SERVICE FEE | K3: VARIANCE PURCHASED | L3: VARIANCE SERVICE FEE | M3: VARIANCE PURCHASED (OVER BUDGET) | O3: VARIANCE SERVICE FEE (OVER BUDGET) | Q3: VARIANCE PURCHASED PERCENTAGE | R3: VARIANCE SERVICE FEE PERCENTAGE | S3: VARIANCE PURCHASED PERCENTAGE (OVER BUDGET) | U3: VARIANCE SERVICE FEE (PERCENTAGE) | W3: PERCENTAGE PURCHASED (OVER BUDGET) | Y3: PERCENTAGE SERVICE FEE (OVER BUDGET)
C4: STOCK | D4: SERVICE FEE | E4: MT. ROCK | F4: EXPEDITION | G4: MT. ROCK | H4: EXPEDITION | M4: MT. ROCK | N4: EXPEDITION | O4: MT. ROCK | P4: EXPEDITION | S4: MT. ROCK | T4: EXPEDITION | U4: MT. ROCK | V4: EXPEDITION | W4: MT. ROCK | X4: EXPEDITION | Y4: MT. ROCK | Z4: EXPEDITION
B5: 2021-2022 | C5: 2.4057859e+08 | D5: =C5*5% -> 12028930 | E5: =SUM('MT.ROCK (PURCHASED & SF)'!H18:H54) -> 57555559 | F5: =SUM('EXPEDITION (PURCHASED & SF)'!H18:H53) -> 1.6480099e+08 | G5: =SUM('MT.ROCK (PURCHASED & SF)'!C17:C48) -> 2848701.4 | H5: =SUM('EXPEDITION (PURCHASED & SF)'!C17:C51) -> 7606941 | I5: =E5+F5 -> 2.2235655e+08 | J5: =G5+H5 -> 10455642 | K5: =C5-I5 -> 18222046 | L5: =D5-J5 -> 1573287.2 | M5: =(C5/2)-E5 -> 62733737 | N5: =(C5/2)-F5 -> -44511691 | O5: =(D5/2)-G5 -> 3165763.4 | P5: =(D5/2)-H5 -> -1592476.2 | Q5: =K5/C5 -> 0.075742591 | R5: =L5/D5 -> 0.13079195 | S5: =M5/(C5/2) -> 0.52152385 | T5: =N5/(C5/2) -> -0.37003867 | U5: =O5/(D5/2) -> 0.52635828 | V5: =P5/(D5/2) -> -0.26477438 | W5: =E5/C5 -> 0.23923807 | X5: =F5/C5 -> 0.68501933 | Y5: =G5/D5 -> 0.23682086 | Z5: =H5/D5 -> 0.63238719
B6: 2022-2023 | C6: 2.7092369e+08 | D6: =C6*5% -> 13546185 | E6: =SUM('MT.ROCK (PURCHASED & SF)'!H55:H83) -> 55708566 | F6: =SUM('EXPEDITION (PURCHASED & SF)'!H54:H82) -> 1.7741011e+08 | G6: =SUM('MT.ROCK (PURCHASED & SF)'!C49:C82) -> 2578030.5 | H6: =SUM('EXPEDITION (PURCHASED & SF)'!C52:C81) -> 9452828.5 | I6: =E6+F6 -> 2.3311868e+08 | J6: =G6+H6 -> 12030859 | K6: =C6-I6 -> 37805013 | L6: =D6-J6 -> 1515325.7 | M6: =(C6/2)-E6 -> 79753280 | N6: =(C6/2)-F6 -> -41948268 | O6: =(D6/2)-G6 -> 4195061.9 | P6: =(D6/2)-H6 -> -2679736.2 | Q6: =K6/C6 -> 0.13954118 | R6: =L6/D6 -> 0.11186365 | S6: =M6/(C6/2) -> 0.58875087 | T6: =N6/(C6/2) -> -0.30966851 | U6: =O6/(D6/2) -> 0.61937172 | V6: =P6/(D6/2) -> -0.39564442 | W6: =E6/C6 -> 0.20562456 | X6: =F6/C6 -> 0.65483425 | Y6: =G6/D6 -> 0.19031414 | Z6: =H6/D6 -> 0.69782221
B7: 2023-2024 | C7: 2.9365232e+08 | D7: =C7*5% -> 14682616 | E7: =SUM('MT.ROCK (PURCHASED & SF)'!H84:H110) -> 50925072 | F7: =SUM('EXPEDITION (PURCHASED & SF)'!H83:H114) -> 1.0726831e+08 | G7: =SUM('MT.ROCK (PURCHASED & SF)'!C83:C110) -> 2729097.4 | H7: =SUM('EXPEDITION (PURCHASED & SF)'!C82:C114) -> 5557550.5 | I7: =E7+F7 -> 1.5819339e+08 | J7: =G7+H7 -> 8286647.9 | K7: =C7-I7 -> 1.3545893e+08 | L7: =D7-J7 -> 6395967.9 | M7: =(C7/2)-E7 -> 95901085 | N7: =(C7/2)-F7 -> 39557845 | O7: =(D7/2)-G7 -> 4612210.5 | P7: =(D7/2)-H7 -> 1783757.4 | Q7: =K7/C7 -> 0.46129018 | R7: =L7/D7 -> 0.43561501 | S7: =M7/(C7/2) -> 0.65316076 | T7: =N7/(C7/2) -> 0.2694196 | U7: =O7/(D7/2) -> 0.62825461 | V7: =P7/(D7/2) -> 0.24297542 | W7: =E7/C7 -> 0.17341962 | X7: =F7/C7 -> 0.3652902 | Y7: =G7/D7 -> 0.1858727 | Z7: =H7/D7 -> 0.37851229
B8: TOTAL | C8: =SUM(C5:C7) -> 8.051546e+08 | D8: =SUM(D5:D7) -> 40257730 | E8: =SUM(E5:E7) -> 1.641892e+08 | F8: =SUM(F5:F7) -> 4.4947941e+08 | G8: =SUM(G5:G7) -> 8155829.3 | H8: =SUM(H5:H7) -> 22617320 | I8: =SUM(I5:I7) -> 6.1366861e+08 | J8: =SUM(J5:J7) -> 30773149 | K8: =C8-I8 -> 1.9148599e+08 | L8: =D8-J8 -> 9484580.7 | M8: =SUM(M5:M7) -> 2.383881e+08 | N8: =SUM(N5:N7) -> -46902114 | O8: =SUM(O5:O7) -> 11973036 | P8: =SUM(P5:P7) -> -2488455 | Q8: =K8/C8 -> 0.23782512 | R8: =L8/D8 -> 0.23559651 | S8: =M8/(C8/2) -> 0.59215485 | T8: =N8/(C8/2) -> -0.11650462 | U8: =O8/(D8/2) -> 0.59481922 | V8: =P8/(D8/2) -> -0.1236262 | W8: =E8/C8 -> 0.20392257 | X8: =F8/C8 -> 0.55825231 | Y8: =G8/D8 -> 0.20259039 | Z8: =H8/D8 -> 0.5618131
B12: VAT EXCLUSIVE
B13: FISCAL YEAR | C13: BUDGET (VAT EXCLUSIVE) | E13: ACTUAL PURCHASED | G13: ACTUAL SERVICE FEE | I13: TOTAL PURCHASED | J13: TOTAL SERVICE FEE | K13: VARIANCE PURCHASED | L13: VARIANCE SERVICE FEE | M13: VARIANCE PURCHASED (OVER BUDGET) | O13: VARIANCE SERVICE FEE (OVER BUDGET) | Q13: VARIANCE PURCHASED PERCENTAGE | R13: VARIANCE SERVICE FEE PERCENTAGE | S13: VARIANCE PURCHASED PERCENTAGE (OVER BUDGET) | U13: VARIANCE SERVICE FEE (PERCENTAGE) | W13: PERCENTAGE PURCHASED (OVER BUDGET) | Y13: PERCENTAGE SERVICE FEE (OVER BUDGET)
C14: STOCK | D14: SERVICE FEE | E14: MT. ROCK | F14: EXPEDITION | G14: MT. ROCK | H14: EXPEDITION | M14: MT. ROCK | N14: EXPEDITION | O14: MT. ROCK | P14: EXPEDITION | S14: MT. ROCK | T14: EXPEDITION | U14: MT. ROCK | V14: EXPEDITION | W14: MT. ROCK | X14: EXPEDITION | Y14: MT. ROCK | Z14: EXPEDITION
B15: 2021-2022 | C15: 2.1480231e+08 | D15: =C15*5% -> 10740116 | E15: =SUM('MT.ROCK (PURCHASED & SF)'!I18:I54) -> 51388892 | F15: =SUM('EXPEDITION (PURCHASED & SF)'!I18:I53) -> 1.4714374e+08 | G15: =SUM('MT.ROCK (PURCHASED & SF)'!D17:D48) -> 2543483.4 | H15: =SUM('EXPEDITION (PURCHASED & SF)'!D17:D51) -> 6791911.6 | I15: =E15+F15 -> 1.9853263e+08 | J15: =G15+H15 -> 9335395.1 | K15: =C15-I15 -> 16269684 | L15: =D15-J15 -> 1404720.7 | M15: =(C15/2)-E15 -> 56012265 | N15: =(C15/2)-F15 -> -39742581 | O15: =(D15/2)-G15 -> 2826574.4 | P15: =(D15/2)-H15 -> -1421853.8 | Q15: =K15/C15 -> 0.075742591 | R15: =L15/D15 -> 0.13079195 | S15: =M15/(C15/2) -> 0.52152385 | T15: =N15/(C15/2) -> -0.37003867 | U15: =O15/(D15/2) -> 0.52635828 | V15: =P15/(D15/2) -> -0.26477438 | W15: =E15/C15 -> 0.23923807 | X15: =F15/C15 -> 0.68501933 | Y15: =G15/D15 -> 0.23682086 | Z15: =H15/D15 -> 0.63238719
B16: 2022-2023 | C16: 2.4189615e+08 | D16: =C16*5% -> 12094808 | E16: =SUM('MT.ROCK (PURCHASED & SF)'!I55:I83) -> 49739791 | F16: =SUM('EXPEDITION (PURCHASED & SF)'!I54:I82) -> 1.5840189e+08 | G16: =SUM('MT.ROCK (PURCHASED & SF)'!D49:D82) -> 2301812.9 | H16: =SUM('EXPEDITION (PURCHASED & SF)'!D52:D81) -> 8440025.5 | I16: =E16+F16 -> 2.0814168e+08 | J16: =G16+H16 -> 10741838 | K16: =C16-I16 -> 33754476 | L16: =D16-J16 -> 1352969.3 | M16: =(C16/2)-E16 -> 71208286 | N16: =(C16/2)-F16 -> -37453810 | O16: =(D16/2)-G16 -> 3745591 | P16: =(D16/2)-H16 -> -2392621.6 | Q16: =K16/C16 -> 0.13954118 | R16: =L16/D16 -> 0.11186365 | S16: =M16/(C16/2) -> 0.58875087 | T16: =N16/(C16/2) -> -0.30966851 | U16: =O16/(D16/2) -> 0.61937172 | V16: =P16/(D16/2) -> -0.39564442 | W16: =E16/C16 -> 0.20562456 | X16: =F16/C16 -> 0.65483425 | Y16: =G16/D16 -> 0.19031414 | Z16: =H16/D16 -> 0.69782221
B17: 2023-2024 | C17: 2.6218957e+08 | D17: =C17*5% -> 13109478 | E17: =SUM('MT.ROCK (PURCHASED & SF)'!I84:I110) -> 45468815 | F17: =SUM('EXPEDITION (PURCHASED & SF)'!I83:I114) -> 95775280 | G17: =SUM('MT.ROCK (PURCHASED & SF)'!D83:D110) -> 2436694.1 | H17: =SUM('EXPEDITION (PURCHASED & SF)'!D82:D114) -> 4962098.7 | I17: =E17+F17 -> 1.4124409e+08 | J17: =G17+H17 -> 7398792.8 | K17: =C17-I17 -> 1.2094547e+08 | L17: =D17-J17 -> 5710685.6 | M17: =(C17/2)-E17 -> 85625969 | N17: =(C17/2)-F17 -> 35319504 | O17: =(D17/2)-G17 -> 4118045.1 | P17: =(D17/2)-H17 -> 1592640.5 | Q17: =K17/C17 -> 0.46129018 | R17: =L17/D17 -> 0.43561501 | S17: =M17/(C17/2) -> 0.65316076 | T17: =N17/(C17/2) -> 0.2694196 | U17: =O17/(D17/2) -> 0.62825461 | V17: =P17/(D17/2) -> 0.24297542 | W17: =E17/C17 -> 0.17341962 | X17: =F17/C17 -> 0.3652902 | Y17: =G17/D17 -> 0.1858727 | Z17: =H17/D17 -> 0.37851229
B18: TOTAL | C18: =SUM(C15:C17) -> 7.1888804e+08 | D18: =SUM(D15:D17) -> 35944402 | E18: =SUM(E15:E17) -> 1.465975e+08 | F18: =SUM(F15:F17) -> 4.0132091e+08 | G18: =SUM(G15:G17) -> 7281990.4 | H18: =SUM(H15:H17) -> 20194036 | I18: =SUM(I15:I17) -> 5.479184e+08 | J18: =SUM(J15:J17) -> 27476026 | K18: =C18-I18 -> 1.7096963e+08 | L18: =D18-J18 -> 8468375.6 | M18: =SUM(M15:M17) -> 2.1284652e+08 | N18: =SUM(N15:N17) -> -41876888 | O18: =SUM(O15:O17) -> 10690210 | P18: =SUM(P15:P17) -> -2221834.9 | Q18: =K18/C18 -> 0.23782512 | R18: =L18/D18 -> 0.23559651 | S18: =M18/(C18/2) -> 0.59215485 | T18: =N18/(C18/2) -> -0.11650462 | U18: =O18/(D18/2) -> 0.59481922 | V18: =P18/(D18/2) -> -0.1236262 | W18: =E18/C18 -> 0.20392257 | X18: =F18/C18 -> 0.55825231 | Y18: =G18/D18 -> 0.20259039 | Z18: =H18/D18 -> 0.5618131

Sheet BUDGET VS USAGE ANALYSIS
B3: 2023-2024 BUDGET | C3: 2023-2024 ACTUAL COST (As May 1) | D3: AVERAGE MONTHLY COST (From July 23-April 24) | E3: VARIANCE (As of December 1, 2024) | F3: SOH OF EXPEDITION (As of MAY 31, 2026) | G3: SOH OF MT. ROCK (MAY 31, 2026) | H3: SOH OF PMC AT MINE SITE (As of MAY 31, 2026) | I3: SOH OF PMC AND SUPPLIER (As of MAY 31,2026)
B4: =C12 -> 2.9365232e+08 | C4: ='MONTHLY COST'!U7 -> 2.1059274e+08 | D4: ='MONTHLY COST'!C8 -> 16199442 | E4: =B4-C4 -> 83059575 | F4: ='EXPEDITION '!H26 -> 68394082 | G4: =MT.ROCK!H18 -> 1488041.2 | H4: ='INVENTORY-MAY'!AV32 -> 31451671 | I4: =F4+G4+H4 -> 1.0133379e+08
B6: 2023-2024 BUDGET | C6: ESTIMATED TOTAL COST on July 1, 2024 | D6: ESTIMATED AVERAGE MONTHLY COST (From July 23-June 24) | E6: ESTIMATED VARIANCE on July 1, 2024 | F6: ESTIMATED SOH OF EXPEDITION on July 1, 2024 | G6: ESTIMATED SOH OF MT. ROCK on July 1, 2024
B7: =C12 -> 2.9365232e+08 | C7: =(C4+D7+D7) -> 2.4299162e+08 | D7: =D4 -> 16199442 | E7: =B7-C7 -> 50660691 | F7: =F4-(D7/2) -> 60294361 | G7: =G4-(D7/2) -> -6611679.6
B11: 2023-2024 BUDGET | C11: 2.6218957e+08 | D11: VAT EXCLUSIVE
C12: =C11+(C11*12%) -> 2.9365232e+08 | D12: VAT INCLUSIVE

Sheet MONTHLY COST
C3: JULY | D3: AUGUST | E3: SEPTEMBER | F3: OCTOBER | G3: NOVEMBER | H3: DECEMBER | I3: JANUARY | J3: FEBRUARY | K3: MARCH | L3: APRIL | M3: MAY | N3: JUNE | O3: JULY | P3: AUGUST | Q3: SEPTEMBER | R3: OCTOBER | S3: NOVEMBER | T3: DECEMBER | U3: TOTAL
B4: MINES | C4: 23482638 | D4: 20074334 | E4: 17770864 | F4: 17764002 | G4: 18199294 | H4: 6077470.5 | I4: 12565355 | J4: 15490003 | K4: 12563498 | L4: 14517292 | M4: 14174044 | N4: 15446444 | O4: 17354880 | U4: =SUM(C4:T4) -> 2.0548012e+08
B5: TIGERWAY | D5: 113291.3 | E5: 125798.94 | H5: 76438.06 | I5: 312951.71 | J5: 239744.38 | K5: 125298.98 | L5: 236620.18 | M5: 345838.47 | N5: 90171.48 | U5: =SUM(C5:T5) -> 1666153.5
B6: RCV PROJECT | C6: 19540.1 | D6: 111430.86 | E6: 119482.66 | F6: 405319.77 | G6: 223081.6 | H6: 163595.25 | I6: 256777.86 | J6: 234803.02 | K6: 260112.71 | L6: 357097.01 | M6: 208625.66 | N6: 589204.35 | O6: 497397.35 | U6: =SUM(C6:T6) -> 3446468.2
B7: TOTAL | C7: =SUM(C4:C6) -> 23502179 | D7: =SUM(D4:D6) -> 20299056 | E7: =SUM(E4:E6) -> 18016145 | F7: =SUM(F4:F6) -> 18169322 | G7: =SUM(G4:G6) -> 18422375 | H7: =SUM(H4:H6) -> 6317503.8 | I7: =SUM(I4:I6) -> 13135084 | J7: =SUM(J4:J6) -> 15964551 | ... O7: =SUM(O4:O6) -> 17852277 | U7: =SUM(U4:U6) -> 2.1059274e+08
B8: AVERAGE | C8: =AVERAGEA(C7:O7) -> 16199442

Sheet SOH-MAY
BL3: =SUMIF(BL11:BL33,"<0",BL11:BL34) -> -12078.02 | BM3: =SUMIF(BM11:BM33,"<0",BM11:BM34) -> -1124666.5
BL4: =SUMIF(BL11:BL33,">0",BL11:BL34) -> 5095.52 | BM4: =SUMIF(BM11:BM33,">0",BM11:BM34) -> 183245.94
BL5: =SUM(BL3:BL4) -> -6982.5 | BM5: =SUM(BM3:BM4) -> -941420.61
A6: EXPLOSIVES STOCK ON HAND/COSTING AS OF MAY 31, 2026
A7: 3
I8: DAILY ISSUANCE | AP8: ACTUAL COUNT SURFACE & UNDERGROUND | BC8: DELIVERIES | BG8: BARROWED MT. ROCK | BI8: LOGBOOK | BL8: VARIANCE | BO8: EXPLOSIVES ISSUANCE COSTING -DAILY | CT8: TOTAL COST
A9: DESCRIPTION | B9: UoM | C9: NEW PRICE 2025-2027 | D9: STOCK CODE | E9: EXPLOSIVES SOH APRIL 30, 2026 | G9: FOR DISPOSAL -SOH | I9: 46143 | J9: 46144 | K9: 46145 | L9: 46146 | M9: 46147 | N9: 46148 | O9: 46149 | P9: 46150 | Q9: 46151 | R9: 46152 | S9: 46153 | T9: 46154 | U9: 46155 | V9: 46156 | W9: 46157 | X9: 46158 | Y9: 46159 | Z9: 46160 | AA9: 46161 | AB9: 46162 | AC9: 46163 | AD9: 46164 | AE9: 46165 | AF9: 46166 | AG9: 46167 | AH9: 46168 | AI9: 46169 | AJ9: 46170 | AK9: 46171 | AL9: 46172 | AM9: 46173 | AN9: MONTHLY CONSUMPTION | AO9: MONTHLY COSTING | AP9: SURFACE AS OF MAY 31 2026 | AQ9: SINUG-ANG | AR9: MARATHON 3150 | AS9: L-5 | AT9: L-7 | AU9: L-8 | AV9: L-9 | AW9: L-10 | AX9: L-11 | AY9: L-12 | AZ9: L425 | BA9: UNDERGROUND AS OF MAY 31, 2026 | BB9: TOTAL QTY | BC9: 46162 | BD9: 46168 | BI9: REMAINING SOH AS MAY 31, 2026 | BJ9: TOTAL COST AS OF MAY 31,2026 | BO9: =I9 -> 46143 | BP9: =J9 -> 46144 | BQ9: =K9 -> 46145 | BR9: =L9 -> 46146 | BS9: =M9 -> 46147 | BT9: =N9 -> 46148 | BU9: =O9 -> 46149 | BV9: =P9 -> 46150 | ... CS9: =AM9 -> 46173
E10: QUANTITY | F10: COSTING | G10: QUANTITY | H10: COSTING | I10: QUANTITY | J10: QUANTITY | K10: QUANTITY | L10: QUANTITY | M10: QUANTITY | N10: QUANTITY | O10: QUANTITY | P10: QUANTITY | Q10: QUANTITY | R10: QUANTITY | S10: QUANTITY | T10: QUANTITY | U10: QUANTITY | V10: QUANTITY | W10: QUANTITY | X10: QUANTITY | Y10: QUANTITY | Z10: QUANTITY | AA10: QUANTITY | AB10: QUANTITY | AC10: QUANTITY | AD10: QUANTITY | AE10: QUANTITY | AF10: QUANTITY | AG10: QUANTITY | AH10: QUANTITY | AI10: QUANTITY | AJ10: QUANTITY | AK10: QUANTITY | AL10: QUANTITY | AM10: QUANTITY | AN10: QUANTITY | AO10: QUANTITY | AP10: QUANTITY | AQ10: QUANTITY | AR10: QUANTITY | AS10: QUANTITY | AT10: QUANTITY | AU10: QUANTITY | AV10: QUANTITY | AW10: QUANTITY | AX10: QUANTITY | AY10: QUANTITY | AZ10: QUANTITY | BA10: QUANTITY | BB10: QUANTITY | BC10: QUANTITY | BD10: QUANTITY | BE10: QUANTITY | BF10: QUANTITY | BG10: QUANTITY | BH10: QUANTITY | BI10: QUANTITY | BJ10: COSTING | BL10: QUANTITY | BM10: AMOUNT | BO10: FRI | BP10: SAT | BQ10: SUN | BR10: MON | BS10: TUE | BT10: WED | BU10: THU | BV10: FRI | BW10: SAT | BX10: SUN | BY10: MON | BZ10: TUE | CA10: WED | CB10: THU | CC10: FRI | CD10: SAT | CE10: SUN | CF10: MON | CG10: TUE | CH10: WED | CI10: THU | CJ10: FRI | CK10: SAT | CL10: SUN | CM10: MON | CN10: TUE | CO10: WED | CP10: THU | CQ10: FRI | CR10: SAT | CS10: SUN
A11: EM AUSTINE 200 | B11: PCS | C11: 26.2921 | E11: 0 | F11: 0 | J11: 0 | K11: 0 | L11: 0 | M11: 0 | N11: 0 | O11: 0 | P11: 0 | Q11: 0 | R11: 0 | S11: 0 | T11: 0 | U11: 0 | V11: 0 | W11: 0 | X11: 0 | Y11: 0 | Z11: 0 | AA11: 0 | AB11: 0 | AC11: 0 | AD11: 0 | AE11: 0 | AF11: 0 | AG11: 0 | AH11: 0 | AI11: 0 | AJ11: 0 | AK11: 0 | AL11: 0 | AM11: 0 | AN11: =SUM(I11:AM11) -> 0 | AO11: =C11*AN11 -> 0 | BA11: =SUM(AQ11:AY11) -> 0 | BB11: =BA11+AP11 -> 0 | BI11: =E11-I11-J11-K11-L11-M11-N11-O11-P11-Q11-R11-S11-T11-U11-V11-Y11-W11-Z11-AA11-AB11-AC11-AD11-AE11-AF11-AG11-AH11-AI11-AJ11-AK11-AM11-X11-AL11+BC11+BE11+BD11+BF11 -> 0 | BJ11: =BI11*C11 -> 0 | BL11: =BB11-BI11 -> 0 | BM11: =BL11*C11 -> 0 | BO11: =I11*C11 -> 0 | BP11: =J11*C11 -> 0 | BQ11: =K11*C11 -> 0 | BR11: =L11*C11 -> 0 | BS11: =M11*C11 -> 0 | BT11: =N11*C11 -> 0 | BU11: =O11*C11 -> 0 | BV11: =P11*C11 -> 0 | BW11: =Q11*C11 -> 0 | BX11: =R11*C11 -> 0 | BY11: =S11*C11 -> 0 | BZ11: =T11*C11 -> 0 | CA11: =U11*C11 -> 0 | CB11: =V11*C11 -> 0 | CC11: =W11*C11 -> 0 | CD11: =X11*C11 -> 0 | CE11: =C11*Y11 -> 0 | CF11: =C11*Z11 -> 0 | CG11: =AA11*C11 -> 0 | CH11: =C11*AB11 -> 0 | CI11: =C11*AC11 -> 0 | CJ11: =C11*AD11 -> 0 | CL11: =C11*AF11 -> 0 | CM11: =C11*AG11 -> 0 | CN11: =C11*AH11 -> 0 | CO11: =C11*AI11 -> 0 | CP11: =C11*AJ11 -> 0 | CQ11: =C11*AK11 -> 0 | CR11: =C11*AL11 -> 0 | CS11: =C11*AM11 -> 0
A12: DYNA NEOGEL 200 | B12: PCS | C12: 27.3438 | D12: 35245 | E12: 38714 | F12: 1559389.6 | J12: 1307 | K12: 1453 | L12: 1895 | M12: 1665 | N12: 2165 | O12: 1665 | P12: 1983 | Q12: 1996 | R12: 1611 | S12: 1697 | T12: 1731 | U12: 1811 | V12: 1339 | W12: 1513 | X12: 1192 | Y12: 1434 | Z12: 1427 | AA12: 1674 | AB12: 1779 | AC12: 1679 | AD12: 1676 | AE12: 1461 | AF12: 448 | AG12: 183 | AH12: 1626 | AI12: 1432 | AJ12: 1848 | AK12: 1795 | AL12: 1347 | AM12: 1532 | AN12: =SUM(I12:AM12) -> 46364 | AO12: =C12*AN12 -> 1267767.9 | AP12: 8000 | AY12: 9661 | AZ12: 4052 | BA12: =SUM(AQ12:AZ12) -> 13713 | BB12: =BA12+AP12 -> 21713 | BC12: 20000 | BD12: 15000 | BI12: =E12-I12-J12-K12-L12-M12-N12-O12-P12-Q12-R12-S12-T12-U12-V12-Y12-W12-Z12-AA12-AB12-AC12-AD12-AE12-AF12-AG12-AH12-AI12-AJ12-AK12-AM12-X12-AL12+BC12+BE12+BD12+BF12 -> 27350 | BJ12: =BI12*C12 -> 747852.93 | BL12: =BB12-BI12 -> -5637 | BM12: =BL12*C12 -> -154137 | BO12: =I12*C12 -> 0 | BP12: =J12*C12 -> 35738.347 | BQ12: =K12*C12 -> 39730.541 | BR12: =L12*C12 -> 51816.501 | BS12: =M12*C12 -> 45527.427 | BT12: =N12*C12 -> 59199.327 | BU12: =O12*C12 -> 45527.427 | BV12: =P12*C12 -> 54222.755 | BW12: =Q12*C12 -> 54578.225 | BX12: =R12*C12 -> 44050.862 | BY12: =S12*C12 -> 46402.429 | BZ12: =T12*C12 -> 47332.118 | CA12: =U12*C12 -> 49519.622 | CB12: =V12*C12 -> 36613.348 | CC12: =W12*C12 -> 41371.169 | CD12: =X12*C12 -> 32593.81 | CE12: =C12*Y12 -> 39211.009 | CF12: =C12*Z12 -> 39019.603 | CG12: =AA12*C12 -> 45773.521 | CH12: =C12*AB12 -> 48644.62 | CI12: =C12*AC12 -> 45910.24 | CJ12: =C12*AD12 -> 45828.209 | CK12: =C12*AE12 -> 39949.292 | CL12: =C12*AF12 -> 12250.022 | CM12: =C12*AG12 -> 5003.9154 | CN12: =C12*AH12 -> 44461.019 | CO12: =C12*AI12 -> 39156.322 | CP12: =C12*AJ12 -> 50531.342 | CQ12: =C12*AK12 -> 49082.121 | CR12: =C12*AL12 -> 36832.099 | CS12: =C12*AM12 -> 41890.702 | CT12: =SUM(BO12:CS12) -> 1267767.9 | CU12: =CT12+CT13+CT14+CT15+CT16+CT17+CT18+CT19+CT20+CT21+CT22+CT23+CT24+CT25+CT28+CT29+CT30+CT31+CT32+CT33 -> 17329054
A13: DYNAPULSAR 215 | B13: PCS | C13: 29.5639 | D13: 11082 | E13: 105602 | F13: 3595650.2 | J13: 822 | K13: 1065 | L13: 1552 | M13: 1323 | N13: 1186 | O13: 1103 | P13: 956 | Q13: 1172 | R13: 811 | S13: 1404 | T13: 1752 | U13: 1617 | V13: 1490 | W13: 926 | X13: 1081 | Y13: 1084 | Z13: 1052 | AA13: 1463 | AB13: 1644 | AC13: 1069 | AD13: 1302 | AE13: 2070 | AF13: 2127 | AG13: 2846 | AH13: 1591 | AI13: 2436 | AJ13: 1278 | AK13: 1503 | AL13: 1622 | AM13: 876 | AN13: =SUM(I13:AM13) -> 42223 | AO13: =C13*AN13 -> 1248276.5 | AP13: 59770 | AR13: 502 | AT13: 3690 | AU13: 14589 | AV13: 11133 | AW13: 9326 | AY13: 3655 | AZ13: 0 | BA13: =SUM(AQ13:AZ13) -> 42895 | BB13: =BA13+AP13 -> 102665 | BC13: 21500 | BD13: 16125 | BI13: =E13-I13-J13-K13-L13-M13-N13-O13-P13-Q13-R13-S13-T13-U13-V13-Y13-W13-Z13-AA13-AB13-AC13-AD13-AE13-AF13-AG13-AH13-AI13-AJ13-AK13-AM13-X13-AL13+BC13+BE13+BD13+BF13 -> 101004 | BJ13: =BI13*C13 -> 2986072.2 | BL13: =BB13-BI13 -> 1661 | BM13: =BL13*C13 -> 49105.638 | BO13: =I13*C13 -> 0 | BP13: =J13*C13 -> 24301.526 | BQ13: =K13*C13 -> 31485.554 | BR13: =L13*C13 -> 45883.173 | BS13: =M13*C13 -> 39113.04 | BT13: =N13*C13 -> 35062.785 | BU13: =O13*C13 -> 32608.982 | BV13: =P13*C13 -> 28263.088 | BW13: =Q13*C13 -> 34648.891 | BX13: =R13*C13 -> 23976.323 | BY13: =S13*C13 -> 41507.716 | BZ13: =T13*C13 -> 51795.953 | CA13: =U13*C13 -> 47804.826 | CB13: =V13*C13 -> 44050.211 | CC13: =W13*C13 -> 27376.171 | CD13: =X13*C13 -> 31958.576 | CE13: =C13*Y13 -> 32047.268 | CF13: =C13*Z13 -> 31101.223 | CG13: =AA13*C13 -> 43251.986 | CH13: =C13*AB13 -> 48603.052 | CI13: =C13*AC13 -> 31603.809 | CJ13: =C13*AD13 -> 38492.198 | CK13: =C13*AE13 -> 61197.273 | CL13: =C13*AF13 -> 62882.415 | CM13: =C13*AG13 -> 84138.859 | CN13: =C13*AH13 -> 47036.165 | CO13: =C13*AI13 -> 72017.66 | CP13: =C13*AJ13 -> 37782.664 | CQ13: =C13*AK13 -> 44434.542 | CR13: =C13*AL13 -> 47952.646 | CS13: =C13*AM13 -> 25897.976 | CT13: =SUM(BO13:CS13) -> 1248276.5
A14: ANFO | B14: KLS | C14: 145.88 | D14: 10128 | E14: 94798.32 | F14: 10136193 | J14: 667 | K14: 757 | L14: 1183 | M14: 1201.2 | N14: 1224 | O14: 1035.2 | P14: 1041.2 | Q14: 1028.8 | R14: 897.6 | S14: 1179 | T14: 1151.2 | U14: 1137.2 | V14: 974.6 | W14: 826.6 | X14: 757.4 | Y14: 799.5 | Z14: 988.2 | AA14: 1145.8 | AB14: 1254 | AC14: 1045 | AD14: 1166.6 | AE14: 1117.8 | AF14: 980.6 | AG14: 1160.4 | AH14: 1111.2 | AI14: 1256.4 | AJ14: 1243.8 | AK14: 939 | AL14: 915.8 | AM14: 776.4 | AN14: =SUM(I14:AM14) -> 30961.5 | AO14: =C14*AN14 -> 4516663.6 | AP14: 67600 | AR14: 195.2 | AT14: 263 | AU14: 3969 | AV14: 1436.2 | AW14: 2042.8 | AY14: 2702.6 | AZ14: 1722 | BA14: =SUM(AQ14:AZ14) -> 12330.8 | BB14: =BA14+AP14 -> 79930.8 | BC14: =350*25 -> 8750 | BD14: =350*25 -> 8750 | BI14: =E14-I14-J14-K14-L14-M14-N14-O14-P14-Q14-R14-S14-T14-U14-V14-Y14-W14-Z14-AA14-AB14-AC14-AD14-AE14-AF14-AG14-AH14-AI14-AJ14-AK14-AM14-X14-AL14+BC14+BE14+BD14+BF14 -> 81336.82 | BJ14: =BI14*C14 -> 11865415 | BL14: =BB14-BI14 -> -1406.02 | BM14: =BL14*C14 -> -205110.2 | BO14: =I14*C14 -> 0 | BP14: =J14*C14 -> 97301.96 | BQ14: =K14*C14 -> 110431.16 | BR14: =L14*C14 -> 172576.04 | BS14: =M14*C14 -> 175231.06 | BT14: =N14*C14 -> 178557.12 | BU14: =O14*C14 -> 151014.98 | BV14: =P14*C14 -> 151890.26 | BW14: =Q14*C14 -> 150081.34 | BX14: =R14*C14 -> 130941.89 | BY14: =S14*C14 -> 171992.52 | BZ14: =T14*C14 -> 167937.06 | CA14: =U14*C14 -> 165894.74 | CB14: =V14*C14 -> 142174.65 | CC14: =W14*C14 -> 120584.41 | CD14: =X14*C14 -> 110489.51 | CE14: =C14*Y14 -> 116631.06 | CF14: =C14*Z14 -> 144158.62 | CG14: =AA14*C14 -> 167149.3 | CH14: =C14*AB14 -> 182933.52 | CI14: =C14*AC14 -> 152444.6 | CJ14: =C14*AD14 -> 170183.61 | CK14: =C14*AE14 -> 163064.66 | CL14: =C14*AF14 -> 143049.93 | CM14: =C14*AG14 -> 169279.15 | CN14: =C14*AH14 -> 162101.86 | CO14: =C14*AI14 -> 183283.63 | CP14: =C14*AJ14 -> 181445.54 | CQ14: =C14*AK14 -> 136981.32 | CR14: =C14*AL14 -> 133596.9 | CS14: =C14*AM14 -> 113261.23 | CT14: =SUM(BO14:CS14) -> 4516663.6
A15: S/FUSE | B15: MTR | C15: 27.66 | D15: 12487 | E15: 23542.47 | F15: 779447.18 | J15: 240.57 | K15: 323.19 | L15: 447.12 | M15: 434.97 | N15: 425.25 | O15: 388.8 | P15: 391.23 | Q15: 413.1 | R15: 330.48 | S15: 464.13 | T15: 422.82 | U15: 456.84 | V15: 349.92 | W15: 332.91 | X15: 313.47 | Y15: 345.06 | Z15: 405.81 | AA15: 417.96 | AB15: 500.58 | AC15: 410.67 | AD15: 447.12 | AE15: 444.69 | AF15: 371.79 | AG15: 432.54 | AH15: 422.82 | AI15: 476.28 | AJ15: 490.86 | AK15: 510.3 | AL15: 425.25 | AM15: 318.33 | AN15: =SUM(I15:AM15) -> 12154.86 | AO15: =C15*AN15 -> 336203.43 | AP15: 15682.5 | AR15: =AR16*2.43 -> 546.75 | AS15: =AS16*2.43 -> 0 | AT15: =AT16*2.43 -> 422.82 | AU15: =AU16*2.43 -> 1873.53 | AV15: =AV16*2.43 -> 993.87 | AW15: =AW16*2.43 -> 879.66 | AX15: =AX16*2.43 -> 0 | AY15: =AY16*2.43 -> 1025.46 | AZ15: =AZ16*2.43 -> 189.54 | BA15: =SUM(AQ15:AZ15) -> 5931.63 | BB15: =BA15+AP15 -> 21614.13 | BC15: 4000 | BD15: 4000 | BI15: =E15-I15-J15-K15-L15-M15-N15-O15-P15-Q15-R15-S15-T15-U15-V15-Y15-W15-Z15-AA15-AB15-AC15-AD15-AE15-AF15-AG15-AH15-AI15-AJ15-AK15-AM15-X15-AL15+BC15+BE15+BD15+BF15 -> 19387.61 | BJ15: =BI15*C15 -> 536261.29 | BL15: =BB15-BI15 -> 2226.52 | BM15: =BL15*C15 -> 61585.543 | BO15: =I15*C15 -> 0 | BP15: =J15*C15 -> 6654.1662 | BQ15: =K15*C15 -> 8939.4354 | BR15: =L15*C15 -> 12367.339 | BS15: =M15*C15 -> 12031.27 | BT15: =N15*C15 -> 11762.415 | BU15: =O15*C15 -> 10754.208 | BV15: =P15*C15 -> 10821.422 | BW15: =Q15*C15 -> 11426.346 | BX15: =R15*C15 -> 9141.0768 | BY15: =S15*C15 -> 12837.836 | BZ15: =T15*C15 -> 11695.201 | CA15: =U15*C15 -> 12636.194 | CB15: =V15*C15 -> 9678.7872 | CC15: =W15*C15 -> 9208.2906 | CD15: =X15*C15 -> 8670.5802 | CE15: =C15*Y15 -> 9544.3596 | CF15: =C15*Z15 -> 11224.705 | CG15: =AA15*C15 -> 11560.774 | CH15: =C15*AB15 -> 13846.043 | CI15: =C15*AC15 -> 11359.132 | CJ15: =C15*AD15 -> 12367.339 | CK15: =C15*AE15 -> 12300.125 | CL15: =C15*AF15 -> 10283.711 | CM15: =C15*AG15 -> 11964.056 | CN15: =C15*AH15 -> 11695.201 | CO15: =C15*AI15 -> 13173.905 | CP15: =C15*AJ15 -> 13577.188 | CQ15: =C15*AK15 -> 14114.898 | CR15: =C15*AL15 -> 11762.415 | CS15: =C15*AM15 -> 8805.0078 | CT15: =SUM(BO15:CS15) -> 336203.43
A16: OBC | B16: PCS | C16: 26.25 | D16: 11966 | E16: 7429 | F16: 328282.5 | J16: 99 | K16: 133 | L16: 184 | M16: 179 | N16: 175 | O16: 160 | P16: 161 | Q16: 170 | R16: 136 | S16: 191 | T16: 174 | U16: 188 | V16: 144 | W16: 137 | X16: 129 | Y16: 142 | Z16: 167 | AA16: 172 | AB16: 206 | AC16: 169 | AD16: 184 | AE16: 183 | AF16: 153 | AG16: 178 | AH16: 174 | AI16: 196 | AJ16: 202 | AK16: 210 | AL16: 175 | AM16: 131 | AN16: =SUM(I16:AM16) -> 5002 | AO16: =C16*AN16 -> 131302.5 | AP16: 4550 | AR16: 225 | AT16: 174 | AU16: 771 | AV16: 409 | AW16: 362 | AY16: 422 | AZ16: 78 | BA16: =SUM(AQ16:AZ16) -> 2441 | BB16: =BA16+AP16 -> 6991 | BC16: 3000 | BD16: 2000 | BI16: =E16-I16-J16-K16-L16-M16-N16-O16-P16-Q16-R16-S16-T16-U16-V16-Y16-W16-Z16-AA16-AB16-AC16-AD16-AE16-AF16-AG16-AH16-AI16-AJ16-AK16-AM16-X16-AL16+BC16+BE16+BD16+BF16 -> 7427 | BJ16: =BI16*C16 -> 194958.75 | BL16: =BB16-BI16 -> -436 | BM16: =BL16*C16 -> -11445 | BO16: =I16*C16 -> 0 | BP16: =J16*C16 -> 2598.75 | BQ16: =K16*C16 -> 3491.25 | BR16: =L16*C16 -> 4830 | BS16: =M16*C16 -> 4698.75 | BT16: =N16*C16 -> 4593.75 | BU16: =O16*C16 -> 4200 | BV16: =P16*C16 -> 4226.25 | BW16: =Q16*C16 -> 4462.5 | BX16: =R16*C16 -> 3570 | BY16: =S16*C16 -> 5013.75 | BZ16: =T16*C16 -> 4567.5 | CA16: =U16*C16 -> 4935 | CB16: =V16*C16 -> 3780 | CC16: =W16*C16 -> 3596.25 | CD16: =X16*C16 -> 3386.25 | CE16: =C16*Y16 -> 3727.5 | CF16: =C16*Z16 -> 4383.75 | CG16: =AA16*C16 -> 4515 | CH16: =C16*AB16 -> 5407.5 | CI16: =C16*AC16 -> 4436.25 | CJ16: =C16*AD16 -> 4830 | CK16: =C16*AE16 -> 4803.75 | CL16: =C16*AF16 -> 4016.25 | CM16: =C16*AG16 -> 4672.5 | CN16: =C16*AH16 -> 4567.5 | CO16: =C16*AI16 -> 5145 | CP16: =C16*AJ16 -> 5302.5 | CQ16: =C16*AK16 -> 5512.5 | CR16: =C16*AL16 -> 4593.75 | CS16: =C16*AM16 -> 3438.75 | CT16: =SUM(BO16:CS16) -> 131302.5
A17: F/LIGHTER | B17: PCS | C17: 20.62 | D17: 11342 | E17: 275 | F17: 5691.12 | J17: 0 | K17: 0 | L17: 0 | M17: 0 | N17: 0 | O17: 0 | P17: 0 | Q17: 0 | R17: 0 | S17: 0 | T17: 0 | U17: 0 | V17: 0 | W17: 0 | X17: 0 | Y17: 0 | Z17: 0 | AA17: 0 | AB17: 0 | AC17: 0 | AD17: 0 | AE17: 0 | AF17: 0 | AG17: 0 | AH17: 0 | AI17: 0 | AJ17: 0 | AK17: 0 | AL17: 0 | AM17: 0 | AN17: =SUM(I17:AM17) -> 0 | AO17: =C17*AN17 -> 0 | AP17: 150 | AR17: 38 | AW17: 87 | BA17: =SUM(AQ17:AZ17) -> 125 | BB17: =BA17+AP17 -> 275 | BI17: =E17-I17-J17-K17-L17-M17-N17-O17-P17-Q17-R17-S17-T17-U17-V17-Y17-W17-Z17-AA17-AB17-AC17-AD17-AE17-AF17-AG17-AH17-AI17-AJ17-AK17-AM17-X17-AL17+BC17+BE17+BD17+BF17 -> 275 | BJ17: =BI17*C17 -> 5670.5 | BL17: =BB17-BI17 -> 0 | BM17: =BL17*C17 -> 0 | BO17: =I17*C17 -> 0 | BP17: =J17*C17 -> 0 | BQ17: =K17*C17 -> 0 | BR17: =L17*C17 -> 0 | BS17: =M17*C17 -> 0 | BT17: =N17*C17 -> 0 | BU17: =O17*C17 -> 0 | BV17: =P17*C17 -> 0 | BW17: =Q17*C17 -> 0 | BX17: =R17*C17 -> 0 | BY17: =S17*C17 -> 0 | BZ17: =T17*C17 -> 0 | CA17: =U17*C17 -> 0 | CB17: =V17*C17 -> 0 | CC17: =W17*C17 -> 0 | CD17: =X17*C17 -> 0 | CE17: =C17*Y17 -> 0 | CF17: =C17*Z17 -> 0 | CG17: =AA17*C17 -> 0 | CH17: =C17*AB17 -> 0 | CI17: =C17*AC17 -> 0 | CJ17: =C17*AD17 -> 0 | CK17: =C17*AE17 -> 0 | CL17: =C17*AF17 -> 0 | CM17: =C17*AG17 -> 0 | CN17: =C17*AH17 -> 0 | CO17: =C17*AI17 -> 0 | CP17: =C17*AJ17 -> 0 | CQ17: =C17*AK17 -> 0 | CR17: =C17*AL17 -> 0 | CS17: =C17*AM17 -> 0 | CT17: =SUM(BO17:CS17) -> 0
A18: NONEL 2.4 | B18: PCS | C18: 171.74107 | D18: 10962 | E18: 0 | F18: 0 | G18: 264 | H18: =G18*C18 -> 45339.643 | J18: 0 | K18: 0 | L18: 0 | M18: 0 | N18: 0 | O18: 0 | P18: 0 | Q18: 0 | R18: 0 | S18: 0 | T18: 0 | U18: 0 | V18: 0 | W18: 0 | X18: 0 | Y18: 0 | Z18: 0 | AA18: 0 | AB18: 0 | AC18: 0 | AD18: 0 | AE18: 0 | AF18: 0 | AG18: 0 | AH18: 0 | AI18: 0 | AJ18: 0 | AK18: 0 | AL18: 0 | AM18: 0 | AN18: =SUM(I18:AM18) -> 0 | AO18: =C18*AN18 -> 0 | AP18: 0 | BA18: =SUM(AQ18:AZ18) -> 0 | BB18: =BA18+AP18 -> 0 | BI18: =E18-I18-J18-K18-L18-M18-N18-O18-P18-Q18-R18-S18-T18-U18-V18-Y18-W18-Z18-AA18-AB18-AC18-AD18-AE18-AF18-AG18-AH18-AI18-AJ18-AK18-AM18-X18-AL18+BC18+BE18+BD18+BF18 -> 0 | BJ18: =BI18*C18 -> 0 | BL18: =BB18-BI18 -> 0 | BM18: =BL18*C18 -> 0 | BO18: =I18*C18 -> 0 | BP18: =J18*C18 -> 0 | BQ18: =K18*C18 -> 0 | BR18: =L18*C18 -> 0 | BS18: =M18*C18 -> 0 | BT18: =N18*C18 -> 0 | BU18: =O18*C18 -> 0 | BV18: =P18*C18 -> 0 | BW18: =Q18*C18 -> 0 | BX18: =R18*C18 -> 0 | BY18: =S18*C18 -> 0 | BZ18: =T18*C18 -> 0 | CA18: =U18*C18 -> 0 | CB18: =V18*C18 -> 0 | CC18: =W18*C18 -> 0 | CD18: =X18*C18 -> 0 | CE18: =C18*Y18 -> 0 | CF18: =C18*Z18 -> 0 | CG18: =AA18*C18 -> 0 | CH18: =C18*AB18 -> 0 | CI18: =C18*AC18 -> 0 | CJ18: =C18*AD18 -> 0 | CK18: =C18*AE18 -> 0 | CL18: =C18*AF18 -> 0 | CM18: =C18*AG18 -> 0 | CN18: =C18*AH18 -> 0 | CO18: =C18*AI18 -> 0 | CP18: =C18*AJ18 -> 0 | CQ18: =C18*AK18 -> 0 | CR18: =C18*AL18 -> 0 | CS18: =C18*AM18 -> 0 | CT18: =SUM(BO18:CS18) -> 0
A19: NONEL 3.6 | B19: PCS | C19: 176.78571 | D19: 15427 | E19: 0 | F19: 0 | G19: 847 | H19: =G19*C19 -> 149737.5 | J19: 0 | K19: 0 | L19: 0 | M19: 0 | N19: 0 | O19: 0 | P19: 0 | Q19: 0 | R19: 0 | S19: 0 | T19: 0 | U19: 0 | V19: 0 | W19: 0 | X19: 0 | Y19: 0 | Z19: 0 | AA19: 0 | AB19: 0 | AC19: 0 | AD19: 0 | AE19: 0 | AF19: 0 | AG19: 0 | AH19: 0 | AI19: 0 | AJ19: 0 | AK19: 0 | AL19: 0 | AM19: 0 | AN19: =SUM(I19:AM19) -> 0 | AO19: =C19*AN19 -> 0 | AP19: 0 | BA19: =SUM(AQ19:AZ19) -> 0 | BB19: =BA19+AP19 -> 0 | BI19: =E19-I19-J19-K19-L19-M19-N19-O19-P19-Q19-R19-S19-T19-U19-V19-Y19-W19-Z19-AA19-AB19-AC19-AD19-AE19-AF19-AG19-AH19-AI19-AJ19-AK19-AM19-X19-AL19+BC19+BE19+BD19+BF19 -> 0 | BJ19: =BI19*C19 -> 0 | BL19: =BB19-BI19 -> 0 | BM19: =BL19*C19 -> 0 | BO19: =I19*C19 -> 0 | BP19: =J19*C19 -> 0 | BQ19: =K19*C19 -> 0 | BR19: =L19*C19 -> 0 | BS19: =M19*C19 -> 0 | BT19: =N19*C19 -> 0 | BU19: =O19*C19 -> 0 | BV19: =P19*C19 -> 0 | BW19: =Q19*C19 -> 0 | BX19: =R19*C19 -> 0 | BY19: =S19*C19 -> 0 | BZ19: =T19*C19 -> 0 | CA19: =U19*C19 -> 0 | CB19: =V19*C19 -> 0 | CC19: =W19*C19 -> 0 | CD19: =X19*C19 -> 0 | CE19: =C19*Y19 -> 0 | CF19: =C19*Z19 -> 0 | CG19: =AA19*C19 -> 0 | CH19: =C19*AB19 -> 0 | CI19: =C19*AC19 -> 0 | CJ19: =C19*AD19 -> 0 | CK19: =C19*AE19 -> 0 | CL19: =C19*AF19 -> 0 | CM19: =C19*AG19 -> 0 | CN19: =C19*AH19 -> 0 | CO19: =C19*AI19 -> 0 | CP19: =C19*AJ19 -> 0 | CQ19: =C19*AK19 -> 0 | CR19: =C19*AL19 -> 0 | CS19: =C19*AM19 -> 0 | CT19: =SUM(BO19:CS19) -> 0
A20: SUPREME 2.4 | B20: PCS | C20: 180.35714 | D20: 16623 | E20: 16364 | F20: 2951364.3 | H20: =G20*C20 -> 0 | J20: 0 | K20: 0 | L20: 0 | M20: 0 | N20: 0 | O20: 0 | P20: 0 | Q20: 0 | R20: 0 | S20: 0 | T20: 0 | U20: 0 | V20: 0 | W20: 0 | X20: 0 | Y20: 0 | Z20: 0 | AA20: 0 | AB20: 0 | AC20: 0 | AD20: 0 | AE20: 0 | AF20: 0 | AG20: 0 | AH20: 0 | AI20: 0 | AJ20: 0 | AK20: 0 | AL20: 0 | AM20: 0 | AN20: =SUM(I20:AM20) -> 0 | AO20: =C20*AN20 -> 0 | AP20: 16361 | BA20: =SUM(AQ20:AZ20) -> 0 | BB20: =BA20+AP20 -> 16361 | BI20: =E20-I20-J20-K20-L20-M20-N20-O20-P20-Q20-R20-S20-T20-U20-V20-Y20-W20-Z20-AA20-AB20-AC20-AD20-AE20-AF20-AG20-AH20-AI20-AJ20-AK20-AM20-X20-AL20+BC20+BE20+BD20+BF20 -> 16364 | BJ20: =BI20*C20 -> 2951364.3 | BL20: =BB20-BI20 -> -3 | BM20: =BL20*C20 -> -541.07143 | BO20: =I20*C20 -> 0 | BP20: =J20*C20 -> 0 | BQ20: =K20*C20 -> 0 | BR20: =L20*C20 -> 0 | BS20: =M20*C20 -> 0 | BT20: =N20*C20 -> 0 | BU20: =O20*C20 -> 0 | BV20: =P20*C20 -> 0 | BW20: =Q20*C20 -> 0 | BX20: =R20*C20 -> 0 | BY20: =S20*C20 -> 0 | BZ20: =T20*C20 -> 0 | CA20: =U20*C20 -> 0 | CB20: =V20*C20 -> 0 | CC20: =W20*C20 -> 0 | CD20: =X20*C20 -> 0 | CE20: =C20*Y20 -> 0 | CF20: =C20*Z20 -> 0 | CG20: =AA20*C20 -> 0 | CH20: =C20*AB20 -> 0 | CI20: =C20*AC20 -> 0 | CJ20: =C20*AD20 -> 0 | CK20: =C20*AE20 -> 0 | CL20: =C20*AF20 -> 0 | CM20: =C20*AG20 -> 0 | CN20: =C20*AH20 -> 0 | CO20: =C20*AI20 -> 0 | CP20: =C20*AJ20 -> 0 | CQ20: =C20*AK20 -> 0 | CR20: =C20*AL20 -> 0 | CS20: =C20*AM20 -> 0 | CT20: =SUM(BO20:CS20) -> 0
A21: SHOCK STAR | B21: PCS | C21: 207 | E21: 0 | F21: 0 | H21: =G21*C21 -> 0 | J21: 0 | K21: 0 | L21: 0 | M21: 0 | N21: 0 | O21: 0 | P21: 0 | Q21: 0 | R21: 0 | S21: 0 | T21: 0 | U21: 0 | V21: 0 | W21: 0 | X21: 0 | Y21: 0 | Z21: 0 | AA21: 0 | AB21: 0 | AC21: 0 | AD21: 0 | AE21: 0 | AF21: 0 | AG21: 0 | AH21: 0 | AI21: 0 | AJ21: 0 | AK21: 0 | AL21: 0 | AM21: 0 | AN21: =SUM(I21:AM21) -> 0 | AO21: =C21*AN21 -> 0 | AP21: 0 | BA21: =SUM(AQ21:AZ21) -> 0 | BB21: =BA21+AP21 -> 0 | BI21: =E21-I21-J21-K21-L21-M21-N21-O21-P21-Q21-R21-S21-T21-U21-V21-Y21-W21-Z21-AA21-AB21-AC21-AD21-AE21-AF21-AG21-AH21-AI21-AJ21-AK21-AM21-X21-AL21+BC21+BE21+BD21+BF21 -> 0 | BJ21: =BI21*C21 -> 0 | BL21: =BB21-BI21 -> 0 | BM21: =BL21*C21 -> 0 | BO21: =I21*C21 -> 0 | BP21: =J21*C21 -> 0 | BQ21: =K21*C21 -> 0 | BR21: =L21*C21 -> 0 | BS21: =M21*C21 -> 0 | BT21: =N21*C21 -> 0 | BU21: =O21*C21 -> 0 | BV21: =P21*C21 -> 0 | BW21: =Q21*C21 -> 0 | BX21: =R21*C21 -> 0 | BY21: =S21*C21 -> 0 | BZ21: =T21*C21 -> 0 | CA21: =U21*C21 -> 0 | CB21: =V21*C21 -> 0 | CC21: =W21*C21 -> 0 | CD21: =X21*C21 -> 0 | CE21: =C21*Y21 -> 0 | CF21: =C21*Z21 -> 0 | CG21: =AA21*C21 -> 0 | CH21: =C21*AB21 -> 0 | CI21: =C21*AC21 -> 0 | CJ21: =C21*AD21 -> 0 | CK21: =C21*AE21 -> 0 | CL21: =C21*AF21 -> 0 | CM21: =C21*AG21 -> 0 | CN21: =C21*AH21 -> 0 | CO21: =C21*AI21 -> 0 | CP21: =C21*AJ21 -> 0 | CQ21: =C21*AK21 -> 0 | CR21: =C21*AL21 -> 0 | CS21: =C21*AM21 -> 0 | CT21: =SUM(BO21:CS21) -> 0
A22: PENTEX STOPE PREIME | B22: PCS | C22: 331 | D22: 12151 | E22: 0 | F22: 0 | G22: 95 | H22: =G22*C22 -> 31445 | AN22: =SUM(I22:AM22) -> 0 | AO22: =C22*AN22 -> 0 | AP22: 0 | BA22: =SUM(AQ22:AZ22) -> 0 | BB22: =BA22+AP22 -> 0 | BI22: =E22-I22-J22-K22-L22-M22-N22-O22-P22-Q22-R22-S22-T22-U22-V22-Y22-W22-Z22-AA22-AB22-AC22-AD22-AE22-AF22-AG22-AH22-AI22-AJ22-AK22-AM22-X22-AL22+BC22+BE22+BD22+BF22 -> 0 | BJ22: =BI22*C22 -> 0 | BL22: =BB22-BI22 -> 0 | BM22: =BL22*C22 -> 0 | BO22: =I22*C22 -> 0 | BP22: =J22*C22 -> 0 | BQ22: =K22*C22 -> 0 | BR22: =L22*C22 -> 0 | BS22: =M22*C22 -> 0 | BT22: =N22*C22 -> 0 | BU22: =O22*C22 -> 0 | BV22: =P22*C22 -> 0 | BW22: =Q22*C22 -> 0 | BX22: =R22*C22 -> 0 | BY22: =S22*C22 -> 0 | BZ22: =T22*C22 -> 0 | CA22: =U22*C22 -> 0 | CB22: =V22*C22 -> 0 | CC22: =W22*C22 -> 0 | CD22: =X22*C22 -> 0 | CE22: =C22*Y22 -> 0 | CF22: =C22*Z22 -> 0 | CG22: =AA22*C22 -> 0 | CH22: =C22*AB22 -> 0 | CI22: =C22*AC22 -> 0 | CJ22: =C22*AD22 -> 0 | CK22: =C22*AE22 -> 0 | CL22: =C22*AF22 -> 0 | CM22: =C22*AG22 -> 0 | CN22: =C22*AH22 -> 0 | CO22: =C22*AI22 -> 0 | CP22: =C22*AJ22 -> 0 | CQ22: =C22*AK22 -> 0 | CR22: =C22*AL22 -> 0 | CS22: =C22*AM22 -> 0 | CT22: =SUM(BO22:CS22) -> 0
A23: EXEL 2.4 | B23: PCS | C23: 189.38 | D23: 10965 | E23: 59481 | F23: 14524878 | H23: =G23*C23 -> 0 | J23: 1057 | K23: 1226 | L23: 1840 | M23: 1733 | N23: 1820 | O23: 1531 | P23: 1548 | Q23: 1597 | R23: 1328 | S23: 1731 | T23: 1779 | U23: 1743 | V23: 1490 | W23: 1298 | X23: 1201 | Y23: 1266 | Z23: 1450 | AA23: 1554 | AB23: 1627 | AC23: 1311 | AD23: 1432 | AE23: 1486 | AF23: 1144 | AG23: 1398 | AH23: 1398 | AI23: 1687 | AJ23: 1665 | AK23: 1406 | AL23: 1366 | AM23: 1110 | AN23: =SUM(I23:AM23) -> 44222 | AO23: =C23*AN23 -> 8374762.4 | AP23: ='EXEL 2.4 (SOH MINE)'!D20 -> 10350 | AR23: ='EXEL 2.4 (SOH MINE)'!E20 -> 2175 | AT23: ='EXEL 2.4 (SOH MINE)'!G20 -> 3650 | AU23: ='EXEL 2.4 (SOH MINE)'!H20 -> 6543 | AV23: ='EXEL 2.4 (SOH MINE)'!I20 -> 6292 | AW23: ='EXEL 2.4 (SOH MINE)'!J20 -> 5081 | AX23: ='EXEL 2.4 (SOH MINE)'!K20 -> 0 | AY23: ='EXEL 2.4 (SOH MINE)'!L20 -> 6240 | AZ23: ='EXEL 2.4 (SOH MINE)'!M20 -> 2594 | BA23: =SUM(AQ23:AZ23) -> 32575 | BB23: =BA23+AP23 -> 42925 | BC23: 25500 | BD23: 6000 | BI23: =E23-I23-J23-K23-L23-M23-N23-O23-P23-Q23-R23-S23-T23-U23-V23-Y23-W23-Z23-AA23-AB23-AC23-AD23-AE23-AF23-AG23-AH23-AI23-AJ23-AK23-AM23-X23-AL23+BC23+BE23+BD23+BF23 -> 46759 | BJ23: =BI23*C23 -> 8855219.4 | BL23: =BB23-BI23 -> -3834 | BM23: =BL23*C23 -> -726082.92 | BO23: =I23*C23 -> 0 | BP23: =J23*C23 -> 200174.66 | BQ23: =K23*C23 -> 232179.88 | BR23: =L23*C23 -> 348459.2 | BS23: =M23*C23 -> 328195.54 | BT23: =N23*C23 -> 344671.6 | BU23: =O23*C23 -> 289940.78 | BV23: =P23*C23 -> 293160.24 | BW23: =Q23*C23 -> 302439.86 | BX23: =R23*C23 -> 251496.64 | BY23: =S23*C23 -> 327816.78 | BZ23: =T23*C23 -> 336907.02 | CA23: =U23*C23 -> 330089.34 | CB23: =V23*C23 -> 282176.2 | CC23: =W23*C23 -> 245815.24 | CD23: =X23*C23 -> 227445.38 | CE23: =C23*Y23 -> 239755.08 | CF23: =C23*Z23 -> 274601 | CG23: =AA23*C23 -> 294296.52 | CH23: =C23*AB23 -> 308121.26 | CI23: =C23*AC23 -> 248277.18 | CJ23: =C23*AD23 -> 271192.16 | CK23: =C23*AE23 -> 281418.68 | CL23: =C23*AF23 -> 216650.72 | CM23: =C23*AG23 -> 264753.24 | CN23: =C23*AH23 -> 264753.24 | CO23: =C23*AI23 -> 319484.06 | CP23: =C23*AJ23 -> 315317.7 | CQ23: =C23*AK23 -> 266268.28 | CR23: =C23*AL23 -> 258693.08 | CS23: =C23*AM23 -> 210211.8 | CT23: =SUM(BO23:CS23) -> 8374762.4
A24: EXEL 4.9 | B24: PCS | C24: 195 | D24: 21809 | E24: 0 | F24: 0 | G24: 646 | H24: =G24*C24 -> 125970 | J24: 0 | K24: 0 | L24: 0 | M24: 0 | N24: 0 | O24: 0 | P24: 0 | Q24: 0 | R24: 0 | S24: 0 | T24: 0 | U24: 0 | V24: 0 | W24: 0 | X24: 0 | Y24: 0 | Z24: 0 | AA24: 0 | AB24: 0 | AC24: 0 | AD24: 0 | AE24: 0 | AF24: 0 | AG24: 0 | AH24: 0 | AI24: 0 | AJ24: 0 | AK24: 0 | AL24: 0 | AM24: 0 | AN24: =SUM(I24:AM24) -> 0 | AO24: =C24*AN24 -> 0 | AP24: 0 | BA24: =SUM(AQ24:AZ24) -> 0 | BB24: =BA24+AP24 -> 0 | BI24: =E24-I24-J24-K24-L24-M24-N24-O24-P24-Q24-R24-S24-T24-U24-V24-Y24-W24-Z24-AA24-AB24-AC24-AD24-AE24-AF24-AG24-AH24-AI24-AJ24-AK24-AM24-X24-AL24+BC24+BE24+BD24+BF24 -> 0 | BJ24: 0 | BL24: =BB24-BI24 -> 0 | BM24: =BL24*C24 -> 0 | BO24: =I24*C24 -> 0 | BP24: =J24*C24 -> 0 | BQ24: =K24*C24 -> 0 | BR24: =L24*C24 -> 0 | BS24: =M24*C24 -> 0 | BT24: =N24*C24 -> 0 | BU24: =O24*C24 -> 0 | BV24: =P24*C24 -> 0 | BW24: =Q24*C24 -> 0 | BX24: =R24*C24 -> 0 | BY24: =S24*C24 -> 0 | BZ24: =T24*C24 -> 0 | CA24: =U24*C24 -> 0 | CB24: =V24*C24 -> 0 | CC24: =W24*C24 -> 0 | CD24: =X24*C24 -> 0 | CE24: =C24*Y24 -> 0 | CF24: =C24*Z24 -> 0 | CG24: =AA24*C24 -> 0 | CH24: =C24*AB24 -> 0 | CI24: =C24*AC24 -> 0 | CJ24: =C24*AD24 -> 0 | CK24: =C24*AE24 -> 0 | CL24: =C24*AF24 -> 0 | CM24: =C24*AG24 -> 0 | CN24: =C24*AH24 -> 0 | CO24: =C24*AI24 -> 0 | CP24: =C24*AJ24 -> 0 | CQ24: =C24*AK24 -> 0 | CR24: =C24*AL24 -> 0 | CS24: =C24*AM24 -> 0 | CT24: =SUM(BO24:CS24) -> 0
A25: EXEL 3.6 | B25: PCS | C25: 195 | D25: 10966 | E25: 15644 | F25: 2275455 | H25: =G25*C25 -> 0 | J25: 13 | K25: 19 | L25: 28 | M25: 48 | N25: 65 | O25: 45 | P25: 51 | Q25: 55 | R25: 26 | S25: 39 | T25: 51 | U25: 59 | V25: 40 | W25: 26 | X25: 29 | Y25: 27 | Z25: 25 | AA25: 146 | AB25: 252 | AC25: 232 | AD25: 292 | AE25: 309 | AF25: 293 | AG25: 333 | AH25: 273 | AI25: 266 | AJ25: 128 | AK25: 122 | AL25: 98 | AM25: 63 | AN25: =SUM(I25:AM25) -> 3453 | AO25: =C25*AN25 -> 673335 | AP25: ='EXEL 3.6 (SOH MINE)'!D19 -> 8060 | AR25: ='EXEL 3.6 (SOH MINE)'!F19 -> 990 | AT25: ='EXEL 3.6 (SOH MINE)'!J19 -> 440 | AU25: ='EXEL 3.6 (SOH MINE)'!K19 -> 1162 | AV25: ='EXEL 3.6 (SOH MINE)'!L19 -> 440 | AW25: ='EXEL 3.6 (SOH MINE)'!M19 -> 493 | AX25: ='EXEL 3.6 (SOH MINE)'!N19 -> 0 | AY25: ='EXEL 3.6 (SOH MINE)'!O19 -> 668 | AZ25: ='EXEL 3.6 (SOH MINE)'!P19 -> 5 | BA25: =SUM(AQ25:AZ25) -> 4198 | BB25: =BA25+AP25 -> 12258 | BI25: =E25-I25-J25-K25-L25-M25-N25-O25-P25-Q25-R25-S25-T25-U25-V25-Y25-W25-Z25-AA25-AB25-AC25-AD25-AE25-AF25-AG25-AH25-AI25-AJ25-AK25-AM25-X25-AL25+BC25+BE25+BD25+BF25 -> 12191 | BJ25: =BI25*C25 -> 2377245 | BL25: =BB25-BI25 -> 67 | BM25: =BL25*C25 -> 13065 | BO25: =I25*C25 -> 0 | BP25: =J25*C25 -> 2535 | BQ25: =K25*C25 -> 3705 | BR25: =L25*C25 -> 5460 | BS25: =M25*C25 -> 9360 | BT25: =N25*C25 -> 12675 | BU25: =O25*C25 -> 8775 | BV25: =P25*C25 -> 9945 | BW25: =Q25*C25 -> 10725 | BX25: =R25*C25 -> 5070 | BY25: =S25*C25 -> 7605 | BZ25: =T25*C25 -> 9945 | CA25: =U25*C25 -> 11505 | CB25: =V25*C25 -> 7800 | CC25: =W25*C25 -> 5070 | CD25: =X25*C25 -> 5655 | CE25: =C25*Y25 -> 5265 | CF25: =C25*Z25 -> 4875 | CG25: =AA25*C25 -> 28470 | CH25: =C25*AB25 -> 49140 | CI25: =C25*AC25 -> 45240 | CJ25: =C25*AD25 -> 56940 | CK25: =C25*AE25 -> 60255 | CL25: =C25*AF25 -> 57135 | CM25: =C25*AG25 -> 64935 | CN25: =C25*AH25 -> 53235 | CO25: =C25*AI25 -> 51870 | CP25: =C25*AJ25 -> 24960 | CQ25: =C25*AK25 -> 23790 | CR25: =C25*AL25 -> 19110 | CS25: =C25*AM25 -> 12285 | CT25: =SUM(BO25:CS25) -> 673335
A26: MS 12 | B26: PCS | C26: 359.83 | E26: 0 | F26: 0 | H26: =G26*C26 -> 0 | AN26: =SUM(I26:AM26) -> 0 | AO26: =C26*AN26 -> 0 | AP26: 0 | BA26: =SUM(AQ26:AZ26) -> 0 | BB26: =BA26+AP26 -> 0 | BI26: =E26-I26-J26-K26-L26-M26-N26-O26-P26-Q26-R26-S26-T26-U26-V26-Y26-W26-Z26-AA26-AB26-AC26-AD26-AE26-AF26-AG26-AH26-AI26-AJ26-AK26-AM26-X26-AL26+BC26+BE26+BD26+BF26 -> 0 | BJ26: =BI26*C26 -> 0 | BL26: =BB26-BI26 -> 0 | BM26: =BL26*C26 -> 0 | BO26: =I26*C26 -> 0 | BP26: =J26*C26 -> 0 | BQ26: =K26*C26 -> 0 | BR26: =L26*C26 -> 0 | BS26: =M26*C26 -> 0 | BT26: =N26*C26 -> 0 | BU26: =O26*C26 -> 0 | BV26: =P26*C26 -> 0 | BW26: =Q26*C26 -> 0 | BX26: =R26*C26 -> 0 | BY26: =S26*C26 -> 0 | BZ26: =T26*C26 -> 0 | CA26: =U26*C26 -> 0 | CB26: =V26*C26 -> 0 | CC26: =W26*C26 -> 0 | CD26: =X26*C26 -> 0 | CE26: =C26*Y26 -> 0 | CF26: =C26*Z26 -> 0 | CG26: =AA26*C26 -> 0 | CH26: =C26*AB26 -> 0 | CI26: =C26*AC26 -> 0 | CJ26: =C26*AD26 -> 0 | CK26: =C26*AE26 -> 0 | CL26: =C26*AF26 -> 0 | CM26: =C26*AG26 -> 0 | CN26: =C26*AH26 -> 0 | CO26: =C26*AI26 -> 0 | CP26: =C26*AJ26 -> 0 | CQ26: =C26*AK26 -> 0 | CR26: =C26*AL26 -> 0 | CS26: =C26*AM26 -> 0 | CT26: =SUM(BO26:CS26) -> 0
A27: MS 18 | B27: PCS | C27: 379.46 | E27: 0 | F27: 0 | H27: =G27*C27 -> 0 | AN27: =SUM(I27:AM27) -> 0 | AO27: =C27*AN27 -> 0 | AP27: 0 | BA27: =SUM(AQ27:AZ27) -> 0 | BB27: =BA27+AP27 -> 0 | BI27: =E27-I27-J27-K27-L27-M27-N27-O27-P27-Q27-R27-S27-T27-U27-V27-Y27-W27-Z27-AA27-AB27-AC27-AD27-AE27-AF27-AG27-AH27-AI27-AJ27-AK27-AM27-X27-AL27+BC27+BE27+BD27+BF27 -> 0 | BJ27: =BI27*C27 -> 0 | BL27: =BB27-BI27 -> 0 | BM27: =BL27*C27 -> 0 | BO27: =I27*C27 -> 0 | BP27: =J27*C27 -> 0 | BQ27: =K27*C27 -> 0 | BR27: =L27*C27 -> 0 | BS27: =M27*C27 -> 0 | BT27: =N27*C27 -> 0 | BU27: =O27*C27 -> 0 | BV27: =P27*C27 -> 0 | BW27: =Q27*C27 -> 0 | BX27: =R27*C27 -> 0 | BY27: =S27*C27 -> 0 | BZ27: =T27*C27 -> 0 | CA27: =U27*C27 -> 0 | CB27: =V27*C27 -> 0 | CC27: =W27*C27 -> 0 | CD27: =X27*C27 -> 0 | CE27: =C27*Y27 -> 0 | CF27: =C27*Z27 -> 0 | CG27: =AA27*C27 -> 0 | CH27: =C27*AB27 -> 0 | CI27: =C27*AC27 -> 0 | CJ27: =C27*AD27 -> 0 | CK27: =C27*AE27 -> 0 | CL27: =C27*AF27 -> 0 | CM27: =C27*AG27 -> 0 | CN27: =C27*AH27 -> 0 | CO27: =C27*AI27 -> 0 | CP27: =C27*AJ27 -> 0 | CQ27: =C27*AK27 -> 0 | CR27: =C27*AL27 -> 0 | CS27: =C27*AM27 -> 0 | CT27: =SUM(BO27:CS27) -> 0
A28: CORDTEX 5 | B28: MTR | C28: 35.15 | D28: 10960 | E28: 17184 | F28: 1110669.7 | H28: =G28*C28 -> 0 | J28: 187 | K28: 313 | L28: 418 | M28: 396 | N28: 318 | O28: 257 | P28: 271 | Q28: 373 | R28: 509 | S28: 692 | T28: 646 | U28: 680 | V28: 591 | W28: 481 | X28: 430 | Y28: 343 | Z28: 339 | AA28: 495 | AB28: 399 | AC28: 329 | AD28: 357 | AE28: 365 | AF28: 252 | AG28: 453 | AH28: 459 | AI28: 389 | AJ28: 416 | AK28: 405 | AL28: 413 | AM28: 284 | AN28: =SUM(I28:AM28) -> 12260 | AO28: =C28*AN28 -> 430939 | AP28: 3600 | AR28: 240 | AT28: 780 | AU28: 4484 | AV28: 1601 | AW28: 597 | AY28: 0 | BA28: =SUM(AQ28:AZ28) -> 7702 | BB28: =BA28+AP28 -> 11302 | BC28: 2700 | BD28: 2700 | BI28: =E28-I28-J28-K28-L28-M28-N28-O28-P28-Q28-R28-S28-T28-U28-V28-Y28-W28-Z28-AA28-AB28-AC28-AD28-AE28-AF28-AG28-AH28-AI28-AJ28-AK28-AM28-X28-AL28+BC28+BE28+BD28+BF28 -> 10324 | BJ28: =BI28*C28 -> 362888.6 | BL28: =BB28-BI28 -> 978 | BM28: =BL28*C28 -> 34376.7 | BO28: =I28*C28 -> 0 | BP28: =J28*C28 -> 6573.05 | BQ28: =K28*C28 -> 11001.95 | BR28: =L28*C28 -> 14692.7 | BS28: =M28*C28 -> 13919.4 | BT28: =N28*C28 -> 11177.7 | BU28: =O28*C28 -> 9033.55 | BV28: =P28*C28 -> 9525.65 | BW28: =Q28*C28 -> 13110.95 | BX28: =R28*C28 -> 17891.35 | BY28: =S28*C28 -> 24323.8 | BZ28: =T28*C28 -> 22706.9 | CA28: =U28*C28 -> 23902 | CB28: =V28*C28 -> 20773.65 | CC28: =W28*C28 -> 16907.15 | CD28: =X28*C28 -> 15114.5 | CE28: =C28*Y28 -> 12056.45 | CF28: =C28*Z28 -> 11915.85 | CG28: =AA28*C28 -> 17399.25 | CH28: =C28*AB28 -> 14024.85 | CI28: =C28*AC28 -> 11564.35 | CJ28: =C28*AD28 -> 12548.55 | CK28: =C28*AE28 -> 12829.75 | CL28: =C28*AF28 -> 8857.8 | CM28: =C28*AG28 -> 15922.95 | CN28: =C28*AH28 -> 16133.85 | CO28: =C28*AI28 -> 13673.35 | CP28: =C28*AJ28 -> 14622.4 | CQ28: =C28*AK28 -> 14235.75 | CR28: =C28*AL28 -> 14516.95 | CS28: =C28*AM28 -> 9982.6 | CT28: =SUM(BO28:CS28) -> 430939
