Workbook

Sheet ALL LEVELS
B1: Mine Production | E1: Total W.Days | F1: 30 | H1: Month of JUNE 2026
B2: Day | C2: 19
C3: DAILY | E3: MTD
B4: DELAY TYPE | C4: QUOTA | D4: ACTUAL | E4: QUOTA | F4: ACTUAL
B5: EMULSION
B6: ANFO
B7: DETONATORS
B8: DETCORDS
B10: TOTAL
J11: MTD
A12: DATE | B12: DAY | C12: EMULSION (KG) | D12: ANFO (KG) | E12: DETONATORS (PCS) | F12: DETCORDS (MTR) | J12: EMULSION | K12: ANFO | L12: DETONATORS | M12: DETCORDS
A13: 1 | B13: MONDAY | C13: ='LEVEL 4'!C13+'LEVEL 5'!C13+'LEVEL 6'!C13+'LEVEL 7'!C13+'LEVEL 8'!C13+'LEVEL 9'!C13+'LEVEL 10'!C13+'LEVEL 11'!C13+'LEVEL 12'!C13+'LEVEL 3'!C13+'SINUG-ANG VEIN'!C13+'L425'!C13+'L460'!C13 -> 294.98837 | D13: ='LEVEL 4'!D13+'LEVEL 5'!D13+'LEVEL 6'!D13+'LEVEL 7'!D13+'LEVEL 8'!D13+'LEVEL 9'!D13+'LEVEL 10'!D13+'LEVEL 11'!D13+'LEVEL 12'!D13+'LEVEL 3'!D13+'SINUG-ANG VEIN'!D13+'L425'!D13+'L460'!D13 -> 981 | E13: ='LEVEL 4'!E13+'LEVEL 5'!E13+'LEVEL 6'!E13+'LEVEL 7'!E13+'LEVEL 8'!E13+'LEVEL 9'!E13+'LEVEL 10'!E13+'LEVEL 11'!E13+'LEVEL 12'!E13+'LEVEL 3'!E13+'SINUG-ANG VEIN'!E13+'L425'!E13+'L460'!E13 -> 1365 | F13: ='LEVEL 4'!F13+'LEVEL 5'!F13+'LEVEL 6'!F13+'LEVEL 7'!F13+'LEVEL 8'!F13+'LEVEL 9'!F13+'LEVEL 10'!F13+'LEVEL 11'!F13+'LEVEL 12'!F13+'LEVEL 3'!F13+'SINUG-ANG VEIN'!F13+'L425'!F13+'L460'!F13 -> 653 | J13: =SUM(C$13:C13) -> 294.98837 | K13: =SUM(D$13:D13) -> 981 | L13: =SUM(E$13:E13) -> 1365 | M13: =SUM(F$13:F13) -> 653
A14: 2 | B14: TUESDAY | C14: ='LEVEL 4'!C14+'LEVEL 5'!C14+'LEVEL 6'!C14+'LEVEL 7'!C14+'LEVEL 8'!C14+'LEVEL 9'!C14+'LEVEL 10'!C14+'LEVEL 11'!C14+'LEVEL 12'!C14+'LEVEL 3'!C14+'SINUG-ANG VEIN'!C14+'L425'!C14+'L460'!C14 -> 331.56977 | D14: ='LEVEL 4'!D14+'LEVEL 5'!D14+'LEVEL 6'!D14+'LEVEL 7'!D14+'LEVEL 8'!D14+'LEVEL 9'!D14+'LEVEL 10'!D14+'LEVEL 11'!D14+'LEVEL 12'!D14+'LEVEL 3'!D14+'SINUG-ANG VEIN'!D14+'L425'!D14+'L460'!D14 -> 1128.2 | E14: ='LEVEL 4'!E14+'LEVEL 5'!E14+'LEVEL 6'!E14+'LEVEL 7'!E14+'LEVEL 8'!E14+'LEVEL 9'!E14+'LEVEL 10'!E14+'LEVEL 11'!E14+'LEVEL 12'!E14+'LEVEL 3'!E14+'SINUG-ANG VEIN'!E14+'L425'!E14+'L460'!E14 -> 1584 | F14: ='LEVEL 4'!F14+'LEVEL 5'!F14+'LEVEL 6'!F14+'LEVEL 7'!F14+'LEVEL 8'!F14+'LEVEL 9'!F14+'LEVEL 10'!F14+'LEVEL 11'!F14+'LEVEL 12'!F14+'LEVEL 3'!F14+'SINUG-ANG VEIN'!F14+'L425'!F14+'L460'!F14 -> 729 | J14: =SUM(C$13:C14) -> 626.55814 | K14: =SUM(D$13:D14) -> 2109.2 | L14: =SUM(E$13:E14) -> 2949 | M14: =SUM(F$13:F14) -> 1382
A15: 3 | B15: WEDNESDAY | C15: ='LEVEL 4'!C15+'LEVEL 5'!C15+'LEVEL 6'!C15+'LEVEL 7'!C15+'LEVEL 8'!C15+'LEVEL 9'!C15+'LEVEL 10'!C15+'LEVEL 11'!C15+'LEVEL 12'!C15+'LEVEL 3'!C15+'SINUG-ANG VEIN'!C15+'L425'!C15+'L460'!C15 -> 371.60756 | D15: ='LEVEL 4'!D15+'LEVEL 5'!D15+'LEVEL 6'!D15+'LEVEL 7'!D15+'LEVEL 8'!D15+'LEVEL 9'!D15+'LEVEL 10'!D15+'LEVEL 11'!D15+'LEVEL 12'!D15+'LEVEL 3'!D15+'SINUG-ANG VEIN'!D15+'L425'!D15+'L460'!D15 -> 1107.8 | E15: ='LEVEL 4'!E15+'LEVEL 5'!E15+'LEVEL 6'!E15+'LEVEL 7'!E15+'LEVEL 8'!E15+'LEVEL 9'!E15+'LEVEL 10'!E15+'LEVEL 11'!E15+'LEVEL 12'!E15+'LEVEL 3'!E15+'SINUG-ANG VEIN'!E15+'L425'!E15+'L460'!E15 -> 1668 | F15: ='LEVEL 4'!F15+'LEVEL 5'!F15+'LEVEL 6'!F15+'LEVEL 7'!F15+'LEVEL 8'!F15+'LEVEL 9'!F15+'LEVEL 10'!F15+'LEVEL 11'!F15+'LEVEL 12'!F15+'LEVEL 3'!F15+'SINUG-ANG VEIN'!F15+'L425'!F15+'L460'!F15 -> 760 | J15: =SUM(C$13:C15) -> 998.1657 | K15: =SUM(D$13:D15) -> 3217 | L15: =SUM(E$13:E15) -> 4617 | M15: =SUM(F$13:F15) -> 2142
A16: 4 | B16: THURSDAY | C16: ='LEVEL 4'!C16+'LEVEL 5'!C16+'LEVEL 6'!C16+'LEVEL 7'!C16+'LEVEL 8'!C16+'LEVEL 9'!C16+'LEVEL 10'!C16+'LEVEL 11'!C16+'LEVEL 12'!C16+'LEVEL 3'!C16+'SINUG-ANG VEIN'!C16+'L425'!C16+'L460'!C16 -> 351.40698 | D16: ='LEVEL 4'!D16+'LEVEL 5'!D16+'LEVEL 6'!D16+'LEVEL 7'!D16+'LEVEL 8'!D16+'LEVEL 9'!D16+'LEVEL 10'!D16+'LEVEL 11'!D16+'LEVEL 12'!D16+'LEVEL 3'!D16+'SINUG-ANG VEIN'!D16+'L425'!D16+'L460'!D16 -> 1183.4 | E16: ='LEVEL 4'!E16+'LEVEL 5'!E16+'LEVEL 6'!E16+'LEVEL 7'!E16+'LEVEL 8'!E16+'LEVEL 9'!E16+'LEVEL 10'!E16+'LEVEL 11'!E16+'LEVEL 12'!E16+'LEVEL 3'!E16+'SINUG-ANG VEIN'!E16+'L425'!E16+'L460'!E16 -> 1677 | F16: ='LEVEL 4'!F16+'LEVEL 5'!F16+'LEVEL 6'!F16+'LEVEL 7'!F16+'LEVEL 8'!F16+'LEVEL 9'!F16+'LEVEL 10'!F16+'LEVEL 11'!F16+'LEVEL 12'!F16+'LEVEL 3'!F16+'SINUG-ANG VEIN'!F16+'L425'!F16+'L460'!F16 -> 812 | J16: =SUM(C$13:C16) -> 1349.5727 | K16: =SUM(D$13:D16) -> 4400.4 | L16: =SUM(E$13:E16) -> 6294 | M16: =SUM(F$13:F16) -> 2954
A17: 5 | B17: FRIDAY | C17: ='LEVEL 4'!C17+'LEVEL 5'!C17+'LEVEL 6'!C17+'LEVEL 7'!C17+'LEVEL 8'!C17+'LEVEL 9'!C17+'LEVEL 10'!C17+'LEVEL 11'!C17+'LEVEL 12'!C17+'LEVEL 3'!C17+'SINUG-ANG VEIN'!C17+'L425'!C17+'L460'!C17 -> 385.69767 | D17: ='LEVEL 4'!D17+'LEVEL 5'!D17+'LEVEL 6'!D17+'LEVEL 7'!D17+'LEVEL 8'!D17+'LEVEL 9'!D17+'LEVEL 10'!D17+'LEVEL 11'!D17+'LEVEL 12'!D17+'LEVEL 3'!D17+'SINUG-ANG VEIN'!D17+'L425'!D17+'L460'!D17 -> 1186.6 | E17: ='LEVEL 4'!E17+'LEVEL 5'!E17+'LEVEL 6'!E17+'LEVEL 7'!E17+'LEVEL 8'!E17+'LEVEL 9'!E17+'LEVEL 10'!E17+'LEVEL 11'!E17+'LEVEL 12'!E17+'LEVEL 3'!E17+'SINUG-ANG VEIN'!E17+'L425'!E17+'L460'!E17 -> 1689 | F17: ='LEVEL 4'!F17+'LEVEL 5'!F17+'LEVEL 6'!F17+'LEVEL 7'!F17+'LEVEL 8'!F17+'LEVEL 9'!F17+'LEVEL 10'!F17+'LEVEL 11'!F17+'LEVEL 12'!F17+'LEVEL 3'!F17+'SINUG-ANG VEIN'!F17+'L425'!F17+'L460'!F17 -> 797 | J17: =SUM(C$13:C17) -> 1735.2703 | K17: =SUM(D$13:D17) -> 5587 | L17: =SUM(E$13:E17) -> 7983 | M17: =SUM(F$13:F17) -> 3751
A18: 6 | B18: SATURDAY | C18: ='LEVEL 4'!C18+'LEVEL 5'!C18+'LEVEL 6'!C18+'LEVEL 7'!C18+'LEVEL 8'!C18+'LEVEL 9'!C18+'LEVEL 10'!C18+'LEVEL 11'!C18+'LEVEL 12'!C18+'LEVEL 3'!C18+'SINUG-ANG VEIN'!C18+'L425'!C18+'L460'!C18 -> 417.15988 | D18: ='LEVEL 4'!D18+'LEVEL 5'!D18+'LEVEL 6'!D18+'LEVEL 7'!D18+'LEVEL 8'!D18+'LEVEL 9'!D18+'LEVEL 10'!D18+'LEVEL 11'!D18+'LEVEL 12'!D18+'LEVEL 3'!D18+'SINUG-ANG VEIN'!D18+'L425'!D18+'L460'!D18 -> 1295.2 | E18: ='LEVEL 4'!E18+'LEVEL 5'!E18+'LEVEL 6'!E18+'LEVEL 7'!E18+'LEVEL 8'!E18+'LEVEL 9'!E18+'LEVEL 10'!E18+'LEVEL 11'!E18+'LEVEL 12'!E18+'LEVEL 3'!E18+'SINUG-ANG VEIN'!E18+'L425'!E18+'L460'!E18 -> 1847 | F18: ='LEVEL 4'!F18+'LEVEL 5'!F18+'LEVEL 6'!F18+'LEVEL 7'!F18+'LEVEL 8'!F18+'LEVEL 9'!F18+'LEVEL 10'!F18+'LEVEL 11'!F18+'LEVEL 12'!F18+'LEVEL 3'!F18+'SINUG-ANG VEIN'!F18+'L425'!F18+'L460'!F18 -> 918 | J18: =SUM(C$13:C18) -> 2152.4302 | K18: =SUM(D$13:D18) -> 6882.2 | L18: =SUM(E$13:E18) -> 9830 | M18: =SUM(F$13:F18) -> 4669
A19: 7 | B19: SUNDAY | C19: ='LEVEL 4'!C19+'LEVEL 5'!C19+'LEVEL 6'!C19+'LEVEL 7'!C19+'LEVEL 8'!C19+'LEVEL 9'!C19+'LEVEL 10'!C19+'LEVEL 11'!C19+'LEVEL 12'!C19+'LEVEL 3'!C19+'SINUG-ANG VEIN'!C19+'L425'!C19+'L460'!C19 -> 318.14535 | D19: ='LEVEL 4'!D19+'LEVEL 5'!D19+'LEVEL 6'!D19+'LEVEL 7'!D19+'LEVEL 8'!D19+'LEVEL 9'!D19+'LEVEL 10'!D19+'LEVEL 11'!D19+'LEVEL 12'!D19+'LEVEL 3'!D19+'SINUG-ANG VEIN'!D19+'L425'!D19+'L460'!D19 -> 887.6 | E19: ='LEVEL 4'!E19+'LEVEL 5'!E19+'LEVEL 6'!E19+'LEVEL 7'!E19+'LEVEL 8'!E19+'LEVEL 9'!E19+'LEVEL 10'!E19+'LEVEL 11'!E19+'LEVEL 12'!E19+'LEVEL 3'!E19+'SINUG-ANG VEIN'!E19+'L425'!E19+'L460'!E19 -> 1285 | F19: ='LEVEL 4'!F19+'LEVEL 5'!F19+'LEVEL 6'!F19+'LEVEL 7'!F19+'LEVEL 8'!F19+'LEVEL 9'!F19+'LEVEL 10'!F19+'LEVEL 11'!F19+'LEVEL 12'!F19+'LEVEL 3'!F19+'SINUG-ANG VEIN'!F19+'L425'!F19+'L460'!F19 -> 609 | J19: =SUM(C$13:C19) -> 2470.5756 | K19: =SUM(D$13:D19) -> 7769.8 | L19: =SUM(E$13:E19) -> 11115 | M19: =SUM(F$13:F19) -> 5278
A20: 8 | B20: MONDAY | C20: ='LEVEL 4'!C20+'LEVEL 5'!C20+'LEVEL 6'!C20+'LEVEL 7'!C20+'LEVEL 8'!C20+'LEVEL 9'!C20+'LEVEL 10'!C20+'LEVEL 11'!C20+'LEVEL 12'!C20+'LEVEL 3'!C20+'SINUG-ANG VEIN'!C20+'L425'!C20+'L460'!C20 -> 372.43895 | D20: ='LEVEL 4'!D20+'LEVEL 5'!D20+'LEVEL 6'!D20+'LEVEL 7'!D20+'LEVEL 8'!D20+'LEVEL 9'!D20+'LEVEL 10'!D20+'LEVEL 11'!D20+'LEVEL 12'!D20+'LEVEL 3'!D20+'SINUG-ANG VEIN'!D20+'L425'!D20+'L460'!D20 -> 1174.8 | E20: ='LEVEL 4'!E20+'LEVEL 5'!E20+'LEVEL 6'!E20+'LEVEL 7'!E20+'LEVEL 8'!E20+'LEVEL 9'!E20+'LEVEL 10'!E20+'LEVEL 11'!E20+'LEVEL 12'!E20+'LEVEL 3'!E20+'SINUG-ANG VEIN'!E20+'L425'!E20+'L460'!E20 -> 1688 | F20: ='LEVEL 4'!F20+'LEVEL 5'!F20+'LEVEL 6'!F20+'LEVEL 7'!F20+'LEVEL 8'!F20+'LEVEL 9'!F20+'LEVEL 10'!F20+'LEVEL 11'!F20+'LEVEL 12'!F20+'LEVEL 3'!F20+'SINUG-ANG VEIN'!F20+'L425'!F20+'L460'!F20 -> 826 | J20: =SUM(C$13:C20) -> 2843.0145 | K20: =SUM(D$13:D20) -> 8944.6 | L20: =SUM(E$13:E20) -> 12803 | M20: =SUM(F$13:F20) -> 6104
A21: 9 | B21: TUESDAY | C21: ='LEVEL 4'!C21+'LEVEL 5'!C21+'LEVEL 6'!C21+'LEVEL 7'!C21+'LEVEL 8'!C21+'LEVEL 9'!C21+'LEVEL 10'!C21+'LEVEL 11'!C21+'LEVEL 12'!C21+'LEVEL 3'!C21+'SINUG-ANG VEIN'!C21+'L425'!C21+'L460'!C21 -> 415.90988 | D21: ='LEVEL 4'!D21+'LEVEL 5'!D21+'LEVEL 6'!D21+'LEVEL 7'!D21+'LEVEL 8'!D21+'LEVEL 9'!D21+'LEVEL 10'!D21+'LEVEL 11'!D21+'LEVEL 12'!D21+'LEVEL 3'!D21+'SINUG-ANG VEIN'!D21+'L425'!D21+'L460'!D21 -> 1241.6 | E21: ='LEVEL 4'!E21+'LEVEL 5'!E21+'LEVEL 6'!E21+'LEVEL 7'!E21+'LEVEL 8'!E21+'LEVEL 9'!E21+'LEVEL 10'!E21+'LEVEL 11'!E21+'LEVEL 12'!E21+'LEVEL 3'!E21+'SINUG-ANG VEIN'!E21+'L425'!E21+'L460'!E21 -> 1811 | F21: ='LEVEL 4'!F21+'LEVEL 5'!F21+'LEVEL 6'!F21+'LEVEL 7'!F21+'LEVEL 8'!F21+'LEVEL 9'!F21+'LEVEL 10'!F21+'LEVEL 11'!F21+'LEVEL 12'!F21+'LEVEL 3'!F21+'SINUG-ANG VEIN'!F21+'L425'!F21+'L460'!F21 -> 889 | J21: =SUM(C$13:C21) -> 3258.9244 | K21: =SUM(D$13:D21) -> 10186.2 | L21: =SUM(E$13:E21) -> 14614 | M21: =SUM(F$13:F21) -> 6993
A22: 10 | B22: WEDNESDAY | C22: ='LEVEL 4'!C22+'LEVEL 5'!C22+'LEVEL 6'!C22+'LEVEL 7'!C22+'LEVEL 8'!C22+'LEVEL 9'!C22+'LEVEL 10'!C22+'LEVEL 11'!C22+'LEVEL 12'!C22+'LEVEL 3'!C22+'SINUG-ANG VEIN'!C22+'L425'!C22+'L460'!C22 -> 363.82267 | D22: ='LEVEL 4'!D22+'LEVEL 5'!D22+'LEVEL 6'!D22+'LEVEL 7'!D22+'LEVEL 8'!D22+'LEVEL 9'!D22+'LEVEL 10'!D22+'LEVEL 11'!D22+'LEVEL 12'!D22+'LEVEL 3'!D22+'SINUG-ANG VEIN'!D22+'L425'!D22+'L460'!D22 -> 1195.2 | E22: ='LEVEL 4'!E22+'LEVEL 5'!E22+'LEVEL 6'!E22+'LEVEL 7'!E22+'LEVEL 8'!E22+'LEVEL 9'!E22+'LEVEL 10'!E22+'LEVEL 11'!E22+'LEVEL 12'!E22+'LEVEL 3'!E22+'SINUG-ANG VEIN'!E22+'L425'!E22+'L460'!E22 -> 1652 | F22: ='LEVEL 4'!F22+'LEVEL 5'!F22+'LEVEL 6'!F22+'LEVEL 7'!F22+'LEVEL 8'!F22+'LEVEL 9'!F22+'LEVEL 10'!F22+'LEVEL 11'!F22+'LEVEL 12'!F22+'LEVEL 3'!F22+'SINUG-ANG VEIN'!F22+'L425'!F22+'L460'!F22 -> 796 | J22: =SUM(C$13:C22) -> 3622.7471 | K22: =SUM(D$13:D22) -> 11381.4 | L22: =SUM(E$13:E22) -> 16266 | M22: =SUM(F$13:F22) -> 7789
A23: 11 | B23: THURSDAY | C23: ='LEVEL 4'!C23+'LEVEL 5'!C23+'LEVEL 6'!C23+'LEVEL 7'!C23+'LEVEL 8'!C23+'LEVEL 9'!C23+'LEVEL 10'!C23+'LEVEL 11'!C23+'LEVEL 12'!C23+'LEVEL 3'!C23+'SINUG-ANG VEIN'!C23+'L425'!C23+'L460'!C23 -> 406.02907 | D23: ='LEVEL 4'!D23+'LEVEL 5'!D23+'LEVEL 6'!D23+'LEVEL 7'!D23+'LEVEL 8'!D23+'LEVEL 9'!D23+'LEVEL 10'!D23+'LEVEL 11'!D23+'LEVEL 12'!D23+'LEVEL 3'!D23+'SINUG-ANG VEIN'!D23+'L425'!D23+'L460'!D23 -> 1339.6 | E23: ='LEVEL 4'!E23+'LEVEL 5'!E23+'LEVEL 6'!E23+'LEVEL 7'!E23+'LEVEL 8'!E23+'LEVEL 9'!E23+'LEVEL 10'!E23+'LEVEL 11'!E23+'LEVEL 12'!E23+'LEVEL 3'!E23+'SINUG-ANG VEIN'!E23+'L425'!E23+'L460'!E23 -> 1891 | F23: ='LEVEL 4'!F23+'LEVEL 5'!F23+'LEVEL 6'!F23+'LEVEL 7'!F23+'LEVEL 8'!F23+'LEVEL 9'!F23+'LEVEL 10'!F23+'LEVEL 11'!F23+'LEVEL 12'!F23+'LEVEL 3'!F23+'SINUG-ANG VEIN'!F23+'L425'!F23+'L460'!F23 -> 885 | J23: =SUM(C$13:C23) -> 4028.7762 | K23: =SUM(D$13:D23) -> 12721 | L23: =SUM(E$13:E23) -> 18157 | M23: =SUM(F$13:F23) -> 8674
A24: 12 | B24: FRIDAY | C24: ='LEVEL 4'!C24+'LEVEL 5'!C24+'LEVEL 6'!C24+'LEVEL 7'!C24+'LEVEL 8'!C24+'LEVEL 9'!C24+'LEVEL 10'!C24+'LEVEL 11'!C24+'LEVEL 12'!C24+'LEVEL 3'!C24+'SINUG-ANG VEIN'!C24+'L425'!C24+'L460'!C24 -> 409.86047 | D24: ='LEVEL 4'!D24+'LEVEL 5'!D24+'LEVEL 6'!D24+'LEVEL 7'!D24+'LEVEL 8'!D24+'LEVEL 9'!D24+'LEVEL 10'!D24+'LEVEL 11'!D24+'LEVEL 12'!D24+'LEVEL 3'!D24+'SINUG-ANG VEIN'!D24+'L425'!D24+'L460'!D24 -> 1301.6 | E24: ='LEVEL 4'!E24+'LEVEL 5'!E24+'LEVEL 6'!E24+'LEVEL 7'!E24+'LEVEL 8'!E24+'LEVEL 9'!E24+'LEVEL 10'!E24+'LEVEL 11'!E24+'LEVEL 12'!E24+'LEVEL 3'!E24+'SINUG-ANG VEIN'!E24+'L425'!E24+'L460'!E24 -> 1844 | F24: ='LEVEL 4'!F24+'LEVEL 5'!F24+'LEVEL 6'!F24+'LEVEL 7'!F24+'LEVEL 8'!F24+'LEVEL 9'!F24+'LEVEL 10'!F24+'LEVEL 11'!F24+'LEVEL 12'!F24+'LEVEL 3'!F24+'SINUG-ANG VEIN'!F24+'L425'!F24+'L460'!F24 -> 904 | J24: =SUM(C$13:C24) -> 4438.6366 | K24: =SUM(D$13:D24) -> 14022.6 | L24: =SUM(E$13:E24) -> 20001 | M24: =SUM(F$13:F24) -> 9578
... A40: 28 | B40: SUNDAY | C40: ='LEVEL 4'!C40+'LEVEL 5'!C40+'LEVEL 6'!C40+'LEVEL 7'!C40+'LEVEL 8'!C40+'LEVEL 9'!C40+'LEVEL 10'!C40+'LEVEL 11'!C40+'LEVEL 12'!C40+'LEVEL 3'!C40+'SINUG-ANG VEIN'!C40+'L425'!C40+'L460'!C40 -> 0 | D40: ='LEVEL 4'!D40+'LEVEL 5'!D40+'LEVEL 6'!D40+'LEVEL 7'!D40+'LEVEL 8'!D40+'LEVEL 9'!D40+'LEVEL 10'!D40+'LEVEL 11'!D40+'LEVEL 12'!D40+'LEVEL 3'!D40+'SINUG-ANG VEIN'!D40+'L425'!D40+'L460'!D40 -> 0 | E40: ='LEVEL 4'!E40+'LEVEL 5'!E40+'LEVEL 6'!E40+'LEVEL 7'!E40+'LEVEL 8'!E40+'LEVEL 9'!E40+'LEVEL 10'!E40+'LEVEL 11'!E40+'LEVEL 12'!E40+'LEVEL 3'!E40+'SINUG-ANG VEIN'!E40+'L425'!E40+'L460'!E40 -> 0 | F40: ='LEVEL 4'!F40+'LEVEL 5'!F40+'LEVEL 6'!F40+'LEVEL 7'!F40+'LEVEL 8'!F40+'LEVEL 9'!F40+'LEVEL 10'!F40+'LEVEL 11'!F40+'LEVEL 12'!F40+'LEVEL 3'!F40+'SINUG-ANG VEIN'!F40+'L425'!F40+'L460'!F40 -> 0 | J40: =SUM(C$13:C40) -> 6771.6105 | K40: =SUM(D$13:D40) -> 21521.1 | L40: =SUM(E$13:E40) -> 30513 | M40: =SUM(F$13:F40) -> 14722
A41: 29 | B41: MONDAY | C41: ='LEVEL 4'!C41+'LEVEL 5'!C41+'LEVEL 6'!C41+'LEVEL 7'!C41+'LEVEL 8'!C41+'LEVEL 9'!C41+'LEVEL 10'!C41+'LEVEL 11'!C41+'LEVEL 12'!C41+'LEVEL 3'!C41+'SINUG-ANG VEIN'!C41+'L425'!C41+'L460'!C41 -> 0 | D41: ='LEVEL 4'!D41+'LEVEL 5'!D41+'LEVEL 6'!D41+'LEVEL 7'!D41+'LEVEL 8'!D41+'LEVEL 9'!D41+'LEVEL 10'!D41+'LEVEL 11'!D41+'LEVEL 12'!D41+'LEVEL 3'!D41+'SINUG-ANG VEIN'!D41+'L425'!D41+'L460'!D41 -> 0 | E41: ='LEVEL 4'!E41+'LEVEL 5'!E41+'LEVEL 6'!E41+'LEVEL 7'!E41+'LEVEL 8'!E41+'LEVEL 9'!E41+'LEVEL 10'!E41+'LEVEL 11'!E41+'LEVEL 12'!E41+'LEVEL 3'!E41+'SINUG-ANG VEIN'!E41+'L425'!E41+'L460'!E41 -> 0 | F41: ='LEVEL 4'!F41+'LEVEL 5'!F41+'LEVEL 6'!F41+'LEVEL 7'!F41+'LEVEL 8'!F41+'LEVEL 9'!F41+'LEVEL 10'!F41+'LEVEL 11'!F41+'LEVEL 12'!F41+'LEVEL 3'!F41+'SINUG-ANG VEIN'!F41+'L425'!F41+'L460'!F41 -> 0
A42: 30 | B42: TUESDAY | C42: ='LEVEL 4'!C42+'LEVEL 5'!C42+'LEVEL 6'!C42+'LEVEL 7'!C42+'LEVEL 8'!C42+'LEVEL 9'!C42+'LEVEL 10'!C42+'LEVEL 11'!C42+'LEVEL 12'!C42+'LEVEL 3'!C42+'SINUG-ANG VEIN'!C42+'L425'!C42+'L460'!C42 -> 0 | D42: ='LEVEL 4'!D42+'LEVEL 5'!D42+'LEVEL 6'!D42+'LEVEL 7'!D42+'LEVEL 8'!D42+'LEVEL 9'!D42+'LEVEL 10'!D42+'LEVEL 11'!D42+'LEVEL 12'!D42+'LEVEL 3'!D42+'SINUG-ANG VEIN'!D42+'L425'!D42+'L460'!D42 -> 0 | E42: ='LEVEL 4'!E42+'LEVEL 5'!E42+'LEVEL 6'!E42+'LEVEL 7'!E42+'LEVEL 8'!E42+'LEVEL 9'!E42+'LEVEL 10'!E42+'LEVEL 11'!E42+'LEVEL 12'!E42+'LEVEL 3'!E42+'SINUG-ANG VEIN'!E42+'L425'!E42+'L460'!E42 -> 0 | F42: ='LEVEL 4'!F42+'LEVEL 5'!F42+'LEVEL 6'!F42+'LEVEL 7'!F42+'LEVEL 8'!F42+'LEVEL 9'!F42+'LEVEL 10'!F42+'LEVEL 11'!F42+'LEVEL 12'!F42+'LEVEL 3'!F42+'SINUG-ANG VEIN'!F42+'L425'!F42+'L460'!F42 -> 0 | J42: =SUM(C$13:C42) -> 6771.6105 | K42: =SUM(D$13:D42) -> 21521.1 | L42: =SUM(E$13:E42) -> 30513 | M42: =SUM(F$13:F42) -> 14722
A43: 31 | B43: WEDNESDAY | C43: ='LEVEL 4'!C43+'LEVEL 5'!C43+'LEVEL 6'!C43+'LEVEL 7'!C43+'LEVEL 8'!C43+'LEVEL 9'!C43+'LEVEL 10'!C43+'LEVEL 11'!C43+'LEVEL 12'!C43+'LEVEL 3'!C43+'SINUG-ANG VEIN'!C43+'L425'!C43+'L460'!C43 -> 0 | D43: ='LEVEL 4'!D43+'LEVEL 5'!D43+'LEVEL 6'!D43+'LEVEL 7'!D43+'LEVEL 8'!D43+'LEVEL 9'!D43+'LEVEL 10'!D43+'LEVEL 11'!D43+'LEVEL 12'!D43+'LEVEL 3'!D43+'SINUG-ANG VEIN'!D43+'L425'!D43+'L460'!D43 -> 0 | E43: ='LEVEL 4'!E43+'LEVEL 5'!E43+'LEVEL 6'!E43+'LEVEL 7'!E43+'LEVEL 8'!E43+'LEVEL 9'!E43+'LEVEL 10'!E43+'LEVEL 11'!E43+'LEVEL 12'!E43+'LEVEL 3'!E43+'SINUG-ANG VEIN'!E43+'L425'!E43+'L460'!E43 -> 0 | F43: ='LEVEL 4'!F43+'LEVEL 5'!F43+'LEVEL 6'!F43+'LEVEL 7'!F43+'LEVEL 8'!F43+'LEVEL 9'!F43+'LEVEL 10'!F43+'LEVEL 11'!F43+'LEVEL 12'!F43+'LEVEL 3'!F43+'SINUG-ANG VEIN'!F43+'L425'!F43+'L460'!F43 -> 0 | G43: ='LEVEL 4'!G43+'LEVEL 5'!G43+'LEVEL 6'!G43+'LEVEL 7'!G43+'LEVEL 8'!G43+'LEVEL 9'!G43+'LEVEL 10'!G43+'LEVEL 11'!G43+'LEVEL 12'!G43+'LEVEL 3'!G43+'SINUG-ANG VEIN'!G43+'L425'!G43+'L460'!G43 -> 0 | H43: ='LEVEL 4'!H43+'LEVEL 5'!H43+'LEVEL 6'!H43+'LEVEL 7'!H43+'LEVEL 8'!H43+'LEVEL 9'!H43+'LEVEL 10'!H43+'LEVEL 11'!H43+'LEVEL 12'!H43+'LEVEL 3'!H43+'SINUG-ANG VEIN'!H43+'L425'!H43+'L460'!H43 -> 0 | J43: =SUM(C$13:C43) -> 6771.6105 | K43: =SUM(D$13:D43) -> 21521.1 | L43: =SUM(E$13:E43) -> 30513 | M43: =SUM(F$13:F43) -> 14722
C44: =SUBTOTAL(109,C13:C43) -> 6771.6105 | D44: =SUBTOTAL(109,D13:D43) -> 21521.1 | E44: =SUBTOTAL(109,E13:E43) -> 30513 | F44: =SUBTOTAL(109,F13:F43) -> 14722 | G44: =SUBTOTAL(109,G13:G43) -> 0 | H44: =SUBTOTAL(109,H13:H43) -> 0

Sheet LEVEL 3
B1: Mine Production | E1: Total W.Days | F1: ='ALL LEVELS'!F1 -> 30 | H1: ='ALL LEVELS'!H1 -> Month of JUNE 2026
B2: Day | C2: ='ALL LEVELS'!C2 -> 19
C3: DAILY | E3: MTD
B4: DELAY TYPE | C4: QUOTA | D4: ACTUAL | E4: QUOTA | F4: ACTUAL
B5: EMULSION
B6: ANFO
B7: DETONATORS
B8: DETCORDS
B10: TOTAL
J11: MTD
A12: DATE | B12: DAY | C12: EMULSION (KG) | D12: ANFO (KG) | E12: DETONATORS (PCS) | F12: DETCORDS (MTR) | J12: EMULSION | K12: ANFO | L12: DETONATORS | M12: DETCORDS
A13: ='ALL LEVELS'!A13 -> 1 | B13: ='ALL LEVELS'!B13 -> MONDAY | J13: =SUM(C$13:C13) -> 0 | K13: =SUM(D$13:D13) -> 0 | L13: =SUM(E$13:E13) -> 0 | M13: =SUM(F$13:F13) -> 0
A14: ='ALL LEVELS'!A14 -> 2 | B14: ='ALL LEVELS'!B14 -> TUESDAY | C14: 3.6046512 | D14: 23.6 | E14: 6 | F14: 21 | J14: =SUM(C$13:C14) -> 3.6046512 | K14: =SUM(D$13:D14) -> 23.6 | L14: =SUM(E$13:E14) -> 6 | M14: =SUM(F$13:F14) -> 21
A15: ='ALL LEVELS'!A15 -> 3 | B15: ='ALL LEVELS'!B15 -> WEDNESDAY | C15: 2.3255814 | D15: 0 | E15: 0 | F15: 0 | J15: =SUM(C$13:C15) -> 5.9302326 | K15: =SUM(D$13:D15) -> 23.6 | L15: =SUM(E$13:E15) -> 6 | M15: =SUM(F$13:F15) -> 21
A16: ='ALL LEVELS'!A16 -> 4 | B16: ='ALL LEVELS'!B16 -> THURSDAY | C16: 2.3255814 | D16: 0 | E16: 0 | F16: 15 | J16: =SUM(C$13:C16) -> 8.255814 | K16: =SUM(D$13:D16) -> 23.6 | L16: =SUM(E$13:E16) -> 6 | M16: =SUM(F$13:F16) -> 36
A17: ='ALL LEVELS'!A17 -> 5 | B17: ='ALL LEVELS'!B17 -> FRIDAY | C17: 3.4883721 | D17: 0 | E17: 0 | F17: 0 | J17: =SUM(C$13:C17) -> 11.744186 | K17: =SUM(D$13:D17) -> 23.6 | L17: =SUM(E$13:E17) -> 6 | M17: =SUM(F$13:F17) -> 36
A18: ='ALL LEVELS'!A18 -> 6 | B18: ='ALL LEVELS'!B18 -> SATURDAY | C18: 2.3255814 | D18: 0 | E18: 0 | F18: 0 | J18: =SUM(C$13:C18) -> 14.069767 | K18: =SUM(D$13:D18) -> 23.6 | L18: =SUM(E$13:E18) -> 6 | M18: =SUM(F$13:F18) -> 36
A19: ='ALL LEVELS'!A19 -> 7 | B19: ='ALL LEVELS'!B19 -> SUNDAY | J19: =SUM(C$13:C19) -> 14.069767 | K19: =SUM(D$13:D19) -> 23.6 | L19: =SUM(E$13:E19) -> 6 | M19: =SUM(F$13:F19) -> 36
A20: ='ALL LEVELS'!A20 -> 8 | B20: ='ALL LEVELS'!B20 -> MONDAY | J20: =SUM(C$13:C20) -> 14.069767 | K20: =SUM(D$13:D20) -> 23.6 | L20: =SUM(E$13:E20) -> 6 | M20: =SUM(F$13:F20) -> 36
A21: ='ALL LEVELS'!A21 -> 9 | B21: ='ALL LEVELS'!B21 -> TUESDAY | J21: =SUM(C$13:C21) -> 14.069767 | K21: =SUM(D$13:D21) -> 23.6 | L21: =SUM(E$13:E21) -> 6 | M21: =SUM(F$13:F21) -> 36
A22: ='ALL LEVELS'!A22 -> 10 | B22: ='ALL LEVELS'!B22 -> WEDNESDAY | J22: =SUM(C$13:C22) -> 14.069767 | K22: =SUM(D$13:D22) -> 23.6 | L22: =SUM(E$13:E22) -> 6 | M22: =SUM(F$13:F22) -> 36
A23: ='ALL LEVELS'!A23 -> 11 | B23: ='ALL LEVELS'!B23 -> THURSDAY | J23: =SUM(C$13:C23) -> 14.069767 | K23: =SUM(D$13:D23) -> 23.6 | L23: =SUM(E$13:E23) -> 6 | M23: =SUM(F$13:F23) -> 36
A24: ='ALL LEVELS'!A24 -> 12 | B24: ='ALL LEVELS'!B24 -> FRIDAY | J24: =SUM(C$13:C24) -> 14.069767 | K24: =SUM(D$13:D24) -> 23.6 | L24: =SUM(E$13:E24) -> 6 | M24: =SUM(F$13:F24) -> 36
A25: ='ALL LEVELS'!A25 -> 13 | B25: ='ALL LEVELS'!B25 -> SATURDAY | C25: 1.744186 | D25: 10 | E25: 0 | F25: 10 | J25: =SUM(C$13:C25) -> 15.813953 | K25: =SUM(D$13:D25) -> 33.6 | L25: =SUM(E$13:E25) -> 6 | M25: =SUM(F$13:F25) -> 46
A26: ='ALL LEVELS'!A26 -> 14 | B26: ='ALL LEVELS'!B26 -> SUNDAY | J26: =SUM(C$13:C26) -> 15.813953 | K26: =SUM(D$13:D26) -> 33.6 | L26: =SUM(E$13:E26) -> 6 | M26: =SUM(F$13:F26) -> 46
A27: ='ALL LEVELS'!A27 -> 15 | B27: ='ALL LEVELS'!B27 -> MONDAY | J27: =SUM(C$13:C27) -> 15.813953 | K27: =SUM(D$13:D27) -> 33.6 | L27: =SUM(E$13:E27) -> 6 | M27: =SUM(F$13:F27) -> 46
A28: ='ALL LEVELS'!A28 -> 16 | B28: ='ALL LEVELS'!B28 -> TUESDAY | J28: =SUM(C$13:C28) -> 15.813953 | K28: =SUM(D$13:D28) -> 33.6 | L28: =SUM(E$13:E28) -> 6 | M28: =SUM(F$13:F28) -> 46
A29: ='ALL LEVELS'!A29 -> 17 | B29: ='ALL LEVELS'!B29 -> WEDNESDAY | C29: 2.3255814 | D29: 0 | E29: 0 | F29: 10 | J29: =SUM(C$13:C29) -> 18.139535 | K29: =SUM(D$13:D29) -> 33.6 | L29: =SUM(E$13:E29) -> 6 | M29: =SUM(F$13:F29) -> 56
A30: ='ALL LEVELS'!A30 -> 18 | B30: ='ALL LEVELS'!B30 -> THURSDAY | J30: =SUM(C$13:C30) -> 18.139535 | K30: =SUM(D$13:D30) -> 33.6 | L30: =SUM(E$13:E30) -> 6 | M30: =SUM(F$13:F30) -> 56
A31: ='ALL LEVELS'!A31 -> 19 | B31: ='ALL LEVELS'!B31 -> FRIDAY | J31: =SUM(C$13:C31) -> 18.139535 | K31: =SUM(D$13:D31) -> 33.6 | L31: =SUM(E$13:E31) -> 6 | M31: =SUM(F$13:F31) -> 56
A32: ='ALL LEVELS'!A32 -> 20 | B32: ='ALL LEVELS'!B32 -> SATURDAY | J32: =SUM(C$13:C32) -> 18.139535 | K32: =SUM(D$13:D32) -> 33.6 | L32: =SUM(E$13:E32) -> 6 | M32: =SUM(F$13:F32) -> 56
A33: ='ALL LEVELS'!A33 -> 21 | B33: ='ALL LEVELS'!B33 -> SUNDAY | J33: =SUM(C$13:C33) -> 18.139535 | K33: =SUM(D$13:D33) -> 33.6 | L33: =SUM(E$13:E33) -> 6 | M33: =SUM(F$13:F33) -> 56
A34: ='ALL LEVELS'!A34 -> 22 | B34: ='ALL LEVELS'!B34 -> MONDAY | J34: =SUM(C$13:C34) -> 18.139535 | K34: =SUM(D$13:D34) -> 33.6 | L34: =SUM(E$13:E34) -> 6 | M34: =SUM(F$13:F34) -> 56
A35: ='ALL LEVELS'!A35 -> 23 | B35: ='ALL LEVELS'!B35 -> TUESDAY | J35: =SUM(C$13:C35) -> 18.139535 | K35: =SUM(D$13:D35) -> 33.6 | L35: =SUM(E$13:E35) -> 6 | M35: =SUM(F$13:F35) -> 56
A36: ='ALL LEVELS'!A36 -> 24 | B36: ='ALL LEVELS'!B33 -> SUNDAY | J36: =SUM(C$13:C36) -> 18.139535 | K36: =SUM(D$13:D36) -> 33.6 | L36: =SUM(E$13:E36) -> 6 | M36: =SUM(F$13:F36) -> 56
A37: ='ALL LEVELS'!A37 -> 25 | B37: ='ALL LEVELS'!B34 -> MONDAY | J37: =SUM(C$13:C37) -> 18.139535 | K37: =SUM(D$13:D37) -> 33.6 | L37: =SUM(E$13:E37) -> 6 | M37: =SUM(F$13:F37) -> 56
A38: ='ALL LEVELS'!A38 -> 26 | B38: ='ALL LEVELS'!B35 -> TUESDAY | J38: =SUM(C$13:C38) -> 18.139535 | K38: =SUM(D$13:D38) -> 33.6 | L38: =SUM(E$13:E38) -> 6 | M38: =SUM(F$13:F38) -> 56
A39: ='ALL LEVELS'!A39 -> 27 | B39: ='ALL LEVELS'!B36 -> WEDNESDAY | J39: =SUM(C$13:C39) -> 18.139535 | K39: =SUM(D$13:D39) -> 33.6 | L39: =SUM(E$13:E39) -> 6 | M39: =SUM(F$13:F39) -> 56
A40: ='ALL LEVELS'!A40 -> 28 | B40: ='ALL LEVELS'!B40 -> SUNDAY | J40: =SUM(C$13:C40) -> 18.139535 | K40: =SUM(D$13:D40) -> 33.6 | L40: =SUM(E$13:E40) -> 6 | M40: =SUM(F$13:F40) -> 56
A41: ='ALL LEVELS'!A41 -> 29 | B41: ='ALL LEVELS'!B41 -> MONDAY
...

Sheet LEVEL 4
B1: Mine Production | E1: Total W.Days | F1: ='ALL LEVELS'!F1 -> 30 | H1: ='ALL LEVELS'!H1 -> Month of JUNE 2026
B2: Day | C2: ='ALL LEVELS'!C2 -> 19
C3: DAILY | E3: MTD
B4: DELAY TYPE | C4: QUOTA | D4: ACTUAL | E4: QUOTA | F4: ACTUAL
B5: EMULSION
B6: ANFO
B7: DETONATORS
B8: DETCORDS
B10: TOTAL
J11: MTD
A12: DATE | B12: DAY | C12: EMULSION (KG) | D12: ANFO (KG) | E12: DETONATORS (PCS) | F12: DETCORDS (MTR) | J12: EMULSION | K12: ANFO | L12: DETONATORS | M12: DETCORDS
A13: ='ALL LEVELS'!A13 -> 1 | B13: ='ALL LEVELS'!B13 -> MONDAY | J13: =SUM(C$13:C13) -> 0 | K13: =SUM(D$13:D13) -> 0 | L13: =SUM(E$13:E13) -> 0 | M13: =SUM(F$13:F13) -> 0
A14: ='ALL LEVELS'!A14 -> 2 | B14: ='ALL LEVELS'!B14 -> TUESDAY | J14: =SUM(C$13:C14) -> 0 | K14: =SUM(D$13:D14) -> 0 | L14: =SUM(E$13:E14) -> 0 | M14: =SUM(F$13:F14) -> 0
A15: ='ALL LEVELS'!A15 -> 3 | B15: ='ALL LEVELS'!B15 -> WEDNESDAY | J15: =SUM(C$13:C15) -> 0 | K15: =SUM(D$13:D15) -> 0 | L15: =SUM(E$13:E15) -> 0 | M15: =SUM(F$13:F15) -> 0
A16: ='ALL LEVELS'!A16 -> 4 | B16: ='ALL LEVELS'!B16 -> THURSDAY | J16: =SUM(C$13:C16) -> 0 | K16: =SUM(D$13:D16) -> 0 | L16: =SUM(E$13:E16) -> 0 | M16: =SUM(F$13:F16) -> 0
A17: ='ALL LEVELS'!A17 -> 5 | B17: ='ALL LEVELS'!B17 -> FRIDAY | J17: =SUM(C$13:C17) -> 0 | K17: =SUM(D$13:D17) -> 0 | L17: =SUM(E$13:E17) -> 0 | M17: =SUM(F$13:F17) -> 0
A18: ='ALL LEVELS'!A18 -> 6 | B18: ='ALL LEVELS'!B18 -> SATURDAY | J18: =SUM(C$13:C18) -> 0 | K18: =SUM(D$13:D18) -> 0 | L18: =SUM(E$13:E18) -> 0 | M18: =SUM(F$13:F18) -> 0
A19: ='ALL LEVELS'!A19 -> 7 | B19: ='ALL LEVELS'!B19 -> SUNDAY | J19: =SUM(C$13:C19) -> 0 | K19: =SUM(D$13:D19) -> 0 | L19: =SUM(E$13:E19) -> 0 | M19: =SUM(F$13:F19) -> 0
A20: ='ALL LEVELS'!A20 -> 8 | B20: ='ALL LEVELS'!B20 -> MONDAY | J20: =SUM(C$13:C20) -> 0 | K20: =SUM(D$13:D20) -> 0 | L20: =SUM(E$13:E20) -> 0 | M20: =SUM(F$13:F20) -> 0
A21: ='ALL LEVELS'!A21 -> 9 | B21: ='ALL LEVELS'!B21 -> TUESDAY | J21: =SUM(C$13:C21) -> 0 | K21: =SUM(D$13:D21) -> 0 | L21: =SUM(E$13:E21) -> 0 | M21: =SUM(F$13:F21) -> 0
A22: ='ALL LEVELS'!A22 -> 10 | B22: ='ALL LEVELS'!B22 -> WEDNESDAY | J22: =SUM(C$13:C22) -> 0 | K22: =SUM(D$13:D22) -> 0 | L22: =SUM(E$13:E22) -> 0 | M22: =SUM(F$13:F22) -> 0
A23: ='ALL LEVELS'!A23 -> 11 | B23: ='ALL LEVELS'!B23 -> THURSDAY | J23: =SUM(C$13:C23) -> 0 | K23: =SUM(D$13:D23) -> 0 | L23: =SUM(E$13:E23) -> 0 | M23: =SUM(F$13:F23) -> 0
A24: ='ALL LEVELS'!A24 -> 12 | B24: ='ALL LEVELS'!B24 -> FRIDAY | J24: =SUM(C$13:C24) -> 0 | K24: =SUM(D$13:D24) -> 0 | L24: =SUM(E$13:E24) -> 0 | M24: =SUM(F$13:F24) -> 0
... A34: ='ALL LEVELS'!A34 -> 22 | B34: ='ALL LEVELS'!B34 -> MONDAY | J34: =SUM(C$13:C34) -> 0 | K34: =SUM(D$13:D34) -> 0 | L34: =SUM(E$13:E34) -> 0 | M34: =SUM(F$13:F34) -> 0
A35: ='ALL LEVELS'!A35 -> 23 | B35: ='ALL LEVELS'!B32 -> SATURDAY | J35: =SUM(C$13:C35) -> 0 | K35: =SUM(D$13:D35) -> 0 | L35: =SUM(E$13:E35) -> 0 | M35: =SUM(F$13:F35) -> 0
A36: ='ALL LEVELS'!A36 -> 24 | B36: ='ALL LEVELS'!B33 -> SUNDAY | J36: =SUM(C$13:C36) -> 0 | K36: =SUM(D$13:D36) -> 0 | L36: =SUM(E$13:E36) -> 0 | M36: =SUM(F$13:F36) -> 0
A37: ='ALL LEVELS'!A37 -> 25 | B37: ='ALL LEVELS'!B34 -> MONDAY | J37: =SUM(C$13:C37) -> 0 | K37: =SUM(D$13:D37) -> 0 | L37: =SUM(E$13:E37) -> 0 | M37: =SUM(F$13:F37) -> 0
A38: ='ALL LEVELS'!A38 -> 26 | B38: ='ALL LEVELS'!B35 -> TUESDAY | J38: =SUM(C$13:C38) -> 0 | K38: =SUM(D$13:D38) -> 0 | L38: =SUM(E$13:E38) -> 0 | M38: =SUM(F$13:F38) -> 0
A39: ='ALL LEVELS'!A39 -> 27 | B39: ='ALL LEVELS'!B36 -> WEDNESDAY | J39: =SUM(C$13:C39) -> 0 | K39: =SUM(D$13:D39) -> 0 | L39: =SUM(E$13:E39) -> 0 | M39: =SUM(F$13:F39) -> 0
A40: ='ALL LEVELS'!A40 -> 28 | B40: ='ALL LEVELS'!B40 -> SUNDAY | J40: =SUM(C$13:C40) -> 0 | K40: =SUM(D$13:D40) -> 0 | L40: =SUM(E$13:E40) -> 0 | M40: =SUM(F$13:F40) -> 0
A41: ='ALL LEVELS'!A41 -> 29 | B41: ='ALL LEVELS'!B41 -> MONDAY
A42: ='ALL LEVELS'!A42 -> 30 | B42: ='ALL LEVELS'!B42 -> TUESDAY | J42: =SUM(C$13:C42) -> 0 | K42: =SUM(D$13:D42) -> 0 | L42: =SUM(E$13:E42) -> 0 | M42: =SUM(F$13:F42) -> 0
A43: ='ALL LEVELS'!A43 -> 31 | B43: ='ALL LEVELS'!B43 -> WEDNESDAY | J43: =SUM(C$13:C43) -> 0 | K43: =SUM(D$13:D43) -> 0 | L43: =SUM(E$13:E43) -> 0 | M43: =SUM(F$13:F43) -> 0
C44: =SUBTOTAL(109,C13:C43) -> 0 | D44: =SUBTOTAL(109,D13:D43) -> 0 | E44: =SUBTOTAL(109,E13:E43) -> 0 | F44: =SUBTOTAL(109,F13:F43) -> 0 | G44: =SUBTOTAL(109,G13:G43) -> 0 | H44: =SUBTOTAL(109,H13:H43) -> 0

Sheet LEVEL 5
B1: Mine Production | E1: Total W.Days | F1: ='ALL LEVELS'!F1 -> 30 | H1: ='ALL LEVELS'!H1 -> Month of JUNE 2026
B2: Day | C2: ='ALL LEVELS'!C2 -> 19
C3: DAILY | E3: MTD
B4: DELAY TYPE | C4: QUOTA | D4: ACTUAL | E4: QUOTA | F4: ACTUAL
B5: EMULSION
B6: ANFO
B7: DETONATORS
B8: DETCORDS
B10: TOTAL
J11: MTD
A12: DATE | B12: DAY | C12: EMULSION (KG) | D12: ANFO (KG) | E12: DETONATORS (PCS) | F12: DETCORDS (MTR) | J12: EMULSION | K12: ANFO | L12: DETONATORS | M12: DETCORDS
A13: ='ALL LEVELS'!A13 -> 1 | B13: ='ALL LEVELS'!B13 -> MONDAY | J13: =SUM(C$13:C13) -> 0 | K13: =SUM(D$13:D13) -> 0 | L13: =SUM(E$13:E13) -> 0 | M13: =SUM(F$13:F13) -> 0
A14: ='ALL LEVELS'!A14 -> 2 | B14: ='ALL LEVELS'!B14 -> TUESDAY | J14: =SUM(C$13:C14) -> 0 | K14: =SUM(D$13:D14) -> 0 | L14: =SUM(E$13:E14) -> 0 | M14: =SUM(F$13:F14) -> 0
A15: ='ALL LEVELS'!A15 -> 3 | B15: ='ALL LEVELS'!B15 -> WEDNESDAY | J15: =SUM(C$13:C15) -> 0 | K15: =SUM(D$13:D15) -> 0 | L15: =SUM(E$13:E15) -> 0 | M15: =SUM(F$13:F15) -> 0
A16: ='ALL LEVELS'!A16 -> 4 | B16: ='ALL LEVELS'!B16 -> THURSDAY | J16: =SUM(C$13:C16) -> 0 | K16: =SUM(D$13:D16) -> 0 | L16: =SUM(E$13:E16) -> 0 | M16: =SUM(F$13:F16) -> 0
A17: ='ALL LEVELS'!A17 -> 5 | B17: ='ALL LEVELS'!B17 -> FRIDAY | J17: =SUM(C$13:C17) -> 0 | K17: =SUM(D$13:D17) -> 0 | L17: =SUM(E$13:E17) -> 0 | M17: =SUM(F$13:F17) -> 0
A18: ='ALL LEVELS'!A18 -> 6 | B18: ='ALL LEVELS'!B18 -> SATURDAY | J18: =SUM(C$13:C18) -> 0 | K18: =SUM(D$13:D18) -> 0 | L18: =SUM(E$13:E18) -> 0 | M18: =SUM(F$13:F18) -> 0
A19: ='ALL LEVELS'!A19 -> 7 | B19: ='ALL LEVELS'!B19 -> SUNDAY | J19: =SUM(C$13:C19) -> 0 | K19: =SUM(D$13:D19) -> 0 | L19: =SUM(E$13:E19) -> 0 | M19: =SUM(F$13:F19) -> 0
A20: ='ALL LEVELS'!A20 -> 8 | B20: ='ALL LEVELS'!B20 -> MONDAY | J20: =SUM(C$13:C20) -> 0 | K20: =SUM(D$13:D20) -> 0 | L20: =SUM(E$13:E20) -> 0 | M20: =SUM(F$13:F20) -> 0
A21: ='ALL LEVELS'!A21 -> 9 | B21: ='ALL LEVELS'!B21 -> TUESDAY | J21: =SUM(C$13:C21) -> 0 | K21: =SUM(D$13:D21) -> 0 | L21: =SUM(E$13:E21) -> 0 | M21: =SUM(F$13:F21) -> 0
A22: ='ALL LEVELS'!A22 -> 10 | B22: ='ALL LEVELS'!B22 -> WEDNESDAY | J22: =SUM(C$13:C22) -> 0 | K22: =SUM(D$13:D22) -> 0 | L22: =SUM(E$13:E22) -> 0 | M22: =SUM(F$13:F22) -> 0
A23: ='ALL LEVELS'!A23 -> 11 | B23: ='ALL LEVELS'!B23 -> THURSDAY | J23: =SUM(C$13:C23) -> 0 | K23: =SUM(D$13:D23) -> 0 | L23: =SUM(E$13:E23) -> 0 | M23: =SUM(F$13:F23) -> 0
A24: ='ALL LEVELS'!A24 -> 12 | B24: ='ALL LEVELS'!B24 -> FRIDAY | J24: =SUM(C$13:C24) -> 0 | K24: =SUM(D$13:D24) -> 0 | L24: =SUM(E$13:E24) -> 0 | M24: =SUM(F$13:F24) -> 0
... A35: ='ALL LEVELS'!A35 -> 23 | B35: ='ALL LEVELS'!B35 -> TUESDAY | J35: =SUM(C$13:C35) -> 0 | K35: =SUM(D$13:D35) -> 0 | L35: =SUM(E$13:E35) -> 0 | M35: =SUM(F$13:F35) -> 0
A36: ='ALL LEVELS'!A36 -> 24 | B36: ='ALL LEVELS'!B33 -> SUNDAY | J36: =SUM(C$13:C36) -> 0 | K36: =SUM(D$13:D36) -> 0 | L36: =SUM(E$13:E36) -> 0 | M36: =SUM(F$13:F36) -> 0
A37: ='ALL LEVELS'!A37 -> 25 | B37: ='ALL LEVELS'!B34 -> MONDAY | J37: =SUM(C$13:C37) -> 0 | K37: =SUM(D$13:D37) -> 0 | L37: =SUM(E$13:E37) -> 0 | M37: =SUM(F$13:F37) -> 0
A38: ='ALL LEVELS'!A38 -> 26 | B38: ='ALL LEVELS'!B35 -> TUESDAY | J38: =SUM(C$13:C38) -> 0 | K38: =SUM(D$13:D38) -> 0 | L38: =SUM(E$13:E38) -> 0 | M38: =SUM(F$13:F38) -> 0
A39: ='ALL LEVELS'!A39 -> 27 | B39: ='ALL LEVELS'!B36 -> WEDNESDAY | J39: =SUM(C$13:C39) -> 0 | K39: =SUM(D$13:D39) -> 0 | L39: =SUM(E$13:E39) -> 0 | M39: =SUM(F$13:F39) -> 0
A40: ='ALL LEVELS'!A40 -> 28 | B40: ='ALL LEVELS'!B40 -> SUNDAY | J40: =SUM(C$13:C40) -> 0 | K40: =SUM(D$13:D40) -> 0 | L40: =SUM(E$13:E40) -> 0 | M40: =SUM(F$13:F40) -> 0
A41: ='ALL LEVELS'!A41 -> 29 | B41: ='ALL LEVELS'!B41 -> MONDAY
A42: ='ALL LEVELS'!A42 -> 30 | B42: ='ALL LEVELS'!B42 -> TUESDAY | J42: =SUM(C$13:C42) -> 0 | K42: =SUM(D$13:D42) -> 0 | L42: =SUM(E$13:E42) -> 0 | M42: =SUM(F$13:F42) -> 0
A43: ='ALL LEVELS'!A43 -> 31 | B43: ='ALL LEVELS'!B43 -> WEDNESDAY | J43: =SUM(C$13:C43) -> 0 | K43: =SUM(D$13:D43) -> 0 | L43: =SUM(E$13:E43) -> 0 | M43: =SUM(F$13:F43) -> 0
C44: =SUBTOTAL(109,C13:C43) -> 0 | D44: =SUBTOTAL(109,D13:D43) -> 0 | E44: =SUBTOTAL(109,E13:E43) -> 0 | F44: =SUBTOTAL(109,F13:F43) -> 0 | G44: =SUBTOTAL(109,G13:G43) -> 0 | H44: =SUBTOTAL(109,H13:H43) -> 0

Sheet LEVEL 6
B1: Mine Production | E1: Total W.Days | F1: ='ALL LEVELS'!F1 -> 30 | H1: ='ALL LEVELS'!H1 -> Month of JUNE 2026
B2: Day | C2: ='ALL LEVELS'!C2 -> 19
C3: DAILY | E3: MTD
B4: DELAY TYPE | C4: QUOTA | D4: ACTUAL | E4: QUOTA | F4: ACTUAL
B5: EMULSION
B6: ANFO
B7: DETONATORS
B8: DETCORDS
B10: TOTAL
J11: MTD
A12: DATE | B12: DAY | C12: EMULSION (KG) | D12: ANFO (KG) | E12: DETONATORS (PCS) | F12: DETCORDS (MTR) | J12: EMULSION | K12: ANFO | L12: DETONATORS | M12: DETCORDS
A13: ='ALL LEVELS'!A13 -> 1 | B13: ='ALL LEVELS'!B13 -> MONDAY | J13: =SUM(C$13:C13) -> 0 | K13: =SUM(D$13:D13) -> 0 | L13: =SUM(E$13:E13) -> 0 | M13: =SUM(F$13:F13) -> 0
A14: ='ALL LEVELS'!A14 -> 2 | B14: ='ALL LEVELS'!B14 -> TUESDAY | J14: =SUM(C$13:C14) -> 0 | K14: =SUM(D$13:D14) -> 0 | L14: =SUM(E$13:E14) -> 0 | M14: =SUM(F$13:F14) -> 0
A15: ='ALL LEVELS'!A15 -> 3 | B15: ='ALL LEVELS'!B15 -> WEDNESDAY | J15: =SUM(C$13:C15) -> 0 | K15: =SUM(D$13:D15) -> 0 | L15: =SUM(E$13:E15) -> 0 | M15: =SUM(F$13:F15) -> 0
A16: ='ALL LEVELS'!A16 -> 4 | B16: ='ALL LEVELS'!B16 -> THURSDAY | J16: =SUM(C$13:C16) -> 0 | K16: =SUM(D$13:D16) -> 0 | L16: =SUM(E$13:E16) -> 0 | M16: =SUM(F$13:F16) -> 0
A17: ='ALL LEVELS'!A17 -> 5 | B17: ='ALL LEVELS'!B17 -> FRIDAY | J17: =SUM(C$13:C17) -> 0 | K17: =SUM(D$13:D17) -> 0 | L17: =SUM(E$13:E17) -> 0 | M17: =SUM(F$13:F17) -> 0
A18: ='ALL LEVELS'!A18 -> 6 | B18: ='ALL LEVELS'!B18 -> SATURDAY | J18: =SUM(C$13:C18) -> 0 | K18: =SUM(D$13:D18) -> 0 | L18: =SUM(E$13:E18) -> 0 | M18: =SUM(F$13:F18) -> 0
A19: ='ALL LEVELS'!A19 -> 7 | B19: ='ALL LEVELS'!B19 -> SUNDAY | J19: =SUM(C$13:C19) -> 0 | K19: =SUM(D$13:D19) -> 0 | L19: =SUM(E$13:E19) -> 0 | M19: =SUM(F$13:F19) -> 0
A20: ='ALL LEVELS'!A20 -> 8 | B20: ='ALL LEVELS'!B20 -> MONDAY | J20: =SUM(C$13:C20) -> 0 | K20: =SUM(D$13:D20) -> 0 | L20: =SUM(E$13:E20) -> 0 | M20: =SUM(F$13:F20) -> 0
A21: ='ALL LEVELS'!A21 -> 9 | B21: ='ALL LEVELS'!B21 -> TUESDAY | J21: =SUM(C$13:C21) -> 0 | K21: =SUM(D$13:D21) -> 0 | L21: =SUM(E$13:E21) -> 0 | M21: =SUM(F$13:F21) -> 0
A22: ='ALL LEVELS'!A22 -> 10 | B22: ='ALL LEVELS'!B22 -> WEDNESDAY | J22: =SUM(C$13:C22) -> 0 | K22: =SUM(D$13:D22) -> 0 | L22: =SUM(E$13:E22) -> 0 | M22: =SUM(F$13:F22) -> 0
A23: ='ALL LEVELS'!A23 -> 11 | B23: ='ALL LEVELS'!B23 -> THURSDAY | J23: =SUM(C$13:C23) -> 0 | K23: =SUM(D$13:D23) -> 0 | L23: =SUM(E$13:E23) -> 0 | M23: =SUM(F$13:F23) -> 0
A24: ='ALL LEVELS'!A24 -> 12 | B24: ='ALL LEVELS'!B24 -> FRIDAY | J24: =SUM(C$13:C24) -> 0 | K24: =SUM(D$13:D24) -> 0 | L24: =SUM(E$13:E24) -> 0 | M24: =SUM(F$13:F24) -> 0
... A35: ='ALL LEVELS'!A35 -> 23 | B35: ='ALL LEVELS'!B35 -> TUESDAY | J35: =SUM(C$13:C35) -> 0 | K35: =SUM(D$13:D35) -> 0 | L35: =SUM(E$13:E35) -> 0 | M35: =SUM(F$13:F35) -> 0
A36: ='ALL LEVELS'!A36 -> 24 | B36: ='ALL LEVELS'!B33 -> SUNDAY | J36: =SUM(C$13:C36) -> 0 | K36: =SUM(D$13:D36) -> 0 | L36: =SUM(E$13:E36) -> 0 | M36: =SUM(F$13:F36) -> 0
A37: ='ALL LEVELS'!A37 -> 25 | B37: ='ALL LEVELS'!B34 -> MONDAY | J37: =SUM(C$13:C37) -> 0 | K37: =SUM(D$13:D37) -> 0 | L37: =SUM(E$13:E37) -> 0 | M37: =SUM(F$13:F37) -> 0
A38: ='ALL LEVELS'!A38 -> 26 | B38: ='ALL LEVELS'!B35 -> TUESDAY | J38: =SUM(C$13:C38) -> 0 | K38: =SUM(D$13:D38) -> 0 | L38: =SUM(E$13:E38) -> 0 | M38: =SUM(F$13:F38) -> 0
A39: ='ALL LEVELS'!A39 -> 27 | B39: ='ALL LEVELS'!B36 -> WEDNESDAY | J39: =SUM(C$13:C39) -> 0 | K39: =SUM(D$13:D39) -> 0 | L39: =SUM(E$13:E39) -> 0 | M39: =SUM(F$13:F39) -> 0
A40: ='ALL LEVELS'!A40 -> 28 | B40: ='ALL LEVELS'!B40 -> SUNDAY | J40: =SUM(C$13:C40) -> 0 | K40: =SUM(D$13:D40) -> 0 | L40: =SUM(E$13:E40) -> 0 | M40: =SUM(F$13:F40) -> 0
A41: ='ALL LEVELS'!A41 -> 29 | B41: ='ALL LEVELS'!B41 -> MONDAY
A42: ='ALL LEVELS'!A42 -> 30 | B42: ='ALL LEVELS'!B42 -> TUESDAY | J42: =SUM(C$13:C42) -> 0 | K42: =SUM(D$13:D42) -> 0 | L42: =SUM(E$13:E42) -> 0 | M42: =SUM(F$13:F42) -> 0
A43: ='ALL LEVELS'!A43 -> 31 | B43: ='ALL LEVELS'!B43 -> WEDNESDAY | J43: =SUM(C$13:C43) -> 0 | K43: =SUM(D$13:D43) -> 0 | L43: =SUM(E$13:E43) -> 0 | M43: =SUM(F$13:F43) -> 0
C44: =SUBTOTAL(109,C13:C43) -> 0 | D44: =SUBTOTAL(109,D13:D43) -> 0 | E44: =SUBTOTAL(109,E13:E43) -> 0 | F44: =SUBTOTAL(109,F13:F43) -> 0 | G44: =SUBTOTAL(109,G13:G43) -> 0 | H44: =SUBTOTAL(109,H13:H43) -> 0

Sheet LEVEL 7
B1: Mine Production | E1: Total W.Days | F1: ='ALL LEVELS'!F1 -> 30 | H1: ='ALL LEVELS'!H1 -> Month of JUNE 2026
B2: Day | C2: ='ALL LEVELS'!C2 -> 19
C3: DAILY | E3: MTD
B4: DELAY TYPE | C4: QUOTA | D4: ACTUAL | E4: QUOTA | F4: ACTUAL
B5: EMULSION
B6: ANFO
B7: DETONATORS
B8: DETCORDS
B10: TOTAL
J11: MTD
A12: DATE | B12: DAY | C12: EMULSION (KG) | D12: ANFO (KG) | E12: DETONATORS (PCS) | F12: DETCORDS (MTR) | J12: EMULSION | K12: ANFO | L12: DETONATORS | M12: DETCORDS
A13: ='ALL LEVELS'!A13 -> 1 | B13: ='ALL LEVELS'!B13 -> MONDAY | C13: 5.3488372 | D13: 17.6 | E13: 26 | F13: 8 | J13: =SUM(C$13:C13) -> 5.3488372 | K13: =SUM(D$13:D13) -> 17.6 | L13: =SUM(E$13:E13) -> 26 | M13: =SUM(F$13:F13) -> 8
A14: ='ALL LEVELS'!A14 -> 2 | B14: ='ALL LEVELS'!B14 -> TUESDAY | J14: =SUM(C$13:C14) -> 5.3488372 | K14: =SUM(D$13:D14) -> 17.6 | L14: =SUM(E$13:E14) -> 26 | M14: =SUM(F$13:F14) -> 8
A15: ='ALL LEVELS'!A15 -> 3 | B15: ='ALL LEVELS'!B15 -> WEDNESDAY | C15: 5.3488372 | D15: 17.6 | E15: 26 | F15: 10 | J15: =SUM(C$13:C15) -> 10.697674 | K15: =SUM(D$13:D15) -> 35.2 | L15: =SUM(E$13:E15) -> 52 | M15: =SUM(F$13:F15) -> 18
A16: ='ALL LEVELS'!A16 -> 4 | B16: ='ALL LEVELS'!B16 -> THURSDAY | J16: =SUM(C$13:C16) -> 10.697674 | K16: =SUM(D$13:D16) -> 35.2 | L16: =SUM(E$13:E16) -> 52 | M16: =SUM(F$13:F16) -> 18
A17: ='ALL LEVELS'!A17 -> 5 | B17: ='ALL LEVELS'!B17 -> FRIDAY | C17: 5.2325581 | D17: 16.8 | E17: 25 | F17: 8 | J17: =SUM(C$13:C17) -> 15.930233 | K17: =SUM(D$13:D17) -> 52 | L17: =SUM(E$13:E17) -> 77 | M17: =SUM(F$13:F17) -> 26
A18: ='ALL LEVELS'!A18 -> 6 | B18: ='ALL LEVELS'!B18 -> SATURDAY | J18: =SUM(C$13:C18) -> 15.930233 | K18: =SUM(D$13:D18) -> 52 | L18: =SUM(E$13:E18) -> 77 | M18: =SUM(F$13:F18) -> 26
A19: ='ALL LEVELS'!A19 -> 7 | B19: ='ALL LEVELS'!B19 -> SUNDAY | J19: =SUM(C$13:C19) -> 15.930233 | K19: =SUM(D$13:D19) -> 52 | L19: =SUM(E$13:E19) -> 77 | M19: =SUM(F$13:F19) -> 26
A20: ='ALL LEVELS'!A20 -> 8 | B20: ='ALL LEVELS'!B20 -> MONDAY | C20: 5.3488372 | D20: 17.6 | E20: 26 | F20: 8 | J20: =SUM(C$13:C20) -> 21.27907 | K20: =SUM(D$13:D20) -> 69.6 | L20: =SUM(E$13:E20) -> 103 | M20: =SUM(F$13:F20) -> 34
A21: ='ALL LEVELS'!A21 -> 9 | B21: ='ALL LEVELS'!B21 -> TUESDAY | J21: =SUM(C$13:C21) -> 21.27907 | K21: =SUM(D$13:D21) -> 69.6 | L21: =SUM(E$13:E21) -> 103 | M21: =SUM(F$13:F21) -> 34
A22: ='ALL LEVELS'!A22 -> 10 | B22: ='ALL LEVELS'!B22 -> WEDNESDAY | C22: 5.6976744 | D22: 20 | E22: 29 | F22: 8 | J22: =SUM(C$13:C22) -> 26.976744 | K22: =SUM(D$13:D22) -> 89.6 | L22: =SUM(E$13:E22) -> 132 | M22: =SUM(F$13:F22) -> 42
A23: ='ALL LEVELS'!A23 -> 11 | B23: ='ALL LEVELS'!B23 -> THURSDAY | C23: 4.4186047 | D23: 13.2 | E23: 26 | F23: 10 | J23: =SUM(C$13:C23) -> 31.395349 | K23: =SUM(D$13:D23) -> 102.8 | L23: =SUM(E$13:E23) -> 158 | M23: =SUM(F$13:F23) -> 52
A24: ='ALL LEVELS'!A24 -> 12 | B24: ='ALL LEVELS'!B24 -> FRIDAY | J24: =SUM(C$13:C24) -> 31.395349 | K24: =SUM(D$13:D24) -> 102.8 | L24: =SUM(E$13:E24) -> 158 | M24: =SUM(F$13:F24) -> 52
A25: ='ALL LEVELS'!A25 -> 13 | B25: ='ALL LEVELS'!B25 -> SATURDAY | J25: =SUM(C$13:C25) -> 31.395349 | K25: =SUM(D$13:D25) -> 102.8 | L25: =SUM(E$13:E25) -> 158 | M25: =SUM(F$13:F25) -> 52
A26: ='ALL LEVELS'!A26 -> 14 | B26: ='ALL LEVELS'!B26 -> SUNDAY | J26: =SUM(C$13:C26) -> 31.395349 | K26: =SUM(D$13:D26) -> 102.8 | L26: =SUM(E$13:E26) -> 158 | M26: =SUM(F$13:F26) -> 52
A27: ='ALL LEVELS'!A27 -> 15 | B27: ='ALL LEVELS'!B27 -> MONDAY | C27: 3.9534884 | D27: 27.2 | E27: 34 | F27: 15 | J27: =SUM(C$13:C27) -> 35.348837 | K27: =SUM(D$13:D27) -> 130 | L27: =SUM(E$13:E27) -> 192 | M27: =SUM(F$13:F27) -> 67
A28: ='ALL LEVELS'!A28 -> 16 | B28: ='ALL LEVELS'!B28 -> TUESDAY | C28: 5.5813953 | D28: 28.8 | E28: 48 | F28: 15 | J28: =SUM(C$13:C28) -> 40.930233 | K28: =SUM(D$13:D28) -> 158.8 | L28: =SUM(E$13:E28) -> 240 | M28: =SUM(F$13:F28) -> 82
A29: ='ALL LEVELS'!A29 -> 17 | B29: ='ALL LEVELS'!B29 -> WEDNESDAY | C29: 7.5581395 | D29: 50 | E29: 65 | F29: 23 | J29: =SUM(C$13:C29) -> 48.488372 | K29: =SUM(D$13:D29) -> 208.8 | L29: =SUM(E$13:E29) -> 305 | M29: =SUM(F$13:F29) -> 105
A30: ='ALL LEVELS'!A30 -> 18 | B30: ='ALL LEVELS'!B30 -> THURSDAY | J30: =SUM(C$13:C30) -> 48.488372 | K30: =SUM(D$13:D30) -> 208.8 | L30: =SUM(E$13:E30) -> 305 | M30: =SUM(F$13:F30) -> 105
A31: ='ALL LEVELS'!A31 -> 19 | B31: ='ALL LEVELS'!B31 -> FRIDAY | J31: =SUM(C$13:C31) -> 48.488372 | K31: =SUM(D$13:D31) -> 208.8 | L31: =SUM(E$13:E31) -> 305 | M31: =SUM(F$13:F31) -> 105
A32: ='ALL LEVELS'!A32 -> 20 | B32: ='ALL LEVELS'!B32 -> SATURDAY | J32: =SUM(C$13:C32) -> 48.488372 | K32: =SUM(D$13:D32) -> 208.8 | L32: =SUM(E$13:E32) -> 305 | M32: =SUM(F$13:F32) -> 105
A33: ='ALL LEVELS'!A33 -> 21 | B33: ='ALL LEVELS'!B33 -> SUNDAY | J33: =SUM(C$13:C33) -> 48.488372 | K33: =SUM(D$13:D33) -> 208.8 | L33: =SUM(E$13:E33) -> 305 | M33: =SUM(F$13:F33) -> 105
A34: ='ALL LEVELS'!A34 -> 22 | B34: ='ALL LEVELS'!B34 -> MONDAY | J34: =SUM(C$13:C34) -> 48.488372 | K34: =SUM(D$13:D34) -> 208.8 | L34: =SUM(E$13:E34) -> 305 | M34: =SUM(F$13:F34) -> 105
A35: ='ALL LEVELS'!A35 -> 23 | B35: ='ALL LEVELS'!B35 -> TUESDAY | J35: =SUM(C$13:C35) -> 48.488372 | K35: =SUM(D$13:D35) -> 208.8 | L35: =SUM(E$13:E35) -> 305 | M35: =SUM(F$13:F35) -> 105
A36: ='ALL LEVELS'!A36 -> 24 | B36: ='ALL LEVELS'!B36 -> WEDNESDAY | J36: =SUM(C$13:C36) -> 48.488372 | K36: =SUM(D$13:D36) -> 208.8 | L36: =SUM(E$13:E36) -> 305 | M36: =SUM(F$13:F36) -> 105
A37: ='ALL LEVELS'!A37 -> 25 | B37: ='ALL LEVELS'!B37 -> THURSDAY | J37: =SUM(C$13:C37) -> 48.488372 | K37: =SUM(D$13:D37) -> 208.8 | L37: =SUM(E$13:E37) -> 305 | M37: =SUM(F$13:F37) -> 105
A38: ='ALL LEVELS'!A38 -> 26 | B38: ='ALL LEVELS'!B38 -> FRIDAY | J38: =SUM(C$13:C38) -> 48.488372 | K38: =SUM(D$13:D38) -> 208.8 | L38: =SUM(E$13:E38) -> 305 | M38: =SUM(F$13:F38) -> 105
A39: ='ALL LEVELS'!A39 -> 27 | B39: ='ALL LEVELS'!B39 -> SATURDAY | J39: =SUM(C$13:C39) -> 48.488372 | K39: =SUM(D$13:D39) -> 208.8 | L39: =SUM(E$13:E39) -> 305 | M39: =SUM(F$13:F39) -> 105
A40: ='ALL LEVELS'!A40 -> 28 | B40: ='ALL LEVELS'!B40 -> SUNDAY | J40: =SUM(C$13:C40) -> 48.488372 | K40: =SUM(D$13:D40) -> 208.8 | L40: =SUM(E$13:E40) -> 305 | M40: =SUM(F$13:F40) -> 105
A41: ='ALL LEVELS'!A41 -> 29 | B41: ='ALL LEVELS'!B41 -> MONDAY
...

Sheet LEVEL 8
B1: Mine Production | E1: Total W.Days | F1: ='ALL LEVELS'!F1 -> 30 | H1: ='ALL LEVELS'!H1 -> Month of JUNE 2026
B2: Day | C2: ='ALL LEVELS'!C2 -> 19
C3: DAILY | E3: MTD
B4: DELAY TYPE | C4: QUOTA | D4: ACTUAL | E4: QUOTA | F4: ACTUAL
B5: EMULSION
B6: ANFO
B7: DETONATORS
B8: DETCORDS
B10: TOTAL
J11: MTD
A12: DATE | B12: DAY | C12: EMULSION (KG) | D12: ANFO (KG) | E12: DETONATORS (PCS) | F12: DETCORDS (MTR) | J12: EMULSION | K12: ANFO | L12: DETONATORS | M12: DETCORDS
A13: ='ALL LEVELS'!A13 -> 1 | B13: ='ALL LEVELS'!B13 -> MONDAY | C13: 35.697674 | D13: 152.6 | E13: 208 | F13: 137 | J13: =SUM(C$13:C13) -> 35.697674 | K13: =SUM(D$13:D13) -> 152.6 | L13: =SUM(E$13:E13) -> 208 | M13: =SUM(F$13:F13) -> 137
A14: ='ALL LEVELS'!A14 -> 2 | B14: ='ALL LEVELS'!B14 -> TUESDAY | C14: 59.883721 | D14: 162.4 | E14: 266 | F14: 140 | J14: =SUM(C$13:C14) -> 95.581395 | K14: =SUM(D$13:D14) -> 315 | L14: =SUM(E$13:E14) -> 474 | M14: =SUM(F$13:F14) -> 277
A15: ='ALL LEVELS'!A15 -> 3 | B15: ='ALL LEVELS'!B15 -> WEDNESDAY | C15: 42.44186 | D15: 63.8 | E15: 132 | F15: 74 | J15: =SUM(C$13:C15) -> 138.02326 | K15: =SUM(D$13:D15) -> 378.8 | L15: =SUM(E$13:E15) -> 606 | M15: =SUM(F$13:F15) -> 351
A16: ='ALL LEVELS'!A16 -> 4 | B16: ='ALL LEVELS'!B16 -> THURSDAY | C16: 60.116279 | D16: 187.2 | E16: 272 | F16: 150 | J16: =SUM(C$13:C16) -> 198.13953 | K16: =SUM(D$13:D16) -> 566 | L16: =SUM(E$13:E16) -> 878 | M16: =SUM(F$13:F16) -> 501
A17: ='ALL LEVELS'!A17 -> 5 | B17: ='ALL LEVELS'!B17 -> FRIDAY | C17: 51.27907 | D17: 148.8 | E17: 193 | F17: 140 | J17: =SUM(C$13:C17) -> 249.4186 | K17: =SUM(D$13:D17) -> 714.8 | L17: =SUM(E$13:E17) -> 1071 | M17: =SUM(F$13:F17) -> 641
A18: ='ALL LEVELS'!A18 -> 6 | B18: ='ALL LEVELS'!B18 -> SATURDAY | C18: 75.930233 | D18: 219.6 | E18: 345 | F18: 192 | J18: =SUM(C$13:C18) -> 325.34884 | K18: =SUM(D$13:D18) -> 934.4 | L18: =SUM(E$13:E18) -> 1416 | M18: =SUM(F$13:F18) -> 833
A19: ='ALL LEVELS'!A19 -> 7 | B19: ='ALL LEVELS'!B19 -> SUNDAY | C19: 45.697674 | D19: 133 | E19: 209 | F19: 109 | J19: =SUM(C$13:C19) -> 371.04651 | K19: =SUM(D$13:D19) -> 1067.4 | L19: =SUM(E$13:E19) -> 1625 | M19: =SUM(F$13:F19) -> 942
A20: ='ALL LEVELS'!A20 -> 8 | B20: ='ALL LEVELS'!B20 -> MONDAY | C20: 63.604651 | D20: 92.6 | E20: 193 | F20: 129 | J20: =SUM(C$13:C20) -> 434.65116 | K20: =SUM(D$13:D20) -> 1160 | L20: =SUM(E$13:E20) -> 1818 | M20: =SUM(F$13:F20) -> 1071
A21: ='ALL LEVELS'!A21 -> 9 | B21: ='ALL LEVELS'!B21 -> TUESDAY | C21: 67.674419 | D21: 173.8 | E21: 278 | F21: 155 | J21: =SUM(C$13:C21) -> 502.32558 | K21: =SUM(D$13:D21) -> 1333.8 | L21: =SUM(E$13:E21) -> 2096 | M21: =SUM(F$13:F21) -> 1226
A22: ='ALL LEVELS'!A22 -> 10 | B22: ='ALL LEVELS'!B22 -> WEDNESDAY | C22: 57.44186 | D22: 216.2 | E22: 264 | F22: 190 | J22: =SUM(C$13:C22) -> 559.76744 | K22: =SUM(D$13:D22) -> 1550 | L22: =SUM(E$13:E22) -> 2360 | M22: =SUM(F$13:F22) -> 1416
A23: ='ALL LEVELS'!A23 -> 11 | B23: ='ALL LEVELS'!B23 -> THURSDAY | C23: 60.465116 | D23: 224.8 | E23: 307 | F23: 209 | J23: =SUM(C$13:C23) -> 620.23256 | K23: =SUM(D$13:D23) -> 1774.8 | L23: =SUM(E$13:E23) -> 2667 | M23: =SUM(F$13:F23) -> 1625
A24: ='ALL LEVELS'!A24 -> 12 | B24: ='ALL LEVELS'!B24 -> FRIDAY | C24: 33.604651 | D24: 147.6 | E24: 169 | F24: 142 | J24: =SUM(C$13:C24) -> 653.83721 | K24: =SUM(D$13:D24) -> 1922.4 | L24: =SUM(E$13:E24) -> 2836 | M24: =SUM(F$13:F24) -> 1767
... A31: ='ALL LEVELS'!A31 -> 19 | B31: ='ALL LEVELS'!B31 -> FRIDAY | C31: 36.395349 | D31: 132 | E31: 156 | F31: 136 | J31: =SUM(C$13:C31) -> 907.2093 | K31: =SUM(D$13:D31) -> 3083.9 | L31: =SUM(E$13:E31) -> 4202 | M31: =SUM(F$13:F31) -> 2742
A32: ='ALL LEVELS'!A32 -> 20 | B32: ='ALL LEVELS'!B32 -> SATURDAY | J32: =SUM(C$13:C32) -> 907.2093 | K32: =SUM(D$13:D32) -> 3083.9 | L32: =SUM(E$13:E32) -> 4202 | M32: =SUM(F$13:F32) -> 2742
A33: ='ALL LEVELS'!A33 -> 21 | B33: ='ALL LEVELS'!B33 -> SUNDAY | J33: =SUM(C$13:C33) -> 907.2093 | K33: =SUM(D$13:D33) -> 3083.9 | L33: =SUM(E$13:E33) -> 4202 | M33: =SUM(F$13:F33) -> 2742
A34: ='ALL LEVELS'!A34 -> 22 | B34: ='ALL LEVELS'!B34 -> MONDAY | J34: =SUM(C$13:C34) -> 907.2093 | K34: =SUM(D$13:D34) -> 3083.9 | L34: =SUM(E$13:E34) -> 4202 | M34: =SUM(F$13:F34) -> 2742
A35: ='ALL LEVELS'!A35 -> 23 | B35: ='ALL LEVELS'!B35 -> TUESDAY | J35: =SUM(C$13:C35) -> 907.2093 | K35: =SUM(D$13:D35) -> 3083.9 | L35: =SUM(E$13:E35) -> 4202 | M35: =SUM(F$13:F35) -> 2742
A36: ='ALL LEVELS'!A36 -> 24 | B36: ='ALL LEVELS'!B36 -> WEDNESDAY | J36: =SUM(C$13:C36) -> 907.2093 | K36: =SUM(D$13:D36) -> 3083.9 | L36: =SUM(E$13:E36) -> 4202 | M36: =SUM(F$13:F36) -> 2742
A37: ='ALL LEVELS'!A37 -> 25 | B37: ='ALL LEVELS'!B37 -> THURSDAY | J37: =SUM(C$13:C37) -> 907.2093 | K37: =SUM(D$13:D37) -> 3083.9 | L37: =SUM(E$13:E37) -> 4202 | M37: =SUM(F$13:F37) -> 2742
A38: ='ALL LEVELS'!A38 -> 26 | B38: ='ALL LEVELS'!B38 -> FRIDAY | J38: =SUM(C$13:C38) -> 907.2093 | K38: =SUM(D$13:D38) -> 3083.9 | L38: =SUM(E$13:E38) -> 4202 | M38: =SUM(F$13:F38) -> 2742
A39: ='ALL LEVELS'!A39 -> 27 | B39: ='ALL LEVELS'!B39 -> SATURDAY | J39: =SUM(C$13:C39) -> 907.2093 | K39: =SUM(D$13:D39) -> 3083.9 | L39: =SUM(E$13:E39) -> 4202 | M39: =SUM(F$13:F39) -> 2742
A40: ='ALL LEVELS'!A40 -> 28 | B40: ='ALL LEVELS'!B40 -> SUNDAY | J40: =SUM(C$13:C40) -> 907.2093 | K40: =SUM(D$13:D40) -> 3083.9 | L40: =SUM(E$13:E40) -> 4202 | M40: =SUM(F$13:F40) -> 2742
A41: ='ALL LEVELS'!A41 -> 29 | B41: ='ALL LEVELS'!B41 -> MONDAY
A42: ='ALL LEVELS'!A42 -> 30 | B42: ='ALL LEVELS'!B42 -> TUESDAY | J42: =SUM(C$13:C42) -> 907.2093 | K42: =SUM(D$13:D42) -> 3083.9 | L42: =SUM(E$13:E42) -> 4202 | M42: =SUM(F$13:F42) -> 2742
A43: ='ALL LEVELS'!A43 -> 31 | B43: ='ALL LEVELS'!B43 -> WEDNESDAY | J43: =SUM(C$13:C43) -> 907.2093 | K43: =SUM(D$13:D43) -> 3083.9 | L43: =SUM(E$13:E43) -> 4202 | M43: =SUM(F$13:F43) -> 2742
C44: =SUBTOTAL(109,C13:C43) -> 907.2093 | D44: =SUBTOTAL(109,D13:D43) -> 3083.9 | E44: =SUBTOTAL(109,E13:E43) -> 4202 | F44: =SUBTOTAL(109,F13:F43) -> 2742 | G44: =SUBTOTAL(109,G13:G43) -> 0 | H44: =SUBTOTAL(109,H13:H43) -> 0

Sheet LEVEL 9
B1: Mine Production | E1: Total W.Days | F1: ='ALL LEVELS'!F1 -> 30 | H1: ='ALL LEVELS'!H1 -> Month of JUNE 2026
B2: Day | C2: ='ALL LEVELS'!C2 -> 19
C3: DAILY | E3: MTD
B4: DELAY TYPE | C4: QUOTA | D4: ACTUAL | E4: QUOTA | F4: ACTUAL
B5: EMULSION
B6: ANFO
B7: DETONATORS
B8: DETCORDS
B10: TOTAL
J11: MTD
A12: DATE | B12: DAY | C12: EMULSION (KG) | D12: ANFO (KG) | E12: DETONATORS (PCS) | F12: DETCORDS (MTR) | J12: EMULSION | K12: ANFO | L12: DETONATORS | M12: DETCORDS
A13: ='ALL LEVELS'!A13 -> 1 | B13: ='ALL LEVELS'!B13 -> MONDAY | C13: 27.325581 | D13: 114.4 | E13: 126 | F13: 92 | J13: =SUM(C$13:C13) -> 27.325581 | K13: =SUM(D$13:D13) -> 114.4 | L13: =SUM(E$13:E13) -> 126 | M13: =SUM(F$13:F13) -> 92
A14: ='ALL LEVELS'!A14 -> 2 | B14: ='ALL LEVELS'!B14 -> TUESDAY | C14: 35.465116 | D14: 115.2 | E14: 119 | F14: 100 | J14: =SUM(C$13:C14) -> 62.790698 | K14: =SUM(D$13:D14) -> 229.6 | L14: =SUM(E$13:E14) -> 245 | M14: =SUM(F$13:F14) -> 192
A15: ='ALL LEVELS'!A15 -> 3 | B15: ='ALL LEVELS'!B15 -> WEDNESDAY | C15: 29.302326 | D15: 100.6 | E15: 98 | F15: 99 | J15: =SUM(C$13:C15) -> 92.093023 | K15: =SUM(D$13:D15) -> 330.2 | L15: =SUM(E$13:E15) -> 343 | M15: =SUM(F$13:F15) -> 291
A16: ='ALL LEVELS'!A16 -> 4 | B16: ='ALL LEVELS'!B16 -> THURSDAY | C16: 20.465116 | D16: 87.8 | E16: 74 | F16: 73 | J16: =SUM(C$13:C16) -> 112.55814 | K16: =SUM(D$13:D16) -> 418 | L16: =SUM(E$13:E16) -> 417 | M16: =SUM(F$13:F16) -> 364
A17: ='ALL LEVELS'!A17 -> 5 | B17: ='ALL LEVELS'!B17 -> FRIDAY | C17: 28.023256 | D17: 126.4 | E17: 111 | F17: 106 | J17: =SUM(C$13:C17) -> 140.5814 | K17: =SUM(D$13:D17) -> 544.4 | L17: =SUM(E$13:E17) -> 528 | M17: =SUM(F$13:F17) -> 470
A18: ='ALL LEVELS'!A18 -> 6 | B18: ='ALL LEVELS'!B18 -> SATURDAY | C18: 20 | D18: 131.6 | E18: 77 | F18: 163 | J18: =SUM(C$13:C18) -> 160.5814 | K18: =SUM(D$13:D18) -> 676 | L18: =SUM(E$13:E18) -> 605 | M18: =SUM(F$13:F18) -> 633
A19: ='ALL LEVELS'!A19 -> 7 | B19: ='ALL LEVELS'!B19 -> SUNDAY | C19: 15.930233 | D19: 99.4 | E19: 47 | F19: 94 | J19: =SUM(C$13:C19) -> 176.51163 | K19: =SUM(D$13:D19) -> 775.4 | L19: =SUM(E$13:E19) -> 652 | M19: =SUM(F$13:F19) -> 727
A20: ='ALL LEVELS'!A20 -> 8 | B20: ='ALL LEVELS'!B20 -> MONDAY | C20: 17.44186 | D20: 124.6 | E20: 70 | F20: 107 | J20: =SUM(C$13:C20) -> 193.95349 | K20: =SUM(D$13:D20) -> 900 | L20: =SUM(E$13:E20) -> 722 | M20: =SUM(F$13:F20) -> 834
A21: ='ALL LEVELS'!A21 -> 9 | B21: ='ALL LEVELS'!B21 -> TUESDAY | C21: 34.883721 | D21: 147 | E21: 88 | F21: 140 | J21: =SUM(C$13:C21) -> 228.83721 | K21: =SUM(D$13:D21) -> 1047 | L21: =SUM(E$13:E21) -> 810 | M21: =SUM(F$13:F21) -> 974
A22: ='ALL LEVELS'!A22 -> 10 | B22: ='ALL LEVELS'!B22 -> WEDNESDAY | C22: 22.209302 | D22: 140.2 | E22: 98 | F22: 117 | J22: =SUM(C$13:C22) -> 251.04651 | K22: =SUM(D$13:D22) -> 1187.2 | L22: =SUM(E$13:E22) -> 908 | M22: =SUM(F$13:F22) -> 1091
A23: ='ALL LEVELS'!A23 -> 11 | B23: ='ALL LEVELS'!B23 -> THURSDAY | C23: 44.767442 | D23: 178.2 | E23: 169 | F23: 135 | J23: =SUM(C$13:C23) -> 295.81395 | K23: =SUM(D$13:D23) -> 1365.4 | L23: =SUM(E$13:E23) -> 1077 | M23: =SUM(F$13:F23) -> 1226
A24: ='ALL LEVELS'!A24 -> 12 | B24: ='ALL LEVELS'!B24 -> FRIDAY | C24: 38.604651 | D24: 176.2 | E24: 171 | F24: 145 | J24: =SUM(C$13:C24) -> 334.4186 | K24: =SUM(D$13:D24) -> 1541.6 | L24: =SUM(E$13:E24) -> 1248 | M24: =SUM(F$13:F24) -> 1371
... A31: ='ALL LEVELS'!A31 -> 19 | B31: ='ALL LEVELS'!B31 -> FRIDAY | C31: 39.069767 | D31: 154.4 | E31: 129 | F31: 167 | J31: =SUM(C$13:C31) -> 513.72093 | K31: =SUM(D$13:D31) -> 2536 | L31: =SUM(E$13:E31) -> 1968 | M31: =SUM(F$13:F31) -> 2217
A32: ='ALL LEVELS'!A32 -> 20 | B32: ='ALL LEVELS'!B32 -> SATURDAY | J32: =SUM(C$13:C32) -> 513.72093 | K32: =SUM(D$13:D32) -> 2536 | L32: =SUM(E$13:E32) -> 1968 | M32: =SUM(F$13:F32) -> 2217
A33: ='ALL LEVELS'!A33 -> 21 | B33: ='ALL LEVELS'!B33 -> SUNDAY | J33: =SUM(C$13:C33) -> 513.72093 | K33: =SUM(D$13:D33) -> 2536 | L33: =SUM(E$13:E33) -> 1968 | M33: =SUM(F$13:F33) -> 2217
A34: ='ALL LEVELS'!A34 -> 22 | B34: ='ALL LEVELS'!B34 -> MONDAY | J34: =SUM(C$13:C34) -> 513.72093 | K34: =SUM(D$13:D34) -> 2536 | L34: =SUM(E$13:E34) -> 1968 | M34: =SUM(F$13:F34) -> 2217
A35: ='ALL LEVELS'!A35 -> 23 | B35: ='ALL LEVELS'!B35 -> TUESDAY | J35: =SUM(C$13:C35) -> 513.72093 | K35: =SUM(D$13:D35) -> 2536 | L35: =SUM(E$13:E35) -> 1968 | M35: =SUM(F$13:F35) -> 2217
A36: ='ALL LEVELS'!A36 -> 24 | B36: ='ALL LEVELS'!B36 -> WEDNESDAY | J36: =SUM(C$13:C36) -> 513.72093 | K36: =SUM(D$13:D36) -> 2536 | L36: =SUM(E$13:E36) -> 1968 | M36: =SUM(F$13:F36) -> 2217
A37: ='ALL LEVELS'!A37 -> 25 | B37: ='ALL LEVELS'!B37 -> THURSDAY | J37: =SUM(C$13:C37) -> 513.72093 | K37: =SUM(D$13:D37) -> 2536 | L37: =SUM(E$13:E37) -> 1968 | M37: =SUM(F$13:F37) -> 2217
A38: ='ALL LEVELS'!A38 -> 26 | B38: ='ALL LEVELS'!B38 -> FRIDAY | J38: =SUM(C$13:C38) -> 513.72093 | K38: =SUM(D$13:D38) -> 2536 | L38: =SUM(E$13:E38) -> 1968 | M38: =SUM(F$13:F38) -> 2217
A39: ='ALL LEVELS'!A39 -> 27 | B39: ='ALL LEVELS'!B39 -> SATURDAY | J39: =SUM(C$13:C39) -> 513.72093 | K39: =SUM(D$13:D39) -> 2536 | L39: =SUM(E$13:E39) -> 1968 | M39: =SUM(F$13:F39) -> 2217
A40: ='ALL LEVELS'!A40 -> 28 | B40: ='ALL LEVELS'!B40 -> SUNDAY | J40: =SUM(C$13:C40) -> 513.72093 | K40: =SUM(D$13:D40) -> 2536 | L40: =SUM(E$13:E40) -> 1968 | M40: =SUM(F$13:F40) -> 2217
A41: ='ALL LEVELS'!A41 -> 29 | B41: ='ALL LEVELS'!B41 -> MONDAY
A42: ='ALL LEVELS'!A42 -> 30 | B42: ='ALL LEVELS'!B42 -> TUESDAY | J42: =SUM(C$13:C42) -> 513.72093 | K42: =SUM(D$13:D42) -> 2536 | L42: =SUM(E$13:E42) -> 1968 | M42: =SUM(F$13:F42) -> 2217
A43: ='ALL LEVELS'!A43 -> 31 | B43: ='ALL LEVELS'!B43 -> WEDNESDAY | J43: =SUM(C$13:C43) -> 513.72093 | K43: =SUM(D$13:D43) -> 2536 | L43: =SUM(E$13:E43) -> 1968 | M43: =SUM(F$13:F43) -> 2217
C44: =SUBTOTAL(109,C13:C43) -> 513.72093 | D44: =SUBTOTAL(109,D13:D43) -> 2536 | E44: =SUBTOTAL(109,E13:E43) -> 1968 | F44: =SUBTOTAL(109,F13:F43) -> 2217 | G44: =SUBTOTAL(109,G13:G43) -> 0 | H44: =SUBTOTAL(109,H13:H43) -> 0

Sheet LEVEL 10
B1: Mine Production | E1: Total W.Days | F1: ='ALL LEVELS'!F1 -> 30 | H1: ='ALL LEVELS'!H1 -> Month of JUNE 2026
B2: Day | C2: ='ALL LEVELS'!C2 -> 19
C3: DAILY | E3: MTD
B4: DELAY TYPE | C4: QUOTA | D4: ACTUAL | E4: QUOTA | F4: ACTUAL
B5: EMULSION
B6: ANFO
B7: DETONATORS
B8: DETCORDS
B10: TOTAL
J11: MTD
A12: DATE | B12: DAY | C12: EMULSION (KG) | D12: ANFO (KG) | E12: DETONATORS (PCS) | F12: DETCORDS (MTR) | J12: EMULSION | K12: ANFO | L12: DETONATORS | M12: DETCORDS
A13: ='ALL LEVELS'!A13 -> 1 | B13: ='ALL LEVELS'!B13 -> MONDAY | C13: 12.790698 | D13: 79.4 | E13: 72 | F13: 51 | J13: =SUM(C$13:C13) -> 12.790698 | K13: =SUM(D$13:D13) -> 79.4 | L13: =SUM(E$13:E13) -> 72 | M13: =SUM(F$13:F13) -> 51
A14: ='ALL LEVELS'!A14 -> 2 | B14: ='ALL LEVELS'!B14 -> TUESDAY | C14: 13.488372 | D14: 65.2 | E14: 91 | F14: 38 | J14: =SUM(C$13:C14) -> 26.27907 | K14: =SUM(D$13:D14) -> 144.6 | L14: =SUM(E$13:E14) -> 163 | M14: =SUM(F$13:F14) -> 89
A15: ='ALL LEVELS'!A15 -> 3 | B15: ='ALL LEVELS'!B15 -> WEDNESDAY | C15: 20.348837 | D15: 120.8 | E15: 150 | F15: 75 | J15: =SUM(C$13:C15) -> 46.627907 | K15: =SUM(D$13:D15) -> 265.4 | L15: =SUM(E$13:E15) -> 313 | M15: =SUM(F$13:F15) -> 164
A16: ='ALL LEVELS'!A16 -> 4 | B16: ='ALL LEVELS'!B16 -> THURSDAY | C16: 8.0232558 | D16: 39.2 | E16: 43 | F16: 40 | J16: =SUM(C$13:C16) -> 54.651163 | K16: =SUM(D$13:D16) -> 304.6 | L16: =SUM(E$13:E16) -> 356 | M16: =SUM(F$13:F16) -> 204
A17: ='ALL LEVELS'!A17 -> 5 | B17: ='ALL LEVELS'!B17 -> FRIDAY | C17: 18.604651 | D17: 67.2 | E17: 90 | F17: 38 | J17: =SUM(C$13:C17) -> 73.255814 | K17: =SUM(D$13:D17) -> 371.8 | L17: =SUM(E$13:E17) -> 446 | M17: =SUM(F$13:F17) -> 242
A18: ='ALL LEVELS'!A18 -> 6 | B18: ='ALL LEVELS'!B18 -> SATURDAY | C18: 21.395349 | D18: 83.2 | E18: 117 | F18: 56 | J18: =SUM(C$13:C18) -> 94.651163 | K18: =SUM(D$13:D18) -> 455 | L18: =SUM(E$13:E18) -> 563 | M18: =SUM(F$13:F18) -> 298
A19: ='ALL LEVELS'!A19 -> 7 | B19: ='ALL LEVELS'!B19 -> SUNDAY | C19: 11.627907 | D19: 46.4 | E19: 65 | F19: 29 | J19: =SUM(C$13:C19) -> 106.27907 | K19: =SUM(D$13:D19) -> 501.4 | L19: =SUM(E$13:E19) -> 628 | M19: =SUM(F$13:F19) -> 327
A20: ='ALL LEVELS'!A20 -> 8 | B20: ='ALL LEVELS'!B20 -> MONDAY | C20: 20.813953 | D20: 100 | E20: 134 | F20: 66 | J20: =SUM(C$13:C20) -> 127.09302 | K20: =SUM(D$13:D20) -> 601.4 | L20: =SUM(E$13:E20) -> 762 | M20: =SUM(F$13:F20) -> 393
A21: ='ALL LEVELS'!A21 -> 9 | B21: ='ALL LEVELS'!B21 -> TUESDAY | C21: 21.395349 | D21: 107 | E21: 142 | F21: 70 | J21: =SUM(C$13:C21) -> 148.48837 | K21: =SUM(D$13:D21) -> 708.4 | L21: =SUM(E$13:E21) -> 904 | M21: =SUM(F$13:F21) -> 463
A22: ='ALL LEVELS'!A22 -> 10 | B22: ='ALL LEVELS'!B22 -> WEDNESDAY | C22: 10.813953 | D22: 36.2 | E22: 49 | F22: 18 | J22: =SUM(C$13:C22) -> 159.30233 | K22: =SUM(D$13:D22) -> 744.6 | L22: =SUM(E$13:E22) -> 953 | M22: =SUM(F$13:F22) -> 481
A23: ='ALL LEVELS'!A23 -> 11 | B23: ='ALL LEVELS'!B23 -> THURSDAY | C23: 14.883721 | D23: 45.6 | E23: 71 | F23: 33 | J23: =SUM(C$13:C23) -> 174.18605 | K23: =SUM(D$13:D23) -> 790.2 | L23: =SUM(E$13:E23) -> 1024 | M23: =SUM(F$13:F23) -> 514
A24: ='ALL LEVELS'!A24 -> 12 | B24: ='ALL LEVELS'!B24 -> FRIDAY | C24: 14.534884 | D24: 47.4 | E24: 60 | F24: 43 | J24: =SUM(C$13:C24) -> 188.72093 | K24: =SUM(D$13:D24) -> 837.6 | L24: =SUM(E$13:E24) -> 1084 | M24: =SUM(F$13:F24) -> 557
... A31: ='ALL LEVELS'!A31 -> 19 | B31: ='ALL LEVELS'!B31 -> FRIDAY | C31: 27.906977 | D31: 98 | E31: 125 | F31: 72 | J31: =SUM(C$13:C31) -> 345.69767 | K31: =SUM(D$13:D31) -> 1338.6 | L31: =SUM(E$13:E31) -> 1817 | M31: =SUM(F$13:F31) -> 905
A32: ='ALL LEVELS'!A32 -> 20 | B32: ='ALL LEVELS'!B32 -> SATURDAY | J32: =SUM(C$13:C32) -> 345.69767 | K32: =SUM(D$13:D32) -> 1338.6 | L32: =SUM(E$13:E32) -> 1817 | M32: =SUM(F$13:F32) -> 905
A33: ='ALL LEVELS'!A33 -> 21 | B33: ='ALL LEVELS'!B33 -> SUNDAY | J33: =SUM(C$13:C33) -> 345.69767 | K33: =SUM(D$13:D33) -> 1338.6 | L33: =SUM(E$13:E33) -> 1817 | M33: =SUM(F$13:F33) -> 905
A34: ='ALL LEVELS'!A34 -> 22 | B34: ='ALL LEVELS'!B34 -> MONDAY | J34: =SUM(C$13:C34) -> 345.69767 | K34: =SUM(D$13:D34) -> 1338.6 | L34: =SUM(E$13:E34) -> 1817 | M34: =SUM(F$13:F34) -> 905
A35: ='ALL LEVELS'!A35 -> 23 | B35: ='ALL LEVELS'!B35 -> TUESDAY | J35: =SUM(C$13:C35) -> 345.69767 | K35: =SUM(D$13:D35) -> 1338.6 | L35: =SUM(E$13:E35) -> 1817 | M35: =SUM(F$13:F35) -> 905
A36: ='ALL LEVELS'!A36 -> 24 | B36: ='ALL LEVELS'!B36 -> WEDNESDAY | J36: =SUM(C$13:C36) -> 345.69767 | K36: =SUM(D$13:D36) -> 1338.6 | L36: =SUM(E$13:E36) -> 1817 | M36: =SUM(F$13:F36) -> 905
A37: ='ALL LEVELS'!A37 -> 25 | B37: ='ALL LEVELS'!B37 -> THURSDAY | J37: =SUM(C$13:C37) -> 345.69767 | K37: =SUM(D$13:D37) -> 1338.6 | L37: =SUM(E$13:E37) -> 1817 | M37: =SUM(F$13:F37) -> 905
A38: ='ALL LEVELS'!A38 -> 26 | B38: ='ALL LEVELS'!B38 -> FRIDAY | J38: =SUM(C$13:C38) -> 345.69767 | K38: =SUM(D$13:D38) -> 1338.6 | L38: =SUM(E$13:E38) -> 1817 | M38: =SUM(F$13:F38) -> 905
A39: ='ALL LEVELS'!A39 -> 27 | B39: ='ALL LEVELS'!B39 -> SATURDAY | J39: =SUM(C$13:C39) -> 345.69767 | K39: =SUM(D$13:D39) -> 1338.6 | L39: =SUM(E$13:E39) -> 1817 | M39: =SUM(F$13:F39) -> 905
A40: ='ALL LEVELS'!A40 -> 28 | B40: ='ALL LEVELS'!B40 -> SUNDAY | J40: =SUM(C$13:C40) -> 345.69767 | K40: =SUM(D$13:D40) -> 1338.6 | L40: =SUM(E$13:E40) -> 1817 | M40: =SUM(F$13:F40) -> 905
A41: ='ALL LEVELS'!A41 -> 29 | B41: ='ALL LEVELS'!B41 -> MONDAY
A42: ='ALL LEVELS'!A42 -> 30 | B42: ='ALL LEVELS'!B42 -> TUESDAY | J42: =SUM(C$13:C42) -> 345.69767 | K42: =SUM(D$13:D42) -> 1338.6 | L42: =SUM(E$13:E42) -> 1817 | M42: =SUM(F$13:F42) -> 905
A43: ='ALL LEVELS'!A43 -> 31 | B43: ='ALL LEVELS'!B43 -> WEDNESDAY | J43: =SUM(C$13:C43) -> 345.69767 | K43: =SUM(D$13:D43) -> 1338.6 | L43: =SUM(E$13:E43) -> 1817 | M43: =SUM(F$13:F43) -> 905
C44: =SUBTOTAL(109,C13:C43) -> 345.69767 | D44: =SUBTOTAL(109,D13:D43) -> 1338.6 | E44: =SUBTOTAL(109,E13:E43) -> 1817 | F44: =SUBTOTAL(109,F13:F43) -> 905 | G44: =SUBTOTAL(109,G13:G43) -> 0 | H44: =SUBTOTAL(109,H13:H43) -> 0

Sheet LEVEL 11
B1: Mine Production | E1: Total W.Days | F1: ='ALL LEVELS'!F1 -> 30 | H1: ='ALL LEVELS'!H1 -> Month of JUNE 2026
B2: Day | C2: ='ALL LEVELS'!C2 -> 19
C3: DAILY | E3: MTD
B4: DELAY TYPE | C4: QUOTA | D4: ACTUAL | E4: QUOTA | F4: ACTUAL
B5: EMULSION
B6: ANFO
B7: DETONATORS
B8: DETCORDS
B10: TOTAL
J11: MTD
A12: DATE | B12: DAY | C12: EMULSION (KG) | D12: ANFO (KG) | E12: DETONATORS (PCS) | F12: DETCORDS (MTR) | J12: EMULSION | K12: ANFO | L12: DETONATORS | M12: DETCORDS
