Workbook

Sheet EXPLOSIVES KG USED
A1: Level | C1: ID | D1: NEOGEL 200 | E1: SUPERPOWER | F1: ANFO | G1: SAFETY FUSE | H1: OBC | I1: NONEL 3.6 | J1: EXEL3.6 | K1: SUPREME 2.4 | L1: SUPREME 3.6 | M1: EXEL2.4 | N1: SHOCK STAR | O1: MS 18 | P1: CORDTEX5M | Q1: CORDTEX10M | R1: CORDTEX40M | S1: DC I 5 | T1: FUSE_LIGHTER | U1: Sum of SENATEL PULSAR 38 | V1: BELL WIRE | W1: Sum of EXEL 4.9 | X1: SENATEL 135 | Y1: SUPER POWER 208 | Z1: SUPER POWER150 | AA1: SENATEL 215 | AB1: EBC | AD1: EMULSION (KG) | AE1: ANFO (KG) | AF1: DETONATORS (PCS) | AG1: DETCORDS (MTR)
A2: Level | C2: ID | D2: SUPERPOWER | E2: EM AUSTIN | F2: ANFO | G2: SAFETY FUSE | H2: OBC | I2: NONEL 3.6 | J2: EXEL3.6 | K2: SUPREME 2.4 | L2: SUPREME 3.6 | M2: EXEL2.4 | N2: TS 2.4 | O2: MS 18 | P2: CORDTEX5M | Q2: CORDTEX10M | R2: CORDTEX40M | S2: DC I 5 | T2: FUSE_LIGHTER | U2: Sum of SENATEL PULSAR 38 | V2: BELL_WIRE | W2: Sum of EXEL 4.9 | X2: SENATEL 135 | Y2: SUPER POWER 208 | Z2: SUPER POWER150 | AA2: SENATEL 215 | AB2: EBC
D3: =25/200 -> 0.125 | E3: =25/200 -> 0.125 | U3: =25/38 -> 0.65789474 | X3: =25/135 -> 0.18518519 | Y3: =25/208 -> 0.12019231 | Z3: =25/150 -> 0.16666667 | AA3: =25/215 -> 0.11627907
A4: L3
A5: L3
C6: SUB-TOTAL | D6: =D5*$D$3 -> 0 | E6: =E5*$E3 -> 0 | F6: =F5 -> 0 | G6: =G5*G3 -> 0 | H6: =H5*H3 -> 0 | I6: =I5 -> 0 | J6: =J5 -> 0 | K6: =K5 -> 0 | L6: =L5 -> 0 | M6: =M5 -> 0 | N6: =N5 -> 0 | O6: =O5*O3 -> 0 | P6: =P5 -> 0 | Q6: =Q5 -> 0 | R6: =R5 -> 0 | S6: =S5 -> 0 | T6: =T5*T3 -> 0 | U6: =U5*$U$3 -> 0 | V6: =V5 -> 0 | W6: =W5*W3 -> 0 | X6: =X5*$X$3 -> 0 | Y6: =Y5*$Y$3 -> 0 | Z6: =Z5*$Z$3 -> 0 | AA6: =AA5*$AA$3 -> 0 | AB6: =SUM(AB5:AB5) -> 0 | AC6: L3 | AD6: =D6+AA6+U6+X6+Y6+Z6+E6 -> 0 | AE6: =F6 -> 0 | AF6: =I6+J6+K6+L6+M6+N6 -> 0 | AG6: =P6+Q6+R6+S6 -> 0
A7: L4
A8: L4
C9: SUB-TOTAL | D9: =D8*$D$3 -> 0 | E9: =E8*$E3 -> 0 | F9: =F8 -> 0 | G9: =G8*G6 -> 0 | H9: =H8*H6 -> 0 | I9: =I8 -> 0 | J9: =J8 -> 0 | K9: =K8 -> 0 | L9: =L8 -> 0 | M9: =M8 -> 0 | N9: =N8 -> 0 | O9: =O8*O6 -> 0 | P9: =P8 -> 0 | Q9: =Q8 -> 0 | R9: =R8 -> 0 | S9: =S8 -> 0 | T9: =T8*T6 -> 0 | U9: =U8*$U$3 -> 0 | V9: =V8*V3 -> 0 | W9: =W8*W6 -> 0 | X9: =X8*$X$3 -> 0 | Y9: =Y8*$Y$3 -> 0 | Z9: =Z8*$Z$3 -> 0 | AA9: =AA8*$AA$3 -> 0 | AB9: =SUM(AB8:AB8) -> 0 | AC9: L4 | AD9: =D9+AA9+U9+X9+Y9+Z9+E9 -> 0 | AE9: =F9 -> 0 | AF9: =I9+J9+K9+L9+M9+N9 -> 0 | AG9: =P9+Q9+R9+S9 -> 0
A10: L05
A11: L05
C12: SUB-TOTAL | D12: =D11*$D$3 -> 0 | E12: =E11*$E3 -> 0 | F12: =F11 -> 0 | G12: =G11*G9 -> 0 | H12: =H11*H9 -> 0 | I12: =I11 -> 0 | J12: =J11 -> 0 | K12: =K11 -> 0 | L12: =L11 -> 0 | M12: =M11 -> 0 | N12: =N11 -> 0 | O12: =O11*O9 -> 0 | P12: =P11 -> 0 | Q12: =Q11 -> 0 | R12: =R11 -> 0 | S12: =S11 -> 0 | T12: =T11*T9 -> 0 | U12: =U11*$U$3 -> 0 | V12: =V11*V9 -> 0 | W12: =W11*W9 -> 0 | X12: =X11*$X$3 -> 0 | Y12: =Y11*$Y$3 -> 0 | Z12: =Z11*$Z$3 -> 0 | AA12: =AA11*$AA$3 -> 0 | AB12: =SUM(AB11:AB11) -> 0 | AC12: L5 | AD12: =D12+AA12+U12+X12+Y12+Z12+E12 -> 0 | AE12: =F12 -> 0 | AF12: =I12+J12+K12+L12+M12+N12 -> 0 | AG12: =P12+Q12+R12+S12 -> 0
A13: L6
A14: L6
C15: SUB-TOTAL | D15: =D14*$D$3 -> 0 | E15: =E14*$E3 -> 0 | F15: =F14 -> 0 | G15: =G14*G12 -> 0 | H15: =H14*H12 -> 0 | I15: =I14 -> 0 | J15: =J14 -> 0 | K15: =K14 -> 0 | L15: =L14 -> 0 | M15: =M14 -> 0 | N15: =N14 -> 0 | O15: =O14*O12 -> 0 | P15: =P14 -> 0 | Q15: =Q14 -> 0 | R15: =R14 -> 0 | S15: =S14 -> 0 | T15: =T14*T12 -> 0 | U15: =U14*$U$3 -> 0 | V15: =V14*V12 -> 0 | W15: =W14*W12 -> 0 | X15: =X14*$X$3 -> 0 | Y15: =Y14*$Y$3 -> 0 | Z15: =Z14*$Z$3 -> 0 | AA15: =AA14*$AA$3 -> 0 | AB15: =SUM(AB14:AB14) -> 0 | AC15: L6 | AD15: =D15+AA15+U15+X15+Y15+Z15+E15 -> 0 | AE15: =F15 -> 0 | AF15: =I15+J15+K15+L15+M15+N15 -> 0 | AG15: =P15+Q15+R15+S15 -> 0
A16: L7
A17: L7
C18: SUB-TOTAL | D18: =D17*$D$3 -> 0 | E18: =-E17*$E3 -> 0 | F18: =F17 -> 0 | G18: =G17*G15 -> 0 | H18: =H17*H15 -> 0 | I18: =I17 -> 0 | J18: =J17 -> 0 | K18: =K17 -> 0 | L18: =L17 -> 0 | M18: =M17 -> 0 | N18: =N17 -> 0 | O18: =O17*O15 -> 0 | P18: =P17 -> 0 | Q18: =Q17 -> 0 | R18: =R17 -> 0 | S18: =S17 -> 0 | T18: =T17*T15 -> 0 | U18: =U17*$U$3 -> 0 | V18: =V17*V15 -> 0 | W18: =W17*W15 -> 0 | X18: =X17*$X$3 -> 0 | Y18: =Y17*$Y$3 -> 0 | Z18: =Z17*$Z$3 -> 0 | AA18: =AA17*$AA$3 -> 0 | AB18: =SUM(AB17:AB17) -> 0 | AC18: L7 | AD18: =D18+AA18+U18+X18+Y18+Z18+E18 -> 0 | AE18: =F18 -> 0 | AF18: =I18+J18+K18+L18+M18+N18 -> 0 | AG18: =P18+Q18+R18+S18 -> 0
A19: L8
A20: L08 | D20: 0 | E20: 0 | F20: 132 | G20: 99.63 | H20: 41 | I20: 0 | J20: 10 | K20: 0 | L20: 0 | M20: 146 | N20: 0 | O20: 0 | P20: 136 | Q20: 0 | R20: 0 | S20: 0 | T20: 0 | U20: 0 | V20: 0 | W20: 0 | X20: 0 | Y20: 0 | Z20: 0 | AA20: 313 | AB20: 4
C21: SUB-TOTAL | D21: =D20*$D$3 -> 0 | E21: =E20*E3 -> 0 | F21: =F20 -> 132 | G21: =G20*G18 -> 0 | H21: =H20*H18 -> 0 | I21: =I20 -> 0 | J21: =J20 -> 10 | K21: =K20 -> 0 | L21: =L20 -> 0 | M21: =M20 -> 146 | N21: =N20 -> 0 | O21: =O20*O18 -> 0 | P21: =P20 -> 136 | Q21: =Q20 -> 0 | R21: =R20 -> 0 | S21: =S20 -> 0 | T21: =T20*T18 -> 0 | U21: =U20*$U$3 -> 0 | V21: =V20*V18 -> 0 | W21: =W20*W18 -> 0 | X21: =X20*$X$3 -> 0 | Y21: =Y20*$Y$3 -> 0 | Z21: =Z20*$Z$3 -> 0 | AA21: =AA20*$AA$3 -> 36.395349 | AB21: =SUM(AB20:AB20) -> 4 | AC21: L8 | AD21: =D21+AA21+U21+X21+Y21+Z21+E21 -> 36.395349 | AE21: =F21 -> 132 | AF21: =I21+J21+K21+L21+M21+N21 -> 156 | AG21: =P21+Q21+R21+S21 -> 136
A22: L9
A23: L09 | D23: 0 | E23: 0 | F23: 154.4 | G23: 82.62 | H23: 34 | I23: 0 | J23: 0 | K23: 0 | L23: 0 | M23: 129 | N23: 0 | O23: 0 | P23: 167 | Q23: 0 | R23: 0 | S23: 0 | T23: 0 | U23: 0 | V23: 0 | W23: 0 | X23: 0 | Y23: 0 | Z23: 0 | AA23: 336 | AB23: 2
C24: SUB-TOTAL | D24: =D23*$D$3 -> 0 | E24: =E23*$E3 -> 0 | F24: =F23 -> 154.4 | G24: =G23*G21 -> 0 | H24: =H23*H21 -> 0 | I24: =I23 -> 0 | J24: =J23 -> 0 | K24: =K23 -> 0 | L24: =L23 -> 0 | M24: =M23 -> 129 | N24: =N23 -> 0 | O24: =O23*O21 -> 0 | P24: =P23 -> 167 | Q24: =Q23 -> 0 | R24: =R23 -> 0 | S24: =S23 -> 0 | T24: =T23*T21 -> 0 | U24: =U23*$U$3 -> 0 | V24: =V23*V21 -> 0 | W24: =W23*W21 -> 0 | X24: =X23*$X$3 -> 0 | Y24: =Y23*$Y$3 -> 0 | Z24: =Z23*$Z$3 -> 0 | AA24: =AA23*$AA$3 -> 39.069767 | AB24: =SUM(AB23:AB23) -> 2 | AC24: L9 | AD24: =D24+AA24+U24+X24+Y24+Z24+E24 -> 39.069767 | AE24: =F24 -> 154.4 | AF24: =I24+J24+K24+L24+M24+N24 -> 129 | AG24: =P24+Q24+R24+S24 -> 167
A25: L10
A26: L10 | D26: 0 | E26: 0 | F26: 98 | G26: 55.89 | H26: 23 | I26: 0 | J26: 43 | K26: 0 | L26: 0 | M26: 82 | N26: 0 | O26: 0 | P26: 72 | Q26: 0 | R26: 0 | S26: 0 | T26: 0 | U26: 0 | V26: 0 | W26: 0 | X26: 0 | Y26: 0 | Z26: 0 | AA26: 240 | AB26: 0
C27: SUB-TOTAL | D27: =D26*$D$3 -> 0 | E27: =E26*E3 -> 0 | F27: =F26 -> 98 | G27: =G26*G24 -> 0 | H27: =H26*H24 -> 0 | I27: =I26 -> 0 | J27: =J26 -> 43 | K27: =K26 -> 0 | L27: =L26 -> 0 | M27: =M26 -> 82 | N27: =N26 -> 0 | O27: =O26*O24 -> 0 | P27: =P26 -> 72 | Q27: =Q26 -> 0 | R27: =R26 -> 0 | S27: =S26 -> 0 | T27: =T26*T24 -> 0 | U27: =U26*$U$3 -> 0 | V27: =V26*V24 -> 0 | W27: =W26*W24 -> 0 | X27: =X26*$X$3 -> 0 | Y27: =Y26*$Y$3 -> 0 | Z27: =Z26*$Z$3 -> 0 | AA27: =AA26*$AA$3 -> 27.906977 | AB27: =SUM(AB26:AB26) -> 0 | AC27: L10 | AD27: =D27+AA27+U27+X27+Y27+Z27+E27 -> 27.906977 | AE27: =F27 -> 98 | AF27: =I27+J27+K27+L27+M27+N27 -> 125 | AG27: =P27+Q27+R27+S27 -> 72 | AI27: {=SUM(F26:Z26+F29:Z29+F41:Z41)} -> 875.01
A28: L11
A29: L11 | D29: 0 | E29: 0 | F29: 120.8 | G29: 58.32 | H29: 24 | I29: 0 | J29: 82 | K29: 0 | L29: 0 | M29: 136 | N29: 0 | O29: 0 | P29: 80 | Q29: 0 | R29: 0 | S29: 0 | T29: 0 | U29: 0 | V29: 0 | W29: 0 | X29: 0 | Y29: 0 | Z29: 0 | AA29: 518 | AB29: 0
C30: SUB-TOTAL | D30: =D29*$D$3 -> 0 | E30: =E29*$E3 -> 0 | F30: =F29 -> 120.8 | G30: =G29*G27 -> 0 | H30: =H29*H27 -> 0 | I30: =I29 -> 0 | J30: =J29 -> 82 | K30: =K29 -> 0 | L30: =L29 -> 0 | M30: =M29 -> 136 | N30: =N29 -> 0 | O30: =O29*O27 -> 0 | P30: =P29 -> 80 | Q30: =Q29 -> 0 | R30: =R29 -> 0 | S30: =S29 -> 0 | T30: =T29*T27 -> 0 | U30: =U29*$U$3 -> 0 | V30: =V29*V27 -> 0 | W30: =W29*W27 -> 0 | X30: =X29*$X$3 -> 0 | Y30: =Y29*$Y$3 -> 0 | Z30: =Z29*$Z$3 -> 0 | AA30: =AA29*$AA$3 -> 60.232558 | AB30: =SUM(AB29:AB29) -> 0 | AC30: L11 | AD30: =D30+AA30+U30+X30+Y30+Z30+E30 -> 60.232558 | AE30: =F30 -> 120.8 | AF30: =I30+J30+K30+L30+M30+N30 -> 218 | AG30: =P30+Q30+R30+S30 -> 80
A31: L12
A32: L12 | D32: 493 | E32: 0 | F32: 182.4 | G32: 60.75 | H32: 25 | I32: 0 | J32: 0 | K32: 0 | L32: 0 | M32: 286 | N32: 0 | O32: 0 | P32: 0 | Q32: 103 | R32: 0 | S32: 0 | T32: 0 | U32: 0 | V32: 0 | W32: 0 | X32: 0 | Y32: 0 | Z32: 0 | AA32: 0 | AB32: 0
C33: SUB-TOTAL | D33: =D32*$D$3 -> 61.625 | E33: =E32*$E3 -> 0 | F33: =F32 -> 182.4 | G33: =G32*G27 -> 0 | H33: =H32*H27 -> 0 | I33: =I32 -> 0 | J33: =J32 -> 0 | K33: =K32 -> 0 | L33: =L32 -> 0 | M33: =M32 -> 286 | N33: =N32 -> 0 | O33: =O32*O30 -> 0 | P33: =P32 -> 0 | Q33: =Q32 -> 103 | R33: =R32 -> 0 | S33: =S32 -> 0 | T33: =T32*T30 -> 0 | U33: =U32*$U$3 -> 0 | V33: =V32*V27 -> 0 | W33: =W32*W27 -> 0 | X33: =X32*$X$3 -> 0 | Y33: =Y32*$Y$3 -> 0 | Z33: =Z32*$Z$3 -> 0 | AA33: =AA32*$AA$3 -> 0 | AB33: =SUM(AB32:AB32) -> 0 | AC33: L12 | AD33: =D33+AA33+U33+X33+Y33+Z33+E33 -> 61.625 | AE33: =F33 -> 182.4 | AF33: =I33+J33+K33+L33+M33+N33 -> 286 | AG33: =P33+Q33+R33+S33 -> 103
A34: L425
A35: L425 | D35: 475 | E35: 0 | F35: 325.6 | G35: 111.78 | H35: 46 | I35: 0 | J35: 8 | K35: 0 | L35: 0 | M35: 478 | N35: 0 | O35: 0 | P35: 80 | Q35: 108 | R35: 0 | S35: 0 | T35: 0 | U35: 0 | V35: 0 | W35: 0 | X35: 0 | Y35: 0 | Z35: 0 | AA35: 367 | AB35: 0
C36: SUB-TOTAL | D36: =D35*$D$3 -> 59.375 | E36: =E35*$E6 -> 0 | F36: =F35 -> 325.6 | G36: =G35*G27 -> 0 | H36: =H35*H27 -> 0 | I36: =I35 -> 0 | J36: =J35 -> 8 | K36: =K35 -> 0 | L36: =L35 -> 0 | M36: =M35 -> 478 | N36: =N35 -> 0 | O36: =O35*O33 -> 0 | P36: =P35 -> 80 | Q36: =Q35 -> 108 | R36: =R35 -> 0 | S36: =S35 -> 0 | T36: =T35*T27 -> 0 | U36: =U35*$U$3 -> 0 | V36: =V35*V27 -> 0 | W36: =W35*W27 -> 0 | X36: =X35*$X$3 -> 0 | Y36: =Y35*$Y$3 -> 0 | Z36: =Z35*$Z$3 -> 0 | AA36: =AA35*$AA$3 -> 42.674419 | AB36: =SUM(AB35:AB35) -> 0 | AC36: L425 | AD36: =D36+AA36+U36+X36+Y36+Z36+E36 -> 102.04942 | AE36: =F36 -> 325.6 | AF36: =I36+J36+K36+L36+M36+N36 -> 486 | AG36: =P36+Q36+R36+S36 -> 188
A37: L460
A38: L460 | D38: 0 | E38: 0 | F38: 106.2 | G38: 46.17 | H38: 19 | I38: 0 | J38: 2 | K38: 0 | L38: 0 | M38: 207 | N38: 0 | O38: 0 | P38: 65 | Q38: 0 | R38: 0 | S38: 0 | T38: 0 | U38: 0 | V38: 0 | W38: 0 | X38: 0 | Y38: 0 | Z38: 0 | AA38: 527 | AB38: 0
C39: SUB-TOTAL | D39: =D38*$D$3 -> 0 | E39: =E38*$E9 -> 0 | F39: =F38 -> 106.2 | G39: =G38*G30 -> 0 | H39: =H38*H30 -> 0 | I39: =I38 -> 0 | J39: =J38 -> 2 | K39: =K38 -> 0 | L39: =L38 -> 0 | M39: =M38 -> 207 | N39: =N38 -> 0 | O39: =O38*O36 -> 0 | P39: =P38 -> 65 | Q39: =Q38 -> 0 | R39: =R38 -> 0 | S39: =S38 -> 0 | T39: =T38*T30 -> 0 | U39: =U38*$U$3 -> 0 | V39: =V38*V30 -> 0 | W39: =W38*W30 -> 0 | X39: =X38*$X$3 -> 0 | Y39: =Y38*$Y$3 -> 0 | Z39: =Z38*$Z$3 -> 0 | AA39: =AA38*$AA$3 -> 61.27907 | AB39: =SUM(AB38:AB38) -> 0 | AC39: L460 | AD39: =D39+AA39+U39+X39+Y39+Z39+E39 -> 61.27907 | AE39: =F39 -> 106.2 | AF39: =I39+J39+K39+L39+M39+N39 -> 209 | AG39: =P39+Q39+R39+S39 -> 65
A40: SV
...

Sheet Sheet1
C1: dyna/215 | D1: 135 | E1: 38 | F1: anfo | G1: nonel | H1: cordtex
B2: L4 | C2: 221 | F2: 117 | G2: 161 | H2: 57
C3: 109 | D3: 29 | F3: 40 | G3: 57 | H3: 37
C7: =SUM(C2:C6) -> 330 | F7: =SUM(F2:F6) -> 157 | G7: =SUM(G2:G6) -> 218 | H7: =SUM(H2:H6) -> 94
B8: L5 | C8: 123 | F8: 62 | H8: 43
C9: 125 | F9: 42 | G9: 90 | H9: 29
G10: 63
C13: =SUM(C8:C12) -> 248 | F13: =SUM(F8:F12) -> 104 | G13: =SUM(G8:G12) -> 153 | H13: =SUM(H8:H12) -> 72
B14: L6
C15: 136 | F15: 71 | G15: 104 | H15: 31
C16: 130 | F16: 30 | G16: 57 | H16: 15
C17: 140 | D17: 4 | F17: 18 | G17: 38 | H17: 16
C19: =SUM(C14:C18) -> 406 | F19: =SUM(F14:F18) -> 119 | G19: =SUM(G14:G18) -> 199 | H19: =SUM(H14:H18) -> 62
B20: L7 | C20: 205
C21: 253 | D21: 4 | F21: 45 | G21: 90 | H21: 29
C22: 20 | D22: 22 | F22: 16 | G22: 45 | H22: 15
G23: 26 | H23: 11
C25: =SUM(C20:C24) -> 478 | F25: =SUM(F20:F24) -> 61 | G25: =SUM(G20:G24) -> 161 | H25: =SUM(H20:H24) -> 55
B26: L8 | F26: 72
C27: 221 | D27: 3 | F27: 98 | G27: 119 | H27: 51
C28: 188 | F28: 9 | G28: 131 | H28: 47
C29: 229 | G29: 129 | H29: 50
C31: =SUM(C26:C30) -> 638 | F31: =SUM(F26:F30) -> 179 | G31: =SUM(G26:G30) -> 379 | H31: =SUM(H26:H30) -> 148
B32: L9
C33: 190 | D33: 10 | F33: 113 | G33: 148 | H33: 56
C34: 104 | D34: 4 | F34: 55 | G34: 74 | H34: 37
C35: 295 | D35: 8 | F35: 166 | G35: 219 | H35: 85
C37: =SUM(C32:C36) -> 589 | F37: =SUM(F32:F36) -> 334 | G37: =SUM(G32:G36) -> 441 | H37: =SUM(H32:H36) -> 178
B38: L10
C40: 1058 | D40: 55 | E40: 23 | F40: 475 | G40: 652 | H40: 265
C43: =SUM(C38:C42) -> 1058 | F43: =SUM(F38:F42) -> 475 | G43: =SUM(G38:G42) -> 652 | H43: =SUM(H38:H42) -> 265 | I43: =SUM(C43:H43) -> 2450
C44: =C55+C61 -> 424 | D44: =D55+D61 -> 0 | F44: =F55+F61 -> 94 | G44: =G55+G61 -> 180 | H44: =H55+H61 -> 59
C45: =C43-C44 -> 634 | D45: =D43-D44 -> 0 | F45: =F43-F44 -> 381 | G45: =G43-G44 -> 472 | H45: =H43-H44 -> 206 | I45: =SUM(C45:H45) -> 1693 | L45: L10 | M45: =I43 -> 2450
L46: L11 | M46: =I55 -> 514
L47: L12 | M47: =I61 -> 243
B48: L11 | C48: 30 | F48: 13 | G48: 24 | H48: 10 | L48: remaining | M48: =M45-M46-M47 -> 1693
C49: 47 | F49: 21 | G49: 27 | H49: 8
C50: 68 | F50: 16 | G50: 28 | H50: 9
C51: 50 | F51: 16 | G51: 25 | H51: 8
C52: 66 | F52: 14 | G52: 26 | H52: 8
...

Sheet SUMMARY
F3: Explosives used
F4: Level | G4: EMULSION (KG) | H4: ANFO (KG) | I4: DETONATORS (PCS) | J4: DETCORDS (MTR)
F5: L3 | G5: ='EXPLOSIVES KG USED'!AD6 -> 0 | H5: ='EXPLOSIVES KG USED'!AE6 -> 0 | I5: ='EXPLOSIVES KG USED'!AF6 -> 0 | J5: ='EXPLOSIVES KG USED'!AG6 -> 0
F6: L4 | G6: ='EXPLOSIVES KG USED'!AD9 -> 0 | H6: ='EXPLOSIVES KG USED'!AE9 -> 0 | I6: ='EXPLOSIVES KG USED'!AF9 -> 0 | J6: ='EXPLOSIVES KG USED'!AG9 -> 0
F7: L 5 | G7: ='EXPLOSIVES KG USED'!AD12 -> 0 | H7: ='EXPLOSIVES KG USED'!AE12 -> 0 | I7: ='EXPLOSIVES KG USED'!AF12 -> 0 | J7: ='EXPLOSIVES KG USED'!AG12 -> 0
F8: L 6 | G8: ='EXPLOSIVES KG USED'!AD15 -> 0 | H8: ='EXPLOSIVES KG USED'!AE15 -> 0 | I8: ='EXPLOSIVES KG USED'!AF15 -> 0 | J8: ='EXPLOSIVES KG USED'!AG15 -> 0
F9: L 7 | G9: ='EXPLOSIVES KG USED'!AD18 -> 0 | H9: ='EXPLOSIVES KG USED'!AE18 -> 0 | I9: ='EXPLOSIVES KG USED'!AF18 -> 0 | J9: ='EXPLOSIVES KG USED'!AG18 -> 0
F10: L 8 | G10: ='EXPLOSIVES KG USED'!AD21 -> 36.395349 | H10: ='EXPLOSIVES KG USED'!AE21 -> 132 | I10: ='EXPLOSIVES KG USED'!AF21 -> 156 | J10: ='EXPLOSIVES KG USED'!AG21 -> 136
F11: L 9 | G11: ='EXPLOSIVES KG USED'!AD24 -> 39.069767 | H11: ='EXPLOSIVES KG USED'!AE24 -> 154.4 | I11: ='EXPLOSIVES KG USED'!AF24 -> 129 | J11: ='EXPLOSIVES KG USED'!AG24 -> 167
F12: L 10 | G12: ='EXPLOSIVES KG USED'!AD27 -> 27.906977 | H12: ='EXPLOSIVES KG USED'!AE27 -> 98 | I12: ='EXPLOSIVES KG USED'!AF27 -> 125 | J12: ='EXPLOSIVES KG USED'!AG27 -> 72
F13: L 11 | G13: ='EXPLOSIVES KG USED'!AD30 -> 60.232558 | H13: ='EXPLOSIVES KG USED'!AE30 -> 120.8 | I13: ='EXPLOSIVES KG USED'!AF30 -> 218 | J13: ='EXPLOSIVES KG USED'!AG30 -> 80
F14: L 12 | G14: ='EXPLOSIVES KG USED'!AD33 -> 61.625 | H14: ='EXPLOSIVES KG USED'!AE33 -> 182.4 | I14: ='EXPLOSIVES KG USED'!AF33 -> 286 | J14: ='EXPLOSIVES KG USED'!AG33 -> 103
F15: L425 | G15: ='EXPLOSIVES KG USED'!AD36 -> 102.04942 | H15: ='EXPLOSIVES KG USED'!AE36 -> 325.6 | I15: ='EXPLOSIVES KG USED'!AF36 -> 486 | J15: ='EXPLOSIVES KG USED'!AG36 -> 188
F16: L460 | G16: ='EXPLOSIVES KG USED'!AD39 -> 61.27907 | H16: ='EXPLOSIVES KG USED'!AE39 -> 106.2 | I16: ='EXPLOSIVES KG USED'!AF39 -> 209 | J16: ='EXPLOSIVES KG USED'!AG39 -> 65
F17: SV | G17: ='EXPLOSIVES KG USED'!AD42 -> 0 | H17: ='EXPLOSIVES KG USED'!AE42 -> 0 | I17: ='EXPLOSIVES KG USED'!AF42 -> 0 | J17: ='EXPLOSIVES KG USED'!AG42 -> 0
F20: TOTAL | G20: =SUM(G5:G17) -> 388.55814 | H20: =SUM(H5:H17) -> 1119.4 | I20: =SUM(I5:I17) -> 1609 | J20: =SUM(J5:J17) -> 811
G21: ='EXPLOSIVES KG USED'!AD47 -> 388.55814 | H21: ='EXPLOSIVES KG USED'!AE47 -> 1119.4 | I21: ='EXPLOSIVES KG USED'!AF47 -> 1609 | J21: ='EXPLOSIVES KG USED'!AG47 -> 811
G22: =G20-G21 -> 0 | H22: =H20-H21 -> 0 | I22: =I20-I21 -> 0 | J22: =J20-J21 -> 0
