Workbook

Sheet FOR OMWS (2)
A1: ACTIVE | D1: STOPPED
A2: WORKING PLACES | B2: TEAM LEADER
A3: {=#REF!} -> #REF!
A20: {=#REF!} -> #REF!
A37: {=#REF!} -> #REF!
A54: {=#REF!} -> #REF!
A71: {=#REF!} -> #REF!
A88: {=#REF!} -> #REF!
A105: {=#REF!} -> #REF!
A122: {=#REF!} -> #REF!
A139: {=#REF!} -> #REF!
A154: {=#REF!} -> #REF!
A170: {=#REF!} -> #REF!
A186: {=#REF!} -> #REF!
... A1047: {=#REF!} -> #REF!

Sheet FINAL LIST WITH REMARKS
B3: STOPE PREP | E3: BREAKING | H3: PULL OUT | K3: DRIFT | N3: RAISES | Q3: WINZES | T3: CROSSCUT | W3: ROBBING / SPECIAL PROJECT
A4: LEVEL 4 | B4: L03_JV_014W_WINZE STOPE PREP | C4: FERNANDEZ, RM | D4: REPLACEMENT OF L03_JV_014W_RAISE. APPROVED ON DECEMBER 11, 2024. TEMPORARY STOPPED ON FEBRUARY 25, 2025 TO PRIORITIZE SPECIAL PROJECT AT L03_003E_ML. STOPPED ON MARCH 31, 2025. TO BE CONVERTED TO STOPE BREAKING. RESUMED AND CONVERTED TO STOPE BREAKING. APPROVED ON MARCH 31, 2025. | E4: L03_JV_014W_WINZE STOPE | F4: FERNANDEZ, RM | G4: REPLACEMENT OF L03_JV_014W_RAISE. APPROVED ON DECEMBER 11, 2024. TEMPORARY STOPPED ON FEBRUARY 25, 2025 TO PRIORITIZE SPECIAL PROJECT AT L03_003E_ML. RESUMED AND CONVERTED TO STOPE BREAKING. APPROVED ON MARCH 31, 2025. STOPPED BREAKING JULY 09,2025 DUE TO NO DATA ON THE UPPER AREA TOWARDS SMALL SCALE MINING ACTIVITIES. FOR STOPE TRAVERSE. | H4: L03_JV_014W_WINZE STOPE | I4: FERNANDEZ, RM | J4: REPLACEMENT OF L03_JV_014W_RAISE. APPROVED ON DECEMBER 11, 2024. TEMPORARY STOPPED ON FEBRUARY 25, 2025 TO PRIORITIZE SPECIAL PROJECT AT L03_003E_ML. RESUMED AND CONVERTED TO STOPE BREAKING. APPROVED ON MARCH 31, 2025. STOPPED BREAKING JULY 09, 2025 DUE TO NO DATA ON THE UPPER AREA TOWARDS SMALL SCALE MINING ACTIVITIES. FOR STOPE TRAVERSE. CONVERTED TO PULL-OUT. APPROVED ON JULY 10, 2025 3RD SHIFT.TO BE CONVERTED INTO ROBBING. STOPPED ON AUGUST 5, 2025. | K4: L03_JV_043W_DW | L4: FERNANDEZ, RM | M4: REPLACEMENT OF L03_JV_040W_ML CLEANINING. APPROVED ON OCTOBER 30, 2024. TEMPORARY STOPPED ON NOVEMBER 22, 2024 DUE TO COLLAPSED ON BAGUIO SHAFT AREA. FOR EVALUATION. RESUMED ON MAY 03, 2025. STOPPED ON JUNE 10, 2025. CHANGE STATUS TO ML CLEANING. | N4: L03_GHV_051W_RAISE | O4: FERNANDEZ 6 | P4: ADDITIONAL WORKING PLACE. MUST LIMIT BREAKING UNTIL +20m SLOPE DISTANCE. APPROVED ON SEPTEMBER 11, 2025.RENAMED FROM L03_GHV_051E_RAISE TO L03_GHV_051W_RAISE FOR PROPER POSITIONING. APPROVED ON SEPTEMBER 19, 2025. RENAMED TEAMLEADER FROM FERNANDEZ TO FERNANDEZ 6. APPROVED ON OCTOBER 13, 2025. STOPPED ON OCTOBER 24, 2025. ALREADY MADE A BREAKTHROUGH. | Q4: L03_JV_014W_WINZE | R4: FERNANDEZ, RM 6 | S4: REPLACEMENT OF L03_CTV_021W_WINZE. APPROVED ON MARCH 01, 2024.STOPPED ON MAY 10, 2024. ALREADY REACHED THE RECOMMENDED SLOPE DISTANCE. | T4: L04_NONE_026W_XCN | U4: MARTINEZ, DN 4 | V4: TARGETING CV VEIN FOR ROBBING. APPROVED ON FEB. 28, 2023.STOPPED ON MARCH 20, 2023. ALREADY FINISHED HEADING. | W4: L03_NONE_025W_XCS | X4: NITRO AV 1 | Y4: ACCESS VENTILATION SHAFT AND VENTILATION RAISE FOR INSPECTION, APPROVED ON FEB.5,2017.STOPPED ON MARCH 25, 2017 AS PER EC BAGUNO. (FINISHED). NO MEMO RECEIVED YET. RESUMED ON JULY 5, 2017 FOR THE PURPOSE OF EXTRACTING REMAINING ORES AND TO COLLAPSE THE CURRENT BACK OF THE OLD MAINLINE FOR BLOCKING PROBABLE ACCESS OF INTRUDERS. STOPPED ON JULY 17, 2017 AS PER LH FRAGINAL. REPLACED BY 38W ROBBING.resumed on august 7, 2021 for widening as access for L01 ventilation raise. TRANSFER FROM DAGAMAC 1 TO SHEPHERD AV1 ON AUGUST 6,2022.CHANGE NAME FROM L04_NONE_025W_XCS TO L03_NONE_025W_XCS DUE TO EXPLOSIVE WITHDRAWAL ISSUE.
B5: L04_JV_020W_STOPE PREP | C5: MARTINEZ, DN 4 | D5: REPLACEMENT OF L04_JV_024W_ROBBING APPROVED ON NOVEMBER 7, 2023.STOPPED ON NOVEMBER 8, 2023, MADE A BREAKTHROUGH TO AN OLD STOPE. | E5: L04_CTV_010W_WINZE STOPE | F5: MARTINEZ, DN 3 | G5: REPLACEMENT OF L04_CTV_010W_WINZE STOPE PREP. APPROVED ON NOVEMBER 28, 2023. TEMPORARILY STOPPED ON JANUARY 16, 2024. 3RD SHIFT. DUE TO LACK OF MANPOWER.RESUMED ON JANUARY 17, 2024. 3RD SHIFT.STOPPED BREAKING ON FEBRUARY 12, 2024. CONVERTED TO PULL-OUT CLEANING. | H5: L04_JVSPLIT_028E_WINZE STOPE | I5: MARTINEZ DN 2 | J5: REPLACEMENT OF L04_JVSPLIT_028E_WINZE_STOPE PREP.APPROVED ON JULY 3,2022.STOPPED ON OCTOBER 7, 2022, CONVERTED TO STOPE PULLOUT.MINED-OUT ON NOVEMBER 21, 2022 WITH 107% PULL-OUT MC. | K5: L04_CV_007E_DW_ISL | L5: MARTINEZ, DN 4 | M5: REPLACEMENT OF L04_CV_006E_DE_ISL .APPROVED ON 2/14/2023.TEMP STOPPED ON MAR 25, 2023 DUE TO MANPOWER ISSUE,RESUMED ON MARCH 28, 2023.STOPPED ON MAY 05, 2023. CONVERTED TO WINZE STOPE PREP.RESUMED ON MAY 19, 2023 AS WELL AS RENAME FROM L04_CV_006E_DW_ISL TO L04_CV_007E_DW_ISL.STOPPED ON JUNE 8, 2023. DUE TO LOW ASSAY GRADE.RESUMED ON NOVEMBER 24, 2023. AS WELL AS CHANGED TEAM LEADER FROM MARTINEZ, RON 1 TO MARTINEZ, DN 4.TEMPORARY STOPPED ON DECEMBER 6, 2023 DUE TO UNSAFE CONDITION OF THE WORKPLACE BASED ON THE JOINT EVALUATION AND ASSESSMENT OF THE CONCERNED DEPARTMENTS AFTER THE EARTHQUAKE INCIDENT. FOR FURTHER EVALUATION. STOPPED ON DECEMBER 09, 2023. MEMO FROM GEO. CURRENT FACE IS APPROACHING L05_NVN_001E_STOPE BASED ON MAP. | N5: L03_CTV_020W_RAISE | O5: FERNANDEZ, RM 2 | P5: REPLACEMENT OF L03_CTV_017W_DE. APPROVED ON APRIL 14, 2023.STOPPED ON MAY 17, 2023. MADE A BREAKTHROUGH. | Q5: L03_CTV_021W_WINZE | R5: FERNANDEZ, RM 6 | S5: REPLACEMENT OF L03_CTV_021W_ROBBING. APPROVED ON JANUARY 24, 2024.STOPPED ON FEBRUARY 29, 2024. DUE TO CONSECUTIVE LOW ASSAY GRADE ON CUT SAMPLES/BULK SAMPLES. | T5: L04_NONE_012W_XCS | U5: SHEPHERD AQ 1 | V5: CROSSCUT TO BREAKTHROUGH TO OPPOSITE MAINLINE TO TARGET BACK UP ROBBING. APPROVED ON SEPTEMBER 20,2022.STOPPED ON OCTOBER 18, 2022 ALREADY BREAKTHROUGH TO THE OLD MAINLINE. | W5: L03_GHV_053W_ROBBING | X5: FERNANDEZ 6 | Y5: REPLACEMENT OF L03_GHV_051W_RAISE. APPROVED ON OCOTBER 29, 2025. TEMPORARY STOPPED ON DECEMBER 06, 2025, DUE TO INACCESSIBILITY OF MAINLINE CAUSED BY COLLAPSED PORTION AT 5W RAISE. RESUMED FOR OPERATIONS ON MARCH 21, 2026. JOINT MANPOWER WITH L03_GHV_052E_ROBBING.
B6: L04_CV_006E_WINZE_STOPE PREP | C6: MARTINEZ, RON 1 | D6: REPLACEMENT OF L04_CV_006E_DW_ISL. APPROVED ON MAY 05, 2023.ALREADY DONE STOPE PREP ON MAY 20, 2023. CONVERT TO STOPE BREAKING. | E6: L04_CV_006E_WINZE_STOPE | F6: MARTINEZ, DN 4 | G6: REPLACEMENT OF L04_CV_006E_DW_ISL. APPROVED ON MAY 05, 2023.ALREADY DONE STOPE PREP ON MAY 20, 2023. CONVERT TO STOPE BREAKING.REPLACEMENT OF L04_CV_006E_WINZE_STOPE PREP, APPROVED ON MAY 20, 2023.TEMPORARY STOPPED ON JUNE 8, 2023 DUE TO THE UNAVAILABIILITY OF AGSAO SHAFT.RESUMED ON OCTOBER 02, 2023. AS WELL AS CHANGED TEAM LEADER FROM MARTINEZ, RON 1 TO MARTINEZ, DN 4.STOPPED BREAKING ON NOVEMBER 09, 2023. AS WELL AS TRAVERSED ON NOVEMBER 10, 2023, 2ND SHIFT. CONVERT TO PULL-OUT CLEANING. | H6: L04_CTV_022W_WINZE STOPE | I6: SHEPHERD AQ 2 | J6: REPLACEMENT ON L04_CTV_022W_WINZE STOPE PREP. APPROVED ON MAY 31,2022.STOPPED BREAKING ON SEPTEMBER 6, 2022 AND CONVERT TO PULL-OUT.MINED-OUT ON SEPTEMBER 26, 2022 WITH 105% PULL-OUT MC. | K6: L04_JVS_008W_DW | L6: MARTINEZ DN 1 | M6: REPLACEMENT OF L04_GHVFW_011E_ROBBING. APPROVED ON OCTOBER 19, 2023.STOPPED ON OCTOBER 20, 2023, TO PRIORITIZE CLEANING.. | N6: L04_CTV_023W_RAISE | O6: CAYMAN 1 | P6: RAISE ON ISL. APPROVED ON FEBRUARY 6, 2023.STOPPED ON FEBRUARY 9, 2023 . TO PROCEED TO WINZE STOPE PREP | Q6: L03_CTV_014W_WINZE | R6: FERNANDEZ, RM 4 | S6: ADDITIONAL FILL WINZE IN LEVEL 3. APPROVED ON JANUARY 08, 2024.STOPPED ON JANUARY 18 2024. ALREADY MADE A BREAKTHROUGH. | T6: L04_NONE_016E_XCN | U6: SHEPHERD AQ | V6: ADDITIONAL HORIZONTAL DEVT APPROVED ON JAN 10, 2022.STOPPED ON FEB.9,2022 | W6: L03_NONE_047E_MAINLINE CLEANING | X6: FERNANDEZ | Y6: NEW WORKING PLACE OF L03. MANPOWER FROM L03_GHV_052E_ROBBING. SPECIAL PROJECT TO ACCESS THE BACK-UP FOR ROBBING. APPROVED ON MAY 18, 2026.
B7: L04_CTV_023W_WINZE STOPE PREP | C7: CAYMAN 3 | D7: REPLACEMENT OF L04_CTV_023W_RAISE. APPROVED ON 2/10/2023.STOPPED AND CONVERT TO STOPE BREAKING ON MARCH 01, 2023.STOPPED AND CONVERT TO STOPE BREAKING ON MARCH 01, 2023. | E7: L04_CTV_023W_WINZE STOPE | F7: CAYMAN 3 | G7: REPLACEMENT OF L04_CTV_023W_WINZE STOPE APPROVED ON MARCH 01, 2023.STOPPED BREAKING ON APRIL 21, 2023. DUE TO ADJACENT STOPE BREAKTHROUGH. | H7: L04_CV_006E_STOPE | I7: MARTINEZ, RON 3 | J7: REPLACEMENT OF L04_CV_006E_STOPE PREP. APPROVED ON JUNE 22, 2022.STOPPED ON AUGUST 24, 2022 AT THE SAME TIME CONVERTED TO PULLOUT CLEANING.MINED OUT ON SEPTEMBER 12, 2022 WITH 87% PULL-OUT MC. | K7: L04_JV_020W_DE | L7: CAYMAN 1 | M7: ADDITONAL HORIZONTAL DEVELOPMENT DRIVE. APPROVED ON APRIL 26, 2023.CHANGED VEIN POSITION FROM L04_JV_027W_DE TO L04_JV_020W_DE FOR PROPER NAMING.STOPPED ON MAY 18, 2023. DUE TO CONSECUTIVE LOW ASSAY GRADE. | N7: L04_RYV_001W_RAISE | O7: APA 1 | P7: REPLACEMENT OF L04_RYV_001E_RAISE. APPROVED ON JANUARY 27,2023.STOPPED ON JAN 30, 2023. VEIN PINCHED OUT. | Q7: L04_CTV_010W_WINZE | R7: MARTINEZ, DN 3 | S7: REPLACEMENT OF L04_CTV_012W_ROBBING. APPROVED ON MAY 17, 2023.TEMPORARY STOPPED ON JUNE 8, 2023 DUE TO THE UNAVAILABIILITY OF AGSAO SHAFT.RESUMED ON OCTOBER 02, 2023.STOPPED ON OCTOBER 11, 2023.ALREADY MADE A BREAKTHROUGH. | T7: L04_NONE_028W_XCN_ISL | U7: MARTINEZ DN 1 | V7: REPLACEMENT OF L04_JVHW_027W_DW_ISL APPROVED ON SEPTEMBER 14, 2021.STOPPED ON SEMPTEBER 22, 2021 | W7: L03_NONE_045W_MAINLINE_CLEANING | X7: FERNANDEZ, RM | Y7: REPLACEMENT OF L03_NONE_043W_DW. MAILINE CLEANING ACTIVITIES INCLUDES GROUND SUPPORT INSTALLATION,CLEANING AND INSTALLATION OF RAILINGS AND WIDENINGS.APPROVED ON AUGUST 3, 2025. STOPPED ON MARCH 21, 2026. ALREADY FINISHED MAINLINE ACTIVITIES AND CLEANING.
B8: L04_GHVFW_010E_WINZE STOPE PREP | C8: MARTINEZ DN 1 | D8: REPLACEMENT OF L04_GHVFW_010E_DE_ISL APPROVED ON AUGUST 15, 2022.STOPPED AND CONVERT TO BREAKING ON AUGUST 31, 2022. | E8: L04_GHVFW_010E_WINZE STOPE | F8: MARTINEZ DN 1 | G8: REPLACEMENT OF L04_GHVFW_010E_WINZE STOPE PREP. APPROVED ON SEPTEMBER 1, 2022.CONDUCTED FILL RAISE ON OCTOBER 19, 2022. | H8: L04_CTV_021W_STOPE | I8: NOCOS 2 | J8: REPLACEMENT OF L04_CTV_021W_ROBBING APPROVED ON JULY 8,2021.stopped on oct.19 ,2021 unsafe.RESUME ON OCT.20, 2021.stopped on nov. 15,2021 converted to pull-out cleaning.TEMP STOPPED ON MARCH 16, 2022. | K8: L03_CTV_017W_DE | L8: FERNANDEZ, RM 2 | M8: REPLACEMENT OF L03_JVSPLIT_023W_ROBBING. APPROVED ON FEBRUARY 03, 2023.TEMPORARY STOPPED ON APRIL 14, 2023. TO PRIORITIZE OTHER VERTICAL DEVELOPMENT.RESUMED ON APRIL 26, 2023.STOPPED ON MAY 10, 2023. ALREADY MADE A BREAKTHROUGH. MEMO TO BE FOLLOWED.STOPPED MEMO RECEIVED ON MAY 12, 2023. | N8: L04_RYV_001E_RAISE | O8: APA 1 | P8: REPLACEMENT OF L04_RYV_001E_DW. APPROVED ON NOV 28 2022.TEMPORARILY STOPPED ON DEC 5 2022 DUE TO MAINLINE COLLAPSE.RESUMED ON DEC. 10, 2022.TEMPORARILY STOPPED ON DECEMBER 14, 2022 DUE TO LACK OF MANPOWER.RESUMED ON JANUARY 10, 2023.CHANGE NAME OF TEAM LEADER FROM SHEPHERD AR 1 TO APA 1, FULL PLEDGED TEAM LEADER APPROVED ON DECEMBER 20,2022.STOPPED ON JANUARY 25,2023 DUE TO CONSECUTIVE LOW ASSAY GRADE | Q8: L03_CTV_016W_WINZE | R8: FERNANDEZ, RM 4 | S8: REPLACEMENT OF L03_CTV_016W_ROBBING. APPROVED ON APRIL 19, 2023. FILL WINZE.STOPPED ON APRIL 21, 2023. | T8: L04_NONE_024W_XCN | U8: MARTINEZ, RONALD 2 | V8: ADDITIONAL HORIZONTAL DEVELOPMENT. APPROVED ON FEB 2 2021.CHANGE WORK HEADING INTO L04 JVSPLIT 024W DW. APPPROVED ON FEBRUARY 11,2021.STOPPED ON FEB. 11, 2021.resumed on april 16, 2021.STOPPED ON JUNE 10,2021 NOTIFY ON JUNE 15, 2021 ALREADY BREAKTHROUGH. | W8: L03_CTV_025W_RAISE | X8: FERNANDEZ, RM 5 | Y8: ADDITIONAL VERTICAL DEVELOPMENT. APPROVED ON JUNE 14, 2024. BLOCKING RAISE.RENAMED FROM L03_DPVE_025W_RAISE TO L03_CTV_025W_RAISE. FOR PROPER NAMING OF VEIN. APPROVED ON JULY 06, 2024.STOPPED ON AUGUST 01, 2024. ALREADY MADE A BREAKTHROUGH.
B9: L04_JVSPLIT_028E_WINZE_STOPE PREP | C9: MARTINEZ DN 2 | D9: REPLACEMENT OF L04_JVSPLIT_028E_DE_ISL. APPROVED ON MAY 5, 2022.STOPPED ON JULY 2,2022 CONVERT TO ACTIVE BREAKING. | E9: L04_JVSPLIT_028E_WINZE STOPE | F9: MARTINEZ DN 2 | G9: REPLACEMENT OF L04_JVSPLIT_028E_WINZE_STOPE PREP.APPROVED ON JULY 3,2022.STOPPED ON OCTOBER 7, 2022, CONVERTED TO STOPE PULLOUT. | H9: L04_GHVSPLIT_029W_STOPE | I9: SHEPHERD AQ | J9: CONVERTED TO PULL-OUT ON FEBRUARY 12, 2022. MINED-OUT ON MARCH 12, 2022 WITH 105% PULL-OUT. | K9: L03_CTV_018W_DW | L9: FERNANDEZ, RM 2 | M9: REPLACEMENT OF L03_CTV_020W_ROBBING. APPROVED ON FEBRUARY 03, 2023. RENAMED FROM L03_CTV_017W_DW TO L03_CTV_018W_DW TO AVOID MISCHARGING APPROVED ON FEBRUARY 5, 2023.STOPPED ON MARCH 1, 2023. ALREADY MADE A BREAKTHROUGH. | N9: L04_JV_042W_RAISE | O9: MARTINEZ, RON 1 | P9: REPLACEMENT OF L04_CV_006E_WINZE APPROVED ON NOVEMBER 18, 2022.STOPPED ON DEC 6 2022 (3RD SHIFT) DUE TO LOW GRADE ASSAYS. | Q9: L04_CV_006E_WINZE | R9: MARTINEZ, RON 1 | S9: REPLACEMENT OF L04_CV_009W_ROBBING. APPROVED ON SEPTEMBER 24, 2022.TEMPORARY STOPPED ON NOVEMBER 18, 2022 TO PRIORITIZE NORMAL WORKPLACES. | T9: L04_NONE_022W_XCS | U9: BAÑEZ 9 | V9: REPLACEMENT OF L04_EDVSPLIT_021W_DW. APPROVED ON OCT 15 2020. TRANSFER FROM MANZANO 2 TO MARTINEZ ON 11/5/2020. TEMP STOPPED ON DEC 21 2020 DUE TO UNSERVICEABLE AREA.resumed on March 26,2021 at the same time transfer from MARTINEZ, DN TO BANEZ. TEMPORARY STOPPED ON MARCH 27,2021 TO PRIORITIZED BY PASS FOR VENTILATION.RESUME ON 4/19/21. CHANGED NAME FROM 21E TO 22E APRIL 23, 2021. CHANGED FROM 22E TO 22W AS PER LEVEL GEO ON APRIL 23, 2021. STOPPED ON MAY 24,2021 ALREADY HIT THE TARGET. | W9: L03_JV_028W_ROBBING | X9: FERNANDEZ, RM 2 | Y9: REPLACEMENT OF L03_JVSPLIT_034W_ROBBING. APPROVED ON MAY 9, 2024. SILL.STOPPED ON AUG 1, 2024 ALREADY FINISHED ROBBING PILLAR.STOPPED ON AUG 1, 2024 ALREADY FINISHED ROBBING PILLAR.
B10: L04_CTV_022W_WINZE STOPE PREP | C10: SHEPHERD AQ3 | D10: REPLACEMENT OF L04_GHVFW_027W_ROBBING AND L04_GHVSPLIT_041W_ROBBING RESUMED APRIL 25, 2022, CHANGE TEAM LEADER FROM COMAINGKING TO SHEPHERD AQ3.STOPPED ON MAY 31,2022 ALREADY BREAKTHROUGH. | E10: L04_CTV_022W_WINZE STOPE | F10: SHEPHERD AQ 3 | G10: REPLACEMENT ON L04_CTV_022W_WINZE STOPE PREP. APPROVED ON MAY 31,2022.STOPPED BREAKING ON SEPTEMBER 6, 2022 AND CONVERT TO PULL-OUT. | H10: L04_GHVSPLIT_031W_STOPE | I10: SHEPHERD AQ | J10: CONVERTED TO PULL OUT ON DECEMBER 09, 2021. STOPPED ON JANUARY 13, 2022 MINED OUT. | K10: L04_CV_006E_DE_ISL | L10: MARTINEZ, RON 1 | M10: REPLACEMENT OF L04_CV_006E_WINZE APPROVED ON JANUARY 10, 2023.STOPPED ON FEBRUARY 10, 2023 VEIN WAS CUT BY A N-S TRENDING FAULT, PINCHED OUT VEIN. | N10: L03_JVSPLIT_016W_RAISE | O10: FERNANDEZ, RM 2 | P10: REPLACEMENT OF L03_JVSPLIT_015W_RAISE. APPROVED ON NOVEMBER 4, 2022.STOPPED ON NOVEMBER 25, 2022 TO PRIORITIZE SILL PILLAR ROBBING. | Q10: L04_CV_009W_WINZE | R10: NOCOS 2 | S10: APPROVED ON JULY 19, 2022, REPLACEMENT OF L04_CV_025W_ROBBING.STOPPED ON AUGUST 31, 2022 DUE TO UNSAFE CONDITION. | T10: L04_NONE_007W_XCN | U10: MARTINEZ, RONALD | V10: ADDITIONAL HORIZONTAL DEVELOPMENT, APPROVED ON JANUARY 11 2021 TO BE USED AS MAINLINE FOR TRAMMING.STOPPED ON MARCH 2, 2021 MADE A BREAKTHROUGH. | W10: L03_JV_029E_ROBBING | X10: FERNANDEZ, RM 3 | Y10: REPLACEMENT OF L03_JVSPLIT_011W_ROBBING. APPROVED ON JUNE 06, 2024. SILL PILLAR.STOPPED ON JUNE 18, 2024. ALREADY FINISHED HEADING.
B11: L04_JVFW_010E_STOPE PREP | C11: COMAINGKING 2 | D11: BLIND STOPE. REPLACEMENT OF L04 JVFW 014E DW. APPROVED ON NOV. 4, 2021.RENAME FROM L04_JVFW_015E_STOPE PREP TO L04_JVFW_010E_STOPE PREP. STARDTING NOVEMBER 6, 2021.STOPPED ON NOV.18,2021 | E11: L04_CTV_020W_STOPE | F11: NOCOS 1 | G11: CONVERTED FROM L04_CTV_020W_ROBBING TO STOPE. APPROVED ON MARCH 15, 2022.temp stopped on march 18,2022. | H11: L04_CV_025W_STOPE | I11: SHEPHERD AR | J11: REPLACEMENT OF L04_CV_025W_STOPE PREP. APPROVED ON SEPTEMBER 25, 2021. STOPPED BREAKING AND CONVERT TO PULL-OUT STAGE ON NOVEMBER 6, 2021. STOPPED ON NOVEMBER 23, 2021. MINED OUT | K11: L03_CTV_024W_DW | L11: FERNANDEZ, RM 4 | M11: ADDITIONAL HORIZONTAL HEADING. APPROVED ON OCTOBER 17, 2022.STOPPED ON NOVEMBER 21, 2022, PINCHED OUT VEIN. | N11: L03_JVSPLIT_015W_RAISE | O11: FERNANDEZ, RM 2 | P11: ADDITIONAL VERTICAL DEVELOPMENT. APPROVED ON SEPTEMBER 24,2022.STOPPED ON NOVEMBER 4, 2022 DUE TO UNSAFE CONDITION. | Q11: L04_GHVFW_010E_WINZE | R11: MARTINEZ DN | S11: REPLACEMENT OF L04_CTV_020W_ROBBING ON MARCH 28 2022.TEMPORARY STOPPED ON APRIL 11,2022 DUE TO TRANSITION OF MANPOWER.RESUMED APRIL 25, 2022 AS WELL AS CHANGE TEAM LEADER FROM NOCOS TO MARTINEZ DN.STOPPED ON JUNE 30, 2022, ALREADY REACHED THE RECOMMENDED STRIKE LENGTH/CROWN PILLAR. | T11: L04_NONE_022E_XCN | U11: BAÑEZ 4 | V11: ADDITIONAL. APPROVED ON OCT 16 2020. stopped on Nov. 11 2020, already hit the target vein. | W11: L04_CTV_010W_ROBBING | X11: MARTINEZ, DN 3 | Y11: REPLACEMENT OF L04_CTV_010W_WINZE STOPE. APPROVED ON FEBRUARY 21, 2024. TOPSLICE.STOPPED ON APRIL 02, 2024, WILL BE CONVERTED TO WINZE STOPE PREP.
B12: L04_GHVSPLIT_031W_STOPE PREP | C12: SHEPHERD AQ | D12: Replacement of L04_GHVSPLIT_027W_STOPE. Approved on Sept 6, 2021. STOPPED ON 10/5/2021 TO BE CONVERTED TO STOPE BREAKING. | E12: L04_GHVSPLIT_029W_STOPE | F12: SHEPHERD AQ | G12: REPLACEMENT OF L04_GHVSPLIT_029W_STOPE_PREP APPROVED ON OCTOBER 4, 2021. STOPPED STOPE BREAKING AND CONVERTED TO PULL-OUT FEB. 12, 2021. | H12: L04_JV_030E_WINZE STOPE | I12: MARTINEZ DN 2 | J12: REPLACEMENT OF L04_JV_030E_ROBBING APPROVED ON 8/19/21. CONVERTED TO ACTIVE STOPE BREAKING APPROVED ON SEPTEMBER 7, 2021.stopped breaking on Sept. 16, 2021. convert to stope pull-out starting September 17, 2021. STOPPED ON SEPTEMBER 27, 2021. FINISHED HEADING. | K12: L04_JV_040W_DW | L12: SHEPHERD AL 1 | M12: REPLACEMENT OF L04_JVSPLIT_027E_DW. APPROVED ON SEPTEMBER 12, 2022.TEMPORARY STOPPED ON SEPTEMBER 13, 2022.RESUMED ON SEPTEMBER 15, 2022.RESUMED ON SEPTEMBER 15, 2022 AT THE SAME TIME CHANGE TEAM LEADER FROM SHEPHERD AL 1 TO NOCOS.TEMPORARY STOPPED ON OCTOBER 4,2022 DUE TO LACK OF MANPOWER.RESUMED ON OCT 5, 2022. TRANSFERRED MANPOWER FROM NOCOS 2 SHEPHERD AQ 2 ON OCT 5 2022.STOPPED ON OCTOBER 19, 2022 DUE TO CONSECUTIVE LOW ASSAY GRADE.TRANSFERRED TO SHEPHERD AL. RESUMED ON OCTOBER 26. AS PER LEVEL GEO, HAS GOOD CUT SAMPLE.TEMPORARY STOPPED ON NOVEMBER 15, 2022 DUE TO INSUFFICIENT MANPOWER AND ABSENTEEISM RESULTING TO ABANDONEMENT OF WORKPLACE, THIS GROUP WILL BE MERGED TO SHEPHERD AL 1. | N12: L04_CV_007E_RAISE | O12: SHEPHERD AL 2 | P12: REPLACEMENT OF L04_CV_007E_DE. APPROVED ON SEPTEMBER 6, 2022.TEMPORARY STOPPED ON OCTOBER 11,2022. LACK OF MANPOWER. | Q12: L04_GHVFW_005W_WINZE | R12: SHEPHERD AL 2 | S12: ADDITIONAL VERTICAL DEVELOPMENT APPROVED ON MARCH 3, 2022. FILL WINZE.stopped on march 14, 2022 | T12: L04_NONE_025W_XCN | U12: MARTINEZ, RONALD | V12: SPECIAL PROJECT: COUNTER DRIVE DISTANCE TO TARGET MAINLINE FOR ROBBING AND VERTICAL DEVELOPMENT. APPROVED ON AUGUST 22 2020. TRANSFERRED TEAM LEADER ON AUGUST 27 2020, FROM BAÑEZ 4 TO MARTINEZ, RONALD. temporary stopped on Sept 6,2020 | W12: L03_GHV_024W_ROBBING | X12: FERNANDEZ, RM 1 | Y12: ADDITIONAL SOURCE OF GOOD ORE. SILL PILLAR ROBBING OF OLD STOPE. APPROVED ON MAY 13, 2024, 2ND SHIFT.TEMPORARY STOPPED ON JUNE 26, 2024. TO PRIORITIZE CLEANING AND BACKFILLING.
B13: L04_GHVFW_019E_WINZE STOPE PREP | C13: SHEPHERD AL 1 | D13: REPLACEMENT OF L04_GHVFW_018E_DE_ISL APPROVED ON JULY 1,2021.STOPPED ON 8/18/21 CONVERTED TO STOPE BREAKING | E13: L04_GHVSPLIT_031W_STOPE | F13: SHEPHERD AQ | G13: REPLACEMENT OF L04_GHVSPLIT_031W_STOPE PREP APPROVEED ON 10/5/2021. STOPPED ON DECEMBER 9, 2021 DUE TO LOW GRADE BULK SAMPLES. | H13: L04_CTV_008E_STOPE | I13: MARTINEZ, RON 3 | J13: CONVERTED TO PULL-OUT CLEANING ON SEPTEMBER 8, 2021. STOPPED ON SEPT.19,2021 DUE TO LOW QA/QC ON CUT/BULK SAMPLES WITH 61% PULL-OUT. | K13: L04_CV_005E_DE | L13: SHEPHERD AR 1 | M13: REPLACEMENT OF L04_CV_014W_ROBBING. APPROVED ON SEPTEMBER 2, 2022.TEMPORARY STOPPED ON SEPTEMBER 6, 2022 TO PRIORITIZE L04 CV 009W ROBBING.RESUMED ON SEPTEMBER 9, 2022 AS WELL AS TRANSFERRED FROM MARTINEZ, RON 1 TO SHEPHERD AR 1.TEMPORARY STOPPED ON SEPTEMBER 17, 2022 TO PRIORITIZE ANOTHER HORIZONTAL DEVELOPMENT. | N13: L04_CV_003E_RAISE | O13: SHEPHERD AL | P13: REPLACEMENT OF L04_CV_007E_DW. APPROVED ON JUNE 16, 2022.TEMPORARY STOPPED ON JUNE 20, 2022 TO PRIORITIZE THE OTHER DEVELOPMENTS AND LESSEN THE TRAFFIC OF THE MINE CARS. | Q13: L04_JVSPLIT_028E_WINZE | R13: MARTINEZ DN 2 | S13: REPLACEMENT OF L04 JV 030E ROBBING. APPROVED ON OCT 16, 2021.STOPPED ON FEB 9, 2022. ALREADY REACHED DESIRED ELEVATION, RECOMMENDED FOR ISL. RESUME ON MARCK 4, 2022.STOPPED ON MARCH 14,2022 | T13: L04_NONE_024W_XCS | U13: BAÑEZ 4 | V13: SPECIAL PROJECT: COUNTER DRIVE DISTANCE TO TARGET MAINLINE. APPROVED ON AUGUST 22 2020. TRANSFERRED TEAM LEADERON AUGUST 27 202 FROM MARTINEZ, RONALD TO BAÑEZ 4. STOPPED ON SEPT. 09 2020 3RD SHIFT. MADE A BREAKTHROUGH. | W13: L03_CTV_014W_ROBBING | X13: FERNANDEZ, RM 4 | Y13: ADDITIONAL SOURCE OF GOOD ORE. APPROVED ON NOVEMBER 17, 2023. TOPSLICE.TEMPORARY STOPPED ON DECEMBER 01, 2023. FOR AN EVALUATION OF A POSSIBLE OLD STOPE AT LEVEL 4.RESUMED ON DECEMBER 08, 2023.TEMPORARILY STOPPED ON JANAURY 08, 2024 IN ORDER TO PRIORITIZED FILL WINZE ALONG ITS MAINLINE.
B14: L04_CTV_008E_STOPE PREP | C14: MARTINEZ, RON 3 | D14: REPLACEMENT OF L08 CTV 008E DE. APPROVED ON JUNE 23 2021.STOPPED ON JULY 14, 2021.AT THE SAME TIME CONVERT TO STOPE BREAKING. | E14: L04_JV_030E_WINZE STOPE | F14: MARTINEZ DN 2 | G14: REPLACEMENT OF L04_JV_030E_ROBBING APPROVED ON 8/19/21. CONVERTED TO ACTIVE STOPE BREAKING APPROVED ON SEPTEMBER 7, 2021.stopped breaking on Sept. 16, 2021. convert to stope pull-out starting September 17, 2021. | H14: L04_CTV_025E_WINZE STOPE | I14: MARTINEZ DN 1 | J14: Replacements of L04_CTV_025E_WINZE STOPE PREP, approved on March 26, 2021.TEMPORARY STOPPED ON APRIL 7, 2021 SINGLE ENTRY. Resumed on April 9,2021. april 17, 2021 has 10m slope distance to connect to the mainline. Stopped on May 03, 2021, converted to Pull Out Cleaning.STOPPED ON MAY 17, 2021 ALREADY MINED OUT. | K14: L04_JVSPLIT_027E_DW | L14: SHEPHERD AL 1 | M14: REPLACEMENT OF L04_CV_004W_ROBBING. APPROVED ON SEPTEMBER 2, 2022. RENAME FROM L04_JV_040W_DW TO L04_JVSPLIT_027E_DW. APPROVED ON SEPTEMBER 5, 2022. STOPPED ON SEPTEMBER 12, 2022 DUE TO PINCHED OUT OF VEIN. | N14: L04_CV_002E_RAISE | O14: ANDILAB 2 | P14: REPLACEMENT OF L04_CV_002E_DE. APPROVED ON MAY 18 2022.TEmPORARILY STOPPED ON MAY 23 2022 DUE TO MANPOWER TRANSFER. | Q14: L04_CTV_008E_WINZE | R14: ANDILAB 1 | S14: REPLACEMENT OF L04 GHV 057E ROBBING. APPROVED ON JAN 24, 2022.STOPPED ON FEB.9, 2022 | T14: L04_NONE_014W_XCS | U14: NOCOS 1 | V14: TARGET CV MAINLINE FOR MAINHOLE STOPING. APPROVED ON JULY 29 2020. stopped august 23, 2020 already breakthrough. | W14: L04_JV_030E_ROBBING | X14: MARTINEZ DN 2 | Y14: REPLACEMENT OF L04_JV_030E_DW_ISL. APPROVED ON AUGUST 17, 2021.TEMPORARY STOPPED ON 19/8/21. RESUME ON SEPTEMBER 27, 2021.STOPPED ON OCT.13,2021
B15: L04_GHVSPLIT_026W_STOPE PREP | C15: BAÑEZ 5 | D15: REPLACEMNT OF L04_GHVSPLIT_026W_RAISE. APPROVED ON JUNE 15, 2021.STOPPED ON STOPE PREP ON JULY 2,2021 CONVERT TO ACTIVE BREAKING NOTIFIED ON JULY 6, 2021.STOPPED ON JULY 7, 2021 AT THE SAME TIME CONVERTED TO STOPE BREAKING. | E15: L04_GHVSPLIT_026W_STOPE | F15: BAÑEZ 5 | G15: REPLACEMNT OF L04_GHVSPLIT_026W_RAISE. APPROVED ON JUNE 15, 2021.STOPPED ON STOPE PREP ON JULY 2,2021 CONVERT TO ACTIVE BREAKING NOTIFIED ON JULY 6, 2021.STOPPED ON JULY 7, 2021 AT THE SAME TIME CONVERTED TO STOPE BREAKING. LOW DIPPING REPORTED ON JULY 20, 2021. STOPPED ON AUGUST 30, 2021 RECOMMENDED FOR ACTIVE STOPE BREAKING. | H15: L04_JVHW_014E_WINZE STOPE | I15: COMAINGKING 3 | J15: REPLACEMENT OF L04 JVHW 014E WINZE STOPE PREP. APPROVED ON JULY 11, 2020. TEMP. STOPPED ON JULY 16, 2020 TO PRIORITIZE WINZE FOR RELOCATING MANWAY. Resumed on Oct 6, 2020.MINE GEOLOGY ALREADY GUIDED SPLIT THE MINER AND OFFSET THE BLATING FF THE MASSIVE MAIN VEIN.STOPPED ON MARCH 18, 2021 CONVERT TO PULL OUT.STOPPED ON MAY 10,2021 MINED-OUT. | K15: L03_RYV_005W_DW | L15: FERNANDEZ, REX 1 | M15: REPLACEMENT OF L03_RYV_005W_DE APPROVED ON AUGUST 20, 2022.STOPPED ON SEPTEMBER 9, 2022 ALREADY REACHED THE RECOMMEND STRIKE LENGTH AS IT BREAKTHROUGH TO THE OLD MAINLINE. | N15: L04_CV_006E_RAISE | O15: MARTINEZ, RON 1 | P15: REPLACEMENT OF L04_CV_006E_DE. APPROVED ON MARCH 28 2022. JUSTIFICATION FOR ITS LOW DIPPING AT 42 DEGREES FROM 9 METER ELEVATION TO ITS CURRENT BACK (17 METERS) ON MAY 2, 2022.STOPPED ON MAY 17 2022 DUE TO PINCHING OUT OF VEIN. | Q15: L04_GHVSPLIT_041W_WINZE | R15: MARTINEZ DN 1 | S15: REPLACEMENT OF L04_JV_028W_DE_ISL.. APPROVED ON SEPTEMBER 27, 2021.STOPPED ON OCT 21, 2021. VEIN PINCHED OUT. | T15: L04_NONE_045W_XCS | U15: MARTINEZ DN.2 | V15: REPLACEMENT OF L04_GHV_045W_ROBBING APPROVED ON MARCH 23, 2020. STOPPED ON MARCH 31 2020 DUE TO MADE A BREAKTHROUGH | W15: L04_CTV_007W_ROBBING | X15: MARTINEZ, RON 1 | Y15: REPLACEMENT OF L04 NONE 007W XCN. APPROVED ON MARCH 3, 2021.RENAMED FROM CTV TO JV ON APRIL 21, 2021 AS PER LEVEL GEO.CORRECTED TO CTV ON APRIL 22, 2021 AS PER LEVEL GEO. STOPPED ON JULY 27, 2021.
B16: L04_GHVSPLIT_027W_STOPE PREP | C16: BAÑEZ 8 | D16: REPLACEMENT FROM L04_GHVSPLIT_027W_RAISE.APPROVED ON APRIL 16, 2021. temporary stopped on april 17, 2021 for grade evaluation and wireframe correction of level geo, The first wireframe used incorrect. Resumed on April 18, 2021. Design was finalized.STOPPED ON MAY 4, 2021 CONVERTED TO STOPE BREAKING. | E16: L04_GHVSPLIT_027W_STOPE | F16: BAÑEZ 8 | G16: REPLACEMENT OF L04_GHVSPLIT_027W_STOPE PREP.APPROVED ON MAY 4, 2021.recommended to continue breaking only 6m strike length form east side manway and leave the remaining length as pillar.STOPPED BREAKING ON 18/8/21 CONVERTED TO PULL-OU AT THE SAME DATE | H16: L04_GHVFW_041W_STOPE | I16: NOCOS 2 | J16: REPLACEMENT OF L04_GHVSPLIT_041W_STOPE PREP. APPROVED ON AUGUST 11 2020. Renamed from GHVSPLIT TO GHVFW ON SEPTEMBER 13,2020 AS PER MEMO OF LEVEL GEO. STOPPED BREAKING ON NOV. 30 2020 CONVERTED TO PULL OUT CLEANING. ALREADY FINISHED ON JAN 13 2021. | K16: L04_CV_007E_DW | L16: SHEPHERD AL | M16: REPLACEMENT OF L04 JVFW 012E ROBBING. APPROVED ON JAN 11, 2022.TEMP STOPPED ON JAN 14, 2022 TO REHAB MINE RAILS TOWARDS WORKING AREA.RESUMED ON JAN 19, 2022. STOPPED ON FEB. 17, 2022 DUE TO LOW GRADE.RESUMED ON MAY 11, 2022 AND TRANSFERRED FROM MARTINEZ, RON 3 TO SHEPHERD AL.TEMPORARY STOPPED ON JUNE 16, 2022 TO PRIORITIZE THE FUTURE STOPES AND REPLACE IT BY A VERTICAL DEVELOPMENT.RESUMED ON AUGUST 11, 2022.STOPPED SEPTEMBER 1, 2022 DUE TO PINCHED OUT OF VEIN. | N16: L04_CTV_022W_RAISE_ISL | O16: COMAINGKING 1 | P16: REPLACEMENT OF L04_CTV_022W_DE_ISL. APPROVED ON MARCH 2, 2022.STOPPED ON APRIL 12 2022. BREAKTHROUGH. | Q16: L04_JV_028W_WINZE | R16: MARTINEZ DN 1 | S16: REPLACEMENT of L04 CTV 025E WINZE STOPE. Approved on May 10, 2021.RENAMED FROML04_JV_027W_WINZE TO L04_JV_028W_WINZE ON MAY 11, 2021. STOPPED ON JULY 14, 2021 TO DRIVE INTERMEDIATE SUBLEVEL. | T16: L04_NONE_028W_XCN | U16: MARTINEZ, RONALD | V16: REPLACEMENT OF L04_GHV_029W_ROBBING. APPROVED ON JANUARY 13, 2020. STOPPED ON JANUARY 28 2020 DUE ALREADY BREAKTHROUGH. | W16: L04_JV_042W_ROBBING | X16: MARTINEZ, RON 2 | Y16: REPLACEMENT OF L04 CV 015W ROBBING. START JULY 14, 2021 (SILL PILLAR).STOPPED ON JULY 21, 2021. FINISHED HEADINGS.
... B32: L04_NV_011W_STOPE PREP | C32: MARTINEZ RON. 1 | D32: REPLACEMENT OF L04 NV 011E RAISE. APPROVED ON DECEMBER 15, 2018. ON WEST POSITION. STOPPED ON JANUARY 16, 2019. | E32: L04_GHVFW_017E_STOPE | F32: CABONITA 1 | G32: REPLACEMENT OF L04_GHVFW_017E_STOPE PREP. APPROVED ON JUNE 28, 2019.STOPPED CONVERT TO PULL-OUT CLEANING ON AUGUST 1, 2019. | H32: L04_JV_002E_STOPE | I32: CABONITA 1 | J32: REPLACEMENT OF L04 JV 002E STOPE PREP. APPROVED ON NOVEMBER 12, 2018. MZC. STOPPED BREAKING ON JANUARY 16, 2018. COVERTED TO PULL-OUT ON JANUARY 16, 2019. MINED-OUT ON 3/20/2019 WITH 78% PULL-OUT CLEANING. | K32: L04_CTV_010E_DW | L32: MARTINEZ DN 2 | M32: REPLACEMENTS OF L04_CTV_010E_DW APPROVE ON APRIL 16, 2021.MEMO RECEIVED ON MAY 2, 2021. Stopped on May 6,2021 notified on May 11,2021. | N32: L04_GHV_028W_RAISE | O32: MARTINEZ RON. 4 | P32: REPLACEMENT OF L04_GHV_028W_DE.APPROVED ON MARCH 26 2020. RENAMED FROM L04 GHVSPLIT 028W DE TO L04 GHV 028W RAISE ON MARCH 27, 2020. TEMP. STOPPED ON APRIL 9 DUE TO PANDEMIC. RESUMED ON JULY 7, 2020. STOPPED ON JULY 24, 2020 DUE TO PINCHED OUT OF VEIN. | Q32: L04_CV_006W_WINZE | R32: BAKAKON 1 | S32: FILL WINZE FOR WASTE PASS. APPROVED ON FEB 9, 2019. MZC. ALREADY BREAKTHROUGH STOPPED ON FEB 27, 2019. | T32: L04_NONE_023W_XCN_ISL | U32: CAYMAN 3 | V32: REPLACEMENT OF L04 CTV 023W WINZE STOPE, APPROVED ON MAY 3, 2023.STOPPED ON MAY 22, 2023 ALREADY INTERCEPTED THE TARGET VEIN. | W32: L04_CTV_011W_ROBBING | X32: NOCOS 1 | Y32: REPLACEMENT OF L04 CTV 010W DW. APPROVED ON JULY 15, 2019. AT L03. TEMPORARY STOPPED ON NOV 15, 2019 DUE TO ON GOING REGRADING AND REHAB OF MAINLINE.
B33: L04_CTV5_016E_STOPE PREP | C33: CABCAD 1 | D33: REPLACEMENT OF L04 CTV5 016E RAISE. APPROVED ON DECEMBER 10, 2018. MZC. STOPPED ON JANUARY 24, 2019. CONVERTED TO STOPE BREAKING. | E33: L04_GHVFW_005E_WINZE STOPE | F33: COMAINGKING 1 | G33: REPLACEMENT OF L04_GHVFW_005E_WINZE STOPE PREP. APPROVED ON JUNE 13, 2019. CONVERTED TO PULL-OUT ON SEPT 13, 2019. | H33: L04_CTV5_016E_STOPE | I33: CABCAD 2 | J33: REPLACEMENT OF L04 CTV5 016E RAISE. APPROVED ON DECEMBER 10, 2018. MZC. STOPPED ON JANUARY 24, 2019. CONVERTED TO STOPE BREAKING ON JANUARY 24, 2019. STOPPED BREAKING ON MARCH 31, 2019, DUE TO CONSECTUIVE LOW CUT SAMPLE; RECOMMENDED FOR STOPE CLEANING.STOP ON 4/9/19-SDNC, CONSECUTIVE LOW ASSAY GRADE RESULT. | K33: L04_JV_012W_DE | L33: ANDILAB 1 | M33: REPLACEMENT OF L04_JV_013W_WINZE APPROVED ON MARCH 19, 2021.Renamed from L04 JV 013W DE to L04 JV 012W DE on March 20,2021. Stopped on May 11,2021. | N33: L04_GHV_041W_RAISE | O33: MARTINEZ RON.3 | P33: REPLACEMENT OF L04_GHV_043W_RAISE. APPROVED ON MARCH 2 2020. STOPPED ON APRIL 8 2020 GEO RECOMMENDED TO MINIMIZE BREAKING WIDTH TO .90-1.00M DUE TO NARROW VEIN CHARACTERISTICS OF THE WORK HEADING. | Q33: L04_JV_016W_WINZE | R33: CABCAD 2 | S33: WASTEPASS, APPROVED ON 4/10/19-SDNC.ALREADY BREAKTHROUGH STOPPED ON APRIL 15, 2019 | W33: L04_RYV_010E_ROBBING | X33: NACARIO, JAIME | Y33: REPLACEMENT OF L04_CV_003W_ROBBING.APPROVED ON NOVEMBER 4, 2019.TRANSFER FROM MARTINEZ TO NACARIO ON NOV 29, 2019. STOPPED ON DEC 2, 2019 DUE TO UNSAFE CONDITION. | AD33: =+S15-'FINAL LIST WITH REMARKS'!L2375S33 -> #VALUE!
B34: L04_GHVFW_014E_STOPE PREP | C34: PARAGUYA 4 | D34: REPLACEMENT OF L04 GHVFW 014E RAISE. APPROVED ON JANUARY 31, 2019. MZC. STOPPED ON FEB 18, 2019. CONVERTED TO ACTIVE BREAKING. | E34: L04_CTV_018W_WINZE STOPE | F34: COMAINGKING 1 | G34: REPLACEMENT OF L04_CTV_018W_WINZE STOPE PREP. APPROVED ON SEPT 11, 2019. THERE'S ONLY 10 METER REMANING PILLAR BALANCE TO CONNECT W/ THE L04 MAINLINE ON OCT. 10, 2019. stopped on oct 18, 2019 convert to pull-out cleaning | H34: L04_NV_011W_STOPE | I34: MARTINEZ RON. 2 | J34: REPLACEMENT OF L04 NV 011E RAISE. APPROVED ON DECEMBER 15, 2018. ON WEST POSITION. CONVERTED TO BREAKING ON JANUARY 21, 2019. CONVERTED STOPE PULL-OUT JAN 28, 2019. DECLARED MINED-OUT MARCH 15, 2019. | K34: L04_GHVSPLIT_028W_DE | L34: BAÑEZ 5 | M34: REPLACEMENT OF L04_GHVSPLIT_028W_RAISE APPROAVED ON FEB.23,2021.STOPPED ON MAY 4, 2021. CONVERTED TO RAISE. | N34: L04_CTV_008W_RAISE | O34: NOCOS 8 | P34: REPLACEMENT OF L04_CTV_008W_DE. APPROVED ON FEBRUARY 17 2020. STOPPED ON MARCH 27 2020 UNSAFE CONDITION NO SOLID PILLAR REMAINING | Q34: L04_JV_020E_WINZE | R34: GEMENTIZA 1 | S34: FILL WINZE FOR WASTE PASS. APPROVED ON APRIL 8, 2019.RENAMED TO 20E FROM 17E ON 4/10/19-LTS. STOPPED ON APRIL 15, 2019 BECAUSE THIS WAS ALREADY BREAKTHROUGH. | W34: L04_GHVFW_008E_ROBBING | X34: COMAINGKING 4 | Y34: REPLACEMENT OF L04 GHVFW 007E DW. Approved on Oct 28, 2019. STOPPED ON DECEMBER 13, 2019 DUE TO CONSECUTIVE LOW ASSAY GRADES ON CUT SAMPLES/ BULK SAMPLES.
B35: L04_GHVFW_015E_STOPE PREP | C35: CABONITA 1 | D35: ADDITIONAL PRODUCTION. APPROVED ON MARCH 12, 2019. STOPPED ON APRIL 9, 2019. CONVERT TO BREAKING | E35: L04_JV_002E_WINZE STOPE | F35: OY-YOY 1 | G35: REPLACEMENT OF L04_JV_002E_WINZE STOPE PREP. APPROVED ON OCT 18, 2019. STOPPED ON NOV 11, 2019 DUE TO ALREADY FINISHED BREAKING AND HAS ALREADY REACHED THE DESIGN PILLAR. STOPPED BREAKING CONVERT TO PULL-OUT CLEANING ON NOV 18, 2019 | H35: L04_JV_042W_STOPE | I35: DUHIG 3 | J35: CONVERTED TO PULL-OUT ON 2/11/19.TEMP.STOP ON 4/10/19-LTS, FOR EVALUATION UNDERGROUND ONLY 78% PULL-OUT BUT ALREADY DECLARED MINED OUT. | K35: L04_CTV_025E_DW | L35: MARTINEZ DN 4 | M35: REPLACEMENT OF L04_CTV_025E_WINZE APPROAVED ON FEB.23,2021.STOPPED ON MARCH 11,2021 CONVERT TO STOPE PREPARATION. | N35: L04_JV_053W_RAISE | O35: SHEPHERD X 1 | P35: REPLACEMENT OF L04 JVSPLIT 058W RAISE. APPROVED ON APRIL 23, 2019. TEMP. STOPPED ON JUNE 20, 2019 BECAUSE THE GROUP WILL UNDERGO EXPLOSIVE SEMINAR AS PER DTAN. RESUMED OPERATION ON JUNE 26, 2019 AS THE GROUP FINISHED THEIR EXPLOSIVE SEMINAR.STOPPED ON JULY 4, 2019 DUE TO FAILURE AMIDST WIRE FRAMING & DESIGN. RESUMED ON JULY 5, 2019 TO PROCEED ON INCLINED RAISE @ EAST SIDE. STOPPED ON JULY 22, 2019 NOT PASS WIRE FRAMING (DILUTED GRADE @ 1.95.GPT) RESUMED ON FEB. 10 2020. STOPPED ON MARCH 10 2020 DUE TO CONSECUTIVE LOW ASSAY GRADES ON CUT SAMPLE. | Q35: L04_GHVFW_018E_WINZE | R35: OY-YOY 1 | S35: REPLACEMENT OF L04 CV 005W WINZE. APPROVED ON FEB 2, 2019. STOPPED ON MAY 8,2019 TO PROPOSE INTERMEDIATE SUBLEVEL. | W35: L04_JV_002E_ROBBING | X35: SHEPHERD Z | Y35: REPLACEMENT OF L04_JV_002E_WINZE STOPE APPROVED ON NOV 22, 2019. TEMPORARY STOP 12/8/19 by (WBO). Resumed on December 9 2019, In the same time Renamed from OY-YOY 1 to Shepherd Z. STOPPED ON DECEMBER 16, 2019 ALREADY REACED THE RECOMMENDED STRIKE LENGTH/CROWN PILLAR.
B36: L04_GHVFW_005E_WINZE STOPE PREP | C36: COMAINGKING 1 | D36: REPLACEMENT OF L04 GHVFW 007E DW. APPROVED ON MAY 17, 2019. MZC. CONVERT TO STOPE BREAKING ON JUNE 13, 2019. | E36: L04_CTV5_015E_WINZE STOPE | F36: BAKAKON 2 | G36: REPLACEMENT OF L04_CTV5_015E_WINZE STOPE PREP. APPROVED ON OCT 11, 2019. STOPPED ON NOV 11, 2019 ALREADY FINISHED THE DRIVING FILL RAISE AND THE SAME TIME CONVERT TO ACTIVE PULL-OUT | H36: L04_CV_011W_STOPE | I36: MARTINEZ RON. 1 | J36: REPLACEMENT OF L04 CV 011W STOPE PREP. APPROCED ON SEPT. 3, 2019.CONVERT TO PULL-OUT ON SEPT 13, 2019. STOPPED ON SEPT 15, 2019, ALREADY REACHED AGREED PULLOUT MINE CARS. | K36: L04_EDV_016W_DW | L36: BAÑEZ 4 | M36: REPLACEMENT OF L04_EDV_017W_DE, APPROVED ON FEB. 15 2021.STOPPED ON MARCH 13,2021 ALREADY BREAKTHROUGH | N36: L04_GHV_043W_RAISE | O36: MARTINEZ RON.2 | P36: ADDITIONAL INCLINED RAISE. APPROVED ON FEBRUARY 6, 2020. STOPPED ON MARCH 2 2020 DUE TO PINCHED OUT VEIN TO 0.05M | Q36: L04_GHV_045W_WINZE | R36: OY-YOY 1 | S36: ADDITIONAL,APPROVED ON MARCH 16,2016.STOPPED ON JULY 8,2016. RESUMED ON MAY 29, 2019 AT THE SAME TIME TRANSFERRED FROM ORIAS NELSON TO OY-YOY 1. STOPPED RECOMMENDS TO CONVERT THIS WORK HEADING INTO L04 JV 045W ISL DW ON JUNE 6, 2019. | W36: L04_GHV_029W_ROBBING | X36: MARTINEZ, RONALD | Y36: REPLACEMENT OF L04_NONE_028W_XCS APPROVED ON SEPT. 17, 2019. TEMP. STOPPED ON SEPT 18, 2019 UNDER REHAB. Resumed on sept. 30, 2019 to proceed in topslice. L04_GHV_029W_ROBBING TRANSFER FROM NACARIO TO MARTINEZ RONALD ON NOV 30, 2019. STOPPED ON JANUARY 13, 2020 DUE TO CONSECUTIVE LOW ASSAY GRADES ON CUT SAMPLES/ BULK SAMPLES./
B37: L04_GHVFW_017E_STOPE PREP | C37: CABONITA 1 | D37: REPLACEMENT OF L04 GHVFW 017E RAISE. APPROVED ON JUNE 8, 2019.RECOMMEND FOR ACTIVE BREAKING APPROVED ON JUNE 28, 2019. | E37: L04_CTV_018W_STOPE | F37: SHEPHERD AA2 | G37: REPLACEMENT OF L04_CTV_018W_STOPE PREP. APPROVED ON MARCH 20 2020. TEMP. STOPPED ON APRIL 9 DUE TO PANDEMIC. Permanent STOPPED ON SEPT. 30 2020. | H37: L04_JV_002E_WINZE STOPE | I37: OY-YOY 1 | J37: REPLACEMENT OF L04_JV_002E_WINZE STOPE PREP. APPROVED ON OCT 18, 2019. STOPPED ON NOV 11, 2019 DUE TO ALREADY FINISHED BREAKING ABD HAS ALREADY REACHED THE DESIGN PILLAR.STOPPED BREAKING CONVERT TO PULL-OUT CLEANING ON NOV 18, 2019 ALREADY REACHED 120% PULL-OUT. | K37: L04_EDV_022W_DW | L37: MARTINEZ DN 3 | M37: RENAME FROM L04 EDV 021W DW TO AVOID MISCHARGING. APPROVED ON FEB.11,2021.STOPPED ON MARCH 4, 2021 DUE TO LOW CONSECUTIVE LOW ASSAY GRADE. | N37: L04_JV_031E_RAISE | O37: SHEPHERD Z.2 | P37: ADDITIONAL INCLINED RAISE APPROVED ON NOV 14, 2019. STOPPED ON DEC 7, 2019 DUE TO CONSECUTIVE LOW ASSAY GRADES ON CUT SAMPLES/BULK SAMPLES. | Q37: L04_CTV5_016E_WINZE | R37: OY-YOY 1 | S37: REPLACEMENT OF L04 CTV5 17E DE, APPROVED ON 5/1/19-SDNC. TEMPORARY STOPPED ON MAY 25,2019 TO PRIORITIZE L04 GHVFW 018E DE. RESUMED ON JULY 12, 2019 AS PER SCS AND AT THE SAME TIME TRANSFER FROM CABCAD TO OY-YOY. STOPPED ON AUGUST 9, 2019 BECAUSE OF ITS PROXIMITY ABOUT PILLAR 20M BALANCE TO THE E15 SHAFT. | W37: L04_CTV_018W_ROBBING | X37: COMAINGKING 3 | Y37: REPLACEMENT OF L04_CTV_009W_RAISE. APPROVED ON DECEMBER 6, 2019. STOPPED ON JANUARY 24 2020 ALREADY FINISHED
B38: L04_CV_011W_STOPE PREP | C38: MARTINEZ RON. 1 | D38: REPLACEMENT OF L04_CV_011W_RAISE. APPROVED ON AUGUST 6, 2019. CONVERT TO ACTIVE BREAKING ON SEPT. 3, 2019. | E38: L04_GHVFW_015E_STOPE | F38: MANZANO | G38: REPLACEMENT OF L04 GHVFW 015E STOPE PREP. APPROVED ON APRIL 9, 2019-LOC.FROM GHVFW 017E RAISE 6TH FLR +10 METERS RECOMMENDED FOR IPR. STOPPED ON MAY 3,2019 DUE TO LOW GRADE NOT TO COMMENCE TO PULL-OUT/ RESUMED PULL OUT ON OCT. 20 2020 IN THE SAME TRANSFERRED FROM CABONITA TO MANZANO. | H38: L04_CTV_019W_STOPE | I38: MARTINEZ, RON 3 | J38: REPLACEMENT OF L04_CTV_019W_STOPE PREP.APPROVED ON APRIL 9, 2021.TRANSFER FROM SHEPHERD AL 1 TO MARTINEZ RON. APPROVED ON APRIL 16, 2021. CONVERTED TO PULL OUT CLEANING ON MAY 03, 2021.STOPPED ON MAY 10, 2021 MINED OUT. | K38: L04_CTV_027E_DW | L38: BAÑEZ | M38: ADDITIONAL DEVELOPMENT DRIVE. APPROVED ON NOV. 19 2020. RESUMED AND transfer from PMC MINERS 1TO BANEZ ON JAN 11 2021. stopped on january 18, 2021, recommended target length has been reached. | N38: L04_CTV_009W_RAISE | O38: COMAINGKING 3 | P38: REPLACEMENT OF L04 CTV 018W WINZE STOPE. APPROVED ON NOV. 30, 2019. INCLINED RAISE. STOPPED ON DEC 6 2019 DUE TO VEIN PINCHED OUT | Q38: L04_JV_029E_WINZE | R38: OY-YOY 1 | S38: REPLACEMENT OF L04_CTV5_015E_DE. APPROVED ON SEPT. 11, 2019. TEMP. STOPPED ON OCTOBER 10, 2019 DUE TO UNSAFE CONDITION. | W38: L04_JV_013W_ROBBING | X38: ANDILAB 1 | Y38: ADDITIONAL SOURCE OF GOOD ORE. APPROVED ON JULY 16, 2019. ON DECEMBER 12/17/ 2019 TRANSFERRED FROM MARTINEZ DN 1 TO ANDILAB GRACIANO. CONVERTED TO SILL PILLAR ON JANUARY 6, 2019. STOPPED ON FEB. 6, 2020 ALREADY REACHED THE RECOMMENDED STRIKE LENGTH FOR SILL.
B39: L04_JVHW_014E_WINZE STOPE PREP | C39: COMAINGKING 3 | D39: REPLACEMENT OF L04_JVHW_014E_DW. APPROVED ON MARCH 20 2020. STOPPED JULY 16, 2020 TO RELOCAT MANWAY FROM ADJACENT L04 JVFW 011E ROBBING MAINLINE DUE TO UNSAFE CONDITION. | E39: L04_GHVFW_041W_STOPE | F39: NOCOS 2 | G39: REPLACEMENT OF L04_GHVSPLIT_041W_STOPE PREP. APPROVED ON AUGUST 11 2020. Renamed from GHVSPLIT TO GHVFW ON SEPTEMBER 13,2020 AS PER MEMO OF LEVEL GEO. STOPPED BREAKING ON NOV. 30 2020 CONVERTED TO PULL OUT CLEANING | H39: L04_GHVFW_018E_WINZE STOPE | I39: SHEPHERD AL 1 | J39: REPLACEMENT OF L04_GHVFW_018E_WINZE STOPE PREP, APPROVED ON DEC 3 2020.TEMP. STOPPED ON MARCH 7, 2021 DUE TO MANPOWER PROBLEM.resumed on MArch 30, 2021 and transferred from Davacol Rowel 1 to Shepherd AL.STOPPED ON MAY 3, 2021 CONVERTED TO STOPE PULL-OUT.STOPPED ON MAY 17, 2021 ALREADY MINED OUT. | K39: L04_EDV_022W_DW | L39: BAÑEZ 4 | M39: REPLACEMENT OF L04 NONE 022W XCN. APPROVED ON NOV 11 2020 Stopped on Nov. 23 2020 due to consecutive low assay grades on cut samples / bulk sample. | N39: L04_CTV5_014E_RAISE | O39: BAKAKON 2 | P39: ADDITIONAL VERTICAL DEVELOPMENT. APPROVED ON OCTOBER 3, 2019. STOPPED ON OCT. 11 2019, NOT ABLE TO CONTINUE DUE TO WINZE STOPE CONDITION. | Q39: L04_JV_014E_WINZE | R39: COMAINGKING 2 | S39: REPLACEMENT OF L04 RYV 012E WINZE. APPROVED ON MARCH 16, 2019. FOR EVALUATION DUE TO LACKING OF LADDER FOR ABOUT 6 METERS.TRANSFER ON JANUARY 24 2020 FROM OY-YOY 2 TO COMAINGKING. STOPPED ON 5/30/19-LOC, CONSECUTIVE LOW GRADE RESULTS. | W39: L04_CTV5_014E_ROBBING | X39: BAKAKON 2 | Y39: REPLACEMENT OF L04_CTV5_015E_WINZE_STOPE ON NOV 26, 2019. STOPPED ON DECEMBER 13, 2019 DUE TO ALREADY REACHED THE RECOMMENDED STRIKE LENGTH/CROWN PILLAR.
B40: L04_JV_030E_WINZE STOPE PREP | C40: MARTINEZ DN 2 | D40: REPLACEMENT OF L04_JV_030E_ROBBING APPROVED ON 8/19/21. STOPPED ON SEPTEMBER 7, 2021 CONVERTED TO BREAKING. | E40: L04_CTV_019W_STOPE | F40: MARTINEZ, RON 3 | G40: REPLACEMENT OF L04_CTV_019W_STOPE PREP.APPROVED ON APRIL 9, 2021.TRANSFER FROM SHEPHERD AL 1 TO MARTINEZ RON. APPROVED ON APRIL 16, 2021. STOPPED AND CONVERTED TO PULL OUT CLEANING ON MAY 03, 2021 | H40: L04_GHVSPLIT_027W_STOPE | I40: BAÑEZ 8 | J40: REPLACEMENT OF L04_GHVSPLIT_027W_STOPE PREP.APPROVED ON MAY 4, 2021.recommended to continue breaking only 6m strike length form east side manway and leave the remaining length as pillar.STOPPED BREAKING ON 18/8/21 CONVERTED TO PULL-OU AT THE SAME DATE.STOPPED ON SEPTEMBER 7,2021 MINED OUT | K40: L04_RYV_003E_DE | L40: MANZANO 2 | M40: ADDITIONAL HORIZONTAL DEVELOPMENT. APPROVED ON NOV. 5 2020.TEMPORARY STOPPED ON NOV. 17 2020 | N40: L04_CV_008W_RAISE | O40: LERIO 5 | P40: REPLACEMENT OF L04_CV_009W_DE.APPROVED ON AUGUST 7, 2019. STOPPED ON AUGUST 14, 2019 DUE TO CONSECUTIVE LOW ASSAY GRADE AND PINCHED OUT VEIN. | Q40: L04_CV_001E_WINZE | R40: MARTINEZ RON. 1 | S40: REPLACEMENT OF L04 CV 001E ROBBING. APPROVED ON JULY 24, 2020. Temporary stopped on August 18 2020 due to no airhoist / electric hoist vailable. Resumed on August 21 2020. STOPPED ON AUGUST 28 2020 DUE TO PINCHED OUT VEIN. | W40: L04_CTV_033W_ROBBING | X40: SHEPHERD AA1 | Y40: REPLACEMENT OF L04 JV 012W RAISE. APPROVED ON JUNE 5,2019. TRANSFERRED ON DECEMBER 17, 2019 FROM MARTINEZ DN 2 TO BAKAKON. TRANSFERRED ON JANUARY 24 2020 FROM BAKAKON 1 TO SHEPHERD AA1. STOPPED ON MARCH 5 2020 DUE TO UNSAFE CONDITION.
B41: L04_CV_025W_STOPE PREP | C41: SHEPHERD AR | D41: Replacement of L04_CV_022W_DW. Approved on August 30, 2021.TRANSFER FROM BAÑEZ TO SHEPHERD AR ON SEPT.20,2021. STOPPED ON SEPTEMBER 25, 2021. | E41: L04_CTV_008E_STOPE | F41: MARTINEZ, RON 3 | G41: REPLACEMENT OF L04_CTV_008E_STOPE.APPROVED ON JULY 14, 2021. STOPPED ON SEPTEMBER 8, 2021. CONVERT TO PULL OUT CLEANING. | H41: L04_JVFW_010E_STOPE | I41: COMAINGKING 2 | J41: CONVERTED TO PULL OUT ON DECEMBER 2, 2021 STOPPED AND MINED-OUT ON DEC. 2, 2021 WITH 156% PULL-OUT. | K41: L04_JV_058W_DW | L41: MARTINEZ RONALD | M41: REPLACEMENT OF L04_JV_055W_DE, APPROVED ON APRIL 8, 2020. TEMP. STOPPED ON APRIL 9 DUE TO PANDEMIC. RESUMED ON OCT 13 2020. stopped on NOV. 16 25020. TO PRIORITY HEADINGS. | N41: L04_JV_023E_RAISE | O41: CABONITA 3 | P41: REPLACEMENT OF L04_GHV_010W_ROBBING APPROVED ON JULY 30, 2019.SDNC.STOPPED ON AUGUST 14, 2019 DUE TO ALREADY PINCHED OUT VEIN. | Q41: L04_JV_012W_WINZE | R41: ANDILAB 1 | S41: REPLACEMENT OF L04_JV_011E_ROBBING. APPROVED ON JULY 28 2020. Stopped on Sept. 12 2020 due to off vein.resumed on September 14,2020 as per Level Geologist. STOPPED ON SEPT. 29 2020 DUE TO VEIN PINCHED OUT. | W41: L04_JV_019W_ROBBING | X41: ANDILAB 1 | Y41: REPLACEMENT OF L04_JV_013W_ROBBING. APPROVED ON FEB. 20, 2020. STOPPED ON MARCH 9 2020 DUE TO CONSECUTIVE LOW ASSAY GRADE ON CUT SAMPLESS.
B42: L04_GHVSPLIT_029W_STOPE PREP | C42: SHEPHERD AQ | D42: REPLACEMENT OF L04_GHVSPLIT_026W_STOPE PREP. APPROVED ON SEPT. 13, 2021. STOPPED ON OCTOBER 4, 2021. CONVERT TO BREAKING. | E42: L04_CV_025W_STOPE | F42: SHEPHERD AR | G42: REPLACEMENT OF L04_CV_025W_STOPE PREP. APPROVED ON SEPTEMBER 25, 2021. STOPPED BREAKING AND CONVERT TO PULL-OUT STAGE ON NOVEMBER 6, 2021. | H42: L04_GHVFW_019E_WINZE STOPE | I42: SHEPHERD AL 1 | J42: REPLACEMENT OF L04_GHVFW_019E_WINZE STOPE PREP ON 8/18/21. STOPPED BREAKING ON JAN 6, 2022, NOT TRAVERSED DUE TO UNSAFE CONDITION, WITH MEMO ACKNOWLEDGED BY SAFETY, FOR PULL OUT CLEANING.MINED OUT FEB.14,2022 | K42: L04_JVSPLIT_054W_DE | L42: PMC MINERS 1 | M42: ADDITIONAL HORIZONTAL DEVELOPMENT. APPROVED ON SEPT. 24 2020. STOPPED ON OCT 15 2020 PER GEO | N42: L04_GHVFW_017E_RAISE | O42: CABONITA 1 | P42: REPLACEMENT OF L04 JV 027W STOPE. APPROVED ON DECEMBER 7,2018. TEMP STOPPED AND TRANSFER TO TAÑEZA 6 FROM PARAGUYA 1 DUE TO GOOD PERFORMANCE OF FORMER TEAM LEADER APPROVED ON MARCH 11,2019. RESUMED ON MAY 12, 2019 AND TRANSFER FROM TANEZA 6 TO CABONITA 1. STOPPED DUE TO A FAULT STRUCTURE TRANSECTING THE MOST RECENT FACE CAUSING THE VEIN TO BE DISPLACED ON JUNE 7, 2019 | Q42: L04_JV_030E_WINZE | R42: MARTINEZ DN 2 | S42: REPLACEMENT OF L04_CTV_010E_DE. APPROVED ON MAY 19,2021.SAFETY CONCER/UNSAFE CONDITION.STOPPED ON JULY 1, 2021. | W42: L04_GHV_045W_ROBBING | X42: MARTINEZ DN 4 | Y42: REPLACEMENT OF L04_GHV_042W_DW APPROVED ON NOV 12, 2019. TRANSFERRED ON DECEMBER 17, 2019 FROM BAKAKON TO MARTINEZ DANNY DUE TO ABSENTEEISM OF MEN. STOPPED ON MARCH 21 2020 ALREADY REACHED THE ALREADY REACHED THE RECOMMENDED STRIKE LENGTH/CROWN PILLAR.
B43: L04_CV_006E_STOPE PREP | C43: MARTINEZ, RON 3 | D43: REPLACEMENT OF L04_CV_006E_DE . APPROVED ON MAY 23 2022.STOPPED ON JUNE 22 2022. | E43: L04_CTV_021W_STOPE | F43: NOCOS 2 | G43: REPLACEMENT OF L04_CTV_021W_ROBBING APPROVED ON JULY 8,2021.stopped on oct.19 ,2021 unsafe.RESUME ON OCT.20, 2021.stopped on nov. 15,2021 converted to pull-out cleaning | H43: L04_CTV_023W_WINZE STOPE | I43: CAYMAN 3 | J43: PULL-OUT ON APRIL 24, 2023 AND TRAVERSED ON THE SAME DAY.ALREADY DONE STOPE PULL OUT CLEANING ON MAY 3, 2023. | K43: L04_EDV_015W_DW | L43: BAÑEZ 4 | M43: ADDITIONAL HORIZONTAL DEVELOPMENT. APPROVED ON APRIL 7 2020. TEMP. STOPPED ON APRIL 9 DUE TO PANDEMIC. Resumed on August 12 2020 In the same time transferred from Shepherd AF.3 to Bañez 4. stopped on Oct 14 2020 consecutive low assay grade | N43: L04_CV_011W_RAISE | O43: MARTINEZ RON. 1 | P43: ACCESS FOR OLD MUCK IN CV 12W ROBBING. APPROVED ON MARCH 1, 2019. STOPPED ON APRIL 11,2019 ALREADY FINISHED. | Q43: L04_JV_013W_WINZE | R43: COMAINGKING | S43: REPLACEMENT OF L04 JV 014E ROBBING. APPROVED ON SEPTEMBER 15, 2021. STOPPED ON 10/08/21 MADE A BREAKTHROUGH. | W43: L04_CTV_008W_ROBBING | X43: NOCOS 3 | Y43: REPLACEMENT OF L04_CTV_008W_ROBBING. APPROVED ON MARCH 31 2020. TEMP. STOPPED ON APRIL 9 DUE TO PANDEMIC.
B44: L04_CTV_010W_WINZE STOPE PREP | C44: MARTINEZ, DN 3 | D44: REPLACEMENT OF L04_CTV_010W_DW_ISL. APPROVED ON NOVEMBER 14, 2023.STOPPED ON NOVEMBER 28, 2023. CONVERT TO STOPE BREAKING. | E44: L04_GHVFW_019E_WINZE STOPE | F44: SHEPHERD AL 1 | G44: REPLACEMENT OF L04_GHVFW_019E_WINZE STOPE PREP ON 8/18/21. STOPPED BREAKING ON JAN 6, 2022, NOT TRAVERSED DUE TO UNSAFE CONDITION, WITH MEMO ACKNOWLEDGED BY SAFETY, FOR PULL OUT CLEANING. | H44: L04_GHVFW_010E_WINZE STOPE | I44: MARTINEZ DN 1 | J44: REPLACEMENT OF L04_GHVFW_010E_WINZE STOPE PREP. APPROVED ON SEPTEMBER 1, 2022.CONDUCTED FILL RAISE ON OCTOBER 19, 2022. STOPPED BREAKING AND CONVERT TO PULL-OUT ON NOV. 5, 2022. TRAVERSED ON NOVEMBER 4, 2022.STOPPED ON NOVERMBER 22, 2022 MINED OUT @ 94% | K44: L04_JV_056W_DW | L44: MARTINEZ DN 3 | M44: REPLACEMENT OF L04_NONE_056W_XCS, APPROVED ON APRIL 5, 2020. TEMP. STOPPED ON APRIL 9 DUE TO PANDEMIC. | N44: L04_JVSPLIT_011W_RAISE | O44: PARAGUYA 1 | P44: ADDITIONAL VERTICAL DEVELOPMENT. APPROVED ON JANUARY 11, 2019. MZC. STOPPED ON JANUARY 19, 2019 ALREADY FINISHED FILL RAISE. | Q44: L04_EDV_018W_WINZE | R44: ANDILAB 1 | S44: REPLACEMENT OF L04_JV_012W_ROBBING. APPROVED ON OCT 11, 2021. TEMP STOPPED ON NOV. 16, 2021. RESUMED ON NOVEMBER 22,2021. STOPPED ON DECEMBER 1, 2021. | W44: L04_NONE_027W_XCS | X44: DAGAMAC 6 | Y44: SPECIAL PROJECT FOR VENTILATION PURPOSES ON JUNE 4, 2019. STOPPED ON JULY 15, 2019 ALREADY ATTAINED BASED ON THE PLAN. RESUMED ON OCT. 21, 2019
B45: L04_CTV_021W_WINZE STOPE PREP | C45: MARTINEZ, DN 5 | D45: REPLACEMENT OF L04_CTV_023W_DW_ISL APPROVED ON NOVEMBER 7, 2023.TEMPORARILY STOPPED ON NOVEMBER 11, 2023 FOR SAFETY EVALUATION. RESUMED ON NOVEMBER 13, 2023, AFTER FURTHER SAFETY EVALUATION.STOPPED ON NOVEMBER 29, 2023. CONVERT TO STOPE BREAKING. | E45: L04_CV_006E_STOPE | F45: MARTINEZ, RON 3 | G45: REPLACEMENT OF L04_CV_006E_STOPE PREP. APPROVED ON JUNE 22, 2022.STOPPED ON AUGUST 24, 2022 AT THE SAME TIME CONVERTED TO PULLOUT CLEANING. | H45: L04_CV_006E_WINZE STOPE | I45: MARTINEZ, DN 4 | J45: REPLACEMENT OF L04_CV_006E_DW_ISL. APPROVED ON MAY 05, 2023.ALREADY DONE STOPE PREP ON MAY 20, 2023. CONVERT TO STOPE BREAKING.REPLACEMENT OF L04_CV_006E_WINZE_STOPE PREP, APPROVED ON MAY 20, 2023.TEMPORARY STOPPED ON JUNE 8, 2023 DUE TO THE UNAVAILABIILITY OF AGSAO SHAFT.RESUMED ON OCTOBER 02, 2023. AS WELL AS CHANGED TEAM LEADER FROM MARTINEZ, RON 1 TO MARTINEZ, DN 4.STOPPED BREAKING ON NOVEMBER 09, 2023. AS WELL AS TRAVERSED ON NOVEMBER 10, 2023, 2ND SHIFT. CONVERT TO PULL-OUT CLEANING.TEMPORARILY STOPPED ON NOVEMBER 11, 2023 FOR SAFETY EVALUATION.RESUMED ON NOVEMBER 13, 2023, AFTER FURTHER SAFETY EVALUATION.STOPPED ON NOVEMBER 22, 2023. ALREADY MINED OUT. | K45: L04_JV_055W_DE | L45: COMAINGKING 5 | M45: ADDITIONAL HORIZONTAL DEVELOPMENT. APPROVED ON MARCH 16 2020. RENAMED ON MARCH 21 2020 FROM L04_JV_005W_DE TO L04_JV_055W_DE. STOPPED ON APRIL 8 2020 DUE TO CONSECUTIVE LOW ASSAY GRADE ON CUT SAMPLE/ BULK SAMPLE. | N45: L04_NV_012W_RAISE | O45: MARTINEZ RON. 1 | P45: ADDITIONAL VERTICAL DEVELOPMENT. APPROVED ON DECEMBER 4, 2018. MZC. STOPPED ON JANUARY 29, 2019 ALREADY BREAKTHROUGH TO OLD STOPE. | Q45: L04_CTV_022W_WINZE | R45: COMAINGKING | S45: REPLACEMENT OF L04_JV_013W_WINZE. APPROVED ON OCT 13, 2021. TEMPORARY STOPPED ON 11/15/21. RESUMED ON NOV. 17, 2021. GROUP FORM L04 GHV 057W ROBBING WILL BE MERGED TO L04 CTV 022W WINZE. STOPPED ON JANUARY 25, 2022 RECOMMENDED FOR SUB LEVEL. RESUMED ON FEB 24, 2022 AS FILL WINZE . STOPPED ON FEBRUARY 28, 2022, FINISHED FILL WINZE. | W45: L04_JVFW_011E_ROBBING | X45: MARTINEZ DN 3 | Y45: REPLACEMENT OF L04 JV 005W ROBBING. APPROVED ON MARCH 6,2020. CONVERT TO SILL PILLAR ON MARCH 27, 2020. TEMPORARY STOPPED ON MARCH 31 2020 WAITING FOR CROWN PILLAR ROBBING TO BE FILLED WITH WASTE PRIOR TO SILL PILLAR ROB. RESUMED ON APRIL 3, 2020. RESUMED ON JULY 3, 2020. TEMPORARY STOPPED ON JULY 18 2020 DUE TO UNSAFE CONDITION
... B47: L03_CTV_025W_STOPE PREP | C47: FERNANDEZ, RM 5 | D47: ADDITIONAL SOURCE OF GOOD ORE. APPROVED ON AUGUST 20, 2024. STOPPED ON SEPTEMBER 17, 2024. AT THE SAME TIME CONVERT TO STOPE BREAKING. | E47: L03_CTV_025W_STOPE | F47: FERNANDEZ, RM 5 | G47: REPLACEMENT OF L03_CTV_025W_STOPE PREP. APPROVED ON SEPTEMBER 17, 2024. STOPPED BREAKING ON OCTOBER 26, 2024 DUE TO PINCHED OUT VEIN/LOW ASSAY GRADE RESULT TO ITS IPR. CONVERTED TO STOPE PULL-OUT CLEANING. | H47: L04_CTV_021W_WINZE STOPE | I47: MARTINEZ, DN 5 | J47: REPLACEMENT OF L04_CTV_021W_WINZE STOPE PREP. APPROVED ON NOVEMBER 29, 2023.STOPPED BREAKING ON FEBRUARY 10, 2024. CONVERT TO PULL-OUT CLEANING.STOPPED ON FEBRUARY 26, 2024. ALREADY MINED OUT. | K47: L04_CTV_011W_DW | L47: NOCOS 1 | M47: REPLACEMENT OF L04_CTV_011W_ROBBING APPROVED ON NOV 15, 2019. TEMPORARY STOPPED ON FEBRUARY 4 2020 DUE TO UNSERVICEABLE AREA. RESUMED ON FEB, 21 2020. STOPPED ON MARCH 26 2020 DUE TO LOW ASSAY GRADE ON CUT SAMPLE/BULK SAMPLE. | N47: L04_JV_002E_RAISE | O47: CABONITA 1 | P47: REPLACEMENT OF L04 JV 002E DW. APPROVED ON SEPT 1, 2018. STOPPED OCTOBER 12,2018. RESUMED ON JANUARY 16, 2019. STOPPED ON FEB 7, 2019 DUE TO OFF-VEIN. | Q47: L04_CV_025W_WINZE | R47: NOCOS 2 | S47: REPLACEMENT OF L04_JVFW_010E_STOPE. APPROVED ON DEC. 3, 2021.TEMP. TEMPORARY STOPPED ON JANUARY 10,2022 MEMO RECEIVED ON JANUARY 18,2022 DUE TO LACK OF MANPOWER.RESUMED ON FEB 21, 2022 AND TRANSFERRED FROM COMAINGKING 2 TO NOCOS 2.TEMP. STOPPED ON MARCH 10, 2022 INSUFFICIENT MAN POWER. RESUMED ON MARCH 15 2022.STOPPED ON MAY 3, 2022, HAS 4 METERS REMAINING DISTANCE TO CONNECT TO OLD STOPE OF LEVEL 5. | W47: L04_NONE_030E_XCS | X47: PMC MINERS 2 | Y47: FOR VENTILATION PURPOSES. APPROVED ON APRIL 7 2020. stopped on april 15 2020.
H48: L03_CTV_025W_STOPE | I48: FERNANDEZ, RM 5 | J48: REPLACEMENT OF L03_CTV_025W_STOPE PREP. APPROVED ON SEPTEMBER 17, 2024. STOPPED BREAKING ON OCTOBER 26, 2024 DUE TO PINCHED OUT VEIN/LOW ASSAY GRADE RESULT TO ITS IPR. CONVERTED TO STOPE PULL-OUT CLEANING. STOPPED ON NOVEMBER 08, 2024. DUE TO CONSECUTIVE LOW ASSAY GRADE. | K48: L04_GHV_028W_DW | L48: MARTINEZ, RONALD | M48: REPLACEMENT OF L04_NONE_028W_XCS. APPROVED ON JANUARY 30 2020. STOPPED ON MARCH 10 2020 DUE TO CONSECUTIVE LOW ASSAY GRADE ON CUT SAMPLES/ BULK SAMPLES. | N48: L04_CV_008W_RAISE | O48: MARTINEZ RON. 1 | P48: REPLACEMENT OF L04 CV 008W DE ON AUGUST 1, 2018/LTS.STOPPE ON AUGUST 28, 2018. RESUMED ON OCTOBER 18,2018 TO CONTINUE ADVANCE UNTIL IT BREAKTHROUGH AT L03 AS PER RDPARONDA.STOPPED DUE TO UNSAFE CONDITION ON OCTOBER 19, 2018 | Q48: L04_GHVFW_008W_WINZE | R48: SHEPHERD AR 1 | S48: REPLACEMENT OF L04_EDV_018W_DE_ISL. APPROVED ON APRIL 6 2022.STOPPED ON JUNE 9, 2022 DUE TO CONSECUTIVE LOW ASSAY GRADES ON CUT SAMPLES/BULK SAMPLE. | W48: L04_CTV_026E_ROBBING | X48: MARTINEZ DN 4 | Y48: REPLACEMENT OF L04_CTVSPLIT_026E_ROBBING. APPROVED ON AUGUST 10 2020. Start Robbing on August 18 2020.STOPPED ON AUGUST 26,2020.DUE TO POOR VIEN MENERALIZATION.
K49: L04_JVHW_014E_DE | L49: COMAINGKING 3 | M49: REPLACEMENT OF L04 JVFW_14E_WINZE.APPROVED ON MAY 31, 2019/ TEMP. STOPPED ON JUNE 17, 2019 DUE TO LACK OF MANPOWER. RESUMED ON FEBRUARY 4, 2020 AS WELL AS TRANSFER FROM OY-YOY 2 TO COMAINGKING 3. STOPPED ON MARCH 6 2020 DUE TO PINCHED OUT VEIN. | N49: L04_RYV_010E_RAISE | O49: MARTINEZ DN 3 | P49: REPLACEMENT OF L04 RYV 010E DW. APPROVED ON JANUARY 19, 2019. MZC. DRIVING INCLINED RAISE TOWARDS WEST ON FEB 25, 2019. STOPPED ON MARCH 14, 2019 DUE TO PINCHED OUT OF VEIN. | Q49: L03_RYV_007W_WINZE | R49: FERNANDEZ, RM 5 | S49: ADDITIONAL VERTICAL DEVELOPMENT APPROVED ON JANUARY 20, 2023.STOPPED ON FEBRUARY 23, 2023 DUE TO CONSECUTIVE LOW GRADE ON BULK SAMPLES. | W49: L04_GHV_051W_ROBBING | X49: BENONGUIL 3 | Y49: ADDITIONAL SOURCE OF GOOD ORE. APPROVED ON JULY 22, 2020 AND STILL ON-GOING CLEANING. Start robbing Sill on August 20 2020. Stopped on Sept 18,2020 already mined out.
K50: L04_JV_054W_DW | L50: SHEPHERD X 2 | M50: REPLACEMENT OF L04 JVSPLIT 058W RAISE. APPROVED ON MARCH 28, 2019/ STOPPED ON MAY 29, 2019 DUE TO CONSECUTIVE LOW GRADE CUT SAMPLES | N50: L04_JV_049W_RAISE | O50: SHEPHERD X 1 | P50: REPLACEMENT OF L04 JV 051W RAISE. APPROVED ON NOV 20, 2018. TEMP. STOPPED ON DECEMBER 10, 2018 AS PER WANCOG. RESUMED ON JANUARY 16, 2019 TO TARGET LOW DIPPING VEIN. TEMP STOPPED AND TRANSFER TO TAÑEZA 8 FROM DUHIG 3 DUE TO GOOD PERFORMANCE OF FORMER TEAM LEADER APPROVED ON MARCH 11,2019. RESUMED ON MARCH 13, 2019 AND TRANSFER FROM TANEZA 8 TO SHEPHERD X 1 (CAPUYAN).STOPPED ON APRIL 7, 2019 ALREADY REACHED THE RECOMMENDED STRIKE LENGTH. | W50: L04_GHV_057W_ROBBING | X50: BAÑEZ 5 | Y50: ADDITIONAL GOOD SOURCE OF GOOD ORE. APPROVED ON SEPTEMBER 07,2020.RENAMED ON SEPT. 22 2020 FROM L04_JV_057W_ROBBING TO L04_GHV_057W_ROBBING. TEMPORARY STOPPED TO PRIORIZE RAISE ON SEPT. 24 2020.
K51: L04_CTV5_017E_DE | L51: CABCAD 1 | M51: REPLACEMENT OF L04 JV 034E DE. APPROVED ON SEPTEMBER 26,2018. TEMPORARY STOPPED ON DECEMBER 6,2018 TO PRIORITIZED ACTIVE STOPE PREP. RESUMED ON JANUARY 28, 2019. TEMP. STOPPED ON FEB. 7, 2019 DUE TO ABSENTEEISM OF MEN RESULTING TO ABANDONMENT OF WP. RESUMED ON FEB 21, 2019; AS PER MEMO BY SCS. TEMPORARY STOPPED ON 3/6/19 DUE TO LACK OF MANPOWER. RESUMED ON APRIL 15, 2019. STOPPED ON APRIL 30, 2019 BECAUSE THIS WAS CUT BY FAULT. | N51: L04_JV_058W_RAISE | O51: SHEPHERD X 2 | P51: ADDITIONAL VERTICAL DEVELOPMENT. APPROVED ON 2/14/19. TRANSFER FROM DUHIG TO SHEPHERD X 2 (CAPUYAN) STARTING ON MARCH 13, 2019.STOP ON APR 4, 2019-LTS. | W51: L04_CV_001E_ROBBING | X51: MARTINEZ RON. 1 | Y51: REPLACEMENT OF L04_JV_053W_RAISE. APPROVED ON MARCH 26 2020. RESUMED ON JULY 11, 2020 FOR CLEANING. START ROBBING ON JULY 14, 2020. STOPPED ON JULY 23, 2020 TO DRIVE WINZE. RESUMED ON SEPT. 2 2020. Stopped on Sept 26, 2020 already done beraking pillars.
K52: L04_RYV_007W_DW | L52: ANDILAB 1 | M52: REPLACEMENT OF L04 NONE 007W XCS.APPROVED ON OCTOBER 24, 2018. STOPPED ON JAN 8. 2019 DUE TO CONSECUTIVE LOW ASSAY GRADE. | N52: L04_NV_020W_RAISE | O52: ANDILAB 1 | P52: REPLACEMENT OF L04 NV 017W DW, APPROVED ON 5/3/19-SDNC.STOPPED ON JUNE 13, 2019 DUE TO CONSECTUVIE LOW ASSAY GRADE. | W52: L04_JV_055W_ROBBING | X52: MARTINEZ, RONALD | Y52: REPLACEMENT OF L04_NONE_025W_XCN. APPROVED ON SEPT. 8 2020. stopped on OCT 12 2020 ALREADY REACHED THE RECOMMENDED STRIKE LENGTH / CROWN PILLAR
K53: L04_JV_049W_DW | L53: DUHIG 3 | M53: REPLACEMENT OF L04 JV 049W RAISE. APPROVED ON DECEMBER 10, 2018. STOPPED ON JANUARY 11, 2019 ALREADY REACHED THE DESIRED STRIKE LENGTH. | N53: L04_GHVFW_024E_RAISE | O53: LERIO 5 | P53: REPLACEMENT OF L04 JV 22W DE, APPROVED ON MAR 5, 2018 AS PER LTS. STOPPED DUE TO LEVEL GEO MEMO ON APRIL 20, 2018. REPLACEMENT OF L04 GHVDW 015E DE ON MAY 30, 2019. STOPPED ON JUNE 10, 2019 DUE TO PINCHED OUT OF VEIN AFTER 2 BLASTS. | W53: L04_CV_013W_ROBBING | X53: MARTINEZ RONALD | Y53: REPLACEMENT OF L04 JV 058W DW. APPROVED ON NOVEMBER 17 2020. STARTED MAINLINECLEANING ON NOV. 28 2020. CONVERTED TO CROWN ON NOV 26 2020. Stopped on Dec 1 2020.
K54: L04_JVSPLIT_012W_DE | L54: MARTINEZ DN 1 | M54: REPLACEMENT OF L04_RYV_011E_DE. APPROVED ON FEB. 6, 2019. STOPPED ON FEB 25, 2019 ALREADY BREAKTHROUGH. | N54: L04_CV_009W_RAISE | O54: MARTINEZ DN 1 | P54: REPLACEMENT OF L04 CV 008W DE. APPROVED ON JUNE 10, 2019.STOPPED DUE TO PINCHED OUT VIEN ON JULY 3, 2019 | W54: L04_JV_056W_ROBBING | X54: MARTINEZ, RON.2 | Y54: REPLACEMENT OF L04_JV_056W_RAISE. APPROVED ON SEPT. 16 2020. ON NOVEMBER 9 2020 STOPPED CROWN & CONVERTED TO SILL PILLAR. MINED OUT JAN 07 2021
K55: L04_JV_003E_DE | L55: CABONITA 1 | M55: REPLACEMENT OF L04 NONE 6W XCN. APPROVED ON JUNE 16, 2018.RENAMED FROM EDV 9W TO NV 9W ON JULY 5, 2018/LTS.TEMPORARY STOPPED DUE TO LACK OF MANPOWER.APPROVED ON SEPTEMBER 18, 2018. TEMPORARY STOPPED ON OCTOBER 10,2018 TO PRIORITIZE L04 NONE 002E XCN. RESUMED ON NOVEMBER 17, 2018.TEMPORARY STOPPED DUE TO INSUFFICIENT MANPOWER ON FEBRUARY 5, 2019. RESUMED ON FEBRUARY 20,2019 AND AT THE SAME TIME TRANSFER FROM ASIS 1 TO CABONITA 1. STOPPED ON MARCH 12, 2019 DUE TO PINCHED OUT OF VEIN. | N55: L04_GHVFW_019E_RAISE | O55: LERIO 5 | P55: REPLACEMENT OF L04 JV 010W STOPE. APPROVED ON FEB. 5, 2019. MZC. TEMPORARY STOPPED ON MARCH 1, 2019. DUE TO CONSECUTIVE LOW ASSAY GRADE. RESUMED ON 6/10/2019 TO CONDUCT INCLINED RAISE FOR EXPLORATORY PURPOSES AND TRANSFER FROM CABONITA 1 TO LERIO 5. STOPPED ON JULY 13, 2019 OFF VEIN. | W55: L04_CTV_025E_ROBBING | X55: MARTINEZ DN 4 | Y55: ADDITIONAL SOURCE OF GOOD ORE. APPROVED ON AUGUST 26 2020. MINED OUT JAN 7, 2021
K56: L04_GHVSPLIT_055W_DW | L56: DUHIG 1 | M56: REPLACEMENT OF L04 NONE 055W XCS. APPROVED ON MARCH 27, 2019.STOP ON 4/9/19-SDNC, PINCHED-OUT VEIN. | N56: L04_CV_011W_RAISE | O56: MARTINEZ DN 1 | P56: REPLACEMENT OF L04_CV_009W_RAISE APPROVED ON JULY 4, 2019.STOPPED ON JULY 11, 2019 ALREADY BREAK THRU. | W56: L04_CTV_019W_ROBBING | X56: SHEPHERD W | Y56: REPLACEMENT OF L04_CTV_019W_DE. Sept. 30 2020 -TOPSLICE CONVERTED TO SILL ON NOV. 28 2020. Stopped due to poor vein mineralization
