Workbook

Sheet EXPEDITION CONSOLIDATION
A1: EXPEDITION DRILLING AND BLASTING, INC.
A2: PHILSAGA MINING CORPORATION (OPERATION)
A3: Bayugan 3, Rosario Agusan del Sur
A5: DAILY CONSOLIDATION BLASTER REPORT
A6: FOR JUNE 1-7, 2026
A8: Location | C8: : | D8: MINE SITE, CO-O, CONSUELO, BUNAWAN , AGUSAN DEL SUR
A10: I. | B10: EXPLOSIVE USED | F10: REQUISITIONED | J10: CONSUMED | N10: REQUIRED
F11: (KLS) | G11: (PCS) | J11: (KLS) | K11: (PCS) | N11: (KLS) | O11: (PCS)
B12: Emulison Senatel Pulsar 38 | F12: =G12/38*25 -> 0 | G12: ='1-2'!G11+'1-2'!G47+'3-4'!G11+'3-4'!G49+'5-6'!G11+'5-6'!G49+'7.'!G11+'7.'!G49+'8'!G11+'8'!G50+'9'!G11+'9'!G49+'10'!G11+'10'!G49 -> 0 | H12: pcs | J12: =F12 -> 0 | K12: =G12 -> 0 | L12: pcs | N12: =F12 -> 0 | O12: =G12 -> 0 | P12: pcs
B13: Emulison Senatel Pulsar 135 | F13: =G13/135*25 -> 0 | G13: ='1-2'!G12+'1-2'!G48+'3-4'!G12+'3-4'!G50+'5-6'!G12+'5-6'!G50+'7.'!G12+'7.'!G50+'8'!G12+'8'!G51+'9'!G12+'9'!G50+'10'!G12+'10'!G50 -> 0 | H13: pcs | J13: =F13 -> 0 | K13: =G13 -> 0 | L13: pcs | N13: =F13 -> 0 | O13: =G13 -> 0 | P13: pcs
B14: Emulsion Senatel Pulsar 215 P | F14: =G14/215*25 -> 1087.3256 | G14: ='1-2'!G13+'1-2'!G49+'3-4'!G13+'3-4'!G51+'5-6'!G13+'5-6'!G51+'7.'!G13+'7.'!G51+'8'!G13+'8'!G52+'9'!G13+'9'!G51+'10'!G13+'10'!G51 -> 9351 | H14: pcs | J14: =F14 -> 1087.3256 | K14: =G14 -> 9351 | L14: pcs | N14: =F14 -> 1087.3256 | O14: =G14 -> 9351 | P14: pcs
B15: Anfo | F15: ='1-2'!F14+'1-2'!F50+'3-4'!F14+'3-4'!F52+'5-6'!F14+'5-6'!F52+'7.'!F14+'7.'!F52+'8'!F14+'8'!F53+'9'!F14+'9'!F52+'10'!F14+'10'!F52 -> 7769.8 | J15: =F15 -> 7769.8 | N15: =F15 -> 7769.8
B16: OBC | G16: ='1-2'!G15+'1-2'!G51+'3-4'!G15+'3-4'!G53+'5-6'!G15+'5-6'!G53+'7.'!G15+'7.'!G53+'8'!G15+'8'!G54+'9'!G15+'9'!G53+'10'!G15+'10'!G53 -> 632 | H16: pcs | K16: =G16 -> 632 | L16: pcs | O16: =G16 -> 632 | P16: pcs
B17: Safety Fuse | G17: ='1-2'!G16+'1-2'!G52+'3-4'!G16+'3-4'!G54+'5-6'!G16+'5-6'!G54+'7.'!G16+'7.'!G54+'8'!G16+'8'!G55+'9'!G16+'9'!G54 -> 1535.76 | H17: meters | K17: =G17 -> 1535.76 | L17: meters | O17: =G17 -> 1535.76 | P17: meters
B18: EXEL Detonator (3.6) | G18: ='1-2'!G17+'1-2'!G53+'3-4'!G17+'3-4'!G55+'5-6'!G17+'5-6'!G55+'7.'!G17+'7.'!G55+'8'!G17+'8'!G56+'9'!G17+'9'!G55+'10'!G17+'10'!G55 -> 580 | H18: pcs | K18: =G18 -> 580 | L18: pcs | O18: =G18 -> 580 | P18: pcs
B19: EXEL Detonator (2.4) | G19: ='1-2'!G18+'1-2'!G54+'3-4'!G18+'3-4'!G56+'5-6'!G18+'5-6'!G56+'7.'!G18+'7.'!G56+'8'!G18+'8'!G57+'9'!G18+'9'!G56+'10'!G18+'10'!G56 -> 10535 | H19: pcs | K19: =G19 -> 10535 | L19: pcs | O19: =G19 -> 10535 | P19: pcs
B20: EXEL Detonator (4.9) | G20: ='1-2'!G19+'1-2'!G55+'3-4'!G19+'3-4'!G57+'5-6'!G19+'5-6'!G57+'7.'!G19+'7.'!G58+'8'!G19+'8'!G58+'9'!G19+'9'!G57+'10'!G19+'10'!G57 -> 0 | H20: pcs | K20: =G20 -> 0 | L20: pcs | O20: =G20 -> 0 | P20: pcs
B21: Cordtex (Detonating Cord) 5 | G21: ='1-2'!G20+'1-2'!G56+'3-4'!G20+'3-4'!G58+'5-6'!G20+'5-6'!G58+'7.'!G20+'7.'!G58+'8'!G20+'8'!G58+'9'!G20+'9'!G57+'10'!G19+'10'!G57 -> 2350 | H21: meters | K21: =G21 -> 2350 | L21: meters | O21: =G21 -> 2350 | P21: meters
B22: Cordtex (DCORD I) 5 | G22: ='1-2'!G21+'1-2'!G57+'3-4'!G21+'3-4'!G59+'5-6'!G21+'5-6'!G59+'7.'!G21+'7.'!G59+'8'!G22+'8'!G60+'9'!G22+'9'!G59+'10'!G21+'10'!G59 -> 0 | H22: meters | K22: =G22 -> 0 | L22: meters | O22: =G22 -> 0 | P22: meters
B23: Cordtex (Detonating Cord) 40 | G23: ='1-2'!G22+'1-2'!G58+'3-4'!G22+'3-4'!G60+'5-6'!G22+'5-6'!G60+'7.'!G22+'7.'!G60+'8'!G23+'8'!G61+'9'!G23+'9'!G60+'10'!G22+'10'!G60 -> 0 | H23: meters | K23: =G23 -> 0 | L23: meters | O23: =G23 -> 0 | P23: meters
B24: MS 12 | G24: ='1-2'!G23+'1-2'!G59+'3-4'!G23+'3-4'!G61+'5-6'!G23+'5-6'!G61+'7.'!G23+'7.'!G61+'8'!G24+'8'!G62+'9'!G24+'9'!G61+'10'!G23+'10'!G61 -> 0 | H24: meters | K24: 0 | L24: meters | O24: 0 | P24: meters
B25: MS 18 | G25: ='1-2'!G24+'1-2'!G60+'3-4'!G24+'3-4'!G62+'5-6'!G24+'5-6'!G62+'7.'!G24+'7.'!G62+'8'!G25+'8'!G63+'9'!G25+'9'!G62+'10'!G24+'10'!G62 -> 0 | H25: meters | K25: 0 | L25: meters | O25: 0 | P25: meters
B26: Fuse Lighter | G26: ='1-2'!G25+'1-2'!G61+'3-4'!G25+'3-4'!G63+'5-6'!G25+'5-6'!G63+'7.'!G25+'7.'!G63+'8'!G26+'8'!G64+'9'!G24+'9'!G63+'10'!G25+'10'!G63 -> 2 | H26: pcs | K26: =G26 -> 2 | L26: meters | O26: =G26 -> 2 | P26: meters
B27: BILL WIRE | G27: ='1-2'!G26+'1-2'!G62+'3-4'!G26+'3-4'!G64+'5-6'!G26+'5-6'!G64+'7.'!G26+'7.'!G64+'8'!G27+'8'!G65+'9'!G25+'9'!G64+'10'!G26+'10'!G64 -> 26 | H27: pcs | K27: =G27 -> 26 | L27: meters | O27: =G27 -> 26 | P27: meters
B28: EBC | G28: ='1-2'!G27+'1-2'!G63+'3-4'!G27+'3-4'!G65+'5-6'!G27+'5-6'!G65+'7.'!G27+'7.'!G65+'8'!G28+'8'!G66+'9'!G28+'9'!G65+'10'!G27+'10'!G65 -> 28 | H28: pcs | K28: =G28 -> 28 | L28: meters | O28: =G28 -> 28 | P28: meters
A30: II. | B30: CHARGED DRILL HOLES
C31: (a) | D31: PRIMARY: | E31: ='1-2'!E30:F30+'1-2'!E66:F66+'3-4'!E30:F30+'3-4'!E68:F68+'5-6'!E30:F30+'5-6'!E68:F68+'7.'!E30:F30+'7.'!E68:F68+'8'!E31:F31+'8'!E68:F68+'9'!E31:F31+'9'!E67:F67+'10'!E30:F30+'10'!E67:F67 -> 450 | G31: No. of holes: | J31: ='1-2'!J30:K30+'1-2'!J66:K66+'3-4'!J30:K30+'3-4'!J68:K68+'5-6'!J30:K30+'5-6'!J68:K68+'7.'!J30:K30+'7.'!J68:K68+'8'!J31:K31+'8'!J68:K68+'9'!J31:K31+'9'!J67:K67+'10'!J30:K30+'10'!J67:K67 -> 11010 | L31: Depth: | N31: 5'X11" | T31: =J31+J32 -> 11115
C32: (b) | D32: SECONDARY: | E32: ='1-2'!E31:F31+'1-2'!E67:F67+'3-4'!E31:F31+'3-4'!E69:F69+'5-6'!E31:F31+'5-6'!E69:F69+'7.'!E31:F31+'7.'!E69:F69+'8'!E32:F32+'8'!E69:F69+'9'!E32:F32+'9'!E68:F68+'10'!E31:F31+'10'!E68:F68 -> 16 | G32: No. of holes: | J32: ='1-2'!J31:K31+'1-2'!J67:K67+'3-4'!J31:K31+'3-4'!J69:K69+'5-6'!J31:K31+'5-6'!J69:K69+'7.'!J31:K31+'7.'!J69:K69+'8'!J32:K32+'8'!J69:K69+'9'!J32:K32+'9'!J68:K68+'10'!J31:K31+'10'!J68:K68 -> 105 | L32: Depth: | N32: 3X'11"
A34: III. | B34: ESTIMATED TONNAGE OF BLASTED MATERIAL
B35: REMARKS:
A38: Prepared by: | F38: Witnessed and Checked by: | L38: Reviewed by:
A41: RONALD V BATERNA | F41: PEMS VER M JULAO | L41: RAFFY D TORRES
A42: LICENSED BLASTER | F42: PNP - PPO AGUSAN DEL SUR REPRESENTATIVE | L42: MINE EXPLOSIVES MANAGER
A43: FPKB15-090124-1069
A46: Noted by:
A49: ENGR EARL M SON
A50: MINE DIVISION MANAGER

Sheet 1-2
A1: EXPEDITION DRILLING AND BLASTING, INC.
A2: PHILSAGA MINING CORPORATION (OPERATION)
A3: Bayugan 3, Rosario Agusan del Sur
A5: DAILY BLASTER REPORT
A6: Location | C6: : | D6: MINE SITE, CO-O, CONSUELO, BUNAWAN , AGUSAN DEL SUR | M6: Date: | N6: 46174
A7: Time of Blasting | C7: : | D7: 6:45 AM / 2:45 PM / 10:45 PM | M7: Shift: | N7: 1ST SHIFT/2ND SHIFT/3RD SHIFT
A9: I. | B9: EXPLOSIVE USED | F9: REQUISITIONED | J9: CONSUMED | N9: REQUIRED
F10: (KLS) | G10: (PCS) | J10: (KLS) | K10: (PCS) | N10: (KLS) | O10: (PCS)
B11: ='EXPEDITION CONSOLIDATION'!B12:D12 -> Emulison Senatel Pulsar 38 | F11: =G11/38*25 -> 0 | H11: pcs | J11: =F11 -> 0 | K11: =G11 -> 0 | L11: pcs | N11: =F11 -> 0 | O11: =G11 -> 0 | P11: pcs
B12: ='EXPEDITION CONSOLIDATION'!B13:D13 -> Emulison Senatel Pulsar 135 | F12: =G12/135*25 -> 0 | H12: pcs | J12: =F12 -> 0 | K12: =G12 -> 0 | L12: pcs | N12: =F12 -> 0 | O12: =G12 -> 0 | P12: pcs
B13: ='EXPEDITION CONSOLIDATION'!B14:D14 -> Emulsion Senatel Pulsar 215 P | F13: =G13/215*25 -> 128.48837 | G13: 1105 | H13: pcs | J13: =F13 -> 128.48837 | K13: =G13 -> 1105 | L13: pcs | N13: =F13 -> 128.48837 | O13: =G13 -> 1105 | P13: pcs
B14: ='EXPEDITION CONSOLIDATION'!B15:D15 -> Anfo | F14: 981 | J14: =F14 -> 981 | N14: =F14 -> 981
B15: ='EXPEDITION CONSOLIDATION'!B16:D16 -> OBC | G15: 80 | H15: pcs | K15: =G15 -> 80 | L15: pcs | O15: =G15 -> 80 | P15: pcs
B16: ='EXPEDITION CONSOLIDATION'!B17:D17 -> Safety Fuse | G16: =G15*2.43 -> 194.4 | H16: meters | K16: =G16 -> 194.4 | L16: meters | O16: =G16 -> 194.4 | P16: meters
B17: ='EXPEDITION CONSOLIDATION'!B18:D18 -> EXEL Detonator (3.6) | G17: 98 | H17: pcs | K17: =G17 -> 98 | L17: pcs | O17: =G17 -> 98 | P17: pcs
B18: ='EXPEDITION CONSOLIDATION'!B19:D19 -> EXEL Detonator (2.4) | G18: 1267 | H18: pcs | K18: =G18 -> 1267 | L18: pcs | O18: =G18 -> 1267 | P18: pcs
B19: ='EXPEDITION CONSOLIDATION'!B20:D20 -> EXEL Detonator (4.9) | H19: pcs | K19: =G19 -> 0 | L19: pcs | O19: =G19 -> 0 | P19: pcs
B20: ='EXPEDITION CONSOLIDATION'!B21:D21 -> Cordtex (Detonating Cord) 5 | G20: 392 | H20: meters | K20: =G20 -> 392 | L20: meters | O20: =G20 -> 392 | P20: meters
B21: ='EXPEDITION CONSOLIDATION'!B22:D22 -> Cordtex (DCORD I) 5 | H21: meters | K21: =G21 -> 0 | L21: meters | O21: =G21 -> 0 | P21: meters
B22: ='EXPEDITION CONSOLIDATION'!B23:D23 -> Cordtex (Detonating Cord) 40 | H22: meters | K22: =G22 -> 0 | L22: meters | O22: =G22 -> 0 | P22: meters
B23: ='EXPEDITION CONSOLIDATION'!B24:D24 -> MS 12 | H23: meters | K23: =G23 -> 0 | L23: meters | O23: =G23 -> 0 | P23: meters
B24: ='EXPEDITION CONSOLIDATION'!B25:D25 -> MS 18 | H24: meters | K24: =G24 -> 0 | L24: meters | O24: =G24 -> 0 | P24: meters
B25: ='EXPEDITION CONSOLIDATION'!B26:D26 -> Fuse Lighter | H25: pcs | K25: =G25 -> 0 | L25: pcs | O25: =G25 -> 0 | P25: pcs
B26: ='EXPEDITION CONSOLIDATION'!B27:D27 -> BILL WIRE | H26: pcs | K26: =G26 -> 0 | L26: pcs | O26: =G26 -> 0 | P26: pcs
B27: ='EXPEDITION CONSOLIDATION'!B28:D28 -> EBC | G27: 2 | H27: pcs | K27: =G27 -> 2 | L27: pcs | O27: =G27 -> 2 | P27: pcs
A29: II. | B29: CHARGED DRILL HOLES
C30: (a) | D30: PRIMARY: | E30: 54 | G30: No. of holes: | J30: =G17+G18+G19-J31 -> 1365 | M30: Depth: | N30: 5'X11"
C31: (b) | D31: SECONDARY: | E31: 0 | G31: No. of holes: | J31: 0 | M31: Depth: | N31: 3X'11"
A33: III. | B33: ESTIMATED TONNAGE OF BLASTED MATERIAL
B34: REMARKS:
A37: EXPEDITION DRILLING AND BLASTING, INC.
A38: PHILSAGA MINING CORPORATION (OPERATION)
A39: Bayugan 3, Rosario Agusan del Sur
A41: DAILY BLASTER REPORT
A42: Location | C42: : | D42: MINE SITE, CO-O, CONSUELO, BUNAWAN , AGUSAN DEL SUR | M42: Date: | N42: 46175
A43: Time of Blasting | C43: : | D43: 6:45 AM / 2:45 PM / 10:45 PM | M43: Shift: | N43: 1ST SHIFT/2ND SHIFT/3RD SHIFT
A45: I. | B45: EXPLOSIVE USED | F45: REQUISITIONED | J45: CONSUMED | N45: REQUIRED
F46: (KLS) | G46: (PCS) | J46: (KLS) | K46: (PCS) | N46: (KLS) | O46: (PCS)
B47: ='EXPEDITION CONSOLIDATION'!B12:D12 -> Emulison Senatel Pulsar 38 | F47: =G47/38*25 -> 0 | H47: pcs | J47: =F47 -> 0 | K47: =G47 -> 0 | L47: pcs | N47: =F47 -> 0 | O47: =G47 -> 0 | P47: pcs
B48: ='EXPEDITION CONSOLIDATION'!B13:D13 -> Emulison Senatel Pulsar 135 | F48: =G48/135*25 -> 0 | H48: pcs | J48: =F48 -> 0 | K48: =G48 -> 0 | L48: pcs | N48: =F48 -> 0 | O48: =G48 -> 0 | P48: pcs
...

Sheet 3-4
A1: EXPEDITION DRILLING AND BLASTING, INC.
A2: PHILSAGA MINING CORPORATION (OPERATION)
A3: Bayugan 3, Rosario Agusan del Sur
A5: DAILY BLASTER REPORT
A6: Location | C6: : | D6: MINE SITE, CO-O, CONSUELO, BUNAWAN , AGUSAN DEL SUR | M6: Date: | N6: 46176
A7: Time of Blasting | C7: : | D7: 6:45 AM / 2:45 PM / 10:45 PM | M7: Shift: | N7: 1ST SHIFT/2ND SHIFT/3RD SHIFT
A9: I. | B9: EXPLOSIVE USED | F9: REQUISITIONED | J9: CONSUMED | N9: REQUIRED
F10: (KLS) | G10: (PCS) | J10: (KLS) | K10: (PCS) | N10: (KLS) | O10: (PCS)
B11: ='EXPEDITION CONSOLIDATION'!B12:D12 -> Emulison Senatel Pulsar 38 | F11: =G11/38*25 -> 0 | H11: pcs | J11: =F11 -> 0 | K11: =G11 -> 0 | L11: pcs | N11: =F11 -> 0 | O11: =G11 -> 0 | P11: pcs
B12: ='EXPEDITION CONSOLIDATION'!B13:D13 -> Emulison Senatel Pulsar 135 | F12: =G12/135*25 -> 0 | H12: pcs | J12: =F12 -> 0 | K12: =G12 -> 0 | L12: pcs | N12: =F12 -> 0 | O12: =G12 -> 0 | P12: pcs
B13: ='EXPEDITION CONSOLIDATION'!B14:D14 -> Emulsion Senatel Pulsar 215 P | F13: =G13/215*25 -> 200.23256 | G13: 1722 | H13: pcs | J13: =F13 -> 200.23256 | K13: =G13 -> 1722 | L13: pcs | N13: =F13 -> 200.23256 | O13: =G13 -> 1722 | P13: pcs
B14: ='EXPEDITION CONSOLIDATION'!B15:D15 -> Anfo | F14: 1107.8 | J14: =F14 -> 1107.8 | N14: =F14 -> 1107.8
B15: ='EXPEDITION CONSOLIDATION'!B16:D16 -> OBC | G15: 88 | H15: pcs | K15: =G15 -> 88 | L15: pcs | O15: =G15 -> 88 | P15: pcs
B16: ='EXPEDITION CONSOLIDATION'!B17:D17 -> Safety Fuse | G16: =G15*2.43 -> 213.84 | H16: meters | K16: =G16 -> 213.84 | L16: pcs | O16: =G16 -> 213.84 | P16: meters
B17: ='EXPEDITION CONSOLIDATION'!B18:D18 -> EXEL Detonator (3.6) | G17: 69 | H17: pcs | K17: =G17 -> 69 | L17: pcs | O17: =G17 -> 69 | P17: pcs
B18: ='EXPEDITION CONSOLIDATION'!B19:D19 -> EXEL Detonator (2.4) | G18: 1599 | H18: pcs | K18: =G18 -> 1599 | L18: pcs | O18: =G18 -> 1599 | P18: pcs
B19: ='EXPEDITION CONSOLIDATION'!B20:D20 -> EXEL Detonator (4.9) | H19: pcs | K19: =G19 -> 0 | L19: pcs | O19: =G19 -> 0 | P19: pcs
B20: ='EXPEDITION CONSOLIDATION'!B21:D21 -> Cordtex (Detonating Cord) 5 | G20: 424 | H20: meters | K20: =G20 -> 424 | L20: meters | O20: =G20 -> 424 | P20: meters
B21: ='EXPEDITION CONSOLIDATION'!B22:D22 -> Cordtex (DCORD I) 5 | H21: meters | K21: =G21 -> 0 | L21: meters | O21: =G21 -> 0 | P21: meters
B22: ='EXPEDITION CONSOLIDATION'!B23:D23 -> Cordtex (Detonating Cord) 40 | H22: meters | K22: =G22 -> 0 | O22: =G22 -> 0 | P22: meters
B23: ='EXPEDITION CONSOLIDATION'!B24:D24 -> MS 12 | H23: meters | K23: =G23 -> 0 | L23: meters | O23: =G23 -> 0 | P23: meters
B24: ='EXPEDITION CONSOLIDATION'!B25:D25 -> MS 18 | H24: meters | K24: =G24 -> 0 | L24: meters | O24: =G24 -> 0 | P24: meters
B25: ='EXPEDITION CONSOLIDATION'!B26:D26 -> Fuse Lighter | H25: pcs | K25: =G25 -> 0 | L25: pcs | O25: =G25 -> 0 | P25: pcs
B26: ='EXPEDITION CONSOLIDATION'!B27:D27 -> BILL WIRE | H26: pcs | K26: =G26 -> 0 | L26: pcs | O26: =G26 -> 0 | P26: pcs
B27: ='EXPEDITION CONSOLIDATION'!B28:D28 -> EBC | G27: 6 | H27: pcs | K27: =G27 -> 6 | L27: pcs | O27: =G27 -> 6 | P27: pcs
A29: II. | B29: CHARGED DRILL HOLES
C30: (a) | D30: PRIMARY: | E30: 65 | G30: No. of holes: | J30: =G17+G18-J31+G19 -> 1652 | M30: Depth: | N30: 5'X11"
C31: (b) | D31: SECONDARY: | E31: 2 | G31: No. of holes: | J31: =6+10 -> 16 | M31: Depth: | N31: 3X'11"
A33: III. | B33: ESTIMATED TONNAGE OF BLASTED MATERIAL
B34: REMARKS:
A39: EXPEDITION DRILLING AND BLASTING, INC.
A40: PHILSAGA MINING CORPORATION (OPERATION)
A41: Bayugan 3, Rosario Agusan del Sur
A43: DAILY BLASTER REPORT
A44: Location | C44: : | D44: MINE SITE, CO-O, CONSUELO, BUNAWAN , AGUSAN DEL SUR | M44: Date: | N44: 46177
A45: Time of Blasting | C45: : | D45: 6:45 AM / 2:45 PM / 10:45 PM | M45: Shift: | N45: 1ST SHIFT/2ND SHIFT/3RD SHIFT
A47: I. | B47: EXPLOSIVE USED | F47: REQUISITIONED | J47: CONSUMED | N47: REQUIRED
F48: (KLS) | G48: (PCS) | J48: (KLS) | K48: (PCS) | N48: (KLS) | O48: (PCS)
B49: ='EXPEDITION CONSOLIDATION'!B12:D12 -> Emulison Senatel Pulsar 38 | F49: =G49/38*25 -> 0 | H49: pcs | J49: =F49 -> 0 | K49: =G49 -> 0 | L49: pcs | N49: =F49 -> 0 | O49: =G49 -> 0 | P49: pcs
B50: ='EXPEDITION CONSOLIDATION'!B13:D13 -> Emulison Senatel Pulsar 135 | F50: =G50/135*25 -> 0 | H50: pcs | J50: =F50 -> 0 | K50: =G50 -> 0 | L50: pcs | N50: =F50 -> 0 | O50: =G50 -> 0 | P50: pcs
...

Sheet 5-6
A1: EXPEDITION DRILLING AND BLASTING, INC.
A2: PHILSAGA MINING CORPORATION (OPERATION)
A3: Bayugan 3, Rosario Agusan del Sur
A5: DAILY BLASTER REPORT
A6: Location | C6: : | D6: MINE SITE, CO-O, CONSUELO, BUNAWAN , AGUSAN DEL SUR | M6: Date: | N6: 46178
A7: Time of Blasting | C7: : | D7: 6:45 AM / 2:45 PM / 10:45 PM | M7: Shift: | N7: 1ST SHIFT/2ND SHIFT/3RD SHIFT
A9: I. | B9: EXPLOSIVE USED | F9: REQUISITIONED | J9: CONSUMED | N9: REQUIRED
F10: (KLS) | G10: (PCS) | J10: (KLS) | K10: (PCS) | N10: (KLS) | O10: (PCS)
B11: ='EXPEDITION CONSOLIDATION'!B12:D12 -> Emulison Senatel Pulsar 38 | F11: =G11/38*25 -> 0 | H11: pcs | J11: =F11 -> 0 | K11: =G11 -> 0 | L11: pcs | N11: =F11 -> 0 | O11: =G11 -> 0 | P11: pcs
B12: ='EXPEDITION CONSOLIDATION'!B13:D13 -> Emulison Senatel Pulsar 135 | F12: =G12/135*25 -> 0 | H12: pcs | J12: =F12 -> 0 | K12: =G12 -> 0 | L12: pcs | N12: =F12 -> 0 | O12: =G12 -> 0 | P12: pcs
B13: ='EXPEDITION CONSOLIDATION'!B14:D14 -> Emulsion Senatel Pulsar 215 P | F13: =G13/215*25 -> 160.69767 | G13: 1382 | H13: pcs | J13: =F13 -> 160.69767 | K13: =G13 -> 1382 | L13: pcs | N13: =F13 -> 160.69767 | O13: =G13 -> 1382 | P13: pcs
B14: ='EXPEDITION CONSOLIDATION'!B15:D15 -> Anfo | F14: 1186.6 | J14: =F14 -> 1186.6 | N14: =F14 -> 1186.6
B15: ='EXPEDITION CONSOLIDATION'!B16:D16 -> OBC | G15: 112 | H15: pcs | K15: =G15 -> 112 | L15: pcs | O15: =G15 -> 112 | P15: pcs
B16: ='EXPEDITION CONSOLIDATION'!B17:D17 -> Safety Fuse | G16: =G15*2.43 -> 272.16 | H16: meters | K16: =G16 -> 272.16 | L16: meters | O16: =G16 -> 272.16 | P16: meters
B17: ='EXPEDITION CONSOLIDATION'!B18:D18 -> EXEL Detonator (3.6) | G17: 74 | H17: pcs | K17: =G17 -> 74 | L17: pcs | O17: =G17 -> 74 | P17: pcs
B18: ='EXPEDITION CONSOLIDATION'!B19:D19 -> EXEL Detonator (2.4) | G18: 1615 | H18: pcs | K18: =G18 -> 1615 | L18: pcs | O18: =G18 -> 1615 | P18: pcs
B19: ='EXPEDITION CONSOLIDATION'!B20:D20 -> EXEL Detonator (4.9) | H19: pcs | K19: =G19 -> 0 | L19: pcs | O19: =G19 -> 0 | P19: pcs
B20: ='EXPEDITION CONSOLIDATION'!B21:D21 -> Cordtex (Detonating Cord) 5 | G20: 254 | H20: meters | K20: =G20 -> 254 | L20: meters | O20: =G20 -> 254 | P20: meters
B21: ='EXPEDITION CONSOLIDATION'!B22:D22 -> Cordtex (DCORD I) 5 | H21: meters | K21: =G21 -> 0 | L21: meters | O21: =G21 -> 0 | P21: meters
B22: ='EXPEDITION CONSOLIDATION'!B23:D23 -> Cordtex (Detonating Cord) 40 | H22: meters | K22: =G22 -> 0 | L22: meters | O22: =G22 -> 0 | P22: meters
B23: ='EXPEDITION CONSOLIDATION'!B24:D24 -> MS 12 | H23: meters | K23: =G23 -> 0 | L23: meters | O23: =G23 -> 0 | P23: meters
B24: ='EXPEDITION CONSOLIDATION'!B25:D25 -> MS 18 | H24: meters | K24: =G24 -> 0 | L24: meters | O24: =G24 -> 0 | P24: meters
B25: ='EXPEDITION CONSOLIDATION'!B26:D26 -> Fuse Lighter | G25: 2 | H25: pcs | K25: =G25 -> 2 | L25: pcs | O25: =G25 -> 2 | P25: pcs
B26: ='EXPEDITION CONSOLIDATION'!B27:D27 -> BILL WIRE | G26: 26 | H26: pcs | K26: =G26 -> 26 | L26: pcs | O26: =G26 -> 26 | P26: pcs
B27: ='EXPEDITION CONSOLIDATION'!B28:D28 -> EBC | G27: 4 | H27: pcs | K27: =G27 -> 4 | L27: pcs | O27: =G27 -> 4 | P27: pcs
A29: II. | B29: CHARGED DRILL HOLES
C30: (a) | D30: PRIMARY: | E30: 68 | G30: No. of holes: | J30: =G17+G18-J31+G19 -> 1661 | M30: Depth: | N30: 5'X11"
C31: (b) | D31: SECONDARY: | E31: 3 | G31: No. of holes: | J31: =9+9+10 -> 28 | M31: Depth: | N31: 3X'11"
A33: III. | B33: ESTIMATED TONNAGE OF BLASTED MATERIAL
B34: REMARKS:
A39: EXPEDITION DRILLING AND BLASTING, INC.
A40: PHILSAGA MINING CORPORATION (OPERATION)
A41: Bayugan 3, Rosario Agusan del Sur
A43: DAILY BLASTER REPORT
A44: Location | C44: : | D44: MINE SITE, CO-O, CONSUELO, BUNAWAN , AGUSAN DEL SUR | M44: Date: | N44: 46179
A45: Time of Blasting | C45: : | D45: 6:45 AM / 2:45 PM / 10:45 PM | M45: Shift: | N45: 1ST SHIFT/2ND SHIFT/3RD SHIFT
A47: I. | B47: EXPLOSIVE USED | F47: REQUISITIONED | J47: CONSUMED | N47: REQUIRED
F48: (KLS) | G48: (PCS) | J48: (KLS) | K48: (PCS) | N48: (KLS) | O48: (PCS)
B49: ='EXPEDITION CONSOLIDATION'!B12:D12 -> Emulison Senatel Pulsar 38 | F49: =G49/38*25 -> 0 | H49: pcs | J49: =F49 -> 0 | K49: =G49 -> 0 | L49: pcs | N49: =F49 -> 0 | O49: =G49 -> 0 | P49: pcs
B50: ='EXPEDITION CONSOLIDATION'!B13:D13 -> Emulison Senatel Pulsar 135 | F50: =G50/135*25 -> 0 | H50: pcs | J50: =F50 -> 0 | K50: =G50 -> 0 | L50: pcs | N50: =F50 -> 0 | O50: =G50 -> 0 | P50: pcs
...

Sheet 7.
A1: EXPEDITION DRILLING AND BLASTING, INC.
A2: PHILSAGA MINING CORPORATION (OPERATION)
A3: Bayugan 3, Rosario Agusan del Sur
A5: DAILY BLASTER REPORT
A6: Location | C6: : | D6: MINE SITE, CO-O, CONSUELO, BUNAWAN , AGUSAN DEL SUR | M6: Date: | N6: 46180
A7: Time of Blasting | C7: : | D7: 6:45 AM / 2:45 PM / 10:45 PM | M7: Shift: | N7: 1ST SHIFT/2ND SHIFT/3RD SHIFT
A9: I. | B9: EXPLOSIVE USED | F9: REQUISITIONED | J9: CONSUMED | N9: REQUIRED
F10: (KLS) | G10: (PCS) | J10: (KLS) | K10: (PCS) | N10: (KLS) | O10: (PCS)
B11: ='EXPEDITION CONSOLIDATION'!B12:D12 -> Emulison Senatel Pulsar 38 | F11: =G11/38*25 -> 0 | H11: pcs | J11: =F11 -> 0 | K11: =G11 -> 0 | L11: pcs | N11: =F11 -> 0 | O11: =G11 -> 0 | P11: pcs
B12: ='EXPEDITION CONSOLIDATION'!B13:D13 -> Emulison Senatel Pulsar 135 | F12: =G12/135*25 -> 0 | H12: pcs | J12: =F12 -> 0 | K12: =G12 -> 0 | L12: pcs | N12: =F12 -> 0 | O12: =G12 -> 0 | P12: pcs
B13: ='EXPEDITION CONSOLIDATION'!B14:D14 -> Emulsion Senatel Pulsar 215 P | F13: =G13/215*25 -> 106.39535 | G13: 915 | H13: pcs | J13: =F13 -> 106.39535 | K13: =G13 -> 915 | L13: pcs | N13: =F13 -> 106.39535 | O13: =G13 -> 915 | P13: pcs
B14: ='EXPEDITION CONSOLIDATION'!B15:D15 -> Anfo | F14: 887.6 | J14: =F14 -> 887.6 | N14: =F14 -> 887.6
B15: ='EXPEDITION CONSOLIDATION'!B16:D16 -> OBC | G15: 72 | H15: pcs | K15: =G15 -> 72 | L15: pcs | O15: =G15 -> 72 | P15: pcs
B16: ='EXPEDITION CONSOLIDATION'!B17:D17 -> Safety Fuse | G16: =G15*2.43 -> 174.96 | H16: meters | K16: =G16 -> 174.96 | L16: meters | O16: =G16 -> 174.96 | P16: meters
B17: ='EXPEDITION CONSOLIDATION'!B18:D18 -> EXEL Detonator (3.6) | G17: 52 | H17: pcs | K17: =G17 -> 52 | L17: pcs | O17: =G17 -> 52 | P17: pcs
B18: ='EXPEDITION CONSOLIDATION'!B19:D19 -> EXEL Detonator (2.4) | G18: 1233 | H18: pcs | K18: =G18 -> 1233 | L18: pcs | O18: =G18 -> 1233 | P18: pcs
B19: ='EXPEDITION CONSOLIDATION'!B20:D20 -> EXEL Detonator (4.9) | H19: pcs | K19: =G19 -> 0 | L19: pcs | O19: =G19 -> 0 | P19: pcs
B20: ='EXPEDITION CONSOLIDATION'!B21:D21 -> Cordtex (Detonating Cord) 5 | G20: 203 | H20: meters | K20: =G20 -> 203 | L20: meters | O20: =G20 -> 203 | P20: meters
B21: ='EXPEDITION CONSOLIDATION'!B22:D22 -> Cordtex (DCORD I) 5 | H21: meters | K21: =G21 -> 0 | L21: meters | O21: =G21 -> 0 | P21: meters
B22: ='EXPEDITION CONSOLIDATION'!B23:D23 -> Cordtex (Detonating Cord) 40 | H22: meters | K22: =G22 -> 0 | L22: meters | O22: =G22 -> 0 | P22: meters
B23: ='EXPEDITION CONSOLIDATION'!B24:D24 -> MS 12 | H23: meters | K23: =G23 -> 0 | L23: meters | O23: =G23 -> 0 | P23: meters
B24: ='EXPEDITION CONSOLIDATION'!B25:D25 -> MS 18 | H24: meters | K24: =G24 -> 0 | L24: meters | O24: =G24 -> 0 | P24: meters
B25: ='EXPEDITION CONSOLIDATION'!B26:D26 -> Fuse Lighter | H25: pcs | K25: =G25 -> 0 | L25: pcs | O25: =G25 -> 0 | P25: pcs
B26: ='EXPEDITION CONSOLIDATION'!B27:D27 -> BILL WIRE | H26: pcs | K26: =G26 -> 0 | L26: pcs | O26: =G26 -> 0 | P26: pcs
B27: ='EXPEDITION CONSOLIDATION'!B28:D28 -> EBC | G27: 2 | H27: pcs | K27: =G27 -> 2 | L27: pcs | O27: =G27 -> 2 | P27: pcs
A29: II. | B29: CHARGED DRILL HOLES
C30: (a) | D30: PRIMARY: | E30: 47 | G30: No. of holes: | J30: =G17+G18-J31+G19 -> 1266 | M30: Depth: | N30: 5'X11"
C31: (b) | D31: SECONDARY: | E31: 3 | G31: No. of holes: | J31: =7+8+4 -> 19 | M31: Depth: | N31: 3X'11"
A33: III. | B33: ESTIMATED TONNAGE OF BLASTED MATERIAL
B34: REMARKS:
A39: EXPEDITION DRILLING AND BLASTING, INC.
A40: PHILSAGA MINING CORPORATION (OPERATION)
A41: Bayugan 3, Rosario Agusan del Sur
A43: DAILY BLASTER REPORT
A44: Location | C44: : | D44: MINE SITE, CO-O, CONSUELO, BUNAWAN , AGUSAN DEL SUR | M44: Date:
A45: Time of Blasting | C45: : | D45: 6:45 AM / 2:45 PM / 10:45 PM | M45: Shift: | N45: 1ST SHIFT/2ND SHIFT/3RD SHIFT
A47: I. | B47: EXPLOSIVE USED | F47: REQUISITIONED | J47: CONSUMED | N47: REQUIRED
F48: (KLS) | G48: (PCS) | J48: (KLS) | K48: (PCS) | N48: (KLS) | O48: (PCS)
B49: ='EXPEDITION CONSOLIDATION'!B12:D12 -> Emulison Senatel Pulsar 38 | F49: =G49/38*25 -> 0 | H49: pcs | J49: =F49 -> 0 | K49: =G49 -> 0 | L49: pcs | N49: =F49 -> 0 | O49: =G49 -> 0 | P49: pcs
B50: ='EXPEDITION CONSOLIDATION'!B13:D13 -> Emulison Senatel Pulsar 135 | F50: =G50/135*25 -> 0 | H50: pcs | J50: =F50 -> 0 | K50: =G50 -> 0 | L50: pcs | N50: =F50 -> 0 | O50: =G50 -> 0 | P50: pcs
...

Sheet 4
A1: EXPEDITION DRILLING AND BLASTING, INC.
A2: PHILSAGA MINING CORPORATION (OPERATION)
A3: Bayugan 3, Rosario Agusan del Sur
A5: DAILY BLASTER REPORT
A6: Location | C6: : | D6: MINE SITE, CO-O, CONSUELO, BUNAWAN , AGUSAN DEL SUR | M6: Date: | N6: 0
A7: Time of Blasting | C7: : | D7: 6:45 AM / 2:45 PM / 10:45 PM | M7: Shift: | N7: 1ST SHIFT/2ND SHIFT/3RD SHIFT
A9: I. | B9: EXPLOSIVE USED | F9: REQUISITIONED | J9: CONSUMED | N9: REQUIRED
F10: (KLS) | G10: (PCS) | J10: (KLS) | K10: (PCS) | N10: (KLS) | O10: (PCS)
B11: ='EXPEDITION CONSOLIDATION'!B12:D12 -> Emulison Senatel Pulsar 38 | F11: =G11/38*25 -> 0 | H11: pcs | J11: =F11 -> 0 | K11: =G11 -> 0 | L11: pcs | N11: =F11 -> 0 | O11: =G11 -> 0 | P11: pcs
B12: ='EXPEDITION CONSOLIDATION'!B13:D13 -> Emulison Senatel Pulsar 135 | F12: =G12/135*25 -> 0 | H12: pcs | J12: =F12 -> 0 | K12: =G12 -> 0 | L12: pcs | N12: =F12 -> 0 | O12: =G12 -> 0 | P12: pcs
B13: ='EXPEDITION CONSOLIDATION'!B14:D14 -> Emulsion Senatel Pulsar 215 P | F13: =G13/215*25 -> 0 | H13: pcs | J13: =F13 -> 0 | K13: =G13 -> 0 | L13: pcs | N13: =F13 -> 0 | O13: =G13 -> 0 | P13: pcs
B14: ='EXPEDITION CONSOLIDATION'!B15:D15 -> Anfo | J14: =F14 -> 0 | N14: =F14 -> 0
B15: ='EXPEDITION CONSOLIDATION'!B16:D16 -> OBC | H15: pcs | K15: =G15 -> 0 | L15: pcs | O15: =G15 -> 0 | P15: pcs
B16: ='EXPEDITION CONSOLIDATION'!B17:D17 -> Safety Fuse | G16: =G15*2.43 -> 0 | H16: meters | K16: =G16 -> 0 | L16: meters | O16: =G16 -> 0 | P16: meters
B17: ='EXPEDITION CONSOLIDATION'!B18:D18 -> EXEL Detonator (3.6) | H17: pcs | K17: =G17 -> 0 | L17: pcs | O17: =G17 -> 0 | P17: pcs
B18: ='EXPEDITION CONSOLIDATION'!B19:D19 -> EXEL Detonator (2.4) | H18: pcs | K18: =G18 -> 0 | L18: pcs | O18: =G18 -> 0 | P18: pcs
B19: ='EXPEDITION CONSOLIDATION'!B20:D20 -> EXEL Detonator (4.9) | H19: pcs | K19: =G19 -> 0 | L19: pcs | O19: =G19 -> 0 | P19: pcs
B20: ='EXPEDITION CONSOLIDATION'!B21:D21 -> Cordtex (Detonating Cord) 5 | H20: meters | K20: =G20 -> 0 | L20: meters | O20: =G20 -> 0 | P20: meters
B21: ='EXPEDITION CONSOLIDATION'!B22:D22 -> Cordtex (DCORD I) 5 | H21: meters | K21: =G21 -> 0 | L21: meters | O21: =G21 -> 0 | P21: meters
B22: ='EXPEDITION CONSOLIDATION'!B23:D23 -> Cordtex (Detonating Cord) 40 | H22: meters | K22: =G22 -> 0 | L22: meters | O22: =G22 -> 0 | P22: meters
B23: ='EXPEDITION CONSOLIDATION'!B24:D24 -> MS 12 | H23: meters | K23: =G23 -> 0 | L23: meters | O23: =G23 -> 0 | P23: meters
B24: ='EXPEDITION CONSOLIDATION'!B25:D25 -> MS 18 | H24: meters | K24: =G24 -> 0 | L24: meters | O24: =G24 -> 0 | P24: meters
B25: ='EXPEDITION CONSOLIDATION'!B26:D26 -> Fuse Lighter | H25: pcs | K25: =G25 -> 0 | L25: pcs | O25: =G25 -> 0 | P25: pcs
B26: ='EXPEDITION CONSOLIDATION'!B27:D27 -> BILL WIRE | H26: pcs | K26: =G26 -> 0 | L26: pcs | O26: =G26 -> 0 | P26: pcs
B27: ='EXPEDITION CONSOLIDATION'!B28:D28 -> EBC | H27: pcs | K27: =G27 -> 0 | L27: pcs | O27: =G27 -> 0 | P27: pcs
A29: II. | B29: CHARGED DRILL HOLES
C30: (a) | D30: PRIMARY: | E30: 0 | G30: No. of holes: | J30: =G17+G18-J31+G19 -> 0 | M30: Depth: | N30: 5'X11"
C31: (b) | D31: SECONDARY: | E31: 0 | G31: No. of holes: | J31: 0 | M31: Depth: | N31: 3X'11"
A33: III. | B33: ESTIMATED TONNAGE OF BLASTED MATERIAL
B34: REMARKS:
A39: EXPEDITION DRILLING AND BLASTING, INC.
A40: PHILSAGA MINING CORPORATION (OPERATION)
A41: Bayugan 3, Rosario Agusan del Sur
A43: DAILY BLASTER REPORT
A44: Location | C44: : | D44: MINE SITE, CO-O, CONSUELO, BUNAWAN , AGUSAN DEL SUR | M44: Date: | N44: 0
A45: Time of Blasting | C45: : | D45: 6:45 AM / 2:45 PM / 10:45 PM | M45: Shift: | N45: 1ST SHIFT/2ND SHIFT/3RD SHIFT
A47: I. | B47: EXPLOSIVE USED | F47: REQUISITIONED | J47: CONSUMED | N47: REQUIRED
F48: (KLS) | G48: (PCS) | J48: (KLS) | K48: (PCS) | N48: (KLS) | O48: (PCS)
B49: ='EXPEDITION CONSOLIDATION'!B12:D12 -> Emulison Senatel Pulsar 38 | F49: =G49/38*25 -> 0 | H49: pcs | J49: =F49 -> 0 | K49: =G49 -> 0 | L49: pcs | N49: =F49 -> 0 | O49: =G49 -> 0 | P49: pcs
B50: ='EXPEDITION CONSOLIDATION'!B13:D13 -> Emulison Senatel Pulsar 135 | F50: =G50/135*25 -> 0 | H50: pcs | J50: =F50 -> 0 | K50: =G50 -> 0 | L50: pcs | N50: =F50 -> 0 | O50: =G50 -> 0 | P50: pcs
...

Sheet MT.ROCK CONSOLIDATION
A1: MT. ROCK POWDER CORPORATION
A2: PHILSAGA MINING CORPORATION (OPERATION)
A3: Bayugan 3, Rosario Agusan del Sur
A5: DAILY CONSOLIDATION BLASTER REPORT
A6: ='EXPEDITION CONSOLIDATION'!A6:P6 -> FOR JUNE 1-7, 2026
A8: Location | C8: : | D8: MINE SITE, CO-O, CONSUELO, BUNAWAN , AGUSAN DEL SUR
A10: I. | B10: EXPLOSIVE USED | F10: REQUISITIONED | J10: CONSUMED | N10: REQUIRED
F11: (KLS) | G11: (PCS) | J11: (KLS) | K11: (PCS) | N11: (KLS) | O11: (PCS)
B12: Emulsion Super Power 208 | F12: =G12/208*25 -> 0 | G12: ='1-2.'!G11+'1-2.'!G47+'3-4.'!G12+'3-4.'!G48+'5-6.'!G11+'5-6.'!G47+'7'!G11+'7'!G47+'12'!G11+'12'!G44+'13'!G11+'13'!G44+'14'!G11+'14'!G45 -> 0 | H12: pcs | J12: =F12 -> 0 | K12: =G12 -> 0 | L12: pcs | N12: =F12 -> 0 | O12: =G12 -> 0 | P12: pcs
B13: NEOGEL 200 | F13: =G13/200*25 -> 1383.25 | G13: ='1-2.'!G12+'1-2.'!G48+'3-4.'!G13+'3-4.'!G49+'5-6.'!G12+'5-6.'!G48+'7'!G12+'7'!G48+'12'!G12+'12'!G45+'13'!G12+'13'!G45+'14'!G12+'14'!G46 -> 11066 | H13: pcs | J13: =F13 -> 1383.25 | K13: =G13 -> 11066 | L13: pcs | N13: =F13 -> 1383.25 | O13: =G13 -> 11066 | P13: pcs
B14: Anfo | F14: ='1-2.'!F13+'1-2.'!F49+'3-4.'!F14+'3-4.'!F50+'5-6.'!F13+'5-6.'!F49+'7'!F13+'7'!F49+'12'!F13+'12'!F46+'13'!F13+'13'!F46+'14'!F13+'14'!F47 -> 0 | J14: =F14 -> 0 | N14: =F14 -> 0
B15: OBC | G15: ='1-2.'!G14+'1-2.'!G50+'3-4.'!G15+'3-4.'!G51+'5-6.'!G14+'5-6.'!G50+'7'!G14+'7'!G50+'12'!G14+'12'!G47+'13'!G14+'13'!G47+'14'!G14+'14'!G48 -> 632 | H15: pcs | K15: =G15 -> 632 | L15: pcs | O15: =G15 -> 632 | P15: pcs
B16: Safety Fuse | G16: ='1-2.'!G15+'1-2.'!G51+'3-4.'!G16+'3-4.'!G52+'5-6.'!G15+'5-6.'!G51+'7'!G15+'7'!G51+'12'!G15+'12'!G48+'13'!G15+'13'!G48+'14'!G15+'14'!G49 -> 1535.76 | H16: mtrs | K16: =G16 -> 1535.76 | L16: mtrs | O16: =G16 -> 1535.76 | P16: mtrs
B17: SHOCKSTAR Detonator 2.4 | G17: ='1-2.'!G16+'1-2.'!G52+'3-4.'!G17+'3-4.'!G53+'5-6.'!G16+'5-6.'!G52+'7'!G16+'7'!G51+'12'!G15+'12'!G48+'13'!G15+'13'!G48+'14'!G15+'14'!G49 -> 0 | H17: pcs | K17: =G17 -> 0 | L17: pcs | O17: =G17 -> 0 | P17: pcs
B18: SUPREME Detonator 2.4 | G18: ='1-2.'!G17+'1-2.'!G53+'3-4.'!G18+'3-4.'!G54+'5-6.'!G17+'5-6.'!G53+'7'!G17+'7'!G53+'12'!G16+'12'!G49+'13'!G16+'13'!G49+'14'!G16+'14'!G50 -> 0 | H18: pcs | K18: =G18 -> 0 | L18: pcs | O18: =G18 -> 0 | P18: pcs
B19: SUPREME Detonator 3.6 | G19: ='1-2.'!G18+'1-2.'!G54+'3-4.'!G19+'3-4.'!G55+'5-6.'!G18+'5-6.'!G54+'7'!G18+'7'!G54+'12'!G17+'12'!G50+'13'!G17+'13'!G50+'14'!G17+'14'!G51 -> 0 | H19: pcs | K19: =G19 -> 0 | L19: pcs | O19: =G19 -> 0 | P19: pcs
B20: NONEL Detonator 2.4 | G20: ='1-2.'!G19+'1-2.'!G55+'3-4.'!G20+'3-4.'!G56+'5-6.'!G19+'5-6.'!G55+'7'!G19+'7'!G55+'12'!G18+'12'!G51+'13'!G18+'13'!G51+'14'!G18+'14'!G52 -> 0 | H20: pcs | K20: =G20 -> 0 | L20: pcs | O20: 0 | P20: pcs
B21: NONEL Detonator 3.6 | G21: ='1-2.'!G20+'1-2.'!G56+'3-4.'!G21+'3-4.'!G57+'5-6.'!G20+'5-6.'!G56+'7'!G20+'7'!G56+'12'!G19+'12'!G52+'13'!G19+'13'!G52+'14'!G19+'14'!G53 -> 0 | H21: pcs | K21: =G21 -> 0 | L21: pcs | O21: =G21 -> 0 | P21: pcs
B22: Solar Detonating Cord 6 | G22: ='1-2.'!G21+'1-2.'!G57+'3-4.'!G22+'3-4.'!G58+'5-6.'!G21+'5-6.'!G57+'7'!G21+'7'!G57+'12'!G20+'12'!G53+'13'!G20+'13'!G53+'14'!G20+'14'!G54 -> 0 | H22: mtrs | K22: =G22 -> 0 | L22: mtrs | O22: =G22 -> 0 | P22: mtrs
B23: Solar Detonating Cord 10 | G23: ='1-2.'!G22+'1-2.'!G58+'3-4.'!G23+'3-4.'!G59+'5-6.'!G22+'5-6.'!G58+'7'!G22+'7'!G58+'12'!G21+'12'!G54+'13'!G21+'13'!G54+'14'!G21+'14'!G55 -> 2928 | H23: mtrs | K23: =G23 -> 2928 | L23: mtrs | O23: =G23 -> 2928 | P23: mtrs
B24: Solar Detonating Cord 40 | G24: ='1-2.'!G23+'1-2.'!G59+'3-4.'!G24+'3-4.'!G60+'5-6.'!G23+'5-6.'!G59+'7'!G23+'7'!G59+'12'!G22+'12'!G55+'13'!G22+'13'!G55+'14'!G22+'14'!G56 -> 0 | H24: mtrs | K24: =G24 -> 0 | L24: mtrs | O24: =G24 -> 0 | P24: mtrs
B25: Fuse Lighter | G25: ='1-2.'!G24+'1-2.'!G60+'3-4.'!G25+'3-4.'!G61+'5-6.'!G24+'5-6.'!G60+'7'!G24+'7'!G60+'12'!G23+'12'!G56+'13'!G23+'13'!G56+'14'!G23+'14'!G57 -> 0 | H25: pcs | K25: =G25 -> 0 | L25: pcs | O25: =G25 -> 0 | P25: pcs
B26: BILL WIRE | G26: ='1-2.'!G25+'1-2.'!G61+'3-4.'!G26+'3-4.'!G62+'5-6.'!G25+'5-6.'!G61+'7'!G25+'7'!G61+'12'!G24+'12'!G57+'13'!G24+'13'!G57+'14'!G24+'14'!G58 -> 0 | H26: mtrs | K26: =G26 -> 0 | L26: mtrs | O26: =G26 -> 0 | P26: mtrs
B27: Solar EBC | G27: ='1-2.'!G26+'1-2.'!G62+'3-4.'!G27+'3-4.'!G63+'5-6.'!G26+'5-6.'!G62+'7'!G26+'7'!G62+'12'!G25+'12'!G58+'13'!G25+'13'!G58+'14'!G25+'14'!G59 -> 0 | H27: pcs | K27: =G27 -> 0 | L27: pcs | O27: =G27 -> 0 | P27: pcs
A29: II. | B29: CHARGED DRILL HOLES
C30: (a) | D30: PRIMARY: | E30: ='1-2.'!E29:F29+'1-2.'!E65:F65+'3-4.'!E30:F30+'3-4.'!E66:F66+'5-6.'!E29:F29+'5-6.'!E65:F65+'7'!E29:F29+'7'!E65:F65+'12'!E28:F28+'12'!E61:F61+'13'!E28:F28+'13'!E61:F61+'14'!E28:F28+'14'!E62:F62 -> 0 | G30: No. of holes: | J30: ='1-2.'!J29:K29+'1-2.'!J65:K65+'3-4.'!J30:K30+'3-4.'!J66:K66+'5-6.'!J29:K29+'5-6.'!J65:K65+'7'!J29:K29+'7'!J65:K65+'12'!J28:K28+'12'!J61:K61+'13'!J28:K28+'13'!J61:K61+'14'!J28:K28+'14'!J62:K62 -> 0 | L30: Depth: | N30: 5'X11" | T30: =J30+J31 -> 0
C31: (b) | D31: SECONDARY: | E31: ='1-2.'!E30:F30+'1-2.'!E66:F66+'3-4.'!E31:F31+'3-4.'!E67:F67+'5-6.'!E30:F30+'5-6.'!E66:F66+'7'!E30:F30+'7'!E66:F66+'12'!E29:F29+'12'!E62:F62+'13'!E29:F29+'13'!E62:F62+'14'!E29:F29+'14'!E63:F63 -> 0 | G31: No. of holes: | J31: ='1-2.'!J30:K30+'1-2.'!J66:K66+'3-4.'!J31:K31+'3-4.'!J67:K67+'5-6.'!J30:K30+'5-6.'!J66:K66+'7'!J30:K30+'7'!J66:K66+'12'!J29:K29+'12'!J62:K62+'13'!J29:K29+'13'!J62:K62+'14'!J29:K29+'14'!J63:K63 -> 0 | L31: Depth: | N31: 3X'11"
A33: III. | B33: ESTIMATED TONNAGE OF BLASTED MATERIAL
B34: REMARKS:
A37: Prepared by: | F37: Witnessed and Checked by: | L37: Reviewed by:
A39: JOHNNY U GALENG | F39: PEMS VER M JULAO | L39: RAFFY D TORRES
A40: LICENSED BLASTER | F40: PNP - PPO AGUSAN DEL SUR REPRESENTATIVE | L40: MINE EXPLOSIVES MANAGER
A41: FPDJ10-111022-0847
A44: Noted by:
A47: ENGR EARL M SON
A48: MINE DIVISION MANAGER

Sheet 8
A1: EXPEDITION DRILLING AND BLASTING, INC.
A2: PHILSAGA MINING CORPORATION (OPERATION)
A3: Bayugan 3, Rosario Agusan del Sur
A5: DAILY BLASTER REPORT
A6: Location | C6: : | D6: MINE SITE, CO-O, CONSUELO, BUNAWAN , AGUSAN DEL SUR | M6: Date: | N6: 0
A7: Time of Blasting | C7: : | D7: 6:45 AM / 2:45 PM / 10:45 PM | M7: Shift: | N7: 1ST SHIFT/2ND SHIFT/3RD SHIFT
A9: I. | B9: EXPLOSIVE USED | F9: REQUISITIONED | J9: CONSUMED | N9: REQUIRED
F10: (KLS) | G10: (PCS) | J10: (KLS) | K10: (PCS) | N10: (KLS) | O10: (PCS)
B11: Emulsion Senatel Pulsar 38 | F11: =G11/200*25 -> 0 | H11: pcs | J11: =F11 -> 0 | K11: =G11 -> 0 | L11: pcs | N11: =F11 -> 0 | O11: =G11 -> 0 | P11: pcs
B12: Emulison Senatel Pulsar 135 | F12: =G12/150*25 -> 0 | H12: pcs | J12: =F12 -> 0 | K12: =G12 -> 0 | L12: pcs | N12: =F12 -> 0 | O12: =G12 -> 0 | P12: pcs
B13: Emulsion Senatel Pulsar 215 P | F13: =G13/215*25 -> 0 | H13: pcs | J13: =F13 -> 0 | K13: =G13 -> 0 | L13: pcs | N13: =F13 -> 0 | O13: =G13 -> 0 | P13: pcs
B14: Anfo | J14: =F14 -> 0 | N14: =F14 -> 0
B15: OBC | H15: pcs | K15: =G15 -> 0 | L15: pcs | O15: =G15 -> 0 | P15: pcs
B16: Safety Fuse | G16: =G15*2.43 -> 0 | H16: meters | K16: =G16 -> 0 | L16: meters | O16: =G16 -> 0 | P16: meters
B17: EXEL Detonator (3.6) | H17: pcs | K17: =G17 -> 0 | L17: pcs | O17: =G17 -> 0 | P17: pcs
B18: EXEL Detonator (2.4) | H18: pcs | K18: =G18 -> 0 | L18: pcs | O18: =G18 -> 0 | P18: pcs
B19: EXEL Detonator (4.9) | H19: pcs | K19: =G19 -> 0 | L19: pcs | O19: =G19 -> 0 | P19: pcs
B20: Cordtex (Detonating Cord) 5 | H20: meters | K20: =G20 -> 0 | L20: meters | O20: =G20 -> 0 | P20: meters
B21: Cordtex (Detonating Cord) 6 | H21: meters | K21: =G21 -> 0 | L21: meters | O21: =G21 -> 0 | P21: meters
B22: Cordtex (Detonating Cord) 10 | H22: meters | K22: =G22 -> 0 | L22: meters | O22: =G22 -> 0 | P22: meters
B23: Cordtex (Detonating Cord) 40 | H23: meters | K23: =G23 -> 0 | L23: meters | O23: =G23 -> 0 | P23: meters
B24: MS 12 | H24: meters | K24: =G24 -> 0 | L24: meters | O24: =G24 -> 0 | P24: meters
B25: MS 18 | H25: meters | K25: =G25 -> 0 | L25: meters | O25: =G25 -> 0 | P25: meters
B26: Fuse Lighter | H26: pcs | K26: =G26 -> 0 | L26: pcs | O26: =G26 -> 0 | P26: pcs
B27: BILL WIRE | H27: pcs | K27: =G27 -> 0 | L27: pcs | O27: =G27 -> 0 | P27: pcs
B28: EBC | H28: pcs | K28: =G28 -> 0 | L28: pcs | O28: =G28 -> 0 | P28: pcs
A30: II. | B30: CHARGED DRILL HOLES
C31: (a) | D31: PRIMARY: | G31: No. of holes: | J31: =G17+G18-J32 -> 0 | M31: Depth: | N31: 5'X11"
C32: (b) | D32: SECONDARY: | G32: No. of holes: | M32: Depth: | N32: 3X'11"
A34: III. | B34: ESTIMATED TONNAGE OF BLASTED MATERIAL
B35: REMARKS:
A40: EXPEDITION DRILLING AND BLASTING, INC.
A41: PHILSAGA MINING CORPORATION (OPERATION)
A42: Bayugan 3, Rosario Agusan del Sur
A44: DAILY BLASTER REPORT
A45: Location | C45: : | D45: MINE SITE, CO-O, CONSUELO, BUNAWAN , AGUSAN DEL SUR | M45: Date: | N45: 0
A46: Time of Blasting | C46: : | D46: 6:45 AM / 2:45 PM / 10:45 PM | M46: Shift: | N46: 1ST SHIFT/2ND SHIFT/3RD SHIFT
A48: I. | B48: EXPLOSIVE USED | F48: REQUISITIONED | J48: CONSUMED | N48: REQUIRED
F49: (KLS) | G49: (PCS) | J49: (KLS) | K49: (PCS) | N49: (KLS) | O49: (PCS)
B50: Emulsion Superdyne 200 | F50: =G50/200*25 -> 0 | H50: pcs | J50: =F50 -> 0 | K50: =G50 -> 0 | L50: pcs | N50: =F50 -> 0 | O50: =G50 -> 0 | P50: pcs
...

Sheet 9
A1: EXPEDITION DRILLING AND BLASTING, INC.
A2: PHILSAGA MINING CORPORATION (OPERATION)
A3: Bayugan 3, Rosario Agusan del Sur
A5: DAILY BLASTER REPORT
A6: Location | C6: : | D6: MINE SITE, CO-O, CONSUELO, BUNAWAN , AGUSAN DEL SUR | M6: Date: | N6: 0
A7: Time of Blasting | C7: : | D7: 6:45 AM / 2:45 PM / 10:45 PM | M7: Shift: | N7: 1ST SHIFT/2ND SHIFT/3RD SHIFT
A9: I. | B9: EXPLOSIVE USED | F9: REQUISITIONED | J9: CONSUMED | N9: REQUIRED
F10: (KLS) | G10: (PCS) | J10: (KLS) | K10: (PCS) | N10: (KLS) | O10: (PCS)
B11: Emulsion Senatel Pulsar 38 | F11: =G11/200*25 -> 0 | H11: pcs | J11: =F11 -> 0 | K11: =G11 -> 0 | L11: pcs | N11: =F11 -> 0 | O11: =G11 -> 0 | P11: pcs
B12: Emulison Senatel Pulsar 135 | F12: =G12/150*25 -> 0 | H12: pcs | J12: =F12 -> 0 | K12: =G12 -> 0 | L12: pcs | N12: =F12 -> 0 | O12: =G12 -> 0 | P12: pcs
B13: Emulsion Senatel Pulsar 215 P | F13: =G13/215*25 -> 0 | H13: pcs | J13: =F13 -> 0 | K13: =G13 -> 0 | L13: pcs | N13: =F13 -> 0 | O13: =G13 -> 0 | P13: pcs
B14: Anfo | J14: =F14 -> 0 | N14: =F14 -> 0
B15: OBC | H15: pcs | K15: =G15 -> 0 | L15: pcs | O15: =G15 -> 0 | P15: pcs
B16: Safety Fuse | G16: =G15*2.43 -> 0 | H16: meters | K16: =G16 -> 0 | L16: meters | O16: =G16 -> 0 | P16: meters
B17: EXEL Detonator (3.6) | H17: pcs | K17: =G17 -> 0 | L17: pcs | O17: =G17 -> 0 | P17: pcs
B18: EXEL Detonator (2.4) | H18: pcs | K18: =G18 -> 0 | L18: pcs | O18: =G18 -> 0 | P18: pcs
B19: EXEL Detonator (4.9) | K19: =G19 -> 0 | L19: pcs | O19: =G19 -> 0 | P19: pcs
B20: Cordtex (Detonating Cord) 5 | H20: meters | K20: =G20 -> 0 | L20: meters | O20: =G20 -> 0 | P20: meters
B21: Cordtex (Detonating Cord) 6 | H21: meters | K21: =G21 -> 0 | L21: meters | O21: =G21 -> 0 | P21: meters
B22: Cordtex (Detonating Cord) 10 | H22: meters | K22: =G22 -> 0 | L22: meters | O22: =G22 -> 0 | P22: meters
B23: Cordtex (Detonating Cord) 40 | H23: meters | K23: =G23 -> 0 | L23: meters | O23: =G23 -> 0 | P23: meters
B24: MS 12 | H24: meters | K24: 0 | L24: meters | O24: 0 | P24: meters
B25: MS 18 | H25: meters | K25: 0 | L25: meters | O25: 0 | P25: meters
B26: Fuse Lighter | H26: pcs | K26: =G26 -> 0 | L26: pcs | O26: =G26 -> 0 | P26: pcs
B27: BILL WIRE | H27: pcs | K27: =G27 -> 0 | L27: pcs | O27: =G27 -> 0 | P27: pcs
B28: EBC | H28: pcs | K28: =G28 -> 0 | L28: pcs | O28: =G28 -> 0 | P28: pcs
A30: II. | B30: CHARGED DRILL HOLES
C31: (a) | D31: PRIMARY: | G31: No. of holes: | J31: =G17+G18-J32 -> 0 | M31: Depth: | N31: 5'X11"
C32: (b) | D32: SECONDARY: | G32: No. of holes: | M32: Depth: | N32: 3X'11"
A34: III. | B34: ESTIMATED TONNAGE OF BLASTED MATERIAL
B35: REMARKS:
A39: EXPEDITION DRILLING AND BLASTING, INC.
A40: PHILSAGA MINING CORPORATION (OPERATION)
A41: Bayugan 3, Rosario Agusan del Sur
A43: DAILY BLASTER REPORT
A44: Location | C44: : | D44: MINE SITE, CO-O, CONSUELO, BUNAWAN , AGUSAN DEL SUR | M44: Date: | N44: 0
A45: Time of Blasting | C45: : | D45: 6:45 AM / 2:45 PM / 10:45 PM | M45: Shift: | N45: 1ST SHIFT/2ND SHIFT/3RD SHIFT
A47: I. | B47: EXPLOSIVE USED | F47: REQUISITIONED | J47: CONSUMED | N47: REQUIRED
F48: (KLS) | G48: (PCS) | J48: (KLS) | K48: (PCS) | N48: (KLS) | O48: (PCS)
B49: Emulsion Superdyne 200 | F49: =G49/200*25 -> 0 | H49: pcs | J49: =F49 -> 0 | K49: =G49 -> 0 | L49: pcs | N49: =F49 -> 0 | O49: =G49 -> 0 | P49: pcs
...

Sheet 10
A1: EXPEDITION DRILLING AND BLASTING, INC.
A2: PHILSAGA MINING CORPORATION (OPERATION)
A3: Bayugan 3, Rosario Agusan del Sur
A5: DAILY BLASTER REPORT
A6: Location | C6: : | D6: MINE SITE, CO-O, CONSUELO, BUNAWAN , AGUSAN DEL SUR | M6: Date: | N6: 0
A7: Time of Blasting | C7: : | D7: 6:45 AM / 2:45 PM / 10:45 PM | M7: Shift: | N7: 1ST SHIFT/2ND SHIFT/3RD SHIFT
A9: I. | B9: EXPLOSIVE USED | F9: REQUISITIONED | J9: CONSUMED | N9: REQUIRED
F10: (KLS) | G10: (PCS) | J10: (KLS) | K10: (PCS) | N10: (KLS) | O10: (PCS)
B11: Emulsion Superdyne 200 | F11: =G11/200*25 -> 0 | H11: pcs | J11: =F11 -> 0 | K11: =G11 -> 0 | L11: pcs | N11: =F11 -> 0 | O11: =G11 -> 0 | P11: pcs
B12: Emulison Senatel Pulsar 135 | F12: =G12/150*25 -> 0 | H12: pcs | J12: =F12 -> 0 | K12: =G12 -> 0 | L12: pcs | N12: =F12 -> 0 | O12: =G12 -> 0 | P12: pcs
B13: Emulsion Senatel Pulsar 215 P | F13: =G13/215*25 -> 0 | H13: pcs | J13: =F13 -> 0 | K13: =G13 -> 0 | L13: pcs | N13: =F13 -> 0 | O13: =G13 -> 0 | P13: pcs
B14: Anfo | J14: =F14 -> 0 | N14: =F14 -> 0
B15: OBC | H15: pcs | K15: =G15 -> 0 | L15: pcs | O15: =G15 -> 0 | P15: pcs
B16: Safety Fuse | G16: =G15*2.43 -> 0 | H16: meters | K16: =G16 -> 0 | L16: meters | O16: =G16 -> 0 | P16: meters
B17: EXEL Detonator (3.6) | H17: pcs | K17: =G17 -> 0 | L17: pcs | O17: =G17 -> 0 | P17: pcs
B18: EXEL Detonator (2.4) | H18: pcs | K18: =G18 -> 0 | L18: pcs | O18: =G18 -> 0 | P18: pcs
B19: Cordtex (Detonating Cord) 5 | H19: meters | K19: =G19 -> 0 | L19: meters | O19: =G19 -> 0 | P19: meters
B20: Cordtex (Detonating Cord) 6 | H20: meters | K20: =G20 -> 0 | L20: meters | O20: =G20 -> 0 | P20: meters
B21: Cordtex (Detonating Cord) 10 | H21: meters | K21: =G21 -> 0 | L21: meters | O21: =G21 -> 0 | P21: meters
B22: Cordtex (Detonating Cord) 40 | H22: meters | K22: =G22 -> 0 | L22: meters | O22: =G22 -> 0 | P22: meters
B23: MS 12 | H23: meters | K23: 0 | L23: meters | O23: 0 | P23: meters
B24: MS 18 | H24: meters | K24: 0 | L24: meters | O24: 0 | P24: meters
B25: Fuse Lighter | H25: pcs | K25: =G25 -> 0 | L25: pcs | O25: =G25 -> 0 | P25: pcs
B26: BILL WIRE | H26: pcs | K26: =G26 -> 0 | L26: pcs | O26: =G26 -> 0 | P26: pcs
B27: EBC | H27: pcs | K27: =G27 -> 0 | L27: pcs | O27: =G27 -> 0 | P27: pcs
A29: II. | B29: CHARGED DRILL HOLES
C30: (a) | D30: PRIMARY: | G30: No. of holes: | J30: =G17+G18-J31 -> 0 | M30: Depth: | N30: 5'X11"
C31: (b) | D31: SECONDARY: | G31: No. of holes: | M31: Depth: | N31: 3X'11"
A33: III. | B33: ESTIMATED TONNAGE OF BLASTED MATERIAL
B34: REMARKS:
A39: EXPEDITION DRILLING AND BLASTING, INC.
A40: PHILSAGA MINING CORPORATION (OPERATION)
A41: Bayugan 3, Rosario Agusan del Sur
A43: DAILY BLASTER REPORT
A44: Location | C44: : | D44: MINE SITE, CO-O, CONSUELO, BUNAWAN , AGUSAN DEL SUR | M44: Date: | N44: 0
A45: Time of Blasting | C45: : | D45: 6:45 AM / 2:45 PM / 10:45 PM | M45: Shift: | N45: 1ST SHIFT/2ND SHIFT/3RD SHIFT
A47: I. | B47: EXPLOSIVE USED | F47: REQUISITIONED | J47: CONSUMED | N47: REQUIRED
F48: (KLS) | G48: (PCS) | J48: (KLS) | K48: (PCS) | N48: (KLS) | O48: (PCS)
B49: Emulsion Superdyne 200 | F49: =G49/200*25 -> 0 | H49: pcs | J49: =F49 -> 0 | K49: =G49 -> 0 | L49: pcs | N49: =F49 -> 0 | O49: =G49 -> 0 | P49: pcs
B50: Emulsion Diagel 150 P | F50: =G50/150*25 -> 0 | H50: pcs | J50: =F50 -> 0 | K50: =G50 -> 0 | L50: pcs | N50: =F50 -> 0 | O50: =G50 -> 0 | P50: pcs
...

Sheet 1-2.
A1: MT. ROCK POWDER CORPORATION
A2: PHILSAGA MINING CORPORATION (OPERATION)
A3: Bayugan 3, Rosario Agusan del Sur
A5: DAILY BLASTER REPORT
A6: Location | C6: : | D6: MINE SITE, CO-O, CONSUELO, BUNAWAN , AGUSAN DEL SUR | M6: Date: | N6: ='1-2'!N6 -> 46174
A7: Time of Blasting | C7: : | D7: 6:45 AM / 2:45 PM / 10:45 PM | M7: Shift: | N7: 1ST SHIFT/2ND SHIFT/3RD SHIFT
A9: I. | B9: EXPLOSIVE USED | F9: REQUISITIONED | J9: CONSUMED | N9: REQUIRED
F10: (KLS) | G10: (PCS) | J10: (KLS) | K10: (PCS) | N10: (KLS) | O10: (PCS)
B11: ='MT.ROCK CONSOLIDATION'!B12:D12 -> Emulsion Super Power 208 | F11: =G11/208*25 -> 0 | H11: pcs | J11: =F11 -> 0 | K11: =G11 -> 0 | L11: pcs | N11: =F11 -> 0 | O11: =G11 -> 0 | P11: pcs
B12: ='MT.ROCK CONSOLIDATION'!B13:D13 -> NEOGEL 200 | F12: =G12/200*25 -> 166.5 | G12: 1332 | H12: pcs | J12: =F12 -> 166.5 | K12: =G12 -> 1332 | L12: pcs | N12: =F12 -> 166.5 | O12: =G12 -> 1332 | P12: pcs
B13: ='MT.ROCK CONSOLIDATION'!B14:D14 -> Anfo | F13: 0 | J13: =F13 -> 0 | N13: =F13 -> 0
B14: ='MT.ROCK CONSOLIDATION'!B15:D15 -> OBC | G14: 79 | H14: pcs | K14: =G14 -> 79 | L14: pcs | O14: =G14 -> 79 | P14: pcs
B15: ='MT.ROCK CONSOLIDATION'!B16:D16 -> Safety Fuse | G15: =G14*2.43 -> 191.97 | H15: meters | K15: =G15 -> 191.97 | L15: meters | O15: =G15 -> 191.97 | P15: meters
B16: ='MT.ROCK CONSOLIDATION'!B17:D17 -> SHOCKSTAR Detonator 2.4 | H16: pcs | K16: =G16 -> 0 | L16: pcs | O16: =G16 -> 0 | P16: pcs
B17: ='MT.ROCK CONSOLIDATION'!B18:D18 -> SUPREME Detonator 2.4 | H17: pcs | K17: =G17 -> 0 | L17: pcs | O17: =G17 -> 0 | P17: pcs
B18: ='MT.ROCK CONSOLIDATION'!B19:D19 -> SUPREME Detonator 3.6 | H18: pcs | K18: =G18 -> 0 | L18: pcs | O18: =G18 -> 0 | P18: pcs
B19: ='MT.ROCK CONSOLIDATION'!B20:D20 -> NONEL Detonator 2.4 | H19: pcs | K19: =G19 -> 0 | L19: pcs | O19: =G19 -> 0 | P19: pcs
B20: ='MT.ROCK CONSOLIDATION'!B21:D21 -> NONEL Detonator 3.6 | H20: pcs | K20: =G20 -> 0 | L20: pcs | O20: =G20 -> 0 | P20: pcs
B21: ='MT.ROCK CONSOLIDATION'!B22:D22 -> Solar Detonating Cord 6 | H21: meters | K21: =G21 -> 0 | L21: meters | O21: =G21 -> 0 | P21: meters
B22: ='MT.ROCK CONSOLIDATION'!B23:D23 -> Solar Detonating Cord 10 | G22: 261 | H22: meters | K22: =G22 -> 261 | L22: meters | O22: =G22 -> 261 | P22: meters
B23: ='MT.ROCK CONSOLIDATION'!B24:D24 -> Solar Detonating Cord 40 | H23: meters | K23: =G23 -> 0 | L23: meters | O23: =G23 -> 0 | P23: meters
B24: ='MT.ROCK CONSOLIDATION'!B25:D25 -> Fuse Lighter | H24: pcs | K24: =G24 -> 0 | L24: pcs | O24: =G24 -> 0 | P24: pcs
B25: ='MT.ROCK CONSOLIDATION'!B26:D26 -> BILL WIRE | H25: meters | K25: =G25 -> 0 | L25: meters | O25: =G25 -> 0 | P25: meters
B26: ='MT.ROCK CONSOLIDATION'!B27:D27 -> Solar EBC | H26: pcs | K26: =G26 -> 0 | L26: pcs | O26: =G26 -> 0 | P26: pcs
A28: II. | B28: CHARGED DRILL HOLES
C29: (a) | D29: PRIMARY: | E29: 0 | G29: No. of holes: | J29: =G16+G17+G18+G19+G20-J30 -> 0 | L29: Depth: | N29: 5'X11"
C30: (b) | D30: SECONDARY: | E30: 0 | G30: No. of holes: | J30: 0 | L30: Depth: | N30: 3X'11"
A32: III. | B32: ESTIMATED TONNAGE OF BLASTED MATERIAL
B33: REMARKS:
A36: MT. ROCK POWDER CORPORATION
A37: PHILSAGA MINING CORPORATION (OPERATION)
A38: Bayugan 3, Rosario Agusan del Sur
A40: DAILY BLASTER REPORT
A42: Location | C42: : | D42: MINE SITE, CO-O, CONSUELO, BUNAWAN , AGUSAN DEL SUR | M42: Date: | N42: ='1-2'!N42 -> 46175
A43: Time of Blasting | C43: : | D43: 6:45 AM / 2:45 PM / 10:45 PM | M43: Shift: | N43: 1ST SHIFT/2ND SHIFT/3RD SHIFT
A45: I. | B45: EXPLOSIVE USED | F45: REQUISITIONED | J45: CONSUMED | N45: REQUIRED
F46: (KLS) | G46: (PCS) | J46: (KLS) | K46: (PCS) | N46: (KLS) | O46: (PCS)
B47: ='MT.ROCK CONSOLIDATION'!B12:D12 -> Emulsion Super Power 208 | F47: =G47/208*25 -> 0 | G47: 0 | H47: pcs | J47: =F47 -> 0 | K47: =G47 -> 0 | L47: pcs | N47: =F47 -> 0 | O47: =G47 -> 0 | P47: pcs
B48: ='MT.ROCK CONSOLIDATION'!B13:D13 -> NEOGEL 200 | F48: =G48/200*25 -> 162.5 | G48: 1300 | H48: pcs | J48: =F48 -> 162.5 | K48: =G48 -> 1300 | L48: pcs | N48: =F48 -> 162.5 | O48: =G48 -> 1300 | P48: pcs
B49: ='MT.ROCK CONSOLIDATION'!B14:D14 -> Anfo | F49: 0 | J49: =F49 -> 0 | N49: =F49 -> 0
...

Sheet 3-4.
A1: MT. ROCK POWDER CORPORATION
A2: PHILSAGA MINING CORPORATION (OPERATION)
A3: Bayugan 3, Rosario Agusan del Sur
A5: DAILY BLASTER REPORT
A7: Location | C7: : | D7: MINE SITE, CO-O, CONSUELO, BUNAWAN , AGUSAN DEL SUR | M7: Date: | N7: ='3-4'!N6 -> 46176
A8: Time of Blasting | C8: : | D8: 6:45 AM / 2:45 PM / 10:45 PM | M8: Shift: | N8: 1ST SHIFT/2ND SHIFT/3RD SHIFT
A10: I. | B10: EXPLOSIVE USED | F10: REQUISITIONED | J10: CONSUMED | N10: REQUIRED
F11: (KLS) | G11: (PCS) | J11: (KLS) | K11: (PCS) | N11: (KLS) | O11: (PCS)
B12: ='MT.ROCK CONSOLIDATION'!B12:D12 -> Emulsion Super Power 208 | F12: =G12/208*25 -> 0 | H12: pcs | J12: =F12 -> 0 | K12: =G12 -> 0 | L12: pcs | N12: =F12 -> 0 | O12: =G12 -> 0 | P12: pcs
B13: ='MT.ROCK CONSOLIDATION'!B13:D13 -> NEOGEL 200 | F13: =G13/200*25 -> 171.375 | G13: 1371 | H13: pcs | J13: =F13 -> 171.375 | K13: =G13 -> 1371 | L13: pcs | N13: =F13 -> 171.375 | O13: =G13 -> 1371 | P13: pcs
B14: ='MT.ROCK CONSOLIDATION'!B14:D14 -> Anfo | F14: 0 | J14: =F14 -> 0 | N14: =F14 -> 0
B15: ='MT.ROCK CONSOLIDATION'!B15:D15 -> OBC | G15: ='3-4'!G15 -> 88 | H15: pcs | K15: =G15 -> 88 | L15: pcs | O15: =G15 -> 88 | P15: pcs
B16: ='MT.ROCK CONSOLIDATION'!B16:D16 -> Safety Fuse | G16: =G15*2.43 -> 213.84 | H16: meters | K16: =G16 -> 213.84 | L16: meters | O16: =G16 -> 213.84 | P16: meters
B17: ='MT.ROCK CONSOLIDATION'!B17:D17 -> SHOCKSTAR Detonator 2.4 | H17: pcs | K17: =G17 -> 0 | L17: pcs | O17: =G17 -> 0 | P17: pcs
B18: ='MT.ROCK CONSOLIDATION'!B18:D18 -> SUPREME Detonator 2.4 | H18: pcs | K18: =G18 -> 0 | L18: pcs | O18: =G18 -> 0 | P18: pcs
B19: ='MT.ROCK CONSOLIDATION'!B19:D19 -> SUPREME Detonator 3.6 | H19: pcs | K19: =G19 -> 0 | L19: pcs | O19: =G19 -> 0 | P19: pcs
B20: ='MT.ROCK CONSOLIDATION'!B20:D20 -> NONEL Detonator 2.4 | H20: pcs | K20: =G20 -> 0 | L20: pcs | O20: =G20 -> 0 | P20: pcs
B21: ='MT.ROCK CONSOLIDATION'!B21:D21 -> NONEL Detonator 3.6 | H21: pcs | K21: =G21 -> 0 | L21: pcs | O21: =G21 -> 0 | P21: pcs
B22: ='MT.ROCK CONSOLIDATION'!B22:D22 -> Solar Detonating Cord 6 | H22: meters | K22: =G22 -> 0 | L22: meters | O22: =G22 -> 0 | P22: meters
B23: ='MT.ROCK CONSOLIDATION'!B23:D23 -> Solar Detonating Cord 10 | G23: 336 | H23: meters | K23: =G23 -> 336 | L23: meters | O23: =G23 -> 336 | P23: meters
B24: ='MT.ROCK CONSOLIDATION'!B24:D24 -> Solar Detonating Cord 40 | H24: meters | K24: =G24 -> 0 | L24: meters | O24: =G24 -> 0 | P24: meters
B25: ='MT.ROCK CONSOLIDATION'!B25:D25 -> Fuse Lighter | H25: pcs | K25: =G25 -> 0 | L25: pcs | O25: =G25 -> 0 | P25: pcs
B26: ='MT.ROCK CONSOLIDATION'!B26:D26 -> BILL WIRE | H26: meters | K26: =G26 -> 0 | L26: meters | O26: =G26 -> 0 | P26: meters
B27: ='MT.ROCK CONSOLIDATION'!B27:D27 -> Solar EBC | H27: pcs | K27: =G27 -> 0 | L27: pcs | O27: =G27 -> 0 | P27: pcs
A29: II. | B29: CHARGED DRILL HOLES
C30: (a) | D30: PRIMARY: | E30: 0 | J30: =G17+G18+G19+G20+G21-J31 -> 0 | L30: Depth: | N30: 5'X11"
C31: (b) | D31: SECONDARY: | E31: 0 | G31: No. of holes: | J31: 0 | L31: Depth: | N31: 3X'11"
A33: III. | B33: ESTIMATED TONNAGE OF BLASTED MATERIAL
B34: REMARKS:
A37: MT. ROCK POWDER CORPORATION
A38: PHILSAGA MINING CORPORATION (OPERATION)
A39: Bayugan 3, Rosario Agusan del Sur
A41: DAILY BLASTER REPORT
A43: Location | C43: : | D43: MINE SITE, CO-O, CONSUELO, BUNAWAN , AGUSAN DEL SUR | M43: Date: | N43: ='3-4'!N44 -> 46177
A44: Time of Blasting | C44: : | D44: 6:45 AM / 2:45 PM / 10:45 PM | M44: Shift: | N44: 1ST SHIFT/2ND SHIFT/3RD SHIFT
A46: I. | B46: EXPLOSIVE USED | F46: REQUISITIONED | J46: CONSUMED | N46: REQUIRED
F47: (KLS) | G47: (PCS) | J47: (KLS) | K47: (PCS) | N47: (KLS) | O47: (PCS)
B48: ='MT.ROCK CONSOLIDATION'!B12:D12 -> Emulsion Super Power 208 | F48: =G48/208*25 -> 0 | H48: pcs | J48: =F48 -> 0 | K48: =G48 -> 0 | L48: pcs | N48: =F48 -> 0 | O48: =G48 -> 0 | P48: pcs
B49: ='MT.ROCK CONSOLIDATION'!B13:D13 -> NEOGEL 200 | F49: =G49/200*25 -> 198.5 | G49: 1588 | H49: pcs | J49: =F49 -> 198.5 | K49: =G49 -> 1588 | L49: pcs | N49: =F49 -> 198.5 | O49: =G49 -> 1588 | P49: pcs
B50: ='MT.ROCK CONSOLIDATION'!B14:D14 -> Anfo | F50: 0 | J50: =F50 -> 0 | N50: =F50 -> 0
...

Sheet 5-6.
A1: MT. ROCK POWDER CORPORATION
A2: PHILSAGA MINING CORPORATION (OPERATION)
A3: Bayugan 3, Rosario Agusan del Sur
A5: DAILY BLASTER REPORT
A6: Location | C6: : | D6: MINE SITE, CO-O, CONSUELO, BUNAWAN , AGUSAN DEL SUR | M6: Date: | N6: ='5-6'!N6 -> 46178
A7: Time of Blasting | C7: : | D7: 6:45 AM / 2:45 PM / 10:45 PM | M7: Shift: | N7: 1ST SHIFT/2ND SHIFT/3RD SHIFT
A9: I. | B9: EXPLOSIVE USED | F9: REQUISITIONED | J9: CONSUMED | N9: REQUIRED
F10: (KLS) | G10: (PCS) | J10: (KLS) | K10: (PCS) | N10: (KLS) | O10: (PCS)
B11: ='MT.ROCK CONSOLIDATION'!B12:D12 -> Emulsion Super Power 208 | F11: =G11/208*25 -> 0 | H11: pcs | J11: =F11 -> 0 | K11: =G11 -> 0 | L11: pcs | N11: =F11 -> 0 | O11: =G11 -> 0 | P11: pcs
B12: ='MT.ROCK CONSOLIDATION'!B13:D13 -> NEOGEL 200 | F12: =G12/200*25 -> 225 | G12: 1800 | H12: pcs | J12: =F12 -> 225 | K12: =G12 -> 1800 | L12: pcs | N12: =F12 -> 225 | O12: =G12 -> 1800 | P12: pcs
B13: ='MT.ROCK CONSOLIDATION'!B14:D14 -> Anfo | F13: 0 | J13: =F13 -> 0 | N13: =F13 -> 0
B14: ='MT.ROCK CONSOLIDATION'!B15:D15 -> OBC | G14: ='5-6'!G15 -> 112 | H14: pcs | K14: =G14 -> 112 | L14: pcs | O14: =G14 -> 112 | P14: pcs
B15: ='MT.ROCK CONSOLIDATION'!B16:D16 -> Safety Fuse | G15: =G14*2.43 -> 272.16 | H15: meters | K15: =G15 -> 272.16 | L15: meters | O15: =G15 -> 272.16 | P15: meters
B16: ='MT.ROCK CONSOLIDATION'!B17:D17 -> SHOCKSTAR Detonator 2.4 | H16: pcs | K16: =G16 -> 0 | L16: pcs | O16: =G16 -> 0 | P16: pcs
B17: ='MT.ROCK CONSOLIDATION'!B18:D18 -> SUPREME Detonator 2.4 | H17: pcs | K17: =G17 -> 0 | L17: pcs | O17: =G17 -> 0 | P17: pcs
B18: ='MT.ROCK CONSOLIDATION'!B19:D19 -> SUPREME Detonator 3.6 | H18: pcs | K18: =G18 -> 0 | L18: pcs | O18: =G18 -> 0 | P18: pcs
B19: ='MT.ROCK CONSOLIDATION'!B20:D20 -> NONEL Detonator 2.4 | H19: pcs | K19: =G19 -> 0 | L19: pcs | O19: =G19 -> 0 | P19: pcs
B20: ='MT.ROCK CONSOLIDATION'!B21:D21 -> NONEL Detonator 3.6 | H20: pcs | K20: =G20 -> 0 | L20: pcs | O20: =G20 -> 0 | P20: pcs
B21: ='MT.ROCK CONSOLIDATION'!B22:D22 -> Solar Detonating Cord 6 | H21: meters | K21: =G21 -> 0 | L21: meters | O21: =G21 -> 0 | P21: meters
B22: ='MT.ROCK CONSOLIDATION'!B23:D23 -> Solar Detonating Cord 10 | G22: 543 | H22: meters | K22: =G22 -> 543 | L22: meters | O22: =G22 -> 543 | P22: meters
B23: ='MT.ROCK CONSOLIDATION'!B24:D24 -> Solar Detonating Cord 40 | H23: meters | K23: =G23 -> 0 | L23: meters | O23: =G23 -> 0 | P23: meters
B24: ='MT.ROCK CONSOLIDATION'!B25:D25 -> Fuse Lighter | H24: pcs | K24: =G24 -> 0 | L24: pcs | O24: =G24 -> 0 | P24: pcs
B25: ='MT.ROCK CONSOLIDATION'!B26:D26 -> BILL WIRE | H25: meters | K25: =G25 -> 0 | L25: meters | O25: =G25 -> 0 | P25: meters
B26: ='MT.ROCK CONSOLIDATION'!B27:D27 -> Solar EBC | H26: pcs | K26: =G26 -> 0 | L26: pcs | O26: =G26 -> 0 | P26: pcs
A28: II. | B28: CHARGED DRILL HOLES
C29: (a) | D29: PRIMARY: | E29: 0 | G29: No. of holes: | J29: =G16+G17+G18+G19+G20-J30 -> 0 | L29: Depth: | N29: 5'X11"
C30: (b) | D30: SECONDARY: | E30: 0 | G30: No. of holes: | J30: 0 | L30: Depth: | N30: 3X'11"
A32: III. | B32: ESTIMATED TONNAGE OF BLASTED MATERIAL
B33: REMARKS:
A36: MT. ROCK POWDER CORPORATION
A37: PHILSAGA MINING CORPORATION (OPERATION)
A38: Bayugan 3, Rosario Agusan del Sur
A40: DAILY BLASTER REPORT
A42: Location | C42: : | D42: MINE SITE, CO-O, CONSUELO, BUNAWAN , AGUSAN DEL SUR | M42: Date: | N42: ='5-6'!N44 -> 46179
A43: Time of Blasting | C43: : | D43: 6:45 AM / 2:45 PM / 10:45 PM | M43: Shift: | N43: 1ST SHIFT/2ND SHIFT/3RD SHIFT
A45: I. | B45: EXPLOSIVE USED | F45: REQUISITIONED | J45: CONSUMED | N45: REQUIRED
F46: (KLS) | G46: (PCS) | J46: (KLS) | K46: (PCS) | N46: (KLS) | O46: (PCS)
B47: ='MT.ROCK CONSOLIDATION'!B12:D12 -> Emulsion Super Power 208 | F47: =G47/208*25 -> 0 | H47: pcs | J47: =F47 -> 0 | K47: =G47 -> 0 | L47: pcs | N47: =F47 -> 0 | O47: =G47 -> 0 | P47: pcs
B48: ='MT.ROCK CONSOLIDATION'!B13:D13 -> NEOGEL 200 | F48: =G48/200*25 -> 247.625 | G48: 1981 | H48: pcs | J48: =F48 -> 247.625 | K48: =G48 -> 1981 | L48: pcs | N48: =F48 -> 247.625 | O48: =G48 -> 1981 | P48: pcs
B49: ='MT.ROCK CONSOLIDATION'!B14:D14 -> Anfo | F49: 0 | J49: =F49 -> 0 | N49: =F49 -> 0
...

Sheet 7
A1: MT. ROCK POWDER CORPORATION
A2: PHILSAGA MINING CORPORATION (OPERATION)
A3: Bayugan 3, Rosario Agusan del Sur
A5: DAILY BLASTER REPORT
A6: Location | C6: : | D6: MINE SITE, CO-O, CONSUELO, BUNAWAN , AGUSAN DEL SUR | M6: Date: | N6: ='7.'!N6:P6 -> 46180
A7: Time of Blasting | C7: : | D7: 6:45 AM / 2:45 PM / 10:45 PM | M7: Shift: | N7: 1ST SHIFT/2ND SHIFT/3RD SHIFT
A9: I. | B9: EXPLOSIVE USED | F9: REQUISITIONED | J9: CONSUMED | N9: REQUIRED
F10: (KLS) | G10: (PCS) | J10: (KLS) | K10: (PCS) | N10: (KLS) | O10: (PCS)
B11: ='MT.ROCK CONSOLIDATION'!B12:D12 -> Emulsion Super Power 208 | F11: =G11/208*25 -> 0 | H11: pcs | J11: =F11 -> 0 | K11: =G11 -> 0 | L11: pcs | N11: =F11 -> 0 | O11: =G11 -> 0 | P11: pcs
B12: ='MT.ROCK CONSOLIDATION'!B13:D13 -> NEOGEL 200 | F12: =G12/200*25 -> 211.75 | G12: 1694 | H12: pcs | J12: =F12 -> 211.75 | K12: =G12 -> 1694 | L12: pcs | N12: =F12 -> 211.75 | O12: =G12 -> 1694 | P12: pcs
B13: ='MT.ROCK CONSOLIDATION'!B14:D14 -> Anfo | F13: 0 | J13: =F13 -> 0 | N13: =F13 -> 0
B14: ='MT.ROCK CONSOLIDATION'!B15:D15 -> OBC | G14: 73 | H14: pcs | K14: =G14 -> 73 | L14: pcs | O14: =G14 -> 73 | P14: pcs
B15: ='MT.ROCK CONSOLIDATION'!B16:D16 -> Safety Fuse | G15: =G14*2.43 -> 177.39 | H15: meters | K15: =G15 -> 177.39 | L15: meters | O15: =G15 -> 177.39 | P15: meters
B16: ='MT.ROCK CONSOLIDATION'!B17:D17 -> SHOCKSTAR Detonator 2.4 | H16: pcs | K16: =G16 -> 0 | L16: pcs | O16: =G16 -> 0 | P16: pcs
B17: ='MT.ROCK CONSOLIDATION'!B18:D18 -> SUPREME Detonator 2.4 | H17: pcs | K17: =G17 -> 0 | L17: pcs | O17: =G17 -> 0 | P17: pcs
B18: ='MT.ROCK CONSOLIDATION'!B19:D19 -> SUPREME Detonator 3.6 | H18: pcs | K18: =G18 -> 0 | L18: pcs | O18: =G18 -> 0 | P18: pcs
B19: ='MT.ROCK CONSOLIDATION'!B20:D20 -> NONEL Detonator 2.4 | H19: pcs | K19: =G19 -> 0 | L19: pcs | O19: =G19 -> 0 | P19: pcs
B20: ='MT.ROCK CONSOLIDATION'!B21:D21 -> NONEL Detonator 3.6 | H20: pcs | K20: =G20 -> 0 | L20: pcs | O20: =G20 -> 0 | P20: pcs
B21: ='MT.ROCK CONSOLIDATION'!B22:D22 -> Solar Detonating Cord 6 | H21: meters | K21: =G21 -> 0 | L21: meters | O21: =G21 -> 0 | P21: meters
B22: ='MT.ROCK CONSOLIDATION'!B23:D23 -> Solar Detonating Cord 10 | G22: 406 | H22: meters | K22: =G22 -> 406 | L22: meters | O22: =G22 -> 406 | P22: meters
B23: ='MT.ROCK CONSOLIDATION'!B24:D24 -> Solar Detonating Cord 40 | H23: meters | K23: =G23 -> 0 | L23: meters | O23: =G23 -> 0 | P23: meters
B24: ='MT.ROCK CONSOLIDATION'!B25:D25 -> Fuse Lighter | H24: pcs | K24: =G24 -> 0 | L24: pcs | O24: =G24 -> 0 | P24: pcs
B25: ='MT.ROCK CONSOLIDATION'!B26:D26 -> BILL WIRE | H25: meters | K25: =G25 -> 0 | L25: meters | O25: =G25 -> 0 | P25: meters
B26: ='MT.ROCK CONSOLIDATION'!B27:D27 -> Solar EBC | H26: pcs | K26: =G26 -> 0 | L26: pcs | O26: =G26 -> 0 | P26: pcs
A28: II. | B28: CHARGED DRILL HOLES
C29: (a) | D29: PRIMARY: | E29: 0 | G29: No. of holes: | J29: =G16+G17+G18+G19+G20-J30 -> 0 | L29: Depth: | N29: 5'X11"
C30: (b) | D30: SECONDARY: | E30: 0 | G30: No. of holes: | J30: 0 | L30: Depth: | N30: 3X'11"
A32: III. | B32: ESTIMATED TONNAGE OF BLASTED MATERIAL
B33: REMARKS:
A36: MT. ROCK POWDER CORPORATION
A37: PHILSAGA MINING CORPORATION (OPERATION)
A38: Bayugan 3, Rosario Agusan del Sur
A40: DAILY BLASTER REPORT
A42: Location | C42: : | D42: MINE SITE, CO-O, CONSUELO, BUNAWAN , AGUSAN DEL SUR | M42: Date:
A43: Time of Blasting | C43: : | D43: 6:45 AM / 2:45 PM / 10:45 PM | M43: Shift: | N43: 1ST SHIFT/2ND SHIFT/3RD SHIFT
A45: I. | B45: EXPLOSIVE USED | F45: REQUISITIONED | J45: CONSUMED | N45: REQUIRED
F46: (KLS) | G46: (PCS) | J46: (KLS) | K46: (PCS) | N46: (KLS) | O46: (PCS)
B47: ='MT.ROCK CONSOLIDATION'!B12:D12 -> Emulsion Super Power 208 | F47: =G47/208*25 -> 0 | H47: pcs | J47: =F47 -> 0 | K47: =G47 -> 0 | L47: pcs | N47: =F47 -> 0 | O47: =G47 -> 0 | P47: pcs
B48: ='MT.ROCK CONSOLIDATION'!B13:D13 -> NEOGEL 200 | F48: =G48/200*25 -> 0 | H48: pcs | J48: =F48 -> 0 | K48: =G48 -> 0 | L48: pcs | N48: =F48 -> 0 | O48: =G48 -> 0 | P48: pcs
B49: ='MT.ROCK CONSOLIDATION'!B14:D14 -> Anfo | F49: ='7.'!F52 -> 0 | J49: =F49 -> 0 | N49: =F49 -> 0
...

Sheet 12
A1: MT. ROCK POWDER CORPORATION
A2: PHILSAGA MINING CORPORATION (OPERATION)
A3: Bayugan 3, Rosario Agusan del Sur
A5: DAILY BLASTER REPORT
