Workbook

Sheet 12-31-2023-01-06-2024
A1: PHILSAGA MINING CORPORATION
A2: Bayugan 3,Rosario Agusan del Sur
A4: EXPLOSIVE WEEKLY CONSUMPTION
A5: DECEMBER 31, 2023 - JANUARY 6, 2024
A8: SUPPLIER | C8: MT. ROCK | G8: EXPEDITION | Q8: MT ROCK | R8: MT. ROCK | W8: EXPEDITION | Z8: MT ROCK | AB8: EXPEDITION | AC8: MT. ROCK | AF8: MT ROCK | AG8: MT ROCK | AH8: EXPEDITION
Q9: EXPEDITION | Z9: EXPEDITION | AF9: EXPEDITION
A10: DATE | B10: DESCRIPTION | C10: PACKAGE EMULSION | Q10: Anfo | R10: DETONATORS | AB10: DETONATING CORD
C11: 200 | E11: 208 | G11: 215 | I11: 135 | K11: 150 | M11: 150 | O11: 38 | R11: NONEL | T11: SUPREME | V11: Shockstar | W11: EXEL | Z11: OBC | AA11: EBC | AB11: Cordtex | AC11: Cordtex | AD11: Cordtex | AE11: Cordtex | AF11: S/Fuse | AG11: Billwire | AH11: FUSE
C12: Super Power | E12: Super Power | G12: Senatel/Pulsar | I12: Senatel/Pulsar | K12: Super Power | M12: Magnum | O12: Senatel/Pulsar | R12: 2.4 | S12: 3.6 | T12: 2.4 | U12: 3.6 | V12: 2.4 | W12: 3.6 | X12: 2.4 | Y12: 4.9 | AB12: 5 | AC12: 10 | AD12: 6 | AE12: 40 | AH12: LIGHTER
C13: 31496 | E13: 17457 | G13: 11082 | I13: 21810 | K13: 17362 | M13: 18389 | O13: 21811 | Q13: 10128 | R13: 10962 | S13: 15427 | T13: 16623 | U13: 16967 | V13: 28230 | W13: 10966 | X13: 10965 | Y13: 21809 | Z13: 11966 | AA13: 11089 | AB13: 10960 | AC13: 10961 | AD13: 10839 | AE13: 10959 | AF13: 12487 | AG13: 16823 | AH13: 11342
C14: Pcs | D14: Kls | E14: Pcs | F14: Kls | G14: Pcs | H14: Kls | I14: Pcs | J14: Kls | K14: Pcs | L14: Kls | M14: Pcs | N14: Kls | O14: Pcs | P14: Kls | Q14: Kls | R14: Pcs | S14: Pcs | T14: Pcs | U14: Pcs | V14: Pcs | W14: Pcs | X14: Pcs | Y14: Pcs | Z14: Pcs | AA14: Pcs | AB14: Mtrs | AC14: Mtrs | AD14: Mtrs | AE14: Mtrs | AF14: Mtrs | AG14: Mtrs | AH14: Pcs
A15: 45291 | B15: BEG. BALANCE | C15: 0 | D15: 0 | E15: 86721 | F15: 10423.197 | G15: 98403 | H15: 11442.209 | I15: 0 | J15: 1.6964208e-13 | K15: 0 | L15: 0 | M15: 0 | N15: 0 | O15: 0 | P15: 2.9309888e-14 | Q15: 110649 | R15: 264 | S15: 847 | T15: 30859 | U15: 0 | V15: 0 | W15: 6214 | X15: 58192 | Y15: 657 | Z15: 8850 | AA15: 205 | AB15: 19454 | AC15: 28969 | AD15: 0 | AE15: 1060 | AF15: 44969 | AG15: 1885 | AH15: 517
B16: Withdrawal of Stock from Main Magazine Mill
B17: TOTAL ON HAND | C17: =C15+C16 -> 0 | D17: =D15+D16 -> 0 | E17: =E15+E16 -> 86721 | F17: =F15+F16 -> 10423.197 | G17: =G15+G16 -> 98403 | H17: =H15+H16 -> 11442.209 | I17: =I15+I16 -> 0 | J17: =J15+J16 -> 1.6964208e-13 | ... AH17: =AH15+AH16 -> 517
B18: Less: Total Weekly Consumption | C18: 0 | D18: =C18/200*25 -> 0 | E18: 485 | F18: =E18/208*25 -> 58.293269 | G18: 1595 | H18: =G18/215*25 -> 185.46512 | I18: 0 | J18: =I18/135*25 -> 0 | K18: 0 | L18: =K18/150*25 -> 0 | M18: 0 | N18: =M18/150*25 -> 0 | P18: =O18/38*25 -> 0 | Q18: 195 | R18: 0 | S18: 0 | T18: 0 | U18: 0 | V18: 0 | W18: 25 | X18: 533 | Y18: 0 | Z18: 81 | AA18: 2 | AB18: 164 | AC18: 48 | AE18: 0 | AF18: =Z18*2.43 -> 196.83 | AG18: 0 | AH18: 0
A19: 45297 | B19: STOCK BALANCE | C19: =C17-C18 -> 0 | D19: =D17-D18 -> 0 | E19: =E17-E18 -> 86236 | F19: =F17-F18 -> 10364.904 | G19: =G17-G18 -> 96808 | H19: =H17-H18 -> 11256.744 | I19: =I17-I18 -> 0 | J19: =J17-J18 -> 1.6964208e-13 | ... AH19: =AH17-AH18 -> 517 | AN19: =400+392+2745.29 -> 3537.29
A20: MINE MAG. STOCK USABLE | C20: =C19 -> 0 | D20: =D19 -> 0 | E20: =E19 -> 86236 | F20: =F19 -> 10364.904 | G20: =G19 -> 96808 | H20: =H19 -> 11256.744 | I20: =I19 -> 0 | J20: =J19 -> 1.6964208e-13 | ... AH20: =AH19 -> 517 | AN20: =10000-AN19 -> 6462.71
A23: Prepared by: | E23: Checked by: | P23: Noted by: | V23: Approved by:
A26: AIHREIN T. BACLAAN | E26: NHOLL GREAL O. LOZADA | P26: ENGR. RAFFY D. TORRES | V26: ENGR. EARL M. SON
A27: Mine Explosives Dept | E27: Mine Explosives Inventory Supervisor | P27: Mine Explosives Manager | V27: Mines Manager

Sheet 01-07-13,2024
A1: PHILSAGA MINING CORPORATION
A2: Bayugan 3,Rosario Agusan del Sur
A4: EXPLOSIVE WEEKLY CONSUMPTION
A5: JANUARY 7-13, 2024
A8: SUPPLIER | C8: MT. ROCK | G8: EXPEDITION | Q8: MT ROCK | R8: MT. ROCK | W8: EXPEDITION | Z8: MT ROCK | AB8: EXPEDITION | AC8: MT. ROCK | AF8: MT ROCK | AG8: MT ROCK | AH8: EXPEDITION
Q9: EXPEDITION | Z9: EXPEDITION | AF9: EXPEDITION
A10: DATE | B10: DESCRIPTION | C10: PACKAGE EMULSION | Q10: Anfo | R10: DETONATORS | AB10: DETONATING CORD
C11: 200 | E11: 208 | G11: 215 | I11: 135 | K11: 150 | M11: 150 | O11: 38 | R11: NONEL | T11: SUPREME | V11: Shockstar | W11: EXEL | Z11: OBC | AA11: EBC | AB11: Cordtex | AC11: Cordtex | AD11: Cordtex | AE11: Cordtex | AF11: S/Fuse | AG11: Billwire | AH11: FUSE
C12: Super Power | E12: Super Power | G12: Senatel/Pulsar | I12: Senatel/Pulsar | K12: Super Power | M12: Magnum | O12: Senatel/Pulsar | R12: 2.4 | S12: 3.6 | T12: 2.4 | U12: 3.6 | V12: 2.4 | W12: 3.6 | X12: 2.4 | Y12: 4.9 | AB12: 5 | AC12: 10 | AD12: 6 | AE12: 40 | AH12: LIGHTER
C13: 31496 | E13: 17457 | G13: 11082 | I13: 21810 | K13: 17362 | M13: 18389 | O13: 21811 | Q13: 10128 | R13: 10962 | S13: 15427 | T13: 16623 | U13: 16967 | V13: 28230 | W13: 10966 | X13: 10965 | Y13: 21809 | Z13: 11966 | AA13: 11089 | AB13: 10960 | AC13: 10961 | AD13: 10839 | AE13: 10959 | AF13: 12487 | AG13: 16823 | AH13: 11342
C14: Pcs | D14: Kls | E14: Pcs | F14: Kls | G14: Pcs | H14: Kls | I14: Pcs | J14: Kls | K14: Pcs | L14: Kls | M14: Pcs | N14: Kls | O14: Pcs | P14: Kls | Q14: Kls | R14: Pcs | S14: Pcs | T14: Pcs | U14: Pcs | V14: Pcs | W14: Pcs | X14: Pcs | Y14: Pcs | Z14: Pcs | AA14: Pcs | AB14: Mtrs | AC14: Mtrs | AD14: Mtrs | AE14: Mtrs | AF14: Mtrs | AG14: Mtrs | AH14: Pcs
A15: 45298 | B15: BEG. BALANCE | C15: ='12-31-2023-01-06-2024'!C20 -> 0 | D15: ='12-31-2023-01-06-2024'!D20 -> 0 | E15: ='12-31-2023-01-06-2024'!E20 -> 86236 | F15: ='12-31-2023-01-06-2024'!F20 -> 10364.904 | G15: ='12-31-2023-01-06-2024'!G20 -> 96808 | H15: ='12-31-2023-01-06-2024'!H20 -> 11256.744 | I15: ='12-31-2023-01-06-2024'!I20 -> 0 | J15: ='12-31-2023-01-06-2024'!J20 -> 1.6964208e-13 | ... AH15: ='12-31-2023-01-06-2024'!AH20 -> 517
B16: Withdrawal of Stock from Main Magazine Mill | D16: =C16/200*25 -> 0 | E16: =50*208 -> 10400 | F16: =E16/208*25 -> 1250 | G16: =50*215 -> 10750 | H16: =G16/215*25 -> 1250 | I16: 0 | J16: 0 | Q16: =600*25 -> 15000 | X16: 15500 | Z16: 2000 | AA16: 100 | AB16: 1800 | AC16: 2000 | AF16: 4000
B17: TOTAL ON HAND | C17: =C15+C16 -> 0 | D17: =D15+D16 -> 0 | E17: =E15+E16 -> 96636 | F17: =F15+F16 -> 11614.904 | G17: =G15+G16 -> 107558 | H17: =H15+H16 -> 12506.744 | I17: =I15+I16 -> 0 | J17: =J15+J16 -> 1.6964208e-13 | ... AH17: =AH15+AH16 -> 517
B18: Less: Total Weekly Consumption | C18: 0 | D18: =C18/200*25 -> 0 | E18: 7101 | F18: =E18/208*25 -> 853.48558 | G18: 9654 | H18: =G18/215*25 -> 1122.5581 | I18: 0 | J18: =I18/135*25 -> 0 | K18: 0 | L18: =K18/150*25 -> 0 | M18: 0 | N18: =M18/150*25 -> 0 | P18: =O18/38*25 -> 0 | Q18: 5211 | R18: 0 | S18: 0 | T18: 954 | U18: 0 | V18: 0 | W18: 135 | X18: 7240 | Y18: 0 | Z18: 1167 | AA18: 8 | AB18: 2697 | AC18: 739 | AF18: =Z18*2.43 -> 2835.81 | AG18: 0 | AH18: 73
A19: 45304 | B19: STOCK BALANCE | C19: =C17-C18 -> 0 | D19: =D17-D18 -> 0 | E19: =E17-E18 -> 89535 | F19: =F17-F18 -> 10761.418 | G19: =G17-G18 -> 97904 | H19: =H17-H18 -> 11384.186 | I19: =I17-I18 -> 0 | J19: =J17-J18 -> 1.6964208e-13 | ... AH19: =AH17-AH18 -> 444 | AN19: =400+392+2745.29 -> 3537.29
A20: MINE MAG. STOCK USABLE | C20: =C19 -> 0 | D20: =D19 -> 0 | E20: =E19 -> 89535 | F20: =F19 -> 10761.418 | G20: =G19 -> 97904 | H20: =H19 -> 11384.186 | I20: =I19 -> 0 | J20: =J19 -> 1.6964208e-13 | ... AH20: =AH19 -> 444 | AN20: =10000-AN19 -> 6462.71
A23: Prepared by: | E23: Checked by: | P23: Noted by: | V23: Approved by:
A26: AIHREIN T. BACLAAN | E26: NHOLL GREAL O. LOZADA | P26: ENGR. RAFFY D. TORRES | V26: ENGR. EARL M. SON
A27: Mine Explosives Dept | E27: Mine Explosives Inventory Supervisor | P27: Mine Explosives Manager | V27: Mines Manager

Sheet 01-14-20,2024
A1: PHILSAGA MINING CORPORATION
A2: Bayugan 3,Rosario Agusan del Sur
A4: EXPLOSIVE WEEKLY CONSUMPTION
A5: JANUARY 14-20, 2024
A8: SUPPLIER | C8: MT. ROCK | G8: EXPEDITION | Q8: MT ROCK | R8: MT. ROCK | W8: EXPEDITION | Z8: MT ROCK | AB8: EXPEDITION | AC8: MT. ROCK | AF8: MT ROCK | AG8: MT ROCK | AH8: EXPEDITION
Q9: EXPEDITION | Z9: EXPEDITION | AF9: EXPEDITION
A10: DATE | B10: DESCRIPTION | C10: PACKAGE EMULSION | Q10: Anfo | R10: DETONATORS | AB10: DETONATING CORD
C11: 200 | E11: 208 | G11: 215 | I11: 135 | K11: 150 | M11: 150 | O11: 38 | R11: NONEL | T11: SUPREME | V11: Shockstar | W11: EXEL | Z11: OBC | AA11: EBC | AB11: Cordtex | AC11: Cordtex | AD11: Cordtex | AE11: Cordtex | AF11: S/Fuse | AG11: Billwire | AH11: FUSE
C12: Super Power | E12: Super Power | G12: Senatel/Pulsar | I12: Senatel/Pulsar | K12: Super Power | M12: Magnum | O12: Senatel/Pulsar | R12: 2.4 | S12: 3.6 | T12: 2.4 | U12: 3.6 | V12: 2.4 | W12: 3.6 | X12: 2.4 | Y12: 4.9 | AB12: 5 | AC12: 10 | AD12: 6 | AE12: 40 | AH12: LIGHTER
C13: 31496 | E13: 17457 | G13: 11082 | I13: 21810 | K13: 17362 | M13: 18389 | O13: 21811 | Q13: 10128 | R13: 10962 | S13: 15427 | T13: 16623 | U13: 16967 | V13: 28230 | W13: 10966 | X13: 10965 | Y13: 21809 | Z13: 11966 | AA13: 11089 | AB13: 10960 | AC13: 10961 | AD13: 10839 | AE13: 10959 | AF13: 12487 | AG13: 16823 | AH13: 11342
C14: Pcs | D14: Kls | E14: Pcs | F14: Kls | G14: Pcs | H14: Kls | I14: Pcs | J14: Kls | K14: Pcs | L14: Kls | M14: Pcs | N14: Kls | O14: Pcs | P14: Kls | Q14: Kls | R14: Pcs | S14: Pcs | T14: Pcs | U14: Pcs | V14: Pcs | W14: Pcs | X14: Pcs | Y14: Pcs | Z14: Pcs | AA14: Pcs | AB14: Mtrs | AC14: Mtrs | AD14: Mtrs | AE14: Mtrs | AF14: Mtrs | AG14: Mtrs | AH14: Pcs
A15: 45305 | B15: BEG. BALANCE | C15: ='01-07-13,2024'!C20 -> 0 | D15: ='01-07-13,2024'!D20 -> 0 | E15: ='01-07-13,2024'!E20 -> 89535 | F15: ='01-07-13,2024'!F20 -> 10761.418 | G15: ='01-07-13,2024'!G20 -> 97904 | H15: ='01-07-13,2024'!H20 -> 11384.186 | I15: ='01-07-13,2024'!I20 -> 0 | J15: ='01-07-13,2024'!J20 -> 1.6964208e-13 | ... AH15: ='01-07-13,2024'!AH20 -> 444
B16: Withdrawal of Stock from Main Magazine Mill
B17: TOTAL ON HAND | C17: =C15+C16 -> 0 | D17: =D15+D16 -> 0 | E17: =E15+E16 -> 89535 | F17: =F15+F16 -> 10761.418 | G17: =G15+G16 -> 97904 | H17: =H15+H16 -> 11384.186 | I17: =I15+I16 -> 0 | J17: =J15+J16 -> 1.6964208e-13 | ... AH17: =AH15+AH16 -> 444
B18: Less: Total Weekly Consumption | C18: 0 | D18: =C18/200*25 -> 0 | E18: 6530 | F18: =E18/208*25 -> 784.85577 | G18: 10419 | H18: =G18/215*25 -> 1211.5116 | I18: 0 | J18: =I18/135*25 -> 0 | K18: 0 | L18: =K18/150*25 -> 0 | M18: 0 | N18: =M18/150*25 -> 0 | P18: =O18/38*25 -> 0 | Q18: 5845 | R18: 0 | S18: 0 | T18: 1083 | U18: 0 | V18: 0 | W18: 135 | X18: 7872 | Y18: 0 | Z18: 1164 | AA18: 10 | AB18: 2418 | AC18: 1203 | AF18: =Z18*2.43 -> 2828.52 | AG18: 80 | AH18: 79
A19: 45311 | B19: STOCK BALANCE | C19: =C17-C18 -> 0 | D19: =D17-D18 -> 0 | E19: =E17-E18 -> 83005 | F19: =F17-F18 -> 9976.5625 | G19: =G17-G18 -> 87485 | H19: =H17-H18 -> 10172.674 | I19: =I17-I18 -> 0 | J19: =J17-J18 -> 1.6964208e-13 | ... AH19: =AH17-AH18 -> 365 | AN19: =400+392+2745.29 -> 3537.29
A20: MINE MAG. STOCK USABLE | C20: =C19 -> 0 | D20: =D19 -> 0 | E20: =E19 -> 83005 | F20: =F19 -> 9976.5625 | G20: =G19 -> 87485 | H20: =H19 -> 10172.674 | I20: =I19 -> 0 | J20: =J19 -> 1.6964208e-13 | ... AH20: =AH19 -> 365 | AN20: =10000-AN19 -> 6462.71
A23: Prepared by: | E23: Checked by: | P23: Noted by: | V23: Approved by:
A26: AIHREIN T. BACLAAN | E26: NHOLL GREAL O. LOZADA | P26: ENGR. RAFFY D. TORRES | V26: ENGR. EARL M. SON
A27: Mine Explosives Dept | E27: Mine Explosives Inventory Supervisor | P27: Mine Explosives Manager | V27: Mines Manager

Sheet 1-21-27,2024
A1: PHILSAGA MINING CORPORATION
A2: Bayugan 3,Rosario Agusan del Sur
A4: EXPLOSIVE WEEKLY CONSUMPTION
A5: JANUARY 21-27, 2024
A8: SUPPLIER | C8: MT. ROCK | G8: EXPEDITION | Q8: MT ROCK | R8: MT. ROCK | W8: EXPEDITION | Z8: MT ROCK | AB8: EXPEDITION | AC8: MT. ROCK | AF8: MT ROCK | AG8: MT ROCK | AH8: EXPEDITION
Q9: EXPEDITION | Z9: EXPEDITION | AF9: EXPEDITION
A10: DATE | B10: DESCRIPTION | C10: PACKAGE EMULSION | Q10: Anfo | R10: DETONATORS | AB10: DETONATING CORD
C11: 200 | E11: 208 | G11: 215 | I11: 135 | K11: 150 | M11: 150 | O11: 38 | R11: NONEL | T11: SUPREME | V11: Shockstar | W11: EXEL | Z11: OBC | AA11: EBC | AB11: Cordtex | AC11: Cordtex | AD11: Cordtex | AE11: Cordtex | AF11: S/Fuse | AG11: Billwire | AH11: FUSE
C12: Super Power | E12: Super Power | G12: Senatel/Pulsar | I12: Senatel/Pulsar | K12: Super Power | M12: Magnum | O12: Senatel/Pulsar | R12: 2.4 | S12: 3.6 | T12: 2.4 | U12: 3.6 | V12: 2.4 | W12: 3.6 | X12: 2.4 | Y12: 4.9 | AB12: 5 | AC12: 10 | AD12: 6 | AE12: 40 | AH12: LIGHTER
C13: 31496 | E13: 17457 | G13: 11082 | I13: 21810 | K13: 17362 | M13: 18389 | O13: 21811 | Q13: 10128 | R13: 10962 | S13: 15427 | T13: 16623 | U13: 16967 | V13: 28230 | W13: 10966 | X13: 10965 | Y13: 21809 | Z13: 11966 | AA13: 11089 | AB13: 10960 | AC13: 10961 | AD13: 10839 | AE13: 10959 | AF13: 12487 | AG13: 16823 | AH13: 11342
C14: Pcs | D14: Kls | E14: Pcs | F14: Kls | G14: Pcs | H14: Kls | I14: Pcs | J14: Kls | K14: Pcs | L14: Kls | M14: Pcs | N14: Kls | O14: Pcs | P14: Kls | Q14: Kls | R14: Pcs | S14: Pcs | T14: Pcs | U14: Pcs | V14: Pcs | W14: Pcs | X14: Pcs | Y14: Pcs | Z14: Pcs | AA14: Pcs | AB14: Mtrs | AC14: Mtrs | AD14: Mtrs | AE14: Mtrs | AF14: Mtrs | AG14: Mtrs | AH14: Pcs
A15: 45312 | B15: BEG. BALANCE | C15: ='01-14-20,2024'!C20 -> 0 | D15: ='01-14-20,2024'!D20 -> 0 | E15: ='01-14-20,2024'!E20 -> 83005 | F15: ='01-14-20,2024'!F20 -> 9976.5625 | G15: ='01-14-20,2024'!G20 -> 87485 | H15: ='01-14-20,2024'!H20 -> 10172.674 | I15: ='01-14-20,2024'!I20 -> 0 | J15: ='01-14-20,2024'!J20 -> 1.6964208e-13 | ... AH15: ='01-14-20,2024'!AH20 -> 365
B16: Withdrawal of Stock from Main Magazine Mill | D16: =C16/200*25 -> 0 | E16: =50*208 -> 10400 | F16: =E16/208*25 -> 1250 | G16: =50*215 -> 10750 | H16: =G16/215*25 -> 1250 | I16: 0 | J16: 0 | Q16: =600*25 -> 15000 | T16: 7560 | X16: 7500 | Z16: 2000 | AB16: 900 | AC16: 1000 | AF16: 0
B17: TOTAL ON HAND | C17: =C15+C16 -> 0 | D17: =D15+D16 -> 0 | E17: =E15+E16 -> 93405 | F17: =F15+F16 -> 11226.563 | G17: =G15+G16 -> 98235 | H17: =H15+H16 -> 11422.674 | I17: =I15+I16 -> 0 | J17: =J15+J16 -> 1.6964208e-13 | ... AH17: =AH15+AH16 -> 365
B18: Less: Total Weekly Consumption | C18: 0 | D18: =C18/200*25 -> 0 | E18: 7976 | F18: =E18/208*25 -> 958.65385 | G18: 13261 | H18: =G18/215*25 -> 1541.9767 | I18: 0 | J18: =I18/135*25 -> 0 | K18: 0 | L18: =K18/150*25 -> 0 | M18: 0 | N18: =M18/150*25 -> 0 | P18: =O18/38*25 -> 0 | Q18: 6629 | R18: 0 | S18: 0 | T18: 948 | U18: 0 | V18: 0 | W18: 267 | X18: 9487 | Y18: 0 | Z18: 1286 | AA18: 18 | AB18: 3417 | AC18: 973 | AF18: =Z18*2.43 -> 3124.98 | AH18: 42
A19: 45318 | B19: STOCK BALANCE | C19: =C17-C18 -> 0 | D19: =D17-D18 -> 0 | E19: =E17-E18 -> 85429 | F19: =F17-F18 -> 10267.909 | G19: =G17-G18 -> 84974 | H19: =H17-H18 -> 9880.6977 | I19: =I17-I18 -> 0 | J19: =J17-J18 -> 1.6964208e-13 | ... AH19: =AH17-AH18 -> 323 | AN19: =400+392+2745.29 -> 3537.29
A20: MINE MAG. STOCK USABLE | C20: =C19 -> 0 | D20: =D19 -> 0 | E20: =E19 -> 85429 | F20: =F19 -> 10267.909 | G20: =G19 -> 84974 | H20: =H19 -> 9880.6977 | I20: =I19 -> 0 | J20: =J19 -> 1.6964208e-13 | ... AH20: =AH19 -> 323 | AN20: =10000-AN19 -> 6462.71
A23: Prepared by: | E23: Checked by: | P23: Noted by: | V23: Approved by:
A26: AIHREIN T. BACLAAN | E26: NHOLL GREAL O. LOZADA | P26: ENGR. RAFFY D. TORRES | V26: ENGR. EARL M. SON
A27: Mine Explosives Dept | E27: Mine Explosives Inventory Supervisor | P27: Mine Explosives Manager | V27: Mines Manager

Sheet 1-28-2-3,2024
A1: PHILSAGA MINING CORPORATION
A2: Bayugan 3,Rosario Agusan del Sur
A4: EXPLOSIVE WEEKLY CONSUMPTION
A5: JANUARY 28 - FEBRUARY 3, 2024
A8: SUPPLIER | C8: MT. ROCK | G8: EXPEDITION | Q8: MT ROCK | R8: MT. ROCK | W8: EXPEDITION | Z8: MT ROCK | AB8: EXPEDITION | AC8: MT. ROCK | AF8: MT ROCK | AG8: MT ROCK | AH8: EXPEDITION
Q9: EXPEDITION | Z9: EXPEDITION | AF9: EXPEDITION
A10: DATE | B10: DESCRIPTION | C10: PACKAGE EMULSION | Q10: Anfo | R10: DETONATORS | AB10: DETONATING CORD
C11: 200 | E11: 208 | G11: 215 | I11: 135 | K11: 150 | M11: 150 | O11: 38 | R11: NONEL | T11: SUPREME | V11: Shockstar | W11: EXEL | Z11: OBC | AA11: EBC | AB11: Cordtex | AC11: Cordtex | AD11: Cordtex | AE11: Cordtex | AF11: S/Fuse | AG11: Billwire | AH11: FUSE
C12: Super Power | E12: Super Power | G12: Senatel/Pulsar | I12: Senatel/Pulsar | K12: Super Power | M12: Magnum | O12: Senatel/Pulsar | R12: 2.4 | S12: 3.6 | T12: 2.4 | U12: 3.6 | V12: 2.4 | W12: 3.6 | X12: 2.4 | Y12: 4.9 | AB12: 5 | AC12: 10 | AD12: 6 | AE12: 40 | AH12: LIGHTER
C13: 31496 | E13: 17457 | G13: 11082 | I13: 21810 | K13: 17362 | M13: 18389 | O13: 21811 | Q13: 10128 | R13: 10962 | S13: 15427 | T13: 16623 | U13: 16967 | V13: 28230 | W13: 10966 | X13: 10965 | Y13: 21809 | Z13: 11966 | AA13: 11089 | AB13: 10960 | AC13: 10961 | AD13: 10839 | AE13: 10959 | AF13: 12487 | AG13: 16823 | AH13: 11342
C14: Pcs | D14: Kls | E14: Pcs | F14: Kls | G14: Pcs | H14: Kls | I14: Pcs | J14: Kls | K14: Pcs | L14: Kls | M14: Pcs | N14: Kls | O14: Pcs | P14: Kls | Q14: Kls | R14: Pcs | S14: Pcs | T14: Pcs | U14: Pcs | V14: Pcs | W14: Pcs | X14: Pcs | Y14: Pcs | Z14: Pcs | AA14: Pcs | AB14: Mtrs | AC14: Mtrs | AD14: Mtrs | AE14: Mtrs | AF14: Mtrs | AG14: Mtrs | AH14: Pcs
A15: 45319 | B15: BEG. BALANCE | C15: ='1-21-27,2024'!C20 -> 0 | D15: ='1-21-27,2024'!D20 -> 0 | E15: ='1-21-27,2024'!E20 -> 85429 | F15: ='1-21-27,2024'!F20 -> 10267.909 | G15: ='1-21-27,2024'!G20 -> 84974 | H15: ='1-21-27,2024'!H20 -> 9880.6977 | I15: ='1-21-27,2024'!I20 -> 0 | J15: ='1-21-27,2024'!J20 -> 1.6964208e-13 | ... AH15: ='1-21-27,2024'!AH20 -> 323
B16: Withdrawal of Stock from Main Magazine Mill
B17: TOTAL ON HAND | C17: =C15+C16 -> 0 | D17: =D15+D16 -> 0 | E17: =E15+E16 -> 85429 | F17: =F15+F16 -> 10267.909 | G17: =G15+G16 -> 84974 | H17: =H15+H16 -> 9880.6977 | I17: =I15+I16 -> 0 | J17: =J15+J16 -> 1.6964208e-13 | ... AH17: =AH15+AH16 -> 323
B18: Less: Total Weekly Consumption | C18: 0 | D18: =C18/200*25 -> 0 | E18: 10106 | F18: =E18/208*25 -> 1214.6635 | G18: 8538 | H18: =G18/215*25 -> 992.7907 | I18: 0 | J18: =I18/135*25 -> 0 | K18: 0 | L18: =K18/150*25 -> 0 | M18: 0 | N18: =M18/150*25 -> 0 | P18: =O18/38*25 -> 0 | Q18: 5941 | R18: 0 | S18: 0 | T18: 878 | U18: 0 | V18: 0 | W18: 129 | X18: 8498 | Z18: 1246 | AA18: 18 | AB18: 3183 | AC18: 920 | AF18: =Z18*2.43 -> 3027.78 | AH18: 17
A19: 45325 | B19: STOCK BALANCE | C19: =C17-C18 -> 0 | D19: =D17-D18 -> 0 | E19: =E17-E18 -> 75323 | F19: =F17-F18 -> 9053.2452 | G19: =G17-G18 -> 76436 | H19: =H17-H18 -> 8887.907 | I19: =I17-I18 -> 0 | J19: =J17-J18 -> 1.6964208e-13 | ... AH19: =AH17-AH18 -> 306 | AN19: =400+392+2745.29 -> 3537.29
A20: MINE MAG. STOCK USABLE | C20: =C19 -> 0 | D20: =D19 -> 0 | E20: =E19 -> 75323 | F20: =F19 -> 9053.2452 | G20: =G19 -> 76436 | H20: =H19 -> 8887.907 | I20: =I19 -> 0 | J20: =J19 -> 1.6964208e-13 | ... AH20: =AH19 -> 306 | AN20: =10000-AN19 -> 6462.71
A23: Prepared by: | E23: Checked by: | P23: Noted by: | V23: Approved by:
A26: AIHREIN T. BACLAAN | E26: NHOLL GREAL O. LOZADA | P26: ENGR. EDWIN B. BATAL | V26: ENGR. EARL M. SON
A27: Mine Explosives Dept | E27: Mine Explosives Inventory Supervisor | P27: Mine Explosives Asst. Manager | V27: Mines Manager

Sheet 2-4-10,2024
A1: PHILSAGA MINING CORPORATION
A2: Bayugan 3,Rosario Agusan del Sur
A4: EXPLOSIVE WEEKLY CONSUMPTION
A5: FEBRUARY 4-10, 2024
A8: SUPPLIER | C8: MT. ROCK | G8: EXPEDITION | Q8: MT ROCK | R8: MT. ROCK | W8: EXPEDITION | Z8: MT ROCK | AB8: EXPEDITION | AC8: MT. ROCK | AF8: MT ROCK | AG8: MT ROCK | AH8: EXPEDITION
Q9: EXPEDITION | Z9: EXPEDITION | AF9: EXPEDITION
A10: DATE | B10: DESCRIPTION | C10: PACKAGE EMULSION | Q10: Anfo | R10: DETONATORS | AB10: DETONATING CORD
C11: 200 | E11: 208 | G11: 215 | I11: 135 | K11: 150 | M11: 150 | O11: 38 | R11: NONEL | T11: SUPREME | V11: Shockstar | W11: EXEL | Z11: OBC | AA11: EBC | AB11: Cordtex | AC11: Cordtex | AD11: Cordtex | AE11: Cordtex | AF11: S/Fuse | AG11: Billwire | AH11: FUSE
C12: Super Power | E12: Super Power | G12: Senatel/Pulsar | I12: Senatel/Pulsar | K12: Super Power | M12: Magnum | O12: Senatel/Pulsar | R12: 2.4 | S12: 3.6 | T12: 2.4 | U12: 3.6 | V12: 2.4 | W12: 3.6 | X12: 2.4 | Y12: 4.9 | AB12: 5 | AC12: 10 | AD12: 6 | AE12: 40 | AH12: LIGHTER
C13: 31496 | E13: 17457 | G13: 11082 | I13: 21810 | K13: 17362 | M13: 18389 | O13: 21811 | Q13: 10128 | R13: 10962 | S13: 15427 | T13: 16623 | U13: 16967 | V13: 28230 | W13: 10966 | X13: 10965 | Y13: 21809 | Z13: 11966 | AA13: 11089 | AB13: 10960 | AC13: 10961 | AD13: 10839 | AE13: 10959 | AF13: 12487 | AG13: 16823 | AH13: 11342
C14: Pcs | D14: Kls | E14: Pcs | F14: Kls | G14: Pcs | H14: Kls | I14: Pcs | J14: Kls | K14: Pcs | L14: Kls | M14: Pcs | N14: Kls | O14: Pcs | P14: Kls | Q14: Kls | R14: Pcs | S14: Pcs | T14: Pcs | U14: Pcs | V14: Pcs | W14: Pcs | X14: Pcs | Y14: Pcs | Z14: Pcs | AA14: Pcs | AB14: Mtrs | AC14: Mtrs | AD14: Mtrs | AE14: Mtrs | AF14: Mtrs | AG14: Mtrs | AH14: Pcs
A15: 45326 | B15: BEG. BALANCE | C15: ='1-28-2-3,2024'!C20 -> 0 | D15: ='1-28-2-3,2024'!D20 -> 0 | E15: ='1-28-2-3,2024'!E20 -> 75323 | F15: ='1-28-2-3,2024'!F20 -> 9053.2452 | G15: ='1-28-2-3,2024'!G20 -> 76436 | H15: ='1-28-2-3,2024'!H20 -> 8887.907 | I15: ='1-28-2-3,2024'!I20 -> 0 | J15: ='1-28-2-3,2024'!J20 -> 1.6964208e-13 | ... AH15: ='1-28-2-3,2024'!AH20 -> 306
B16: Withdrawal of Stock from Main Magazine Mill
B17: TOTAL ON HAND | C17: =C15+C16 -> 0 | D17: =D15+D16 -> 0 | E17: =E15+E16 -> 75323 | F17: =F15+F16 -> 9053.2452 | G17: =G15+G16 -> 76436 | H17: =H15+H16 -> 8887.907 | I17: =I15+I16 -> 0 | J17: =J15+J16 -> 1.6964208e-13 | ... AH17: =AH15+AH16 -> 306
B18: Less: Total Weekly Consumption | C18: 0 | D18: =C18/200*25 -> 0 | E18: 11631 | F18: =E18/208*25 -> 1397.9567 | G18: 7661 | H18: =G18/215*25 -> 890.81395 | I18: 0 | J18: =I18/135*25 -> 0 | K18: 0 | L18: =K18/150*25 -> 0 | M18: 0 | N18: =M18/150*25 -> 0 | P18: =O18/38*25 -> 0 | Q18: 6142 | R18: 0 | S18: 0 | T18: 757 | U18: 0 | V18: 0 | W18: 143 | X18: 8928 | Z18: 1221 | AA18: 16 | AB18: 1892 | AC18: 2293 | AF18: =Z18*2.43 -> 2967.03 | AH18: 8
A19: 45332 | B19: STOCK BALANCE | C19: =C17-C18 -> 0 | D19: =D17-D18 -> 0 | E19: =E17-E18 -> 63692 | F19: =F17-F18 -> 7655.2885 | G19: =G17-G18 -> 68775 | H19: =H17-H18 -> 7997.093 | I19: =I17-I18 -> 0 | J19: =J17-J18 -> 1.6964208e-13 | ... AH19: =AH17-AH18 -> 298 | AN19: =400+392+2745.29 -> 3537.29
A20: MINE MAG. STOCK USABLE | C20: =C19 -> 0 | D20: =D19 -> 0 | E20: =E19 -> 63692 | F20: =F19 -> 7655.2885 | G20: =G19 -> 68775 | H20: =H19 -> 7997.093 | I20: =I19 -> 0 | J20: =J19 -> 1.6964208e-13 | ... AH20: =AH19 -> 298 | AN20: =10000-AN19 -> 6462.71
A23: Prepared by: | E23: Checked by: | P23: Noted by: | V23: Approved by:
A26: AIHREIN T. BACLAAN | E26: NHOLL GREAL O. LOZADA | P26: ENGR. RAFFY D. TORRES | V26: ENGR. EARL M. SON
A27: Mine Explosives Dept | E27: Mine Explosives Inventory Supervisor | P27: Mine Explosives Manager | V27: Mines Manager

Sheet 2-11-17,2024
A1: PHILSAGA MINING CORPORATION
A2: Bayugan 3,Rosario Agusan del Sur
A4: EXPLOSIVE WEEKLY CONSUMPTION
A5: FEBRUARY 11-17, 2024
A8: SUPPLIER | C8: MT. ROCK | G8: EXPEDITION | Q8: MT ROCK | R8: MT. ROCK | W8: EXPEDITION | Z8: MT ROCK | AB8: EXPEDITION | AC8: MT. ROCK | AF8: MT ROCK | AG8: MT ROCK | AH8: EXPEDITION
Q9: EXPEDITION | Z9: EXPEDITION | AF9: EXPEDITION
A10: DATE | B10: DESCRIPTION | C10: PACKAGE EMULSION | Q10: Anfo | R10: DETONATORS | AB10: DETONATING CORD
C11: 200 | E11: 208 | G11: 215 | I11: 135 | K11: 150 | M11: 150 | O11: 38 | R11: NONEL | T11: SUPREME | V11: Shockstar | W11: EXEL | Z11: OBC | AA11: EBC | AB11: Cordtex | AC11: Cordtex | AD11: Cordtex | AE11: Cordtex | AF11: S/Fuse | AG11: Billwire | AH11: FUSE
C12: Super Power | E12: Super Power | G12: Senatel/Pulsar | I12: Senatel/Pulsar | K12: Super Power | M12: Magnum | O12: Senatel/Pulsar | R12: 2.4 | S12: 3.6 | T12: 2.4 | U12: 3.6 | V12: 2.4 | W12: 3.6 | X12: 2.4 | Y12: 4.9 | AB12: 5 | AC12: 10 | AD12: 6 | AE12: 40 | AH12: LIGHTER
C13: 31496 | E13: 17457 | G13: 11082 | I13: 21810 | K13: 17362 | M13: 18389 | O13: 21811 | Q13: 10128 | R13: 10962 | S13: 15427 | T13: 16623 | U13: 16967 | V13: 28230 | W13: 10966 | X13: 10965 | Y13: 21809 | Z13: 11966 | AA13: 11089 | AB13: 10960 | AC13: 10961 | AD13: 10839 | AE13: 10959 | AF13: 12487 | AG13: 16823 | AH13: 11342
C14: Pcs | D14: Kls | E14: Pcs | F14: Kls | G14: Pcs | H14: Kls | I14: Pcs | J14: Kls | K14: Pcs | L14: Kls | M14: Pcs | N14: Kls | O14: Pcs | P14: Kls | Q14: Kls | R14: Pcs | S14: Pcs | T14: Pcs | U14: Pcs | V14: Pcs | W14: Pcs | X14: Pcs | Y14: Pcs | Z14: Pcs | AA14: Pcs | AB14: Mtrs | AC14: Mtrs | AD14: Mtrs | AE14: Mtrs | AF14: Mtrs | AG14: Mtrs | AH14: Pcs
A15: 45333 | B15: BEG. BALANCE | C15: ='2-4-10,2024'!C20 -> 0 | D15: ='2-4-10,2024'!D20 -> 0 | E15: ='2-4-10,2024'!E20 -> 63692 | F15: ='2-4-10,2024'!F20 -> 7655.2885 | G15: ='2-4-10,2024'!G20 -> 68775 | H15: ='2-4-10,2024'!H20 -> 7997.093 | I15: ='2-4-10,2024'!I20 -> 0 | J15: ='2-4-10,2024'!J20 -> 1.6964208e-13 | ... AH15: ='2-4-10,2024'!AH20 -> 298
B16: Withdrawal of Stock from Main Magazine Mill | D16: =C16/200*25 -> 0 | E16: =50*208 -> 10400 | F16: =E16/208*25 -> 1250 | G16: =50*215 -> 10750 | H16: =G16/215*25 -> 1250 | I16: 0 | J16: 0 | Q16: =600*25 -> 15000 | T16: 10800 | X16: 15500 | Z16: 2000 | AA16: 100 | AB16: 5400 | AC16: 6000 | AF16: 0 | AG16: 600 | AH16: 200
B17: TOTAL ON HAND | C17: =C15+C16 -> 0 | D17: =D15+D16 -> 0 | E17: =E15+E16 -> 74092 | F17: =F15+F16 -> 8905.2885 | G17: =G15+G16 -> 79525 | H17: =H15+H16 -> 9247.093 | I17: =I15+I16 -> 0 | J17: =J15+J16 -> 1.6964208e-13 | ... AH17: =AH15+AH16 -> 498
B18: Less: Total Weekly Consumption | C18: 0 | D18: =C18/200*25 -> 0 | E18: 12008 | F18: =E18/208*25 -> 1443.2692 | G18: 7898 | H18: =G18/215*25 -> 918.37209 | I18: 0 | J18: =I18/135*25 -> 0 | K18: 0 | L18: =K18/150*25 -> 0 | M18: 0 | N18: =M18/150*25 -> 0 | P18: =O18/38*25 -> 0 | Q18: 6028 | R18: 0 | S18: 0 | T18: 911 | U18: 0 | V18: 0 | W18: 82 | X18: 8828 | Y18: 0 | Z18: 1205 | AA18: 12 | AB18: 2100 | AC18: 2023 | AE18: 0 | AF18: =Z18*2.43 -> 2928.15 | AG18: 0 | AH18: 22
A19: 45339 | B19: STOCK BALANCE | C19: =C17-C18 -> 0 | D19: =D17-D18 -> 0 | E19: =E17-E18 -> 62084 | F19: =F17-F18 -> 7462.0192 | G19: =G17-G18 -> 71627 | H19: =H17-H18 -> 8328.7209 | I19: =I17-I18 -> 0 | J19: =J17-J18 -> 1.6964208e-13 | ... AH19: =AH17-AH18 -> 476 | AN19: =400+392+2745.29 -> 3537.29
A20: MINE MAG. STOCK USABLE | C20: =C19 -> 0 | D20: =D19 -> 0 | E20: =E19 -> 62084 | F20: =F19 -> 7462.0192 | G20: =G19 -> 71627 | H20: =H19 -> 8328.7209 | I20: =I19 -> 0 | J20: =J19 -> 1.6964208e-13 | ... AH20: =AH19 -> 476 | AN20: =10000-AN19 -> 6462.71
A23: Prepared by: | E23: Checked by: | P23: Noted by: | V23: Approved by:
A26: AIHREIN T. BACLAAN | E26: NHOLL GREAL O. LOZADA | P26: ENGR. RAFFY D. TORRES | V26: ENGR. EARL M. SON
A27: Mine Explosives Dept | E27: Mine Explosives Inventory Supervisor | P27: Mine Explosives Manager | V27: Mines Manager

Sheet 2-18-24,2024
A1: PHILSAGA MINING CORPORATION
A2: Bayugan 3,Rosario Agusan del Sur
A4: EXPLOSIVE WEEKLY CONSUMPTION
A5: FEBRUARY 18-24, 2024
A8: SUPPLIER | C8: MT. ROCK | G8: EXPEDITION | Q8: MT ROCK | R8: MT. ROCK | W8: EXPEDITION | Z8: MT ROCK | AB8: EXPEDITION | AC8: MT. ROCK | AF8: MT ROCK | AG8: MT ROCK | AH8: EXPEDITION
Q9: EXPEDITION | Z9: EXPEDITION | AF9: EXPEDITION
A10: DATE | B10: DESCRIPTION | C10: PACKAGE EMULSION | Q10: Anfo | R10: DETONATORS | AB10: DETONATING CORD
C11: 200 | E11: 208 | G11: 215 | I11: 135 | K11: 150 | M11: 150 | O11: 38 | R11: NONEL | T11: SUPREME | V11: Shockstar | W11: EXEL | Z11: OBC | AA11: EBC | AB11: Cordtex | AC11: Cordtex | AD11: Cordtex | AE11: Cordtex | AF11: S/Fuse | AG11: Billwire | AH11: FUSE
C12: Super Power | E12: Super Power | G12: Senatel/Pulsar | I12: Senatel/Pulsar | K12: Super Power | M12: Magnum | O12: Senatel/Pulsar | R12: 2.4 | S12: 3.6 | T12: 2.4 | U12: 3.6 | V12: 2.4 | W12: 3.6 | X12: 2.4 | Y12: 4.9 | AB12: 5 | AC12: 10 | AD12: 6 | AE12: 40 | AH12: LIGHTER
C13: 31496 | E13: 17457 | G13: 11082 | I13: 21810 | K13: 17362 | M13: 18389 | O13: 21811 | Q13: 10128 | R13: 10962 | S13: 15427 | T13: 16623 | U13: 16967 | V13: 28230 | W13: 10966 | X13: 10965 | Y13: 21809 | Z13: 11966 | AA13: 11089 | AB13: 10960 | AC13: 10961 | AD13: 10839 | AE13: 10959 | AF13: 12487 | AG13: 16823 | AH13: 11342
C14: Pcs | D14: Kls | E14: Pcs | F14: Kls | G14: Pcs | H14: Kls | I14: Pcs | J14: Kls | K14: Pcs | L14: Kls | M14: Pcs | N14: Kls | O14: Pcs | P14: Kls | Q14: Kls | R14: Pcs | S14: Pcs | T14: Pcs | U14: Pcs | V14: Pcs | W14: Pcs | X14: Pcs | Y14: Pcs | Z14: Pcs | AA14: Pcs | AB14: Mtrs | AC14: Mtrs | AD14: Mtrs | AE14: Mtrs | AF14: Mtrs | AG14: Mtrs | AH14: Pcs
A15: 45340 | B15: BEG. BALANCE | C15: ='2-11-17,2024'!C20 -> 0 | D15: ='2-11-17,2024'!D20 -> 0 | E15: ='2-11-17,2024'!E20 -> 62084 | F15: ='2-11-17,2024'!F20 -> 7462.0192 | G15: ='2-11-17,2024'!G20 -> 71627 | H15: ='2-11-17,2024'!H20 -> 8328.7209 | I15: ='2-11-17,2024'!I20 -> 0 | J15: ='2-11-17,2024'!J20 -> 1.6964208e-13 | ... AH15: ='2-11-17,2024'!AH20 -> 476
B16: Withdrawal of Stock from Main Magazine Mill | D16: =C16/200*25 -> 0 | E16: =50*208 -> 10400 | F16: =E16/208*25 -> 1250 | G16: =50*215 -> 10750 | H16: =G16/215*25 -> 1250 | I16: 0 | J16: 0 | Q16: =600*25 -> 15000 | T16: 5040 | X16: 8000 | Z16: 5000 | AB16: 4500 | AC16: 4000 | AF16: 0
B17: TOTAL ON HAND | C17: =C15+C16 -> 0 | D17: =D15+D16 -> 0 | E17: =E15+E16 -> 72484 | F17: =F15+F16 -> 8712.0192 | G17: =G15+G16 -> 82377 | H17: =H15+H16 -> 9578.7209 | I17: =I15+I16 -> 0 | J17: =J15+J16 -> 1.6964208e-13 | ... AH17: =AH15+AH16 -> 476
B18: Less: Total Weekly Consumption | C18: 0 | D18: =C18/200*25 -> 0 | E18: 10901 | F18: =E18/208*25 -> 1310.2163 | G18: 9620 | H18: =G18/215*25 -> 1118.6047 | I18: 0 | J18: =I18/135*25 -> 0 | K18: 0 | L18: =K18/150*25 -> 0 | M18: 0 | N18: =M18/150*25 -> 0 | P18: =O18/38*25 -> 0 | Q18: 5789 | R18: 0 | S18: 0 | T18: 1714 | U18: 0 | V18: 0 | W18: 212 | X18: 7645 | Y18: 0 | Z18: 1300 | AA18: 28 | AB18: 3032 | AC18: 881 | AF18: =Z18*2.43 -> 3159 | AG18: 0 | AH18: 18
A19: 45346 | B19: STOCK BALANCE | C19: =C17-C18 -> 0 | D19: =D17-D18 -> 0 | E19: =E17-E18 -> 61583 | F19: =F17-F18 -> 7401.8029 | G19: =G17-G18 -> 72757 | H19: =H17-H18 -> 8460.1163 | I19: =I17-I18 -> 0 | J19: =J17-J18 -> 1.6964208e-13 | ... AH19: =AH17-AH18 -> 458 | AN19: =400+392+2745.29 -> 3537.29
A20: MINE MAG. STOCK USABLE | C20: =C19 -> 0 | D20: =D19 -> 0 | E20: =E19 -> 61583 | F20: =F19 -> 7401.8029 | G20: =G19 -> 72757 | H20: =H19 -> 8460.1163 | I20: =I19 -> 0 | J20: =J19 -> 1.6964208e-13 | ... AH20: =AH19 -> 458 | AN20: =10000-AN19 -> 6462.71
A23: Prepared by: | E23: Checked by: | P23: Noted by: | V23: Approved by:
A26: AIHREIN T. BACLAAN | E26: NHOLL GREAL O. LOZADA | P26: ENGR. RAFFY D. TORRES | V26: ENGR. EARL M. SON
A27: Mine Explosives Dept | E27: Mine Explosives Inventory Supervisor | P27: Mine Explosives Manager | V27: Mines Manager

Sheet 2-25-3-2,2024
A1: PHILSAGA MINING CORPORATION
A2: Bayugan 3,Rosario Agusan del Sur
A4: EXPLOSIVE WEEKLY CONSUMPTION
A5: FEBRUARY 25 - MARCH 2, 2024
A8: SUPPLIER | C8: MT. ROCK | G8: EXPEDITION | Q8: MT ROCK | R8: MT. ROCK | W8: EXPEDITION | Z8: MT ROCK | AB8: EXPEDITION | AC8: MT. ROCK | AF8: MT ROCK | AG8: MT ROCK | AH8: EXPEDITION
Q9: EXPEDITION | Z9: EXPEDITION | AF9: EXPEDITION
A10: DATE | B10: DESCRIPTION | C10: PACKAGE EMULSION | Q10: Anfo | R10: DETONATORS | AB10: DETONATING CORD
C11: 200 | E11: 208 | G11: 215 | I11: 135 | K11: 150 | M11: 150 | O11: 38 | R11: NONEL | T11: SUPREME | V11: Shockstar | W11: EXEL | Z11: OBC | AA11: EBC | AB11: Cordtex | AC11: Cordtex | AD11: Cordtex | AE11: Cordtex | AF11: S/Fuse | AG11: Billwire | AH11: FUSE
C12: Super Power | E12: Super Power | G12: Senatel/Pulsar | I12: Senatel/Pulsar | K12: Super Power | M12: Magnum | O12: Senatel/Pulsar | R12: 2.4 | S12: 3.6 | T12: 2.4 | U12: 3.6 | V12: 2.4 | W12: 3.6 | X12: 2.4 | Y12: 4.9 | AB12: 5 | AC12: 10 | AD12: 6 | AE12: 40 | AH12: LIGHTER
C13: 31496 | E13: 17457 | G13: 11082 | I13: 21810 | K13: 17362 | M13: 18389 | O13: 21811 | Q13: 10128 | R13: 10962 | S13: 15427 | T13: 16623 | U13: 16967 | V13: 28230 | W13: 10966 | X13: 10965 | Y13: 21809 | Z13: 11966 | AA13: 11089 | AB13: 10960 | AC13: 10961 | AD13: 10839 | AE13: 10959 | AF13: 12487 | AG13: 16823 | AH13: 11342
C14: Pcs | D14: Kls | E14: Pcs | F14: Kls | G14: Pcs | H14: Kls | I14: Pcs | J14: Kls | K14: Pcs | L14: Kls | M14: Pcs | N14: Kls | O14: Pcs | P14: Kls | Q14: Kls | R14: Pcs | S14: Pcs | T14: Pcs | U14: Pcs | V14: Pcs | W14: Pcs | X14: Pcs | Y14: Pcs | Z14: Pcs | AA14: Pcs | AB14: Mtrs | AC14: Mtrs | AD14: Mtrs | AE14: Mtrs | AF14: Mtrs | AG14: Mtrs | AH14: Pcs
A15: 45347 | B15: BEG. BALANCE | C15: ='2-18-24,2024'!C20 -> 0 | D15: ='2-18-24,2024'!D20 -> 0 | E15: ='2-18-24,2024'!E20 -> 61583 | F15: ='2-18-24,2024'!F20 -> 7401.8029 | G15: ='2-18-24,2024'!G20 -> 72757 | H15: ='2-18-24,2024'!H20 -> 8460.1163 | I15: ='2-18-24,2024'!I20 -> 0 | J15: ='2-18-24,2024'!J20 -> 1.6964208e-13 | ... AH15: ='2-18-24,2024'!AH20 -> 458
B16: Withdrawal of Stock from Main Magazine Mill
B17: TOTAL ON HAND | C17: =C15+C16 -> 0 | D17: =D15+D16 -> 0 | E17: =E15+E16 -> 61583 | F17: =F15+F16 -> 7401.8029 | G17: =G15+G16 -> 72757 | H17: =H15+H16 -> 8460.1163 | I17: =I15+I16 -> 0 | J17: =J15+J16 -> 1.6964208e-13 | ... AH17: =AH15+AH16 -> 458
B18: Less: Total Weekly Consumption | C18: 0 | D18: =C18/200*25 -> 0 | E18: 9154 | F18: =E18/208*25 -> 1100.2404 | G18: 12408 | H18: =G18/215*25 -> 1442.7907 | I18: 0 | J18: =I18/135*25 -> 0 | K18: 0 | L18: =K18/150*25 -> 0 | M18: 0 | N18: =M18/150*25 -> 0 | P18: =O18/38*25 -> 0 | Q18: 6260 | R18: 0 | S18: 0 | T18: 2169 | U18: 0 | V18: 0 | W18: 115 | X18: 7986 | Y18: 0 | Z18: 1295 | AA18: 34 | AB18: 3384 | AC18: 993 | AE18: 0 | AF18: =Z18*2.43 -> 3146.85 | AG18: 0 | AH18: 15
A19: 45353 | B19: STOCK BALANCE | C19: =C17-C18 -> 0 | D19: =D17-D18 -> 0 | E19: =E17-E18 -> 52429 | F19: =F17-F18 -> 6301.5625 | G19: =G17-G18 -> 60349 | H19: =H17-H18 -> 7017.3256 | I19: =I17-I18 -> 0 | J19: =J17-J18 -> 1.6964208e-13 | ... AH19: =AH17-AH18 -> 443 | AN19: =400+392+2745.29 -> 3537.29
A20: MINE MAG. STOCK USABLE | C20: =C19 -> 0 | D20: =D19 -> 0 | E20: =E19 -> 52429 | F20: =F19 -> 6301.5625 | G20: =G19 -> 60349 | H20: =H19 -> 7017.3256 | I20: =I19 -> 0 | J20: =J19 -> 1.6964208e-13 | ... AH20: =AH19 -> 443 | AN20: =10000-AN19 -> 6462.71
A23: Prepared by: | F23: Checked by: | Q23: Noted by: | W23: Approved by:
A26: AIHREIN T. BACLAAN | F26: NHOLL GREAL O. LOZADA | Q26: ENGR. EDWIN B. BATAL | W26: ENGR. EARL M. SON
A27: Mine Explosives Dept | F27: Mine Explosives Inventory Supervisor | Q27: Mine Explosives Asst. Manager | W27: Mines Manager

Sheet 3-3-9,2024
A1: PHILSAGA MINING CORPORATION
A2: Bayugan 3,Rosario Agusan del Sur
A4: EXPLOSIVE WEEKLY CONSUMPTION
A5: MARCH 3-9, 2024
A8: SUPPLIER | C8: MT. ROCK | G8: EXPEDITION | Q8: MT ROCK | R8: MT. ROCK | W8: EXPEDITION | Z8: MT ROCK | AB8: EXPEDITION | AC8: MT. ROCK | AF8: MT ROCK | AG8: MT ROCK | AH8: EXPEDITION
Q9: EXPEDITION | Z9: EXPEDITION | AF9: EXPEDITION
A10: DATE | B10: DESCRIPTION | C10: PACKAGE EMULSION | Q10: Anfo | R10: DETONATORS | AB10: DETONATING CORD
C11: 200 | E11: 208 | G11: 215 | I11: 135 | K11: 150 | M11: 150 | O11: 38 | R11: NONEL | T11: SUPREME | V11: Shockstar | W11: EXEL | Z11: OBC | AA11: EBC | AB11: Cordtex | AC11: Cordtex | AD11: Cordtex | AE11: Cordtex | AF11: S/Fuse | AG11: Billwire | AH11: FUSE
C12: Super Power | E12: Super Power | G12: Senatel/Pulsar | I12: Senatel/Pulsar | K12: Super Power | M12: Magnum | O12: Senatel/Pulsar | R12: 2.4 | S12: 3.6 | T12: 2.4 | U12: 3.6 | V12: 2.4 | W12: 3.6 | X12: 2.4 | Y12: 4.9 | AB12: 5 | AC12: 10 | AD12: 6 | AE12: 40 | AH12: LIGHTER
C13: 31496 | E13: 17457 | G13: 11082 | I13: 21810 | K13: 17362 | M13: 18389 | O13: 21811 | Q13: 10128 | R13: 10962 | S13: 15427 | T13: 16623 | U13: 16967 | V13: 28230 | W13: 10966 | X13: 10965 | Y13: 21809 | Z13: 11966 | AA13: 11089 | AB13: 10960 | AC13: 10961 | AD13: 10839 | AE13: 10959 | AF13: 12487 | AG13: 16823 | AH13: 11342
C14: Pcs | D14: Kls | E14: Pcs | F14: Kls | G14: Pcs | H14: Kls | I14: Pcs | J14: Kls | K14: Pcs | L14: Kls | M14: Pcs | N14: Kls | O14: Pcs | P14: Kls | Q14: Kls | R14: Pcs | S14: Pcs | T14: Pcs | U14: Pcs | V14: Pcs | W14: Pcs | X14: Pcs | Y14: Pcs | Z14: Pcs | AA14: Pcs | AB14: Mtrs | AC14: Mtrs | AD14: Mtrs | AE14: Mtrs | AF14: Mtrs | AG14: Mtrs | AH14: Pcs
A15: 45354 | B15: BEG. BALANCE | C15: ='2-18-24,2024'!C20 -> 0 | D15: ='2-18-24,2024'!D20 -> 0 | E15: ='2-25-3-2,2024'!E20 -> 52429 | F15: ='2-25-3-2,2024'!F20 -> 6301.5625 | G15: ='2-25-3-2,2024'!G20 -> 60349 | H15: ='2-25-3-2,2024'!H20 -> 7017.3256 | I15: ='2-25-3-2,2024'!I20 -> 0 | J15: ='2-25-3-2,2024'!J20 -> 1.6964208e-13 | K15: ='2-25-3-2,2024'!K20 -> 0 | L15: ='2-25-3-2,2024'!L20 -> 0 | ... AH15: ='2-25-3-2,2024'!AH20 -> 443
B16: Withdrawal of Stock from Main Magazine Mill
B17: TOTAL ON HAND | C17: =C15+C16 -> 0 | D17: =D15+D16 -> 0 | E17: =E15+E16 -> 52429 | F17: =F15+F16 -> 6301.5625 | G17: =G15+G16 -> 60349 | H17: =H15+H16 -> 7017.3256 | I17: =I15+I16 -> 0 | J17: =J15+J16 -> 1.6964208e-13 | ... AH17: =AH15+AH16 -> 443
B18: Less: Total Weekly Consumption | C18: 0 | D18: =C18/200*25 -> 0 | E18: 4498 | F18: =E18/208*25 -> 540.625 | G18: 14099 | H18: =G18/215*25 -> 1639.4186 | I18: 0 | J18: =I18/135*25 -> 0 | K18: 0 | L18: =K18/150*25 -> 0 | M18: 0 | N18: =M18/150*25 -> 0 | P18: =O18/38*25 -> 0 | Q18: 4981 | R18: 0 | S18: 0 | T18: 1988 | U18: 0 | V18: 0 | W18: 117 | X18: 6260 | Y18: 11 | Z18: 1094 | AA18: 30 | AB18: 2672 | AC18: 743 | AE18: 0 | AF18: =Z18*2.43 -> 2658.42 | AG18: 0 | AH18: 4
A19: 45360 | B19: STOCK BALANCE | C19: =C17-C18 -> 0 | D19: =D17-D18 -> 0 | E19: =E17-E18 -> 47931 | F19: =F17-F18 -> 5760.9375 | G19: =G17-G18 -> 46250 | H19: =H17-H18 -> 5377.907 | I19: =I17-I18 -> 0 | J19: =J17-J18 -> 1.6964208e-13 | ... AH19: =AH17-AH18 -> 439 | AN19: =400+392+2745.29 -> 3537.29
A20: MINE MAG. STOCK USABLE | C20: =C19 -> 0 | D20: =D19 -> 0 | E20: =E19 -> 47931 | F20: =F19 -> 5760.9375 | G20: =G19 -> 46250 | H20: =H19 -> 5377.907 | I20: =I19 -> 0 | J20: =J19 -> 1.6964208e-13 | ... AH20: =AH19 -> 439 | AN20: =10000-AN19 -> 6462.71
A23: Prepared by: | F23: Checked by: | Q23: Noted by: | W23: Approved by:
A26: AIHREIN T. BACLAAN | F26: NHOLL GREAL O. LOZADA | Q26: ENGR. EDWIN B. BATAL | W26: ENGR. EARL M. SON
A27: Mine Explosives Dept | F27: Mine Explosives Inventory Supervisor | Q27: Mine Explosives Asst. Manager | W27: Mines Manager

Sheet 3-10-16,2024
A1: PHILSAGA MINING CORPORATION
A2: Bayugan 3,Rosario Agusan del Sur
A4: EXPLOSIVE WEEKLY CONSUMPTION
A5: MARCH 10-16, 2024
A8: SUPPLIER | C8: MT. ROCK | G8: EXPEDITION | Q8: MT ROCK | R8: MT. ROCK | W8: EXPEDITION | Z8: MT ROCK | AB8: EXPEDITION | AC8: MT. ROCK | AF8: MT ROCK | AG8: MT ROCK | AH8: EXPEDITION
Q9: EXPEDITION | Z9: EXPEDITION | AF9: EXPEDITION
A10: DATE | B10: DESCRIPTION | C10: PACKAGE EMULSION | Q10: Anfo | R10: DETONATORS | AB10: DETONATING CORD
C11: 200 | E11: 208 | G11: 215 | I11: 135 | K11: 150 | M11: 150 | O11: 38 | R11: NONEL | T11: SUPREME | V11: Shockstar | W11: EXEL | Z11: OBC | AA11: EBC | AB11: Cordtex | AC11: Cordtex | AD11: Cordtex | AE11: Cordtex | AF11: S/Fuse | AG11: Billwire | AH11: FUSE
C12: Super Power | E12: Super Power | G12: Senatel/Pulsar | I12: Senatel/Pulsar | K12: Super Power | M12: Magnum | O12: Senatel/Pulsar | R12: 2.4 | S12: 3.6 | T12: 2.4 | U12: 3.6 | V12: 2.4 | W12: 3.6 | X12: 2.4 | Y12: 4.9 | AB12: 5 | AC12: 10 | AD12: 6 | AE12: 40 | AH12: LIGHTER
C13: 31496 | E13: 17457 | G13: 11082 | I13: 21810 | K13: 17362 | M13: 18389 | O13: 21811 | Q13: 10128 | R13: 10962 | S13: 15427 | T13: 16623 | U13: 16967 | V13: 28230 | W13: 10966 | X13: 10965 | Y13: 21809 | Z13: 11966 | AA13: 11089 | AB13: 10960 | AC13: 10961 | AD13: 10839 | AE13: 10959 | AF13: 12487 | AG13: 16823 | AH13: 11342
C14: Pcs | D14: Kls | E14: Pcs | F14: Kls | G14: Pcs | H14: Kls | I14: Pcs | J14: Kls | K14: Pcs | L14: Kls | M14: Pcs | N14: Kls | O14: Pcs | P14: Kls | Q14: Kls | R14: Pcs | S14: Pcs | T14: Pcs | U14: Pcs | V14: Pcs | W14: Pcs | X14: Pcs | Y14: Pcs | Z14: Pcs | AA14: Pcs | AB14: Mtrs | AC14: Mtrs | AD14: Mtrs | AE14: Mtrs | AF14: Mtrs | AG14: Mtrs | AH14: Pcs
A15: 45361 | B15: BEG. BALANCE | C15: ='2-18-24,2024'!C20 -> 0 | D15: ='2-18-24,2024'!D20 -> 0 | E15: ='3-3-9,2024'!E20 -> 47931 | F15: ='3-3-9,2024'!F20 -> 5760.9375 | G15: ='3-3-9,2024'!G20 -> 46250 | H15: ='3-3-9,2024'!H20 -> 5377.907 | I15: ='3-3-9,2024'!I20 -> 0 | J15: ='3-3-9,2024'!J20 -> 1.6964208e-13 | K15: ='3-3-9,2024'!K20 -> 0 | L15: ='3-3-9,2024'!L20 -> 0 | ... AH15: ='3-3-9,2024'!AH20 -> 439
B16: Withdrawal of Stock from Main Magazine Mill
B17: TOTAL ON HAND | C17: =C15+C16 -> 0 | D17: =D15+D16 -> 0 | E17: =E15+E16 -> 47931 | F17: =F15+F16 -> 5760.9375 | G17: =G15+G16 -> 46250 | H17: =H15+H16 -> 5377.907 | I17: =I15+I16 -> 0 | J17: =J15+J16 -> 1.6964208e-13 | ... AH17: =AH15+AH16 -> 439
B18: Less: Total Weekly Consumption | C18: 0 | D18: =C18/200*25 -> 0 | E18: 4959 | F18: =E18/208*25 -> 596.03365 | G18: 14174 | H18: =G18/215*25 -> 1648.1395 | I18: 0 | J18: =I18/135*25 -> 0 | K18: 0 | L18: =K18/150*25 -> 0 | M18: 0 | N18: =M18/150*25 -> 0 | P18: =O18/38*25 -> 0 | Q18: 5262 | R18: 0 | S18: 0 | T18: 2615 | U18: 0 | V18: 0 | W18: 108 | X18: 6122 | Y18: 0 | Z18: 1168 | AA18: 18 | AB18: 2873 | AC18: 754 | AF18: =Z18*2.43 -> 2838.24 | AG18: 0 | AH18: 18
A19: 45367 | B19: STOCK BALANCE | C19: =C17-C18 -> 0 | D19: =D17-D18 -> 0 | E19: =E17-E18 -> 42972 | F19: =F17-F18 -> 5164.9038 | G19: =G17-G18 -> 32076 | H19: =H17-H18 -> 3729.7674 | I19: =I17-I18 -> 0 | J19: =J17-J18 -> 1.6964208e-13 | ... AH19: =AH17-AH18 -> 421 | AN19: =400+392+2745.29 -> 3537.29
A20: MINE MAG. STOCK USABLE | C20: =C19 -> 0 | D20: =D19 -> 0 | E20: =E19 -> 42972 | F20: =F19 -> 5164.9038 | G20: =G19 -> 32076 | H20: =H19 -> 3729.7674 | I20: =I19 -> 0 | J20: =J19 -> 1.6964208e-13 | ... AH20: =AH19 -> 421 | AN20: =10000-AN19 -> 6462.71
A23: Prepared by: | F23: Checked by: | Q23: Noted by: | W23: Approved by:
A26: AIHREIN T. BACLAAN | F26: NHOLL GREAL O. LOZADA | Q26: ENGR. RAFFY D. TORRES | W26: ENGR. EARL M. SON
A27: Mine Explosives Dept | F27: Mine Explosives Inventory Supervisor | Q27: Mine Explosives Manager | W27: Mines Manager

Sheet 3-17-23,2024
A1: PHILSAGA MINING CORPORATION
A2: Bayugan 3,Rosario Agusan del Sur
A4: EXPLOSIVE WEEKLY CONSUMPTION
A5: MARCH 17-23, 2024
A8: SUPPLIER | C8: MT. ROCK | G8: EXPEDITION | Q8: MT ROCK | R8: MT. ROCK | W8: EXPEDITION | Z8: MT ROCK | AB8: EXPEDITION | AC8: MT. ROCK | AF8: MT ROCK | AG8: MT ROCK | AH8: EXPEDITION
Q9: EXPEDITION | Z9: EXPEDITION | AF9: EXPEDITION
A10: DATE | B10: DESCRIPTION | C10: PACKAGE EMULSION | Q10: Anfo | R10: DETONATORS | AB10: DETONATING CORD
C11: 200 | E11: 208 | G11: 215 | I11: 135 | K11: 150 | M11: 150 | O11: 38 | R11: NONEL | T11: SUPREME | V11: Shockstar | W11: EXEL | Z11: OBC | AA11: EBC | AB11: Cordtex | AC11: Cordtex | AD11: Cordtex | AE11: Cordtex | AF11: S/Fuse | AG11: Billwire | AH11: FUSE
C12: Super Power | E12: Super Power | G12: Senatel/Pulsar | I12: Senatel/Pulsar | K12: Super Power | M12: Magnum | O12: Senatel/Pulsar | R12: 2.4 | S12: 3.6 | T12: 2.4 | U12: 3.6 | V12: 2.4 | W12: 3.6 | X12: 2.4 | Y12: 4.9 | AB12: 5 | AC12: 10 | AD12: 6 | AE12: 40 | AH12: LIGHTER
C13: 31496 | E13: 17457 | G13: 11082 | I13: 21810 | K13: 17362 | M13: 18389 | O13: 21811 | Q13: 10128 | R13: 10962 | S13: 15427 | T13: 16623 | U13: 16967 | V13: 28230 | W13: 10966 | X13: 10965 | Y13: 21809 | Z13: 11966 | AA13: 11089 | AB13: 10960 | AC13: 10961 | AD13: 10839 | AE13: 10959 | AF13: 12487 | AG13: 16823 | AH13: 11342
C14: Pcs | D14: Kls | E14: Pcs | F14: Kls | G14: Pcs | H14: Kls | I14: Pcs | J14: Kls | K14: Pcs | L14: Kls | M14: Pcs | N14: Kls | O14: Pcs | P14: Kls | Q14: Kls | R14: Pcs | S14: Pcs | T14: Pcs | U14: Pcs | V14: Pcs | W14: Pcs | X14: Pcs | Y14: Pcs | Z14: Pcs | AA14: Pcs | AB14: Mtrs | AC14: Mtrs | AD14: Mtrs | AE14: Mtrs | AF14: Mtrs | AG14: Mtrs | AH14: Pcs
A15: 45368 | B15: BEG. BALANCE | C15: ='2-18-24,2024'!C20 -> 0 | D15: ='2-18-24,2024'!D20 -> 0 | E15: ='3-10-16,2024'!E20 -> 42972 | F15: ='3-10-16,2024'!F20 -> 5164.9038 | G15: ='3-10-16,2024'!G20 -> 32076 | H15: ='3-10-16,2024'!H20 -> 3729.7674 | I15: ='3-10-16,2024'!I20 -> 0 | J15: ='3-10-16,2024'!J20 -> 1.6964208e-13 | K15: ='3-10-16,2024'!K20 -> 0 | L15: ='3-10-16,2024'!L20 -> 0 | ... AH15: ='3-10-16,2024'!AH20 -> 421
B16: Withdrawal of Stock from Main Magazine Mill
B17: TOTAL ON HAND | C17: =C15+C16 -> 0 | D17: =D15+D16 -> 0 | E17: =E15+E16 -> 42972 | F17: =F15+F16 -> 5164.9038 | G17: =G15+G16 -> 32076 | H17: =H15+H16 -> 3729.7674 | I17: =I15+I16 -> 0 | J17: =J15+J16 -> 1.6964208e-13 | ... AH17: =AH15+AH16 -> 421
B18: Less: Total Weekly Consumption | C18: 0 | D18: =C18/200*25 -> 0 | E18: 7696 | F18: =E18/208*25 -> 925 | G18: 10934 | H18: =G18/215*25 -> 1271.3953 | I18: 0 | J18: =I18/135*25 -> 0 | K18: 0 | L18: =K18/150*25 -> 0 | M18: 0 | N18: =M18/150*25 -> 0 | P18: =O18/38*25 -> 0 | Q18: 5540 | R18: 0 | S18: 0 | T18: 4375 | U18: 0 | V18: 0 | W18: 78 | X18: 4494 | Y18: 0 | Z18: 1218 | AA18: 10 | AB18: 1634 | AC18: 2042 | AE18: 0 | AF18: =Z18*2.43 -> 2959.74 | AG18: 0 | AH18: 12
A19: 45375 | B19: STOCK BALANCE | C19: =C17-C18 -> 0 | D19: =D17-D18 -> 0 | E19: =E17-E18 -> 35276 | F19: =F17-F18 -> 4239.9038 | G19: =G17-G18 -> 21142 | H19: =H17-H18 -> 2458.3721 | I19: =I17-I18 -> 0 | J19: =J17-J18 -> 1.6964208e-13 | ... AH19: =AH17-AH18 -> 409 | AN19: =400+392+2745.29 -> 3537.29
A20: MINE MAG. STOCK USABLE | C20: =C19 -> 0 | D20: =D19 -> 0 | E20: =E19 -> 35276 | F20: =F19 -> 4239.9038 | G20: =G19 -> 21142 | H20: =H19 -> 2458.3721 | I20: =I19 -> 0 | J20: =J19 -> 1.6964208e-13 | ... AH20: =AH19 -> 409 | AN20: =10000-AN19 -> 6462.71
A23: Prepared by: | F23: Checked by: | Q23: Noted by: | W23: Approved by:
A26: AIHREIN T. BACLAAN | F26: NHOLL GREAL O. LOZADA | Q26: ENGR. RAFFY D. TORRES | W26: ENGR. JOHN PAUHL T. NAVARRO
A27: Mine Explosives Dept | F27: Mine Explosives Inventory Supervisor | Q27: Mine Explosives Manager | W27: Tigerway Project Manager /Asst. Mines Manager

Sheet 3-24-30,2024
A1: PHILSAGA MINING CORPORATION
A2: Bayugan 3,Rosario Agusan del Sur
A4: EXPLOSIVE WEEKLY CONSUMPTION
A5: MARCH 24-30, 2024
A8: SUPPLIER | C8: MT. ROCK | G8: EXPEDITION | Q8: MT ROCK | R8: MT. ROCK | W8: EXPEDITION | Z8: MT ROCK | AB8: EXPEDITION | AC8: MT. ROCK | AF8: MT ROCK | AG8: MT ROCK | AH8: EXPEDITION
Q9: EXPEDITION | Z9: EXPEDITION | AF9: EXPEDITION
A10: DATE | B10: DESCRIPTION | C10: PACKAGE EMULSION | Q10: Anfo | R10: DETONATORS | AB10: DETONATING CORD
C11: 200 | E11: 208 | G11: 215 | I11: 135 | K11: 150 | M11: 150 | O11: 38 | R11: NONEL | T11: SUPREME | V11: Shockstar | W11: EXEL | Z11: OBC | AA11: EBC | AB11: Cordtex | AC11: Cordtex | AD11: Cordtex | AE11: Cordtex | AF11: S/Fuse | AG11: Billwire | AH11: FUSE
C12: Super Power | E12: Super Power | G12: Senatel/Pulsar | I12: Senatel/Pulsar | K12: Super Power | M12: Magnum | O12: Senatel/Pulsar | R12: 2.4 | S12: 3.6 | T12: 2.4 | U12: 3.6 | V12: 2.4 | W12: 3.6 | X12: 2.4 | Y12: 4.9 | AB12: 5 | AC12: 10 | AD12: 6 | AE12: 40 | AH12: LIGHTER
C13: 31496 | E13: 17457 | G13: 11082 | I13: 21810 | K13: 17362 | M13: 18389 | O13: 21811 | Q13: 10128 | R13: 10962 | S13: 15427 | T13: 16623 | U13: 16967 | V13: 28230 | W13: 10966 | X13: 10965 | Y13: 21809 | Z13: 11966 | AA13: 11089 | AB13: 10960 | AC13: 10961 | AD13: 10839 | AE13: 10959 | AF13: 12487 | AG13: 16823 | AH13: 11342
C14: Pcs | D14: Kls | E14: Pcs | F14: Kls | G14: Pcs | H14: Kls | I14: Pcs | J14: Kls | K14: Pcs | L14: Kls | M14: Pcs | N14: Kls | O14: Pcs | P14: Kls | Q14: Kls | R14: Pcs | S14: Pcs | T14: Pcs | U14: Pcs | V14: Pcs | W14: Pcs | X14: Pcs | Y14: Pcs | Z14: Pcs | AA14: Pcs | AB14: Mtrs | AC14: Mtrs | AD14: Mtrs | AE14: Mtrs | AF14: Mtrs | AG14: Mtrs | AH14: Pcs
A15: 45375 | B15: BEG. BALANCE | C15: ='2-18-24,2024'!C20 -> 0 | D15: ='2-18-24,2024'!D20 -> 0 | E15: ='3-17-23,2024'!E20 -> 35276 | F15: ='3-17-23,2024'!F20 -> 4239.9038 | G15: ='3-17-23,2024'!G20 -> 21142 | H15: ='3-17-23,2024'!H20 -> 2458.3721 | I15: ='3-17-23,2024'!I20 -> 0 | J15: ='3-17-23,2024'!J20 -> 1.6964208e-13 | K15: ='3-17-23,2024'!K20 -> 0 | L15: ='3-17-23,2024'!L20 -> 0 | ... AH15: ='3-17-23,2024'!AH20 -> 409
B16: Withdrawal of Stock from Main Magazine Mill | E16: =40*208 -> 8320 | F16: =E16/208*25 -> 1000 | G16: =40*215 -> 8600 | H16: =G16/215*25 -> 1000 | I16: =50*215 -> 10750 | J16: =I16/215*25 -> 1250 | K16: 0 | L16: 0 | T16: =360*14 -> 5040 | X16: =20*250 -> 5000 | AB16: 3600 | AC16: 3000
B17: TOTAL ON HAND | C17: =C15+C16 -> 0 | D17: =D15+D16 -> 0 | E17: =E15+E16 -> 43596 | F17: =F15+F16 -> 5239.9038 | G17: =G15+G16 -> 29742 | H17: =H15+H16 -> 3458.3721 | I17: =I15+I16 -> 10750 | J17: =J15+J16 -> 1250 | ... AH17: =AH15+AH16 -> 409
B18: Less: Total Weekly Consumption | C18: 0 | D18: =C18/200*25 -> 0 | E18: 5688 | F18: =E18/208*25 -> 683.65385 | G18: 3544 | H18: =G18/215*25 -> 412.09302 | I18: 0 | J18: =I18/135*25 -> 0 | K18: 0 | L18: =K18/150*25 -> 0 | M18: 0 | N18: =M18/150*25 -> 0 | P18: =O18/38*25 -> 0 | Q18: 2207 | R18: 0 | S18: 0 | T18: 2458 | U18: 0 | V18: 0 | W18: 227 | X18: 1258 | Z18: 445 | AA18: 20 | AB18: 612 | AC18: 992 | AE18: 0 | AF18: =Z18*2.43 -> 1081.35 | AG18: 80 | AH18: 2
A19: 45381 | B19: STOCK BALANCE | C19: =C17-C18 -> 0 | D19: =D17-D18 -> 0 | E19: =E17-E18 -> 37908 | F19: =F17-F18 -> 4556.25 | G19: =G17-G18 -> 26198 | H19: =H17-H18 -> 3046.2791 | I19: =I17-I18 -> 10750 | J19: =J17-J18 -> 1250 | ... AH19: =AH17-AH18 -> 407 | AL19: =400+392+2745.29 -> 3537.29
A20: MINE MAG. STOCK USABLE | C20: =C19 -> 0 | D20: =D19 -> 0 | E20: =E19 -> 37908 | F20: =F19 -> 4556.25 | G20: =G19 -> 26198 | H20: =H19 -> 3046.2791 | I20: =I19 -> 10750 | J20: =J19 -> 1250 | ... AH20: =AH19 -> 407 | AL20: =10000-AL19 -> 6462.71
A23: Prepared by: | F23: Checked by: | Q23: Noted by: | W23: Approved by:
A26: AIHREIN T. BACLAAN | F26: NHOLL GREAL O. LOZADA | Q26: ENGR. RAFFY D. TORRES | W26: ENGR. EARL M. SON
A27: Mine Explosives Dept | F27: Mine Explosives Inventory Supervisor | Q27: Mine Explosives Manager | W27: Mines Manager

Sheet 3-31-4-6,2024
A1: PHILSAGA MINING CORPORATION
A2: Bayugan 3,Rosario Agusan del Sur
A4: EXPLOSIVE WEEKLY CONSUMPTION
A5: MARCH 31 - APRIL 6, 2024
A8: SUPPLIER | C8: MT. ROCK | G8: EXPEDITION | Q8: MT ROCK | R8: MT. ROCK | W8: EXPEDITION | Z8: MT ROCK | AB8: EXPEDITION | AC8: MT. ROCK | AF8: MT ROCK | AG8: MT ROCK | AH8: EXPEDITION
Q9: EXPEDITION | Z9: EXPEDITION | AF9: EXPEDITION
A10: DATE | B10: DESCRIPTION | C10: PACKAGE EMULSION | Q10: Anfo | R10: DETONATORS | AB10: DETONATING CORD
C11: 200 | E11: 208 | G11: 215 | I11: 135 | K11: 150 | M11: 150 | O11: 38 | R11: NONEL | T11: SUPREME | V11: Shockstar | W11: EXEL | Z11: OBC | AA11: EBC | AB11: Cordtex | AC11: Cordtex | AD11: Cordtex | AE11: Cordtex | AF11: S/Fuse | AG11: Billwire | AH11: FUSE
C12: Super Power | E12: Super Power | G12: Senatel/Pulsar | I12: Senatel/Pulsar | K12: Super Power | M12: Magnum | O12: Senatel/Pulsar | R12: 2.4 | S12: 3.6 | T12: 2.4 | U12: 3.6 | V12: 2.4 | W12: 3.6 | X12: 2.4 | Y12: 4.9 | AB12: 5 | AC12: 10 | AD12: 6 | AE12: 40 | AH12: LIGHTER
C13: 31496 | E13: 17457 | G13: 11082 | I13: 21810 | K13: 17362 | M13: 18389 | O13: 21811 | Q13: 10128 | R13: 10962 | S13: 15427 | T13: 16623 | U13: 16967 | V13: 28230 | W13: 10966 | X13: 10965 | Y13: 21809 | Z13: 11966 | AA13: 11089 | AB13: 10960 | AC13: 10961 | AD13: 10839 | AE13: 10959 | AF13: 12487 | AG13: 16823 | AH13: 11342
C14: Pcs | D14: Kls | E14: Pcs | F14: Kls | G14: Pcs | H14: Kls | I14: Pcs | J14: Kls | K14: Pcs | L14: Kls | M14: Pcs | N14: Kls | O14: Pcs | P14: Kls | Q14: Kls | R14: Pcs | S14: Pcs | T14: Pcs | U14: Pcs | V14: Pcs | W14: Pcs | X14: Pcs | Y14: Pcs | Z14: Pcs | AA14: Pcs | AB14: Mtrs | AC14: Mtrs | AD14: Mtrs | AE14: Mtrs | AF14: Mtrs | AG14: Mtrs | AH14: Pcs
A15: 45382 | B15: BEG. BALANCE | C15: ='2-18-24,2024'!C20 -> 0 | D15: ='2-18-24,2024'!D20 -> 0 | E15: ='3-24-30,2024'!E20 -> 37908 | F15: ='3-24-30,2024'!F20 -> 4556.25 | G15: ='3-24-30,2024'!G20 -> 26198 | H15: ='3-24-30,2024'!H20 -> 3046.2791 | I15: ='3-24-30,2024'!I20 -> 10750 | J15: ='3-24-30,2024'!J20 -> 1250 | K15: ='3-24-30,2024'!K20 -> 0 | L15: ='3-24-30,2024'!L20 -> 0 | ... AH15: ='3-24-30,2024'!AH20 -> 407
B16: Withdrawal of Stock from Main Magazine Mill
B17: TOTAL ON HAND | C17: =C15+C16 -> 0 | D17: =D15+D16 -> 0 | E17: =E15+E16 -> 37908 | F17: =F15+F16 -> 4556.25 | G17: =G15+G16 -> 26198 | H17: =H15+H16 -> 3046.2791 | I17: =I15+I16 -> 10750 | J17: =J15+J16 -> 1250 | ... AH17: =AH15+AH16 -> 407
B18: Less: Total Weekly Consumption | C18: 0 | D18: =C18/200*25 -> 0 | E18: 11059 | F18: =E18/208*25 -> 1329.2067 | G18: 5617 | H18: =G18/215*25 -> 653.13953 | I18: 0 | J18: =I18/135*25 -> 0 | K18: 0 | L18: =K18/150*25 -> 0 | M18: 0 | N18: =M18/150*25 -> 0 | P18: =O18/38*25 -> 0 | Q18: 4376 | R18: 0 | S18: 0 | T18: 4797 | U18: 0 | V18: 0 | W18: 354 | X18: 2429 | Y18: 0 | Z18: 980 | AA18: 28 | AB18: 710 | AC18: 2306 | AE18: 0 | AF18: =Z18*2.43 -> 2381.4 | AG18: 0 | AH18: 11
A19: 45388 | B19: STOCK BALANCE | C19: =C17-C18 -> 0 | D19: =D17-D18 -> 0 | E19: =E17-E18 -> 26849 | F19: =F17-F18 -> 3227.0433 | G19: =G17-G18 -> 20581 | H19: =H17-H18 -> 2393.1395 | I19: =I17-I18 -> 10750 | J19: =J17-J18 -> 1250 | ... AH19: =AH17-AH18 -> 396 | AL19: =400+392+2745.29 -> 3537.29
A20: MINE MAG. STOCK USABLE | C20: =C19 -> 0 | D20: =D19 -> 0 | E20: =E19 -> 26849 | F20: =F19 -> 3227.0433 | G20: =G19 -> 20581 | H20: =H19 -> 2393.1395 | I20: =I19 -> 10750 | J20: =J19 -> 1250 | ... AH20: =AH19 -> 396 | AL20: =10000-AL19 -> 6462.71
A23: Prepared by: | F23: Checked by: | Q23: Noted by: | W23: Approved by:
A26: AIHREIN T. BACLAAN | F26: NHOLL GREAL O. LOZADA | Q26: ENGR. RAFFY D. TORRES | W26: ENGR. EARL M. SON
A27: Mine Explosives Dept | F27: Mine Explosives Inventory Supervisor | Q27: Mine Explosives Manager | W27: Mines Manager

Sheet 4-7-13,2024
A1: PHILSAGA MINING CORPORATION
A2: Bayugan 3,Rosario Agusan del Sur
A4: EXPLOSIVE WEEKLY CONSUMPTION
A5: APRIL 7-13, 2024
A8: SUPPLIER | C8: MT. ROCK | G8: EXPEDITION | Q8: MT ROCK | R8: MT. ROCK | W8: EXPEDITION | Z8: MT ROCK | AB8: EXPEDITION | AC8: MT. ROCK | AF8: MT ROCK | AG8: MT ROCK | AH8: EXPEDITION
Q9: EXPEDITION | Z9: EXPEDITION | AF9: EXPEDITION
A10: DATE | B10: DESCRIPTION | C10: PACKAGE EMULSION | Q10: Anfo | R10: DETONATORS | AB10: DETONATING CORD
C11: 200 | E11: 208 | G11: 215 | I11: 135 | K11: 150 | M11: 150 | O11: 38 | R11: NONEL | T11: SUPREME | V11: Shockstar | W11: EXEL | Z11: OBC | AA11: EBC | AB11: Cordtex | AC11: Cordtex | AD11: Cordtex | AE11: Cordtex | AF11: S/Fuse | AG11: Billwire | AH11: FUSE
C12: Super Power | E12: Super Power | G12: Senatel/Pulsar | I12: Senatel/Pulsar | K12: Super Power | M12: Magnum | O12: Senatel/Pulsar | R12: 2.4 | S12: 3.6 | T12: 2.4 | U12: 3.6 | V12: 2.4 | W12: 3.6 | X12: 2.4 | Y12: 4.9 | AB12: 5 | AC12: 10 | AD12: 6 | AE12: 40 | AH12: LIGHTER
C13: 31496 | E13: 17457 | G13: 11082 | I13: 21810 | K13: 17362 | M13: 18389 | O13: 21811 | Q13: 10128 | R13: 10962 | S13: 15427 | T13: 16623 | U13: 16967 | V13: 28230 | W13: 10966 | X13: 10965 | Y13: 21809 | Z13: 11966 | AA13: 11089 | AB13: 10960 | AC13: 10961 | AD13: 10839 | AE13: 10959 | AF13: 12487 | AG13: 16823 | AH13: 11342
C14: Pcs | D14: Kls | E14: Pcs | F14: Kls | G14: Pcs | H14: Kls | I14: Pcs | J14: Kls | K14: Pcs | L14: Kls | M14: Pcs | N14: Kls | O14: Pcs | P14: Kls | Q14: Kls | R14: Pcs | S14: Pcs | T14: Pcs | U14: Pcs | V14: Pcs | W14: Pcs | X14: Pcs | Y14: Pcs | Z14: Pcs | AA14: Pcs | AB14: Mtrs | AC14: Mtrs | AD14: Mtrs | AE14: Mtrs | AF14: Mtrs | AG14: Mtrs | AH14: Pcs
A15: 45389 | B15: BEG. BALANCE | C15: ='2-18-24,2024'!C20 -> 0 | D15: ='2-18-24,2024'!D20 -> 0 | E15: ='3-31-4-6,2024'!E20 -> 26849 | F15: ='3-31-4-6,2024'!F20 -> 3227.0433 | G15: ='3-31-4-6,2024'!G20 -> 20581 | H15: ='3-31-4-6,2024'!H20 -> 2393.1395 | I15: ='3-31-4-6,2024'!I20 -> 10750 | J15: ='3-31-4-6,2024'!J20 -> 1250 | K15: ='3-31-4-6,2024'!K20 -> 0 | L15: ='3-31-4-6,2024'!L20 -> 0 | ... AH15: ='3-31-4-6,2024'!AH20 -> 396
B16: Withdrawal of Stock from Main Magazine Mill | E16: =100*208 -> 20800 | F16: =E16/208*25 -> 2500 | G16: =100*215 -> 21500 | H16: =G16/215*25 -> 2500 | I16: =50*215 -> 10750 | J16: =I16/215*25 -> 1250 | K16: 0 | L16: 0 | T16: =12*360 -> 4320 | X16: 4250 | Z16: 2000 | AA16: 30 | AB16: 1800 | AC16: 2000 | AF16: 2000
B17: TOTAL ON HAND | C17: =C15+C16 -> 0 | D17: =D15+D16 -> 0 | E17: =E15+E16 -> 47649 | F17: =F15+F16 -> 5727.0433 | G17: =G15+G16 -> 42081 | H17: =H15+H16 -> 4893.1395 | I17: =I15+I16 -> 21500 | J17: =J15+J16 -> 2500 | ... AH17: =AH15+AH16 -> 396
B18: Less: Total Weekly Consumption | C18: 0 | D18: =C18/200*25 -> 0 | E18: 11873 | F18: =E18/208*25 -> 1427.0433 | G18: 6535 | H18: =G18/215*25 -> 759.88372 | I18: 0 | J18: =I18/135*25 -> 0 | K18: 0 | L18: =K18/150*25 -> 0 | M18: 0 | N18: =M18/150*25 -> 0 | P18: =O18/38*25 -> 0 | Q18: 5795 | R18: 0 | S18: 0 | T18: 5174 | U18: 0 | V18: 0 | W18: 195 | X18: 4025 | Y18: 0 | Z18: 1080 | AA18: 18 | AB18: 337 | AC18: 3330 | AE18: 0 | AF18: =Z18*2.43 -> 2624.4 | AG18: 0 | AH18: 8
A19: 45395 | B19: STOCK BALANCE | C19: =C17-C18 -> 0 | D19: =D17-D18 -> 0 | E19: =E17-E18 -> 35776 | F19: =F17-F18 -> 4300 | G19: =G17-G18 -> 35546 | H19: =H17-H18 -> 4133.2558 | I19: =I17-I18 -> 21500 | J19: =J17-J18 -> 2500 | ... AH19: =AH17-AH18 -> 388 | AL19: =400+392+2745.29 -> 3537.29
A20: MINE MAG. STOCK USABLE | C20: =C19 -> 0 | D20: =D19 -> 0 | E20: =E19 -> 35776 | F20: =F19 -> 4300 | G20: =G19 -> 35546 | H20: =H19 -> 4133.2558 | I20: =I19 -> 21500 | J20: =J19 -> 2500 | ... AH20: =AH19 -> 388 | AL20: =10000-AL19 -> 6462.71
A23: Prepared by: | F23: Checked by: | Q23: Noted by: | W23: Approved by:
A26: AIHREIN T. BACLAAN | F26: NHOLL GREAL O. LOZADA | Q26: ENGR. EDWIN B. BATAL | W26: ENGR. EARL M. SON
A27: Mine Explosives Dept | F27: Mine Explosives Inventory Supervisor | Q27: Mine Explosives Asst. Manager | W27: Mines Manager

Sheet 4-14-20,2024
A1: PHILSAGA MINING CORPORATION
A2: Bayugan 3,Rosario Agusan del Sur
A4: EXPLOSIVE WEEKLY CONSUMPTION
A5: APRIL 14-20, 2024
A8: SUPPLIER | C8: MT. ROCK | G8: EXPEDITION | Q8: MT ROCK | R8: MT. ROCK | W8: EXPEDITION | Z8: MT ROCK | AB8: EXPEDITION | AC8: MT. ROCK | AF8: MT ROCK | AG8: MT ROCK | AH8: EXPEDITION
Q9: EXPEDITION | Z9: EXPEDITION | AF9: EXPEDITION
A10: DATE | B10: DESCRIPTION | C10: PACKAGE EMULSION | Q10: Anfo | R10: DETONATORS | AB10: DETONATING CORD
C11: 200 | E11: 208 | G11: 215 | I11: 135 | K11: 150 | M11: 150 | O11: 38 | R11: NONEL | T11: SUPREME | V11: Shockstar | W11: EXEL | Z11: OBC | AA11: EBC | AB11: Cordtex | AC11: Cordtex | AD11: Cordtex | AE11: Cordtex | AF11: S/Fuse | AG11: Billwire | AH11: FUSE
C12: Super Power | E12: Super Power | G12: Senatel/Pulsar | I12: Senatel/Pulsar | K12: Super Power | M12: Magnum | O12: Senatel/Pulsar | R12: 2.4 | S12: 3.6 | T12: 2.4 | U12: 3.6 | V12: 2.4 | W12: 3.6 | X12: 2.4 | Y12: 4.9 | AB12: 5 | AC12: 10 | AD12: 6 | AE12: 40 | AH12: LIGHTER
C13: 31496 | E13: 17457 | G13: 11082 | I13: 21810 | K13: 17362 | M13: 18389 | O13: 21811 | Q13: 10128 | R13: 10962 | S13: 15427 | T13: 16623 | U13: 16967 | V13: 28230 | W13: 10966 | X13: 10965 | Y13: 21809 | Z13: 11966 | AA13: 11089 | AB13: 10960 | AC13: 10961 | AD13: 10839 | AE13: 10959 | AF13: 12487 | AG13: 16823 | AH13: 11342
C14: Pcs | D14: Kls | E14: Pcs | F14: Kls | G14: Pcs | H14: Kls | I14: Pcs | J14: Kls | K14: Pcs | L14: Kls | M14: Pcs | N14: Kls | O14: Pcs | P14: Kls | Q14: Kls | R14: Pcs | S14: Pcs | T14: Pcs | U14: Pcs | V14: Pcs | W14: Pcs | X14: Pcs | Y14: Pcs | Z14: Pcs | AA14: Pcs | AB14: Mtrs | AC14: Mtrs | AD14: Mtrs | AE14: Mtrs | AF14: Mtrs | AG14: Mtrs | AH14: Pcs
