Workbook

Sheet 8-1-7,2023
A10: TIGERWAY DECLINE PROJECT - WEEKLY CONSUMPTION
A11: AUGUST 1-7,2023
A14: SUPPLIER | D14: MT. ROCK
A16: DATE | B16: DESCRIPTION | D16: EMULSION | F16: EMULSION | H16: Dyna | J16: EMULSION | L16: EMULSION | N16: Dyna | P16: EMULSION | R16: EMULSION | T16: Pentex | U16: Anfo | V16: S/Fuse | W16: S/Fuse | X16: OBC | Y16: SHOCKSTAR | Z16: SUPREME | AA16: NEOCORD | AB16: DETCORD | AC16: Billwire | AD16: EBC
D17: 62 | F17: 36 | H17: 200 | J17: 208 | L17: 150 | N17: 150 | P17: 91 | R17: 135 | T17: Spider | V17: (savings) | Y17: 4.8 | Z17: 4.9 | AA17: 10 | AB17: 40
D18: Neogel 901 | F18: Emulex | H18: Superdyne | J18: EMULEX | L18: Super Power | N18: Senatel/Pulsar | P18: Netro EM | R18: Senatel/Pulsar
D19: Pcs | E19: Kls | F19: Pcs | G19: Kls | H19: Pcs | I19: Kls | J19: Pcs | K19: Kls | L19: Pcs | M19: Kls | N19: Pcs | O19: Kls | P19: Pcs | Q19: Kls | R19: Pcs | S19: Kls | T19: Pcs | U19: Kls | V19: Mtrs | W19: Mtrs | X19: Pcs | Y19: Pcs | Z19: Pcs | AA19: Mtrs | AB19: Mtrs | AC19: Mtrs | AD19: Pcs
A20: 45139 | B20: Beginning Balance | D20: =57*62 -> 3534 | E20: =D20/62*25 -> 1425 | F20: =45*36 -> 1620 | G20: =F20/36*25 -> 1125 | H20: =#REF! -> #REF! | I20: =#REF! -> #REF! | J20: 0 | K20: =J20/208*25 -> 0 | L20: 0 | M20: =L20/150*25 -> 0 | N20: =#REF! -> #REF! | O20: =#REF! -> #REF! | P20: 0 | Q20: =P20/91*25 -> 0 | R20: 0 | S20: =R20/135*25 -> 0 | T20: =#REF! -> #REF! | U20: =39*25 -> 975 | V20: =#REF! -> #REF! | W20: 2040 | X20: 182 | Y20: 1818 | Z20: 1007 | AA20: 1970 | AB20: 1460 | AC20: 300 | AD20: 0
A21: Entry From Consignee Magazine | D21: =60*62 -> 3720 | E21: =D21/62*25 -> 1500 | F21: =160*36 -> 5760 | G21: =F21/36*25 -> 4000 | P21: =20*92 -> 1840 | Q21: =P21/91*25 -> 505.49451 | U21: 0 | W21: 1000 | X21: 100 | Y21: 2302 | Z21: 2200 | AA21: 2000 | AB21: 1500 | AC21: 0 | AD21: 0
A22: Total Stock On Hand | D22: =D20+D21 -> 7254 | E22: =E20+E21 -> 2925 | F22: =F20+F21 -> 7380 | G22: =G20+G21 -> 5125 | H22: =H20+H21 -> #REF! | I22: =I20+I21 -> #REF! | J22: =J20+J21 -> 0 | K22: =K20+K21 -> 0 | ... AD22: =AD20+AD21 -> 0
A23: Less: Total Weekly Consumption | D23: =7*62 -> 434 | E23: =D23/62*25 -> 175 | F23: =38*36 -> 1368 | G23: =F23/36*25 -> 950 | H23: =#REF! -> #REF! | I23: =#REF! -> #REF! | J23: 0 | K23: =J23/208*25 -> 0 | L23: 0 | M23: =L23/150*25 -> 0 | N23: 0 | O23: =N23/150*20 -> 0 | P23: =3*92 -> 276 | Q23: =P23/91*25 -> 75.824176 | R23: 0 | S23: =R23/135*25 -> 0 | T23: - | U23: 0 | W23: 100 | X23: 24 | Y23: 255 | Z23: 112 | AA23: 360 | AB23: 200 | AC23: 0 | AD23: 0
A24: 45145 | B24: Remaining Stock Balance | D24: =D22-D23 -> 6820 | E24: =E22-E23 -> 2750 | F24: =F22-F23 -> 6012 | G24: =G22-G23 -> 4175 | H24: =H22-H23 -> #REF! | I24: =I22-I23 -> #REF! | J24: =J22-J23 -> 0 | K24: =K22-K23 -> 0 | ... AD24: =AD22-AD23 -> 0
A27: Prepared by: | E27: Confirmed by: | R27: Certified correct by: | W27: Review and Noted by:
A30: MR. JUN RAY C. ENDICO | E30: MR. RAFFY D. TORRES | R30: ENGR. EDWIN B. BATAL | W30: ENGR. JOHN PAUHL T. NAVARRO
A31: Drill and Blast Engineer | E31: Mine Explosives Manager | R31: Mine Explosive Asst. Manager | W31: Tigerway Project Manager
A32: Mount Rock Powder Corp. | E32: PHILSAGA MINING CORPORATION | V32: Mine Explosives Manager | W32: PHILSAGA MINING CORPORATION
A33: Blaster License: FPDJ10-090819-04922 | E33: Blaster License: FKB15 - 080917- 04562

Sheet 8-8-14,2023
A10: TIGERWAY DECLINE PROJECT - WEEKLY CONSUMPTION
A11: AUGUST 8-14, 2023
A14: SUPPLIER | D14: MT. ROCK
A16: DATE | B16: DESCRIPTION | D16: EMULSION | F16: EMULSION | H16: Dyna | J16: EMULSION | L16: EMULSION | N16: Dyna | P16: EMULSION | R16: EMULSION | T16: Pentex | U16: Anfo | V16: S/Fuse | W16: S/Fuse | X16: OBC | Y16: SHOCKSTAR | Z16: SUPREME | AA16: NEOCORD | AB16: DETCORD | AC16: Billwire | AD16: EBC
D17: 62 | F17: 36 | H17: 200 | J17: 208 | L17: 150 | N17: 150 | P17: 91 | R17: 135 | T17: Spider | V17: (savings) | Y17: 4.8 | Z17: 4.9 | AA17: 10 | AB17: 40
D18: Neogel 901 | F18: Emulex | H18: Superdyne | J18: EMULEX | L18: Super Power | N18: Senatel/Pulsar | P18: Netro EM | R18: Senatel/Pulsar
D19: Pcs | E19: Kls | F19: Pcs | G19: Kls | H19: Pcs | I19: Kls | J19: Pcs | K19: Kls | L19: Pcs | M19: Kls | N19: Pcs | O19: Kls | P19: Pcs | Q19: Kls | R19: Pcs | S19: Kls | T19: Pcs | U19: Kls | V19: Mtrs | W19: Mtrs | X19: Pcs | Y19: Pcs | Z19: Pcs | AA19: Mtrs | AB19: Mtrs | AC19: Mtrs | AD19: Pcs
A20: 45146 | B20: Beginning Balance | D20: ='8-1-7,2023'!D24 -> 6820 | E20: ='8-1-7,2023'!E24 -> 2750 | F20: ='8-1-7,2023'!F24 -> 6012 | G20: ='8-1-7,2023'!G24 -> 4175 | H20: ='8-1-7,2023'!H24 -> #REF! | I20: ='8-1-7,2023'!I24 -> #REF! | J20: ='8-1-7,2023'!J24 -> 0 | K20: ='8-1-7,2023'!K24 -> 0 | ... AD20: ='8-1-7,2023'!AD24 -> 0
A21: Entry From Consignee Magazine
A22: Total Stock On Hand | D22: =D20+D21 -> 6820 | E22: =E20+E21 -> 2750 | F22: =F20+F21 -> 6012 | G22: =G20+G21 -> 4175 | H22: =H20+H21 -> #REF! | I22: =I20+I21 -> #REF! | J22: =J20+J21 -> 0 | K22: =K20+K21 -> 0 | ... AD22: =AD20+AD21 -> 0
A23: Less: Total Weekly Consumption | D23: =5*62 -> 310 | E23: =D23/92*25 -> 84.23913 | F23: 1800 | G23: =F23/36*25 -> 1250 | H23: =#REF! -> #REF! | I23: =#REF! -> #REF! | J23: 0 | K23: =J23/208*25 -> 0 | L23: 0 | M23: =L23/150*25 -> 0 | N23: 0 | O23: =N23/150*20 -> 0 | P23: =92*4 -> 368 | Q23: =P23/91*25 -> 101.0989 | R23: 0 | S23: =R23/135*25 -> 0 | T23: - | U23: 0 | W23: 175 | X23: 47 | Y23: 672 | Z23: 214 | AA23: 505 | AB23: 350 | AC23: 0 | AD23: 0
A24: 45152 | B24: Remaining Stock Balance | D24: =D22-D23 -> 6510 | E24: =E22-E23 -> 2665.7609 | F24: =F22-F23 -> 4212 | G24: =G22-G23 -> 2925 | H24: =H22-H23 -> #REF! | I24: =I22-I23 -> #REF! | J24: =J22-J23 -> 0 | K24: =K22-K23 -> 0 | ... AD24: =AD22-AD23 -> 0
A27: Prepared by: | E27: Confirmed by: | R27: Certified correct by: | W27: Review and Noted by:
A30: MR. JUN RAY C. ENDICO | E30: MR. RAFFY D. TORRES | R30: ENGR. EDWIN B. BATAL | W30: ENGR. JOHN PAUHL T. NAVARRO
A31: Drill and Blast Engineer | E31: Mine Explosives Manager | R31: Mine Explosive Asst. Manager | W31: Tigerway Project Manager
A32: Mount Rock Powder Corp. | E32: PHILSAGA MINING CORPORATION | V32: Mine Explosives Manager | W32: PHILSAGA MINING CORPORATION
A33: Blaster License: FPDJ10-090819-04922 | E33: Blaster License: FKB15 - 080917- 04562

Sheet 8-15-21,2023
A10: TIGERWAY DECLINE PROJECT - WEEKLY CONSUMPTION
A11: AUGUST 15-21, 2023
A14: SUPPLIER | D14: MT. ROCK
A16: DATE | B16: DESCRIPTION | D16: EMULSION | F16: EMULSION | H16: Dyna | J16: EMULSION | L16: EMULSION | N16: Dyna | P16: EMULSION | R16: EMULSION | T16: Pentex | U16: Anfo | V16: S/Fuse | W16: S/Fuse | X16: OBC | Y16: SHOCKSTAR | Z16: SUPREME | AA16: NEOCORD | AB16: DETCORD | AC16: Billwire | AD16: EBC
D17: 62 | F17: 36 | H17: 200 | J17: 208 | L17: 150 | N17: 150 | P17: 91 | R17: 135 | T17: Spider | V17: (savings) | Y17: 4.8 | Z17: 4.9 | AA17: 10 | AB17: 40
D18: Neogel 901 | F18: Emulex | H18: Superdyne | J18: EMULEX | L18: Super Power | N18: Senatel/Pulsar | P18: Netro EM | R18: Senatel/Pulsar
D19: Pcs | E19: Kls | F19: Pcs | G19: Kls | H19: Pcs | I19: Kls | J19: Pcs | K19: Kls | L19: Pcs | M19: Kls | N19: Pcs | O19: Kls | P19: Pcs | Q19: Kls | R19: Pcs | S19: Kls | T19: Pcs | U19: Kls | V19: Mtrs | W19: Mtrs | X19: Pcs | Y19: Pcs | Z19: Pcs | AA19: Mtrs | AB19: Mtrs | AC19: Mtrs | AD19: Pcs
A20: 45146 | B20: Beginning Balance | D20: ='8-8-14,2023'!D24 -> 6510 | E20: ='8-8-14,2023'!E24 -> 2665.7609 | F20: ='8-8-14,2023'!F24 -> 4212 | G20: ='8-8-14,2023'!G24 -> 2925 | H20: ='8-8-14,2023'!H24 -> #REF! | I20: ='8-8-14,2023'!I24 -> #REF! | J20: ='8-8-14,2023'!J24 -> 0 | K20: ='8-8-14,2023'!K24 -> 0 | ... AD20: ='8-8-14,2023'!AD24 -> 0
A21: Entry From Consignee Magazine | E21: =D21/92*25 -> 0 | F21: =605*36 -> 21780 | G21: =F21/36*25 -> 15125 | Q21: =P21/92*25 -> 0 | U21: 0 | W21: 1000 | X21: 200 | Y21: 2379 | Z21: 1980 | AA21: 2000 | AB21: 1500 | AC21: 0 | AD21: 0
A22: Total Stock On Hand | D22: =D20+D21 -> 6510 | E22: =E20+E21 -> 2665.7609 | F22: =F20+F21 -> 25992 | G22: =G20+G21 -> 18050 | H22: =H20+H21 -> #REF! | I22: =I20+I21 -> #REF! | J22: =J20+J21 -> 0 | K22: =K20+K21 -> 0 | ... AD22: =AD20+AD21 -> 0
A23: Less: Total Weekly Consumption | D23: 62 | E23: =D23/62*25 -> 25 | F23: =180+108+360+216 -> 864 | G23: =F23/36*25 -> 600 | H23: =#REF! -> #REF! | I23: =#REF! -> #REF! | J23: 0 | K23: =J23/208*25 -> 0 | L23: 0 | M23: =L23/150*25 -> 0 | N23: 0 | O23: =N23/150*20 -> 0 | P23: 91 | Q23: =P23/91*25 -> 25 | R23: 0 | S23: =R23/135*25 -> 0 | T23: - | U23: 0 | W23: =45+20 -> 65 | X23: 20 | Y23: =48+38+69+65 -> 220 | Z23: =17+15+20+20 -> 72 | AA23: =20+15+70+70 -> 175 | AB23: 100 | AC23: 0 | AD23: 0
A24: 45152 | B24: Remaining Stock Balance | D24: =D22-D23 -> 6448 | E24: =E22-E23 -> 2640.7609 | F24: =F22-F23 -> 25128 | G24: =G22-G23 -> 17450 | H24: =H22-H23 -> #REF! | I24: =I22-I23 -> #REF! | J24: =J22-J23 -> 0 | K24: =K22-K23 -> 0 | ... AD24: =AD22-AD23 -> 0
A27: Prepared by: | E27: Confirmed by: | R27: Certified correct by: | W27: Review and Noted by:
A30: MR. JUN RAY C. ENDICO | E30: MR. RAFFY D. TORRES | R30: ENGR. EDWIN B. BATAL | W30: ENGR. JOHN PAUHL T. NAVARRO
A31: Drill and Blast Engineer | E31: Mine Explosives Manager | R31: Mine Explosive Asst. Manager | W31: Tigerway Project Manager
A32: Mount Rock Powder Corp. | E32: PHILSAGA MINING CORPORATION | V32: Mine Explosives Manager | W32: PHILSAGA MINING CORPORATION
A33: Blaster License: FPDJ10-090819-04922 | E33: Blaster License: FKB15 - 080917- 04562

Sheet 8-22-30,2023
A10: TIGERWAY DECLINE PROJECT - WEEKLY CONSUMPTION
A11: AUGUST 22-31, 2023
A14: SUPPLIER | D14: MT. ROCK
A16: DATE | B16: DESCRIPTION | D16: EMULSION | F16: EMULSION | H16: Dyna | J16: EMULSION | L16: EMULSION | N16: Dyna | P16: EMULSION | R16: EMULSION | T16: Pentex | U16: Anfo | V16: S/Fuse | W16: S/Fuse | X16: OBC | Y16: SHOCKSTAR | Z16: SUPREME | AA16: NEOCORD | AB16: DETCORD | AC16: Billwire | AD16: EBC
D17: 62 | F17: 36 | H17: 200 | J17: 208 | L17: 150 | N17: 150 | P17: 91 | R17: 135 | T17: Spider | V17: (savings) | Y17: 4.8 | Z17: 4.9 | AA17: 10 | AB17: 40
D18: Neogel 901 | F18: Emulex | H18: Superdyne | J18: EMULEX | L18: Super Power | N18: Senatel/Pulsar | P18: Netro EM | R18: Senatel/Pulsar
D19: Pcs | E19: Kls | F19: Pcs | G19: Kls | H19: Pcs | I19: Kls | J19: Pcs | K19: Kls | L19: Pcs | M19: Kls | N19: Pcs | O19: Kls | P19: Pcs | Q19: Kls | R19: Pcs | S19: Kls | T19: Pcs | U19: Kls | V19: Mtrs | W19: Mtrs | X19: Pcs | Y19: Pcs | Z19: Pcs | AA19: Mtrs | AB19: Mtrs | AC19: Mtrs | AD19: Pcs
A20: 45160 | B20: Beginning Balance | D20: =6448+682 -> 7130 | E20: 2640.7609 | F20: =25128+543 -> 25671 | G20: 17450 | H20: #REF! | I20: #REF! | J20: 0 | K20: 0 | L20: 0 | M20: 0 | N20: #REF! | O20: #REF! | P20: =1105+639 -> 1744 | Q20: 300.27174 | R20: 0 | S20: 0 | T20: #REF! | U20: 975 | V20: #REF! | W20: =3700+275 -> 3975 | X20: =391+71 -> 462 | Y20: =5352+927 -> 6279 | Z20: =4789+326 -> 5115 | AA20: =4930+865 -> 5795 | AB20: =3810+550 -> 4360 | AC20: 300 | AD20: 0
A21: Entry From Consignee Magazine
A22: Total Stock On Hand | D22: =D20+D21 -> 7130 | E22: =E20+E21 -> 2640.7609 | F22: =F20+F21 -> 25671 | G22: =G20+G21 -> 17450 | H22: =H20+H21 -> #REF! | I22: =I20+I21 -> #REF! | J22: =J20+J21 -> 0 | K22: =K20+K21 -> 0 | ... AD22: =AD20+AD21 -> 0
A23: Less: Total Weekly Consumption | D23: 62 | E23: =D23/62*25 -> 25 | F23: =16+4+18+18+19 -> 75 | G23: =F23/36*25 -> 52.083333 | H23: =#REF! -> #REF! | I23: =#REF! -> #REF! | J23: 0 | K23: =J23/208*25 -> 0 | L23: 0 | M23: =L23/150*25 -> 0 | N23: 0 | O23: =N23/150*20 -> 0 | P23: =91+91+91+91 -> 364 | Q23: =P23/91*25 -> 100 | R23: 0 | S23: =R23/135*25 -> 0 | T23: - | U23: 0 | W23: =20+15+20+20+20 -> 95 | X23: 25 | Y23: =120+40+134+136+124 -> 554 | Z23: =41+17+44+44+42 -> 188 | AA23: =70+20+100+120+120 -> 430 | AB23: =50+50+100+50 -> 250 | AC23: 0 | AD23: 0
A24: 45169 | B24: Remaining Stock Balance | D24: =D22-D23 -> 7068 | E24: =E22-E23 -> 2615.7609 | F24: =F22-F23 -> 25596 | G24: =G22-G23 -> 17397.917 | H24: =H22-H23 -> #REF! | I24: =I22-I23 -> #REF! | J24: =J22-J23 -> 0 | K24: =K22-K23 -> 0 | ... AD24: =AD22-AD23 -> 0
A27: Prepared by: | E27: Confirmed by: | R27: Certified correct by: | W27: Review and Noted by:
A30: MR. JUN RAY C. ENDICO | E30: MR. RAFFY D. TORRES | R30: ENGR. EDWIN B. BATAL | W30: ENGR. JOHN PAUHL T. NAVARRO
A31: Drill and Blast Engineer | E31: Mine Explosives Manager | R31: Mine Explosive Asst. Manager | W31: Tigerway Project Manager
A32: Mount Rock Powder Corp. | E32: PHILSAGA MINING CORPORATION | V32: Mine Explosives Manager | W32: PHILSAGA MINING CORPORATION
A33: Blaster License: FPDJ10-090819-04922 | E33: Blaster License: FKB15 - 080917- 04562

Sheet 9-1-7,2023
A10: EXPLOSIVES WEEKLY CONSUMPTION - TIGERWAY DECLINE PROJECT
A11: SEPTEMBER 1-7,2023
A14: SUPPLIER | D14: MT. ROCK
A16: DATE | B16: DESCRIPTION | D16: EMULSION | F16: EMULSION | H16: Dyna | J16: EMULSION | L16: EMULSION | N16: Dyna | P16: EMULSION | R16: EMULSION | T16: Pentex | U16: Anfo | V16: S/Fuse | W16: S/Fuse | X16: OBC | Y16: SHOCKSTAR | Z16: SUPREME | AA16: NEOCORD | AB16: DETCORD | AC16: Billwire | AD16: EBC
D17: 62 | F17: 36 | H17: 200 | J17: 208 | L17: 150 | N17: 150 | P17: 91 | R17: 135 | T17: Spider | V17: (savings) | Y17: 4.8 | Z17: 4.9 | AA17: 10 | AB17: 40
D18: Neogel 901 | F18: Emulex | H18: Superdyne | J18: EMULEX | L18: Super Power | N18: Senatel/Pulsar | P18: Netro EM | R18: Senatel/Pulsar
D19: Pcs | E19: Kls | F19: Pcs | G19: Kls | H19: Pcs | I19: Kls | J19: Pcs | K19: Kls | L19: Pcs | M19: Kls | N19: Pcs | O19: Kls | P19: Pcs | Q19: Kls | R19: Pcs | S19: Kls | T19: Pcs | U19: Kls | V19: Mtrs | W19: Mtrs | X19: Pcs | Y19: Pcs | Z19: Pcs | AA19: Mtrs | AB19: Mtrs | AC19: Mtrs | AD19: Pcs
A20: 45170 | B20: Beginning Balance | D20: =95*62 -> 5890 | E20: 2640.7609 | F20: =603*36 -> 21708 | G20: 17450 | H20: #REF! | I20: #REF! | J20: 0 | K20: 0 | L20: 0 | M20: 0 | N20: #REF! | O20: #REF! | P20: =8*91 -> 728 | Q20: =P20/91*25 -> 200 | R20: 0 | S20: 0 | T20: #REF! | U20: =39*25 -> 975 | V20: #REF! | W20: 3605 | X20: 366 | Y20: 4798 | Z20: 4601 | AA20: 4500 | AB20: 3560 | AC20: 300 | AD20: 96
A21: Entry From Consignee Magazine
A22: Total Stock On Hand | D22: =D20+D21 -> 5890 | E22: =E20+E21 -> 2640.7609 | F22: =F20+F21 -> 21708 | G22: =G20+G21 -> 17450 | H22: =H20+H21 -> #REF! | I22: =I20+I21 -> #REF! | J22: =J20+J21 -> 0 | K22: =K20+K21 -> 0 | ... AD22: =AD20+AD21 -> 96
A23: Less: Total Weekly Consumption | D23: 0 | E23: =D23/62*25 -> 0 | F23: 3708 | G23: =F23/36*25 -> 2575 | H23: =#REF! -> #REF! | I23: =#REF! -> #REF! | J23: 0 | K23: =J23/208*25 -> 0 | L23: 0 | M23: =L23/150*25 -> 0 | N23: 0 | O23: =N23/150*20 -> 0 | P23: 728 | Q23: =P23/91*25 -> 200 | R23: 0 | S23: =R23/135*25 -> 0 | T23: - | U23: 0 | W23: 225 | X23: 58 | Y23: 691 | Z23: 252 | AA23: 775 | AB23: 500 | AC23: 0 | AD23: 0
A24: 45176 | B24: Remaining Stock Balance | D24: =D22-D23 -> 5890 | E24: =E22-E23 -> 2640.7609 | F24: =F22-F23 -> 18000 | G24: =G22-G23 -> 14875 | H24: =H22-H23 -> #REF! | I24: =I22-I23 -> #REF! | J24: =J22-J23 -> 0 | K24: =K22-K23 -> 0 | ... AD24: =AD22-AD23 -> 96
A27: Prepared by: | E27: Checked by: | R27: Certified correct by: | W27: Certified Correct by:
A30: MR. JUN RAY C. ENDICO | E30: MR. RAFFY D. TORRES | R30: ENGR. EDWIN B. BATAL | W30: ENGR. JOHN PAUHL T. NAVARRO
A31: Drill and Blast Engineer | E31: Mine Explosives Manager | R31: Mine Explosive Asst. Manager | W31: Tigerway Project Manager
A32: Mount Rock Powder Corp. | E32: PHILSAGA MINING CORPORATION | V32: Mine Explosives Manager | W32: PHILSAGA MINING CORPORATION
A33: Blaster License: FPDJ10-090819-04922 | E33: Blaster License: FKB15 - 080917- 04562

Sheet 9-8-14,2023
A10: EXPLOSIVES WEEKLY CONSUMPTION - TIGERWAY DECLINE PROJECT
A11: SEPTEMBER 8-14,2023
A14: SUPPLIER | D14: MT. ROCK
A16: DATE | B16: DESCRIPTION | D16: EMULSION | F16: EMULSION | H16: Dyna | J16: EMULSION | L16: EMULSION | N16: Dyna | P16: EMULSION | R16: EMULSION | T16: Pentex | U16: Anfo | V16: S/Fuse | W16: S/Fuse | X16: OBC | Y16: SHOCKSTAR | Z16: SUPREME | AA16: NEOCORD | AB16: DETCORD | AC16: Billwire | AD16: EBC
D17: 62 | F17: 36 | H17: 200 | J17: 208 | L17: 150 | N17: 150 | P17: 91 | R17: 135 | T17: Spider | V17: (savings) | Y17: 4.8 | Z17: 4.9 | AA17: 10 | AB17: 40
D18: Neogel 901 | F18: Emulex | H18: Superdyne | J18: EMULEX | L18: Super Power | N18: Senatel/Pulsar | P18: Netro EM | R18: Senatel/Pulsar
D19: Pcs | E19: Kls | F19: Pcs | G19: Kls | H19: Pcs | I19: Kls | J19: Pcs | K19: Kls | L19: Pcs | M19: Kls | N19: Pcs | O19: Kls | P19: Pcs | Q19: Kls | R19: Pcs | S19: Kls | T19: Pcs | U19: Kls | V19: Mtrs | W19: Mtrs | X19: Pcs | Y19: Pcs | Z19: Pcs | AA19: Mtrs | AB19: Mtrs | AC19: Mtrs | AD19: Pcs
A20: 45177 | B20: Beginning Balance | D20: ='9-1-7,2023'!D24 -> 5890 | E20: ='9-1-7,2023'!E24 -> 2640.7609 | F20: ='9-1-7,2023'!F24 -> 18000 | G20: ='9-1-7,2023'!G24 -> 14875 | H20: ='9-1-7,2023'!H24 -> #REF! | I20: ='9-1-7,2023'!I24 -> #REF! | J20: ='9-1-7,2023'!J24 -> 0 | K20: ='9-1-7,2023'!K24 -> 0 | ... AD20: ='9-1-7,2023'!AD24 -> 96
A21: Entry From Consignee Magazine
A22: Total Stock On Hand | D22: =D20+D21 -> 5890 | E22: =E20+E21 -> 2640.7609 | F22: =F20+F21 -> 18000 | G22: =G20+G21 -> 14875 | H22: =H20+H21 -> #REF! | I22: =I20+I21 -> #REF! | J22: =J20+J21 -> 0 | K22: =K20+K21 -> 0 | ... AD22: =AD20+AD21 -> 96
A23: Less: Total Weekly Consumption | D23: 0 | E23: =D23/62*25 -> 0 | F23: 3348 | G23: =F23/36*25 -> 2325 | H23: =#REF! -> #REF! | I23: =#REF! -> #REF! | J23: 0 | K23: =J23/208*25 -> 0 | L23: 0 | M23: =L23/150*25 -> 0 | N23: 0 | O23: =N23/150*20 -> 0 | P23: 0 | Q23: =P23/91*25 -> 0 | R23: 0 | S23: =R23/135*25 -> 0 | T23: - | U23: 0 | W23: 200 | X23: 50 | Y23: 614 | Z23: 200 | AA23: 675 | AB23: 500 | AC23: 0 | AD23: 0
A24: 45183 | B24: Remaining Stock Balance | D24: =D22-D23 -> 5890 | E24: =E22-E23 -> 2640.7609 | F24: =F22-F23 -> 14652 | G24: =G22-G23 -> 12550 | H24: =H22-H23 -> #REF! | I24: =I22-I23 -> #REF! | J24: =J22-J23 -> 0 | K24: =K22-K23 -> 0 | ... AD24: =AD22-AD23 -> 96
A27: Prepared by: | E27: Checked by: | R27: Certified correct by: | W27: Certified Correct by:
A30: MR. JUN RAY C. ENDICO | E30: MR. RAFFY D. TORRES | R30: ENGR. EDWIN B. BATAL | W30: ENGR. JOHN PAUHL T. NAVARRO
A31: Drill and Blast Engineer | E31: Mine Explosives Manager | R31: Mine Explosive Asst. Manager | W31: Tigerway Project Manager
A32: Mount Rock Powder Corp. | E32: PHILSAGA MINING CORPORATION | V32: Mine Explosives Manager | W32: PHILSAGA MINING CORPORATION
A33: Blaster License: FPDJ10-090819-04922 | E33: Blaster License: FKB15 - 080917- 04562

Sheet 9-15-21,2023
A10: EXPLOSIVES WEEKLY CONSUMPTION - TIGERWAY DECLINE PROJECT
A11: SEPTEMBER 15-21,2023
A14: SUPPLIER | D14: MT. ROCK
A16: DATE | B16: DESCRIPTION | D16: EMULSION | F16: EMULSION | H16: Dyna | J16: EMULSION | L16: EMULSION | N16: Dyna | P16: EMULSION | R16: EMULSION | T16: Pentex | U16: Anfo | V16: S/Fuse | W16: S/Fuse | X16: OBC | Y16: SHOCKSTAR | Z16: SUPREME | AA16: NEOCORD | AB16: DETCORD | AC16: Billwire | AD16: EBC
D17: 62 | F17: 36 | H17: 200 | J17: 208 | L17: 150 | N17: 150 | P17: 91 | R17: 135 | T17: Spider | V17: (savings) | Y17: 4.8 | Z17: 4.9 | AA17: 10 | AB17: 40
D18: Neogel 901 | F18: Emulex | H18: Superdyne | J18: EMULEX | L18: Super Power | N18: Senatel/Pulsar | P18: Netro EM | R18: Senatel/Pulsar
D19: Pcs | E19: Kls | F19: Pcs | G19: Kls | H19: Pcs | I19: Kls | J19: Pcs | K19: Kls | L19: Pcs | M19: Kls | N19: Pcs | O19: Kls | P19: Pcs | Q19: Kls | R19: Pcs | S19: Kls | T19: Pcs | U19: Kls | V19: Mtrs | W19: Mtrs | X19: Pcs | Y19: Pcs | Z19: Pcs | AA19: Mtrs | AB19: Mtrs | AC19: Mtrs | AD19: Pcs
A20: 45184 | B20: Beginning Balance | D20: ='9-8-14,2023'!D24 -> 5890 | E20: ='9-8-14,2023'!E24 -> 2640.7609 | F20: ='9-8-14,2023'!F24 -> 14652 | G20: ='9-8-14,2023'!G24 -> 12550 | H20: ='9-8-14,2023'!H24 -> #REF! | I20: ='9-8-14,2023'!I24 -> #REF! | J20: ='9-8-14,2023'!J24 -> 0 | K20: ='9-8-14,2023'!K24 -> 0 | ... AD20: ='9-8-14,2023'!AD24 -> 96
A21: Entry From Consignee Magazine
A22: Total Stock On Hand | D22: =D20+D21 -> 5890 | E22: =E20+E21 -> 2640.7609 | F22: =F20+F21 -> 14652 | G22: =G20+G21 -> 12550 | H22: =H20+H21 -> #REF! | I22: =I20+I21 -> #REF! | J22: =J20+J21 -> 0 | K22: =K20+K21 -> 0 | ... AD22: =AD20+AD21 -> 96
A23: Less: Total Weekly Consumption | D23: 0 | E23: =D23/62*25 -> 0 | F23: 2916 | G23: =F23/36*25 -> 2025 | H23: =#REF! -> #REF! | I23: =#REF! -> #REF! | J23: 0 | K23: =J23/208*25 -> 0 | L23: 0 | M23: =L23/150*25 -> 0 | N23: 0 | O23: =N23/150*20 -> 0 | P23: 0 | Q23: =P23/91*25 -> 0 | R23: 0 | S23: =R23/135*25 -> 0 | T23: - | U23: 0 | W23: 150 | X23: 39 | Y23: 522 | Z23: 190 | AA23: 560 | AB23: 400 | AC23: 0 | AD23: 0
A24: 45190 | B24: Remaining Stock Balance | D24: =D22-D23 -> 5890 | E24: =E22-E23 -> 2640.7609 | F24: =F22-F23 -> 11736 | G24: =G22-G23 -> 10525 | H24: =H22-H23 -> #REF! | I24: =I22-I23 -> #REF! | J24: =J22-J23 -> 0 | K24: =K22-K23 -> 0 | ... AD24: =AD22-AD23 -> 96
A27: Prepared by: | E27: Checked by: | R27: Certified correct by: | W27: Certified Correct by:
A30: MR. JUN RAY C. ENDICO | E30: MR. RAFFY D. TORRES | R30: ENGR. EDWIN B. BATAL | W30: ENGR. JOHN PAUHL T. NAVARRO
A31: Drill and Blast Engineer | E31: Mine Explosives Manager | R31: Mine Explosive Asst. Manager | W31: Tigerway Project Manager
A32: Mount Rock Powder Corp. | E32: PHILSAGA MINING CORPORATION | V32: Mine Explosives Manager | W32: PHILSAGA MINING CORPORATION
A33: Blaster License: FPDJ10-090819-04922 | E33: Blaster License: FKB15 - 080917- 04562

Sheet 9-22-31,2023
A10: EXPLOSIVES WEEKLY CONSUMPTION - TIGERWAY DECLINE PROJECT
A11: SEPTEMBER 22-30,2023
A14: SUPPLIER | D14: MT. ROCK
A16: DATE | B16: DESCRIPTION | D16: EMULSION | F16: EMULSION | H16: Dyna | J16: EMULSION | L16: EMULSION | N16: Dyna | P16: EMULSION | R16: EMULSION | T16: Pentex | U16: Anfo | V16: S/Fuse | W16: S/Fuse | X16: OBC | Y16: SHOCKSTAR | Z16: SUPREME | AA16: NEOCORD | AB16: DETCORD | AC16: Billwire | AD16: EBC
D17: 62 | F17: 36 | H17: 200 | J17: 208 | L17: 150 | N17: 150 | P17: 91 | R17: 135 | T17: Spider | V17: (savings) | Y17: 4.8 | Z17: 4.9 | AA17: 10 | AB17: 40
D18: Neogel 901 | F18: Emulex | H18: Superdyne | J18: EMULEX | L18: Super Power | N18: Senatel/Pulsar | P18: Netro EM | R18: Senatel/Pulsar
D19: Pcs | E19: Kls | F19: Pcs | G19: Kls | H19: Pcs | I19: Kls | J19: Pcs | K19: Kls | L19: Pcs | M19: Kls | N19: Pcs | O19: Kls | P19: Pcs | Q19: Kls | R19: Pcs | S19: Kls | T19: Pcs | U19: Kls | V19: Mtrs | W19: Mtrs | X19: Pcs | Y19: Pcs | Z19: Pcs | AA19: Mtrs | AB19: Mtrs | AC19: Mtrs | AD19: Pcs
A20: 45191 | B20: Beginning Balance | D20: ='9-15-21,2023'!D24 -> 5890 | E20: ='9-15-21,2023'!E24 -> 2640.7609 | F20: ='9-15-21,2023'!F24 -> 11736 | G20: ='9-15-21,2023'!G24 -> 10525 | H20: ='9-15-21,2023'!H24 -> #REF! | I20: ='9-15-21,2023'!I24 -> #REF! | J20: ='9-15-21,2023'!J24 -> 0 | K20: ='9-15-21,2023'!K24 -> 0 | ... AB20: ='9-15-21,2023'!AB24 -> 2160 | AC20: 300 | AD20: ='9-15-21,2023'!AD24 -> 96
A21: Entry From Consignee Magazine | E21: =D21/62*25 -> 0 | F21: =270*36 -> 9720 | G21: =F21/36*25 -> 6750 | P21: =30*91 -> 2730 | Q21: =P21/91*25 -> 750 | U21: 0 | W21: 1000 | X21: 200 | Y21: 2400 | Z21: 2420 | AA21: 3000 | AB21: 2100 | AC21: 0 | AD21: 0
A22: Total Stock On Hand | D22: =D20+D21 -> 5890 | E22: =E20+E21 -> 2640.7609 | F22: =F20+F21 -> 21456 | G22: =G20+G21 -> 17275 | H22: =H20+H21 -> #REF! | I22: =I20+I21 -> #REF! | J22: =J20+J21 -> 0 | K22: =K20+K21 -> 0 | ... AD22: =AD20+AD21 -> 96
A23: Less: Total Weekly Consumption | D23: 0 | E23: =D23/62*25 -> 0 | F23: 5508 | G23: =F23/36*25 -> 3825 | H23: =#REF! -> #REF! | I23: =#REF! -> #REF! | J23: 0 | K23: =J23/208*25 -> 0 | L23: 0 | M23: =L23/150*25 -> 0 | N23: 0 | O23: =N23/150*20 -> 0 | P23: 0 | Q23: =P23/91*25 -> 0 | R23: 0 | S23: =R23/135*25 -> 0 | T23: - | U23: 0 | W23: 250 | X23: 67 | Y23: 977 | Z23: 423 | AA23: 945 | AB23: 750 | AC23: 0 | AD23: 0
A24: 45199 | B24: Remaining Stock Balance | D24: =D22-D23 -> 5890 | E24: =E22-E23 -> 2640.7609 | F24: =F22-F23 -> 15948 | G24: =G22-G23 -> 13450 | H24: =H22-H23 -> #REF! | I24: =I22-I23 -> #REF! | J24: =J22-J23 -> 0 | K24: =K22-K23 -> 0 | ... AD24: =AD22-AD23 -> 96
A27: Prepared by: | E27: Checked by: | R27: Certified correct by: | W27: Certified Correct by:
A30: MR. JUN RAY C. ENDICO | E30: MR. RAFFY D. TORRES | R30: ENGR. EDWIN B. BATAL | W30: ENGR. JOHN PAUHL T. NAVARRO
A31: Drill and Blast Engineer | E31: Mine Explosives Manager | R31: Mine Explosive Asst. Manager | W31: Tigerway Project Manager
A32: Mount Rock Powder Corp. | E32: PHILSAGA MINING CORPORATION | V32: Mine Explosives Manager | W32: PHILSAGA MINING CORPORATION
A33: Blaster License: FPDJ10-090819-04922 | E33: Blaster License: FKB15 - 080917- 04562

Sheet 10-1-8,2023
A10: EXPLOSIVES WEEKLY CONSUMPTION - TIGERWAY DECLINE PROJECT
A11: OCTOBER 1-8,2023
A14: SUPPLIER | D14: MT. ROCK
A16: DATE | B16: DESCRIPTION | D16: EMULSION | F16: EMULSION | H16: Dyna | J16: EMULSION | L16: EMULSION | N16: Dyna | P16: EMULSION | R16: EMULSION | T16: Pentex | U16: Anfo | V16: S/Fuse | W16: S/Fuse | X16: OBC | Y16: SHOCKSTAR | Z16: SUPREME | AA16: NEOCORD | AB16: DETCORD | AC16: Billwire | AD16: EBC
D17: 62 | F17: 36 | H17: 200 | J17: 208 | L17: 150 | N17: 150 | P17: 91 | R17: 135 | T17: Spider | V17: (savings) | Y17: 4.8 | Z17: 4.9 | AA17: 10 | AB17: 40
D18: Neogel 901 | F18: Emulex | H18: Superdyne | J18: EMULEX | L18: Super Power | N18: Senatel/Pulsar | P18: Netro EM | R18: Senatel/Pulsar
D19: Pcs | E19: Kls | F19: Pcs | G19: Kls | H19: Pcs | I19: Kls | J19: Pcs | K19: Kls | L19: Pcs | M19: Kls | N19: Pcs | O19: Kls | P19: Pcs | Q19: Kls | R19: Pcs | S19: Kls | T19: Pcs | U19: Kls | V19: Mtrs | W19: Mtrs | X19: Pcs | Y19: Pcs | Z19: Pcs | AA19: Mtrs | AB19: Mtrs | AC19: Mtrs | AD19: Pcs
A20: 45200 | B20: Beginning Balance | D20: ='9-22-31,2023'!D24 -> 5890 | E20: ='9-22-31,2023'!E24 -> 2640.7609 | F20: ='9-22-31,2023'!F24 -> 15948 | G20: ='9-22-31,2023'!G24 -> 13450 | H20: ='9-22-31,2023'!H24 -> #REF! | I20: ='9-22-31,2023'!I24 -> #REF! | J20: ='9-22-31,2023'!J24 -> 0 | K20: ='9-22-31,2023'!K24 -> 0 | ... AD20: ='9-22-31,2023'!AD24 -> 96
A21: Entry From Consignee Magazine
A22: Total Stock On Hand | D22: =D20+D21 -> 5890 | E22: =E20+E21 -> 2640.7609 | F22: =F20+F21 -> 15948 | G22: =G20+G21 -> 13450 | H22: =H20+H21 -> #REF! | I22: =I20+I21 -> #REF! | J22: =J20+J21 -> 0 | K22: =K20+K21 -> 0 | ... AD22: =AD20+AD21 -> 96
A23: Less: Total Weekly Consumption | D23: 0 | E23: =D23/62*25 -> 0 | F23: =91*36 -> 3276 | G23: =F23/36*25 -> 2275 | H23: =#REF! -> #REF! | I23: =#REF! -> #REF! | J23: 0 | K23: =J23/208*25 -> 0 | L23: 0 | M23: =L23/150*25 -> 0 | N23: 0 | O23: =N23/150*20 -> 0 | P23: 819 | Q23: =P23/91*25 -> 225 | R23: 0 | S23: =R23/135*25 -> 0 | T23: - | U23: 0 | W23: 180 | X23: 45 | Y23: 567 | Z23: 269 | AA23: 600 | AB23: 450 | AC23: 0 | AD23: 0
A24: 45207 | B24: Remaining Stock Balance | D24: =D22-D23 -> 5890 | E24: =E22-E23 -> 2640.7609 | F24: =F22-F23 -> 12672 | G24: =G22-G23 -> 11175 | H24: =H22-H23 -> #REF! | I24: =I22-I23 -> #REF! | J24: =J22-J23 -> 0 | K24: =K22-K23 -> 0 | ... AD24: =AD22-AD23 -> 96
A27: Prepared by: | E27: Checked by: | R27: Certified correct by: | W27: Certified Correct by:
A30: MR. JUN RAY C. ENDICO | E30: MR. EDWIN B. BATAL | R30: ENGR. EDWIN B. BATAL | W30: ENGR. JOHN PAUHL T. NAVARRO
A31: Drill and Blast Engineer | E31: Mine Explosives Asst. Manager | R31: Mine Explosive Asst. Manager | W31: Tigerway Project Manager
A32: Mount Rock Powder Corp. | E32: PHILSAGA MINING CORPORATION | V32: Mine Explosives Manager | W32: PHILSAGA MINING CORPORATION
A33: Blaster License: FPDJ10-090819-04922 | E33: Blaster License: FKB15 - 080917- 04561

Sheet 10-9-15,2023
A10: EXPLOSIVES WEEKLY CONSUMPTION - TIGERWAY DECLINE PROJECT
A11: OCTOBER 9-15,2023
A14: SUPPLIER | D14: MT. ROCK
A16: DATE | B16: DESCRIPTION | D16: EMULSION | F16: EMULSION | H16: Dyna | J16: EMULSION | L16: EMULSION | N16: Dyna | P16: EMULSION | R16: EMULSION | T16: Pentex | U16: Anfo | V16: S/Fuse | W16: S/Fuse | X16: OBC | Y16: SHOCKSTAR | Z16: SUPREME | AA16: NEOCORD | AB16: DETCORD | AC16: Billwire | AD16: EBC
D17: 62 | F17: 36 | H17: 200 | J17: 208 | L17: 150 | N17: 150 | P17: 91 | R17: 135 | T17: Spider | V17: (savings) | Y17: 4.8 | Z17: 4.9 | AA17: 10 | AB17: 40
D18: Neogel 901 | F18: Emulex | H18: Superdyne | J18: EMULEX | L18: Super Power | N18: Senatel/Pulsar | P18: Netro EM | R18: Senatel/Pulsar
D19: Pcs | E19: Kls | F19: Pcs | G19: Kls | H19: Pcs | I19: Kls | J19: Pcs | K19: Kls | L19: Pcs | M19: Kls | N19: Pcs | O19: Kls | P19: Pcs | Q19: Kls | R19: Pcs | S19: Kls | T19: Pcs | U19: Kls | V19: Mtrs | W19: Mtrs | X19: Pcs | Y19: Pcs | Z19: Pcs | AA19: Mtrs | AB19: Mtrs | AC19: Mtrs | AD19: Pcs
A20: 45208 | B20: Beginning Balance | D20: ='10-1-8,2023'!D24 -> 5890 | E20: ='10-1-8,2023'!E24 -> 2640.7609 | F20: ='10-1-8,2023'!F24 -> 12672 | G20: ='10-1-8,2023'!G24 -> 11175 | H20: ='10-1-8,2023'!H24 -> #REF! | I20: ='10-1-8,2023'!I24 -> #REF! | J20: ='10-1-8,2023'!J24 -> 0 | K20: ='10-1-8,2023'!K24 -> 0 | ... AD20: ='10-1-8,2023'!AD24 -> 96
A21: Entry From Consignee Magazine
A22: Total Stock On Hand | D22: =D20+D21 -> 5890 | E22: =E20+E21 -> 2640.7609 | F22: =F20+F21 -> 12672 | G22: =G20+G21 -> 11175 | H22: =H20+H21 -> #REF! | I22: =I20+I21 -> #REF! | J22: =J20+J21 -> 0 | K22: =K20+K21 -> 0 | ... AD22: =AD20+AD21 -> 96
A23: Less: Total Weekly Consumption | D23: 558 | E23: =D23/62*25 -> 225 | F23: 3024 | G23: =F23/36*25 -> 2100 | H23: =#REF! -> #REF! | I23: =#REF! -> #REF! | J23: 0 | K23: =J23/208*25 -> 0 | L23: 0 | M23: =L23/150*25 -> 0 | N23: 0 | O23: =N23/150*20 -> 0 | P23: 910 | Q23: =P23/91*25 -> 250 | R23: 0 | S23: =R23/135*25 -> 0 | T23: - | U23: 0 | W23: 200 | X23: 50 | Y23: 560 | Z23: 326 | AA23: 660 | AB23: 500 | AC23: 0 | AD23: 0
A24: 45214 | B24: Remaining Stock Balance | D24: =D22-D23 -> 5332 | E24: =E22-E23 -> 2415.7609 | F24: =F22-F23 -> 9648 | G24: =G22-G23 -> 9075 | H24: =H22-H23 -> #REF! | I24: =I22-I23 -> #REF! | J24: =J22-J23 -> 0 | K24: =K22-K23 -> 0 | ... AD24: =AD22-AD23 -> 96
A27: Prepared by: | E27: Checked by: | R27: Certified correct by: | W27: Certified Correct by:
A30: MR. JUN RAY C. ENDICO | E30: MR. EDWIN B. BATAL | R30: ENGR. EDWIN B. BATAL | W30: ENGR. JOHN PAUHL T. NAVARRO
A31: Drill and Blast Engineer | E31: Mine Explosives Asst. Manager | R31: Mine Explosive Asst. Manager | W31: Tigerway Project Manager
A32: Mount Rock Powder Corp. | E32: PHILSAGA MINING CORPORATION | V32: Mine Explosives Manager | W32: PHILSAGA MINING CORPORATION
A33: Blaster License: FPDJ10-090819-04922 | E33: Blaster License: FKB15 - 080917- 04561

Sheet 10-16-22,2023
A10: EXPLOSIVES WEEKLY CONSUMPTION - TIGERWAY DECLINE PROJECT
A11: OCTOBER 16-22,2023
A14: SUPPLIER | D14: MT. ROCK
A16: DATE | B16: DESCRIPTION | D16: EMULSION | F16: EMULSION | H16: Dyna | J16: EMULSION | L16: EMULSION | N16: Dyna | P16: EMULSION | R16: EMULSION | T16: Pentex | U16: Anfo | V16: S/Fuse | W16: S/Fuse | X16: OBC | Y16: SHOCKSTAR | Z16: SUPREME | AA16: NEOCORD | AB16: DETCORD | AC16: Billwire | AD16: EBC
D17: 62 | F17: 36 | H17: 200 | J17: 208 | L17: 150 | N17: 150 | P17: 91 | R17: 135 | T17: Spider | V17: (savings) | Y17: 4.8 | Z17: 4.9 | AA17: 10 | AB17: 40
D18: Neogel 901 | F18: Emulex | H18: Superdyne | J18: EMULEX | L18: Super Power | N18: Senatel/Pulsar | P18: Netro EM | R18: Senatel/Pulsar
D19: Pcs | E19: Kls | F19: Pcs | G19: Kls | H19: Pcs | I19: Kls | J19: Pcs | K19: Kls | L19: Pcs | M19: Kls | N19: Pcs | O19: Kls | P19: Pcs | Q19: Kls | R19: Pcs | S19: Kls | T19: Pcs | U19: Kls | V19: Mtrs | W19: Mtrs | X19: Pcs | Y19: Pcs | Z19: Pcs | AA19: Mtrs | AB19: Mtrs | AC19: Mtrs | AD19: Pcs
A20: 45215 | B20: Beginning Balance | D20: ='10-9-15,2023'!D24 -> 5332 | E20: ='10-9-15,2023'!E24 -> 2415.7609 | F20: ='10-9-15,2023'!F24 -> 9648 | G20: ='10-9-15,2023'!G24 -> 9075 | H20: ='10-9-15,2023'!H24 -> #REF! | I20: ='10-9-15,2023'!I24 -> #REF! | J20: ='10-9-15,2023'!J24 -> 0 | K20: ='10-9-15,2023'!K24 -> 0 | ... AD20: ='10-9-15,2023'!AD24 -> 96
A21: Entry From Consignee Magazine
A22: Total Stock On Hand | D22: =D20+D21 -> 5332 | E22: =E20+E21 -> 2415.7609 | F22: =F20+F21 -> 9648 | G22: =G20+G21 -> 9075 | H22: =H20+H21 -> #REF! | I22: =I20+I21 -> #REF! | J22: =J20+J21 -> 0 | K22: =K20+K21 -> 0 | ... AD22: =AD20+AD21 -> 96
A23: Less: Total Weekly Consumption | D23: 2752 | E23: =D23/62*25 -> 1109.6774 | F23: 900 | G23: =F23/36*25 -> 625 | H23: =#REF! -> #REF! | I23: =#REF! -> #REF! | J23: 0 | K23: =J23/208*25 -> 0 | L23: 0 | M23: =L23/150*25 -> 0 | N23: 0 | O23: =N23/150*20 -> 0 | P23: 455 | Q23: =P23/91*25 -> 125 | R23: 0 | S23: =R23/135*25 -> 0 | T23: - | U23: 0 | W23: 210 | X23: 54 | Y23: 652 | Z23: 408 | AA23: 755 | AB23: 550 | AC23: 0 | AD23: 0
A24: 45221 | B24: Remaining Stock Balance | D24: =D22-D23 -> 2580 | E24: =E22-E23 -> 1306.0835 | F24: =F22-F23 -> 8748 | G24: =G22-G23 -> 8450 | H24: =H22-H23 -> #REF! | I24: =I22-I23 -> #REF! | J24: =J22-J23 -> 0 | K24: =K22-K23 -> 0 | ... AD24: =AD22-AD23 -> 96
A27: Prepared by: | E27: Checked by: | R27: Certified correct by: | W27: Certified Correct by:
A30: MR. JUN RAY C. ENDICO | E30: MR. RAFFY D. TORRES | R30: ENGR. EDWIN B. BATAL | W30: ENGR. JOHN PAUHL T. NAVARRO
A31: Drill and Blast Engineer | E31: Mine Explosives Manager | R31: Mine Explosive Asst. Manager | W31: Tigerway Project Manager
A32: Mount Rock Powder Corp. | E32: PHILSAGA MINING CORPORATION | V32: Mine Explosives Manager | W32: PHILSAGA MINING CORPORATION
A33: Blaster License: FPDJ10-090819-04922 | E33: Blaster License: FKB15 - 080917- 04561

Sheet 10-23-31,2023
A10: EXPLOSIVES WEEKLY CONSUMPTION - TIGERWAY DECLINE PROJECT
A11: OCTOBER 23-31,2023
A14: SUPPLIER | D14: MT. ROCK
A16: DATE | B16: DESCRIPTION | D16: EMULSION | F16: EMULSION | H16: Dyna | J16: EMULSION | L16: EMULSION | N16: Dyna | P16: EMULSION | R16: EMULSION | T16: Pentex | U16: Anfo | V16: S/Fuse | W16: S/Fuse | X16: OBC | Y16: SHOCKSTAR | Z16: SUPREME | AA16: NEOCORD | AB16: DETCORD | AC16: Billwire | AD16: EBC
D17: 62 | F17: 36 | H17: 200 | J17: 208 | L17: 150 | N17: 150 | P17: 91 | R17: 135 | T17: Spider | V17: (savings) | Y17: 4.8 | Z17: 4.9 | AA17: 10 | AB17: 40
D18: Neogel 901 | F18: Emulex | H18: Superdyne | J18: EMULEX | L18: Super Power | N18: Senatel/Pulsar | P18: Netro EM | R18: Senatel/Pulsar
D19: Pcs | E19: Kls | F19: Pcs | G19: Kls | H19: Pcs | I19: Kls | J19: Pcs | K19: Kls | L19: Pcs | M19: Kls | N19: Pcs | O19: Kls | P19: Pcs | Q19: Kls | R19: Pcs | S19: Kls | T19: Pcs | U19: Kls | V19: Mtrs | W19: Mtrs | X19: Pcs | Y19: Pcs | Z19: Pcs | AA19: Mtrs | AB19: Mtrs | AC19: Mtrs | AD19: Pcs
A20: 45222 | B20: Beginning Balance | D20: 0 | E20: =D20/62*25 -> 0 | F20: ='10-16-22,2023'!F24 -> 8748 | G20: =F20/36*25 -> 6075 | H20: ='10-16-22,2023'!H24 -> #REF! | I20: ='10-16-22,2023'!I24 -> #REF! | J20: ='10-16-22,2023'!J24 -> 0 | K20: ='10-16-22,2023'!K24 -> 0 | L20: ='10-16-22,2023'!L24 -> 0 | M20: ='10-16-22,2023'!M24 -> 0 | N20: ='10-16-22,2023'!N24 -> #REF! | O20: ='10-16-22,2023'!O24 -> #REF! | P20: 546 | Q20: =P20/91*25 -> 150 | R20: ='10-16-22,2023'!R24 -> 0 | S20: ='10-16-22,2023'!S24 -> 0 | T20: ='10-16-22,2023'!T24 -> #REF! | U20: ='10-16-22,2023'!U24 -> 975 | V20: ='10-16-22,2023'!V24 -> #REF! | W20: ='10-16-22,2023'!W24 -> 3190 | X20: ='10-16-22,2023'!X24 -> 203 | Y20: ='10-16-22,2023'!Y24 -> 2615 | Z20: =4953+220 -> 5173 | AA20: ='10-16-22,2023'!AA24 -> 2530 | AB20: ='10-16-22,2023'!AB24 -> 2010 | AC20: ='10-16-22,2023'!AC24 -> 300 | AD20: ='10-16-22,2023'!AD24 -> 96
A21: Entry From Consignee Magazine | F21: =270*36 -> 9720 | G21: =F21/36*25 -> 6750 | X21: 200 | Y21: 2480 | Z21: 2640 | AA21: 3000 | AB21: 3000
A22: Total Stock On Hand | D22: =D20+D21 -> 0 | E22: =E20+E21 -> 0 | F22: =F20+F21 -> 18468 | G22: =G20+G21 -> 12825 | H22: =H20+H21 -> #REF! | I22: =I20+I21 -> #REF! | J22: =J20+J21 -> 0 | K22: =K20+K21 -> 0 | ... AD22: =AD20+AD21 -> 96
A23: Less: Total Weekly Consumption | D23: 0 | E23: =D23/62*25 -> 0 | F23: =144*36 -> 5184 | G23: =F23/36*25 -> 3600 | H23: =#REF! -> #REF! | I23: =#REF! -> #REF! | J23: 0 | K23: =J23/208*25 -> 0 | L23: 0 | M23: =L23/150*25 -> 0 | N23: 0 | O23: =N23/150*20 -> 0 | P23: =6*91 -> 546 | Q23: =P23/91*25 -> 150 | R23: 0 | S23: =R23/135*25 -> 0 | T23: - | U23: 0 | W23: 200 | X23: 57 | Y23: 697 | Z23: 642 | AA23: 840 | AB23: 650 | AC23: 0 | AD23: 0
A24: 45230 | B24: Remaining Stock Balance | D24: =D22-D23 -> 0 | E24: =E22-E23 -> 0 | F24: =F22-F23 -> 13284 | G24: =G22-G23 -> 9225 | H24: =H22-H23 -> #REF! | I24: =I22-I23 -> #REF! | J24: =J22-J23 -> 0 | K24: =K22-K23 -> 0 | ... AD24: =AD22-AD23 -> 96
A27: Prepared by: | E27: Checked by: | R27: Certified correct by: | W27: Certified Correct by:
A30: MR. JUN RAY C. ENDICO | E30: MR. RAFFY D. TORRES | R30: ENGR. EDWIN B. BATAL | W30: ENGR. JOHN PAUHL T. NAVARRO
A31: Drill and Blast Engineer | E31: Mine Explosives Manager | R31: Mine Explosive Asst. Manager | W31: Tigerway Project Manager
A32: Mount Rock Powder Corp. | E32: PHILSAGA MINING CORPORATION | V32: Mine Explosives Manager | W32: PHILSAGA MINING CORPORATION
A33: Blaster License: FPDJ10-090819-04922 | E33: Blaster License: FKB15 - 080917- 04562

Sheet 11-1-5,2023
A10: EXPLOSIVES WEEKLY CONSUMPTION - TIGERWAY DECLINE PROJECT
A11: NOVEMBER 1-5,2023
A14: SUPPLIER | D14: MT. ROCK
A16: DATE | B16: DESCRIPTION | D16: EMULSION | F16: EMULSION | H16: Dyna | J16: EMULSION | L16: EMULSION | N16: Dyna | P16: EMULSION | R16: EMULSION | T16: Pentex | U16: Anfo | V16: S/Fuse | W16: S/Fuse | X16: OBC | Y16: SHOCKSTAR | Z16: SUPREME | AA16: NEOCORD | AB16: DETCORD | AC16: Billwire | AD16: EBC
D17: 62 | F17: 36 | H17: 200 | J17: 208 | L17: 150 | N17: 150 | P17: 91 | R17: 135 | T17: Spider | V17: (savings) | Y17: 4.8 | Z17: 4.9 | AA17: 10 | AB17: 40
D18: Neogel 901 | F18: Emulex | H18: Superdyne | J18: EMULEX | L18: Super Power | N18: Senatel/Pulsar | P18: Netro EM | R18: Senatel/Pulsar
D19: Pcs | E19: Kls | F19: Pcs | G19: Kls | H19: Pcs | I19: Kls | J19: Pcs | K19: Kls | L19: Pcs | M19: Kls | N19: Pcs | O19: Kls | P19: Pcs | Q19: Kls | R19: Pcs | S19: Kls | T19: Pcs | U19: Kls | V19: Mtrs | W19: Mtrs | X19: Pcs | Y19: Pcs | Z19: Pcs | AA19: Mtrs | AB19: Mtrs | AC19: Mtrs | AD19: Pcs
A20: 45231 | B20: Beginning Balance | D20: ='10-23-31,2023'!D24 -> 0 | E20: ='10-23-31,2023'!E24 -> 0 | F20: ='10-23-31,2023'!F24 -> 13284 | G20: ='10-23-31,2023'!G24 -> 9225 | H20: ='10-23-31,2023'!H24 -> #REF! | I20: ='10-23-31,2023'!I24 -> #REF! | J20: ='10-23-31,2023'!J24 -> 0 | K20: ='10-23-31,2023'!K24 -> 0 | ... Y20: ='10-23-31,2023'!Y24 -> 4398 | Z20: 6951 | AA20: ='10-23-31,2023'!AA24 -> 4690 | AB20: ='10-23-31,2023'!AB24 -> 4360 | AC20: ='10-23-31,2023'!AC24 -> 300 | AD20: ='10-23-31,2023'!AD24 -> 96
A21: Entry From Consignee Magazine
A22: Total Stock On Hand | D22: =D20+D21 -> 0 | E22: =E20+E21 -> 0 | F22: =F20+F21 -> 13284 | G22: =G20+G21 -> 9225 | H22: =H20+H21 -> #REF! | I22: =I20+I21 -> #REF! | J22: =J20+J21 -> 0 | K22: =K20+K21 -> 0 | ... AD22: =AD20+AD21 -> 96
A23: Less: Total Weekly Consumption | D23: 0 | E23: =D23/62*25 -> 0 | F23: 1548 | G23: =F23/36*25 -> 1075 | H23: =#REF! -> #REF! | I23: =#REF! -> #REF! | J23: 0 | K23: =J23/208*25 -> 0 | L23: 0 | M23: =L23/150*25 -> 0 | N23: 0 | O23: =N23/150*20 -> 0 | Q23: =P23/91*25 -> 0 | R23: 0 | S23: =R23/135*25 -> 0 | T23: - | U23: 0 | W23: 100 | X23: 28 | Y23: 276 | Z23: 202 | AA23: 330 | AB23: 200
A24: 45235 | B24: Remaining Stock Balance | D24: =D22-D23 -> 0 | E24: =E22-E23 -> 0 | F24: =F22-F23 -> 11736 | G24: =G22-G23 -> 8150 | H24: =H22-H23 -> #REF! | I24: =I22-I23 -> #REF! | J24: =J22-J23 -> 0 | K24: =K22-K23 -> 0 | ... AD24: =AD22-AD23 -> 96
A27: Prepared by: | E27: Checked by: | R27: Certified correct by: | W27: Certified Correct by:
A30: MR. JUN RAY C. ENDICO | E30: MR. RAFFY D. TORRES | R30: ENGR. EDWIN B. BATAL | W30: ENGR. JOHN PAUHL T. NAVARRO
A31: Drill and Blast Engineer | E31: Mine Explosives Manager | R31: Mine Explosive Asst. Manager | W31: Tigerway Project Manager
A32: Mount Rock Powder Corp. | E32: PHILSAGA MINING CORPORATION | V32: Mine Explosives Manager | W32: PHILSAGA MINING CORPORATION
A33: Blaster License: FPDJ10-090819-04922 | E33: Blaster License: FKB15 - 080917- 04562

Sheet 11-6-12,2023
A10: EXPLOSIVES WEEKLY CONSUMPTION - TIGERWAY DECLINE PROJECT
A11: NOVEMBER 6-12,2023
A14: SUPPLIER | D14: MT. ROCK
A16: DATE | B16: DESCRIPTION | D16: EMULSION | F16: EMULSION | H16: Dyna | J16: EMULSION | L16: EMULSION | N16: Dyna | P16: EMULSION | R16: EMULSION | T16: Pentex | U16: Anfo | V16: S/Fuse | W16: S/Fuse | X16: OBC | Y16: SHOCKSTAR | Z16: SUPREME | AA16: NEOCORD | AB16: DETCORD | AC16: Billwire | AD16: EBC
D17: 62 | F17: 36 | H17: 200 | J17: 208 | L17: 150 | N17: 150 | P17: 91 | R17: 135 | T17: Spider | V17: (savings) | Y17: 4.8 | Z17: 4.9 | AA17: 10 | AB17: 40
D18: Neogel 901 | F18: Emulex | H18: Superdyne | J18: EMULEX | L18: Super Power | N18: Senatel/Pulsar | P18: Netro EM | R18: Senatel/Pulsar
D19: Pcs | E19: Kls | F19: Pcs | G19: Kls | H19: Pcs | I19: Kls | J19: Pcs | K19: Kls | L19: Pcs | M19: Kls | N19: Pcs | O19: Kls | P19: Pcs | Q19: Kls | R19: Pcs | S19: Kls | T19: Pcs | U19: Kls | V19: Mtrs | W19: Mtrs | X19: Pcs | Y19: Pcs | Z19: Pcs | AA19: Mtrs | AB19: Mtrs | AC19: Mtrs | AD19: Pcs
A20: 45236 | B20: Beginning Balance | D20: ='11-1-5,2023'!D24 -> 0 | E20: ='11-1-5,2023'!E24 -> 0 | F20: ='11-1-5,2023'!F24 -> 11736 | G20: ='11-1-5,2023'!G24 -> 8150 | H20: ='11-1-5,2023'!H24 -> #REF! | I20: ='11-1-5,2023'!I24 -> #REF! | J20: ='11-1-5,2023'!J24 -> 0 | K20: ='11-1-5,2023'!K24 -> 0 | ... AD20: ='11-1-5,2023'!AD24 -> 96
A21: Entry From Consignee Magazine
A22: Total Stock On Hand | D22: =D20+D21 -> 0 | E22: =E20+E21 -> 0 | F22: =F20+F21 -> 11736 | G22: =G20+G21 -> 8150 | H22: =H20+H21 -> #REF! | I22: =I20+I21 -> #REF! | J22: =J20+J21 -> 0 | K22: =K20+K21 -> 0 | ... AD22: =AD20+AD21 -> 96
A23: Less: Total Weekly Consumption | D23: 0 | E23: =D23/62*25 -> 0 | F23: =121*36 -> 4356 | G23: =F23/36*25 -> 3025 | H23: =#REF! -> #REF! | I23: =#REF! -> #REF! | J23: 0 | K23: =J23/208*25 -> 0 | L23: 0 | M23: =L23/150*25 -> 0 | N23: 0 | O23: =N23/150*20 -> 0 | Q23: =P23/91*25 -> 0 | R23: 0 | S23: =R23/135*25 -> 0 | T23: - | U23: 0 | W23: 230 | X23: 62 | Y23: 606 | Z23: 534 | AA23: 750 | AB23: 750 | AC23: 0
A24: 45242 | B24: Remaining Stock Balance | D24: =D22-D23 -> 0 | E24: =E22-E23 -> 0 | F24: =F22-F23 -> 7380 | G24: =G22-G23 -> 5125 | H24: =H22-H23 -> #REF! | I24: =I22-I23 -> #REF! | J24: =J22-J23 -> 0 | K24: =K22-K23 -> 0 | ... AD24: =AD22-AD23 -> 96
A27: Prepared by: | E27: Checked by: | R27: Certified correct by: | W27: Certified Correct by:
A30: MR. JUN RAY C. ENDICO | E30: MR. RAFFY D. TORRES | R30: ENGR. EDWIN B. BATAL | W30: ENGR. JOHN PAUHL T. NAVARRO
A31: Drill and Blast Engineer | E31: Mine Explosives Manager | R31: Mine Explosive Asst. Manager | W31: Tigerway Project Manager
A32: Mount Rock Powder Corp. | E32: PHILSAGA MINING CORPORATION | V32: Mine Explosives Manager | W32: PHILSAGA MINING CORPORATION
A33: Blaster License: FPDJ10-090819-04922 | E33: Blaster License: FKB15 - 080917- 04562

Sheet 11-13-19,2023
A10: EXPLOSIVES WEEKLY CONSUMPTION - TIGERWAY DECLINE PROJECT
A11: NOVEMBER 13-19,2023
A14: SUPPLIER | D14: MT. ROCK
A16: DATE | B16: DESCRIPTION | D16: EMULSION | F16: EMULSION | H16: Dyna | J16: EMULSION | L16: EMULSION | N16: Dyna | P16: EMULSION | R16: EMULSION | T16: Pentex | U16: Anfo | V16: S/Fuse | W16: S/Fuse | X16: OBC | Y16: SHOCKSTAR | Z16: SUPREME | AA16: NEOCORD | AB16: DETCORD | AC16: Billwire | AD16: EBC
D17: 62 | F17: 36 | H17: 200 | J17: 208 | L17: 150 | N17: 150 | P17: 91 | R17: 135 | T17: Spider | V17: (savings) | Y17: 4.8 | Z17: 4.9 | AA17: 10 | AB17: 40
D18: Neogel 901 | F18: Emulex | H18: Superdyne | J18: EMULEX | L18: Super Power | N18: Senatel/Pulsar | P18: Netro EM | R18: Senatel/Pulsar
D19: Pcs | E19: Kls | F19: Pcs | G19: Kls | H19: Pcs | I19: Kls | J19: Pcs | K19: Kls | L19: Pcs | M19: Kls | N19: Pcs | O19: Kls | P19: Pcs | Q19: Kls | R19: Pcs | S19: Kls | T19: Pcs | U19: Kls | V19: Mtrs | W19: Mtrs | X19: Pcs | Y19: Pcs | Z19: Pcs | AA19: Mtrs | AB19: Mtrs | AC19: Mtrs | AD19: Pcs
A20: 45243 | B20: Beginning Balance | D20: ='11-6-12,2023'!D24 -> 0 | E20: ='11-6-12,2023'!E24 -> 0 | F20: ='11-6-12,2023'!F24 -> 7380 | G20: ='11-6-12,2023'!G24 -> 5125 | H20: ='11-6-12,2023'!H24 -> #REF! | I20: ='11-6-12,2023'!I24 -> #REF! | J20: ='11-6-12,2023'!J24 -> 0 | K20: ='11-6-12,2023'!K24 -> 0 | ... AD20: ='11-6-12,2023'!AD24 -> 96
A21: Entry From Consignee Magazine
A22: Total Stock On Hand | D22: =D20+D21 -> 0 | E22: =E20+E21 -> 0 | F22: =F20+F21 -> 7380 | G22: =G20+G21 -> 5125 | H22: =H20+H21 -> #REF! | I22: =I20+I21 -> #REF! | J22: =J20+J21 -> 0 | K22: =K20+K21 -> 0 | ... AD22: =AD20+AD21 -> 96
A23: Less: Total Weekly Consumption | D23: 0 | E23: =D23/62*25 -> 0 | F23: =118*36 -> 4248 | G23: =F23/36*25 -> 2950 | H23: =#REF! -> #REF! | I23: =#REF! -> #REF! | J23: 0 | K23: =J23/208*25 -> 0 | L23: 0 | M23: =L23/150*25 -> 0 | N23: 0 | O23: =N23/150*20 -> 0 | Q23: =P23/91*25 -> 0 | R23: 0 | S23: =R23/135*25 -> 0 | T23: - | U23: 0 | W23: 180 | X23: 51 | Y23: 580 | Z23: 516 | AA23: 680 | AB23: 400 | AC23: 0
A24: 45249 | B24: Remaining Stock Balance | D24: =D22-D23 -> 0 | E24: =E22-E23 -> 0 | F24: =F22-F23 -> 3132 | G24: =G22-G23 -> 2175 | H24: =H22-H23 -> #REF! | I24: =I22-I23 -> #REF! | J24: =J22-J23 -> 0 | K24: =K22-K23 -> 0 | ... AD24: =AD22-AD23 -> 96
A27: Prepared by: | E27: Checked by: | R27: Certified correct by: | W27: Certified Correct by:
A30: MR. JUN RAY C. ENDICO | E30: MR. RAFFY D. TORRES | R30: ENGR. EDWIN B. BATAL | W30: ENGR. JOHN PAUHL T. NAVARRO
A31: Drill and Blast Engineer | E31: Mine Explosives Manager | R31: Mine Explosive Asst. Manager | W31: Tigerway Project Manager
A32: Mount Rock Powder Corp. | E32: PHILSAGA MINING CORPORATION | V32: Mine Explosives Manager | W32: PHILSAGA MINING CORPORATION
A33: Blaster License: FPDJ10-090819-04922 | E33: Blaster License: FKB15 - 080917- 04562

Sheet 11-20-26,2023
A10: EXPLOSIVES WEEKLY CONSUMPTION - TIGERWAY DECLINE PROJECT
A11: NOVEMBER 20-26,2023
A14: SUPPLIER | D14: MT. ROCK
A16: DATE | B16: DESCRIPTION | D16: EMULSION | F16: EMULSION | H16: Dyna | J16: EMULSION | L16: EMULSION | N16: Dyna | P16: EMULSION | R16: EMULSION | T16: Pentex | U16: Anfo | V16: S/Fuse | W16: S/Fuse | X16: OBC | Y16: SHOCKSTAR | Z16: SUPREME | AA16: NEOCORD | AB16: DETCORD | AC16: Billwire | AD16: EBC
D17: 62 | F17: 36 | H17: 200 | J17: 208 | L17: 150 | N17: 150 | P17: 91 | R17: 135 | T17: Spider | V17: (savings) | Y17: 4.8 | Z17: 4.9 | AA17: 10 | AB17: 40
D18: Neogel 901 | F18: Emulex | H18: Superdyne | J18: EMULEX | L18: Super Power | N18: Senatel/Pulsar | P18: Netro EM | R18: Senatel/Pulsar
D19: Pcs | E19: Kls | F19: Pcs | G19: Kls | H19: Pcs | I19: Kls | J19: Pcs | K19: Kls | L19: Pcs | M19: Kls | N19: Pcs | O19: Kls | P19: Pcs | Q19: Kls | R19: Pcs | S19: Kls | T19: Pcs | U19: Kls | V19: Mtrs | W19: Mtrs | X19: Pcs | Y19: Pcs | Z19: Pcs | AA19: Mtrs | AB19: Mtrs | AC19: Mtrs | AD19: Pcs
A20: 45250 | B20: Beginning Balance | D20: ='11-13-19,2023'!D24 -> 0 | E20: ='11-13-19,2023'!E24 -> 0 | F20: ='11-13-19,2023'!F24-288 -> 2844 | G20: ='11-13-19,2023'!G24-200 -> 1975 | H20: ='11-13-19,2023'!H24 -> #REF! | I20: ='11-13-19,2023'!I24 -> #REF! | J20: ='11-13-19,2023'!J24 -> 0 | K20: ='11-13-19,2023'!K24 -> 0 | L20: ='11-13-19,2023'!L24 -> 0 | M20: ='11-13-19,2023'!M24 -> 0 | N20: ='11-13-19,2023'!N24 -> #REF! | O20: ='11-13-19,2023'!O24 -> #REF! | ... V20: ='11-13-19,2023'!V24 -> #REF! | W20: ='11-13-19,2023'!W24-20 -> 2460 | X20: ='11-13-19,2023'!X24-5 -> 200 | Y20: ='11-13-19,2023'!Y24-36 -> 2900 | Z20: ='11-13-19,2023'!Z24-45 -> 5654 | AA20: ='11-13-19,2023'!AA24-70 -> 2860 | AB20: ='11-13-19,2023'!AB24-50 -> 2960 | AC20: ='11-13-19,2023'!AC24 -> 300 | AD20: ='11-13-19,2023'!AD24 -> 96
A21: Entry From Consignee Magazine | D21: =390*62 -> 24180 | E21: =D21/62*25 -> 9750 | F21: =10*36 -> 360 | G21: =F21/36*25 -> 250 | P21: 0 | Q21: =P21/91*25 -> 0 | U21: 0 | W21: 0 | X21: 200 | Y21: 1200 | Z21: 0 | AA21: 3000 | AB21: 1500 | AC21: 0 | AD21: 0
A22: Total Stock On Hand | D22: =D20+D21 -> 24180 | E22: =E20+E21 -> 9750 | F22: =F20+F21 -> 3204 | G22: =G20+G21 -> 2225 | H22: =H20+H21 -> #REF! | I22: =I20+I21 -> #REF! | J22: =J20+J21 -> 0 | K22: =K20+K21 -> 0 | ... AD22: =AD20+AD21 -> 96
A23: Less: Total Weekly Consumption | D23: =30*62 -> 1860 | E23: =D23/62*25 -> 750 | F23: =89*36 -> 3204 | G23: =F23/36*25 -> 2225 | H23: =#REF! -> #REF! | I23: =#REF! -> #REF! | J23: 0 | K23: =J23/208*25 -> 0 | L23: 0 | M23: =L23/150*25 -> 0 | N23: 0 | O23: =N23/150*20 -> 0 | Q23: =P23/91*25 -> 0 | R23: 0 | S23: =R23/135*25 -> 0 | T23: - | U23: 0 | W23: 180 | X23: 45 | Y23: 501 | Z23: 586 | AA23: 790 | AB23: 600 | AC23: 0
A24: 45256 | B24: Remaining Stock Balance | D24: =D22-D23 -> 22320 | E24: =E22-E23 -> 9000 | F24: =F22-F23 -> 0 | G24: =G22-G23 -> 0 | H24: =H22-H23 -> #REF! | I24: =I22-I23 -> #REF! | J24: =J22-J23 -> 0 | K24: =K22-K23 -> 0 | ... AD24: =AD22-AD23 -> 96
A27: Prepared by: | E27: Checked by: | R27: Certified correct by: | W27: Certified Correct by:
A30: MR. JUN RAY C. ENDICO | E30: MR. RAFFY D. TORRES | R30: ENGR. EDWIN B. BATAL | W30: ENGR. JOHN PAUHL T. NAVARRO
A31: Drill and Blast Engineer | E31: Mine Explosives Manager | R31: Mine Explosive Asst. Manager | W31: Tigerway Project Manager
A32: Mount Rock Powder Corp. | E32: PHILSAGA MINING CORPORATION | V32: Mine Explosives Manager | W32: PHILSAGA MINING CORPORATION
A33: Blaster License: FPDJ10-090819-04922 | E33: Blaster License: FKB15 - 080917- 04562

Sheet 11-26-12-3,2023
A10: EXPLOSIVES WEEKLY CONSUMPTION - TIGERWAY DECLINE PROJECT
A11: NOVEMBER 27-DECEMBER 3,2023
A14: SUPPLIER | D14: MT. ROCK
A16: DATE | B16: DESCRIPTION | D16: EMULSION | F16: EMULSION | H16: Dyna | J16: EMULSION | L16: EMULSION | N16: Dyna | P16: EMULSION | R16: EMULSION | T16: Pentex | U16: Anfo | V16: S/Fuse | W16: S/Fuse | X16: OBC | Y16: SHOCKSTAR | Z16: SUPREME | AA16: NEOCORD | AB16: DETCORD | AC16: Billwire | AD16: EBC
D17: 62 | F17: 36 | H17: 200 | J17: 208 | L17: 150 | N17: 150 | P17: 91 | R17: 135 | T17: Spider | V17: (savings) | Y17: 4.8 | Z17: 4.9 | AA17: 10 | AB17: 40
D18: Neogel 901 | F18: Emulex | H18: Superdyne | J18: EMULEX | L18: Super Power | N18: Senatel/Pulsar | P18: Netro EM | R18: Senatel/Pulsar
D19: Pcs | E19: Kls | F19: Pcs | G19: Kls | H19: Pcs | I19: Kls | J19: Pcs | K19: Kls | L19: Pcs | M19: Kls | N19: Pcs | O19: Kls | P19: Pcs | Q19: Kls | R19: Pcs | S19: Kls | T19: Pcs | U19: Kls | V19: Mtrs | W19: Mtrs | X19: Pcs | Y19: Pcs | Z19: Pcs | AA19: Mtrs | AB19: Mtrs | AC19: Mtrs | AD19: Pcs
A20: 45257 | B20: Beginning Balance | D20: =302*62 -> 18724 | E20: ='11-20-26,2023'!E24 -> 9000 | F20: ='11-20-26,2023'!F24 -> 0 | G20: ='11-20-26,2023'!G24 -> 0 | H20: ='11-20-26,2023'!H24 -> #REF! | I20: ='11-20-26,2023'!I24 -> #REF! | J20: ='11-20-26,2023'!J24 -> 0 | K20: ='11-20-26,2023'!K24 -> 0 | L20: ='11-20-26,2023'!L24 -> 0 | ... AD20: ='11-20-26,2023'!AD24 -> 96
A21: Entry From Consignee Magazine
A22: Total Stock On Hand | D22: =D20+D21 -> 18724 | E22: =E20+E21 -> 9000 | F22: =F20+F21 -> 0 | G22: =G20+G21 -> 0 | H22: =H20+H21 -> #REF! | I22: =I20+I21 -> #REF! | J22: =J20+J21 -> 0 | K22: =K20+K21 -> 0 | ... AD22: =AD20+AD21 -> 96
A23: Less: Total Weekly Consumption | D23: =87*62 -> 5394 | E23: =D23/62*25 -> 2175 | F23: 0 | G23: =F23/36*25 -> 0 | H23: =#REF! -> #REF! | I23: =#REF! -> #REF! | J23: 0 | K23: =J23/208*25 -> 0 | L23: 0 | M23: =L23/150*25 -> 0 | N23: 0 | O23: =N23/150*20 -> 0 | Q23: =P23/91*25 -> 0 | R23: 0 | S23: =R23/135*25 -> 0 | T23: - | U23: 0 | W23: 188 | X23: 49 | Y23: 324 | Z23: 150 | AA23: 640 | AB23: 450 | AC23: 0
A24: 45263 | B24: Remaining Stock Balance | D24: =D22-D23 -> 13330 | E24: =E22-E23 -> 6825 | F24: =F22-F23 -> 0 | G24: =G22-G23 -> 0 | H24: =H22-H23 -> #REF! | I24: =I22-I23 -> #REF! | J24: =J22-J23 -> 0 | K24: =K22-K23 -> 0 | ... AD24: =AD22-AD23 -> 96
A27: Prepared by: | E27: Checked by: | R27: Certified correct by: | W27: Certified Correct by:
A30: MR. JUN RAY C. ENDICO | E30: MR. RAFFY D. TORRES | R30: ENGR. EDWIN B. BATAL | W30: ENGR. JOHN PAUHL T. NAVARRO
A31: Drill and Blast Engineer | E31: Mine Explosives Manager | R31: Mine Explosive Asst. Manager | W31: Tigerway Project Manager
A32: Mount Rock Powder Corp. | E32: PHILSAGA MINING CORPORATION | V32: Mine Explosives Manager | W32: PHILSAGA MINING CORPORATION
A33: Blaster License: FPDJ10-090819-04922 | E33: Blaster License: FKB15 - 080917- 04562

Sheet 12-4-10,2023
A10: EXPLOSIVES WEEKLY CONSUMPTION - TIGERWAY DECLINE PROJECT
A11: DECEMBER 4-10,2023
A14: SUPPLIER | D14: MT. ROCK
A16: DATE | B16: DESCRIPTION | D16: EMULSION | F16: EMULSION | H16: Dyna | J16: EMULSION | L16: EMULSION | N16: Dyna | P16: EMULSION | R16: EMULSION | T16: Pentex | U16: Anfo | V16: S/Fuse | W16: S/Fuse | X16: OBC | Y16: SHOCKSTAR | Z16: SUPREME | AA16: NEOCORD | AB16: DETCORD | AC16: Billwire | AD16: EBC
D17: 62 | F17: 36 | H17: 200 | J17: 208 | L17: 150 | N17: 150 | P17: 91 | R17: 135 | T17: Spider | V17: (savings) | Y17: 4.8 | Z17: 4.9 | AA17: 10 | AB17: 40
D18: Neogel 901 | F18: Emulex | H18: Superdyne | J18: EMULEX | L18: Super Power | N18: Senatel/Pulsar | P18: Netro EM | R18: Senatel/Pulsar
D19: Pcs | E19: Kls | F19: Pcs | G19: Kls | H19: Pcs | I19: Kls | J19: Pcs | K19: Kls | L19: Pcs | M19: Kls | N19: Pcs | O19: Kls | P19: Pcs | Q19: Kls | R19: Pcs | S19: Kls | T19: Pcs | U19: Kls | V19: Mtrs | W19: Mtrs | X19: Pcs | Y19: Pcs | Z19: Pcs | AA19: Mtrs | AB19: Mtrs | AC19: Mtrs | AD19: Pcs
A20: 45264 | B20: Beginning Balance | D20: ='11-26-12-3,2023'!D24+3782 -> 17112 | E20: ='11-26-12-3,2023'!E24 -> 6825 | F20: ='11-26-12-3,2023'!F24 -> 0 | G20: ='11-26-12-3,2023'!G24 -> 0 | H20: ='11-26-12-3,2023'!H24 -> #REF! | I20: ='11-26-12-3,2023'!I24 -> #REF! | J20: ='11-26-12-3,2023'!J24 -> 0 | K20: ='11-26-12-3,2023'!K24 -> 0 | L20: ='11-26-12-3,2023'!L24 -> 0 | ... AD20: ='11-26-12-3,2023'!AD24 -> 96
A21: Entry From Consignee Magazine
A22: Total Stock On Hand | D22: =D20+D21 -> 17112 | E22: =E20+E21 -> 6825 | F22: =F20+F21 -> 0 | G22: =G20+G21 -> 0 | H22: =H20+H21 -> #REF! | I22: =I20+I21 -> #REF! | J22: =J20+J21 -> 0 | K22: =K20+K21 -> 0 | ... AD22: =AD20+AD21 -> 96
A23: Less: Total Weekly Consumption | D23: =87*62 -> 5394 | E23: =D23/62*25 -> 2175 | F23: 0 | G23: =F23/36*25 -> 0 | H23: =#REF! -> #REF! | I23: =#REF! -> #REF! | J23: 0 | K23: =J23/208*25 -> 0 | L23: 0 | M23: =L23/150*25 -> 0 | N23: 0 | O23: =N23/150*20 -> 0 | Q23: =P23/91*25 -> 0 | R23: 0 | S23: =R23/135*25 -> 0 | T23: - | U23: 0 | W23: 160 | X23: 40 | Y23: 332 | Z23: 395 | AA23: 600 | AB23: 400 | AC23: 0
A24: 45270 | B24: Remaining Stock Balance | D24: =D22-D23 -> 11718 | E24: =E22-E23 -> 4650 | F24: =F22-F23 -> 0 | G24: =G22-G23 -> 0 | H24: =H22-H23 -> #REF! | I24: =I22-I23 -> #REF! | J24: =J22-J23 -> 0 | K24: =K22-K23 -> 0 | ... AD24: =AD22-AD23 -> 96
A27: Prepared by: | E27: Checked by: | R27: Certified correct by: | W27: Certified Correct by:
A30: MR. JUN RAY C. ENDICO | E30: MR. RAFFY D. TORRES | R30: ENGR. EDWIN B. BATAL | W30: ENGR. JOHN PAUHL T. NAVARRO
A31: Drill and Blast Engineer | E31: Mine Explosives Manager | R31: Mine Explosive Asst. Manager | W31: Tigerway Project Manager
A32: Mount Rock Powder Corp. | E32: PHILSAGA MINING CORPORATION | V32: Mine Explosives Manager | W32: PHILSAGA MINING CORPORATION
A33: Blaster License: FPDJ10-090819-04922 | E33: Blaster License: FKB15 - 080917- 04562

Sheet 12-11-17,2023
A10: EXPLOSIVES WEEKLY CONSUMPTION - TIGERWAY DECLINE PROJECT
A11: DECEMBER 11-17,2023
A14: SUPPLIER | D14: MT. ROCK
A16: DATE | B16: DESCRIPTION | D16: EMULSION | F16: EMULSION | H16: Dyna | J16: EMULSION | L16: EMULSION | N16: Dyna | P16: EMULSION | R16: EMULSION | T16: Pentex | U16: Anfo | V16: S/Fuse | W16: S/Fuse | X16: OBC | Y16: SHOCKSTAR | Z16: SUPREME | AA16: NEOCORD | AB16: DETCORD | AC16: Billwire | AD16: EBC
D17: 62 | F17: 36 | H17: 200 | J17: 208 | L17: 150 | N17: 150 | P17: 91 | R17: 135 | T17: Spider | V17: (savings) | Y17: 4.8 | Z17: 4.9 | AA17: 10 | AB17: 40
D18: Neogel 901 | F18: Emulex | H18: Superdyne | J18: EMULEX | L18: Super Power | N18: Senatel/Pulsar | P18: Netro EM | R18: Senatel/Pulsar
D19: Pcs | E19: Kls | F19: Pcs | G19: Kls | H19: Pcs | I19: Kls | J19: Pcs | K19: Kls | L19: Pcs | M19: Kls | N19: Pcs | O19: Kls | P19: Pcs | Q19: Kls | R19: Pcs | S19: Kls | T19: Pcs | U19: Kls | V19: Mtrs | W19: Mtrs | X19: Pcs | Y19: Pcs | Z19: Pcs | AA19: Mtrs | AB19: Mtrs | AC19: Mtrs | AD19: Pcs
A20: 45271 | B20: Beginning Balance | D20: ='12-4-10,2023'!D24 -> 11718 | E20: ='12-4-10,2023'!E24 -> 4650 | F20: ='12-4-10,2023'!F24 -> 0 | G20: ='12-4-10,2023'!G24 -> 0 | H20: ='12-4-10,2023'!H24 -> #REF! | I20: ='12-4-10,2023'!I24 -> #REF! | J20: ='12-4-10,2023'!J24 -> 0 | K20: ='12-4-10,2023'!K24 -> 0 | ... AD20: ='12-4-10,2023'!AD24 -> 96
A21: Entry From Consignee Magazine | D21: =350*62 -> 21700 | E21: =D21/62*25 -> 8750 | F21: 0 | G21: 0 | P21: 0 | Q21: =P21/91*25 -> 0 | U21: 0 | W21: 1000 | X21: 200 | Y21: 2480 | Z21: 3300 | AA21: 3000 | AB21: 0 | AC21: 0 | AD21: 0
A22: Total Stock On Hand | D22: =D20+D21 -> 33418 | E22: =E20+E21 -> 13400 | F22: =F20+F21 -> 0 | G22: =G20+G21 -> 0 | H22: =H20+H21 -> #REF! | I22: =I20+I21 -> #REF! | J22: =J20+J21 -> 0 | K22: =K20+K21 -> 0 | ... AD22: =AD20+AD21 -> 96
A23: Less: Total Weekly Consumption | D23: =104*62 -> 6448 | E23: =D23/62*25 -> 2600 | F23: 0 | G23: =F23/36*25 -> 0 | H23: =#REF! -> #REF! | I23: =#REF! -> #REF! | J23: 0 | K23: =J23/208*25 -> 0 | L23: 0 | M23: =L23/150*25 -> 0 | N23: 0 | O23: =N23/150*20 -> 0 | P23: 0 | Q23: =P23/91*25 -> 0 | R23: 0 | S23: =R23/135*25 -> 0 | T23: - | U23: 0 | W23: 151 | X23: 47 | Y23: 342 | Z23: 472 | AA23: 580 | AB23: 400 | AC23: 0 | AD23: 0
A24: 45277 | B24: Remaining Stock Balance | D24: =D22-D23 -> 26970 | E24: =E22-E23 -> 10800 | F24: =F22-F23 -> 0 | G24: =G22-G23 -> 0 | H24: =H22-H23 -> #REF! | I24: =I22-I23 -> #REF! | J24: =J22-J23 -> 0 | K24: =K22-K23 -> 0 | ... AD24: =AD22-AD23 -> 96
A27: Prepared by: | E27: Checked by: | R27: Certified correct by: | W27: Certified Correct by:
A30: MR. JUN RAY C. ENDICO | E30: MR. RAFFY D. TORRES | R30: ENGR. EDWIN B. BATAL | W30: ENGR. JOHN PAUHL T. NAVARRO
A31: Drill and Blast Engineer | E31: Mine Explosives Manager | R31: Mine Explosive Asst. Manager | W31: Tigerway Project Manager
A32: Mount Rock Powder Corp. | E32: PHILSAGA MINING CORPORATION | V32: Mine Explosives Manager | W32: PHILSAGA MINING CORPORATION
A33: Blaster License: FPDJ10-090819-04922 | E33: Blaster License: FKB15 - 080917- 04562

Sheet 12-18-24,2023
A10: EXPLOSIVES WEEKLY CONSUMPTION - TIGERWAY DECLINE PROJECT
A11: DECEMBER 18-24,2023
A14: SUPPLIER | D14: MT. ROCK
A16: DATE | B16: DESCRIPTION | D16: EMULSION | F16: EMULSION | H16: Dyna | J16: EMULSION | L16: EMULSION | N16: Dyna | P16: EMULSION | R16: EMULSION | T16: Pentex | U16: Anfo | V16: S/Fuse | W16: S/Fuse | X16: OBC | Y16: SHOCKSTAR | Z16: SUPREME | AA16: NEOCORD | AB16: DETCORD | AC16: Billwire | AD16: EBC
D17: 62 | F17: 36 | H17: 200 | J17: 208 | L17: 150 | N17: 150 | P17: 91 | R17: 135 | T17: Spider | V17: (savings) | Y17: 4.8 | Z17: 4.9 | AA17: 10 | AB17: 40
D18: Neogel 901 | F18: Emulex | H18: Superdyne | J18: EMULEX | L18: Super Power | N18: Senatel/Pulsar | P18: Netro EM | R18: Senatel/Pulsar
D19: Pcs | E19: Kls | F19: Pcs | G19: Kls | H19: Pcs | I19: Kls | J19: Pcs | K19: Kls | L19: Pcs | M19: Kls | N19: Pcs | O19: Kls | P19: Pcs | Q19: Kls | R19: Pcs | S19: Kls | T19: Pcs | U19: Kls | V19: Mtrs | W19: Mtrs | X19: Pcs | Y19: Pcs | Z19: Pcs | AA19: Mtrs | AB19: Mtrs | AC19: Mtrs | AD19: Pcs
A20: 45278 | B20: Beginning Balance | D20: ='12-11-17,2023'!D24 -> 26970 | E20: ='12-11-17,2023'!E24 -> 10800 | F20: ='12-11-17,2023'!F24 -> 0 | G20: ='12-11-17,2023'!G24 -> 0 | H20: ='12-11-17,2023'!H24 -> #REF! | I20: ='12-11-17,2023'!I24 -> #REF! | J20: ='12-11-17,2023'!J24 -> 0 | K20: ='12-11-17,2023'!K24 -> 0 | ... AD20: ='12-11-17,2023'!AD24 -> 96
A21: Entry From Consignee Magazine
