Workbook

Sheet JANUARY 2026 -PMC  
A1: FROM: OFFICE OF DIRECTOR | E1: FAX NO. : 9209130
B3: MGB Form No. 15-8
A5: Republic of the Philippines
A6: Department of Environment and Natural Resources
A7: MINES AND GEOSCIENCES BUREAU
A8: North Avenue, Diliman, Quezon City
A10: EXPLOSIVES AND ACCESSORIES CONSUMPTION
A11: REPORT FOR THE MONTH OF JANUARY 2026
F13: DATE | G13: JANUARY 1-31,2026
A14: Company : | C14: PHILSAGA MINING CORPORATION - CO-O GOLD PROJECT
C15: (MPSA No. 262-2008-XIII PARCEL 1)
A16: Minesite Address : | C16: Coo-Consuelo, Bunawan, Agusan del Sur | F16: PPEL No.P- | G16: 0425-298-2011
A17: Head of Project : | C17: ENGR. EARL M. SON
A18: Drilling and Blasting Engineer/s : | C18: ENGR. RAFFY D. TORRES | F18: BPL No.F- | G18: EXPL-0411128
A20: ITEM | C20: UNIT | D20: BRAND | E20: SUPPLIERS/CONTRACTOR | F20: SPECIFICATION | G20: QUANTITY USED | H20: QUANTITY USED | M20: =1049-15 -> 1034
G21: PCS/METERS | H21: KLS
A22: A. DYNA / EMULSION PACKAGE | C22: Pieces/Kilograms | D22: EMULEX AUSTIN 200 | E22: MT. ROCK POWDER CORP. | F22: 25 x 200mm | G22: - | H22: -
D23: SUPER POWER 150 | E23: MT. ROCK POWDER CORP. | F23: 25 x 200mm | G23: - | H23: -
D24: NEOGEL 200 | E24: MT. ROCK POWDER CORP. | F24: 25 x 200mm | G24: 45072 | H24: =G24/200*25 -> 5634
D25: SUPERDYNE 200 | E25: EXPEDITION MBDInc. | F25: 25x 200mm | G25: - | H25: -
D26: SENATEL MAGNUM 150 | E26: EXPEDITION MBDInc. | F26: 25x 300mm | G26: -
D27: DYAGEL 150 | E27: EXPEDITION MBDInc. | F27: 20x 200mm | G27: - | H27: -
D28: SENATEL PULSAR 150 | E28: EXPEDITION MBDInc. | F28: 25x 200mm | G28: - | H28: -
D29: SENATEL PULSAR 38 | E29: EXPEDITION MBDInc. | F29: 32x 200mm | G29: - | H29: -
D30: SENATEL PULSAR 135 | E30: EXPEDITION MBDInc. | F30: 32x 200mm | G30: - | H30: -
D31: SENATEL PULSAR 215 | E31: EXPEDITION MBDInc. | F31: 25x 200mm | G31: 45911 | H31: =G31/215*25 -> 5338.4884
A32: B. Ammonium | C32: Kilograms | D32: PEXPO ANFO | E32: EXPEDITION MBDInc. | F32: 25 KGS/BAG | G32: - | H32: =I32 -> 30440.5 | I32: 30440.5 | J32: =H32+H33 -> #VALUE!
A33: Nitrate fuel oil (ANFO) | D33: ROCK ANFO | E33: MT. ROCK POWDER CORP. | F33: 25 KGS/BAG | G33: - | H33: - | J33: =I32/3 -> 10146.833 | K33: =J33*2 -> 20293.667
A34: C. Slurry | C34: Kilograms | D34: - | E34: - | F34: - | G34: - | H34: -
A35: D. Electric Blasting CAP | C35: Pieces | D35: EBC | E35: EXPEDITION MBDInc. | F35: - | G35: 92 | H35: -
A36: E. Ordinary Blasting CAP | C36: Pieces | D36: OBC | E36: EXPEDITION MBDInc. | G36: =I36/2 -> 2706.5 | I36: 5413
D37: OBC | E37: MT. ROCK POWDER CORP. | F37: (#8) | G37: =I36/2 -> 2706.5 | H37: -
A38: F. Non Electric Detonator (LP) | C38: Pieces | D38: NONEL | E38: MT. ROCK POWDER CORP. | F38: 2.4 METER | G38: 0 | H38: -
D39: NONEL | E39: MT. ROCK POWDER CORP. | F39: 3.6 METER | G39: 0 | H39: -
A40: Non Electric Detonator (LP) | C40: Pieces | D40: SUPREME | E40: MT. ROCK POWDER CORP. | F40: 2.4 METER | G40: 0 | H40: -
A41: Non Electric Detonator (LP) | C41: Pieces | D41: SUPREME | E41: MT. ROCK POWDER CORP. | F41: 3.6 METER | G41: 0 | H41: -
A42: Non Electric Detonator (LP) | C42: Pieces | D42: SHOCKSTAR | E42: MT. ROCK POWDER CORP. | F42: 2.4 METER | G42: 0 | H42: -
A43: Non Electric Detonator (LP) | C43: Pieces | D43: EXEL LP | E43: EXPEDITION MBDInc. | F43: 2.4 METER | G43: 44575 | H43: -
A44: Non Electric Detonator (LP) | C44: Pieces | D44: EXEL LP | E44: EXPEDITION MBDInc. | F44: 3.6 METER | G44: 836 | H44: -
A45: Non Electric Detonator (LP) | C45: Pieces | D45: EXEL LP | E45: EXPEDITION MBDInc. | F45: 4.9 METER | G45: 0 | H45: -
...

Sheet JANUARY 2026 - EXPLO 
A1: FROM: OFFICE OF DIRECTOR | E1: FAX NO. : 9209130
B3: MGB Form No. 15-8
A5: Republic of the Philippines
A6: Department of Environment and Natural Resources
A7: MINES AND GEOSCIENCES BUREAU
A8: North Avenue, Diliman, Quezon City
A10: EXPLOSIVES AND ACCESSORIES CONSUMPTION
A11: ='JANUARY 2026 -PMC '!A11:H11 -> REPORT FOR THE MONTH OF JANUARY 2026
F13: DATE | G13: ='JANUARY 2026 -PMC '!G13:H13 -> JANUARY 1-31,2026
A14: Company : | C14: PHILSAGA MINING CORPORATION. - EXPLORATION PROJECT
C15: (MPSA No. 262-2008-XIII PARCEL-2)
A16: Project site Address : | C16: BAYUGAN 3, ROSARIO, AGUSAN DEL SUR | F16: PPEL No.P- | G16: 0425-298-2011
A17: Head of Project : | C17: ENGR. EARL M. SON
A18: Drilling and Blasting Engineer/s : | C18: ENGR. RAFFY D. TORRES | F18: BPL No.F- | G18: EXPL-0411128
A20: ITEM | C20: UNIT | D20: BRAND | E20: SUPPLIERS/CONTRACTOR | F20: SPECIFICATION | G20: QUANTITY USED | H20: QUANTITY USED
G21: PCS/METERS | H21: KLS
A22: A. DYNA / EMULSION | C22: Pieces/Kilograms | D22: SENATEL PULSAR 215 | E22: EXPEDITION MBDInc. | F22: 25x 200mm | G22: 3128 | H22: =G22/215*25 -> 363.72093
A23: B. Ammonium Nitrate fuel oil (ANFO) | C23: Kilograms | D23: PEXPO ANFO | E23: EXPEDITION MBDInc. | F23: 25 KGS/BAG | G23: - | H23: 375.6
A24: C. Slurry | C24: Kilograms | D24: - | E24: EXPEDITION MBDInc. | F24: - | H24: -
A25: D. Electric Blasting CAP | C25: Pieces | D25: EBC | E25: EXPEDITION MBDInc. | F25: - | G25: 0 | H25: -
A26: E. Ordinary Blasting CAP | C26: Pieces | D26: OBC | E26: EXPEDITION MBDInc. | F26: (#8) | G26: 84
A27: F. Non Electric / LP Detonator | C27: Pieces | D27: EXEL LP | E27: EXPEDITION MBDInc. | F27: 2.4 METER | G27: 175
C28: Pieces | D28: EXEL LP | E28: EXPEDITION MBDInc. | F28: 3.6 METER | G28: 773 | H28: -
A29: G. Safety Fuse | C29: Meter | D29: SAFETY FUSE | E29: EXPEDITION MBDInc. | F29: 410mmx410mmx270mm | G29: =G26*2.43 -> 204.12 | H29: -
A30: H. Detonating Cords | C30: Meter | D30: CORDTEX | E30: EXPEDITION MBDInc. | F30: 5 GRAMS/METER | G30: 328 | H30: -
A31: I. Primer | C31: Pieces | D31: PENTEX(STOPE PRIME) | E31: EXPEDITION MBDInc. | F31: 250 GRAMS/PIECE | G31: - | H31: -
D32: PENTEX(PRIME SPIDER) | E32: EXPEDITION MBDInc. | G32: - | H32: -
A33: J. Connector Cord | C33: Meter | D33: - | E33: - | F33: - | G33: - | H33: -
D34: - | E34: - | F34: - | G34: - | H34: -
A35: K. Fuse Lighter | C35: Pieces | D35: FIRE FUSE | E35: EXPEDITION MBDInc. | F35: - | G35: 3 | H35: -
A36: L. Spitter/Igniter Cord | C36: Meter | D36: - | E36: - | F36: - | G36: - | H36: -
A37: M.Bill Wire | C37: Meter | D37: - | E37: - | F37: - | G37: - | H37: -
A40: Prepared by: | D40: Confirmed by: | F40: Review by:
A43: MR. RAFFY D. TORRES | D43: MR. MARJUN T. ANTIPUESTO | F43: ENGR. JONEL L. CABRIADAS
A44: Mine Explosives Manager | D44: Blaster Foreman | F44: Lift Manager
A45: PHILSAGA MINING CORPORATION | D45: Expedition MBDInc | F45: PHILSAGA MINING CORPORATION
A46: Blaster License: FKB15 - 080917- 04562 | D46: Blaster License: FKD02-090321-0640
A49: Noted by:
A52: ENGR. EARL M. SON
A53: Mine Division Manager
...

Sheet JANUARY 2026- TIGERWAY  
A1: FROM: OFFICE OF DIRECTOR | E1: FAX NO. : 9209130
B3: MGB Form No. 15-8
A4: Republic of the Philippines
A5: Department of Environment and Natural Resources
A6: MINES AND GEOSCIENCES BUREAU
A7: North Avenue, Diliman, Quezon City
A9: EXPLOSIVES AND ACCESSORIES CONSUMPTION
A10: ='JANUARY 2026 -PMC '!A11:H11 -> REPORT FOR THE MONTH OF JANUARY 2026
G12: DATE | H12: JANUARY 1-31,2026
A13: Company : | C13: PHILSAGA MINING CORP. - TIGERWAY DECLINE PROJECT
C14: (MPSA No. 262-2008-XIII PARCEL 1)
A15: Project site Address : | C15: UPPER CO-O, CONSUELO, BUNAWAN, AGUSAN DEL SUR | G15: PPEL No.P- | H15: 0425-298-2011
A16: Head of Project : | C16: ENGR. EARL M. SON
A17: Drilling and Blasting Engineer/s : | C17: ENGR. RAFFY D. TORRES | G17: BPL No.F- | H17: EXPL-0411128
A19: ITEM | C19: UNIT | D19: BRAND | E19: SUPPLIERS/CONTRACTOR | G19: SPECIFICATION | H19: QUANTITY USED | I19: QUANTITY USED
H20: PCS/METERS | I20: KLS
A21: A. DYNA / EMULSION | C21: Pieces/Kilograms | D21: SENATEL PULSAR 215 | E21: EXPEDITION MBDInc. | G21: 25x 200mm
C22: Pieces/Kilograms | D22: SUPERPOWER90 91 | E22: MT. ROCK POWDER CORP. | G22: 32x300mm | H22: 0 | I22: =H22/91*25 -> 0
C23: Pieces/Kilograms | D23: SUPERPOWER90 208 | E23: MT. ROCK POWDER CORP. | G23: 25x200mm | H23: 0 | I23: =H23/208*25 -> 0
C24: Pieces/Kilograms | D24: NEOGEL 901 91 | E24: MT. ROCK POWDER CORP. | G24: 32X300mm | H24: =177*91 -> 16107 | I24: =H24/91*25 -> 4425
C25: Pieces/Kilograms | D25: NEOGEL 901 200 | E25: MT. ROCK POWDER CORP. | G25: 25X200mm | H25: 0 | I25: =H25/200*25 -> 0
A26: B. Ammonium Nitrate fuel oil (ANFO) | C26: Kilograms | D26: ANFO | E26: MT. ROCK POWDER CORP. | G26: 25 KGS/BAG | I26: =112*25 -> 2800
A27: C. Slurry | C27: Kilograms | D27: - | E27: MT. ROCK POWDER CORP. | G27: - | H27: - | I27: -
A28: D. Electric Blasting CAP | C28: Pieces | D28: EBC | E28: MT. ROCK POWDER CORP. | G28: - | H28: - | I28: -
A29: E. Ordinary Blasting CAP | C29: Pieces | D29: OBC | E29: MT. ROCK POWDER CORP. | G29: (#8) | H29: 179
A30: F. Non Electric / LP Detonator | C30: Pieces | D30: SUPREME | E30: MT. ROCK POWDER CORP. | G30: 2.4 METER | H30: 6 | I30: -
C31: Pieces | D31: SUPREME | E31: MT. ROCK POWDER CORP. | G31: 4.9 METER | H31: 1780 | I31: -
C32: Pieces | D32: SHOCKSTAR | E32: MT. ROCK POWDER CORP. | G32: 2.4 METER | H32: - | I32: -
C33: Pieces | D33: SHOCKSTAR | E33: MT. ROCK POWDER CORP. | G33: 4.8 METER | H33: -
A34: G. Safety Fuse | C34: Meter | D34: SAFETY FUSE | E34: MT. ROCK POWDER CORP. | G34: 410mmx410mmx270mm | H34: 249 | I34: -
A35: H. Detonating Cords | C35: Meter | D35: NEO. CORD | E35: MT. ROCK POWDER CORP. | G35: 10 GRAMS/METER | H35: 0 | I35: -
C36: Meter | D36: DET. CORD | E36: MT. ROCK POWDER CORP. | G36: 10 GRAMS/METER | H36: 1451
C37: Meter | D37: DET. CORD | E37: MT. ROCK POWDER CORP. | G37: 40 GRAMS/METER | H37: 1275
A38: I. Primer | C38: Pieces | D38: PENTEX(STOPE PRIME) | E38: MT. ROCK POWDER CORP. | G38: 250 GRAMS/PIECE | H38: - | I38: -
D39: PENTEX(PRIME SPIDER) | E39: MT. ROCK POWDER CORP. | H39: - | I39: -
A40: J. Connector Cord | C40: Meter | D40: - | E40: - | G40: - | H40: - | I40: -
D41: - | E41: - | G41: - | H41: - | I41: -
A42: K. Fuse Lighter | C42: Pieces | D42: FIRE FUSE | E42: MT. ROCK POWDER CORP. | G42: - | H42: - | I42: -
A43: L. Spitter/Igniter Cord | C43: Meter | D43: - | E43: - | G43: - | H43: - | I43: -
A44: M.Bill Wire | C44: Meter | D44: - | E44: - | G44: - | H44: - | I44: -
...

Sheet FEBRUARY 2026 -PMC 
A1: FROM: OFFICE OF DIRECTOR | E1: FAX NO. : 9209130
B3: MGB Form No. 15-8
A5: Republic of the Philippines
A6: Department of Environment and Natural Resources
A7: MINES AND GEOSCIENCES BUREAU
A8: North Avenue, Diliman, Quezon City
A10: EXPLOSIVES AND ACCESSORIES CONSUMPTION
A11: REPORT FOR THE MONTH OF FEBRUARY 2026
F13: DATE | G13: FEBRUARY 1-28,2026
A14: Company : | C14: PHILSAGA MINING CORPORATION - CO-O GOLD PROJECT
C15: (MPSA No. 262-2008-XIII PARCEL 1)
A16: Minesite Address : | C16: Coo-Consuelo, Bunawan, Agusan del Sur | F16: PPEL No.P- | G16: 0425-298-2011
A17: Head of Project : | C17: ENGR. EARL M. SON
A18: Drilling and Blasting Engineer/s : | C18: ENGR. RAFFY D. TORRES | F18: BPL No.F- | G18: EXPL-0411128
A20: ITEM | C20: UNIT | D20: BRAND | E20: SUPPLIERS/CONTRACTOR | F20: SPECIFICATION | G20: QUANTITY USED | H20: QUANTITY USED | M20: =1049-15 -> 1034
G21: PCS/METERS | H21: KLS
A22: A. DYNA / EMULSION PACKAGE | C22: Pieces/Kilograms | D22: EMULEX AUSTIN 200 | E22: MT. ROCK POWDER CORP. | F22: 25 x 200mm | G22: - | H22: -
D23: SUPER POWER 150 | E23: MT. ROCK POWDER CORP. | F23: 25 x 200mm | G23: - | H23: -
D24: NEOGEL 200 | E24: MT. ROCK POWDER CORP. | F24: 25 x 200mm | G24: 41302 | H24: =G24/200*25 -> 5162.75
D25: SUPERDYNE 200 | E25: EXPEDITION MBDInc. | F25: 25x 200mm | G25: - | H25: -
D26: SENATEL MAGNUM 150 | E26: EXPEDITION MBDInc. | F26: 25x 300mm | G26: -
D27: DYAGEL 150 | E27: EXPEDITION MBDInc. | F27: 20x 200mm | G27: - | H27: -
D28: SENATEL PULSAR 150 | E28: EXPEDITION MBDInc. | F28: 25x 200mm | G28: - | H28: -
D29: SENATEL PULSAR 38 | E29: EXPEDITION MBDInc. | F29: 32x 200mm | G29: - | H29: -
D30: SENATEL PULSAR 135 | E30: EXPEDITION MBDInc. | F30: 32x 200mm | G30: - | H30: -
D31: SENATEL PULSAR 215 | E31: EXPEDITION MBDInc. | F31: 25x 200mm | G31: 39560 | H31: =G31/215*25 -> 4600
A32: B. Ammonium | C32: Kilograms | D32: PEXPO ANFO | E32: EXPEDITION MBDInc. | F32: 25 KGS/BAG | G32: - | H32: =I32 -> 39560 | I32: 39560 | J32: =H32+H33 -> #VALUE!
A33: Nitrate fuel oil (ANFO) | D33: ROCK ANFO | E33: MT. ROCK POWDER CORP. | F33: 25 KGS/BAG | G33: - | H33: - | J33: =I32/3 -> 13186.667 | K33: =J33*2 -> 26373.333
A34: C. Slurry | C34: Kilograms | D34: - | E34: - | F34: - | G34: - | H34: -
A35: D. Electric Blasting CAP | C35: Pieces | D35: EBC | E35: EXPEDITION MBDInc. | F35: - | G35: 158 | H35: -
A36: E. Ordinary Blasting CAP | C36: Pieces | D36: OBC | E36: EXPEDITION MBDInc. | G36: =I36/2 -> 2310 | I36: 4620
D37: OBC | E37: MT. ROCK POWDER CORP. | F37: (#8) | G37: =I36/2 -> 2310 | H37: -
A38: F. Non Electric Detonator (LP) | C38: Pieces | D38: NONEL | E38: MT. ROCK POWDER CORP. | F38: 2.4 METER | G38: 0 | H38: -
D39: NONEL | E39: MT. ROCK POWDER CORP. | F39: 3.6 METER | G39: 0 | H39: -
A40: Non Electric Detonator (LP) | C40: Pieces | D40: SUPREME | E40: MT. ROCK POWDER CORP. | F40: 2.4 METER | G40: 0 | H40: -
A41: Non Electric Detonator (LP) | C41: Pieces | D41: SUPREME | E41: MT. ROCK POWDER CORP. | F41: 3.6 METER | G41: 0 | H41: -
A42: Non Electric Detonator (LP) | C42: Pieces | D42: SHOCKSTAR | E42: MT. ROCK POWDER CORP. | F42: 2.4 METER | G42: 0 | H42: -
A43: Non Electric Detonator (LP) | C43: Pieces | D43: EXEL LP | E43: EXPEDITION MBDInc. | F43: 2.4 METER | G43: 39733 | H43: -
A44: Non Electric Detonator (LP) | C44: Pieces | D44: EXEL LP | E44: EXPEDITION MBDInc. | F44: 3.6 METER | G44: 414 | H44: -
A45: Non Electric Detonator (LP) | C45: Pieces | D45: EXEL LP | E45: EXPEDITION MBDInc. | F45: 4.9 METER | G45: 0 | H45: -
...

Sheet FEBRUARY 2026 - EXPLO
A1: FROM: OFFICE OF DIRECTOR | E1: FAX NO. : 9209130
B3: MGB Form No. 15-8
A5: Republic of the Philippines
A6: Department of Environment and Natural Resources
A7: MINES AND GEOSCIENCES BUREAU
A8: North Avenue, Diliman, Quezon City
A10: EXPLOSIVES AND ACCESSORIES CONSUMPTION
A11: ='FEBRUARY 2026 -PMC '!A11:H11 -> REPORT FOR THE MONTH OF FEBRUARY 2026
F13: DATE | G13: ='FEBRUARY 2026 -PMC '!G13:H13 -> FEBRUARY 1-28,2026
A14: Company : | C14: PHILSAGA MINING CORPORATION. - EXPLORATION PROJECT
C15: (MPSA No. 262-2008-XIII PARCEL-2)
A16: Project site Address : | C16: BAYUGAN 3, ROSARIO, AGUSAN DEL SUR | F16: PPEL No.P- | G16: 0425-298-2011
A17: Head of Project : | C17: ENGR. EARL M. SON
A18: Drilling and Blasting Engineer/s : | C18: ENGR. RAFFY D. TORRES | F18: BPL No.F- | G18: EXPL-0411128
A20: ITEM | C20: UNIT | D20: BRAND | E20: SUPPLIERS/CONTRACTOR | F20: SPECIFICATION | G20: QUANTITY USED | H20: QUANTITY USED
G21: PCS/METERS | H21: KLS
A22: A. DYNA / EMULSION | C22: Pieces/Kilograms | D22: SENATEL PULSAR 215 | E22: EXPEDITION MBDInc. | F22: 25x 200mm | G22: 1090 | H22: =G22/215*25 -> 126.74419
A23: B. Ammonium Nitrate fuel oil (ANFO) | C23: Kilograms | D23: PEXPO ANFO | E23: EXPEDITION MBDInc. | F23: 25 KGS/BAG | G23: - | H23: 118.4
A24: C. Slurry | C24: Kilograms | D24: - | E24: EXPEDITION MBDInc. | F24: - | H24: -
A25: D. Electric Blasting CAP | C25: Pieces | D25: EBC | E25: EXPEDITION MBDInc. | F25: - | G25: 0 | H25: -
A26: E. Ordinary Blasting CAP | C26: Pieces | D26: OBC | E26: EXPEDITION MBDInc. | F26: (#8) | G26: 30
A27: F. Non Electric / LP Detonator | C27: Pieces | D27: EXEL LP | E27: EXPEDITION MBDInc. | F27: 2.4 METER | G27: 145
C28: Pieces | D28: EXEL LP | E28: EXPEDITION MBDInc. | F28: 3.6 METER | G28: 173 | H28: -
A29: G. Safety Fuse | C29: Meter | D29: SAFETY FUSE | E29: EXPEDITION MBDInc. | F29: 410mmx410mmx270mm | G29: =G26*2.43 -> 72.9 | H29: -
A30: H. Detonating Cords | C30: Meter | D30: CORDTEX | E30: EXPEDITION MBDInc. | F30: 5 GRAMS/METER | G30: 110 | H30: -
A31: I. Primer | C31: Pieces | D31: PENTEX(STOPE PRIME) | E31: EXPEDITION MBDInc. | F31: 250 GRAMS/PIECE | G31: - | H31: -
D32: PENTEX(PRIME SPIDER) | E32: EXPEDITION MBDInc. | G32: - | H32: -
A33: J. Connector Cord | C33: Meter | D33: - | E33: - | F33: - | G33: - | H33: -
D34: - | E34: - | F34: - | G34: - | H34: -
A35: K. Fuse Lighter | C35: Pieces | D35: FIRE FUSE | E35: EXPEDITION MBDInc. | F35: - | G35: 0 | H35: -
A36: L. Spitter/Igniter Cord | C36: Meter | D36: - | E36: - | F36: - | G36: - | H36: -
A37: M.Bill Wire | C37: Meter | D37: - | E37: - | F37: - | G37: - | H37: -
A40: Prepared by: | D40: Confirmed by: | F40: Review by:
A43: MR. RAFFY D. TORRES | D43: MR. MARJUN T. ANTIPUESTO | F43: ENGR. JONEL L. CABRIADAS
A44: Mine Explosives Manager | D44: Blaster Foreman | F44: Lift Manager
A45: PHILSAGA MINING CORPORATION | D45: Expedition MBDInc | F45: PHILSAGA MINING CORPORATION
A46: Blaster License: FKB15 - 080917- 04562 | D46: Blaster License: FKD02-090321-0640
A49: Noted by:
A52: ENGR. EARL M. SON
A53: Mine Division Manager
...

Sheet FEBRUARY 2026- TIGERWAY  
A1: FROM: OFFICE OF DIRECTOR | E1: FAX NO. : 9209130
B3: MGB Form No. 15-8
A4: Republic of the Philippines
A5: Department of Environment and Natural Resources
A6: MINES AND GEOSCIENCES BUREAU
A7: North Avenue, Diliman, Quezon City
A9: EXPLOSIVES AND ACCESSORIES CONSUMPTION
A10: ='FEBRUARY 2026 -PMC '!A11:H11 -> REPORT FOR THE MONTH OF FEBRUARY 2026
G12: DATE | H12: FEBRUARY 1-28,2026
A13: Company : | C13: PHILSAGA MINING CORP. - TIGERWAY DECLINE PROJECT
C14: (MPSA No. 262-2008-XIII PARCEL 1)
A15: Project site Address : | C15: UPPER CO-O, CONSUELO, BUNAWAN, AGUSAN DEL SUR | G15: PPEL No.P- | H15: 0425-298-2011
A16: Head of Project : | C16: ENGR. EARL M. SON
A17: Drilling and Blasting Engineer/s : | C17: ENGR. RAFFY D. TORRES | G17: BPL No.F- | H17: EXPL-0411128
A19: ITEM | C19: UNIT | D19: BRAND | E19: SUPPLIERS/CONTRACTOR | G19: SPECIFICATION | H19: QUANTITY USED | I19: QUANTITY USED
H20: PCS/METERS | I20: KLS
A21: A. DYNA / EMULSION | C21: Pieces/Kilograms | D21: SENATEL PULSAR 215 | E21: EXPEDITION MBDInc. | G21: 25x 200mm
C22: Pieces/Kilograms | D22: SUPERPOWER90 91 | E22: MT. ROCK POWDER CORP. | G22: 32x300mm | H22: 0 | I22: =H22/91*25 -> 0
C23: Pieces/Kilograms | D23: SUPERPOWER90 208 | E23: MT. ROCK POWDER CORP. | G23: 25x200mm | H23: 0 | I23: =H23/208*25 -> 0
C24: Pieces/Kilograms | D24: NEOGEL 901 91 | E24: MT. ROCK POWDER CORP. | G24: 32X300mm | H24: 2002 | I24: =H24/91*25 -> 550
C25: Pieces/Kilograms | D25: NEO PRIME 93 | E25: MT. ROCK POWDER CORP. | G25: 32X300mm | H25: 11904 | I25: =H25/93*25 -> 3200
C26: Pieces/Kilograms | D26: NEOGEL 901 200 | E26: MT. ROCK POWDER CORP. | G26: 25X200mm | H26: 0 | I26: =H26/200*25 -> 0
A27: B. Ammonium Nitrate fuel oil (ANFO) | C27: Kilograms | D27: ANFO | E27: MT. ROCK POWDER CORP. | G27: 25 KGS/BAG | I27: 3575
A28: C. Slurry | C28: Kilograms | D28: - | E28: MT. ROCK POWDER CORP. | G28: - | H28: - | I28: -
A29: D. Electric Blasting CAP | C29: Pieces | D29: EBC | E29: MT. ROCK POWDER CORP. | G29: - | H29: - | I29: -
A30: E. Ordinary Blasting CAP | C30: Pieces | D30: OBC | E30: MT. ROCK POWDER CORP. | G30: (#8) | H30: 147
A31: F. Non Electric / LP Detonator | C31: Pieces | D31: SUPREME | E31: MT. ROCK POWDER CORP. | G31: 2.4 METER | H31: 0 | I31: -
C32: Pieces | D32: SUPREME | E32: MT. ROCK POWDER CORP. | G32: 4.9 METER | H32: 1683 | I32: -
C33: Pieces | D33: SHOCKSTAR | E33: MT. ROCK POWDER CORP. | G33: 2.4 METER | H33: - | I33: -
C34: Pieces | D34: SHOCKSTAR | E34: MT. ROCK POWDER CORP. | G34: 4.8 METER | H34: -
A35: G. Safety Fuse | C35: Meter | D35: SAFETY FUSE | E35: MT. ROCK POWDER CORP. | G35: 410mmx410mmx270mm | H35: 171 | I35: -
A36: H. Detonating Cords | C36: Meter | D36: NEO. CORD | E36: MT. ROCK POWDER CORP. | G36: 10 GRAMS/METER | H36: 0 | I36: -
C37: Meter | D37: DET. CORD | E37: MT. ROCK POWDER CORP. | G37: 10 GRAMS/METER | H37: 1406
C38: Meter | D38: DET. CORD | E38: MT. ROCK POWDER CORP. | G38: 40 GRAMS/METER | H38: 1575
A39: I. Primer | C39: Pieces | D39: PENTEX(STOPE PRIME) | E39: MT. ROCK POWDER CORP. | G39: 250 GRAMS/PIECE | H39: - | I39: -
D40: PENTEX(PRIME SPIDER) | E40: MT. ROCK POWDER CORP. | H40: - | I40: -
A41: J. Connector Cord | C41: Meter | D41: - | E41: - | G41: - | H41: - | I41: -
D42: - | E42: - | G42: - | H42: - | I42: -
A43: K. Fuse Lighter | C43: Pieces | D43: FIRE FUSE | E43: MT. ROCK POWDER CORP. | G43: - | H43: - | I43: -
A44: L. Spitter/Igniter Cord | C44: Meter | D44: - | E44: - | G44: - | H44: - | I44: -
...

Sheet MARCH  2026 -PMC  
A1: FROM: OFFICE OF DIRECTOR | E1: FAX NO. : 9209130
B3: MGB Form No. 15-8
A5: Republic of the Philippines
A6: Department of Environment and Natural Resources
A7: MINES AND GEOSCIENCES BUREAU
A8: North Avenue, Diliman, Quezon City
A10: EXPLOSIVES AND ACCESSORIES CONSUMPTION
A11: REPORT FOR THE MONTH OF MARCH 2026
F13: DATE | G13: MARCH 1-31,2026
A14: Company : | C14: PHILSAGA MINING CORPORATION - CO-O GOLD PROJECT
C15: (MPSA No. 262-2008-XIII PARCEL 1)
A16: Minesite Address : | C16: Coo-Consuelo, Bunawan, Agusan del Sur | F16: PPEL No.P- | G16: 0425-298-2011
A17: Head of Project : | C17: ENGR. EARL M. SON
A18: Drilling and Blasting Engineer/s : | C18: ENGR. EDWIN B. BATAL | F18: BPL No.F- | G18: EXPL-0411128
A20: ITEM | C20: UNIT | D20: BRAND | E20: SUPPLIERS/CONTRACTOR | F20: SPECIFICATION | G20: QUANTITY USED | H20: QUANTITY USED | M20: =1049-15 -> 1034
G21: PCS/METERS | H21: KLS
A22: A. DYNA / EMULSION PACKAGE | C22: Pieces/Kilograms | D22: EMULEX AUSTIN 200 | E22: MT. ROCK POWDER CORP. | F22: 25 x 200mm | G22: - | H22: -
D23: SUPER POWER 150 | E23: MT. ROCK POWDER CORP. | F23: 25 x 200mm | G23: - | H23: -
D24: NEOGEL 200 | E24: MT. ROCK POWDER CORP. | F24: 25 x 200mm | G24: 55225 | H24: =G24/200*25 -> 6903.125
D25: SUPERDYNE 200 | E25: EXPEDITION MBDInc. | F25: 25x 200mm | G25: - | H25: -
D26: SENATEL MAGNUM 150 | E26: EXPEDITION MBDInc. | F26: 25x 300mm | G26: -
D27: DYAGEL 150 | E27: EXPEDITION MBDInc. | F27: 20x 200mm | G27: - | H27: -
D28: SENATEL PULSAR 150 | E28: EXPEDITION MBDInc. | F28: 25x 200mm | G28: - | H28: -
D29: SENATEL PULSAR 38 | E29: EXPEDITION MBDInc. | F29: 32x 200mm | G29: - | H29: -
D30: SENATEL PULSAR 135 | E30: EXPEDITION MBDInc. | F30: 32x 200mm | G30: - | H30: -
D31: SENATEL PULSAR 215 | E31: EXPEDITION MBDInc. | F31: 25x 200mm | G31: 46249 | H31: =G31/215*25 -> 5377.7907
A32: B. Ammonium | C32: Kilograms | D32: PEXPO ANFO | E32: EXPEDITION MBDInc. | F32: 25 KGS/BAG | G32: - | H32: =I32 -> 35141.07 | I32: 35141.07 | J32: =H32+H33 -> #VALUE!
A33: Nitrate fuel oil (ANFO) | D33: ROCK ANFO | E33: MT. ROCK POWDER CORP. | F33: 25 KGS/BAG | G33: - | H33: - | J33: =I32/3 -> 11713.69 | K33: =J33*2 -> 23427.38
A34: C. Slurry | C34: Kilograms | D34: - | E34: - | F34: - | G34: - | H34: -
A35: D. Electric Blasting CAP | C35: Pieces | D35: EBC | E35: EXPEDITION MBDInc. | F35: - | G35: 156 | H35: -
A36: E. Ordinary Blasting CAP | C36: Pieces | D36: OBC | E36: EXPEDITION MBDInc. | G36: =I36/2 -> 2914 | I36: 5828
D37: OBC | E37: MT. ROCK POWDER CORP. | F37: (#8) | G37: =I36/2 -> 2914 | H37: -
A38: F. Non Electric Detonator (LP) | C38: Pieces | D38: NONEL | E38: MT. ROCK POWDER CORP. | F38: 2.4 METER | G38: 0 | H38: -
D39: NONEL | E39: MT. ROCK POWDER CORP. | F39: 3.6 METER | G39: 0 | H39: -
A40: Non Electric Detonator (LP) | C40: Pieces | D40: SUPREME | E40: MT. ROCK POWDER CORP. | F40: 2.4 METER | G40: 0 | H40: -
A41: Non Electric Detonator (LP) | C41: Pieces | D41: SUPREME | E41: MT. ROCK POWDER CORP. | F41: 3.6 METER | G41: 0 | H41: -
A42: Non Electric Detonator (LP) | C42: Pieces | D42: SHOCKSTAR | E42: MT. ROCK POWDER CORP. | F42: 2.4 METER | G42: 0 | H42: -
A43: Non Electric Detonator (LP) | C43: Pieces | D43: EXEL LP | E43: EXPEDITION MBDInc. | F43: 2.4 METER | G43: 49312 | H43: -
A44: Non Electric Detonator (LP) | C44: Pieces | D44: EXEL LP | E44: EXPEDITION MBDInc. | F44: 3.6 METER | G44: 368 | H44: -
A45: Non Electric Detonator (LP) | C45: Pieces | D45: EXEL LP | E45: EXPEDITION MBDInc. | F45: 4.9 METER | G45: 0 | H45: -
...

Sheet MARCH 2026 - EXPLO
A1: FROM: OFFICE OF DIRECTOR | E1: FAX NO. : 9209130
B3: MGB Form No. 15-8
A5: Republic of the Philippines
A6: Department of Environment and Natural Resources
A7: MINES AND GEOSCIENCES BUREAU
A8: North Avenue, Diliman, Quezon City
A10: EXPLOSIVES AND ACCESSORIES CONSUMPTION
A11: ='MARCH 2026 -PMC '!A11:H11 -> REPORT FOR THE MONTH OF MARCH 2026
F13: DATE | G13: ='MARCH 2026 -PMC '!G13:H13 -> MARCH 1-31,2026
A14: Company : | C14: PHILSAGA MINING CORPORATION. - EXPLORATION PROJECT
C15: (MPSA No. 262-2008-XIII PARCEL-2)
A16: Project site Address : | C16: BAYUGAN 3, ROSARIO, AGUSAN DEL SUR | F16: PPEL No.P- | G16: 0425-298-2011
A17: Head of Project : | C17: ENGR. EARL M. SON
A18: Drilling and Blasting Engineer/s : | C18: ENGR. EDWIN B. BATAL | F18: BPL No.F- | G18: EXPL-0411128
A20: ITEM | C20: UNIT | D20: BRAND | E20: SUPPLIERS/CONTRACTOR | F20: SPECIFICATION | G20: QUANTITY USED | H20: QUANTITY USED
G21: PCS/METERS | H21: KLS
A22: A. DYNA / EMULSION | C22: Pieces/Kilograms | D22: SENATEL PULSAR 215 | E22: EXPEDITION MBDInc. | F22: 25x 200mm | G22: - | H22: -
A23: B. Ammonium Nitrate fuel oil (ANFO) | C23: Kilograms | D23: PEXPO ANFO | E23: EXPEDITION MBDInc. | F23: 25 KGS/BAG | G23: - | H23: -
A24: C. Slurry | C24: Kilograms | D24: - | E24: EXPEDITION MBDInc. | F24: - | G24: - | H24: -
A25: D. Electric Blasting CAP | C25: Pieces | D25: EBC | E25: EXPEDITION MBDInc. | F25: - | G25: - | H25: -
A26: E. Ordinary Blasting CAP | C26: Pieces | D26: OBC | E26: EXPEDITION MBDInc. | F26: (#8) | G26: - | H26: -
A27: F. Non Electric / LP Detonator | C27: Pieces | D27: EXEL LP | E27: EXPEDITION MBDInc. | F27: 2.4 METER | G27: - | H27: -
C28: Pieces | D28: EXEL LP | E28: EXPEDITION MBDInc. | F28: 3.6 METER | G28: - | H28: -
A29: G. Safety Fuse | C29: Meter | D29: SAFETY FUSE | E29: EXPEDITION MBDInc. | F29: 410mmx410mmx270mm | G29: - | H29: -
A30: H. Detonating Cords | C30: Meter | D30: CORDTEX | E30: EXPEDITION MBDInc. | F30: 5 GRAMS/METER | G30: - | H30: -
A31: I. Primer | C31: Pieces | D31: PENTEX(STOPE PRIME) | E31: EXPEDITION MBDInc. | F31: 250 GRAMS/PIECE | G31: - | H31: -
D32: PENTEX(PRIME SPIDER) | E32: EXPEDITION MBDInc. | G32: - | H32: -
A33: J. Connector Cord | C33: Meter | D33: - | E33: - | F33: - | G33: - | H33: -
D34: - | E34: - | F34: - | G34: - | H34: -
A35: K. Fuse Lighter | C35: Pieces | D35: FIRE FUSE | E35: EXPEDITION MBDInc. | F35: - | G35: - | H35: -
A36: L. Spitter/Igniter Cord | C36: Meter | D36: - | E36: - | F36: - | G36: - | H36: -
A37: M.Bill Wire | C37: Meter | D37: - | E37: - | F37: - | G37: - | H37: -
A40: Prepared by: | D40: Confirmed by: | F40: Review by:
A43: MR. EDWIN B. BATAL | D43: MR. ELMER L. GANZON | F43: ENGR. JONEL L. CABRIADAS
A44: Mine Explosives Asst. Manager | D44: Blaster Foreman | F44: Lift Manager
A45: PHILSAGA MINING CORPORATION | D45: Expedition MBDInc | F45: PHILSAGA MINING CORPORATION
A46: Blaster License: FKB15 - 080917- 04561 | D46: Blaster License: FPKB15-081325-0107
A49: Noted by:
A52: ENGR. EARL M. SON
A53: Mine Division Manager
...

Sheet MARCH 2026- TIGERWAY  
A1: FROM: OFFICE OF DIRECTOR | E1: FAX NO. : 9209130
B3: MGB Form No. 15-8
A4: Republic of the Philippines
A5: Department of Environment and Natural Resources
A6: MINES AND GEOSCIENCES BUREAU
A7: North Avenue, Diliman, Quezon City
A9: EXPLOSIVES AND ACCESSORIES CONSUMPTION
A10: ='MARCH 2026 -PMC '!A11:H11 -> REPORT FOR THE MONTH OF MARCH 2026
G12: DATE | H12: MARCH 1-31,2026
A13: Company : | C13: PHILSAGA MINING CORP. - TIGERWAY DECLINE PROJECT
C14: (MPSA No. 262-2008-XIII PARCEL 1)
A15: Project site Address : | C15: UPPER CO-O, CONSUELO, BUNAWAN, AGUSAN DEL SUR | G15: PPEL No.P- | H15: 0425-298-2011
A16: Head of Project : | C16: ENGR. EARL M. SON
A17: Drilling and Blasting Engineer/s : | C17: ENGR. EDWIN B. BATAL | G17: BPL No.F- | H17: EXPL-0411128
A19: ITEM | C19: UNIT | D19: BRAND | E19: SUPPLIERS/CONTRACTOR | G19: SPECIFICATION | H19: QUANTITY USED | I19: QUANTITY USED
H20: PCS/METERS | I20: KLS
A21: A. DYNA / EMULSION | C21: Pieces/Kilograms | D21: SENATEL PULSAR 215 | E21: EXPEDITION MBDInc. | G21: 25x 200mm
C22: Pieces/Kilograms | D22: SUPERPOWER90 91 | E22: MT. ROCK POWDER CORP. | G22: 32x300mm | H22: 0 | I22: =H22/91*25 -> 0
C23: Pieces/Kilograms | D23: SUPERPOWER90 208 | E23: MT. ROCK POWDER CORP. | G23: 25x200mm | H23: 0 | I23: =H23/208*25 -> 0
C24: Pieces/Kilograms | D24: NEOGEL 901 91 | E24: MT. ROCK POWDER CORP. | G24: 32X300mm | H24: 637 | I24: =H24/91*25 -> 175
C25: Pieces/Kilograms | D25: NEO PRIME 93 | E25: MT. ROCK POWDER CORP. | G25: 32X300mm | H25: 14880 | I25: =H25/93*25 -> 4000
C26: Pieces/Kilograms | D26: NEOGEL 901 200 | E26: MT. ROCK POWDER CORP. | G26: 25X200mm | H26: 0 | I26: =H26/200*25 -> 0
A27: B. Ammonium Nitrate fuel oil (ANFO) | C27: Kilograms | D27: ANFO | E27: MT. ROCK POWDER CORP. | G27: 25 KGS/BAG | I27: 2325
A28: C. Slurry | C28: Kilograms | D28: - | E28: MT. ROCK POWDER CORP. | G28: - | H28: - | I28: -
A29: D. Electric Blasting CAP | C29: Pieces | D29: EBC | E29: MT. ROCK POWDER CORP. | G29: - | H29: - | I29: -
A30: E. Ordinary Blasting CAP | C30: Pieces | D30: OBC | E30: MT. ROCK POWDER CORP. | G30: (#8) | H30: 166
A31: F. Non Electric / LP Detonator | C31: Pieces | D31: SUPREME | E31: MT. ROCK POWDER CORP. | G31: 2.4 METER | H31: 0 | I31: -
C32: Pieces | D32: SUPREME | E32: MT. ROCK POWDER CORP. | G32: 4.9 METER | H32: 1820 | I32: -
C33: Pieces | D33: SUPREME | E33: MT. ROCK POWDER CORP. | G33: 4.5 METER | H33: 210 | I33: -
C34: Pieces | D34: RIONEL | E34: MT. ROCK POWDER CORP. | G34: 6 METER | H34: 10
C35: Pieces | D35: SHOCKSTAR | E35: MT. ROCK POWDER CORP. | G35: 2.4 METER | H35: - | I35: -
C36: Pieces | D36: SHOCKSTAR | E36: MT. ROCK POWDER CORP. | G36: 4.8 METER | H36: -
A37: G. Safety Fuse | C37: Meter | D37: SAFETY FUSE | E37: MT. ROCK POWDER CORP. | G37: 410mmx410mmx270mm | H37: 239 | I37: -
A38: H. Detonating Cords | C38: Meter | D38: NEO. CORD | E38: MT. ROCK POWDER CORP. | G38: 10 GRAMS/METER | H38: 145 | I38: -
C39: Meter | D39: DET. CORD | E39: MT. ROCK POWDER CORP. | G39: 10 GRAMS/METER | H39: 856
C40: Meter | D40: DET. CORD | E40: MT. ROCK POWDER CORP. | G40: 40 GRAMS/METER | H40: 1200
A41: I. Primer | C41: Pieces | D41: PENTEX(STOPE PRIME) | E41: MT. ROCK POWDER CORP. | G41: 250 GRAMS/PIECE | H41: - | I41: -
D42: PENTEX(PRIME SPIDER) | E42: MT. ROCK POWDER CORP. | H42: - | I42: -
A43: J. Connector Cord | C43: Meter | D43: - | E43: - | G43: - | H43: - | I43: -
D44: - | E44: - | G44: - | H44: - | I44: -
...

Sheet APRIL  2026 -PMC 
A1: FROM: OFFICE OF DIRECTOR | E1: FAX NO. : 9209130
B3: MGB Form No. 15-8
A5: Republic of the Philippines
A6: Department of Environment and Natural Resources
A7: MINES AND GEOSCIENCES BUREAU
A8: North Avenue, Diliman, Quezon City
A10: EXPLOSIVES AND ACCESSORIES CONSUMPTION
A11: REPORT FOR THE MONTH OF APRIL 2026
F13: DATE | G13: APRIL 1-30,2026
A14: Company : | C14: PHILSAGA MINING CORPORATION - CO-O GOLD PROJECT
C15: (MPSA No. 262-2008-XIII PARCEL 1)
A16: Minesite Address : | C16: Coo-Consuelo, Bunawan, Agusan del Sur | F16: PPEL No.P- | G16: 0425-298-2011
A17: Head of Project : | C17: ENGR. EARL M. SON
A18: Drilling and Blasting Engineer/s : | C18: ENGR. EDWIN B. BATAL | F18: BPL No.F- | G18: EXPL-0411128
A20: ITEM | C20: UNIT | D20: BRAND | E20: SUPPLIERS/CONTRACTOR | F20: SPECIFICATION | G20: QUANTITY USED | H20: QUANTITY USED | M20: =1049-15 -> 1034
G21: PCS/METERS | H21: KLS
A22: A. DYNA / EMULSION PACKAGE | C22: Pieces/Kilograms | D22: EMULEX AUSTIN 200 | E22: MT. ROCK POWDER CORP. | F22: 25 x 200mm | G22: - | H22: -
D23: SUPER POWER 150 | E23: MT. ROCK POWDER CORP. | F23: 25 x 200mm | G23: - | H23: -
D24: NEOGEL 200 | E24: MT. ROCK POWDER CORP. | F24: 25 x 200mm | G24: 16788 | H24: =G24/200*25 -> 2098.5
D25: SUPERDYNE 200 | E25: EXPEDITION MBDInc. | F25: 25x 200mm | G25: - | H25: -
D26: SENATEL MAGNUM 150 | E26: EXPEDITION MBDInc. | F26: 25x 300mm | G26: -
D27: DYAGEL 150 | E27: EXPEDITION MBDInc. | F27: 20x 200mm | G27: - | H27: -
D28: SENATEL PULSAR 150 | E28: EXPEDITION MBDInc. | F28: 25x 200mm | G28: - | H28: -
D29: SENATEL PULSAR 38 | E29: EXPEDITION MBDInc. | F29: 32x 200mm | G29: - | H29: -
D30: SENATEL PULSAR 135 | E30: EXPEDITION MBDInc. | F30: 32x 200mm | G30: - | H30: -
D31: SENATEL PULSAR 215 | E31: EXPEDITION MBDInc. | F31: 25x 200mm | G31: 63497 | H31: =G31/215*25 -> 7383.3721
A32: B. Ammonium | C32: Kilograms | D32: PEXPO ANFO | E32: EXPEDITION MBDInc. | F32: 25 KGS/BAG | G32: - | H32: 26252.2 | I32: 35141.07 | J32: =H32+H33 -> #VALUE!
A33: Nitrate fuel oil (ANFO) | D33: ROCK ANFO | E33: MT. ROCK POWDER CORP. | F33: 25 KGS/BAG | G33: - | H33: - | J33: =I32/3 -> 11713.69 | K33: =J33*2 -> 23427.38
A34: C. Slurry | C34: Kilograms | D34: - | E34: - | F34: - | G34: - | H34: -
A35: D. Electric Blasting CAP | C35: Pieces | D35: EBC | E35: EXPEDITION MBDInc. | F35: - | G35: 148 | H35: -
A36: E. Ordinary Blasting CAP | C36: Pieces | D36: OBC | E36: EXPEDITION MBDInc. | G36: =I36/2 -> 2299.5 | I36: 4599
D37: OBC | E37: MT. ROCK POWDER CORP. | F37: (#8) | G37: =I36/2 -> 2299.5 | H37: -
A38: F. Non Electric Detonator (LP) | C38: Pieces | D38: NONEL | E38: MT. ROCK POWDER CORP. | F38: 2.4 METER | G38: 0 | H38: -
D39: NONEL | E39: MT. ROCK POWDER CORP. | F39: 3.6 METER | G39: 0 | H39: -
A40: Non Electric Detonator (LP) | C40: Pieces | D40: SUPREME | E40: MT. ROCK POWDER CORP. | F40: 2.4 METER | G40: 0 | H40: -
A41: Non Electric Detonator (LP) | C41: Pieces | D41: SUPREME | E41: MT. ROCK POWDER CORP. | F41: 3.6 METER | G41: 0 | H41: -
A42: Non Electric Detonator (LP) | C42: Pieces | D42: SHOCKSTAR | E42: MT. ROCK POWDER CORP. | F42: 2.4 METER | G42: 0 | H42: -
A43: Non Electric Detonator (LP) | C43: Pieces | D43: EXEL LP | E43: EXPEDITION MBDInc. | F43: 2.4 METER | G43: 39526 | H43: -
A44: Non Electric Detonator (LP) | C44: Pieces | D44: EXEL LP | E44: EXPEDITION MBDInc. | F44: 3.6 METER | G44: 570 | H44: -
A45: Non Electric Detonator (LP) | C45: Pieces | D45: EXEL LP | E45: EXPEDITION MBDInc. | F45: 4.9 METER | G45: 0 | H45: -
...

Sheet APRIL 2026 - EXPLO 
A1: FROM: OFFICE OF DIRECTOR | E1: FAX NO. : 9209130
B3: MGB Form No. 15-8
A5: Republic of the Philippines
A6: Department of Environment and Natural Resources
A7: MINES AND GEOSCIENCES BUREAU
A8: North Avenue, Diliman, Quezon City
A10: EXPLOSIVES AND ACCESSORIES CONSUMPTION
A11: ='APRIL 2026 -PMC '!A11:H11 -> REPORT FOR THE MONTH OF APRIL 2026
F13: DATE | G13: ='APRIL 2026 -PMC '!G13:H13 -> APRIL 1-30,2026
A14: Company : | C14: PHILSAGA MINING CORPORATION. - EXPLORATION PROJECT
C15: (MPSA No. 262-2008-XIII PARCEL-2)
A16: Project site Address : | C16: BAYUGAN 3, ROSARIO, AGUSAN DEL SUR | F16: PPEL No.P- | G16: 0425-298-2011
A17: Head of Project : | C17: ENGR. EARL M. SON
A18: Drilling and Blasting Engineer/s : | C18: ENGR. EDWIN B. BATAL | F18: BPL No.F- | G18: EXPL-0411128
A20: ITEM | C20: UNIT | D20: BRAND | E20: SUPPLIERS/CONTRACTOR | F20: SPECIFICATION | G20: QUANTITY USED | H20: QUANTITY USED
G21: PCS/METERS | H21: KLS
A22: A. DYNA / EMULSION | C22: Pieces/Kilograms | D22: SENATEL PULSAR 215 | E22: EXPEDITION MBDInc. | F22: 25x 200mm | G22: - | H22: -
A23: B. Ammonium Nitrate fuel oil (ANFO) | C23: Kilograms | D23: PEXPO ANFO | E23: EXPEDITION MBDInc. | F23: 25 KGS/BAG | G23: - | H23: -
A24: C. Slurry | C24: Kilograms | D24: - | E24: EXPEDITION MBDInc. | F24: - | G24: - | H24: -
A25: D. Electric Blasting CAP | C25: Pieces | D25: EBC | E25: EXPEDITION MBDInc. | F25: - | G25: - | H25: -
A26: E. Ordinary Blasting CAP | C26: Pieces | D26: OBC | E26: EXPEDITION MBDInc. | F26: (#8) | G26: - | H26: -
A27: F. Non Electric / LP Detonator | C27: Pieces | D27: EXEL LP | E27: EXPEDITION MBDInc. | F27: 2.4 METER | G27: - | H27: -
C28: Pieces | D28: EXEL LP | E28: EXPEDITION MBDInc. | F28: 3.6 METER | G28: - | H28: -
A29: G. Safety Fuse | C29: Meter | D29: SAFETY FUSE | E29: EXPEDITION MBDInc. | F29: 410mmx410mmx270mm | G29: - | H29: -
A30: H. Detonating Cords | C30: Meter | D30: CORDTEX | E30: EXPEDITION MBDInc. | F30: 5 GRAMS/METER | G30: - | H30: -
A31: I. Primer | C31: Pieces | D31: PENTEX(STOPE PRIME) | E31: EXPEDITION MBDInc. | F31: 250 GRAMS/PIECE | G31: - | H31: -
D32: PENTEX(PRIME SPIDER) | E32: EXPEDITION MBDInc. | G32: - | H32: -
A33: J. Connector Cord | C33: Meter | D33: - | E33: - | F33: - | G33: - | H33: -
D34: - | E34: - | F34: - | G34: - | H34: -
A35: K. Fuse Lighter | C35: Pieces | D35: FIRE FUSE | E35: EXPEDITION MBDInc. | F35: - | G35: - | H35: -
A36: L. Spitter/Igniter Cord | C36: Meter | D36: - | E36: - | F36: - | G36: - | H36: -
A37: M.Bill Wire | C37: Meter | D37: - | E37: - | F37: - | G37: - | H37: -
A40: Prepared by: | D40: Confirmed by: | F40: Review by:
A43: MR. EDWIN B. BATAL | D43: MR. JOHN XERCES C. ANTIPUESTO | F43: ENGR. JONEL L. CABRIADAS
A44: Mine Explosives Asst. Manager | D44: Blaster Foreman | F44: Lift Manager
A45: PHILSAGA MINING CORPORATION | D45: Expedition MBDInc | F45: PHILSAGA MINING CORPORATION
A46: Blaster License: FKB15 - 080917- 04561 | D46: Blaster License: FPKB15-100925-0131
A49: Noted by:
A52: ENGR. EARL M. SON
A53: Mine Division Manager
...

Sheet APRIL 2026- TIGERWAY  
A1: FROM: OFFICE OF DIRECTOR | E1: FAX NO. : 9209130
B3: MGB Form No. 15-8
A4: Republic of the Philippines
A5: Department of Environment and Natural Resources
A6: MINES AND GEOSCIENCES BUREAU
A7: North Avenue, Diliman, Quezon City
A9: EXPLOSIVES AND ACCESSORIES CONSUMPTION
A10: ='APRIL 2026 -PMC '!A11:H11 -> REPORT FOR THE MONTH OF APRIL 2026
G12: DATE | H12: APRIL 1-30,2026
A13: Company : | C13: PHILSAGA MINING CORP. - TIGERWAY DECLINE PROJECT
C14: (MPSA No. 262-2008-XIII PARCEL 1)
A15: Project site Address : | C15: UPPER CO-O, CONSUELO, BUNAWAN, AGUSAN DEL SUR | G15: PPEL No.P- | H15: 0425-298-2011
A16: Head of Project : | C16: ENGR. EARL M. SON
A17: Drilling and Blasting Engineer/s : | C17: ENGR. EDWIN B. BATAL | G17: BPL No.F- | H17: EXPL-0411128
A19: ITEM | C19: UNIT | D19: BRAND | E19: SUPPLIERS/CONTRACTOR | G19: SPECIFICATION | H19: QUANTITY USED | I19: QUANTITY USED
H20: PCS/METERS | I20: KLS
A21: A. DYNA / EMULSION | C21: Pieces/Kilograms | D21: SENATEL PULSAR 215 | E21: EXPEDITION MBDInc. | G21: 25x 200mm
C22: Pieces/Kilograms | D22: SUPERPOWER90 91 | E22: MT. ROCK POWDER CORP. | G22: 32x300mm | H22: 0 | I22: =H22/91*25 -> 0
C23: Pieces/Kilograms | D23: SUPERPOWER90 208 | E23: MT. ROCK POWDER CORP. | G23: 25x200mm | H23: 0 | I23: =H23/208*25 -> 0
C24: Pieces/Kilograms | D24: NEOGEL 901 91 | E24: MT. ROCK POWDER CORP. | G24: 32X300mm | H24: 9464 | I24: =H24/91*25 -> 2600
C25: Pieces/Kilograms | D25: NEO PRIME 93 | E25: MT. ROCK POWDER CORP. | G25: 32X300mm | H25: 5208 | I25: =H25/93*25 -> 1400
C26: Pieces/Kilograms | D26: NEOGEL 901 200 | E26: MT. ROCK POWDER CORP. | G26: 25X200mm | H26: 400 | I26: =H26/200*25 -> 50
A27: B. Ammonium Nitrate fuel oil (ANFO) | C27: Kilograms | D27: ANFO | E27: MT. ROCK POWDER CORP. | G27: 25 KGS/BAG | I27: 2175
A28: C. Slurry | C28: Kilograms | D28: - | E28: MT. ROCK POWDER CORP. | G28: - | H28: - | I28: -
A29: D. Electric Blasting CAP | C29: Pieces | D29: EBC | E29: MT. ROCK POWDER CORP. | G29: - | H29: - | I29: -
A30: E. Ordinary Blasting CAP | C30: Pieces | D30: OBC | E30: MT. ROCK POWDER CORP. | G30: (#8) | H30: 157
A31: F. Non Electric / LP Detonator | C31: Pieces | D31: SUPREME | E31: MT. ROCK POWDER CORP. | G31: 2.4 METER | H31: 65 | I31: -
C32: Pieces | D32: SUPREME | E32: MT. ROCK POWDER CORP. | G32: 4.9 METER | H32: 2083 | I32: -
C33: Pieces | D33: SUPREME | E33: MT. ROCK POWDER CORP. | G33: 4.5 METER | H33: - | I33: -
C34: Pieces | D34: SUPREME | E34: MT. ROCK POWDER CORP. | G34: TLD | H34: 10
C35: Pieces | D35: RIONEL | E35: MT. ROCK POWDER CORP. | G35: 6 METER | H35: 200
C36: Pieces | D36: SHOCKSTAR | E36: MT. ROCK POWDER CORP. | G36: 2.4 METER | H36: - | I36: -
C37: Pieces | D37: SHOCKSTAR | E37: MT. ROCK POWDER CORP. | G37: 4.8 METER | H37: -
A38: G. Safety Fuse | C38: Meter | D38: SAFETY FUSE | E38: MT. ROCK POWDER CORP. | G38: 410mmx410mmx270mm | H38: 153 | I38: -
A39: H. Detonating Cords | C39: Meter | D39: NEO. CORD | E39: MT. ROCK POWDER CORP. | G39: 10 GRAMS/METER | H39: 1065 | I39: -
C40: Meter | D40: DET. CORD | E40: MT. ROCK POWDER CORP. | G40: 10 GRAMS/METER | H40: -
C41: Meter | D41: DET. CORD | E41: MT. ROCK POWDER CORP. | G41: 40 GRAMS/METER | H41: 1350
A42: I. Primer | C42: Pieces | D42: PENTEX(STOPE PRIME) | E42: MT. ROCK POWDER CORP. | G42: 250 GRAMS/PIECE | H42: - | I42: -
D43: PENTEX(PRIME SPIDER) | E43: MT. ROCK POWDER CORP. | H43: - | I43: -
A44: J. Connector Cord | C44: Meter | D44: - | E44: - | G44: - | H44: - | I44: -
...

Sheet MAY  2026 -PMC  
A1: FROM: OFFICE OF DIRECTOR | E1: FAX NO. : 9209130
B3: MGB Form No. 15-8
A5: Republic of the Philippines
A6: Department of Environment and Natural Resources
A7: MINES AND GEOSCIENCES BUREAU
A8: North Avenue, Diliman, Quezon City
A10: EXPLOSIVES AND ACCESSORIES CONSUMPTION
A11: REPORT FOR THE MONTH OF MAY 2026
F13: DATE | G13: MAY 1-31,2026
A14: Company : | C14: PHILSAGA MINING CORPORATION - CO-O GOLD PROJECT
C15: (MPSA No. 262-2008-XIII PARCEL 1)
A16: Minesite Address : | C16: Coo-Consuelo, Bunawan, Agusan del Sur | F16: PPEL No.P- | G16: 0425-298-2011
A17: Head of Project : | C17: ENGR. EARL M. SON
A18: Drilling and Blasting Engineer/s : | C18: ENGR. RAFFY D. TORRES | F18: BPL No.F- | G18: EXPL-0411128
A20: ITEM | C20: UNIT | D20: BRAND | E20: SUPPLIERS/CONTRACTOR | F20: SPECIFICATION | G20: QUANTITY USED | H20: QUANTITY USED | M20: =1049-15 -> 1034
G21: PCS/METERS | H21: KLS
A22: A. DYNA / EMULSION PACKAGE | C22: Pieces/Kilograms | D22: EMULEX AUSTIN 200 | E22: MT. ROCK POWDER CORP. | F22: 25 x 200mm | G22: - | H22: -
D23: SUPER POWER 150 | E23: MT. ROCK POWDER CORP. | F23: 25 x 200mm | G23: - | H23: -
D24: NEOGEL 200 | E24: MT. ROCK POWDER CORP. | F24: 25 x 200mm | G24: 46364 | H24: =G24/200*25 -> 5795.5
D25: SUPERDYNE 200 | E25: EXPEDITION MBDInc. | F25: 25x 200mm | G25: - | H25: -
D26: SENATEL MAGNUM 150 | E26: EXPEDITION MBDInc. | F26: 25x 300mm | G26: -
D27: DYAGEL 150 | E27: EXPEDITION MBDInc. | F27: 20x 200mm | G27: - | H27: -
D28: SENATEL PULSAR 150 | E28: EXPEDITION MBDInc. | F28: 25x 200mm | G28: - | H28: -
D29: SENATEL PULSAR 38 | E29: EXPEDITION MBDInc. | F29: 32x 200mm | G29: - | H29: -
D30: SENATEL PULSAR 135 | E30: EXPEDITION MBDInc. | F30: 32x 200mm | G30: - | H30: -
D31: SENATEL PULSAR 215 | E31: EXPEDITION MBDInc. | F31: 25x 200mm | G31: 42223 | H31: =G31/215*25 -> 4909.6512
A32: B. Ammonium | C32: Kilograms | D32: PEXPO ANFO | E32: EXPEDITION MBDInc. | F32: 25 KGS/BAG | G32: - | H32: =I32 -> 30961.5 | I32: 30961.5 | J32: =H32+H33 -> #VALUE!
A33: Nitrate fuel oil (ANFO) | D33: ROCK ANFO | E33: MT. ROCK POWDER CORP. | F33: 25 KGS/BAG | G33: - | H33: - | J33: =I32/3 -> 10320.5 | K33: =J33*2 -> 20641
A34: C. Slurry | C34: Kilograms | D34: - | E34: - | F34: - | G34: - | H34: -
A35: D. Electric Blasting CAP | C35: Pieces | D35: EBC | E35: EXPEDITION MBDInc. | F35: - | G35: 128 | H35: -
A36: E. Ordinary Blasting CAP | C36: Pieces | D36: OBC | E36: EXPEDITION MBDInc. | G36: =I36/2 -> 2501 | I36: 5002
D37: OBC | E37: MT. ROCK POWDER CORP. | F37: (#8) | G37: =I36/2 -> 2501 | H37: -
A38: F. Non Electric Detonator (LP) | C38: Pieces | D38: NONEL | E38: MT. ROCK POWDER CORP. | F38: 2.4 METER | G38: 0 | H38: -
D39: NONEL | E39: MT. ROCK POWDER CORP. | F39: 3.6 METER | G39: 0 | H39: -
A40: Non Electric Detonator (LP) | C40: Pieces | D40: SUPREME | E40: MT. ROCK POWDER CORP. | F40: 2.4 METER | G40: 0 | H40: -
A41: Non Electric Detonator (LP) | C41: Pieces | D41: SUPREME | E41: MT. ROCK POWDER CORP. | F41: 3.6 METER | G41: 0 | H41: -
A42: Non Electric Detonator (LP) | C42: Pieces | D42: SHOCKSTAR | E42: MT. ROCK POWDER CORP. | F42: 2.4 METER | G42: 0 | H42: -
A43: Non Electric Detonator (LP) | C43: Pieces | D43: EXEL LP | E43: EXPEDITION MBDInc. | F43: 2.4 METER | G43: 44222 | H43: -
A44: Non Electric Detonator (LP) | C44: Pieces | D44: EXEL LP | E44: EXPEDITION MBDInc. | F44: 3.6 METER | G44: 3453 | H44: -
A45: Non Electric Detonator (LP) | C45: Pieces | D45: EXEL LP | E45: EXPEDITION MBDInc. | F45: 4.9 METER | G45: 0 | H45: -
...

Sheet MAY 2026 - EXPLO  
A1: FROM: OFFICE OF DIRECTOR | E1: FAX NO. : 9209130
B3: MGB Form No. 15-8
A5: Republic of the Philippines
A6: Department of Environment and Natural Resources
A7: MINES AND GEOSCIENCES BUREAU
A8: North Avenue, Diliman, Quezon City
A10: EXPLOSIVES AND ACCESSORIES CONSUMPTION
A11: ='MAY 2026 -PMC '!A11:H11 -> REPORT FOR THE MONTH OF MAY 2026
F13: DATE | G13: ='MAY 2026 -PMC '!G13:H13 -> MAY 1-31,2026
A14: Company : | C14: PHILSAGA MINING CORPORATION. - EXPLORATION PROJECT
C15: (MPSA No. 262-2008-XIII PARCEL-2)
A16: Project site Address : | C16: BAYUGAN 3, ROSARIO, AGUSAN DEL SUR | F16: PPEL No.P- | G16: 0425-298-2011
A17: Head of Project : | C17: ENGR. EARL M. SON
A18: Drilling and Blasting Engineer/s : | C18: ENGR. RAFFY D. TORRES | F18: BPL No.F- | G18: EXPL-0411128
A20: ITEM | C20: UNIT | D20: BRAND | E20: SUPPLIERS/CONTRACTOR | F20: SPECIFICATION | G20: QUANTITY USED | H20: QUANTITY USED
G21: PCS/METERS | H21: KLS
A22: A. DYNA / EMULSION | C22: Pieces/Kilograms | D22: SENATEL PULSAR 215 | E22: EXPEDITION MBDInc. | F22: 25x 200mm | G22: - | H22: -
A23: B. Ammonium Nitrate fuel oil (ANFO) | C23: Kilograms | D23: PEXPO ANFO | E23: EXPEDITION MBDInc. | F23: 25 KGS/BAG | G23: - | H23: -
A24: C. Slurry | C24: Kilograms | D24: - | E24: EXPEDITION MBDInc. | F24: - | G24: - | H24: -
A25: D. Electric Blasting CAP | C25: Pieces | D25: EBC | E25: EXPEDITION MBDInc. | F25: - | G25: - | H25: -
A26: E. Ordinary Blasting CAP | C26: Pieces | D26: OBC | E26: EXPEDITION MBDInc. | F26: (#8) | G26: - | H26: -
A27: F. Non Electric / LP Detonator | C27: Pieces | D27: EXEL LP | E27: EXPEDITION MBDInc. | F27: 2.4 METER | G27: - | H27: -
C28: Pieces | D28: EXEL LP | E28: EXPEDITION MBDInc. | F28: 3.6 METER | G28: - | H28: -
A29: G. Safety Fuse | C29: Meter | D29: SAFETY FUSE | E29: EXPEDITION MBDInc. | F29: 410mmx410mmx270mm | G29: - | H29: -
A30: H. Detonating Cords | C30: Meter | D30: CORDTEX | E30: EXPEDITION MBDInc. | F30: 5 GRAMS/METER | G30: - | H30: -
A31: I. Primer | C31: Pieces | D31: PENTEX(STOPE PRIME) | E31: EXPEDITION MBDInc. | F31: 250 GRAMS/PIECE | G31: - | H31: -
D32: PENTEX(PRIME SPIDER) | E32: EXPEDITION MBDInc. | G32: - | H32: -
A33: J. Connector Cord | C33: Meter | D33: - | E33: - | F33: - | G33: - | H33: -
D34: - | E34: - | F34: - | G34: - | H34: -
A35: K. Fuse Lighter | C35: Pieces | D35: FIRE FUSE | E35: EXPEDITION MBDInc. | F35: - | G35: - | H35: -
A36: L. Spitter/Igniter Cord | C36: Meter | D36: - | E36: - | F36: - | G36: - | H36: -
A37: M.Bill Wire | C37: Meter | D37: - | E37: - | F37: - | G37: - | H37: -
A40: Prepared by: | D40: Confirmed by: | F40: Review and Noted by:
A43: MR. RAFFY D. TORRES | D43: MR. JOHN XERCES C. ANTIPUESTO | F43: ENGR. EARL M. SON
A44: Mine Explosives Manager | D44: Blaster Foreman | F44: Mine Division Manager
A45: PHILSAGA MINING CORPORATION | D45: Expedition MBDInc | F45: PHILSAGA MINING CORPORATION
A46: Blaster License: FKB15 - 080917- 04562 | D46: Blaster License: FPKB15-100925-0131

Sheet MAY 2026- TIGERWAY
A1: FROM: OFFICE OF DIRECTOR | E1: FAX NO. : 9209130
B3: MGB Form No. 15-8
A4: Republic of the Philippines
A5: Department of Environment and Natural Resources
A6: MINES AND GEOSCIENCES BUREAU
A7: North Avenue, Diliman, Quezon City
A9: EXPLOSIVES AND ACCESSORIES CONSUMPTION
A10: ='MAY 2026 -PMC '!A11:H11 -> REPORT FOR THE MONTH OF MAY 2026
G12: DATE | H12: MAY 1-31,2026
A13: Company : | C13: PHILSAGA MINING CORP. - TIGERWAY DECLINE PROJECT
C14: (MPSA No. 262-2008-XIII PARCEL 1)
A15: Project site Address : | C15: UPPER CO-O, CONSUELO, BUNAWAN, AGUSAN DEL SUR | G15: PPEL No.P- | H15: 0425-298-2011
A16: Head of Project : | C16: ENGR. EARL M. SON
A17: Drilling and Blasting Engineer/s : | C17: ENGR. RAFFY D. TORRES | G17: BPL No.F- | H17: EXPL-0411128
A19: ITEM | C19: UNIT | D19: BRAND | E19: SUPPLIERS/CONTRACTOR | G19: SPECIFICATION | H19: QUANTITY USED | I19: QUANTITY USED
H20: PCS/METERS | I20: KLS
A21: A. DYNA / EMULSION | C21: Pieces/Kilograms | D21: SENATEL PULSAR 215 | E21: EXPEDITION MBDInc. | G21: 25x 200mm
C22: Pieces/Kilograms | D22: SUPERPOWER90 91 | E22: MT. ROCK POWDER CORP. | G22: 32x300mm | H22: 0 | I22: =H22/91*25 -> 0
C23: Pieces/Kilograms | D23: SUPERPOWER90 208 | E23: MT. ROCK POWDER CORP. | G23: 25x200mm | H23: 0 | I23: =H23/208*25 -> 0
C24: Pieces/Kilograms | D24: NEOGEL 901 91 | E24: MT. ROCK POWDER CORP. | G24: 32X300mm | H24: =47*91 -> 4277 | I24: =H24/91*25 -> 1175
C25: Pieces/Kilograms | D25: NEO PRIME 93 | E25: MT. ROCK POWDER CORP. | G25: 32X300mm | H25: =82*93 -> 7626 | I25: =H25/93*25 -> 2050
C26: Pieces/Kilograms | D26: NEOGEL 901 200 | E26: MT. ROCK POWDER CORP. | G26: 25X200mm | H26: 0 | I26: =H26/200*25 -> 0
A27: B. Ammonium Nitrate fuel oil (ANFO) | C27: Kilograms | D27: ANFO | E27: MT. ROCK POWDER CORP. | G27: 25 KGS/BAG | I27: =97*25 -> 2425
A28: C. Slurry | C28: Kilograms | D28: - | E28: MT. ROCK POWDER CORP. | G28: - | H28: - | I28: -
A29: D. Electric Blasting CAP | C29: Pieces | D29: EBC | E29: MT. ROCK POWDER CORP. | G29: - | H29: - | I29: -
A30: E. Ordinary Blasting CAP | C30: Pieces | D30: OBC | E30: MT. ROCK POWDER CORP. | G30: (#8) | H30: 175
A31: F. Non Electric / LP Detonator | C31: Pieces | D31: SUPREME | E31: MT. ROCK POWDER CORP. | G31: 2.4 METER | H31: 4 | I31: -
C32: Pieces | D32: SUPREME | E32: MT. ROCK POWDER CORP. | G32: 4.9 METER | H32: 1349 | I32: -
C33: Pieces | D33: SUPREME | E33: MT. ROCK POWDER CORP. | G33: 4.5 METER | H33: - | I33: -
C34: Pieces | D34: SUPREME | E34: MT. ROCK POWDER CORP. | G34: TLD | H34: 190
C35: Pieces | D35: RIONEL | E35: MT. ROCK POWDER CORP. | G35: 6 METER | H35: 210
C36: Pieces | D36: SHOCKSTAR | E36: MT. ROCK POWDER CORP. | G36: 2.4 METER | H36: - | I36: -
C37: Pieces | D37: SHOCKSTAR | E37: MT. ROCK POWDER CORP. | G37: 4.8 METER | H37: -
A38: G. Safety Fuse | C38: Meter | D38: SAFETY FUSE | E38: MT. ROCK POWDER CORP. | G38: 410mmx410mmx270mm | H38: 175 | I38: -
A39: H. Detonating Cords | C39: Meter | D39: NEO. CORD | E39: MT. ROCK POWDER CORP. | G39: 10 GRAMS/METER | H39: 1066 | I39: -
C40: Meter | D40: DET. CORD | E40: MT. ROCK POWDER CORP. | G40: 10 GRAMS/METER | H40: -
C41: Meter | D41: DET. CORD | E41: MT. ROCK POWDER CORP. | G41: 40 GRAMS/METER | H41: 1575
A42: I. Primer | C42: Pieces | D42: PENTEX(STOPE PRIME) | E42: MT. ROCK POWDER CORP. | G42: 250 GRAMS/PIECE | H42: - | I42: -
D43: PENTEX(PRIME SPIDER) | E43: MT. ROCK POWDER CORP. | H43: - | I43: -
A44: J. Connector Cord | C44: Meter | D44: - | E44: - | G44: - | H44: - | I44: -
...
