Workbook

Sheet JANUARY 2026 - PMC 
B1: Republic of the Philippines
B2: Department of Environment and Natural Resources
B3: MINES AND GEOSCIENCES BUREAU
B4: North Avenue, Diliman, Quezon City
B6: MONTHLY REPORT
B7: RECORD SHOWING EXPLOSIVES ON HAND, AMOUNT IMPORTED, PURCHASED FOUND, TAKEN UP, OR RECEIVED FROM AN
B8: OTHER SOURCE AND RECORD OF EXPLOSIVE ISSUED, TRANSFERRED AND/OR OTHERWISE GIVEN DISPOSITION
B10: The Chief
B11: Philippine National Police
B12: Thru The Provincial Director of PATIN-AY, PROSPERIDAD, AGUSAN DEL SUR
B13: SIR : I have the honor to submit the following report of explosive transaction and usage of PMC- Co-o Gold Project for the month of JANUARY 2026
B16: RECEIPTS | C16: JANUARY 1-31,2026 | D16: NAME | E16: ADDRESS | F16: LICENSE NO. | G16: PACKAGE EMULSION | Q16: ANFO | R16: DETONATORS | AB16: DETONATING CORD | AI16: savings SAFETY FUSE | AJ16: SAFETY FUSE | AK16: BILL WIRE | AL16: MS DETONATOR | AN16: FUSE LIGHTER | AO16: ACID | AP16: OTHERS | AQ16: PUR POSE | AR16: NAME OF PERSON
G17: EMULEX | H17: SUPERDYNE | I17: EM AUSTIN | J17: NEOGEL | K17: SENATEL PULSAR | N17: SUPER POWER | O17: MAG NUM | P17: SENATEL PULSAR | R17: NONEL | S17: NONEL | T17: SUPREME | V17: SHOCK STAR | W17: EXEL | Z17: OBC | AA17: EBC | AB17: 5 GRAMS | AC17: DCORD I5 GRAMS | AD17: 10 GRAMS | AE17: #11 | AF17: #6 | AG17: 6 GRAMS | AH17: 40 GRAMS | AR17: (LICENSE)
G18: 208/CASE | H18: 200 | I18: 200/CASE | J18: 200/CASE | K18: 215/CASE | L18: MAGNUM 215 | M18: 135/CASE | N18: 150/CASE | O18: 150/CASE | P18: 38/CASE | R18: 2.4 | S18: 3.6 | T18: 2.4 | U18: 3.6 | V18: 2.4 | W18: 3.6 | X18: 2.4 | Y18: 4.9 | AL18: MS 12 | AM18: MS 18 | AR18: MAKING DELIVERY
G19: PIECES | H19: PIECES | I19: PIECES | J19: PIECES | K19: PIECES | L19: PIECES | M19: PIECES | N19: PIECES | O19: PIECES | P19: PIECES | Q19: KILOS | R19: PIECES | S19: PIECES | T19: PIECES | U19: PIECES | V19: PIECES | W19: PIECES | X19: PIECES | Y19: PIECES | Z19: PIECES | AA19: PIECES | AB19: METERS | AC19: METERS | AD19: METERS | AE19: METERS | AF19: METERS | AG19: METERS | AH19: METERS | AI19: METERS | AJ19: METERS | AK19: METERS | AL19: PIECES | AM19: PIECES | AN19: PIECES | AO19: KILOS
B21: Beginning Stock as of as of January 1, 2026 | G21: =#REF! -> #REF! | H21: =#REF! -> #REF! | I21: =#REF! -> #REF! | J21: 42101 | K21: 103861 | L21: 0 | M21: 0 | N21: 0 | O21: 0 | P21: 0 | Q21: 62515.69 | R21: 264 | S21: 847 | T21: 16364 | U21: 0 | V21: 0 | W21: 5042 | X21: 60944 | Y21: 646 | Z21: 11885 | AA21: 192 | AB21: 23308 | AC21: 2473 | AD21: 1532 | AE21: 0 | AF21: 0 | AG21: 0 | AH21: 1060 | AI21: 0 | AJ21: 23250.55 | AK21: 1545 | AL21: 0 | AM21: 0 | AN21: 238 | AO21: =#REF! -> #REF! | AP21: =#REF! -> #REF! | AQ21: =#REF! -> #REF!
C23: 01/15/2026 | D23: MOUNT ROCK POWDER CORP. | E23: AGUSAN DEL SUR | F23: PPB08-220509-03374 | J23: =100*200 -> 20000 | Z23: 1000 | AR23: V. S. GUEVARA
D24: EXPEDITION MBDInc. | E24: DAVAO CITY | F24: PKB15-111108-03269 | K24: =100*215 -> 21500 | Q24: =600*25 -> 15000 | W24: 3960 | X24: 23000 | Z24: 1000 | AA24: 40 | AB24: 9000 | AJ24: 3000 | AR24: NESTOR MA
C25: 01/21/2026 | D25: MOUNT ROCK POWDER CORP. | E25: AGUSAN DEL SUR | F25: PPB08-220509-03374 | J25: =100*200 -> 20000 | Z25: 1000 | AR25: V. S. GUEVARA
D26: EXPEDITION MBDInc. | E26: DAVAO CITY | F26: PKB15-111108-03269 | K26: =100*215 -> 21500 | Q26: 7500 | X26: 24250 | Z26: 1000 | AB26: 13500 | AJ26: 10000 | AK26: 300 | AR26: NESTOR MA
C27: 01/29/2026 | D27: MOUNT ROCK POWDER CORP. | E27: AGUSAN DEL SUR | F27: PPB08-220509-03374 | J27: 20000 | Z27: 1000 | AA27: 10 | AR27: V. S. GUEVARA
D28: EXPEDITION MBDInc. | E28: DAVAO CITY | F28: PKB15-111108-03269 | K28: 21500 | Q28: =600*25 -> 15000 | W28: 3520 | X28: 13250 | Z28: 1000 | AB28: 5400 | AJ28: 5000 | AK28: 300 | AR28: NESTOR MA
D29: MOUNT ROCK POWDER CORP. | E29: AGUSAN DEL SUR | F29: PPB08-220509-03374 | AR29: V. S. GUEVARA
D30: EXPEDITION MBDInc. | E30: DAVAO CITY | F30: PKB15-111108-03269 | AR30: NESTOR MA
B31: FOUND
B32: Taken Up
B33: TOTAL | G33: =SUM(G21:G32) -> #REF! | H33: =SUM(H21:H32) -> #REF! | I33: =SUM(I21:I32) -> #REF! | J33: =SUM(J21:J32) -> 102101 | K33: =SUM(K21:K32) -> 168361 | L33: =SUM(L21:L32) -> 0 | M33: =SUM(M21:M32) -> 0 | N33: =SUM(N21:N32) -> 0 | ... AQ33: =SUM(AQ21:AQ32) -> #REF!
B34: Disposition
B35: Used or Transferred | D35: PHILSAGA MINING CORP. CO-O GOLD PROJECT CONSUMPTION (MPSA No. 262-2008-XIII PARCEL 1) | I35: 0 | J35: 45072 | K35: 45911 | Q35: 30440.5 | R35: 0 | S35: 0 | T35: 0 | W35: 836 | X35: 44575 | Z35: 5413 | AA35: 92 | AB35: 19801 | AC35: 1676 | AH35: 0 | AJ35: =Z35*2.43 -> 13153.59 | AK35: 310 | AN35: 0
D36: TRANSFEERED (THRU EXPEDITION MBDInc.) TO PMC-EXPLORATION PROJECT (MPSA No. 262-2008-XIII PARCEL-2) | G36: 0 | K36: 5375 | Q36: 875 | W36: 1150 | X36: 760 | Z36: 200 | AB36: 900 | AJ36: =Z36*2.43 -> 486 | AO36: 0 | AP36: 0 | AQ36: 0
B38: Remaining Stock as of January 31,2026 | G38: =G33-G35-G36 -> #REF! | H38: =H33-H35-H36 -> #REF! | I38: =I33-I35-I36 -> #REF! | J38: =J33-J35-J36 -> 57029 | K38: =K33-K35-K36 -> 117075 | L38: =L33-L35-L36 -> 0 | M38: =M33-M35-M36 -> 0 | N38: =N33-N35-N36 -> 0 | ... AQ38: =AQ33-AQ35-AQ36 -> #REF!
K39: =K38+'JANUARY 2026 - EXPLO'!J30 -> 121623 | Q39: =Q38+'JANUARY 2026 - EXPLO'!O30 -> 69483.09 | W39: =W38+'JANUARY 2026 - EXPLO'!T30 -> 11669 | X39: =X38+'JANUARY 2026 - EXPLO'!U30 -> 76697 | Z39: =Z38+'JANUARY 2026 - EXPLO'!V30 -> 12506 | AA39: =AA38+'JANUARY 2026 - EXPLO'!W30 -> 204 | AB39: =AB38+'JANUARY 2026 - EXPLO'!X30 -> 31598 | AJ39: =AJ38+'JANUARY 2026 - EXPLO'!AE30 -> 28179.58 | AK39: =AK38+'JANUARY 2026 - EXPLO'!AF30 -> 2135 | AN39: =AN38+'JANUARY 2026 - EXPLO'!AI30 -> 276
C43: Subscribed and sworn to before me this____________day | K43: Form of License | R43: BLASTER FOREMAN | X43: FKB15 - 080917- 04562 | AD43: Very respectfully | AM43: Very respectfully
C44: of ___________________, 20 _____
C46: Doc. No. | F46: _________________________________ | G46: _________________________________ | AD46: MR. RAFFY D. TORRES
C47: Page of | F47: NOTARY PUBLIC | G47: NOTARY PUBLIC | AD47: Con. Tax. Cert. No. CC1202213000572
C48: Book of | F48: Until Dec. 31, 20___________________ | G48: Until Dec. 31, 20___________________ | AD48: Issued at Consuelo Bunawan Agusan del Sur
C49: Series of | F49: Ptr No. ___________________________ | G49: Ptr No. ___________________________ | AD49: Dated Issued: June 5, 2025

Sheet JANUARY 2026 - EXPLO
B1: Republic of the Philippines
B2: Department of Environment and Natural Resources
B3: MINES AND GEOSCIENCES BUREAU
B4: North Avenue, Diliman, Quezon City
B6: MONTHLY REPORT
B7: RECORD SHOWING EXPLOSIVES ON HAND, AMOUNT IMPORTED, PURCHASED FOUND, TAKEN UP, OR RECEIVED FROM AN
B8: OTHER SOURCE AND RECORD OF EXPLOSIVE ISSUED, TRANSFERRED AND/OR OTHERWISE GIVEN DISPOSITION
B10: The Chief
B11: Philippine National Police
B12: Thru The Provincial Director of PATIN-AY, PROSPERIDAD, AGUSAN DEL SUR
B13: SIR : I have the honor to submit the following report of explosive transactions and usage of PMC - Exploration Project for the month of JANUARY 2026
B16: RECEIPTS | C16: JANUARY 1-31,2026 | D16: NAME | E16: ADDRESS | F16: LICENSE NO. | G16: PACKAGE EMULSION | O16: ANFO | P16: DETONATORS | X16: DETONATING CORD | AD16: savings SAFETY FUSE | AE16: SAFETY FUSE | AF16: BILL WIRE | AG16: MS DETONATOR | AI16: FUSE LIGHTER | AJ16: ACID | AK16: OTHERS | AL16: PUR POSE | AM16: NAME OF PERSON
G17: EMULEX | H17: SUPERDYNE | I17: SUPER POWER | J17: SENATELPULSAR | M17: SUPER POWER | N17: MAGNUM | P17: NONEL | Q17: NONEL | R17: SUPREME | T17: EXEL | V17: OBC | W17: EBC | X17: 5 GRAMS | Y17: 10 GRAMS | Z17: #11 | AA17: #6 | AB17: 6 GRAMS | AC17: 40 GRAMS | AM17: (LICENSE)
G18: 208/CASE | H18: 200 | I18: 208/CASE | J18: 215/CASE | K18: MAGNUM 215 | L18: DYAGEL 150 | M18: 150/CASE | N18: 150/CASE | P18: 2.4 | Q18: 3.6 | R18: 2.4 | S18: 3.6 | T18: 3.6 | U18: 2.4 | AG18: MS 12 | AH18: MS 18 | AM18: MAKING DELIVERY
G19: PIECES | H19: PIECES | I19: PIECES | J19: PIECES | K19: PIECES | L19: PIECES | M19: PIECES | N19: PIECES | O19: KILOS | P19: PIECES | Q19: PIECES | R19: PIECES | S19: PIECES | T19: PIECES | U19: PIECES | V19: PIECES | W19: PIECES | X19: METERS | Y19: METERS | Z19: METERS | AA19: METERS | AB19: METERS | AC19: METERS | AD19: METERS | AE19: METERS | AF19: METERS | AG19: PIECES | AH19: PIECES | AI19: PIECES | AJ19: KILOS
B21: ='JANUARY 2026 - PMC '!B21:D21 -> Beginning Stock as of as of January 1, 2026 | G21: =#REF! -> #REF! | H21: =#REF! -> #REF! | I21: =#REF! -> #REF! | J21: 2301 | K21: 0 | L21: 0 | M21: 0 | N21: 0 | O21: 283.5 | P21: 0 | Q21: 0 | R21: 0 | S21: 0 | T21: 756 | U21: 3 | V21: 118 | W21: 54 | X21: 519 | Y21: 0 | Z21: 0 | AA21: 0 | AB21: 0 | AC21: 0 | AD21: 0 | AE21: 286.74 | AF21: 300 | AG21: 0 | AH21: 0 | AI21: 41 | AJ21: =#REF! -> #REF! | AK21: =#REF! -> #REF! | AL21: =#REF! -> #REF!
C23: 01/13/2026 | D23: EXPEDITION MBDInc. | E23: DAVAO CITY | F23: PKB15-111108-03269 | J23: =10*215 -> 2150 | O23: =20*25 -> 500 | T23: 670 | U23: 260 | V23: 100 | AE23: =V23*2.43 -> 243 | AM23: NESTOR MA
C24: 1/27/2026 | D24: EXPEDITION MBDInc. | E24: DAVAO CITY | F24: PKB15-111108-03269 | J24: =15*215 -> 3225 | O24: =15*25 -> 375 | T24: 480 | U24: 500 | V24: 100 | X24: 900 | AE24: =V24*2.43 -> 243 | AM24: NESTOR MA
B25: FOUND
B26: Taken Up
B27: TOTAL | G27: =SUM(G21:G26) -> #REF! | H27: =SUM(H21:H26) -> #REF! | I27: =SUM(I21:I26) -> #REF! | J27: =SUM(J21:J26) -> 7676 | K27: =SUM(K21:K26) -> 0 | L27: =SUM(L21:L26) -> 0 | M27: =SUM(M21:M26) -> 0 | N27: =SUM(N21:N26) -> 0 | ... AL27: =SUM(AL21:AL26) -> #REF!
B28: Disposition
B29: USAGE | D29: MONTHLY USAGE /CONSUMPTION OF PMC- EXPLORATION PROJECT (MPSA No. 262-2008-XIII PARCEL-2) | G29: =SUM(G23:G28) -> #REF! | H29: =SUM(H23:H28) -> #REF! | I29: =SUM(I23:I28) -> #REF! | J29: 3128 | O29: 375.6 | T29: 773 | U29: 175 | V29: 84 | W29: 0 | X29: 328 | AC29: 0 | AE29: =V29*2.43 -> 204.12 | AF29: 0 | AI29: 3
B30: Remaining Stock as of December 31, 2025 | C30: ='JANUARY 2026 - PMC '!B38 -> Remaining Stock as of January 31,2026 | G30: =G27-G29 -> #REF! | H30: =H27-H29 -> #REF! | I30: =I27-I29 -> #REF! | J30: =J27-J29 -> 4548 | K30: =K27-K29 -> 0 | L30: =L27-L29 -> 0 | M30: =M27-M29 -> 0 | N30: =N27-N29 -> 0 | ... AL30: =AL27-AL29 -> #REF!
C35: Subscribed and sworn to before me this____________day | J35: Form of License | O35: BLASTER FOREMAN | V35: FKB15 - 080917- 04562 | AE35: Very respectfully | AH35: Very respectfully
C36: of ___________________, 20 _____
C38: Doc. No. | J38: _________________________________ | AE38: MR. RAFFY D. TORRES
C39: Page of | J39: NOTARY PUBLIC | AE39: Con. Tax. Cert. No. CC1202213000572
C40: Book of | J40: Until Dec. 31, 20___________________ | AE40: Issued at Consuelo Bunawan Agusan del Sur
C41: Series of | J41: Ptr No. ___________________________ | AE41: Dated Issued: June 5, 2025

Sheet JANUARY 2026- TIGERWAY 
B1: Republic of the Philippines
B2: Department of Environment and Natural Resources
B3: MINES AND GEOSCIENCES BUREAU
B4: North Avenue, Diliman, Quezon City
B6: MONTHLY REPORT
B7: RECORD SHOWING EXPLOSIVES ON HAND, AMOUNT IMPORTED, PURCHASED FOUND, TAKEN UP, OR RECEIVED FROM AN
B8: OTHER SOURCE AND RECORD OF EXPLOSIVE ISSUED, TRANSFERRED AND/OR OTHERWISE GIVEN DISPOSITION
B10: The Chief
B11: Philippine National Police
B12: Thru The Provincial Director of PATIN-AY, PROSPERIDAD, AGUSAN DEL SUR
B13: SIR : I have the honor to submit the following report of explosives transactions and usage of the PMC Tigerway Decline Project for the month of JANUARY 2026
B16: RECEIPTS | C16: JANUARY 1-31,2026 | D16: NAME | E16: ADDRESS | F16: LICENSE NO. | P16: PACKAGE EMULSION | V16: ANFO | W16: DETONATORS | AH16: DETONATING CORD | AO16: SAFETY FUSE | AP16: BILL WIRE | AQ16: MS DETONATOR | AS16: FUSE LIGHTER | AT16: ACID | AU16: OTHERS | AV16: PUR POSE | AW16: NAME OF PERSON
I17: SENATELPULSAR | L17: SUPER POWER | M17: MAGNUM | N17: NEOGEL 901 | O17: EMULEX | P17: SENATEL | Q17: NITRO EM | R17: NEOGEL 901 | T17: EMULEX | U17: SUPER POWER | W17: NONEL | X17: NONEL | Y17: SUPREME | AA17: SHOCKSTAR | AE17: OBC | AF17: EBC | AH17: NEOCORD10 GRAMS | AI17: DETCORD 10 GRAMS | AJ17: 40 GRAMS | AW17: (LICENSE)
I18: 215/CASE | J18: MAGNUM 215 | K18: DYAGEL 150 | L18: 150/CASE | M18: 150/CASE | N18: 62/CASE | O18: 36 CASE | P18: 215/CASE | Q18: 91/CASE | R18: 91/CASE | S18: 200/CASE | T18: 80/CASE | U18: 208/CASE | W18: 2.4 | X18: 3.6 | Y18: 2.4 | Z18: 4.9 | AA18: 2.4 | AB18: 4.8 | AQ18: MS 12 | AR18: MS 18 | AW18: MAKING DELIVERY
I19: PIECES | J19: PIECES | K19: PIECES | L19: PIECES | M19: PIECES | N19: PIECES | O19: PIECES | P19: PIECES | Q19: PIECES | R19: PIECES | S19: PIECES | T19: PIECES | U19: PIECES | V19: KILOS | W19: PIECES | X19: PIECES | Y19: PIECES | Z19: PIECES | AA19: PIECES | AB19: PIECES | AE19: PIECES | AF19: PIECES | AH19: METERS | AI19: METERS | AJ19: METERS | AO19: METERS | AP19: METERS | AQ19: PIECES | AR19: PIECES | AS19: PIECES | AT19: KILOS
B21: ='JANUARY 2026 - PMC '!B21:D21 -> Beginning Stock as of as of January 1, 2026 | I21: =#REF! -> #REF! | J21: =#REF! -> #REF! | K21: =#REF! -> #REF! | L21: =#REF! -> #REF! | M21: =#REF! -> #REF! | N21: =#REF! -> #REF! | O21: =#REF! -> #REF! | P21: =#REF! -> #REF! | Q21: 0 | R21: 32123 | S21: 15800 | T21: 0 | U21: 0 | V21: 4575 | W21: 0 | X21: 0 | Y21: 1832 | Z21: 7802 | AA21: 0 | AB21: 0 | AE21: 630 | AF21: 96 | AH21: 0 | AI21: 3713 | AJ21: 1350 | AO21: 717 | AP21: 0 | AQ21: 0 | AR21: 0 | AS21: 0 | AT21: =#REF! -> #REF! | AU21: =#REF! -> #REF! | AV21: =#REF! -> #REF!
D23: MOUNT ROCK POWDER CORP. | E23: AGUSAN DEL SUR | F23: PPB08-220509-03374 | O23: =235*36 -> 8460 | AW23: V. S. GUEVARA
C24: 10/15/2025 | D24: MOUNT ROCK POWDER CORP. | E24: AGUSAN DEL SUR | F24: PPB08-220509-03374 | AW24: V. S. GUEVARA
C25: 9/26/2025 | D25: MOUNT ROCK POWDER CORP. | E25: AGUSAN DEL SUR | F25: PPB08-220509-03374 | AW25: V. S. GUEVARA
B26: FOUND
B27: Taken Up
B28: TOTAL | I28: =SUM(I21:I27) -> #REF! | J28: =SUM(J21:J27) -> #REF! | K28: =SUM(K21:K27) -> #REF! | L28: =SUM(L21:L27) -> #REF! | M28: =SUM(M21:M27) -> #REF! | N28: =SUM(N21:N27) -> #REF! | O28: =SUM(O21:O27) -> #REF! | P28: =SUM(P21:P27) -> #REF! | ... AB28: =SUM(AB21:AB27) -> 0 | AE28: =SUM(AE21:AE27) -> 630 | AF28: =SUM(AF21:AF27) -> 96 | AH28: =SUM(AH21:AH27) -> 0 | AI28: =SUM(AI21:AI27) -> 3713 | AJ28: =SUM(AJ21:AJ27) -> 1350 | AO28: =SUM(AO21:AO27) -> 717 | AP28: =SUM(AP21:AP27) -> 0 | AQ28: =SUM(AQ21:AQ27) -> 0 | AR28: =SUM(AR21:AR27) -> 0 | AS28: =SUM(AS21:AS27) -> 0 | AT28: =SUM(AT21:AT27) -> #REF! | AU28: =SUM(AU21:AU27) -> #REF! | AV28: =SUM(AV21:AV27) -> #REF!
B29: Disposition
B30: USAGE | D30: MONTHLY USAGE /CONSUMPTION OF PMC- TIGERWAY DECLINE PROJECT (MPSA No. 262-2008-XIII PARCEL 1) | I30: 0 | J30: =SUM(J26:J29) -> #REF! | K30: =SUM(K26:K29) -> #REF! | L30: =SUM(L26:L29) -> #REF! | M30: =SUM(M26:M29) -> #REF! | O30: =350*36 -> 12600 | R30: 16107 | S30: 0 | U30: 0 | V30: 2800 | Y30: 6 | Z30: 1780 | AA30: 0 | AB30: 0 | AE30: 179 | AF30: 0 | AH30: 0 | AI30: 1451 | AJ30: 1275 | AO30: 249 | AP30: 0 | AS30: 0
B31: ='JANUARY 2026 - PMC '!B38 -> Remaining Stock as of January 31,2026 | I31: =I28-I30 -> #REF! | J31: =J28-J30 -> #REF! | K31: =K28-K30 -> #REF! | L31: =L28-L30 -> #REF! | M31: =M28-M30 -> #REF! | N31: =N28-N30 -> #REF! | O31: =O28-O30 -> #REF! | P31: =P28-P30 -> #REF! | ... AB31: =AB28-AB30 -> 0 | AE31: =AE28-AE30 -> 451 | AF31: =AF28-AF30 -> 96 | AH31: =AH28-AH30 -> 0 | AI31: =AI28-AI30 -> 2262 | AJ31: =AJ28-AJ30 -> 75 | AO31: =AO28-AO30 -> 468 | AP31: =AP28-AP30 -> 0 | AQ31: =AQ28-AQ30 -> 0 | AR31: =AR28-AR30 -> 0 | AS31: =AS28-AS30 -> 0 | AT31: =AT28-AT30 -> #REF! | AU31: =AU28-AU30 -> #REF! | AV31: =AV28-AV30 -> #REF!
R32: =R31/91 -> 176 | S32: =S31/200 -> 79 | V32: =V31/25 -> 71
C36: Subscribed and sworn to before me this____________day | F36: Form of License | S36: BLASTER FOREMAN | AA36: FKB15 - 080917- 04562 | AI36: Very respectfully | AR36: Very respectfully
C37: of ___________________, 20 _____
C39: Doc. No. | F39: _________________________________ | AI39: MR. RAFFY D. TORRES
C40: Page of | F40: NOTARY PUBLIC | AI40: Con. Tax. Cert. No. CC1202213000572
C41: Book of | F41: Until Dec. 31, 20___________________ | AI41: Issued at Consuelo Bunawan Agusan del Sur
C42: Series of | F42: Ptr No. ___________________________ | AI42: Dated Issued: June 5, 2025

Sheet FEBRUARY 2026 - PMC 
B1: Republic of the Philippines
B2: Department of Environment and Natural Resources
B3: MINES AND GEOSCIENCES BUREAU
B4: North Avenue, Diliman, Quezon City
B6: MONTHLY REPORT
B7: RECORD SHOWING EXPLOSIVES ON HAND, AMOUNT IMPORTED, PURCHASED FOUND, TAKEN UP, OR RECEIVED FROM AN
B8: OTHER SOURCE AND RECORD OF EXPLOSIVE ISSUED, TRANSFERRED AND/OR OTHERWISE GIVEN DISPOSITION
B10: The Chief
B11: Philippine National Police
B12: Thru The Provincial Director of PATIN-AY, PROSPERIDAD, AGUSAN DEL SUR
B13: SIR : I have the honor to submit the following report of explosive transaction and usage of PMC- Co-o Gold Project for the month of FEBRUARY 2026
B16: RECEIPTS | C16: FEBRUARY 1-28,2026 | D16: NAME | E16: ADDRESS | F16: LICENSE NO. | G16: PACKAGE EMULSION | Q16: ANFO | R16: DETONATORS | AB16: DETONATING CORD | AI16: savings SAFETY FUSE | AJ16: SAFETY FUSE | AK16: BILL WIRE | AL16: MS DETONATOR | AN16: FUSE LIGHTER | AO16: ACID | AP16: OTHERS | AQ16: PUR POSE | AR16: NAME OF PERSON
G17: EMULEX | H17: SUPERDYNE | I17: EM AUSTIN | J17: NEOGEL | K17: SENATEL PULSAR | N17: SUPER POWER | O17: MAG NUM | P17: SENATEL PULSAR | R17: NONEL | S17: NONEL | T17: SUPREME | V17: SHOCK STAR | W17: EXEL | Z17: OBC | AA17: EBC | AB17: 5 GRAMS | AC17: DCORD I5 GRAMS | AD17: 10 GRAMS | AE17: #11 | AF17: #6 | AG17: 6 GRAMS | AH17: 40 GRAMS | AR17: (LICENSE)
G18: 208/CASE | H18: 200 | I18: 200/CASE | J18: 200/CASE | K18: 215/CASE | L18: MAGNUM 215 | M18: 135/CASE | N18: 150/CASE | O18: 150/CASE | P18: 38/CASE | R18: 2.4 | S18: 3.6 | T18: 2.4 | U18: 3.6 | V18: 2.4 | W18: 3.6 | X18: 2.4 | Y18: 4.9 | AL18: MS 12 | AM18: MS 18 | AR18: MAKING DELIVERY
G19: PIECES | H19: PIECES | I19: PIECES | J19: PIECES | K19: PIECES | L19: PIECES | M19: PIECES | N19: PIECES | O19: PIECES | P19: PIECES | Q19: KILOS | R19: PIECES | S19: PIECES | T19: PIECES | U19: PIECES | V19: PIECES | W19: PIECES | X19: PIECES | Y19: PIECES | Z19: PIECES | AA19: PIECES | AB19: METERS | AC19: METERS | AD19: METERS | AE19: METERS | AF19: METERS | AG19: METERS | AH19: METERS | AI19: METERS | AJ19: METERS | AK19: METERS | AL19: PIECES | AM19: PIECES | AN19: PIECES | AO19: KILOS
B21: Beginning Stock as of as of February 1, 2026 | G21: =#REF! -> #REF! | H21: =#REF! -> #REF! | I21: =#REF! -> #REF! | J21: ='JANUARY 2026 - PMC '!J38 -> 57029 | K21: =117075-412 -> 116663 | L21: ='JANUARY 2026 - PMC '!L38 -> 0 | M21: ='JANUARY 2026 - PMC '!M38 -> 0 | N21: ='JANUARY 2026 - PMC '!N38 -> 0 | O21: ='JANUARY 2026 - PMC '!O38 -> 0 | P21: ='JANUARY 2026 - PMC '!P38 -> 0 | Q21: =68700.19+14.5-0.1 -> 68714.59 | R21: ='JANUARY 2026 - PMC '!R38 -> 264 | S21: ='JANUARY 2026 - PMC '!S38 -> 847 | T21: ='JANUARY 2026 - PMC '!T38 -> 16364 | U21: ='JANUARY 2026 - PMC '!U38 -> 0 | V21: ='JANUARY 2026 - PMC '!V38 -> 0 | W21: =10536+75 -> 10611 | X21: =76109-82 -> 76027 | Y21: ='JANUARY 2026 - PMC '!Y38 -> 646 | Z21: =12272+12 -> 12284 | AA21: 190 | AB21: =30507-148 -> 30359 | AC21: ='JANUARY 2026 - PMC '!AC38 -> 797 | AD21: ='JANUARY 2026 - PMC '!AD38 -> 1532 | AE21: ='JANUARY 2026 - PMC '!AE38 -> 0 | AF21: ='JANUARY 2026 - PMC '!AF38 -> 0 | AG21: ='JANUARY 2026 - PMC '!AG38 -> 0 | AH21: ='JANUARY 2026 - PMC '!AH38 -> 1060 | AI21: ='JANUARY 2026 - PMC '!AI38 -> 0 | AJ21: =27610.96+29.16 -> 27640.12 | AK21: ='JANUARY 2026 - PMC '!AK38 -> 1835 | AL21: ='JANUARY 2026 - PMC '!AL38 -> 0 | AM21: ='JANUARY 2026 - PMC '!AM38 -> 0 | AN21: =238+8 -> 246 | AO21: =#REF! -> #REF! | AP21: =#REF! -> #REF! | AQ21: =#REF! -> #REF!
C23: 46358 | D23: MOUNT ROCK POWDER CORP. | E23: AGUSAN DEL SUR | F23: PPB08-220509-03374 | J23: =100*200 -> 20000 | Z23: 1000 | AA23: 40 | AR23: V. S. GUEVARA
D24: EXPEDITION MBDInc. | E24: DAVAO CITY | F24: PKB15-111108-03269 | K24: =100*215 -> 21500 | Q24: =600*25 -> 15000 | X24: 17750 | Z24: 1000 | AB24: 9000 | AJ24: 10000 | AR24: NESTOR MA
C25: 2/23/2026 | D25: MOUNT ROCK POWDER CORP. | E25: AGUSAN DEL SUR | F25: PPB08-220509-03374 | J25: =75*200 -> 15000 | Z25: 1000 | AA25: 120 | AR25: V. S. GUEVARA
D26: EXPEDITION MBDInc. | E26: DAVAO CITY | F26: PKB15-111108-03269 | K26: =75*215 -> 16125 | Q26: 15000 | X26: 14500 | Z26: 1000 | AB26: 5400 | AJ26: 5000 | AK26: 600 | AR26: NESTOR MA
D27: MOUNT ROCK POWDER CORP. | E27: AGUSAN DEL SUR | F27: PPB08-220509-03374 | AR27: V. S. GUEVARA
D28: EXPEDITION MBDInc. | E28: DAVAO CITY | F28: PKB15-111108-03269 | AR28: NESTOR MA
D29: MOUNT ROCK POWDER CORP. | E29: AGUSAN DEL SUR | F29: PPB08-220509-03374 | AR29: V. S. GUEVARA
D30: EXPEDITION MBDInc. | E30: DAVAO CITY | F30: PKB15-111108-03269 | AR30: NESTOR MA
B31: FOUND
B32: Taken Up
B33: TOTAL | G33: =SUM(G21:G32) -> #REF! | H33: =SUM(H21:H32) -> #REF! | I33: =SUM(I21:I32) -> #REF! | J33: =SUM(J21:J32) -> 92029 | K33: =SUM(K21:K32) -> 154288 | L33: =SUM(L21:L32) -> 0 | M33: =SUM(M21:M32) -> 0 | N33: =SUM(N21:N32) -> 0 | ... AQ33: =SUM(AQ21:AQ32) -> #REF!
B34: Disposition
B35: Used or Transferred | D35: PHILSAGA MINING CORP. CO-O GOLD PROJECT CONSUMPTION (MPSA No. 262-2008-XIII PARCEL 1) | I35: 0 | J35: 41302 | K35: 39560 | Q35: 29423 | R35: 0 | S35: 0 | T35: 0 | W35: 414 | X35: 39733 | Z35: 4620 | AA35: 158 | AB35: 18752 | AC35: 797 | AD35: 20 | AH35: 0 | AJ35: =Z35*2.43 -> 11226.6 | AK35: 340 | AN35: 1
D36: RETURNED EXPLOSIVES STOCK FROM RCV SINUG-ANG MAGAZINE | G36: 0 | K36: 3870 | Q36: 650 | W36: 885 | X36: 525 | Z36: 192 | AA36: 14 | AB36: 1129 | AJ36: =Z36*2.43 -> 466.56 | AK36: 300 | AN36: 30 | AO36: 0 | AP36: 0 | AQ36: 0
B38: Remaining Stock as of February 28,2026 | G38: =G33-G35-G36 -> #REF! | H38: =H33-H35-H36 -> #REF! | I38: =I33-I35-I36 -> #REF! | J38: =J33-J35+J36 -> 50727 | K38: =K33-K35+K36 -> 118598 | L38: =L33-L35+L36 -> 0 | M38: =M33-M35+M36 -> 0 | N38: =N33-N35+N36 -> 0 | O38: =O33-O35+O36 -> 0 | P38: =P33-P35+P36 -> 0 | Q38: =Q33-Q35+Q36 -> 69941.59 | ... AN38: =AN33-AN35+AN36 -> 275 | AO38: =AO33-AO35-AO36 -> #REF! | AP38: =AP33-AP35-AP36 -> #REF! | AQ38: =AQ33-AQ35-AQ36 -> #REF!
C43: Subscribed and sworn to before me this____________day | K43: Form of License | R43: BLASTER FOREMAN | X43: FKB15 - 080917- 04562 | AD43: Very respectfully | AM43: Very respectfully
C44: of ___________________, 20 _____
C46: Doc. No. | F46: _________________________________ | G46: _________________________________ | AD46: MR. RAFFY D. TORRES
C47: Page of | F47: NOTARY PUBLIC | G47: NOTARY PUBLIC | AD47: Con. Tax. Cert. No. CC1202213000572
C48: Book of | F48: Until Dec. 31, 20___________________ | G48: Until Dec. 31, 20___________________ | AD48: Issued at Consuelo Bunawan Agusan del Sur
C49: Series of | F49: Ptr No. ___________________________ | G49: Ptr No. ___________________________ | AD49: Dated Issued: June 5, 2025

Sheet FEBRUARY 2026 - EXPLO
B1: Republic of the Philippines
B2: Department of Environment and Natural Resources
B3: MINES AND GEOSCIENCES BUREAU
B4: North Avenue, Diliman, Quezon City
B6: MONTHLY REPORT
B7: RECORD SHOWING EXPLOSIVES ON HAND, AMOUNT IMPORTED, PURCHASED FOUND, TAKEN UP, OR RECEIVED FROM AN
B8: OTHER SOURCE AND RECORD OF EXPLOSIVE ISSUED, TRANSFERRED AND/OR OTHERWISE GIVEN DISPOSITION
B10: The Chief
B11: Philippine National Police
B12: Thru The Provincial Director of PATIN-AY, PROSPERIDAD, AGUSAN DEL SUR
B13: SIR : I have the honor to submit the following report of explosive transactions and usage of PMC - Exploration Project for the month of FEBRUARY 2026
B16: RECEIPTS | C16: FEBRUARY 1-28,2026 | D16: NAME | E16: ADDRESS | F16: LICENSE NO. | G16: PACKAGE EMULSION | O16: ANFO | P16: DETONATORS | X16: DETONATING CORD | AD16: savings SAFETY FUSE | AE16: SAFETY FUSE | AF16: BILL WIRE | AG16: MS DETONATOR | AI16: FUSE LIGHTER | AJ16: ACID | AK16: OTHERS | AL16: PUR POSE | AM16: NAME OF PERSON
G17: EMULEX | H17: SUPERDYNE | I17: SUPER POWER | J17: SENATELPULSAR | M17: SUPER POWER | N17: MAGNUM | P17: NONEL | Q17: NONEL | R17: SUPREME | T17: EXEL | V17: OBC | W17: EBC | X17: 5 GRAMS | Y17: 10 GRAMS | Z17: #11 | AA17: #6 | AB17: 6 GRAMS | AC17: 40 GRAMS | AM17: (LICENSE)
G18: 208/CASE | H18: 200 | I18: 208/CASE | J18: 215/CASE | K18: MAGNUM 215 | L18: DYAGEL 150 | M18: 150/CASE | N18: 150/CASE | P18: 2.4 | Q18: 3.6 | R18: 2.4 | S18: 3.6 | T18: 3.6 | U18: 2.4 | AG18: MS 12 | AH18: MS 18 | AM18: MAKING DELIVERY
G19: PIECES | H19: PIECES | I19: PIECES | J19: PIECES | K19: PIECES | L19: PIECES | M19: PIECES | N19: PIECES | O19: KILOS | P19: PIECES | Q19: PIECES | R19: PIECES | S19: PIECES | T19: PIECES | U19: PIECES | V19: PIECES | W19: PIECES | X19: METERS | Y19: METERS | Z19: METERS | AA19: METERS | AB19: METERS | AC19: METERS | AD19: METERS | AE19: METERS | AF19: METERS | AG19: PIECES | AH19: PIECES | AI19: PIECES | AJ19: KILOS
B21: ='FEBRUARY 2026 - PMC '!B21:D21 -> Beginning Stock as of as of February 1, 2026 | G21: =#REF! -> #REF! | H21: =#REF! -> #REF! | I21: =#REF! -> #REF! | J21: =4548+412 -> 4960 | K21: ='JANUARY 2026 - EXPLO'!K30 -> 0 | L21: ='JANUARY 2026 - EXPLO'!L30 -> 0 | M21: ='JANUARY 2026 - EXPLO'!M30 -> 0 | N21: ='JANUARY 2026 - EXPLO'!N30 -> 0 | O21: =782.9-14.5 -> 768.4 | P21: ='JANUARY 2026 - EXPLO'!P30 -> 0 | Q21: ='JANUARY 2026 - EXPLO'!Q30 -> 0 | R21: ='JANUARY 2026 - EXPLO'!R30 -> 0 | S21: ='JANUARY 2026 - EXPLO'!S30 -> 0 | T21: =1133-75 -> 1058 | U21: =588+82 -> 670 | V21: =234-12 -> 222 | W21: 14 | X21: =1091+148 -> 1239 | Y21: ='JANUARY 2026 - EXPLO'!Y30 -> 0 | Z21: ='JANUARY 2026 - EXPLO'!Z30 -> 0 | AA21: ='JANUARY 2026 - EXPLO'!AA30 -> 0 | AB21: ='JANUARY 2026 - EXPLO'!AB30 -> 0 | AC21: ='JANUARY 2026 - EXPLO'!AC30 -> 0 | AD21: ='JANUARY 2026 - EXPLO'!AD30 -> 0 | AE21: ='JANUARY 2026 - EXPLO'!AE30 -> 568.62 | AF21: ='JANUARY 2026 - EXPLO'!AF30 -> 300 | ... AH21: ='JANUARY 2026 - EXPLO'!AH30 -> 0 | AI21: 30 | AJ21: =#REF! -> #REF! | AK21: =#REF! -> #REF! | AL21: =#REF! -> #REF!
D23: EXPEDITION MBDInc. | E23: DAVAO CITY | F23: PKB15-111108-03269 | AM23: NESTOR MA
D24: EXPEDITION MBDInc. | E24: DAVAO CITY | F24: PKB15-111108-03269 | AM24: NESTOR MA
B25: FOUND
B26: Taken Up
B27: TOTAL | G27: =SUM(G21:G26) -> #REF! | H27: =SUM(H21:H26) -> #REF! | I27: =SUM(I21:I26) -> #REF! | J27: =SUM(J21:J26) -> 4960 | K27: =SUM(K21:K26) -> 0 | L27: =SUM(L21:L26) -> 0 | M27: =SUM(M21:M26) -> 0 | N27: =SUM(N21:N26) -> 0 | ... AL27: =SUM(AL21:AL26) -> #REF!
B28: Disposition
B29: Used or Transferred | D29: MONTHLY USAGE /CONSUMPTION OF PMC- EXPLORATION PROJECT (MPSA No. 262-2008-XIII PARCEL-2) | G29: =SUM(G23:G28) -> #REF! | H29: =SUM(H23:H28) -> #REF! | I29: =SUM(I23:I28) -> #REF! | J29: 1090 | O29: 118.4 | T29: 173 | U29: 145 | V29: 30 | X29: 110 | AE29: =V29*2.43 -> 72.9
D30: TRANSFERRED EXPLOSIVES STOCK BACK TO PMC MINE SITE | J30: 3870 | K30: 0 | L30: 0 | M30: 0 | N30: 0 | O30: 650 | P30: 0 | Q30: 0 | R30: 0 | S30: 0 | T30: 885 | U30: 525 | V30: 192 | W30: 14 | X30: 1129 | Y30: 0 | Z30: 0 | AA30: 0 | AB30: 0 | AC30: 0 | AD30: 0 | AE30: 495.72 | AF30: 300 | AG30: 0 | AH30: 0 | AI30: 30
B31: ='FEBRUARY 2026 - PMC '!B38 -> Remaining Stock as of February 28,2026 | G31: =G27-G29 -> #REF! | H31: =H27-H29 -> #REF! | I31: =I27-I29 -> #REF! | J31: =J27-J29-J30 -> 0 | K31: =K27-K29-K30 -> 0 | L31: =L27-L29-L30 -> 0 | M31: =M27-M29-M30 -> 0 | N31: =N27-N29-N30 -> 0 | O31: =O27-O29-O30 -> 0 | P31: =P27-P29-P30 -> 0 | Q31: =Q27-Q29-Q30 -> 0 | ... AI31: =AI27-AI29-AI30 -> 0 | AJ31: =AJ27-AJ29 -> #REF! | AK31: =AK27-AK29 -> #REF! | AL31: =AL27-AL29 -> #REF!
C34: Subscribed and sworn to before me this____________day | J34: Form of License | O34: BLASTER FOREMAN | V34: FKB15 - 080917- 04562 | AE34: Very respectfully | AH34: Very respectfully
C35: of ___________________, 20 _____
C37: Doc. No. | J37: _________________________________ | AE37: MR. RAFFY D. TORRES
C38: Page of | J38: NOTARY PUBLIC | AE38: Con. Tax. Cert. No. CC1202213000572
C39: Book of | J39: Until Dec. 31, 20___________________ | AE39: Issued at Consuelo Bunawan Agusan del Sur
C40: Series of | J40: Ptr No. ___________________________ | AE40: Dated Issued: June 5, 2025

Sheet FEBRUARY 2026- TIGERWAY
B1: Republic of the Philippines
B2: Department of Environment and Natural Resources
B3: MINES AND GEOSCIENCES BUREAU
B4: North Avenue, Diliman, Quezon City
B6: MONTHLY REPORT
B7: RECORD SHOWING EXPLOSIVES ON HAND, AMOUNT IMPORTED, PURCHASED FOUND, TAKEN UP, OR RECEIVED FROM AN
B8: OTHER SOURCE AND RECORD OF EXPLOSIVE ISSUED, TRANSFERRED AND/OR OTHERWISE GIVEN DISPOSITION
B10: The Chief
B11: Philippine National Police
B12: Thru The Provincial Director of PATIN-AY, PROSPERIDAD, AGUSAN DEL SUR
B13: SIR : I have the honor to submit the following report of explosives transactions and usage of the PMC Tigerway Decline Project for the month of FEBRUARY 2026
B16: RECEIPTS | C16: FEBRUARY 1-28,2026 | D16: NAME | E16: ADDRESS | F16: LICENSE NO. | P16: PACKAGE EMULSION | V16: ANFO | W16: DETONATORS | AH16: DETONATING CORD | AO16: SAFETY FUSE | AP16: BILL WIRE | AQ16: MS DETONATOR | AS16: FUSE LIGHTER | AT16: ACID | AU16: OTHERS | AV16: PUR POSE | AW16: NAME OF PERSON
I17: SENATELPULSAR | L17: SUPER POWER | M17: MAGNUM | N17: NEOGEL 901 | O17: EMULEX | P17: SENATEL | Q17: NITRO EM | R17: NEOGEL 901 | T17: NEP PRIME | U17: SUPER POWER | W17: NONEL | X17: NONEL | Y17: SUPREME | AA17: SHOCKSTAR | AE17: OBC | AF17: EBC | AH17: NEOCORD10 GRAMS | AI17: DETCORD 10 GRAMS | AJ17: 40 GRAMS | AW17: (LICENSE)
I18: 215/CASE | J18: MAGNUM 215 | K18: DYAGEL 150 | L18: 150/CASE | M18: 150/CASE | N18: 62/CASE | O18: 36 CASE | P18: 215/CASE | Q18: 91/CASE | R18: 91/CASE | S18: 200/CASE | T18: 93/CASE | U18: 208/CASE | W18: 2.4 | X18: 3.6 | Y18: 2.4 | Z18: 4.9 | AA18: 2.4 | AB18: 4.8 | AQ18: MS 12 | AR18: MS 18 | AW18: MAKING DELIVERY
I19: PIECES | J19: PIECES | K19: PIECES | L19: PIECES | M19: PIECES | N19: PIECES | O19: PIECES | P19: PIECES | Q19: PIECES | R19: PIECES | S19: PIECES | T19: PIECES | U19: PIECES | V19: KILOS | W19: PIECES | X19: PIECES | Y19: PIECES | Z19: PIECES | AA19: PIECES | AB19: PIECES | AE19: PIECES | AF19: PIECES | AH19: METERS | AI19: METERS | AJ19: METERS | AO19: METERS | AP19: METERS | AQ19: PIECES | AR19: PIECES | AS19: PIECES | AT19: KILOS
B21: ='FEBRUARY 2026 - PMC '!B21:D21 -> Beginning Stock as of as of February 1, 2026 | I21: =#REF! -> #REF! | J21: =#REF! -> #REF! | K21: =#REF! -> #REF! | L21: =#REF! -> #REF! | M21: =#REF! -> #REF! | N21: =#REF! -> #REF! | O21: =#REF! -> #REF! | P21: =#REF! -> #REF! | Q21: ='JANUARY 2026- TIGERWAY '!Q31 -> 0 | R21: ='JANUARY 2026- TIGERWAY '!R31 -> 16016 | S21: ='JANUARY 2026- TIGERWAY '!S31 -> 15800 | T21: ='JANUARY 2026- TIGERWAY '!T31 -> 0 | U21: ='JANUARY 2026- TIGERWAY '!U31 -> 0 | V21: ='JANUARY 2026- TIGERWAY '!V31 -> 1775 | W21: ='JANUARY 2026- TIGERWAY '!W31 -> 0 | X21: ='JANUARY 2026- TIGERWAY '!X31 -> 0 | ... AS21: ='JANUARY 2026- TIGERWAY '!AS31 -> 0 | AT21: =#REF! -> #REF! | AU21: =#REF! -> #REF! | AV21: =#REF! -> #REF!
C23: 46114 | D23: MOUNT ROCK POWDER CORP. | E23: AGUSAN DEL SUR | F23: PPB08-220509-03374 | O23: =235*36 -> 8460 | T23: =270*93 -> 25110 | V23: =40*25 -> 1000 | Z23: 5280 | AE23: 500 | AJ23: 3000 | AO23: 1000 | AW23: V. S. GUEVARA
C24: 2/19/2026 | D24: MOUNT ROCK POWDER CORP. | E24: AGUSAN DEL SUR | F24: PPB08-220509-03374 | V24: =80*25 -> 2000 | AW24: V. S. GUEVARA
D25: MOUNT ROCK POWDER CORP. | E25: AGUSAN DEL SUR | F25: PPB08-220509-03374 | AW25: V. S. GUEVARA
B26: FOUND
B27: Taken Up
B28: TOTAL | I28: =SUM(I21:I27) -> #REF! | J28: =SUM(J21:J27) -> #REF! | K28: =SUM(K21:K27) -> #REF! | L28: =SUM(L21:L27) -> #REF! | M28: =SUM(M21:M27) -> #REF! | N28: =SUM(N21:N27) -> #REF! | O28: =SUM(O21:O27) -> #REF! | P28: =SUM(P21:P27) -> #REF! | ... AB28: =SUM(AB21:AB27) -> 0 | AE28: =SUM(AE21:AE27) -> 951 | AF28: =SUM(AF21:AF27) -> 96 | AH28: =SUM(AH21:AH27) -> 0 | AI28: =SUM(AI21:AI27) -> 2262 | AJ28: =SUM(AJ21:AJ27) -> 3075 | AO28: =SUM(AO21:AO27) -> 1468 | AP28: =SUM(AP21:AP27) -> 0 | AQ28: =SUM(AQ21:AQ27) -> 0 | AR28: =SUM(AR21:AR27) -> 0 | AS28: =SUM(AS21:AS27) -> 0 | AT28: =SUM(AT21:AT27) -> #REF! | AU28: =SUM(AU21:AU27) -> #REF! | AV28: =SUM(AV21:AV27) -> #REF!
B29: Disposition
B30: USAGE | D30: MONTHLY USAGE /CONSUMPTION OF PMC- TIGERWAY DECLINE PROJECT (MPSA No. 262-2008-XIII PARCEL 1) | I30: 0 | J30: =SUM(J26:J29) -> #REF! | K30: =SUM(K26:K29) -> #REF! | L30: =SUM(L26:L29) -> #REF! | M30: =SUM(M26:M29) -> #REF! | O30: =350*36 -> 12600 | R30: 2002 | T30: 11904 | V30: 3575 | Z30: 1683 | AE30: 147 | AF30: 0 | AI30: 1406 | AJ30: 1575 | AO30: 171 | AP30: 0 | AS30: 0
B31: ='FEBRUARY 2026 - PMC '!B38 -> Remaining Stock as of February 28,2026 | I31: =I28-I30 -> #REF! | J31: =J28-J30 -> #REF! | K31: =K28-K30 -> #REF! | L31: =L28-L30 -> #REF! | M31: =M28-M30 -> #REF! | N31: =N28-N30 -> #REF! | O31: =O28-O30 -> #REF! | P31: =P28-P30 -> #REF! | ... AB31: =AB28-AB30 -> 0 | AE31: =AE28-AE30 -> 804 | AF31: =AF28-AF30 -> 96 | AH31: =AH28-AH30 -> 0 | AI31: =AI28-AI30 -> 856 | AJ31: =AJ28-AJ30 -> 1500 | AO31: =AO28-AO30 -> 1297 | AP31: =AP28-AP30 -> 0 | AQ31: =AQ28-AQ30 -> 0 | AR31: =AR28-AR30 -> 0 | AS31: =AS28-AS30 -> 0 | AT31: =AT28-AT30 -> #REF! | AU31: =AU28-AU30 -> #REF! | AV31: =AV28-AV30 -> #REF!
C36: Subscribed and sworn to before me this____________day | F36: Form of License | S36: BLASTER FOREMAN | AA36: FKB15 - 080917- 04562 | AI36: Very respectfully | AR36: Very respectfully
C37: of ___________________, 20 _____
C39: Doc. No. | F39: _________________________________ | AI39: MR. RAFFY D. TORRES
C40: Page of | F40: NOTARY PUBLIC | AI40: Con. Tax. Cert. No. CC1202213000572
C41: Book of | F41: Until Dec. 31, 20___________________ | AI41: Issued at Consuelo Bunawan Agusan del Sur
C42: Series of | F42: Ptr No. ___________________________ | AI42: Dated Issued: June 5, 2025

Sheet MARCH 2026 - PMC 
B1: Republic of the Philippines
B2: Department of Environment and Natural Resources
B3: MINES AND GEOSCIENCES BUREAU
B4: North Avenue, Diliman, Quezon City
B6: MONTHLY REPORT
B7: RECORD SHOWING EXPLOSIVES ON HAND, AMOUNT IMPORTED, PURCHASED FOUND, TAKEN UP, OR RECEIVED FROM AN
B8: OTHER SOURCE AND RECORD OF EXPLOSIVE ISSUED, TRANSFERRED AND/OR OTHERWISE GIVEN DISPOSITION
B10: The Chief
B11: Philippine National Police
B12: Thru The Provincial Director of PATIN-AY, PROSPERIDAD, AGUSAN DEL SUR
B13: SIR : I have the honor to submit the following report of explosive transaction and usage of PMC- Co-o Gold Project for the month of MARCH 2026
B16: RECEIPTS | C16: MARCH 1-31,2026 | D16: NAME | E16: ADDRESS | F16: LICENSE NO. | G16: PACKAGE EMULSION | Q16: ANFO | R16: DETONATORS | AB16: DETONATING CORD | AI16: savings SAFETY FUSE | AJ16: SAFETY FUSE | AK16: BILL WIRE | AL16: MS DETONATOR | AN16: FUSE LIGHTER | AO16: ACID | AP16: OTHERS | AQ16: PUR POSE | AR16: NAME OF PERSON
G17: EMULEX | H17: SUPERDYNE | I17: EM AUSTIN | J17: NEOGEL | K17: SENATEL PULSAR | N17: SUPER POWER | O17: MAG NUM | P17: SENATEL PULSAR | R17: NONEL | S17: NONEL | T17: SUPREME | V17: SHOCK STAR | W17: EXEL | Z17: OBC | AA17: EBC | AB17: 5 GRAMS | AC17: DCORD I5 GRAMS | AD17: 10 GRAMS | AE17: #11 | AF17: #6 | AG17: 6 GRAMS | AH17: 40 GRAMS | AR17: (LICENSE)
G18: 208/CASE | H18: 200 | I18: 200/CASE | J18: 200/CASE | K18: 215/CASE | L18: MAGNUM 215 | M18: 135/CASE | N18: 150/CASE | O18: 150/CASE | P18: 38/CASE | R18: 2.4 | S18: 3.6 | T18: 2.4 | U18: 3.6 | V18: 2.4 | W18: 3.6 | X18: 2.4 | Y18: 4.9 | AL18: MS 12 | AM18: MS 18 | AR18: MAKING DELIVERY
G19: PIECES | H19: PIECES | I19: PIECES | J19: PIECES | K19: PIECES | L19: PIECES | M19: PIECES | N19: PIECES | O19: PIECES | P19: PIECES | Q19: KILOS | R19: PIECES | S19: PIECES | T19: PIECES | U19: PIECES | V19: PIECES | W19: PIECES | X19: PIECES | Y19: PIECES | Z19: PIECES | AA19: PIECES | AB19: METERS | AC19: METERS | AD19: METERS | AE19: METERS | AF19: METERS | AG19: METERS | AH19: METERS | AI19: METERS | AJ19: METERS | AK19: METERS | AL19: PIECES | AM19: PIECES | AN19: PIECES | AO19: KILOS
B21: Beginning Stock as of as of March 1, 2026 | G21: =#REF! -> #REF! | H21: =#REF! -> #REF! | I21: =#REF! -> #REF! | J21: ='FEBRUARY 2026 - PMC '!J38 -> 50727 | K21: ='FEBRUARY 2026 - PMC '!K38 -> 118598 | L21: ='FEBRUARY 2026 - PMC '!L38 -> 0 | M21: ='FEBRUARY 2026 - PMC '!M38 -> 0 | N21: ='FEBRUARY 2026 - PMC '!N38 -> 0 | O21: ='FEBRUARY 2026 - PMC '!O38 -> 0 | P21: ='FEBRUARY 2026 - PMC '!P38 -> 0 | Q21: ='FEBRUARY 2026 - PMC '!Q38 -> 69941.59 | ... AQ21: ='FEBRUARY 2026 - PMC '!AQ38 -> #REF!
C23: 46359 | D23: MOUNT ROCK POWDER CORP. | E23: AGUSAN DEL SUR | F23: PPB08-220509-03374 | J23: =50*200 -> 10000 | Z23: 500 | AA23: 30 | AD23: 5000 | AR23: V. S. GUEVARA
D24: EXPEDITION MBDInc. | E24: DAVAO CITY | F24: PKB15-111108-03269 | K24: =50*215 -> 10750 | Q24: 15000 | X24: 18500 | Z24: 500 | AA24: 30 | AB24: 5400 | AJ24: 2000 | AR24: NESTOR MA
C25: 3/19/2026 | D25: MOUNT ROCK POWDER CORP. | E25: AGUSAN DEL SUR | F25: PPB08-220509-03374 | Z25: 500 | AA25: 30 | AD25: 7000 | AR25: V. S. GUEVARA
D26: EXPEDITION MBDInc. | E26: DAVAO CITY | F26: PKB15-111108-03269 | K26: 32250 | Q26: 15000 | X26: 17250 | Z26: 500 | AA26: 30 | AB26: 7200 | AJ26: 2000 | AR26: NESTOR MA
D27: MOUNT ROCK POWDER CORP. | E27: AGUSAN DEL SUR | F27: PPB08-220509-03374 | AR27: V. S. GUEVARA
D28: EXPEDITION MBDInc. | E28: DAVAO CITY | F28: PKB15-111108-03269 | AR28: NESTOR MA
D29: MOUNT ROCK POWDER CORP. | E29: AGUSAN DEL SUR | F29: PPB08-220509-03374 | AR29: V. S. GUEVARA
D30: EXPEDITION MBDInc. | E30: DAVAO CITY | F30: PKB15-111108-03269 | AR30: NESTOR MA
B31: FOUND
B32: Taken Up
B33: TOTAL | G33: =SUM(G21:G32) -> #REF! | H33: =SUM(H21:H32) -> #REF! | I33: =SUM(I21:I32) -> #REF! | J33: =SUM(J21:J32) -> 60727 | K33: =SUM(K21:K32) -> 161598 | L33: =SUM(L21:L32) -> 0 | M33: =SUM(M21:M32) -> 0 | N33: =SUM(N21:N32) -> 0 | ... AQ33: =SUM(AQ21:AQ32) -> #REF!
B34: Disposition
B35: Used or Transferred | D35: PHILSAGA MINING CORP. CO-O GOLD PROJECT CONSUMPTION (MPSA No. 262-2008-XIII PARCEL 1) | I35: 0 | J35: 55225 | K35: 46249 | Q35: 35141.07 | R35: 0 | S35: 0 | T35: 0 | W35: 368 | X35: 49312 | Y35: 0 | Z35: 5828 | AA35: 156 | AB35: 24333 | AC35: 0 | AD35: 0 | AH35: 0 | AJ35: =Z35*2.43 -> 14162.04 | AK35: 90 | AN35: 0
D36: RETURNED EXPLOSIVES STOCK FROM RCV SINUG-ANG MAGAZINE | G36: 0 | AO36: 0 | AP36: 0 | AQ36: 0
B38: Remaining Stock as of March 31,2026 | G38: =G33-G35-G36 -> #REF! | H38: =H33-H35-H36 -> #REF! | I38: =I33-I35-I36 -> #REF! | J38: =J33-J35+J36 -> 5502 | K38: =K33-K35+K36 -> 115349 | L38: =L33-L35+L36 -> 0 | M38: =M33-M35+M36 -> 0 | N38: =N33-N35+N36 -> 0 | O38: =O33-O35+O36 -> 0 | P38: =P33-P35+P36 -> 0 | Q38: =Q33-Q35+Q36 -> 64800.52 | ... AN38: =AN33-AN35+AN36 -> 275 | AO38: =AO33-AO35-AO36 -> #REF! | AP38: =AP33-AP35-AP36 -> #REF! | AQ38: =AQ33-AQ35-AQ36 -> #REF!
C43: Subscribed and sworn to before me this____________day | K43: Form of License | R43: BLASTER FOREMAN | X43: FKB15 - 080917- 04561 | AD43: Very respectfully | AM43: Very respectfully
C44: of ___________________, 20 _____
C46: Doc. No. | F46: _________________________________ | G46: _________________________________ | AD46: MR. EDWIN B. BATAL
C47: Page of | F47: NOTARY PUBLIC | G47: NOTARY PUBLIC | AD47: Con. Tax. Cert. No. CCI2022 13113698
C48: Book of | F48: Until Dec. 31, 20___________________ | G48: Until Dec. 31, 20___________________ | AD48: Issued at P-5 Poblacion Prosperidad Agusan del Sur
C49: Series of | F49: Ptr No. ___________________________ | G49: Ptr No. ___________________________ | AD49: Dated Issued: June 5, 2025

Sheet MARCH 2026 - EXPLO
B1: Republic of the Philippines
B2: Department of Environment and Natural Resources
B3: MINES AND GEOSCIENCES BUREAU
B4: North Avenue, Diliman, Quezon City
B6: MONTHLY REPORT
B7: RECORD SHOWING EXPLOSIVES ON HAND, AMOUNT IMPORTED, PURCHASED FOUND, TAKEN UP, OR RECEIVED FROM AN
B8: OTHER SOURCE AND RECORD OF EXPLOSIVE ISSUED, TRANSFERRED AND/OR OTHERWISE GIVEN DISPOSITION
B10: The Chief
B11: Philippine National Police
B12: Thru The Provincial Director of PATIN-AY, PROSPERIDAD, AGUSAN DEL SUR
B13: SIR : I have the honor to submit the following report of explosive transactions and usage of PMC - Exploration Project for the month of MARCH 2026
B16: RECEIPTS | C16: MARCH 1-31,2026 | D16: NAME | E16: ADDRESS | F16: LICENSE NO. | G16: PACKAGE EMULSION | O16: ANFO | P16: DETONATORS | X16: DETONATING CORD | AD16: savings SAFETY FUSE | AE16: SAFETY FUSE | AF16: BILL WIRE | AG16: MS DETONATOR | AI16: FUSE LIGHTER | AJ16: ACID | AK16: OTHERS | AL16: PUR POSE | AM16: NAME OF PERSON
G17: EMULEX | H17: SUPERDYNE | I17: SUPER POWER | J17: SENATELPULSAR | M17: SUPER POWER | N17: MAGNUM | P17: NONEL | Q17: NONEL | R17: SUPREME | T17: EXEL | V17: OBC | W17: EBC | X17: 5 GRAMS | Y17: 10 GRAMS | Z17: #11 | AA17: #6 | AB17: 6 GRAMS | AC17: 40 GRAMS | AM17: (LICENSE)
G18: 208/CASE | H18: 200 | I18: 208/CASE | J18: 215/CASE | K18: MAGNUM 215 | L18: DYAGEL 150 | M18: 150/CASE | N18: 150/CASE | P18: 2.4 | Q18: 3.6 | R18: 2.4 | S18: 3.6 | T18: 3.6 | U18: 2.4 | AG18: MS 12 | AH18: MS 18 | AM18: MAKING DELIVERY
G19: PIECES | H19: PIECES | I19: PIECES | J19: PIECES | K19: PIECES | L19: PIECES | M19: PIECES | N19: PIECES | O19: KILOS | P19: PIECES | Q19: PIECES | R19: PIECES | S19: PIECES | T19: PIECES | U19: PIECES | V19: PIECES | W19: PIECES | X19: METERS | Y19: METERS | Z19: METERS | AA19: METERS | AB19: METERS | AC19: METERS | AD19: METERS | AE19: METERS | AF19: METERS | AG19: PIECES | AH19: PIECES | AI19: PIECES | AJ19: KILOS
B21: ='MARCH 2026 - PMC '!B21:D21 -> Beginning Stock as of as of March 1, 2026 | G21: =#REF! -> #REF! | H21: =#REF! -> #REF! | I21: =#REF! -> #REF! | J21: ='FEBRUARY 2026 - EXPLO'!J31 -> 0 | K21: ='FEBRUARY 2026 - EXPLO'!K31 -> 0 | L21: ='FEBRUARY 2026 - EXPLO'!L31 -> 0 | M21: ='FEBRUARY 2026 - EXPLO'!M31 -> 0 | N21: ='FEBRUARY 2026 - EXPLO'!N31 -> 0 | O21: ='FEBRUARY 2026 - EXPLO'!O31 -> 0 | P21: ='FEBRUARY 2026 - EXPLO'!P31 -> 0 | Q21: ='FEBRUARY 2026 - EXPLO'!Q31 -> 0 | ... AL21: ='FEBRUARY 2026 - EXPLO'!AL31 -> #REF!
D23: EXPEDITION MBDInc. | E23: DAVAO CITY | F23: PKB15-111108-03269 | AM23: NESTOR MA
D24: EXPEDITION MBDInc. | E24: DAVAO CITY | F24: PKB15-111108-03269 | AM24: NESTOR MA
B25: FOUND
B26: Taken Up
B27: TOTAL | G27: =SUM(G21:G26) -> #REF! | H27: =SUM(H21:H26) -> #REF! | I27: =SUM(I21:I26) -> #REF! | J27: =SUM(J21:J26) -> 0 | K27: =SUM(K21:K26) -> 0 | L27: =SUM(L21:L26) -> 0 | M27: =SUM(M21:M26) -> 0 | N27: =SUM(N21:N26) -> 0 | ... AL27: =SUM(AL21:AL26) -> #REF!
B28: Disposition
B29: Used or Transferred | D29: MONTHLY USAGE /CONSUMPTION OF PMC- EXPLORATION PROJECT (MPSA No. 262-2008-XIII PARCEL-2) | G29: =SUM(G23:G28) -> #REF! | H29: =SUM(H23:H28) -> #REF! | I29: =SUM(I23:I28) -> #REF!
D30: TRANSFERRED EXPLOSIVES STOCK BACK TO PMC MINE SITE
B31: ='MARCH 2026 - PMC '!B38 -> Remaining Stock as of March 31,2026 | G31: =G27-G29 -> #REF! | H31: =H27-H29 -> #REF! | I31: =I27-I29 -> #REF! | J31: =J27-J29-J30 -> 0 | K31: =K27-K29-K30 -> 0 | L31: =L27-L29-L30 -> 0 | M31: =M27-M29-M30 -> 0 | N31: =N27-N29-N30 -> 0 | O31: =O27-O29-O30 -> 0 | P31: =P27-P29-P30 -> 0 | Q31: =Q27-Q29-Q30 -> 0 | ... AI31: =AI27-AI29-AI30 -> 0 | AJ31: =AJ27-AJ29 -> #REF! | AK31: =AK27-AK29 -> #REF! | AL31: =AL27-AL29 -> #REF!
C34: Subscribed and sworn to before me this____________day | J34: Form of License | O34: BLASTER FOREMAN | V34: FKB15 - 080917- 04561 | AE34: Very respectfully | AH34: Very respectfully
C35: of ___________________, 20 _____
C37: Doc. No. | J37: _________________________________ | AE37: MR. EDWIN B. BATAL
C38: Page of | J38: NOTARY PUBLIC | AE38: Con. Tax. Cert. No. CCI2022 13113698
C39: Book of | J39: Until Dec. 31, 20___________________ | AE39: Issued at P-5 Poblacion Prosperidad Agusan del Sur
C40: Series of | J40: Ptr No. ___________________________ | AE40: Dated Issued: June 5, 2025

Sheet MARCH 2026 TIGERWAY
B1: Republic of the Philippines
B2: Department of Environment and Natural Resources
B3: MINES AND GEOSCIENCES BUREAU
B4: North Avenue, Diliman, Quezon City
B6: MONTHLY REPORT
B7: RECORD SHOWING EXPLOSIVES ON HAND, AMOUNT IMPORTED, PURCHASED FOUND, TAKEN UP, OR RECEIVED FROM AN
B8: OTHER SOURCE AND RECORD OF EXPLOSIVE ISSUED, TRANSFERRED AND/OR OTHERWISE GIVEN DISPOSITION
B10: The Chief
B11: Philippine National Police
B12: Thru The Provincial Director of PATIN-AY, PROSPERIDAD, AGUSAN DEL SUR
B13: SIR : I have the honor to submit the following report of explosives transactions and usage of the PMC Tigerway Decline Project for the month of MARCH 2026
B16: RECEIPTS | C16: MARCH 1-31,2026 | D16: NAME | E16: ADDRESS | F16: LICENSE NO. | P16: PACKAGE EMULSION | V16: ANFO | W16: DETONATORS | AJ16: DETONATING CORD | AQ16: SAFETY FUSE | AR16: BILL WIRE | AS16: MS DETONATOR | AU16: FUSE LIGHTER | AV16: ACID | AW16: OTHERS | AX16: PUR POSE | AY16: NAME OF PERSON
I17: SENATELPULSAR | L17: SUPER POWER | M17: MAGNUM | N17: NEOGEL 901 | O17: EMULEX | P17: SENATEL | Q17: NITRO EM | R17: NEOGEL 901 | T17: NEO PRIME | U17: SUPER POWER | W17: NONEL | X17: NONEL | Y17: SUPREME | AB17: RIONEL | AC17: SHOCKSTAR | AG17: OBC | AH17: EBC | AJ17: NEOCORD10 GRAMS | AK17: DETCORD 10 GRAMS | AL17: 40 GRAMS | AY17: (LICENSE)
I18: 215/CASE | J18: MAGNUM 215 | K18: DYAGEL 150 | L18: 150/CASE | M18: 150/CASE | N18: 62/CASE | O18: 36 CASE | P18: 215/CASE | Q18: 91/CASE | R18: 91/CASE | S18: 200/CASE | T18: 93/CASE | U18: 208/CASE | W18: 2.4 | X18: 3.6 | Y18: 2.4 | Z18: 4.9 | AA18: 4.5 | AB18: 6 | AC18: 2.4 | AD18: 4.8 | AS18: MS 12 | AT18: MS 18 | AY18: MAKING DELIVERY
I19: PIECES | J19: PIECES | K19: PIECES | L19: PIECES | M19: PIECES | N19: PIECES | O19: PIECES | P19: PIECES | Q19: PIECES | R19: PIECES | S19: PIECES | T19: PIECES | U19: PIECES | V19: KILOS | W19: PIECES | X19: PIECES | Y19: PIECES | Z19: PIECES | AA19: PIECES | AB19: PIECES | AC19: PIECES | AD19: PIECES | AG19: PIECES | AH19: PIECES | AJ19: METERS | AK19: METERS | AL19: METERS | AQ19: METERS | AR19: METERS | AS19: PIECES | AT19: PIECES | AU19: PIECES | AV19: KILOS
B21: ='MARCH 2026 - PMC '!B21:D21 -> Beginning Stock as of as of March 1, 2026 | I21: =#REF! -> #REF! | J21: =#REF! -> #REF! | K21: =#REF! -> #REF! | L21: =#REF! -> #REF! | M21: =#REF! -> #REF! | N21: =#REF! -> #REF! | O21: =#REF! -> #REF! | P21: =#REF! -> #REF! | Q21: ='FEBRUARY 2026- TIGERWAY'!Q31 -> 0 | R21: ='FEBRUARY 2026- TIGERWAY'!R31 -> 14014 | S21: ='FEBRUARY 2026- TIGERWAY'!S31 -> 15800 | T21: ='FEBRUARY 2026- TIGERWAY'!T31 -> 13206 | U21: ='FEBRUARY 2026- TIGERWAY'!U31 -> 0 | V21: ='FEBRUARY 2026- TIGERWAY'!V31 -> 1200 | W21: ='FEBRUARY 2026- TIGERWAY'!W31 -> 0 | X21: ='FEBRUARY 2026- TIGERWAY'!X31 -> 0 | ... Z21: ='FEBRUARY 2026- TIGERWAY'!Z31 -> 9619 | AC21: ='FEBRUARY 2026- TIGERWAY'!AA31 -> 0 | AD21: ='FEBRUARY 2026- TIGERWAY'!AB31 -> 0 | AE21: ='FEBRUARY 2026- TIGERWAY'!AC31 -> 0 | AF21: ='FEBRUARY 2026- TIGERWAY'!AD31 -> 0 | AG21: ='FEBRUARY 2026- TIGERWAY'!AE31 -> 804 | AH21: ='FEBRUARY 2026- TIGERWAY'!AF31 -> 96 | AI21: ='FEBRUARY 2026- TIGERWAY'!AG31 -> 0 | AJ21: ='FEBRUARY 2026- TIGERWAY'!AH31 -> 0 | ... AU21: ='FEBRUARY 2026- TIGERWAY'!AS31 -> 0 | AV21: =#REF! -> #REF! | AW21: =#REF! -> #REF! | AX21: =#REF! -> #REF!
C23: 46298 | D23: MOUNT ROCK POWDER CORP. | E23: AGUSAN DEL SUR | F23: PPB08-220509-03374 | O23: =235*36 -> 8460 | R23: =91*70 -> 6370 | T23: =230*93 -> 21390 | AA23: 210 | AB23: 210 | AJ23: 10000 | AL23: 3000 | AY23: V. S. GUEVARA
C24: 03/18/2026 | D24: MOUNT ROCK POWDER CORP. | E24: AGUSAN DEL SUR | F24: PPB08-220509-03374 | V24: =80*25 -> 2000 | AY24: V. S. GUEVARA
D25: MOUNT ROCK POWDER CORP. | E25: AGUSAN DEL SUR | F25: PPB08-220509-03374 | AY25: V. S. GUEVARA
B26: FOUND
B27: Taken Up
B28: TOTAL | I28: =SUM(I21:I27) -> #REF! | J28: =SUM(J21:J27) -> #REF! | K28: =SUM(K21:K27) -> #REF! | L28: =SUM(L21:L27) -> #REF! | M28: =SUM(M21:M27) -> #REF! | N28: =SUM(N21:N27) -> #REF! | O28: =SUM(O21:O27) -> #REF! | P28: =SUM(P21:P27) -> #REF! | ... AD28: =SUM(AD21:AD27) -> 0 | AG28: =SUM(AG21:AG27) -> 804 | AH28: =SUM(AH21:AH27) -> 96 | AJ28: =SUM(AJ21:AJ27) -> 10000 | AK28: =SUM(AK21:AK27) -> 856 | AL28: =SUM(AL21:AL27) -> 4500 | AQ28: =SUM(AQ21:AQ27) -> 1297 | AR28: =SUM(AR21:AR27) -> 0 | AS28: =SUM(AS21:AS27) -> 0 | AT28: =SUM(AT21:AT27) -> 0 | AU28: =SUM(AU21:AU27) -> 0 | AV28: =SUM(AV21:AV27) -> #REF! | AW28: =SUM(AW21:AW27) -> #REF! | AX28: =SUM(AX21:AX27) -> #REF!
B29: Disposition
B30: USAGE | D30: MONTHLY USAGE /CONSUMPTION OF PMC- TIGERWAY DECLINE PROJECT (MPSA No. 262-2008-XIII PARCEL 1) | I30: 0 | J30: =SUM(J26:J29) -> #REF! | K30: =SUM(K26:K29) -> #REF! | L30: =SUM(L26:L29) -> #REF! | M30: =SUM(M26:M29) -> #REF! | O30: =350*36 -> 12600 | R30: 637 | S30: 0 | T30: 14880 | V30: 2325 | Y30: 0 | Z30: 1820 | AA30: 210 | AB30: 10 | AG30: 166 | AH30: 0 | AJ30: 145 | AK30: 856 | AL30: 1200 | AQ30: 239
B31: ='MARCH 2026 - PMC '!B38 -> Remaining Stock as of March 31,2026 | I31: =I28-I30 -> #REF! | J31: =J28-J30 -> #REF! | K31: =K28-K30 -> #REF! | L31: =L28-L30 -> #REF! | M31: =M28-M30 -> #REF! | N31: =N28-N30 -> #REF! | O31: =O28-O30 -> #REF! | P31: =P28-P30 -> #REF! | ... AD31: =AD28-AD30 -> 0 | AG31: =AG28-AG30 -> 638 | AH31: =AH28-AH30 -> 96 | AJ31: =AJ28-AJ30 -> 9855 | AK31: =AK28-AK30 -> 0 | AL31: =AL28-AL30 -> 3300 | AQ31: =AQ28-AQ30 -> 1058 | AR31: =AR28-AR30 -> 0 | AS31: =AS28-AS30 -> 0 | AT31: =AT28-AT30 -> 0 | AU31: =AU28-AU30 -> 0 | AV31: =AV28-AV30 -> #REF! | AW31: =AW28-AW30 -> #REF! | AX31: =AX28-AX30 -> #REF!
C36: Subscribed and sworn to before me this____________day | F36: Form of License | S36: BLASTER FOREMAN | AA36: FKB15 - 080917- 04561 | AC36: FKB15 - 080917- 04562 | AK36: Very respectfully | AT36: Very respectfully
C37: of ___________________, 20 _____
C39: Doc. No. | F39: _________________________________ | AK39: MR. EDWIN B. BATAL
C40: Page of | F40: NOTARY PUBLIC | AK40: Con. Tax. Cert. No. CCI2022 13113698
C41: Book of | F41: Until Dec. 31, 20___________________ | AK41: Issued at P-5 Poblacion Prosperidad Agusan del Sur
C42: Series of | F42: Ptr No. ___________________________ | AK42: Dated Issued: June 5, 2025

Sheet APRIL 2026 - PMC  
B1: Republic of the Philippines
B2: Department of Environment and Natural Resources
B3: MINES AND GEOSCIENCES BUREAU
B4: North Avenue, Diliman, Quezon City
B6: MONTHLY REPORT
B7: RECORD SHOWING EXPLOSIVES ON HAND, AMOUNT IMPORTED, PURCHASED FOUND, TAKEN UP, OR RECEIVED FROM AN
B8: OTHER SOURCE AND RECORD OF EXPLOSIVE ISSUED, TRANSFERRED AND/OR OTHERWISE GIVEN DISPOSITION
B10: The Chief
B11: Philippine National Police
B12: Thru The Provincial Director of PATIN-AY, PROSPERIDAD, AGUSAN DEL SUR
B13: SIR : I have the honor to submit the following report of explosive transaction and usage of PMC- Co-o Gold Project for the month of APRIL 2026
B16: RECEIPTS | C16: APRIL 1-30,2026 | D16: NAME | E16: ADDRESS | F16: LICENSE NO. | G16: PACKAGE EMULSION | Q16: ANFO | R16: DETONATORS | AB16: DETONATING CORD | AI16: savings SAFETY FUSE | AJ16: SAFETY FUSE | AK16: BILL WIRE | AL16: MS DETONATOR | AN16: FUSE LIGHTER | AO16: ACID | AP16: OTHERS | AQ16: PUR POSE | AR16: NAME OF PERSON
G17: EMULEX | H17: SUPERDYNE | I17: EM AUSTIN | J17: NEOGEL | K17: SENATEL PULSAR | N17: SUPER POWER | O17: MAG NUM | P17: SENATEL PULSAR | R17: NONEL | S17: NONEL | T17: SUPREME | V17: SHOCK STAR | W17: EXEL | Z17: OBC | AA17: EBC | AB17: 5 GRAMS | AC17: DCORD I5 GRAMS | AD17: 10 GRAMS | AE17: #11 | AF17: #6 | AG17: 6 GRAMS | AH17: 40 GRAMS | AR17: (LICENSE)
G18: 208/CASE | H18: 200 | I18: 200/CASE | J18: 200/CASE | K18: 215/CASE | L18: MAGNUM 215 | M18: 135/CASE | N18: 150/CASE | O18: 150/CASE | P18: 38/CASE | R18: 2.4 | S18: 3.6 | T18: 2.4 | U18: 3.6 | V18: 2.4 | W18: 3.6 | X18: 2.4 | Y18: 4.9 | AL18: MS 12 | AM18: MS 18 | AR18: MAKING DELIVERY
G19: PIECES | H19: PIECES | I19: PIECES | J19: PIECES | K19: PIECES | L19: PIECES | M19: PIECES | N19: PIECES | O19: PIECES | P19: PIECES | Q19: KILOS | R19: PIECES | S19: PIECES | T19: PIECES | U19: PIECES | V19: PIECES | W19: PIECES | X19: PIECES | Y19: PIECES | Z19: PIECES | AA19: PIECES | AB19: METERS | AC19: METERS | AD19: METERS | AE19: METERS | AF19: METERS | AG19: METERS | AH19: METERS | AI19: METERS | AJ19: METERS | AK19: METERS | AL19: PIECES | AM19: PIECES | AN19: PIECES | AO19: KILOS
B21: Beginning Stock as of as of April 1, 2026 | G21: =#REF! -> #REF! | H21: =#REF! -> #REF! | I21: =#REF! -> #REF! | J21: ='MARCH 2026 - PMC '!J38 -> 5502 | K21: ='MARCH 2026 - PMC '!K38 -> 115349 | L21: ='MARCH 2026 - PMC '!L38 -> 0 | M21: ='MARCH 2026 - PMC '!M38 -> 0 | N21: ='MARCH 2026 - PMC '!N38 -> 0 | O21: ='MARCH 2026 - PMC '!O38 -> 0 | P21: ='MARCH 2026 - PMC '!P38 -> 0 | Q21: ='MARCH 2026 - PMC '!Q38 -> 64800.52 | ... AN21: ='MARCH 2026 - PMC '!AN38 -> 275 | AO21: ='FEBRUARY 2026 - PMC '!AO38 -> #REF! | AP21: ='FEBRUARY 2026 - PMC '!AP38 -> #REF! | AQ21: ='FEBRUARY 2026 - PMC '!AQ38 -> #REF!
C23: 46238 | D23: MOUNT ROCK POWDER CORP. | E23: AGUSAN DEL SUR | F23: PPB08-220509-03374 | J23: =75*200 -> 15000 | Q23: =175*25 -> 4375 | X23: 20250 | Z23: 500 | AA23: 100 | AD23: 3000 | AR23: V. S. GUEVARA
D24: EXPEDITION MBDInc. | E24: DAVAO CITY | F24: PKB15-111108-03269 | K24: =75*215 -> 16125 | Q24: =175*25 -> 4375 | Z24: 500 | AA24: 100 | AB24: 3600 | AJ24: 3000 | AR24: NESTOR MA
C25: 4/16/2026 | D25: MOUNT ROCK POWDER CORP. | E25: AGUSAN DEL SUR | F25: PPB08-220509-03374 | Q25: =300*25 -> 7500 | X25: 7500 | Z25: 500 | AD25: 3000 | AR25: V. S. GUEVARA
D26: EXPEDITION MBDInc. | E26: DAVAO CITY | F26: PKB15-111108-03269 | Q26: 7500 | Z26: 500 | AB26: 3600 | AJ26: 4000 | AR26: NESTOR MA
C27: 4/23/2026 | D27: MOUNT ROCK POWDER CORP. | E27: AGUSAN DEL SUR | F27: PPB08-220509-03374 | J27: 20000 | Z27: 500 | AA27: 50 | AD27: 3000 | AR27: V. S. GUEVARA
D28: EXPEDITION MBDInc. | E28: DAVAO CITY | F28: PKB15-111108-03269 | K28: 21500 | Q28: =350*25 -> 8750 | W28: 1100 | X28: 11000 | Z28: 500 | AA28: 50 | AB28: 2700 | AJ28: 3000 | AR28: NESTOR MA
C29: 4/30/2026 | D29: MOUNT ROCK POWDER CORP. | E29: AGUSAN DEL SUR | F29: PPB08-220509-03374 | J29: =75*200 -> 15000 | Z29: 500 | AD29: 2000 | AR29: V. S. GUEVARA
D30: EXPEDITION MBDInc. | E30: DAVAO CITY | F30: PKB15-111108-03269 | K30: =75*215 -> 16125 | Q30: =950*25 -> 23750 | W30: 4400 | X30: 4750 | Z30: 500 | AB30: 2700 | AJ30: 3000 | AR30: NESTOR MA
B31: FOUND
B32: Taken Up
B33: TOTAL | G33: =SUM(G21:G32) -> #REF! | H33: =SUM(H21:H32) -> #REF! | I33: =SUM(I21:I32) -> #REF! | J33: =SUM(J21:J32) -> 55502 | K33: =SUM(K21:K32) -> 169099 | L33: =SUM(L21:L32) -> 0 | M33: =SUM(M21:M32) -> 0 | N33: =SUM(N21:N32) -> 0 | ... AQ33: =SUM(AQ21:AQ32) -> #REF!
B34: Disposition
B35: Used or Transferred | D35: PHILSAGA MINING CORP. CO-O GOLD PROJECT CONSUMPTION (MPSA No. 262-2008-XIII PARCEL 1) | I35: 0 | J35: 16788 | K35: 63497 | Q35: 26252.2 | R35: 0 | S35: 0 | T35: 0 | W35: 570 | X35: 39526 | Z35: 4599 | AA35: 148 | AB35: 10819 | AC35: 0 | AD35: 8389 | AH35: 0 | AJ35: =Z35*2.43 -> 11175.57 | AK35: 30 | AN35: 0
D36: RETURNED EXPLOSIVES STOCK FROM RCV SINUG-ANG MAGAZINE | G36: 0 | AO36: 0 | AP36: 0 | AQ36: 0
B38: Remaining Stock as of April 30,2026 | G38: =G33-G35-G36 -> #REF! | H38: =H33-H35-H36 -> #REF! | I38: =I33-I35-I36 -> #REF! | J38: =J33-J35+J36 -> 38714 | K38: =K33-K35+K36 -> 105602 | L38: =L33-L35+L36 -> 0 | M38: =M33-M35+M36 -> 0 | N38: =N33-N35+N36 -> 0 | O38: =O33-O35+O36 -> 0 | P38: =P33-P35+P36 -> 0 | Q38: =Q33-Q35+Q36 -> 94798.32 | ... AN38: =AN33-AN35+AN36 -> 275 | AO38: =AO33-AO35-AO36 -> #REF! | AP38: =AP33-AP35-AP36 -> #REF! | AQ38: =AQ33-AQ35-AQ36 -> #REF!
C43: Subscribed and sworn to before me this____________day | K43: Form of License | R43: BLASTER FOREMAN | X43: FKB15 - 080917- 04561 | AD43: Very respectfully | AM43: Very respectfully
C44: of ___________________, 20 _____
C46: Doc. No. | F46: _________________________________ | G46: _________________________________ | AD46: MR. EDWIN B. BATAL
C47: Page of | F47: NOTARY PUBLIC | G47: NOTARY PUBLIC | AD47: Con. Tax. Cert. No. CCI2022 13113698
C48: Book of | F48: Until Dec. 31, 20___________________ | G48: Until Dec. 31, 20___________________ | AD48: Issued at P-5 Poblacion Prosperidad Agusan del Sur
C49: Series of | F49: Ptr No. ___________________________ | G49: Ptr No. ___________________________ | AD49: Dated Issued: June 5, 2025

Sheet APRIL 2026 - EXPLO
B1: Republic of the Philippines
B2: Department of Environment and Natural Resources
B3: MINES AND GEOSCIENCES BUREAU
B4: North Avenue, Diliman, Quezon City
B6: MONTHLY REPORT
B7: RECORD SHOWING EXPLOSIVES ON HAND, AMOUNT IMPORTED, PURCHASED FOUND, TAKEN UP, OR RECEIVED FROM AN
B8: OTHER SOURCE AND RECORD OF EXPLOSIVE ISSUED, TRANSFERRED AND/OR OTHERWISE GIVEN DISPOSITION
B10: The Chief
B11: Philippine National Police
B12: Thru The Provincial Director of PATIN-AY, PROSPERIDAD, AGUSAN DEL SUR
B13: SIR : I have the honor to submit the following report of explosive transactions and usage of PMC - Exploration Project for the month of APRIL 2026
B16: RECEIPTS | C16: APRIL 1-30,2026 | D16: NAME | E16: ADDRESS | F16: LICENSE NO. | G16: PACKAGE EMULSION | O16: ANFO | P16: DETONATORS | X16: DETONATING CORD | AD16: savings SAFETY FUSE | AE16: SAFETY FUSE | AF16: BILL WIRE | AG16: MS DETONATOR | AI16: FUSE LIGHTER | AJ16: ACID | AK16: OTHERS | AL16: PUR POSE | AM16: NAME OF PERSON
G17: EMULEX | H17: SUPERDYNE | I17: SUPER POWER | J17: SENATELPULSAR | M17: SUPER POWER | N17: MAGNUM | P17: NONEL | Q17: NONEL | R17: SUPREME | T17: EXEL | V17: OBC | W17: EBC | X17: 5 GRAMS | Y17: 10 GRAMS | Z17: #11 | AA17: #6 | AB17: 6 GRAMS | AC17: 40 GRAMS | AM17: (LICENSE)
G18: 208/CASE | H18: 200 | I18: 208/CASE | J18: 215/CASE | K18: MAGNUM 215 | L18: DYAGEL 150 | M18: 150/CASE | N18: 150/CASE | P18: 2.4 | Q18: 3.6 | R18: 2.4 | S18: 3.6 | T18: 3.6 | U18: 2.4 | AG18: MS 12 | AH18: MS 18 | AM18: MAKING DELIVERY
G19: PIECES | H19: PIECES | I19: PIECES | J19: PIECES | K19: PIECES | L19: PIECES | M19: PIECES | N19: PIECES | O19: KILOS | P19: PIECES | Q19: PIECES | R19: PIECES | S19: PIECES | T19: PIECES | U19: PIECES | V19: PIECES | W19: PIECES | X19: METERS | Y19: METERS | Z19: METERS | AA19: METERS | AB19: METERS | AC19: METERS | AD19: METERS | AE19: METERS | AF19: METERS | AG19: PIECES | AH19: PIECES | AI19: PIECES | AJ19: KILOS
B21: ='APRIL 2026 - PMC '!B21:D21 -> Beginning Stock as of as of April 1, 2026 | G21: =#REF! -> #REF! | H21: =#REF! -> #REF! | I21: =#REF! -> #REF! | J21: ='FEBRUARY 2026 - EXPLO'!J31 -> 0 | K21: ='FEBRUARY 2026 - EXPLO'!K31 -> 0 | L21: ='FEBRUARY 2026 - EXPLO'!L31 -> 0 | M21: ='FEBRUARY 2026 - EXPLO'!M31 -> 0 | N21: ='FEBRUARY 2026 - EXPLO'!N31 -> 0 | O21: ='FEBRUARY 2026 - EXPLO'!O31 -> 0 | P21: ='FEBRUARY 2026 - EXPLO'!P31 -> 0 | Q21: ='FEBRUARY 2026 - EXPLO'!Q31 -> 0 | ... AL21: ='FEBRUARY 2026 - EXPLO'!AL31 -> #REF!
D23: EXPEDITION MBDInc. | E23: DAVAO CITY | F23: PKB15-111108-03269 | AM23: NESTOR MA
D24: EXPEDITION MBDInc. | E24: DAVAO CITY | F24: PKB15-111108-03269 | AM24: NESTOR MA
B25: FOUND
B26: Taken Up
B27: TOTAL | G27: =SUM(G21:G26) -> #REF! | H27: =SUM(H21:H26) -> #REF! | I27: =SUM(I21:I26) -> #REF! | J27: =SUM(J21:J26) -> 0 | K27: =SUM(K21:K26) -> 0 | L27: =SUM(L21:L26) -> 0 | M27: =SUM(M21:M26) -> 0 | N27: =SUM(N21:N26) -> 0 | ... AL27: =SUM(AL21:AL26) -> #REF!
B28: Disposition
B29: Used or Transferred | D29: MONTHLY USAGE /CONSUMPTION OF PMC- EXPLORATION PROJECT (MPSA No. 262-2008-XIII PARCEL-2) | G29: =SUM(G23:G28) -> #REF! | H29: =SUM(H23:H28) -> #REF! | I29: =SUM(I23:I28) -> #REF!
D30: TRANSFERRED EXPLOSIVES STOCK BACK TO PMC MINE SITE
B31: ='APRIL 2026 - PMC '!B38 -> Remaining Stock as of April 30,2026 | G31: =G27-G29 -> #REF! | H31: =H27-H29 -> #REF! | I31: =I27-I29 -> #REF! | J31: =J27-J29-J30 -> 0 | K31: =K27-K29-K30 -> 0 | L31: =L27-L29-L30 -> 0 | M31: =M27-M29-M30 -> 0 | N31: =N27-N29-N30 -> 0 | O31: =O27-O29-O30 -> 0 | P31: =P27-P29-P30 -> 0 | Q31: =Q27-Q29-Q30 -> 0 | ... AI31: =AI27-AI29-AI30 -> 0 | AJ31: =AJ27-AJ29 -> #REF! | AK31: =AK27-AK29 -> #REF! | AL31: =AL27-AL29 -> #REF!
